Workbook

Sheet Historical Financials
B2: Klarna Group plc (KLAR)
B3: Historical Financials
B4: $ mm except per share
A6: X | B6: Income Statement | C6: FYE | Q6: Quarterly | W6: LTM | AK6: LTM | AL6: LTM | AR6: Variance
B7: Fiscal Period | C7: 2022 | D7: 2023 | E7: 2024 | G7: 1Q22 | H7: 2Q22 | I7: 3Q22 | J7: 4Q22 | K7: 1Q23 | L7: 2Q23 | M7: 3Q23 | N7: 4Q23 | O7: 1Q24 | P7: 2Q24 | Q7: 3Q24 | R7: 4Q24 | S7: 1Q25 | T7: 2Q25 | U7: 3Q25 | W7: =#REF! -> #REF! | X7: =#REF! -> #REF! | Y7: =#REF! -> #REF! | Z7: =#REF! -> #REF! | AA7: =#REF! -> #REF! | AB7: =#REF! -> #REF! | AC7: =#REF! -> #REF! | AD7: =#REF! -> #REF! | ... AI7: =#REF! -> #REF! | AJ7: =O7 -> 1Q24 | AK7: =P7 -> 2Q24 | AL7: =Q7 -> 3Q24 | AM7: =R7 -> 4Q24 | AN7: =S7 -> 1Q25 | AO7: =T7 -> 2Q25 | AP7: =U7 -> 3Q25
B8: Fiscal Period End Date | C8: 44926 | D8: 45291 | E8: 45657 | G8: 44651 | H8: 44742 | I8: 44834 | J8: =C8 -> 44926 | K8: 45016 | L8: 45107 | M8: 45199 | N8: =D8 -> 45291 | O8: 45382 | P8: 45473 | Q8: 45565 | R8: =E8 -> 45657 | S8: 45747 | T8: 45838 | U8: 45930 | W8: =#REF! -> #REF! | X8: =#REF! -> #REF! | Y8: =#REF! -> #REF! | Z8: =#REF! -> #REF! | AA8: =#REF! -> #REF! | AB8: =#REF! -> #REF! | AC8: =#REF! -> #REF! | AD8: =#REF! -> #REF! | ... AI8: =#REF! -> #REF! | AJ8: =O8 -> 45382 | AK8: =P8 -> 45473 | AL8: =Q8 -> 45565 | AM8: =R8 -> 45657 | AN8: =S8 -> 45747 | AO8: =T8 -> 45838 | AP8: =U8 -> 45930
B10: Consolidated Revenue | C10: 1904 | D10: 2276 | E10: 2811 | G10: 457.87832 | H10: 483.44314 | I10: 433.10787 | J10: =SUM(C10-SUM(G10:I10)) -> 529.57067 | K10: 484.15423 | L10: 534.07557 | M10: 574.77938 | N10: =SUM(D10-SUM(K10:M10)) -> 682.99082 | O10: 635.32869 | P10: 675.93368 | Q10: 718.35223 | R10: =SUM(E10-SUM(O10:Q10)) -> 781.38539 | S10: 701.13716 | T10: 823.10162 | U10: 903 | W10: =SUM(#REF!) -> #REF! | X10: =SUM(#REF!) -> #REF! | Y10: =SUM(#REF!) -> #REF! | Z10: =SUM(#REF!) -> #REF! | AA10: =SUM(#REF!) -> #REF! | AB10: =SUM(#REF!) -> #REF! | AC10: =SUM(#REF!) -> #REF! | AD10: =SUM(#REF!) -> #REF! | ... AI10: =SUM(#REF!) -> #REF! | AJ10: =SUM(O10:O10) -> 635.32869 | AK10: =SUM(O10:P10) -> 1311.2624 | AL10: =SUM(O10:Q10) -> 2029.6146 | AM10: =SUM(O10:R10) -> 2811 | AN10: =SUM(P10:S10) -> 2876.8085 | AO10: =SUM(Q10:T10) -> 3023.9764 | AP10: =SUM(R10:U10) -> 3208.6242 | AR10: =SUM(AP10/AL10)-1 -> 0.58090317
B11: Total Revenue | C11: =+SUM(C10:C10) -> 1904 | D11: =+SUM(D10:D10) -> 2276 | E11: =+SUM(E10:E10) -> 2811 | G11: =+SUM(G10:G10) -> 457.87832 | H11: =+SUM(H10:H10) -> 483.44314 | I11: =+SUM(I10:I10) -> 433.10787 | J11: =+SUM(J10:J10) -> 529.57067 | K11: =+SUM(K10:K10) -> 484.15423 | L11: =+SUM(L10:L10) -> 534.07557 | M11: =+SUM(M10:M10) -> 574.77938 | N11: =+SUM(N10:N10) -> 682.99082 | ... U11: =+SUM(U10:U10) -> 903 | W11: =+SUM(W10:W10) -> #REF! | X11: =+SUM(X10:X10) -> #REF! | Y11: =+SUM(Y10:Y10) -> #REF! | Z11: =+SUM(Z10:Z10) -> #REF! | AA11: =+SUM(AA10:AA10) -> #REF! | AB11: =+SUM(AB10:AB10) -> #REF! | AC11: =+SUM(AC10:AC10) -> #REF! | AD11: =+SUM(AD10:AD10) -> #REF! | ... AP11: =+SUM(AP10:AP10) -> 3208.6242 | AR11: =SUM(AP11/AL11)-1 -> 0.58090317
B13: Processing and servicing costs | C13: -520 | D13: -541 | E13: -596 | G13: -122.86115 | H13: -140.3493 | I13: -119.00793 | J13: =SUM(C13-SUM(G13:I13)) -> -137.78162 | K13: -127.9813 | L13: -131.41075 | M13: -133.22809 | N13: =SUM(D13-SUM(K13:M13)) -> -148.37987 | O13: -135.90164 | P13: -148.01296 | Q13: -151.29141 | R13: =SUM(E13-SUM(O13:Q13)) -> -160.79398 | S13: -163.90402 | T13: -187.17015 | U13: -208 | W13: =SUM(#REF!) -> #REF! | X13: =SUM(#REF!) -> #REF! | Y13: =SUM(#REF!) -> #REF! | Z13: =SUM(#REF!) -> #REF! | AA13: =SUM(#REF!) -> #REF! | AB13: =SUM(#REF!) -> #REF! | AC13: =SUM(#REF!) -> #REF! | AD13: =SUM(#REF!) -> #REF! | ... AI13: =SUM(#REF!) -> #REF! | AJ13: =SUM(O13:O13) -> -135.90164 | AK13: =SUM(O13:P13) -> -283.91461 | AL13: =SUM(O13:Q13) -> -435.20602 | AM13: =SUM(O13:R13) -> -596 | AN13: =SUM(P13:S13) -> -624.00238 | AO13: =SUM(Q13:T13) -> -663.15957 | AP13: =SUM(R13:U13) -> -719.86816 | AR13: =SUM(AP13/AL13)-1 -> 0.65408593
B14: Consumer credit losses | C14: -550 | D14: -353 | E14: -495 | G14: -124.71731 | H14: -166.09766 | I14: -136.43861 | J14: =SUM(C14-SUM(G14:I14)) -> -122.74643 | K14: -72.849766 | L14: -88.327096 | M14: -72.010591 | N14: =SUM(D14-SUM(K14:M14)) -> -119.81255 | O14: -116.66508 | P14: -106.30731 | Q14: -115.60805 | R14: =SUM(E14-SUM(O14:Q14)) -> -156.41956 | S14: -136.19618 | T14: -173.5701 | U14: -235 | AL14: =SUM(O14:Q14) -> -338.58044 | AM14: =SUM(O14:R14) -> -495 | AN14: =SUM(P14:S14) -> -514.5311 | AO14: =SUM(Q14:T14) -> -581.79389 | AP14: =SUM(R14:U14) -> -701.18584 | AR14: =SUM(AP14/AL14)-1 -> 1.0709579
B15: Funding costs | C15: -147 | D15: -297 | E15: -503 | G15: -30.028678 | H15: -30.251101 | I15: -39.36219 | J15: =SUM(C15-SUM(G15:I15)) -> -47.358031 | K15: -56.835333 | L15: -62.384282 | M15: -77.893781 | N15: =SUM(D15-SUM(K15:M15)) -> -99.886603 | O15: -113.38908 | P15: -119.84023 | Q15: -122.80654 | R15: =SUM(E15-SUM(O15:Q15)) -> -146.96414 | S15: -130.27724 | T15: -147.34958 | U15: -180 | AL15: =SUM(O15:Q15) -> -356.03586 | AM15: =SUM(O15:R15) -> -503 | AN15: =SUM(P15:S15) -> -519.88816 | AO15: =SUM(Q15:T15) -> -547.39751 | AP15: =SUM(R15:U15) -> -604.59097 | AR15: =SUM(AP15/AL15)-1 -> 0.6981182
B16: Gross Profit (Transaction Margin Dollars) | C16: =+SUM(C11+SUM(C13:C15)) -> 687 | D16: =+SUM(D11+SUM(D13:D15)) -> 1085 | E16: =+SUM(E11+SUM(E13:E15)) -> 1217 | G16: =+SUM(G11+SUM(G13:G15)) -> 180.27119 | H16: =+SUM(H11+SUM(H13:H15)) -> 146.74508 | I16: =+SUM(I11+SUM(I13:I15)) -> 138.29914 | J16: =+SUM(J11+SUM(J13:J15)) -> 221.68459 | K16: =+SUM(K11+SUM(K13:K15)) -> 226.48784 | L16: =+SUM(L11+SUM(L13:L15)) -> 251.95345 | M16: =+SUM(M11+SUM(M13:M15)) -> 291.64691 | N16: =+SUM(N11+SUM(N13:N15)) -> 314.9118 | ... U16: =+SUM(U11+SUM(U13:U15)) -> 280 | W16: =+SUM(W11+SUM(W13:W13)) -> #REF! | X16: =+SUM(X11+SUM(X13:X13)) -> #REF! | Y16: =+SUM(Y11+SUM(Y13:Y13)) -> #REF! | Z16: =+SUM(Z11+SUM(Z13:Z13)) -> #REF! | AA16: =+SUM(AA11+SUM(AA13:AA13)) -> #REF! | AB16: =+SUM(AB11+SUM(AB13:AB13)) -> #REF! | AC16: =+SUM(AC11+SUM(AC13:AC13)) -> #REF! | AD16: =+SUM(AD11+SUM(AD13:AD13)) -> #REF! | ... AK16: =+SUM(AK11+SUM(AK13:AK13)) -> 1027.3478 | AL16: =+SUM(AL11+SUM(AL13:AL15)) -> 899.79229 | AM16: =+SUM(AM11+SUM(AM13:AM15)) -> 1217 | AN16: =+SUM(AN11+SUM(AN13:AN15)) -> 1218.3868 | AO16: =+SUM(AO11+SUM(AO13:AO15)) -> 1231.6254 | AP16: =+SUM(AP11+SUM(AP13:AP15)) -> 1182.9792 | AR16: =SUM(AP16/AL16)-1 -> 0.31472476
B17: Gross Margin (%) | C17: =C16/C11 -> 0.36081933 | D17: =D16/D11 -> 0.47671353 | E17: =E16/E11 -> 0.43294201 | G17: =G16/G11 -> 0.39370981 | H17: =H16/H11 -> 0.30354155 | I17: =I16/I11 -> 0.31931801 | J17: =J16/J11 -> 0.41861191 | K17: =K16/K11 -> 0.46780101 | L17: =L16/L11 -> 0.47175617 | M17: =M16/M11 -> 0.50740671 | N17: =N16/N11 -> 0.46107765 | ... U17: =U16/U11 -> 0.31007752 | W17: =W16/W11 -> #REF! | X17: =X16/X11 -> #REF! | Y17: =Y16/Y11 -> #REF! | Z17: =Z16/Z11 -> #REF! | AA17: =AA16/AA11 -> #REF! | AB17: =AB16/AB11 -> #REF! | AC17: =AC16/AC11 -> #REF! | AD17: =AD16/AD11 -> #REF! | ... AP17: =AP16/AP11 -> 0.36868737 | AR17: =SUM(AP17-AL17)*1000 -> -74.64423
B19: Technology and product development | C19: -355.14437 | D19: -276.4925 | E19: -307.83389 | G19: -96.741726 | H19: -107.08367 | I19: -69.442446 | J19: =SUM(C19-SUM(G19:I19)) -> -81.876523 | K19: -66.668118 | L19: -70.24335 | M19: -64.689124 | N19: =SUM(D19-SUM(K19:M19)) -> -74.89191 | O19: -78.315834 | P19: -80.95758 | Q19: -77.696906 | R19: =SUM(E19-SUM(O19:Q19)) -> -70.863571 | S19: -83.019928 | T19: -93.232776 | U19: -97 | AL19: =SUM(O19:Q19) -> -236.97032 | AM19: =SUM(O19:R19) -> -307.83389 | AN19: =SUM(P19:S19) -> -312.53798 | AO19: =SUM(Q19:T19) -> -324.81318 | AP19: =SUM(R19:U19) -> -344.11627 | AR19: =SUM(AP19/AL19)-1 -> 0.45214926
B20: Sales and Marketing (S&M) | C20: -523.16659 | D20: -371.67993 | E20: -309.06155 | G20: -136.26446 | H20: -154.38537 | I20: -96.270785 | J20: =SUM(C20-SUM(G20:I20)) -> -136.24597 | K20: -74.05317 | L20: -81.772555 | M20: -78.908538 | N20: =SUM(D20-SUM(K20:M20)) -> -136.94567 | O20: -76.354386 | P20: -76.742658 | Q20: -65.442832 | R20: =SUM(E20-SUM(O20:Q20)) -> -90.52167 | S20: -79.667124 | T20: -82.899178 | U20: -85 | AL20: =SUM(O20:Q20) -> -218.53988 | AM20: =SUM(O20:R20) -> -309.06155 | AN20: =SUM(P20:S20) -> -312.37428 | AO20: =SUM(Q20:T20) -> -318.5308 | AP20: =SUM(R20:U20) -> -338.08797 | AR20: =SUM(AP20/AL20)-1 -> 0.54703104
B21: Customer service and operations | C21: -285.51807 | D21: -238.31196 | E21: -192.41582 | G21: -78.401399 | H21: -80.958778 | I21: -60.835907 | J21: =SUM(C21-SUM(G21:I21)) -> -65.321982 | K21: -62.666632 | L21: -53.704776 | M21: -52.34587 | N21: =SUM(D21-SUM(K21:M21)) -> -69.594678 | O21: -56.855008 | P21: -47.379999 | Q21: -42.017432 | R21: =SUM(E21-SUM(O21:Q21)) -> -46.163386 | S21: -50.275283 | T21: -48.020048 | U21: -50 | AL21: =SUM(O21:Q21) -> -146.25244 | AM21: =SUM(O21:R21) -> -192.41582 | AN21: =SUM(P21:S21) -> -185.8361 | AO21: =SUM(Q21:T21) -> -186.47615 | AP21: =SUM(R21:U21) -> -194.45872 | AR21: =SUM(AP21/AL21)-1 -> 0.32961008
B22: General and Administrative (G&A) | C22: -248.72763 | D22: -247.95489 | E22: -226.7649 | G22: -65.534632 | H22: -53.049638 | I22: -61.373631 | J22: =SUM(C22-SUM(G22:I22)) -> -68.769733 | K22: -60.081628 | L22: -55.965976 | M22: -50.3652 | N22: =SUM(D22-SUM(K22:M22)) -> -81.542083 | O22: -50.458582 | P22: -57.564682 | Q22: -51.71173 | R22: =SUM(E22-SUM(O22:Q22)) -> -67.029906 | S22: -54.492572 | T22: -61.598968 | U22: -63 | AL22: =SUM(O22:Q22) -> -159.73499 | AM22: =SUM(O22:R22) -> -226.7649 | AN22: =SUM(P22:S22) -> -230.79889 | AO22: =SUM(Q22:T22) -> -234.83318 | AP22: =SUM(R22:U22) -> -246.12145 | AR22: =SUM(AP22/AL22)-1 -> 0.54081106
B23: Restructuring Charges | C23: -35.728705 | D23: -5.308423 | E23: -5.7080184 | G23: 0 | H23: -34.404786 | I23: 1.1317286 | J23: =SUM(C23-SUM(G23:I23)) -> -2.4556476 | K23: 0 | L23: -2.204065 | M23: 0.021758 | N23: =SUM(D23-SUM(K23:M23)) -> -3.126116 | O23: 0 | P23: 0 | Q23: -2.917737 | R23: =SUM(E23-SUM(O23:Q23)) -> -2.7902814 | S23: -4.3000001e-07 | T23: 4.2173656 | U23: -5 | AL23: =SUM(O23:Q23) -> -2.917737 | AM23: =SUM(O23:R23) -> -5.7080184 | AN23: =SUM(P23:S23) -> -5.7080188 | AO23: =SUM(Q23:T23) -> -1.4906532 | AP23: =SUM(R23:U23) -> -3.5729162 | AR23: =SUM(AP23/AL23)-1 -> 0.22455047
B24: Share based Payments | C24: -56.314768 | D24: -42.596111 | E24: -91.840168 | G24: -18.302156 | H24: -16.410189 | I24: -8.6047788 | J24: =SUM(C24-SUM(G24:I24)) -> -12.997645 | K24: -9.8012168 | L24: -12.632712 | M24: -8.7612611 | N24: =SUM(D24-SUM(K24:M24)) -> -11.400921 | O24: -5.4089236 | P24: -8.8826422 | Q24: -20.142968 | R24: =SUM(E24-SUM(O24:Q24)) -> -57.405634 | S24: -58.543661 | T24: -26.392681 | U24: -39 | AL24: =SUM(O24:Q24) -> -34.434534 | AM24: =SUM(O24:R24) -> -91.840168 | AN24: =SUM(P24:S24) -> -144.97491 | AO24: =SUM(Q24:T24) -> -162.48494 | AP24: =SUM(R24:U24) -> -181.34198 | AR24: =SUM(AP24/AL24)-1 -> 4.2662823
B25: IPO Related Charges | C25: 0 | D25: 0 | E25: -15.123364 | G25: 0 | H25: 0 | I25: 0 | J25: =SUM(C25-SUM(G25:I25)) -> 0 | K25: 0 | L25: 0 | M25: 0 | N25: =SUM(D25-SUM(K25:M25)) -> 0 | O25: -1.5503133 | P25: -2.2861342 | Q25: -6.0381063 | R25: =SUM(E25-SUM(O25:Q25)) -> -5.2488098 | S25: -8.3823611 | T25: -1.9570492 | U25: 0 | AL25: =SUM(O25:Q25) -> -9.8745538 | AM25: =SUM(O25:R25) -> -15.123364 | AN25: =SUM(P25:S25) -> -21.955411 | AO25: =SUM(Q25:T25) -> -21.626326 | AP25: =SUM(R25:U25) -> -15.58822 | AR25: =SUM(AP25/AL25)-1 -> 0.57862527
B26: Depreciation, amortization and impairments | C26: -161.9695 | D26: -226.06808 | E26: -188.8674 | G26: -29.04236 | H26: -41.805338 | I26: -46.63717 | J26: =SUM(C26-SUM(G26:I26)) -> -44.484636 | K26: -55.639149 | L26: -52.558621 | M26: -40.713393 | N26: =SUM(D26-SUM(K26:M26)) -> -77.156919 | O26: -36.23425 | P26: -37.992838 | Q26: -37.228717 | R26: =SUM(E26-SUM(O26:Q26)) -> -77.4116 | S26: -25.947516 | T26: -50.733473 | U26: -25 | AL26: =SUM(O26:Q26) -> -111.4558 | AM26: =SUM(O26:R26) -> -188.8674 | AN26: =SUM(P26:S26) -> -178.58067 | AO26: =SUM(Q26:T26) -> -191.32131 | AP26: =SUM(R26:U26) -> -179.09259 | AR26: =SUM(AP26/AL26)-1 -> 0.60684846
B27: Operating Profit | C27: =+SUM(C16+SUM(C19:C26)) -> -979.56963 | D27: =+SUM(D16+SUM(D19:D26)) -> -323.41189 | E27: =+SUM(E16+SUM(E19:E26)) -> -120.61512 | G27: =+SUM(G16+SUM(G19:G26)) -> -244.01555 | H27: =+SUM(H16+SUM(H19:H26)) -> -341.35269 | I27: =+SUM(I16+SUM(I19:I26)) -> -203.73385 | J27: =+SUM(J16+SUM(J19:J26)) -> -190.46755 | K27: =+SUM(K16+SUM(K19:K26)) -> -102.42208 | L27: =+SUM(L16+SUM(L19:L26)) -> -77.128606 | M27: =+SUM(M16+SUM(M19:M26)) -> -4.1147128 | N27: =+SUM(N16+SUM(N19:N26)) -> -139.74649 | ... U27: =+SUM(U16+SUM(U19:U26)) -> -84 | W27: =+SUM(W16+SUM(W19:W26)) -> #REF! | X27: =+SUM(X16+SUM(X19:X26)) -> #REF! | Y27: =+SUM(Y16+SUM(Y19:Y26)) -> #REF! | Z27: =+SUM(Z16+SUM(Z19:Z26)) -> #REF! | AA27: =+SUM(AA16+SUM(AA19:AA26)) -> #REF! | AB27: =+SUM(AB16+SUM(AB19:AB26)) -> #REF! | AC27: =+SUM(AC16+SUM(AC19:AC26)) -> #REF! | AD27: =+SUM(AD16+SUM(AD19:AD26)) -> #REF! | ... AP27: =+SUM(AP16+SUM(AP19:AP26)) -> -319.4009 | AR27: =SUM(AP27/AL27)-1 -> 14.666148
B28: Operating Margin (%) | C28: =C27/C11 -> -0.51447985 | D28: =D27/D11 -> -0.14209661 | E28: =E27/E11 -> -0.042908259 | G28: =G27/G11 -> -0.53292663 | H28: =H27/H11 -> -0.70608653 | I28: =I27/I11 -> -0.47039979 | J28: =J27/J11 -> -0.35966408 | K28: =K27/K11 -> -0.21154845 | L28: =L27/L11 -> -0.14441515 | M28: =M27/M11 -> -0.007158769 | N28: =N27/N11 -> -0.20460962 | ... U28: =U27/U11 -> -0.093023256 | W28: =W27/W11 -> #REF! | X28: =X27/X11 -> #REF! | Y28: =Y27/Y11 -> #REF! | Z28: =Z27/Z11 -> #REF! | AA28: =AA27/AA11 -> #REF! | AB28: =AB27/AB11 -> #REF! | AC28: =AC27/AC11 -> #REF! | AD28: =AD27/AD11 -> #REF! | ... AP28: =AP27/AP11 -> -0.099544504 | AR28: =SUM(AP28-AL28)*1000 -> -89.499264
B30: Other income (expense) | C30: -58 | D30: 19 | E30: 154 | G30: -39.595378 | H30: -41.426308 | I30: 14.249358 | J30: =SUM(C30-SUM(G30:I30)) -> 8.7723281 | K30: 3.884331 | L30: -4.4317395 | M30: 7.8084026 | N30: =SUM(D30-SUM(K30:M30)) -> 11.739006 | O30: 10.32992 | P30: 7.2860645 | Q30: -10.722127 | R30: =SUM(E30-SUM(O30:Q30)) -> 147.10614 | S30: -1.8055911 | T30: -0.23400613 | U30: -4 | W30: =SUM(#REF!) -> #REF! | X30: =SUM(#REF!) -> #REF! | Y30: =SUM(#REF!) -> #REF! | Z30: =SUM(#REF!) -> #REF! | AA30: =SUM(#REF!) -> #REF! | AB30: =SUM(#REF!) -> #REF! | AC30: =SUM(#REF!) -> #REF! | AD30: =SUM(#REF!) -> #REF! | ... AI30: =SUM(#REF!) -> #REF! | AJ30: =SUM(O30:O30) -> 10.32992 | AK30: =SUM(O30:P30) -> 17.615985 | AL30: =SUM(O30:Q30) -> 6.8938572 | AM30: =SUM(O30:R30) -> 154 | AN30: =SUM(P30:S30) -> 141.86449 | AO30: =SUM(Q30:T30) -> 134.34442 | AP30: =SUM(R30:U30) -> 141.06655 | AR30: =SUM(AP30/AL30)-1 -> 19.462644
B31: Earning Before Taxes | C31: =SUM(C27+SUM(C30:C30)) -> -1037.5696 | D31: =SUM(D27+SUM(D30:D30)) -> -304.41189 | E31: =SUM(E27+SUM(E30:E30)) -> 33.384884 | G31: =SUM(G27+SUM(G30:G30)) -> -283.61093 | H31: =SUM(H27+SUM(H30:H30)) -> -382.779 | I31: =SUM(I27+SUM(I30:I30)) -> -189.48449 | J31: =SUM(J27+SUM(J30:J30)) -> -181.69522 | K31: =SUM(K27+SUM(K30:K30)) -> -98.537746 | L31: =SUM(L27+SUM(L30:L30)) -> -81.560346 | M31: =SUM(M27+SUM(M30:M30)) -> 3.6936898 | N31: =SUM(N27+SUM(N30:N30)) -> -128.00749 | ... U31: =SUM(U27+SUM(U30:U30)) -> -88 | W31: =SUM(W27+SUM(W30:W30)) -> #REF! | X31: =SUM(X27+SUM(X30:X30)) -> #REF! | Y31: =SUM(Y27+SUM(Y30:Y30)) -> #REF! | Z31: =SUM(Z27+SUM(Z30:Z30)) -> #REF! | AA31: =SUM(AA27+SUM(AA30:AA30)) -> #REF! | AB31: =SUM(AB27+SUM(AB30:AB30)) -> #REF! | AC31: =SUM(AC27+SUM(AC30:AC30)) -> #REF! | AD31: =SUM(AD27+SUM(AD30:AD30)) -> #REF! | ... AP31: =SUM(AP27+SUM(AP30:AP30)) -> -178.33436 | AR31: =SUM(AP31/AL31)-1 -> 12.215719
B32: EBT Margin (%) | C32: =C31/C11 -> -0.54494203 | D32: =D31/D11 -> -0.13374863 | E32: =E31/E11 -> 0.011876515 | G32: =G31/G11 -> -0.61940239 | H32: =H31/H11 -> -0.79177666 | I32: =I31/I11 -> -0.43749954 | J32: =J31/J11 -> -0.3430991 | K32: =K31/K11 -> -0.20352553 | L32: =L31/L11 -> -0.15271312 | M32: =M31/M11 -> 0.0064262741 | N32: =N31/N11 -> -0.18742197 | ... U32: =U31/U11 -> -0.097452935 | W32: =W31/W11 -> #REF! | X32: =X31/X11 -> #REF! | Y32: =Y31/Y11 -> #REF! | Z32: =Z31/Z11 -> #REF! | AA32: =AA31/AA11 -> #REF! | AB32: =AB31/AB11 -> #REF! | AC32: =AC31/AC11 -> #REF! | AD32: =AD31/AD11 -> #REF! | ... AP32: =AP31/AP11 -> -0.055579696 | AR32: =SUM(AP32-AL32)*1000 -> -48.931089
B34: Provision for taxes | C34: -8.2544085 | D34: 60 | E34: -12 | G34: -3.0776812 | H34: -1.036735 | I34: -3.3575318 | J34: =SUM(C34-SUM(G34:I34)) -> -0.78246048 | K34: 54.984441 | L34: -10.274186 | M34: 0.35908703 | N34: =SUM(D34-SUM(K34:M34)) -> 14.930658 | O34: -4.9203694 | P34: 0.93651644 | Q34: -2.3003912 | R34: =SUM(E34-SUM(O34:Q34)) -> -5.7157559 | S34: -7.4439852 | T34: -7.0970093 | U34: -8 | W34: =SUM(#REF!) -> #REF! | X34: =SUM(#REF!) -> #REF! | Y34: =SUM(#REF!) -> #REF! | Z34: =SUM(#REF!) -> #REF! | AA34: =SUM(#REF!) -> #REF! | AB34: =SUM(#REF!) -> #REF! | AC34: =SUM(#REF!) -> #REF! | AD34: =SUM(#REF!) -> #REF! | ... AI34: =SUM(#REF!) -> #REF! | AJ34: =SUM(O34:O34) -> -4.9203694 | AK34: =SUM(O34:P34) -> -3.9838529 | AL34: =SUM(O34:Q34) -> -6.2842441 | AM34: =SUM(O34:R34) -> -12 | AN34: =SUM(P34:S34) -> -14.523616 | AO34: =SUM(Q34:T34) -> -22.557142 | AP34: =SUM(R34:U34) -> -28.25675 | AR34: =SUM(AP34/AL34)-1 -> 3.4964438
B35: Net loss | C35: =SUM(C31+SUM(C34:C34)) -> -1045.824 | D35: =SUM(D31+SUM(D34:D34)) -> -244.41189 | E35: =SUM(E31+SUM(E34:E34)) -> 21.384884 | G35: =SUM(G31+SUM(G34:G34)) -> -286.68861 | H35: =SUM(H31+SUM(H34:H34)) -> -383.81573 | I35: =SUM(I31+SUM(I34:I34)) -> -192.84202 | J35: =SUM(J31+SUM(J34:J34)) -> -182.47768 | K35: =SUM(K31+SUM(K34:K34)) -> -43.553305 | L35: =SUM(L31+SUM(L34:L34)) -> -91.834532 | M35: =SUM(M31+SUM(M34:M34)) -> 4.0527769 | N35: =SUM(N31+SUM(N34:N34)) -> -113.07683 | ... U35: =SUM(U31+SUM(U34:U34)) -> -96 | W35: =SUM(W31+SUM(W34:W34)) -> #REF! | X35: =SUM(X31+SUM(X34:X34)) -> #REF! | Y35: =SUM(Y31+SUM(Y34:Y34)) -> #REF! | Z35: =SUM(Z31+SUM(Z34:Z34)) -> #REF! | AA35: =SUM(AA31+SUM(AA34:AA34)) -> #REF! | AB35: =SUM(AB31+SUM(AB34:AB34)) -> #REF! | AC35: =SUM(AC31+SUM(AC34:AC34)) -> #REF! | AD35: =SUM(AD31+SUM(AD34:AD34)) -> #REF! | ... AP35: =SUM(AP31+SUM(AP34:AP34)) -> -206.59111 | AR35: =SUM(AP35/AL35)-1 -> 9.4453137
B36: Net Margin (%) | C36: =C35/C11 -> -0.54927733 | D36: =D35/D11 -> -0.10738659 | E36: =E35/E11 -> 0.0076075716 | G36: =G35/G11 -> -0.62612401 | H36: =H35/H11 -> -0.79392114 | I36: =I35/I11 -> -0.44525172 | J36: =J35/J11 -> -0.34457663 | K36: =K35/K11 -> -0.089957502 | L36: =L35/L11 -> -0.17195044 | M36: =M35/M11 -> 0.007051013 | N36: =N35/N11 -> -0.16556127 | ... U36: =U35/U11 -> -0.10631229 | W36: =W35/W11 -> #REF! | X36: =X35/X11 -> #REF! | Y36: =Y35/Y11 -> #REF! | Z36: =Z35/Z11 -> #REF! | AA36: =AA35/AA11 -> #REF! | AB36: =AB35/AB11 -> #REF! | AC36: =AC35/AC11 -> #REF! | AD36: =AD35/AD11 -> #REF! | ... AP36: =AP35/AP11 -> -0.064386197 | AR36: =SUM(AP36-AL36)*1000 -> -54.641315
B38: Basic Shares | C38: 382.33536 | D38: 382.33536 | E38: 382.33536 | G38: 382.33536 | H38: 382.33536 | I38: 382.33536 | J38: =C38 -> 382.33536 | K38: 382.33536 | L38: 382.33536 | M38: 382.33536 | N38: =D38 -> 382.33536 | O38: 382.33536 | P38: 382.33536 | Q38: 382.33536 | R38: =E38 -> 382.33536 | S38: 382.33536 | T38: 382.33536 | U38: 382.33536 | W38: =B38 -> Basic Shares | X38: =C38 -> 382.33536 | Y38: =D38 -> 382.33536 | Z38: =E38 -> 382.33536 | AA38: =F38 -> 0 | AB38: =G38 -> 382.33536 | AC38: =H38 -> 382.33536 | AD38: =I38 -> 382.33536 | ... AP38: =U38 -> 382.33536 | AR38: =SUM(AP38/AL38)-1 -> 0
B39: Basic EPS | C39: =C35/C38 -> -2.7353579 | D39: =D35/D38 -> -0.63926049 | E39: =E35/E38 -> 0.055932268 | G39: =G35/G38 -> -0.74983546 | H39: =H35/H38 -> -1.0038719 | I39: =I35/I38 -> -0.50437925 | J39: =J35/J38 -> -0.47727126 | K39: =K35/K38 -> -0.11391388 | L39: =L35/L38 -> -0.24019367 | M39: =M35/M38 -> 0.010600058 | N39: =N35/N38 -> -0.295753 | ... U39: =U35/U38 -> -0.25108847 | W39: =W35/W38 -> #REF! | X39: =X35/X38 -> #REF! | Y39: =Y35/Y38 -> #REF! | Z39: =Z35/Z38 -> #REF! | AA39: =AA35/AA38 -> #REF! | AB39: =AB35/AB38 -> #REF! | AC39: =AC35/AC38 -> #REF! | AD39: =AD35/AD38 -> #REF! | ... AP39: =AP35/AP38 -> -0.54034005 | AR39: =SUM(AP39/AL39)-1 -> 9.4453137
B41: Fully Diluted Shares | C41: 385.56633 | D41: 385.56633 | E41: 385.56633 | G41: 385.56633 | H41: 385.56633 | I41: 385.56633 | J41: =C41 -> 385.56633 | K41: 385.56633 | L41: 385.56633 | M41: 385.56633 | N41: =D41 -> 385.56633 | O41: 385.56633 | P41: 385.56633 | Q41: 385.56633 | R41: =E41 -> 385.56633 | S41: 385.56633 | T41: 385.56633 | U41: 385.56633 | W41: =B41 -> Fully Diluted Shares | X41: =C41 -> 385.56633 | Y41: =D41 -> 385.56633 | Z41: =E41 -> 385.56633 | AA41: =F41 -> 0 | AB41: =G41 -> 385.56633 | AC41: =H41 -> 385.56633 | AD41: =I41 -> 385.56633 | ... AP41: =U41 -> 385.56633 | AR41: =SUM(AP41/AL41)-1 -> 0
B42: Fully Diluted EPS | C42: =C35/C41 -> -2.7124361 | D42: =D35/D41 -> -0.63390362 | E42: =E35/E41 -> 0.055463567 | G42: =G35/G41 -> -0.74355199 | H42: =H35/H41 -> -0.99545968 | I42: =I35/I41 -> -0.50015266 | J42: =J35/J41 -> -0.47327182 | K42: =K35/K41 -> -0.11295931 | L42: =L35/L41 -> -0.23818089 | M42: =M35/M41 -> 0.010511231 | N42: =N35/N41 -> -0.29327465 | ... U42: =U35/U41 -> -0.2489844 | W42: =W35/W41 -> #REF! | X42: =X35/X41 -> #REF! | Y42: =Y35/Y41 -> #REF! | Z42: =Z35/Z41 -> #REF! | AA42: =AA35/AA41 -> #REF! | AB42: =AB35/AB41 -> #REF! | AC42: =AC35/AC41 -> #REF! | AD42: =AD35/AD41 -> #REF! | ... AP42: =AP35/AP41 -> -0.53581211 | AR42: =SUM(AP42/AL42)-1 -> 9.4453137
A44: X | B44: Balance Sheet | AK44: LTM | AR44: Variance
B45: =B7 -> Fiscal Period | C45: =C7 -> 2022 | D45: =D7 -> 2023 | E45: =E7 -> 2024 | G45: =G7 -> 1Q22 | H45: =H7 -> 2Q22 | I45: =I7 -> 3Q22 | J45: =J7 -> 4Q22 | K45: =K7 -> 1Q23 | L45: =L7 -> 2Q23 | M45: =M7 -> 3Q23 | N45: =N7 -> 4Q23 | ... U45: =U7 -> 3Q25 | W45: =W7 -> #REF! | X45: =X7 -> #REF! | Y45: =Y7 -> #REF! | Z45: =Z7 -> #REF! | AA45: =AA7 -> #REF! | AB45: =AB7 -> #REF! | AC45: =AC7 -> #REF! | AD45: =AD7 -> #REF! | ... AP45: =AP7 -> 3Q25
B46: =B8 -> Fiscal Period End Date | C46: =C8 -> 44926 | D46: =D8 -> 45291 | E46: =E8 -> 45657 | G46: =G8 -> 44651 | H46: =H8 -> 44742 | I46: =I8 -> 44834 | J46: =J8 -> 44926 | K46: =K8 -> 45016 | L46: =L8 -> 45107 | M46: =M8 -> 45199 | N46: =N8 -> 45291 | ... U46: =U8 -> 45930 | W46: =W8 -> #REF! | X46: =X8 -> #REF! | Y46: =Y8 -> #REF! | Z46: =Z8 -> #REF! | AA46: =AA8 -> #REF! | AB46: =AB8 -> #REF! | AC46: =AC8 -> #REF! | AD46: =AD8 -> #REF! | ... AP46: =AP8 -> 45930
B48: Assets
B49: Cash and cash equivalents | C49: 1694.2579 | D49: 2390.1 | E49: 3242.9703 | G49: 1253.2419 | H49: 907.76546 | I49: 1545.2618 | J49: =C49 -> 1694.2579 | K49: 2162.3429 | L49: 1263.809 | M49: 2344.1758 | N49: =D49 -> 2390.1 | O49: 3629 | P49: 3419.4387 | Q49: 3843.3251 | R49: =E49 -> 3242.9703 | S49: 4104.9278 | T49: 5503.6166 | U49: 6795 | W49: =#REF! -> #REF! | X49: =#REF! -> #REF! | Y49: =#REF! -> #REF! | Z49: =#REF! -> #REF! | AA49: =#REF! -> #REF! | AB49: =#REF! -> #REF! | AC49: =#REF! -> #REF! | AD49: =#REF! -> #REF! | ... AI49: =#REF! -> #REF! | AJ49: =O49 -> 3629 | AK49: =P49 -> 3419.4387 | AL49: =Q49 -> 3843.3251 | AM49: =R49 -> 3242.9703 | AN49: =S49 -> 4104.9278 | AO49: =T49 -> 5503.6166 | AP49: =U49 -> 6795 | AR49: =SUM(AP49/AL49)-1 -> 0.76800031
B50: Debt securities | C50: 1121.1853 | D50: 798.6 | E50: 453.71243 | G50: 1580.4882 | H50: 1272.571 | I50: 1192.9042 | J50: =C50 -> 1121.1853 | K50: 1089.7286 | L50: 970.11563 | M50: 872.75237 | N50: =D50 -> 798.6 | O50: 1014.1019 | P50: 972.36892 | Q50: 785.17702 | R50: =E50 -> 453.71243 | S50: 1187.7035 | T50: 1380.9545 | U50: 1657 | W50: =#REF! -> #REF! | X50: =#REF! -> #REF! | Y50: =#REF! -> #REF! | Z50: =#REF! -> #REF! | AA50: =#REF! -> #REF! | AB50: =#REF! -> #REF! | AC50: =#REF! -> #REF! | AD50: =#REF! -> #REF! | ... AI50: =#REF! -> #REF! | AJ50: =O50 -> 1014.1019 | AK50: =P50 -> 972.36892 | AL50: =Q50 -> 785.17702 | AM50: =R50 -> 453.71243 | AN50: =S50 -> 1187.7035 | AO50: =T50 -> 1380.9545 | AP50: =U50 -> 1657 | AR50: =SUM(AP50/AL50)-1 -> 1.1103521
B51: Consumer receivables | C51: 6756.7639 | D51: 8082.9 | E51: 8141.0163 | G51: 6406.4419 | H51: 6397.3181 | I51: 5649.0709 | J51: =C51 -> 6756.7639 | K51: 6209.947 | L51: 6801.8853 | M51: 6681.2242 | N51: =D51 -> 8082.9 | O51: 7501.6233 | P51: 7954.5852 | Q51: 8548.41 | R51: =E51 -> 8141.0163 | S51: 8123.756 | T51: 9950.1662 | U51: 10095 | W51: =#REF! -> #REF! | X51: =#REF! -> #REF! | Y51: =#REF! -> #REF! | Z51: =#REF! -> #REF! | AA51: =#REF! -> #REF! | AB51: =#REF! -> #REF! | AC51: =#REF! -> #REF! | AD51: =#REF! -> #REF! | ... AI51: =#REF! -> #REF! | AJ51: =O51 -> 7501.6233 | AK51: =P51 -> 7954.5852 | AL51: =Q51 -> 8548.41 | AM51: =R51 -> 8141.0163 | AN51: =S51 -> 8123.756 | AO51: =T51 -> 9950.1662 | AP51: =U51 -> 10095 | AR51: =SUM(AP51/AL51)-1 -> 0.18092137
...

Sheet Revenue Drivers
B2: ='Historical Financials'!B2 -> Klarna Group plc (KLAR) | C2: FYE | G2: Quarterly | H2: Quarterly | O2: Quarterly | P2: Quarterly | W2: LTM | AA2: LTM | AC2: LTM | AI2: Variance
B3: Segment Anaysis | C3: ='Historical Financials'!C7 -> 2022 | D3: ='Historical Financials'!D7 -> 2023 | E3: ='Historical Financials'!E7 -> 2024 | G3: ='Historical Financials'!G7 -> 1Q22 | H3: ='Historical Financials'!H7 -> 2Q22 | I3: ='Historical Financials'!I7 -> 3Q22 | J3: ='Historical Financials'!J7 -> 4Q22 | K3: ='Historical Financials'!K7 -> 1Q23 | L3: ='Historical Financials'!L7 -> 2Q23 | M3: ='Historical Financials'!M7 -> 3Q23 | N3: ='Historical Financials'!N7 -> 4Q23 | ... U3: ='Historical Financials'!U7 -> 3Q25 | W3: =#REF! -> #REF! | X3: =#REF! -> #REF! | Y3: =#REF! -> #REF! | Z3: =#REF! -> #REF! | AA3: =O3 -> 1Q24 | AB3: =P3 -> 2Q24 | AC3: =Q3 -> 3Q24 | AD3: =R3 -> 4Q24 | AE3: =S3 -> 1Q25 | AF3: =T3 -> 2Q25 | AG3: =U3 -> 3Q25
B4: $ mm except per share | C4: ='Historical Financials'!C8 -> 44926 | D4: ='Historical Financials'!D8 -> 45291 | E4: ='Historical Financials'!E8 -> 45657 | G4: ='Historical Financials'!G8 -> 44651 | H4: ='Historical Financials'!H8 -> 44742 | I4: ='Historical Financials'!I8 -> 44834 | J4: ='Historical Financials'!J8 -> 44926 | K4: ='Historical Financials'!K8 -> 45016 | L4: ='Historical Financials'!L8 -> 45107 | M4: ='Historical Financials'!M8 -> 45199 | N4: ='Historical Financials'!N8 -> 45291 | ... U4: ='Historical Financials'!U8 -> 45930 | W4: =#REF! -> #REF! | X4: =#REF! -> #REF! | Y4: =#REF! -> #REF! | Z4: =#REF! -> #REF! | AA4: =O4 -> 45382 | AB4: =P4 -> 45473 | AC4: =Q4 -> 45565 | AD4: =R4 -> 45657 | AE4: =S4 -> 45747 | AF4: =T4 -> 45838 | AG4: =U4 -> 45930
A6: X | B6: Offerings Drivers
B8: Disaggregated Revenues
B9: Transaction and service revenue | C9: 1468 | D9: 1768 | E9: 2136 | G9: 344.58814 | H9: 369.20095 | I9: 331.21869 | J9: =SUM(C9-SUM(G9:I9)) -> 422.99222 | K9: 368.13111 | L9: 417.98173 | M9: 440.43433 | N9: =SUM(D9-SUM(K9:M9)) -> 541.45284 | O9: 478.72442 | P9: 512.16003 | Q9: 544.55104 | R9: =SUM(E9-SUM(O9:Q9)) -> 600.56451 | S9: 519.31403 | T9: 603.94886 | U9: 634 | W9: =SUM(#REF!) -> #REF! | X9: =SUM(#REF!) -> #REF! | Y9: =SUM(#REF!) -> #REF! | Z9: =SUM(#REF!) -> #REF! | AA9: =SUM(O9:O9) -> 478.72442 | AB9: =SUM(O9:P9) -> 990.88445 | AC9: =SUM(O9:Q9) -> 1535.4355 | AD9: =SUM(O9:R9) -> 2136 | AE9: =SUM(P9:S9) -> 2176.5896 | AF9: =SUM(Q9:T9) -> 2268.3784 | AG9: =SUM(R9:U9) -> 2357.8274 | AI9: =SUM(AG9/AC9)-1 -> 0.53560825
B10: Interest income | C10: 436 | D10: 508 | E10: 675 | G10: 113.29018 | H10: 114.24219 | I10: 101.88917 | J10: =SUM(C10-SUM(G10:I10)) -> 106.57845 | K10: 116.02312 | L10: 116.09384 | M10: 134.34505 | N10: =SUM(D10-SUM(K10:M10)) -> 141.53799 | O10: 156.60428 | P10: 163.77365 | Q10: 173.80119 | R10: =SUM(E10-SUM(O10:Q10)) -> 180.82088 | S10: 181.82312 | T10: 219.15276 | U10: 269 | AC10: =SUM(O10:Q10) -> 494.17912 | AD10: =SUM(O10:R10) -> 675 | AE10: =SUM(P10:S10) -> 700.21885 | AF10: =SUM(Q10:T10) -> 755.59796 | AG10: =SUM(R10:U10) -> 850.79676 | AI10: =SUM(AG10/AC10)-1 -> 0.72163641
B11: Total Net Revenue | C11: =SUM(C9:C10) -> 1904 | D11: =SUM(D9:D10) -> 2276 | E11: =SUM(E9:E10) -> 2811 | G11: =SUM(G9:G10) -> 457.87832 | H11: =SUM(H9:H10) -> 483.44314 | I11: =SUM(I9:I10) -> 433.10787 | J11: =SUM(J9:J10) -> 529.57067 | K11: =SUM(K9:K10) -> 484.15423 | L11: =SUM(L9:L10) -> 534.07557 | M11: =SUM(M9:M10) -> 574.77938 | N11: =SUM(N9:N10) -> 682.99082 | ... U11: =SUM(U9:U10) -> 903 | W11: =SUM(W9:W10) -> #REF! | X11: =SUM(X9:X10) -> #REF! | Y11: =SUM(Y9:Y10) -> #REF! | Z11: =SUM(Z9:Z10) -> #REF! | AA11: =SUM(AA9:AA10) -> 478.72442 | AB11: =SUM(AB9:AB10) -> 990.88445 | AC11: =SUM(AC9:AC10) -> 2029.6146 | AD11: =SUM(AD9:AD10) -> 2811 | ... AG11: =SUM(AG9:AG10) -> 3208.6242 | AI11: =SUM(AG11/AC11)-1 -> 0.58090317
B12: Variance Check | C12: =+C11-'Historical Financials'!C11 -> 0 | D12: =+D11-'Historical Financials'!D11 -> 0 | E12: =+E11-'Historical Financials'!E11 -> 0 | G12: =G11-'Historical Financials'!G11 -> 0 | H12: =H11-'Historical Financials'!H11 -> 0 | I12: =I11-'Historical Financials'!I11 -> 0 | J12: =J11-'Historical Financials'!J11 -> 0 | K12: =K11-'Historical Financials'!K11 -> 0 | L12: =L11-'Historical Financials'!L11 -> 0 | M12: =M11-'Historical Financials'!M11 -> 0 | N12: =N11-'Historical Financials'!N11 -> 0 | ... U12: =U11-'Historical Financials'!U11 -> 0 | W12: =+W11-'Historical Financials'!AF11 -> #REF! | X12: =+X11-'Historical Financials'!AG11 -> #REF! | Y12: =+Y11-'Historical Financials'!AH11 -> #REF! | Z12: =+Z11-'Historical Financials'!AI11 -> #REF! | AA12: =+AA11-'Historical Financials'!AJ11 -> -156.60428 | AB12: =+AB11-'Historical Financials'!AK11 -> -320.37793 | AC12: =+AC11-'Historical Financials'!AL11 -> 0 | AD12: =+AD11-'Historical Financials'!AM11 -> 0 | ... AF12: =+AF11-'Historical Financials'!AO11 -> 0 | AG12: =AG11-'Historical Financials'!AP11 -> 0
B14: Transaction and Service Revenue
B15: Merchant Revenue | C15: =C$9*C22 -> 1115.68 | D15: =D$9*D22 -> 1343.68 | E15: =E$9*E22 -> 1602 | J15: =SUM(C15-SUM(G15:I15)) -> 1115.68 | R15: =SUM(E15-SUM(O15:Q15)) -> 1602 | W15: =SUM(#REF!) -> #REF! | X15: =SUM(#REF!) -> #REF! | Y15: =SUM(#REF!) -> #REF! | Z15: =SUM(#REF!) -> #REF! | AA15: =SUM(O15:O15) -> 0 | AB15: =SUM(O15:P15) -> 0 | AC15: =SUM(O15:Q15) -> 0 | AD15: =SUM(O15:R15) -> 1602 | AE15: =SUM(P15:S15) -> 1602 | AF15: =SUM(Q15:T15) -> 1602 | AG15: =SUM(R15:U15) -> 1602 | AI15: =SUM(AG15/AC15)-1 -> #DIV/0!
B16: Advertising Revenue | C16: =C$9*C23 -> 161.48 | D16: =D$9*D23 -> 159.12 | E16: =E$9*E23 -> 170.88 | J16: =SUM(C16-SUM(G16:I16)) -> 161.48 | R16: =SUM(E16-SUM(O16:Q16)) -> 170.88
B17: Consumer Service Revenue | C17: =C$9*C24 -> 176.16 | D17: =D$9*D24 -> 229.84 | E17: =E$9*E24 -> 341.76 | J17: =SUM(C17-SUM(G17:I17)) -> 176.16 | R17: =SUM(E17-SUM(O17:Q17)) -> 341.76 | AC17: =SUM(O17:Q17) -> 0 | AD17: =SUM(O17:R17) -> 341.76 | AE17: =SUM(P17:S17) -> 341.76 | AF17: =SUM(Q17:T17) -> 341.76 | AG17: =SUM(R17:U17) -> 341.76 | AI17: =SUM(AG17/AC17)-1 -> #DIV/0!
B18: Intersegment Elimination | C18: =+SUM(C9-SUM(C15:C17)) -> 14.68 | D18: =+SUM(D9-SUM(D15:D17)) -> 35.36 | E18: =+SUM(E9-SUM(E15:E17)) -> 21.36 | J18: =SUM(C18-SUM(G18:I18)) -> 14.68 | R18: =SUM(E18-SUM(O18:Q18)) -> 21.36
B19: Total Transaction & Service Revenue | C19: =SUM(C15:C18) -> 1468 | D19: =SUM(D15:D18) -> 1768 | E19: =SUM(E15:E18) -> 2136 | G19: =SUM(G15:G17) -> 0 | H19: =SUM(H15:H17) -> 0 | I19: =SUM(I15:I17) -> 0 | J19: =SUM(J15:J17) -> 1453.32 | K19: =SUM(K15:K17) -> 0 | L19: =SUM(L15:L17) -> 0 | M19: =SUM(M15:M17) -> 0 | N19: =SUM(N15:N17) -> 0 | ... U19: =SUM(U15:U17) -> 0 | W19: =SUM(W15:W17) -> #REF! | X19: =SUM(X15:X17) -> #REF! | Y19: =SUM(Y15:Y17) -> #REF! | Z19: =SUM(Z15:Z17) -> #REF! | AA19: =SUM(AA15:AA17) -> 0 | AB19: =SUM(AB15:AB17) -> 0 | AC19: =SUM(AC15:AC17) -> 0 | AD19: =SUM(AD15:AD17) -> 1943.76 | ... AG19: =SUM(AG15:AG17) -> 1943.76 | AI19: =SUM(AG19/AC19)-1 -> #DIV/0!
B20: Variance Check | C20: =+C19-C9 -> 0 | D20: =+D19-D9 -> 0 | E20: =+E19-E9 -> 0 | G20: =G19-'Historical Financials'!#REF! -> #REF! | H20: =H19-'Historical Financials'!#REF! -> #REF! | I20: =I19-'Historical Financials'!#REF! -> #REF! | J20: =J19-'Historical Financials'!#REF! -> #REF! | K20: =K19-'Historical Financials'!#REF! -> #REF! | L20: =L19-'Historical Financials'!#REF! -> #REF! | M20: =M19-'Historical Financials'!#REF! -> #REF! | N20: =N19-'Historical Financials'!#REF! -> #REF! | ... U20: =U19-'Historical Financials'!#REF! -> #REF! | W20: =+W19-'Historical Financials'!#REF! -> #REF! | X20: =+X19-'Historical Financials'!#REF! -> #REF! | Y20: =+Y19-'Historical Financials'!#REF! -> #REF! | Z20: =+Z19-'Historical Financials'!#REF! -> #REF! | AA20: =+AA19-'Historical Financials'!#REF! -> #REF! | AB20: =+AB19-'Historical Financials'!#REF! -> #REF! | AC20: =+AC19-'Historical Financials'!#REF! -> #REF! | AD20: =+AD19-'Historical Financials'!#REF! -> #REF! | ... AF20: =+AF19-'Historical Financials'!#REF! -> #REF! | AG20: =AG19-'Historical Financials'!#REF! -> #REF!
B22: Merchant Revenue (%) | C22: 0.76 | D22: 0.76 | E22: 0.75
B23: Advertising Revenue (%) | C23: 0.11 | D23: 0.09 | E23: 0.08
B24: Consumer Service Revenue (%) | C24: 0.12 | D24: 0.13 | E24: 0.16
B26: Consumer Service Revenue
B27: Reminder Fees | C27: =C$17*C32 -> 165.5904 | D27: =D$17*D32 -> 190.7672 | E27: =E$17*E32 -> 252.9024 | J27: =SUM(C27-SUM(G27:I27)) -> 165.5904 | R27: =SUM(E27-SUM(O27:Q27)) -> 252.9024 | AC27: =SUM(O27:Q27) -> 0 | AD27: =SUM(O27:R27) -> 252.9024 | AE27: =SUM(P27:S27) -> 252.9024 | AF27: =SUM(Q27:T27) -> 252.9024 | AG27: =SUM(R27:U27) -> 252.9024 | AI27: =SUM(AG27/AC27)-1 -> #DIV/0!
B28: Other Revenues | C28: =C$17*C33 -> 10.5696 | D28: =D$17*D33 -> 39.0728 | E28: =E$17*E33 -> 88.8576 | J28: =SUM(C28-SUM(G28:I28)) -> 10.5696 | R28: =SUM(E28-SUM(O28:Q28)) -> 88.8576
B29: Total Transaction & Service Revenue | C29: =SUM(C27:C28) -> 176.16 | D29: =SUM(D27:D28) -> 229.84 | E29: =SUM(E27:E28) -> 341.76 | G29: =SUM(G27:G27) -> 0 | H29: =SUM(H27:H27) -> 0 | I29: =SUM(I27:I27) -> 0 | J29: =SUM(J27:J27) -> 165.5904 | K29: =SUM(K27:K27) -> 0 | L29: =SUM(L27:L27) -> 0 | M29: =SUM(M27:M27) -> 0 | N29: =SUM(N27:N27) -> 0 | ... U29: =SUM(U27:U27) -> 0 | W29: =SUM(W27:W27) -> 0 | X29: =SUM(X27:X27) -> 0 | Y29: =SUM(Y27:Y27) -> 0 | Z29: =SUM(Z27:Z27) -> 0 | AA29: =SUM(AA27:AA27) -> 0 | AB29: =SUM(AB27:AB27) -> 0 | AC29: =SUM(AC27:AC27) -> 0 | AD29: =SUM(AD27:AD27) -> 252.9024 | ... AG29: =SUM(AG27:AG27) -> 252.9024 | AI29: =SUM(AG29/AC29)-1 -> #DIV/0!
B30: Variance Check | C30: =C29-C17 -> 0 | D30: =D29-D17 -> 0 | E30: =E29-E17 -> 0 | G30: =G29-'Historical Financials'!G31 -> 283.61093 | H30: =H29-'Historical Financials'!H31 -> 382.779 | I30: =I29-'Historical Financials'!I31 -> 189.48449 | J30: =J29-'Historical Financials'!J31 -> 347.28562 | K30: =K29-'Historical Financials'!K31 -> 98.537746 | L30: =L29-'Historical Financials'!L31 -> 81.560346 | M30: =M29-'Historical Financials'!M31 -> -3.6936898 | N30: =N29-'Historical Financials'!N31 -> 128.00749 | ... U30: =U29-'Historical Financials'!U31 -> 88 | W30: =+W29-'Historical Financials'!AF31 -> #REF! | X30: =+X29-'Historical Financials'!AG31 -> #REF! | Y30: =+Y29-'Historical Financials'!AH31 -> #REF! | Z30: =+Z29-'Historical Financials'!AI31 -> #REF! | AA30: =+AA29-'Historical Financials'!AJ31 -> -509.75697 | AB30: =+AB29-'Historical Financials'!AK31 -> -1044.9638 | AC30: =+AC29-'Historical Financials'!AL31 -> 13.494109 | AD30: =+AD29-'Historical Financials'!AM31 -> 219.51752 | ... AF30: =+AF29-'Historical Financials'!AO31 -> 328.50908 | AG30: =AG29-'Historical Financials'!AP31 -> 431.23676
B32: Merchant Revenue (%) | C32: 0.94 | D32: 0.83 | E32: 0.74
B33: Consumer Service Revenue (%) | C33: =1-C32 -> 0.06 | D33: =1-D32 -> 0.17 | E33: =1-E32 -> 0.26
A35: X | B35: KPIs
B37: GMV Per Channel
B38: Merchant checkout | C38: 75239 | D38: 84642 | E38: 95623 | R38: =SUM(E38-SUM(O38:Q38)) -> 95623
B39: Direct-to-consumer | C39: 7598 | D39: 7823 | E39: 9392 | R39: =SUM(E39-SUM(O39:Q39)) -> 9392 | W39: =SUM(#REF!) -> #REF! | X39: =SUM(#REF!) -> #REF! | Y39: =SUM(#REF!) -> #REF! | Z39: =SUM(#REF!) -> #REF! | AA39: =SUM(O39:O39) -> 0 | AB39: =SUM(O39:P39) -> 0 | AC39: =SUM(O39:Q39) -> 0 | AD39: =SUM(O39:R39) -> 9392 | AE39: =SUM(P39:S39) -> 9392 | AF39: =SUM(Q39:T39) -> 9392 | AG39: =SUM(R39:U39) -> 9392 | AI39: =SUM(AG39/AC39)-1 -> #DIV/0!
B40: Total GMW | C40: =SUM(C38:C39) -> 82837 | D40: =SUM(D38:D39) -> 92465 | E40: =SUM(E38:E39) -> 105015 | G40: =SUM(G38:G39) -> 0 | H40: =SUM(H38:H39) -> 0 | I40: =SUM(I38:I39) -> 0 | J40: =SUM(J38:J39) -> 0 | K40: =SUM(K38:K39) -> 0 | L40: =SUM(L38:L39) -> 0 | M40: =SUM(M38:M39) -> 0 | N40: =SUM(N38:N39) -> 0 | ... U40: =SUM(U38:U39) -> 0 | W40: =SUM(W39:W39) -> #REF! | X40: =SUM(X39:X39) -> #REF! | Y40: =SUM(Y39:Y39) -> #REF! | Z40: =SUM(Z39:Z39) -> #REF! | AA40: =SUM(AA39:AA39) -> 0 | AB40: =SUM(AB39:AB39) -> 0 | AC40: =SUM(AC39:AC39) -> 0 | AD40: =SUM(AD39:AD39) -> 9392 | ... AG40: =SUM(AG39:AG39) -> 9392 | AI40: =SUM(AG40/AC40)-1 -> #DIV/0!
B42: Pay in Full (%) | C42: 0.26 | D42: 0.21 | E42: 0.16
B43: Pay Later (%) | C43: 0.7 | D43: 0.75 | E43: 0.79
B44: Fair Financing (%) | C44: 0.04 | D44: 0.04 | E44: 0.05
B46: GMV Per Payment Structure
B47: Pay in Full | C47: =C42*C40 -> 21537.62 | D47: =D42*D40 -> 19417.65 | E47: =E42*E40 -> 16802.4 | R47: =SUM(E47-SUM(O47:Q47)) -> 16802.4
B48: Pay Later | C48: =C43*C40 -> 57985.9 | D48: =D43*D40 -> 69348.75 | E48: =E43*E40 -> 82961.85 | R48: =SUM(E48-SUM(O48:Q48)) -> 82961.85
B49: Fair Financing | C49: =C44*C40 -> 3313.48 | D49: =D44*D40 -> 3698.6 | E49: =E44*E40 -> 5250.75 | R49: =SUM(E49-SUM(O49:Q49)) -> 5250.75 | W49: =SUM(#REF!) -> #REF! | X49: =SUM(#REF!) -> #REF! | Y49: =SUM(#REF!) -> #REF! | Z49: =SUM(#REF!) -> #REF! | AA49: =SUM(O49:O49) -> 0 | AB49: =SUM(O49:P49) -> 0 | AC49: =SUM(O49:Q49) -> 0 | AD49: =SUM(O49:R49) -> 5250.75 | AE49: =SUM(P49:S49) -> 5250.75 | AF49: =SUM(Q49:T49) -> 5250.75 | AG49: =SUM(R49:U49) -> 5250.75 | AI49: =SUM(AG49/AC49)-1 -> #DIV/0!
B50: Total GMW | C50: =SUM(C47:C49) -> 82837 | D50: =SUM(D47:D49) -> 92465 | E50: =SUM(E47:E49) -> 105015 | G50: =SUM(G47:G49) -> 0 | H50: =SUM(H47:H49) -> 0 | I50: =SUM(I47:I49) -> 0 | J50: =SUM(J47:J49) -> 0 | K50: =SUM(K47:K49) -> 0 | L50: =SUM(L47:L49) -> 0 | M50: =SUM(M47:M49) -> 0 | N50: =SUM(N47:N49) -> 0 | ... U50: =SUM(U47:U49) -> 0 | W50: =SUM(W49:W49) -> #REF! | X50: =SUM(X49:X49) -> #REF! | Y50: =SUM(Y49:Y49) -> #REF! | Z50: =SUM(Z49:Z49) -> #REF! | AA50: =SUM(AA49:AA49) -> 0 | AB50: =SUM(AB49:AB49) -> 0 | AC50: =SUM(AC49:AC49) -> 0 | AD50: =SUM(AD49:AD49) -> 5250.75 | ... AG50: =SUM(AG49:AG49) -> 5250.75 | AI50: =SUM(AG50/AC50)-1 -> #DIV/0!
B52: Number of Active Klarna Consumers
...

Sheet Other Segment Analysis
B2: ='Historical Financials'!B2 -> Klarna Group plc (KLAR) | C2: FYE | G2: Quarterly | H2: Quarterly | O2: LTM | S2: LTM | U2: LTM | AA2: Variance
B3: Other Segment Analysis | C3: ='Historical Financials'!C7 -> 2022 | D3: ='Historical Financials'!D7 -> 2023 | E3: ='Historical Financials'!E7 -> 2024 | G3: ='Historical Financials'!O7 -> 1Q24 | H3: ='Historical Financials'!P7 -> 2Q24 | I3: ='Historical Financials'!Q7 -> 3Q24 | J3: ='Historical Financials'!R7 -> 4Q24 | K3: ='Historical Financials'!S7 -> 1Q25 | L3: ='Historical Financials'!T7 -> 2Q25 | M3: ='Historical Financials'!U7 -> 3Q25 | O3: =#REF! -> #REF! | P3: =#REF! -> #REF! | Q3: =#REF! -> #REF! | R3: =#REF! -> #REF! | S3: =G3 -> 1Q24 | T3: =H3 -> 2Q24 | U3: =I3 -> 3Q24 | V3: =J3 -> 4Q24 | W3: =K3 -> 1Q25 | X3: =L3 -> 2Q25 | Y3: =M3 -> 3Q25
B4: $ mm except per share | C4: ='Historical Financials'!C8 -> 44926 | D4: ='Historical Financials'!D8 -> 45291 | E4: ='Historical Financials'!E8 -> 45657 | G4: ='Historical Financials'!O8 -> 45382 | H4: ='Historical Financials'!P8 -> 45473 | I4: ='Historical Financials'!Q8 -> 45565 | J4: ='Historical Financials'!R8 -> 45657 | K4: ='Historical Financials'!S8 -> 45747 | L4: ='Historical Financials'!T8 -> 45838 | M4: ='Historical Financials'!U8 -> 45930 | O4: =#REF! -> #REF! | P4: =#REF! -> #REF! | Q4: =#REF! -> #REF! | R4: =#REF! -> #REF! | S4: =G4 -> 45382 | T4: =H4 -> 45473 | U4: =I4 -> 45565 | V4: =J4 -> 45657 | W4: =K4 -> 45747 | X4: =L4 -> 45838 | Y4: =M4 -> 45930
A6: X | B6: Operating Expenses
B8: Funding Costs
B9: Processing and servicing costs | C9: -520 | D9: -541 | E9: -596 | J9: =SUM(E9-SUM(G9:I9)) -> -596 | O9: =SUM(#REF!) -> #REF! | P9: =SUM(#REF!) -> #REF! | Q9: =SUM(#REF!) -> #REF! | R9: =SUM(#REF!) -> #REF! | S9: =SUM(G9:G9) -> 0 | T9: =SUM(G9:H9) -> 0 | U9: =SUM(G9:I9) -> 0 | V9: =SUM(G9:J9) -> -596 | W9: =SUM(H9:K9) -> -596 | X9: =SUM(I9:L9) -> -596 | Y9: =SUM(J9:M9) -> -596 | AA9: =SUM(Y9/U9)-1 -> #DIV/0!
B10: Consumer credit losses | C10: -550 | D10: -353 | E10: -495
B11: Funding costs | C11: -147 | D11: -297 | E11: -503 | J11: =SUM(E11-SUM(G11:I11)) -> -503 | U11: =SUM(G11:I11) -> 0 | V11: =SUM(G11:J11) -> -503 | W11: =SUM(H11:K11) -> -503 | X11: =SUM(I11:L11) -> -503 | Y11: =SUM(J11:M11) -> -503 | AA11: =SUM(Y11/U11)-1 -> #DIV/0!
B12: Total Funding Costs | C12: =SUM(C9:C11) -> -1217 | D12: =SUM(D9:D11) -> -1191 | E12: =SUM(E9:E11) -> -1594 | G12: =SUM(G9:G11) -> 0 | H12: =SUM(H9:H11) -> 0 | I12: =SUM(I9:I11) -> 0 | J12: =SUM(J9:J11) -> -1099 | K12: =SUM(K9:K11) -> 0 | L12: =SUM(L9:L11) -> 0 | M12: =SUM(M9:M11) -> 0 | O12: =SUM(O9:O11) -> #REF! | P12: =SUM(P9:P11) -> #REF! | Q12: =SUM(Q9:Q11) -> #REF! | R12: =SUM(R9:R11) -> #REF! | S12: =SUM(S9:S11) -> 0 | T12: =SUM(T9:T11) -> 0 | U12: =SUM(U9:U11) -> 0 | V12: =SUM(V9:V11) -> -1099 | ... Y12: =SUM(Y9:Y11) -> -1099 | AA12: =SUM(Y12/U12)-1 -> #DIV/0!
B13: Variance Check | C13: =C12-'Historical Financials'!#REF! -> #REF! | D13: =+D12-'Historical Financials'!D11 -> -3467 | E13: =+E12-'Historical Financials'!E11 -> -4405 | G13: =G12-'Historical Financials'!O11 -> -635.32869 | H13: =H12-'Historical Financials'!P11 -> -675.93368 | I13: =I12-'Historical Financials'!Q11 -> -718.35223 | J13: =J12-'Historical Financials'!R11 -> -1880.3854 | K13: =K12-'Historical Financials'!S11 -> -701.13716 | L13: =L12-'Historical Financials'!T11 -> -823.10162 | M13: =M12-'Historical Financials'!U11 -> -903 | O13: =+O12-'Historical Financials'!AF11 -> #REF! | P13: =+P12-'Historical Financials'!AG11 -> #REF! | Q13: =+Q12-'Historical Financials'!AH11 -> #REF! | R13: =+R12-'Historical Financials'!AI11 -> #REF! | S13: =+S12-'Historical Financials'!AJ11 -> -635.32869 | T13: =+T12-'Historical Financials'!AK11 -> -1311.2624 | U13: =+U12-'Historical Financials'!AL11 -> -2029.6146 | V13: =+V12-'Historical Financials'!AM11 -> -3910 | ... X13: =+X12-'Historical Financials'!AO11 -> -4122.9764 | Y13: =Y12-'Historical Financials'!AP11 -> -4307.6242
B15: Transaction and Service Revenue
B16: Merchant Revenue | C16: =C$9*C23 -> -395.2 | D16: =D$9*D23 -> -411.16 | E16: =E$9*E23 -> -447 | J16: =SUM(E16-SUM(G16:I16)) -> -447 | O16: =SUM(#REF!) -> #REF! | P16: =SUM(#REF!) -> #REF! | Q16: =SUM(#REF!) -> #REF! | R16: =SUM(#REF!) -> #REF! | S16: =SUM(G16:G16) -> 0 | T16: =SUM(G16:H16) -> 0 | U16: =SUM(G16:I16) -> 0 | V16: =SUM(G16:J16) -> -447 | W16: =SUM(H16:K16) -> -447 | X16: =SUM(I16:L16) -> -447 | Y16: =SUM(J16:M16) -> -447 | AA16: =SUM(Y16/U16)-1 -> #DIV/0!
B17: Advertising Revenue | C17: =C$9*C24 -> -57.2 | D17: =D$9*D24 -> -48.69 | E17: =E$9*E24 -> -47.68
B18: Consumer Service Revenue | C18: =C$9*C25 -> -62.4 | D18: =D$9*D25 -> -70.33 | E18: =E$9*E25 -> -95.36 | J18: =SUM(E18-SUM(G18:I18)) -> -95.36 | U18: =SUM(G18:I18) -> 0 | V18: =SUM(G18:J18) -> -95.36 | W18: =SUM(H18:K18) -> -95.36 | X18: =SUM(I18:L18) -> -95.36 | Y18: =SUM(J18:M18) -> -95.36 | AA18: =SUM(Y18/U18)-1 -> #DIV/0!
B19: Intersegment Elimination | C19: =+SUM(C9-SUM(C16:C18)) -> -5.2 | D19: =+SUM(D9-SUM(D16:D18)) -> -10.82 | E19: =+SUM(E9-SUM(E16:E18)) -> -5.96
B20: Total Transaction & Service Revenue | C20: =SUM(C16:C19) -> -520 | D20: =SUM(D16:D19) -> -541 | E20: =SUM(E16:E19) -> -596 | G20: =SUM(G16:G18) -> 0 | H20: =SUM(H16:H18) -> 0 | I20: =SUM(I16:I18) -> 0 | J20: =SUM(J16:J18) -> -542.36 | K20: =SUM(K16:K18) -> 0 | L20: =SUM(L16:L18) -> 0 | M20: =SUM(M16:M18) -> 0 | O20: =SUM(O16:O18) -> #REF! | P20: =SUM(P16:P18) -> #REF! | Q20: =SUM(Q16:Q18) -> #REF! | R20: =SUM(R16:R18) -> #REF! | S20: =SUM(S16:S18) -> 0 | T20: =SUM(T16:T18) -> 0 | U20: =SUM(U16:U18) -> 0 | V20: =SUM(V16:V18) -> -542.36 | ... Y20: =SUM(Y16:Y18) -> -542.36 | AA20: =SUM(Y20/U20)-1 -> #DIV/0!
B21: Variance Check | C21: =+C20-C9 -> 0 | D21: =+D20-D9 -> 0 | E21: =+E20-E9 -> 0 | G21: =G20-'Historical Financials'!#REF! -> #REF! | H21: =H20-'Historical Financials'!#REF! -> #REF! | I21: =I20-'Historical Financials'!#REF! -> #REF! | J21: =J20-'Historical Financials'!#REF! -> #REF! | K21: =K20-'Historical Financials'!#REF! -> #REF! | L21: =L20-'Historical Financials'!#REF! -> #REF! | M21: =M20-'Historical Financials'!#REF! -> #REF! | O21: =+O20-'Historical Financials'!#REF! -> #REF! | P21: =+P20-'Historical Financials'!#REF! -> #REF! | Q21: =+Q20-'Historical Financials'!#REF! -> #REF! | R21: =+R20-'Historical Financials'!#REF! -> #REF! | S21: =+S20-'Historical Financials'!#REF! -> #REF! | T21: =+T20-'Historical Financials'!#REF! -> #REF! | U21: =+U20-'Historical Financials'!#REF! -> #REF! | V21: =+V20-'Historical Financials'!#REF! -> #REF! | ... X21: =+X20-'Historical Financials'!#REF! -> #REF! | Y21: =Y20-'Historical Financials'!#REF! -> #REF!
B23: Merchant Revenue (%) | C23: 0.76 | D23: 0.76 | E23: 0.75
B24: Advertising Revenue (%) | C24: 0.11 | D24: 0.09 | E24: 0.08
B25: Consumer Service Revenue (%) | C25: 0.12 | D25: 0.13 | E25: 0.16
B27: Consumer Service Revenue
B28: Reminder Fees | C28: =C$18*C33 -> -58.656 | D28: =D$18*D33 -> -58.3739 | E28: =E$18*E33 -> -70.5664 | J28: =SUM(E28-SUM(G28:I28)) -> -70.5664 | U28: =SUM(G28:I28) -> 0 | V28: =SUM(G28:J28) -> -70.5664 | W28: =SUM(H28:K28) -> -70.5664 | X28: =SUM(I28:L28) -> -70.5664 | Y28: =SUM(J28:M28) -> -70.5664 | AA28: =SUM(Y28/U28)-1 -> #DIV/0!
B29: Other Revenues | C29: =C$18*C34 -> -3.744 | D29: =D$18*D34 -> -11.9561 | E29: =E$18*E34 -> -24.7936
B30: Total Transaction & Service Revenue | C30: =SUM(C28:C29) -> -62.4 | D30: =SUM(D28:D29) -> -70.33 | E30: =SUM(E28:E29) -> -95.36 | G30: =SUM(G28:G28) -> 0 | H30: =SUM(H28:H28) -> 0 | I30: =SUM(I28:I28) -> 0 | J30: =SUM(J28:J28) -> -70.5664 | K30: =SUM(K28:K28) -> 0 | L30: =SUM(L28:L28) -> 0 | M30: =SUM(M28:M28) -> 0 | O30: =SUM(O28:O28) -> 0 | P30: =SUM(P28:P28) -> 0 | Q30: =SUM(Q28:Q28) -> 0 | R30: =SUM(R28:R28) -> 0 | S30: =SUM(S28:S28) -> 0 | T30: =SUM(T28:T28) -> 0 | U30: =SUM(U28:U28) -> 0 | V30: =SUM(V28:V28) -> -70.5664 | ... Y30: =SUM(Y28:Y28) -> -70.5664 | AA30: =SUM(Y30/U30)-1 -> #DIV/0!
B31: Variance Check | C31: =C30-C18 -> 0 | D31: =D30-D18 -> 0 | E31: =E30-E18 -> 0 | G31: =G30-'Historical Financials'!O31 -> 25.474493 | H31: =H30-'Historical Financials'!P31 -> 2.7472887 | I31: =I30-'Historical Financials'!Q31 -> -14.727673 | J31: =J30-'Historical Financials'!R31 -> -117.44539 | K31: =K30-'Historical Financials'!S31 -> 91.374325 | L31: =L30-'Historical Financials'!T31 -> 45.839025 | M31: =M30-'Historical Financials'!U31 -> 88 | O31: =+O30-'Historical Financials'!AF31 -> #REF! | P31: =+P30-'Historical Financials'!AG31 -> #REF! | Q31: =+Q30-'Historical Financials'!AH31 -> #REF! | R31: =+R30-'Historical Financials'!AI31 -> #REF! | S31: =+S30-'Historical Financials'!AJ31 -> -509.75697 | T31: =+T30-'Historical Financials'!AK31 -> -1044.9638 | U31: =+U30-'Historical Financials'!AL31 -> 13.494109 | V31: =+V30-'Historical Financials'!AM31 -> -103.95128 | ... X31: =+X30-'Historical Financials'!AO31 -> 5.0402839 | Y31: =Y30-'Historical Financials'!AP31 -> 107.76796
B33: Merchant Revenue (%) | C33: 0.94 | D33: 0.83 | E33: 0.74
B34: Consumer Service Revenue (%) | C34: =1-C33 -> 0.06 | D34: =1-D33 -> 0.17 | E34: =1-E33 -> 0.26
A36: X | B36: KPIs
B38: % of Purchases by Vertical (U.S)
B39: Apparel & Accessories | J39: =SUM(E39-SUM(G39:I39)) -> 0
B40: Health & Beauty
B41: Home & Electronics
B42: Food & Beverage
B43: Leisure
B44: Events & Services
B45: Travel
B46: Total U.S Purchases by Vertical | C46: =SUM(C39:C45) -> 0 | D46: =SUM(D39:D45) -> 0 | E46: =SUM(E39:E45) -> 0 | G46: =SUM(G39:G45) -> 0 | H46: =SUM(H39:H45) -> 0 | I46: =SUM(I39:I45) -> 0 | J46: =SUM(J39:J45) -> 0 | K46: =SUM(K39:K45) -> 0 | L46: =SUM(L39:L45) -> 0 | M46: =SUM(M39:M45) -> 0 | O46: =SUM(#REF!) -> #REF! | P46: =SUM(#REF!) -> #REF! | Q46: =SUM(#REF!) -> #REF! | R46: =SUM(#REF!) -> #REF! | S46: =SUM(#REF!) -> #REF! | T46: =SUM(#REF!) -> #REF! | U46: =SUM(#REF!) -> #REF! | V46: =SUM(#REF!) -> #REF! | ... Y46: =SUM(#REF!) -> #REF! | AA46: =SUM(Y46/U46)-1 -> #REF!
B48: =B39&"(%)" -> Apparel & Accessories (%) | E48: 0.69
B49: =B40&"(%)" -> Health & Beauty (%) | E49: 0.03
B50: =B41&"(%)" -> Home & Electronics (%) | E50: 0.04
...

Sheet FCF
B2: ='Historical Financials'!B2 -> Klarna Group plc (KLAR) | C2: FYE | G2: Quarterly | Q2: Quarterly | W2: LTM | AD2: LTM | AE2: LTM | AK2: Variance
B3: FCF Analysis | C3: ='Historical Financials'!C7 -> 2022 | D3: ='Historical Financials'!D7 -> 2023 | E3: ='Historical Financials'!E7 -> 2024 | G3: ='Historical Financials'!G7 -> 1Q22 | H3: ='Historical Financials'!H7 -> 2Q22 | I3: ='Historical Financials'!I7 -> 3Q22 | J3: ='Historical Financials'!J7 -> 4Q22 | K3: ='Historical Financials'!K7 -> 1Q23 | L3: ='Historical Financials'!L7 -> 2Q23 | M3: ='Historical Financials'!M7 -> 3Q23 | N3: ='Historical Financials'!N7 -> 4Q23 | ... U3: ='Historical Financials'!U7 -> 3Q25 | W3: =I3 -> 3Q22 | X3: =J3 -> 4Q22 | Y3: =K3 -> 1Q23 | Z3: =L3 -> 2Q23 | AA3: =M3 -> 3Q23 | AB3: =N3 -> 4Q23 | AC3: =O3 -> 1Q24 | AD3: =P3 -> 2Q24 | ... AI3: =U3 -> 3Q25
B4: $ mm except per share | C4: ='Historical Financials'!C8 -> 44926 | D4: ='Historical Financials'!D8 -> 45291 | E4: ='Historical Financials'!E8 -> 45657 | G4: ='Historical Financials'!G8 -> 44651 | H4: ='Historical Financials'!H8 -> 44742 | I4: ='Historical Financials'!I8 -> 44834 | J4: ='Historical Financials'!J8 -> 44926 | K4: ='Historical Financials'!K8 -> 45016 | L4: ='Historical Financials'!L8 -> 45107 | M4: ='Historical Financials'!M8 -> 45199 | N4: ='Historical Financials'!N8 -> 45291 | ... U4: ='Historical Financials'!U8 -> 45930 | W4: =I4 -> 44834 | X4: =J4 -> 44926 | Y4: =K4 -> 45016 | Z4: =L4 -> 45107 | AA4: =M4 -> 45199 | AB4: =N4 -> 45291 | AC4: =O4 -> 45382 | AD4: =P4 -> 45473 | ... AI4: =U4 -> 45930
B6: ='Revenue Drivers'!B9 -> Transaction and service revenue | C6: ='Revenue Drivers'!C9 -> 1468 | D6: ='Revenue Drivers'!D9 -> 1768 | E6: ='Revenue Drivers'!E9 -> 2136 | G6: ='Revenue Drivers'!G9 -> 344.58814 | H6: ='Revenue Drivers'!H9 -> 369.20095 | I6: ='Revenue Drivers'!I9 -> 331.21869 | J6: ='Revenue Drivers'!J9 -> 422.99222 | K6: ='Revenue Drivers'!K9 -> 368.13111 | L6: ='Revenue Drivers'!L9 -> 417.98173 | M6: ='Revenue Drivers'!M9 -> 440.43433 | N6: ='Revenue Drivers'!N9 -> 541.45284 | ... U6: ='Revenue Drivers'!U9 -> 634 | W6: =SUM(F6:I6) -> 1045.0078 | X6: =SUM(G6:J6) -> 1468 | Y6: =SUM(H6:K6) -> 1491.543 | Z6: =SUM(I6:L6) -> 1540.3237 | AA6: =SUM(J6:M6) -> 1649.5394 | AB6: =SUM(K6:N6) -> 1768 | AC6: =SUM(L6:O6) -> 1878.5933 | AD6: =SUM(M6:P6) -> 1972.7716 | ... AI6: =SUM(R6:U6) -> 2357.8274 | AK6: =SUM(AI6/AE6)-1 -> 0.13526923
B7: ='Revenue Drivers'!B10 -> Interest income | C7: ='Revenue Drivers'!C10 -> 436 | D7: ='Revenue Drivers'!D10 -> 508 | E7: ='Revenue Drivers'!E10 -> 675 | G7: ='Revenue Drivers'!G10 -> 113.29018 | H7: ='Revenue Drivers'!H10 -> 114.24219 | I7: ='Revenue Drivers'!I10 -> 101.88917 | J7: ='Revenue Drivers'!J10 -> 106.57845 | K7: ='Revenue Drivers'!K10 -> 116.02312 | L7: ='Revenue Drivers'!L10 -> 116.09384 | M7: ='Revenue Drivers'!M10 -> 134.34505 | N7: ='Revenue Drivers'!N10 -> 141.53799 | ... U7: ='Revenue Drivers'!U10 -> 269 | AE7: =SUM(N7:Q7) -> 635.71711 | AF7: =SUM(O7:R7) -> 675 | AG7: =SUM(P7:S7) -> 700.21885 | AH7: =SUM(Q7:T7) -> 755.59796 | AI7: =SUM(R7:U7) -> 850.79676 | AK7: =SUM(AI7/AE7)-1 -> 0.33832605
B8: Total Revenue | C8: =SUM(C6:C7) -> 1904 | D8: =SUM(D6:D7) -> 2276 | E8: =SUM(E6:E7) -> 2811 | G8: =SUM(G6:G7) -> 457.87832 | H8: =SUM(H6:H7) -> 483.44314 | I8: =SUM(I6:I7) -> 433.10787 | J8: =SUM(J6:J7) -> 529.57067 | K8: =SUM(K6:K7) -> 484.15423 | L8: =SUM(L6:L7) -> 534.07557 | M8: =SUM(M6:M7) -> 574.77938 | N8: =SUM(N6:N7) -> 682.99082 | ... U8: =SUM(U6:U7) -> 903 | W8: =SUM(W6:W7) -> 1045.0078 | X8: =SUM(X6:X7) -> 1468 | Y8: =SUM(Y6:Y7) -> 1491.543 | Z8: =SUM(Z6:Z7) -> 1540.3237 | AA8: =SUM(AA6:AA7) -> 1649.5394 | AB8: =SUM(AB6:AB7) -> 1768 | AC8: =SUM(AC6:AC7) -> 1878.5933 | AD8: =SUM(AD6:AD7) -> 1972.7716 | ... AI8: =SUM(AI6:AI7) -> 3208.6242 | AK8: =SUM(AI8/AE8)-1 -> 0.18285694
B9: Y/Y Growth (%) | C9: =SUM(C8/#REF!)-1 -> #REF! | D9: =SUM(D8/C8)-1 -> 0.19537815 | E9: =SUM(E8/D8)-1 -> 0.23506151 | K9: =SUM(K8/G8)-1 -> 0.057386227 | L9: =SUM(L8/H8)-1 -> 0.10473296 | M9: =SUM(M8/I8)-1 -> 0.32710445 | N9: =SUM(N8/J8)-1 -> 0.28970666 | O9: =SUM(O8/K8)-1 -> 0.31224443 | P9: =SUM(P8/L8)-1 -> 0.26561431 | Q9: =SUM(Q8/M8)-1 -> 0.24978777 | R9: =SUM(R8/N8)-1 -> 0.14406426 | ... U9: =SUM(U8/Q8)-1 -> 0.25704349 | AA9: =SUM(AA8/W8)-1 -> 0.57849483 | AB9: =SUM(AB8/X8)-1 -> 0.20435967 | AC9: =SUM(AC8/Y8)-1 -> 0.25949661 | AD9: =SUM(AD8/Z8)-1 -> 0.28075128 | AE9: =SUM(AE8/AA8)-1 -> 0.64446236 | AF9: =SUM(AF8/AB8)-1 -> 0.58993213 | AG9: =SUM(AG8/AC8)-1 -> 0.53136309 | AH9: =SUM(AH8/AD8)-1 -> 0.53285681 | AI9: =SUM(AI8/AE8)-1 -> 0.18285694 | AK9: =SUM(AI9-AE9)*10000 -> -4616.0542
B10: Q/Q Growth (%) | C10: N/A | D10: N/A | E10: N/A | H10: =SUM(H8/G8)-1 -> 0.055833218 | I10: =SUM(I8/H8)-1 -> -0.10411829 | J10: =SUM(J8/I8)-1 -> 0.22272236 | K10: =SUM(K8/J8)-1 -> -0.085760867 | L10: =SUM(L8/K8)-1 -> 0.10311041 | M10: =SUM(M8/L8)-1 -> 0.076213565 | N10: =SUM(N8/M8)-1 -> 0.18826606 | O10: =SUM(O8/N8)-1 -> -0.069784437 | ... U10: =SUM(U8/T8)-1 -> 0.09706988 | W10: N/A | X10: N/A | Y10: N/A | Z10: N/A | AA10: N/A | AB10: N/A | AC10: N/A | AD10: N/A | AE10: N/A | AF10: N/A | AG10: N/A | AH10: N/A | AI10: N/A
B12: (-) Processing and servicing costs | C12: ='Historical Financials'!C13 -> -520 | D12: ='Historical Financials'!D13 -> -541 | E12: ='Historical Financials'!E13 -> -596 | G12: ='Historical Financials'!G13 -> -122.86115 | H12: ='Historical Financials'!H13 -> -140.3493 | I12: ='Historical Financials'!I13 -> -119.00793 | J12: ='Historical Financials'!J13 -> -137.78162 | K12: ='Historical Financials'!K13 -> -127.9813 | L12: ='Historical Financials'!L13 -> -131.41075 | M12: ='Historical Financials'!M13 -> -133.22809 | N12: ='Historical Financials'!N13 -> -148.37987 | ... U12: ='Historical Financials'!U13 -> -208 | W12: =SUM(F12:I12) -> -382.21838 | X12: =SUM(G12:J12) -> -520 | Y12: =SUM(H12:K12) -> -525.12015 | Z12: =SUM(I12:L12) -> -516.18159 | AA12: =SUM(J12:M12) -> -530.40175 | AB12: =SUM(K12:N12) -> -541 | AC12: =SUM(L12:O12) -> -548.92035 | AD12: =SUM(M12:P12) -> -565.52257 | ... AI12: =SUM(R12:U12) -> -719.86816 | AK12: =SUM(AI12/AE12)-1 -> 0.23352563
B13: (-) Consumer credit losses | C13: ='Historical Financials'!C14 -> -550 | D13: ='Historical Financials'!D14 -> -353 | E13: ='Historical Financials'!E14 -> -495 | G13: ='Historical Financials'!G14 -> -124.71731 | H13: ='Historical Financials'!H14 -> -166.09766 | I13: ='Historical Financials'!I14 -> -136.43861 | J13: ='Historical Financials'!J14 -> -122.74643 | K13: ='Historical Financials'!K14 -> -72.849766 | L13: ='Historical Financials'!L14 -> -88.327096 | M13: ='Historical Financials'!M14 -> -72.010591 | N13: ='Historical Financials'!N14 -> -119.81255 | ... U13: ='Historical Financials'!U14 -> -235 | W13: =SUM(F13:I13) -> -427.25357 | X13: =SUM(G13:J13) -> -550 | Y13: =SUM(H13:K13) -> -498.13245 | Z13: =SUM(I13:L13) -> -420.36189 | AA13: =SUM(J13:M13) -> -355.93388 | AB13: =SUM(K13:N13) -> -353 | AC13: =SUM(L13:O13) -> -396.81531 | AD13: =SUM(M13:P13) -> -414.79553 | ... AI13: =SUM(R13:U13) -> -701.18584 | AK13: =SUM(AI13/AE13)-1 -> 0.52966092
B14: (-) Funding costs | C14: ='Historical Financials'!C15 -> -147 | D14: ='Historical Financials'!D15 -> -297 | E14: ='Historical Financials'!E15 -> -503 | G14: ='Historical Financials'!G15 -> -30.028678 | H14: ='Historical Financials'!H15 -> -30.251101 | I14: ='Historical Financials'!I15 -> -39.36219 | J14: ='Historical Financials'!J15 -> -47.358031 | K14: ='Historical Financials'!K15 -> -56.835333 | L14: ='Historical Financials'!L15 -> -62.384282 | M14: ='Historical Financials'!M15 -> -77.893781 | N14: ='Historical Financials'!N15 -> -99.886603 | ... U14: ='Historical Financials'!U15 -> -180 | W14: =SUM(F14:I14) -> -99.641969 | X14: =SUM(G14:J14) -> -147 | Y14: =SUM(H14:K14) -> -173.80666 | Z14: =SUM(I14:L14) -> -205.93984 | AA14: =SUM(J14:M14) -> -244.47143 | AB14: =SUM(K14:N14) -> -297 | AC14: =SUM(L14:O14) -> -353.55375 | AD14: =SUM(M14:P14) -> -411.0097 | ... AI14: =SUM(R14:U14) -> -604.59097 | AK14: =SUM(AI14/AE14)-1 -> 0.32608288
B15: Gross Profit | C15: =+C8+SUM(C12:C14) -> 687 | D15: =+D8+SUM(D12:D14) -> 1085 | E15: =+E8+SUM(E12:E14) -> 1217 | G15: =+G8+SUM(G12:G14) -> 180.27119 | H15: =+H8+SUM(H12:H14) -> 146.74508 | I15: =+I8+SUM(I12:I14) -> 138.29914 | J15: =+J8+SUM(J12:J14) -> 221.68459 | K15: =+K8+SUM(K12:K14) -> 226.48784 | L15: =+L8+SUM(L12:L14) -> 251.95345 | M15: =+M8+SUM(M12:M14) -> 291.64691 | N15: =+N8+SUM(N12:N14) -> 314.9118 | ... U15: =+U8+SUM(U12:U14) -> 280 | W15: =+W8+W12 -> 662.7894 | X15: =+X8+X12 -> 948 | Y15: =+Y8+Y12 -> 966.42282 | Z15: =+Z8+Z12 -> 1024.1422 | AA15: =+AA8+AA12 -> 1119.1376 | AB15: =+AB8+AB12 -> 1227 | AC15: =+AC8+AC12 -> 1329.673 | AD15: =+AD8+AD12 -> 1407.249 | AE15: =+AE8+SUM(AE12:AE14) -> 1214.7041 | AF15: =+AF8+SUM(AF12:AF14) -> 1217 | AG15: =+AG8+SUM(AG12:AG14) -> 1218.3868 | AH15: =+AH8+SUM(AH12:AH14) -> 1231.6254 | AI15: =+AI8+SUM(AI12:AI14) -> 1182.9792 | AK15: =SUM(AI15/AE15)-1 -> -0.026117377
B16: Gross Margin (%) | C16: =C15/C8 -> 0.36081933 | D16: =D15/D8 -> 0.47671353 | E16: =E15/E8 -> 0.43294201 | G16: =G15/G8 -> 0.39370981 | H16: =H15/H8 -> 0.30354155 | I16: =I15/I8 -> 0.31931801 | J16: =J15/J8 -> 0.41861191 | K16: =K15/K8 -> 0.46780101 | L16: =L15/L8 -> 0.47175617 | M16: =M15/M8 -> 0.50740671 | N16: =N15/N8 -> 0.46107765 | ... U16: =U15/U8 -> 0.31007752 | W16: =W15/W8 -> 0.63424351 | X16: =X15/X8 -> 0.64577657 | Y16: =Y15/Y8 -> 0.64793495 | Z16: =Z15/Z8 -> 0.6648876 | AA16: =AA15/AA8 -> 0.67845463 | AB16: =AB15/AB8 -> 0.69400452 | AC16: =AC15/AC8 -> 0.70780246 | AD16: =AD15/AD8 -> 0.71333602 | ... AI16: =AI15/AI8 -> 0.36868737 | AK16: =SUM(AI16-AE16)*10000 -> -791.12402
B18: (-) Technology and product development | C18: ='Historical Financials'!C19 -> -355.14437 | D18: ='Historical Financials'!D19 -> -276.4925 | E18: ='Historical Financials'!E19 -> -307.83389 | G18: ='Historical Financials'!G19 -> -96.741726 | H18: ='Historical Financials'!H19 -> -107.08367 | I18: ='Historical Financials'!I19 -> -69.442446 | J18: ='Historical Financials'!J19 -> -81.876523 | K18: ='Historical Financials'!K19 -> -66.668118 | L18: ='Historical Financials'!L19 -> -70.24335 | M18: ='Historical Financials'!M19 -> -64.689124 | N18: ='Historical Financials'!N19 -> -74.89191 | ... U18: ='Historical Financials'!U19 -> -97 | W18: =SUM(F18:I18) -> -273.26784 | X18: =SUM(G18:J18) -> -355.14437 | Y18: =SUM(H18:K18) -> -325.07076 | Z18: =SUM(I18:L18) -> -288.23044 | AA18: =SUM(J18:M18) -> -283.47711 | AB18: =SUM(K18:N18) -> -276.4925 | AC18: =SUM(L18:O18) -> -288.14022 | AD18: =SUM(M18:P18) -> -298.85445 | ... AI18: =SUM(R18:U18) -> -344.11627 | AK18: =SUM(AI18/AE18)-1 -> 0.10342402
