Workbook

Sheet Background
B2: Company Name | C2: Ticker
B3: #VALUE! | C3: HUMA
B5: Pipeline
B6: Target | C6: Drug | D6: Indication | E6: Stage | F6: Data Release
B7: ACELLULAR TISSUE ENGINEERED VESSELS:
B8: TRAUMA | C8: N/A | E8: 3
B9: DIALYSIS (AV ACCESS) | C9: N/A | E9: 3
B10: PERIPHERAL ARTERY DISEASE (PAD) | C10: N/A | E10: 2
B11: CORONARY ARTERY BYPASS GRAFTING (CABG) | C11: N/A | E11: PRECLINICAL
B12: PEDIATRIC HEART DISEASE | C12: N/A | E12: PRECLINICAL
B13: ADVANCED ORGAN SYSTEMS:
B14: BIOVASCULAR PANCREAS™ (TYPE 1 DIABETES) | C14: N/A | E14: PRECLINICAL
B15: LUNG | C15: N/A | E15: PRECLINICAL
B16: ADVANCED TISSUE CONSTRUCTS:
B17: URINARY CONDUIT | C17: N/A | E17: PRECLINICAL
B18: TRACHEAL REPLACEMENT | C18: N/A | E18: PRECLINICAL
B19: ESOPHAGEAL REPLACEMENT | C19: N/A | E19: PRECLINICAL

Sheet Base Financials
B2: Humacyte Inc (NASDAQ: HUMA) | D2: FYE | H2: Quarterly | Q2: Quarterly | W2: LTM | AC2: LTM | AI2: Variance
B3: 3-Statement Model | C3: 2021 | D3: 2022 | E3: 2023 | F3: 2024 | H3: 1Q22 | I3: 2Q22 | J3: 3Q22 | K3: 4Q22 | L3: 1Q23 | M3: 2Q23 | N3: 3Q23 | O3: 4Q23 | P3: 1Q24 | Q3: 2Q24 | R3: 3Q24 | S3: 4Q24 | T3: 1Q25 | U3: 2Q25 | W3: =K3 -> 4Q22 | X3: =L3 -> 1Q23 | Y3: =M3 -> 2Q23 | Z3: =N3 -> 3Q23 | AA3: =O3 -> 4Q23 | AB3: =P3 -> 1Q24 | AC3: =Q3 -> 2Q24 | AD3: =R3 -> 3Q24 | ... AG3: =U3 -> 2Q25
B4: ($ In Thousands) | C4: 44561 | D4: 44926 | E4: 45291 | F4: 45657 | H4: 44651 | I4: 44742 | J4: 44834 | K4: 44926 | L4: 45016 | M4: 45107 | N4: 45199 | O4: 45291 | P4: 45382 | Q4: 45473 | R4: 45565 | S4: 45657 | T4: 45747 | U4: 45838 | W4: =K4 -> 44926 | X4: =L4 -> 45016 | Y4: =M4 -> 45107 | Z4: =N4 -> 45199 | AA4: =O4 -> 45291 | AB4: =P4 -> 45382 | AC4: =Q4 -> 45473 | AD4: =R4 -> 45565 | ... AG4: =U4 -> 45838
A6: X | B6: Income Statement
B8: Product Revenue | C8: 0 | D8: 0 | E8: 0 | F8: 0 | H8: 0 | I8: 0 | J8: 0 | K8: =SUM(D8-SUM(H8:J8)) -> 0 | L8: 0 | M8: 0 | N8: 0 | O8: =SUM(E8-SUM(L8:N8)) -> 0 | P8: 0 | Q8: 0 | R8: 0 | S8: =SUM(F8-SUM(P8:R8)) -> 0 | T8: 147 | U8: 100 | W8: =SUM(H8:K8) -> 0 | X8: =SUM(I8:L8) -> 0 | Y8: =SUM(J8:M8) -> 0 | Z8: =SUM(K8:N8) -> 0 | AA8: =SUM(L8:O8) -> 0 | AB8: =SUM(M8:P8) -> 0 | AC8: =SUM(N8:Q8) -> 0 | AD8: =SUM(O8:R8) -> 0 | ... AG8: =SUM(R8:U8) -> 247 | AI8: =SUM(AG8/AC8)-1 -> #DIV/0!
B9: Contract Revenue | C9: 0 | D9: 0 | E9: 0 | F9: 0 | H9: 0 | I9: 0 | J9: 0 | K9: =SUM(D9-SUM(H9:J9)) -> 0 | L9: 0 | M9: 0 | N9: 0 | O9: =SUM(E9-SUM(L9:N9)) -> 0 | P9: 0 | Q9: 0 | R9: 0 | S9: =SUM(F9-SUM(P9:R9)) -> 0 | T9: 370 | U9: 201 | W9: =SUM(H9:K9) -> 0 | X9: =SUM(I9:L9) -> 0 | Y9: =SUM(J9:M9) -> 0 | Z9: =SUM(K9:N9) -> 0 | AA9: =SUM(L9:O9) -> 0 | AB9: =SUM(M9:P9) -> 0 | AC9: =SUM(N9:Q9) -> 0 | AD9: =SUM(O9:R9) -> 0 | ... AG9: =SUM(R9:U9) -> 571 | AI9: =SUM(AG9/AC9)-1 -> #DIV/0!
B10: Grant Revenue | C10: 1263 | D10: 1565 | E10: 0 | F10: 0 | H10: 233 | I10: 1301 | J10: 31 | K10: =SUM(D10-SUM(H10:J10)) -> 0 | L10: 0 | M10: 0 | N10: 0 | O10: =SUM(E10-SUM(L10:N10)) -> 0 | P10: 0 | Q10: 0 | R10: 0 | S10: =SUM(F10-SUM(P10:R10)) -> 0 | T10: 0 | U10: 0 | W10: =SUM(H10:K10) -> 1565 | X10: =SUM(I10:L10) -> 1332 | Y10: =SUM(J10:M10) -> 31 | Z10: =SUM(K10:N10) -> 0 | AA10: =SUM(L10:O10) -> 0 | AB10: =SUM(M10:P10) -> 0 | AC10: =SUM(N10:Q10) -> 0 | AD10: =SUM(O10:R10) -> 0 | ... AG10: =SUM(R10:U10) -> 0 | AI10: =SUM(AG10/AC10)-1 -> #DIV/0!
B11: Total Revenue | C11: =SUM(C8:C10) -> 1263 | D11: =SUM(D8:D10) -> 1565 | E11: =SUM(E8:E10) -> 0 | F11: =SUM(F8:F10) -> 0 | H11: =SUM(H8:H10) -> 233 | I11: =SUM(I8:I10) -> 1301 | J11: =SUM(J8:J10) -> 31 | K11: =SUM(K8:K10) -> 0 | L11: =SUM(L8:L10) -> 0 | M11: =SUM(M8:M10) -> 0 | N11: =SUM(N8:N10) -> 0 | O11: =SUM(O8:O10) -> 0 | ... U11: =SUM(U8:U10) -> 301 | W11: =SUM(W8:W10) -> 1565 | X11: =SUM(X8:X10) -> 1332 | Y11: =SUM(Y8:Y10) -> 31 | Z11: =SUM(Z8:Z10) -> 0 | AA11: =SUM(AA8:AA10) -> 0 | AB11: =SUM(AB8:AB10) -> 0 | AC11: =SUM(AC8:AC10) -> 0 | AD11: =SUM(AD8:AD10) -> 0 | ... AG11: =SUM(AG8:AG10) -> 818 | AI11: =SUM(AG11/AC11)-1 -> #DIV/0!
B13: Cost of Goods Sold | C13: 0 | D13: 0 | E13: 0 | F13: 0 | H13: 0 | I13: 0 | J13: 0 | K13: =SUM(D13-SUM(H13:J13)) -> 0 | L13: 0 | M13: 0 | N13: 0 | O13: =SUM(E13-SUM(L13:N13)) -> 0 | P13: 0 | Q13: 0 | R13: 0 | S13: =SUM(F13-SUM(P13:R13)) -> 0 | T13: -147 | U13: -213 | W13: =SUM(H13:K13) -> 0 | X13: =SUM(I13:L13) -> 0 | Y13: =SUM(J13:M13) -> 0 | Z13: =SUM(K13:N13) -> 0 | AA13: =SUM(L13:O13) -> 0 | AB13: =SUM(M13:P13) -> 0 | AC13: =SUM(N13:Q13) -> 0 | AD13: =SUM(O13:R13) -> 0 | ... AG13: =SUM(R13:U13) -> -360 | AI13: =SUM(AG13/AC13)-1 -> #DIV/0!
B14: Gross Profit (Loss) | C14: =+SUM(C11+C13) -> 1263 | D14: =+SUM(D11+D13) -> 1565 | E14: =+SUM(E11+E13) -> 0 | F14: =+SUM(F11+F13) -> 0 | H14: =+SUM(H11+H13) -> 233 | I14: =+SUM(I11+I13) -> 1301 | J14: =+SUM(J11+J13) -> 31 | K14: =+SUM(K11+K13) -> 0 | L14: =+SUM(L11+L13) -> 0 | M14: =+SUM(M11+M13) -> 0 | N14: =+SUM(N11+N13) -> 0 | O14: =+SUM(O11+O13) -> 0 | ... U14: =+SUM(U11+U13) -> 88 | W14: =+SUM(W11+W13) -> 1565 | X14: =+SUM(X11+X13) -> 1332 | Y14: =+SUM(Y11+Y13) -> 31 | Z14: =+SUM(Z11+Z13) -> 0 | AA14: =+SUM(AA11+AA13) -> 0 | AB14: =+SUM(AB11+AB13) -> 0 | AC14: =+SUM(AC11+AC13) -> 0 | AD14: =+SUM(AD11+AD13) -> 0 | ... AG14: =+SUM(AG11+AG13) -> 458 | AI14: =SUM(AG14/AC14)-1 -> #DIV/0!
B16: Research and Development (R&D) | C16: -61341 | D16: -63260 | E16: -76550 | F16: -88599 | H16: -16314 | I16: -14652 | J16: -17337 | K16: =SUM(D16-SUM(H16:J16)) -> -14957 | L16: -17278 | M16: -20540 | N16: -18552 | O16: =SUM(E16-SUM(L16:N16)) -> -20180 | P16: -21264 | Q16: -23753 | R16: -22926 | S16: =SUM(F16-SUM(P16:R16)) -> -20656 | T16: -15418 | U16: -22006 | W16: =SUM(H16:K16) -> -63260 | X16: =SUM(I16:L16) -> -64224 | Y16: =SUM(J16:M16) -> -70112 | Z16: =SUM(K16:N16) -> -71327 | AA16: =SUM(L16:O16) -> -76550 | AB16: =SUM(M16:P16) -> -80536 | AC16: =SUM(N16:Q16) -> -83749 | AD16: =SUM(O16:R16) -> -88123 | ... AG16: =SUM(R16:U16) -> -81006 | AI16: =SUM(AG16/AC16)-1 -> -0.03275263
B17: General and Administrative (G&A) | C17: -21130 | D17: -22883 | E17: -23497 | F17: -25799 | H17: -5682 | I17: -5180 | J17: -6188 | K17: =SUM(D17-SUM(H17:J17)) -> -5833 | L17: -5234 | M17: -6191 | N17: -6070 | O17: =SUM(E17-SUM(L17:N17)) -> -6002 | P17: -5314 | Q17: -5746 | R17: -7307 | S17: =SUM(F17-SUM(P17:R17)) -> -7432 | T17: -8136 | U17: -7809 | W17: =SUM(H17:K17) -> -22883 | X17: =SUM(I17:L17) -> -22435 | Y17: =SUM(J17:M17) -> -23446 | Z17: =SUM(K17:N17) -> -23328 | AA17: =SUM(L17:O17) -> -23497 | AB17: =SUM(M17:P17) -> -23577 | AC17: =SUM(N17:Q17) -> -23132 | AD17: =SUM(O17:R17) -> -24369 | ... AG17: =SUM(R17:U17) -> -30684 | AI17: =SUM(AG17/AC17)-1 -> 0.32647415
B18: Total Operating Profit (Loss) | C18: =+SUM(C14+SUM(C16:C17)) -> -81208 | D18: =+SUM(D14+SUM(D16:D17)) -> -84578 | E18: =+SUM(E14+SUM(E16:E17)) -> -100047 | F18: =+SUM(F14+SUM(F16:F17)) -> -114398 | H18: =+SUM(H14+SUM(H16:H17)) -> -21763 | I18: =+SUM(I14+SUM(I16:I17)) -> -18531 | J18: =+SUM(J14+SUM(J16:J17)) -> -23494 | K18: =+SUM(K14+SUM(K16:K17)) -> -20790 | L18: =+SUM(L14+SUM(L16:L17)) -> -22512 | M18: =+SUM(M14+SUM(M16:M17)) -> -26731 | N18: =+SUM(N14+SUM(N16:N17)) -> -24622 | O18: =+SUM(O14+SUM(O16:O17)) -> -26182 | ... U18: =+SUM(U14+SUM(U16:U17)) -> -29727 | W18: =+SUM(W14+SUM(W16:W17)) -> -84578 | X18: =+SUM(X14+SUM(X16:X17)) -> -85327 | Y18: =+SUM(Y14+SUM(Y16:Y17)) -> -93527 | Z18: =+SUM(Z14+SUM(Z16:Z17)) -> -94655 | AA18: =+SUM(AA14+SUM(AA16:AA17)) -> -100047 | AB18: =+SUM(AB14+SUM(AB16:AB17)) -> -104113 | AC18: =+SUM(AC14+SUM(AC16:AC17)) -> -106881 | AD18: =+SUM(AD14+SUM(AD16:AD17)) -> -112492 | ... AG18: =+SUM(AG14+SUM(AG16:AG17)) -> -111232 | AI18: =SUM(AG18/AC18)-1 -> 0.040708826
B20: Interest income | C20: 16 | D20: 2629 | E20: 5467 | F20: 4104 | H20: 31 | I20: 301 | J20: 883 | K20: =SUM(D20-SUM(H20:J20)) -> 1414 | L20: 1475 | M20: 1479 | N20: 1369 | O20: =SUM(E20-SUM(L20:N20)) -> 1144 | P20: 1031 | Q20: 1310 | R20: 911 | S20: =SUM(F20-SUM(P20:R20)) -> 852 | T20: 662 | U20: 832 | W20: =SUM(H20:K20) -> 2629 | X20: =SUM(I20:L20) -> 4073 | Y20: =SUM(J20:M20) -> 5251 | Z20: =SUM(K20:N20) -> 5737 | AA20: =SUM(L20:O20) -> 5467 | AB20: =SUM(M20:P20) -> 5023 | AC20: =SUM(N20:Q20) -> 4854 | AD20: =SUM(O20:R20) -> 4396 | ... AG20: =SUM(R20:U20) -> 3257 | AI20: =SUM(AG20/AC20)-1 -> -0.329007
B21: Interest expense | C21: -4348 | D21: -6200 | E21: -6599 | F21: -9277 | H21: -1432 | I21: -1488 | J21: -1641 | K21: =SUM(D21-SUM(H21:J21)) -> -1639 | L21: -1699 | M21: -1710 | N21: -1463 | O21: =SUM(E21-SUM(L21:N21)) -> -1727 | P21: -1816 | Q21: -2515 | R21: -2438 | S21: =SUM(F21-SUM(P21:R21)) -> -2508 | T21: -3000 | U21: -2545 | W21: =SUM(H21:K21) -> -6200 | X21: =SUM(I21:L21) -> -6467 | Y21: =SUM(J21:M21) -> -6689 | Z21: =SUM(K21:N21) -> -6511 | AA21: =SUM(L21:O21) -> -6599 | AB21: =SUM(M21:P21) -> -6716 | AC21: =SUM(N21:Q21) -> -7521 | AD21: =SUM(O21:R21) -> -8496 | ... AG21: =SUM(R21:U21) -> -10491 | AI21: =SUM(AG21/AC21)-1 -> 0.3948943
B22: Change in fair value of Contingent Earnout Liability | C22: 55772 | D22: 75767 | E22: -10023 | F22: -33045 | H22: 3258 | I22: 56353 | J22: -962 | K22: =SUM(D22-SUM(H22:J22)) -> 17118 | L22: -14191 | M22: 3627 | N22: -1144 | O22: =SUM(E22-SUM(L22:N22)) -> 1685 | P22: -4593 | Q22: -25571 | R22: -8489 | S22: =SUM(F22-SUM(P22:R22)) -> 5608 | T22: 49731 | U22: -5470 | W22: =SUM(H22:K22) -> 75767 | X22: =SUM(I22:L22) -> 58318 | Y22: =SUM(J22:M22) -> 5592 | Z22: =SUM(K22:N22) -> 5410 | AA22: =SUM(L22:O22) -> -10023 | AB22: =SUM(M22:P22) -> -425 | AC22: =SUM(N22:Q22) -> -29623 | AD22: =SUM(O22:R22) -> -36968 | ... AG22: =SUM(R22:U22) -> 41380 | AI22: =SUM(AG22/AC22)-1 -> -2.3968876
B23: Change in fair value of derivative liabilities | C23: 0 | D23: 417 | E23: -260 | F23: 3915 | H23: 0 | I23: 0 | J23: 0 | K23: =SUM(D23-SUM(H23:J23)) -> 417 | L23: 0 | M23: -57 | N23: -135 | O23: =SUM(E23-SUM(L23:N23)) -> -68 | P23: 60 | Q23: -388 | R23: 1047 | S23: =SUM(F23-SUM(P23:R23)) -> 3196 | T23: 14930 | U23: -748 | W23: =SUM(H23:K23) -> 417 | X23: =SUM(I23:L23) -> 417 | Y23: =SUM(J23:M23) -> 360 | Z23: =SUM(K23:N23) -> 225 | AA23: =SUM(L23:O23) -> -260 | AB23: =SUM(M23:P23) -> -200 | AC23: =SUM(N23:Q23) -> -531 | AD23: =SUM(O23:R23) -> 651 | ... AG23: =SUM(R23:U23) -> 18425 | AI23: =SUM(AG23/AC23)-1 -> -35.698682
B24: Other Gains, Losses, and Adjustments (1) | C24: =56+3284-49 -> 3291 | D24: 0 | E24: =3107-2421 -> 686 | F24: 0 | H24: 74 | I24: 233 | J24: -67 | K24: =SUM(D24-SUM(H24:J24)) -> -240 | L24: -42 | M24: =3107-2421 -> 686 | N24: 0 | O24: =SUM(E24-SUM(L24:N24)) -> 42 | P24: 0 | Q24: 0 | R24: 0 | S24: =SUM(F24-SUM(P24:R24)) -> 0 | T24: 0 | U24: 0 | AC24: =SUM(N24:Q24) -> 42 | AD24: =SUM(O24:R24) -> 42 | AE24: =SUM(P24:S24) -> 0 | AF24: =SUM(Q24:T24) -> 0 | AG24: =SUM(R24:U24) -> 0 | AI24: =SUM(AG24/AC24)-1 -> -1
B25: Net loss | C25: =SUM(C18+SUM(C20:C24)) -> -26477 | D25: =SUM(D18+SUM(D20:D24)) -> -11965 | E25: =SUM(E18+SUM(E20:E24)) -> -110776 | F25: =SUM(F18+SUM(F20:F24)) -> -148701 | H25: =SUM(H18+SUM(H20:H24)) -> -19832 | I25: =SUM(I18+SUM(I20:I24)) -> 36868 | J25: =SUM(J18+SUM(J20:J24)) -> -25281 | K25: =SUM(K18+SUM(K20:K24)) -> -3720 | L25: =SUM(L18+SUM(L20:L24)) -> -36969 | M25: =SUM(M18+SUM(M20:M24)) -> -22706 | N25: =SUM(N18+SUM(N20:N24)) -> -25995 | O25: =SUM(O18+SUM(O20:O24)) -> -25106 | ... U25: =SUM(U18+SUM(U20:U24)) -> -37658 | W25: =SUM(W20:W24)-W18 -> 157191 | X25: =SUM(X20:X24)-X18 -> 141668 | Y25: =SUM(Y20:Y24)-Y18 -> 98041 | Z25: =SUM(Z20:Z24)-Z18 -> 99516 | AA25: =SUM(AA20:AA24)-AA18 -> 88632 | AB25: =SUM(AB20:AB24)-AB18 -> 101795 | AC25: =SUM(AC20:AC24)-AC18 -> 74102 | AD25: =SUM(AD20:AD24)-AD18 -> 72117 | ... AG25: =SUM(AG20:AG24)-AG18 -> 163803 | AI25: =SUM(AG25/AC25)-1 -> 1.2105071
B27: Weighted-average shares outstanding, diluted | C27: 39970.398 | D27: 103051.37 | E27: 103420.24 | F27: 118479.1 | H27: 103004.09 | I27: 103908.44 | J27: 103031.98 | K27: =D27 -> 103051.37 | L27: 103263.53 | M27: 103361.5 | N27: 103444.25 | O27: =E27 -> 103420.24 | P27: 108246.01 | Q27: 119174.68 | R27: 119408.57 | S27: =F27 -> 118479.1 | T27: 131759.3 | U27: 155437.28 | W27: =K27 -> 103051.37 | X27: =L27 -> 103263.53 | Y27: =M27 -> 103361.5 | Z27: =N27 -> 103444.25 | AA27: =O27 -> 103420.24 | AB27: =P27 -> 108246.01 | AC27: =Q27 -> 119174.68 | AD27: =R27 -> 119408.57 | ... AG27: =U27 -> 155437.28
B28: Earnings (Net Loss) Per Share | C28: =C25/C27 -> -0.66241522 | D28: =D25/D27 -> -0.11610715 | E28: =E25/E27 -> -1.071125 | F28: =F25/F27 -> -1.2550822 | H28: =H25/H27 -> -0.19253605 | I28: =I25/I27 -> 0.35481237 | J28: =J25/J27 -> -0.24537042 | K28: =K25/K27 -> -0.036098503 | L28: =L25/L27 -> -0.35800636 | M28: =M25/M27 -> -0.2196756 | N28: =N25/N27 -> -0.25129479 | O28: =O25/O27 -> -0.24275713 | ... U28: =U25/U27 -> -0.24227135 | W28: =W25/W27 -> 1.5253655 | X28: =X25/X27 -> 1.3719074 | Y28: =Y25/Y27 -> 0.94852531 | Z28: =Z25/Z27 -> 0.96202548 | AA28: =AA25/AA27 -> 0.85700828 | AB28: =AB25/AB27 -> 0.94040419 | AC28: =AC25/AC27 -> 0.62179315 | AD28: =AD25/AD27 -> 0.60395165 | ... AG28: =AG25/AG27 -> 1.0538205 | AI28: =SUM(AG28/AC28)-1 -> 0.69480887
B30: 1) "Other Gains, Losses, and Adjustments Consist of: Change in fair value of common stock warrant liabilities, Gain on PPP loan forgiveness, Employee retention credit, Loss on extinguishment of debt, and Transaction costs expensed.
A32: X | B32: Balance Sheet
B34: Current Assets
B35: Cash and cash equivalents | C35: 217502 | D35: 149772 | E35: 80448 | F35: 44937 | H35: 198222 | I35: 181035 | J35: 163731 | K35: =D35 -> 149772 | L35: 129570 | M35: 114604 | N35: 99986 | O35: =E35 -> 80448 | P35: 115505 | Q35: 93563 | R35: 20571 | S35: =F35 -> 44937 | T35: 62847 | U35: 38032 | W35: =K35 -> 149772 | X35: =L35 -> 129570 | Y35: =M35 -> 114604 | Z35: =N35 -> 99986 | AA35: =O35 -> 80448 | AB35: =P35 -> 115505 | AC35: =Q35 -> 93563 | AD35: =R35 -> 20571 | ... AG35: =U35 -> 38032 | AI35: =SUM(AG35/AC35)-1 -> -0.59351453
B36: Accounts receivable | C36: 176 | D36: 31 | E36: 0 | F36: 0 | H36: 233 | I36: 1301 | J36: 31 | K36: =D36 -> 31 | L36: 0 | M36: 0 | N36: 0 | O36: =E36 -> 0 | P36: 0 | Q36: 0 | R36: 0 | S36: =F36 -> 0 | T36: 488 | U36: 394 | W36: =K36 -> 31 | X36: =L36 -> 0 | Y36: =M36 -> 0 | Z36: =N36 -> 0 | AA36: =O36 -> 0 | AB36: =P36 -> 0 | AC36: =Q36 -> 0 | AD36: =R36 -> 0 | ... AG36: =U36 -> 394 | AI36: =SUM(AG36/AC36)-1 -> #DIV/0!
B37: Short-term investments | C37: 8000 | D37: 2107 | E37: 0 | F37: 0 | H37: 8000 | I37: 8000 | J37: 8000 | K37: =D37 -> 2107 | L37: 2107 | M37: 0 | N37: 0 | O37: =E37 -> 0 | P37: 0 | Q37: 0 | R37: 0 | S37: =F37 -> 0 | T37: 0 | U37: 0 | W37: =K37 -> 2107 | X37: =L37 -> 2107 | Y37: =M37 -> 0 | Z37: =N37 -> 0 | AA37: =O37 -> 0 | AB37: =P37 -> 0 | AC37: =Q37 -> 0 | AD37: =R37 -> 0 | ... AG37: =U37 -> 0 | AI37: =SUM(AG37/AC37)-1 -> #DIV/0!
B38: Inventory | C38: 0 | D38: 0 | E38: 0 | F38: 0 | H38: 0 | I38: 0 | J38: 0 | K38: =D38 -> 0 | L38: 0 | M38: 0 | N38: 0 | O38: =E38 -> 0 | P38: 0 | Q38: 0 | R38: 0 | S38: =F38 -> 0 | T38: 8020 | U38: 11067 | W38: =K38 -> 0 | X38: =L38 -> 0 | Y38: =M38 -> 0 | Z38: =N38 -> 0 | AA38: =O38 -> 0 | AB38: =P38 -> 0 | AC38: =Q38 -> 0 | AD38: =R38 -> 0 | ... AG38: =U38 -> 11067 | AI38: =SUM(AG38/AC38)-1 -> #DIV/0!
B39: Prepaid expenses and other current assets | C39: 3662 | D39: 2298 | E39: 2830 | F39: 2922 | H39: 2840 | I39: 2694 | J39: 2850 | K39: =D39 -> 2298 | L39: 2178 | M39: 5958 | N39: 2865 | O39: =E39 -> 2830 | P39: 2421 | Q39: 2547 | R39: 2434 | S39: =F39 -> 2922 | T39: 2350 | U39: 2237 | W39: =K39 -> 2298 | X39: =L39 -> 2178 | Y39: =M39 -> 5958 | Z39: =N39 -> 2865 | AA39: =O39 -> 2830 | AB39: =P39 -> 2421 | AC39: =Q39 -> 2547 | AD39: =R39 -> 2434 | ... AG39: =U39 -> 2237 | AI39: =SUM(AG39/AC39)-1 -> -0.12171182
B40: Total Current Assets | C40: =SUM(C35:C39) -> 229340 | D40: =SUM(D35:D39) -> 154208 | E40: =SUM(E35:E39) -> 83278 | F40: =SUM(F35:F39) -> 47859 | H40: =SUM(H35:H39) -> 209295 | I40: =SUM(I35:I39) -> 193030 | J40: =SUM(J35:J39) -> 174612 | K40: =SUM(K35:K39) -> 154208 | L40: =SUM(L35:L39) -> 133855 | M40: =SUM(M35:M39) -> 120562 | N40: =SUM(N35:N39) -> 102851 | O40: =SUM(O35:O39) -> 83278 | ... U40: =SUM(U35:U39) -> 51730 | W40: =SUM(W35:W39) -> 154208 | X40: =SUM(X35:X39) -> 133855 | Y40: =SUM(Y35:Y39) -> 120562 | Z40: =SUM(Z35:Z39) -> 102851 | AA40: =SUM(AA35:AA39) -> 83278 | AB40: =SUM(AB35:AB39) -> 117926 | AC40: =SUM(AC35:AC39) -> 96110 | AD40: =SUM(AD35:AD39) -> 23005 | ... AG40: =SUM(AG35:AG39) -> 51730 | AI40: =SUM(AG40/AC40)-1 -> -0.46176256
B42: Long-Term Assets
B43: Restricted cash | C43: 0 | D43: 0 | E43: 0 | F43: 50209 | H43: 0 | I43: 0 | J43: 0 | K43: =D43 -> 0 | L43: 0 | M43: 0 | N43: 0 | O43: =E43 -> 0 | P43: 0 | Q43: 0 | R43: 50209 | S43: =F43 -> 50209 | T43: 50209 | U43: 50209 | W43: =K43 -> 0 | X43: =L43 -> 0 | Y43: =M43 -> 0 | Z43: =N43 -> 0 | AA43: =O43 -> 0 | AB43: =P43 -> 0 | AC43: =Q43 -> 0 | AD43: =R43 -> 50209 | ... AG43: =U43 -> 50209 | AI43: =SUM(AG43/AC43)-1 -> #DIV/0!
B44: Property and equipment, net | C44: 35034 | D44: 30039 | E44: 26791 | F44: 23063 | H44: 33540 | I44: 32227 | J44: 31026 | K44: =D44 -> 30039 | L44: 29593 | M44: 28543 | N44: 27851 | O44: =E44 -> 26791 | P44: 25653 | Q44: 24820 | R44: 24250 | S44: =F44 -> 23063 | T44: 22436 | U44: 21191 | W44: =K44 -> 30039 | X44: =L44 -> 29593 | Y44: =M44 -> 28543 | Z44: =N44 -> 27851 | AA44: =O44 -> 26791 | AB44: =P44 -> 25653 | AC44: =Q44 -> 24820 | AD44: =R44 -> 24250 | ... AG44: =U44 -> 21191 | AI44: =SUM(AG44/AC44)-1 -> -0.14621273
B45: Finance lease right-of-use assets, net | C45: 21432 | D45: 19373 | E45: 17313 | F45: 15490 | H45: 20917 | I45: 20403 | J45: 19888 | K45: =D45 -> 19373 | L45: 18858 | M45: 18343 | N45: 17828 | O45: =E45 -> 17313 | P45: 17059 | Q45: 16536 | R45: 16013 | S45: =F45 -> 15490 | T45: 14966 | U45: 14443 | W45: =K45 -> 19373 | X45: =L45 -> 18858 | Y45: =M45 -> 18343 | Z45: =N45 -> 17828 | AA45: =O45 -> 17313 | AB45: =P45 -> 17059 | AC45: =Q45 -> 16536 | AD45: =R45 -> 16013 | ... AG45: =U45 -> 14443 | AI45: =SUM(AG45/AC45)-1 -> -0.12657233
B46: Other long-term assets | C46: 727 | D46: 682 | E46: 841 | F46: 1251 | H46: 716 | I46: 705 | J46: 693 | K46: =D46 -> 682 | L46: 670 | M46: 658 | N46: 855 | O46: =E46 -> 841 | P46: 828 | Q46: 815 | R46: 1287 | S46: =F46 -> 1251 | T46: 1237 | U46: 1222 | W46: =K46 -> 682 | X46: =L46 -> 670 | Y46: =M46 -> 658 | Z46: =N46 -> 855 | AA46: =O46 -> 841 | AB46: =P46 -> 828 | AC46: =Q46 -> 815 | AD46: =R46 -> 1287 | ... AG46: =U46 -> 1222 | AI46: =SUM(AG46/AC46)-1 -> 0.4993865
B47: Total Assets | C47: =SUM(C43:C46)+C40 -> 286533 | D47: =SUM(D43:D46)+D40 -> 204302 | E47: =SUM(E43:E46)+E40 -> 128223 | F47: =SUM(F43:F46)+F40 -> 137872 | H47: =SUM(H43:H46)+H40 -> 264468 | I47: =SUM(I43:I46)+I40 -> 246365 | J47: =SUM(J43:J46)+J40 -> 226219 | K47: =SUM(K43:K46)+K40 -> 204302 | L47: =SUM(L43:L46)+L40 -> 182976 | M47: =SUM(M43:M46)+M40 -> 168106 | N47: =SUM(N43:N46)+N40 -> 149385 | O47: =SUM(O43:O46)+O40 -> 128223 | ... U47: =SUM(U43:U46)+U40 -> 138795 | W47: =SUM(W43:W46)+W40 -> 204302 | X47: =SUM(X43:X46)+X40 -> 182976 | Y47: =SUM(Y43:Y46)+Y40 -> 168106 | Z47: =SUM(Z43:Z46)+Z40 -> 149385 | AA47: =SUM(AA43:AA46)+AA40 -> 128223 | AB47: =SUM(AB43:AB46)+AB40 -> 161466 | AC47: =SUM(AC43:AC46)+AC40 -> 138281 | AD47: =SUM(AD43:AD46)+AD40 -> 114764 | ... AG47: =SUM(AG43:AG46)+AG40 -> 138795 | AI47: =SUM(AG47/AC47)-1 -> 0.0037170689
B49: Current Liabilities
B50: Accounts payable | C50: 2094 | D50: 1595 | E50: 6490 | F50: 4490 | H50: 3037 | I50: 2537 | J50: 3255 | K50: =D50 -> 1595 | L50: 1954 | M50: 2362 | N50: 3018 | O50: =E50 -> 6490 | P50: 3452 | Q50: 6005 | R50: 6903 | S50: =F50 -> 4490 | T50: 5572 | U50: 6629 | W50: =K50 -> 1595 | X50: =L50 -> 1954 | Y50: =M50 -> 2362 | Z50: =N50 -> 3018 | AA50: =O50 -> 6490 | AB50: =P50 -> 3452 | AC50: =Q50 -> 6005 | AD50: =R50 -> 6903 | ... AG50: =U50 -> 6629 | AI50: =SUM(AG50/AC50)-1 -> 0.10391341
B51: Accrued expenses | C51: 6757 | D51: 7108 | E51: 9340 | F51: 11424 | H51: 5460 | I51: 6186 | J51: 7959 | K51: =D51 -> 7108 | L51: 6411 | M51: 6571 | N51: 9586 | O51: =E51 -> 9340 | P51: 7917 | Q51: 8950 | R51: 11151 | S51: =F51 -> 11424 | T51: 9701 | U51: 9186 | W51: =K51 -> 7108 | X51: =L51 -> 6411 | Y51: =M51 -> 6571 | Z51: =N51 -> 9586 | AA51: =O51 -> 9340 | AB51: =P51 -> 7917 | AC51: =Q51 -> 8950 | AD51: =R51 -> 11151 | ... AG51: =U51 -> 9186 | AI51: =SUM(AG51/AC51)-1 -> 0.026368715
B52: Finance lease obligation, current portion | C52: 1981 | D52: 2256 | E52: 2560 | F52: 2917 | H52: 2047 | I52: 2115 | J52: 2185 | K52: =D52 -> 2256 | L52: 2329 | M52: 2404 | N52: 2481 | O52: =E52 -> 2560 | P52: 2663 | Q52: 2746 | R52: 2831 | S52: =F52 -> 2917 | T52: 3006 | U52: 3093 | W52: =K52 -> 2256 | X52: =L52 -> 2329 | Y52: =M52 -> 2404 | Z52: =N52 -> 2481 | AA52: =O52 -> 2560 | AB52: =P52 -> 2663 | AC52: =Q52 -> 2746 | AD52: =R52 -> 2831 | ... AG52: =U52 -> 3093 | AI52: =SUM(AG52/AC52)-1 -> 0.12636562
...

Sheet FCF Analysis
B2: Humacyte Inc (NASDAQ: HUMA) | C2: FYE | D2: FYE | H2: Quarterly | P2: Quarterly | Q2: Quarterly | W2: LTM | AA2: LTM | AC2: LTM | AI2: Variance
B3: FCF Analysis | C3: 2021 | D3: 2022 | E3: 2023 | F3: 2024 | H3: 1Q22 | I3: 2Q22 | J3: 3Q22 | K3: 4Q22 | L3: 1Q23 | M3: 2Q23 | N3: 3Q23 | O3: 4Q23 | P3: 1Q24 | Q3: 2Q24 | R3: 3Q24 | S3: 4Q24 | T3: 1Q25 | U3: 2Q25 | W3: =K3 -> 4Q22 | X3: =L3 -> 1Q23 | Y3: =M3 -> 2Q23 | Z3: =N3 -> 3Q23 | AA3: =O3 -> 4Q23 | AB3: =P3 -> 1Q24 | AC3: =Q3 -> 2Q24 | AD3: =R3 -> 3Q24 | ... AG3: =U3 -> 2Q25
B4: ($ In Thousands) | C4: 44561 | D4: 44926 | E4: 45291 | F4: 45657 | H4: 44651 | I4: 44742 | J4: 44834 | K4: 44926 | L4: 45016 | M4: 45107 | N4: 45199 | O4: 45291 | P4: 45382 | Q4: 45473 | R4: 45565 | S4: 45657 | T4: 45747 | U4: 45838 | W4: =K4 -> 44926 | X4: =L4 -> 45016 | Y4: =M4 -> 45107 | Z4: =N4 -> 45199 | AA4: =O4 -> 45291 | AB4: =P4 -> 45382 | AC4: =Q4 -> 45473 | AD4: =R4 -> 45565 | ... AG4: =U4 -> 45838
B6: Product Revenue | C6: ='Base Financials'!C8 -> 0 | D6: ='Base Financials'!D8 -> 0 | E6: ='Base Financials'!E8 -> 0 | F6: ='Base Financials'!F8 -> 0 | H6: ='Base Financials'!H8 -> 0 | I6: ='Base Financials'!I8 -> 0 | J6: ='Base Financials'!J8 -> 0 | K6: ='Base Financials'!K8 -> 0 | L6: ='Base Financials'!L8 -> 0 | M6: ='Base Financials'!M8 -> 0 | N6: ='Base Financials'!N8 -> 0 | O6: ='Base Financials'!O8 -> 0 | ... U6: ='Base Financials'!U8 -> 100 | W6: =SUM(H6:K6) -> 0 | X6: =SUM(I6:L6) -> 0 | Y6: =SUM(J6:M6) -> 0 | Z6: =SUM(K6:N6) -> 0 | AA6: =SUM(L6:O6) -> 0 | AB6: =SUM(M6:P6) -> 0 | AC6: =SUM(N6:Q6) -> 0 | AD6: =SUM(O6:R6) -> 0 | ... AG6: =SUM(R6:U6) -> 247 | AI6: =SUM(AG6/AC6)-1 -> #DIV/0!
B7: Contract Revenue | C7: ='Base Financials'!C9 -> 0 | D7: ='Base Financials'!D9 -> 0 | E7: ='Base Financials'!E9 -> 0 | F7: ='Base Financials'!F9 -> 0 | H7: ='Base Financials'!H9 -> 0 | I7: ='Base Financials'!I9 -> 0 | J7: ='Base Financials'!J9 -> 0 | K7: ='Base Financials'!K9 -> 0 | L7: ='Base Financials'!L9 -> 0 | M7: ='Base Financials'!M9 -> 0 | N7: ='Base Financials'!N9 -> 0 | O7: ='Base Financials'!O9 -> 0 | ... U7: ='Base Financials'!U9 -> 201 | W7: =SUM(H7:K7) -> 0 | X7: =SUM(I7:L7) -> 0 | Y7: =SUM(J7:M7) -> 0 | Z7: =SUM(K7:N7) -> 0 | AA7: =SUM(L7:O7) -> 0 | AB7: =SUM(M7:P7) -> 0 | AC7: =SUM(N7:Q7) -> 0 | AD7: =SUM(O7:R7) -> 0 | ... AG7: =SUM(R7:U7) -> 571 | AI7: =SUM(AG7/AC7)-1 -> #DIV/0!
B8: Grant Revenue | C8: ='Base Financials'!C10 -> 1263 | D8: ='Base Financials'!D10 -> 1565 | E8: ='Base Financials'!E10 -> 0 | F8: ='Base Financials'!F10 -> 0 | H8: ='Base Financials'!H10 -> 233 | I8: ='Base Financials'!I10 -> 1301 | J8: ='Base Financials'!J10 -> 31 | K8: ='Base Financials'!K10 -> 0 | L8: ='Base Financials'!L10 -> 0 | M8: ='Base Financials'!M10 -> 0 | N8: ='Base Financials'!N10 -> 0 | O8: ='Base Financials'!O10 -> 0 | ... U8: ='Base Financials'!U10 -> 0 | W8: =SUM(H8:K8) -> 1565 | X8: =SUM(I8:L8) -> 1332 | Y8: =SUM(J8:M8) -> 31 | Z8: =SUM(K8:N8) -> 0 | AA8: =SUM(L8:O8) -> 0 | AB8: =SUM(M8:P8) -> 0 | AC8: =SUM(N8:Q8) -> 0 | AD8: =SUM(O8:R8) -> 0 | ... AG8: =SUM(R8:U8) -> 0 | AI8: =SUM(AG8/AC8)-1 -> #DIV/0!
B9: Total Revenue | C9: =SUM(C6:C8) -> 1263 | D9: =SUM(D6:D8) -> 1565 | E9: =SUM(E6:E8) -> 0 | F9: =SUM(F6:F8) -> 0 | H9: =SUM(H6:H8) -> 233 | I9: =SUM(I6:I8) -> 1301 | J9: =SUM(J6:J8) -> 31 | K9: =SUM(K6:K8) -> 0 | L9: =SUM(L6:L8) -> 0 | M9: =SUM(M6:M8) -> 0 | N9: =SUM(N6:N8) -> 0 | O9: =SUM(O6:O8) -> 0 | ... U9: =SUM(U6:U8) -> 301 | W9: =SUM(W6:W8) -> 1565 | X9: =SUM(X6:X8) -> 1332 | Y9: =SUM(Y6:Y8) -> 31 | Z9: =SUM(Z6:Z8) -> 0 | AA9: =SUM(AA6:AA8) -> 0 | AB9: =SUM(AB6:AB8) -> 0 | AC9: =SUM(AC6:AC8) -> 0 | AD9: =SUM(AD6:AD8) -> 0 | ... AG9: =SUM(AG6:AG8) -> 818 | AI9: =SUM(AG9/AC9)-1 -> #DIV/0!
B10: Y/Y Growth (%) | D10: =SUM(D9/C9)-1 -> 0.23911322 | E10: =SUM(E9/D9)-1 -> -1 | F10: =SUM(F9/E9)-1 -> #DIV/0! | L10: =SUM(L9/H9)-1 -> -1 | M10: =SUM(M9/I9)-1 -> -1 | N10: =SUM(N9/J9)-1 -> -1 | O10: =SUM(O9/K9)-1 -> #DIV/0! | P10: =SUM(P9/L9)-1 -> #DIV/0! | Q10: =SUM(Q9/M9)-1 -> #DIV/0! | R10: =SUM(R9/N9)-1 -> #DIV/0! | S10: =SUM(S9/O9)-1 -> #DIV/0! | ... U10: =SUM(U9/Q9)-1 -> #DIV/0! | AA10: =SUM(AA9/W9)-1 -> -1 | AB10: =SUM(AB9/X9)-1 -> -1 | AC10: =SUM(AC9/Y9)-1 -> -1 | AD10: =SUM(AD9/Z9)-1 -> #DIV/0! | AE10: =SUM(AE9/AA9)-1 -> #DIV/0! | AF10: =SUM(AF9/AB9)-1 -> #DIV/0! | AG10: =SUM(AG9/AC9)-1 -> #DIV/0! | AI10: =SUM(AG10-AC10)*10000 -> #DIV/0!
B11: Q/Q Growth (%) | C11: N/A | D11: N/A | E11: N/A | F11: N/A | I11: =SUM(I9/H9)-1 -> 4.583691 | J11: =SUM(J9/I9)-1 -> -0.97617218 | K11: =SUM(K9/J9)-1 -> -1 | L11: =SUM(L9/K9)-1 -> #DIV/0! | M11: =SUM(M9/L9)-1 -> #DIV/0! | N11: =SUM(N9/M9)-1 -> #DIV/0! | O11: =SUM(O9/N9)-1 -> #DIV/0! | P11: =SUM(P9/O9)-1 -> #DIV/0! | ... U11: =SUM(U9/T9)-1 -> -0.41779497 | W11: N/A | X11: N/A | Y11: N/A | Z11: N/A | AA11: N/A | AB11: N/A | AC11: N/A | AD11: N/A | AE11: N/A | AF11: N/A | AG11: N/A
B13: (-) Cost of Goods Sold | C13: ='Base Financials'!C13 -> 0 | D13: ='Base Financials'!D13 -> 0 | E13: ='Base Financials'!E13 -> 0 | F13: ='Base Financials'!F13 -> 0 | H13: ='Base Financials'!H13 -> 0 | I13: ='Base Financials'!I13 -> 0 | J13: ='Base Financials'!J13 -> 0 | K13: ='Base Financials'!K13 -> 0 | L13: ='Base Financials'!L13 -> 0 | M13: ='Base Financials'!M13 -> 0 | N13: ='Base Financials'!N13 -> 0 | O13: ='Base Financials'!O13 -> 0 | ... U13: ='Base Financials'!U13 -> -213 | W13: =SUM(H13:K13) -> 0 | X13: =SUM(I13:L13) -> 0 | Y13: =SUM(J13:M13) -> 0 | Z13: =SUM(K13:N13) -> 0 | AA13: =SUM(L13:O13) -> 0 | AB13: =SUM(M13:P13) -> 0 | AC13: =SUM(N13:Q13) -> 0 | AD13: =SUM(O13:R13) -> 0 | ... AG13: =SUM(R13:U13) -> -360 | AI13: =SUM(AG13/AC13)-1 -> #DIV/0!
B14: Gross Profit | C14: =+C9+C13 -> 1263 | D14: =+D9+D13 -> 1565 | E14: =+E9+E13 -> 0 | F14: =+F9+F13 -> 0 | H14: =+H9+H13 -> 233 | I14: =+I9+I13 -> 1301 | J14: =+J9+J13 -> 31 | K14: =+K9+K13 -> 0 | L14: =+L9+L13 -> 0 | M14: =+M9+M13 -> 0 | N14: =+N9+N13 -> 0 | O14: =+O9+O13 -> 0 | ... U14: =+U9+U13 -> 88 | W14: =+W9+W13 -> 1565 | X14: =+X9+X13 -> 1332 | Y14: =+Y9+Y13 -> 31 | Z14: =+Z9+Z13 -> 0 | AA14: =+AA9+AA13 -> 0 | AB14: =+AB9+AB13 -> 0 | AC14: =+AC9+AC13 -> 0 | AD14: =+AD9+AD13 -> 0 | ... AG14: =+AG9+AG13 -> 458 | AI14: =SUM(AG14/AC14)-1 -> #DIV/0!
B15: Gross Margin (%) | C15: =C14/C9 -> 1 | D15: =D14/D9 -> 1 | E15: =E14/E9 -> #DIV/0! | F15: =F14/F9 -> #DIV/0! | H15: =H14/H9 -> 1 | I15: =I14/I9 -> 1 | J15: =J14/J9 -> 1 | K15: =K14/K9 -> #DIV/0! | L15: =L14/L9 -> #DIV/0! | M15: =M14/M9 -> #DIV/0! | N15: =N14/N9 -> #DIV/0! | O15: =O14/O9 -> #DIV/0! | ... U15: =U14/U9 -> 0.2923588 | W15: =W14/W9 -> 1 | X15: =X14/X9 -> 1 | Y15: =Y14/Y9 -> 1 | Z15: =Z14/Z9 -> #DIV/0! | AA15: =AA14/AA9 -> #DIV/0! | AB15: =AB14/AB9 -> #DIV/0! | AC15: =AC14/AC9 -> #DIV/0! | AD15: =AD14/AD9 -> #DIV/0! | ... AG15: =AG14/AG9 -> 0.5599022 | AI15: =SUM(AG15-AC15)*10000 -> #DIV/0!
B17: (-) Research and Development (R&D) | C17: ='Base Financials'!C16 -> -61341 | D17: ='Base Financials'!D16 -> -63260 | E17: ='Base Financials'!E16 -> -76550 | F17: ='Base Financials'!F16 -> -88599 | H17: ='Base Financials'!H16 -> -16314 | I17: ='Base Financials'!I16 -> -14652 | J17: ='Base Financials'!J16 -> -17337 | K17: ='Base Financials'!K16 -> -14957 | L17: ='Base Financials'!L16 -> -17278 | M17: ='Base Financials'!M16 -> -20540 | N17: ='Base Financials'!N16 -> -18552 | O17: ='Base Financials'!O16 -> -20180 | ... U17: ='Base Financials'!U16 -> -22006 | W17: =SUM(H17:K17) -> -63260 | X17: =SUM(I17:L17) -> -64224 | Y17: =SUM(J17:M17) -> -70112 | Z17: =SUM(K17:N17) -> -71327 | AA17: =SUM(L17:O17) -> -76550 | AB17: =SUM(M17:P17) -> -80536 | AC17: =SUM(N17:Q17) -> -83749 | AD17: =SUM(O17:R17) -> -88123 | ... AG17: =SUM(R17:U17) -> -81006 | AI17: =SUM(AG17/AC17)-1 -> -0.03275263
B18: (-) General and Administrative (G&A) | C18: ='Base Financials'!C17 -> -21130 | D18: ='Base Financials'!D17 -> -22883 | E18: ='Base Financials'!E17 -> -23497 | F18: ='Base Financials'!F17 -> -25799 | H18: ='Base Financials'!H17 -> -5682 | I18: ='Base Financials'!I17 -> -5180 | J18: ='Base Financials'!J17 -> -6188 | K18: ='Base Financials'!K17 -> -5833 | L18: ='Base Financials'!L17 -> -5234 | M18: ='Base Financials'!M17 -> -6191 | N18: ='Base Financials'!N17 -> -6070 | O18: ='Base Financials'!O17 -> -6002 | ... U18: ='Base Financials'!U17 -> -7809 | W18: =SUM(H18:K18) -> -22883 | X18: =SUM(I18:L18) -> -22435 | Y18: =SUM(J18:M18) -> -23446 | Z18: =SUM(K18:N18) -> -23328 | AA18: =SUM(L18:O18) -> -23497 | AB18: =SUM(M18:P18) -> -23577 | AC18: =SUM(N18:Q18) -> -23132 | AD18: =SUM(O18:R18) -> -24369 | ... AG18: =SUM(R18:U18) -> -30684 | AI18: =SUM(AG18/AC18)-1 -> 0.32647415
B19: Earning before Interest & Taxes (EBIT) | C19: =SUM(C14+SUM(C17:C18)) -> -81208 | D19: =SUM(D14+SUM(D17:D18)) -> -84578 | E19: =SUM(E14+SUM(E17:E18)) -> -100047 | F19: =SUM(F14+SUM(F17:F18)) -> -114398 | H19: =SUM(H14+SUM(H17:H18)) -> -21763 | I19: =SUM(I14+SUM(I17:I18)) -> -18531 | J19: =SUM(J14+SUM(J17:J18)) -> -23494 | K19: =SUM(K14+SUM(K17:K18)) -> -20790 | L19: =SUM(L14+SUM(L17:L18)) -> -22512 | M19: =SUM(M14+SUM(M17:M18)) -> -26731 | N19: =SUM(N14+SUM(N17:N18)) -> -24622 | O19: =SUM(O14+SUM(O17:O18)) -> -26182 | ... U19: =SUM(U14+SUM(U17:U18)) -> -29727 | W19: =SUM(W14+SUM(W17:W18)) -> -84578 | X19: =SUM(X14+SUM(X17:X18)) -> -85327 | Y19: =SUM(Y14+SUM(Y17:Y18)) -> -93527 | Z19: =SUM(Z14+SUM(Z17:Z18)) -> -94655 | AA19: =SUM(AA14+SUM(AA17:AA18)) -> -100047 | AB19: =SUM(AB14+SUM(AB17:AB18)) -> -104113 | AC19: =SUM(AC14+SUM(AC17:AC18)) -> -106881 | AD19: =SUM(AD14+SUM(AD17:AD18)) -> -112492 | ... AG19: =SUM(AG14+SUM(AG17:AG18)) -> -111232 | AI19: =SUM(AG19/AC19)-1 -> 0.040708826
B20: Operating Margin (%) | C20: =C19/C9 -> -64.297704 | D20: =D19/D9 -> -54.04345 | E20: =E19/E9 -> #DIV/0! | F20: =F19/F9 -> #DIV/0! | H20: =H19/H9 -> -93.403433 | I20: =I19/I9 -> -14.243659 | J20: =J19/J9 -> -757.87097 | K20: =K19/K9 -> #DIV/0! | L20: =L19/L9 -> #DIV/0! | M20: =M19/M9 -> #DIV/0! | N20: =N19/N9 -> #DIV/0! | O20: =O19/O9 -> #DIV/0! | ... U20: =U19/U9 -> -98.760797 | W20: =W19/W9 -> -54.04345 | X20: =X19/X9 -> -64.059309 | Y20: =Y19/Y9 -> -3017 | Z20: =Z19/Z9 -> #DIV/0! | AA20: =AA19/AA9 -> #DIV/0! | AB20: =AB19/AB9 -> #DIV/0! | AC20: =AC19/AC9 -> #DIV/0! | AD20: =AD19/AD9 -> #DIV/0! | ... AG20: =AG19/AG9 -> -135.98044 | AI20: =SUM(AG20-AC20)*10000 -> #DIV/0!
B22: (+) Depreciation and Amortization | C22: =SUM('Base Financials'!C84:C85) -> 8241 | D22: =SUM('Base Financials'!D84:D85) -> 8210 | E22: =SUM('Base Financials'!E84:E85) -> 7719 | F22: =SUM('Base Financials'!F84:F85) -> 7190 | H22: =SUM('Base Financials'!H84:H85) -> 2040 | I22: =SUM('Base Financials'!I84:I85) -> 2021 | J22: =SUM('Base Financials'!J84:J85) -> 2035 | K22: =SUM('Base Financials'!K84:K85) -> 2114 | L22: =SUM('Base Financials'!L84:L85) -> 2073 | M22: =SUM('Base Financials'!M84:M85) -> 1983 | N22: =SUM('Base Financials'!N84:N85) -> 1830 | O22: =SUM('Base Financials'!O84:O85) -> 1833 | ... U22: =SUM('Base Financials'!U84:U85) -> 1860 | W22: =SUM(H22:K22) -> 8210 | X22: =SUM(I22:L22) -> 8243 | Y22: =SUM(J22:M22) -> 8205 | Z22: =SUM(K22:N22) -> 8000 | AA22: =SUM(L22:O22) -> 7719 | AB22: =SUM(M22:P22) -> 7437 | AC22: =SUM(N22:Q22) -> 7233 | AD22: =SUM(O22:R22) -> 7215 | ... AG22: =SUM(R22:U22) -> 7312 | AI22: =SUM(AG22/AC22)-1 -> 0.010922162
B23: EBITDA | C23: =SUM(C19+C22) -> -72967 | D23: =SUM(D19+D22) -> -76368 | E23: =SUM(E19+E22) -> -92328 | F23: =SUM(F19+F22) -> -107208 | H23: =SUM(H19+H22) -> -19723 | I23: =SUM(I19+I22) -> -16510 | J23: =SUM(J19+J22) -> -21459 | K23: =SUM(K19+K22) -> -18676 | L23: =SUM(L19+L22) -> -20439 | M23: =SUM(M19+M22) -> -24748 | N23: =SUM(N19+N22) -> -22792 | O23: =SUM(O19+O22) -> -24349 | ... U23: =SUM(U19+U22) -> -27867 | W23: =SUM(W19+W22) -> -76368 | X23: =SUM(X19+X22) -> -77084 | Y23: =SUM(Y19+Y22) -> -85322 | Z23: =SUM(Z19+Z22) -> -86655 | AA23: =SUM(AA19+AA22) -> -92328 | AB23: =SUM(AB19+AB22) -> -96676 | AC23: =SUM(AC19+AC22) -> -99648 | AD23: =SUM(AD19+AD22) -> -105277 | ... AG23: =SUM(AG19+AG22) -> -103920 | AI23: =SUM(AG23/AC23)-1 -> 0.042870906
B24: EBITDA Margin (%) | C24: =C23/C9 -> -57.772763 | D24: =D23/D9 -> -48.797444 | E24: =E23/E9 -> #DIV/0! | F24: =F23/F9 -> #DIV/0! | H24: =H23/H9 -> -84.648069 | I24: =I23/I9 -> -12.690238 | J24: =J23/J9 -> -692.22581 | K24: =K23/K9 -> #DIV/0! | L24: =L23/L9 -> #DIV/0! | M24: =M23/M9 -> #DIV/0! | N24: =N23/N9 -> #DIV/0! | O24: =O23/O9 -> #DIV/0! | ... U24: =U23/U9 -> -92.581395 | W24: =W23/W9 -> -48.797444 | X24: =X23/X9 -> -57.870871 | Y24: =Y23/Y9 -> -2752.3226 | Z24: =Z23/Z9 -> #DIV/0! | AA24: =AA23/AA9 -> #DIV/0! | AB24: =AB23/AB9 -> #DIV/0! | AC24: =AC23/AC9 -> #DIV/0! | AD24: =AD23/AD9 -> #DIV/0! | ... AG24: =AG23/AG9 -> -127.04156 | AI24: =SUM(AG24-AC24)*10000 -> #DIV/0!
B26: (+) Share-based Compensation (SBC) | C26: ='Base Financials'!C86 -> 10146 | D26: ='Base Financials'!D86 -> 6184 | E26: ='Base Financials'!E86 -> 6828 | F26: ='Base Financials'!F86 -> 6137 | H26: ='Base Financials'!H86 -> 1547 | I26: ='Base Financials'!I86 -> 1491 | J26: ='Base Financials'!J86 -> 1476 | K26: ='Base Financials'!K86 -> 1670 | L26: ='Base Financials'!L86 -> 1809 | M26: ='Base Financials'!M86 -> 1841 | N26: ='Base Financials'!N86 -> 1772 | O26: ='Base Financials'!O86 -> 1406 | ... U26: ='Base Financials'!U86 -> 2335 | W26: =SUM(H26:K26) -> 6184 | X26: =SUM(I26:L26) -> 6446 | Y26: =SUM(J26:M26) -> 6796 | Z26: =SUM(K26:N26) -> 7092 | AA26: =SUM(L26:O26) -> 6828 | AB26: =SUM(M26:P26) -> 6473 | AC26: =SUM(N26:Q26) -> 6069 | AD26: =SUM(O26:R26) -> 5849 | ... AG26: =SUM(R26:U26) -> 8068 | AI26: =SUM(AG26/AC26)-1 -> 0.32937881
B27: (+/-) Change in Fair Value of Contingent Earnout Liability | C27: ='Base Financials'!C87 -> -55772 | D27: ='Base Financials'!D87 -> -75767 | E27: ='Base Financials'!E87 -> 10023 | F27: ='Base Financials'!F87 -> 33045 | H27: ='Base Financials'!H87 -> -3258 | I27: ='Base Financials'!I87 -> -56353 | J27: ='Base Financials'!J87 -> 962 | K27: ='Base Financials'!K87 -> -17118 | L27: ='Base Financials'!L87 -> 14191 | M27: ='Base Financials'!M87 -> -3627 | N27: ='Base Financials'!N87 -> 1144 | O27: ='Base Financials'!O87 -> -1685 | ... U27: ='Base Financials'!U87 -> 5470 | W27: =SUM(H27:K27) -> -75767 | X27: =SUM(I27:L27) -> -58318 | Y27: =SUM(J27:M27) -> -5592 | Z27: =SUM(K27:N27) -> -5410 | AA27: =SUM(L27:O27) -> 10023 | AB27: =SUM(M27:P27) -> 425 | AC27: =SUM(N27:Q27) -> 29623 | AD27: =SUM(O27:R27) -> 36968 | ... AG27: =SUM(R27:U27) -> -41380 | AI27: =SUM(AG27/AC27)-1 -> -2.3968876
B28: (+/-) Change in Fair Value of Derivative Liabilities | C28: ='Base Financials'!C88 -> -56 | D28: ='Base Financials'!D88 -> -417 | E28: ='Base Financials'!E88 -> 260 | F28: ='Base Financials'!F88 -> -3915 | H28: ='Base Financials'!H88 -> 0 | I28: ='Base Financials'!I88 -> 0 | J28: ='Base Financials'!J88 -> 0 | K28: ='Base Financials'!K88 -> 0 | L28: ='Base Financials'!L88 -> 0 | M28: ='Base Financials'!M88 -> 99 | N28: ='Base Financials'!N88 -> 135 | O28: ='Base Financials'!O88 -> 26 | ... U28: ='Base Financials'!U88 -> 748 | AC28: =SUM(N28:Q28) -> 489 | AD28: =SUM(O28:R28) -> -693 | AE28: =SUM(P28:S28) -> -3915 | AF28: =SUM(Q28:T28) -> -18785 | AG28: =SUM(R28:U28) -> -18425 | AI28: =SUM(AG28/AC28)-1 -> -38.678937
B29: Adj. EBITDA | C29: =+SUM(C23+SUM(C26:C28)) -> -118649 | D29: =+SUM(D23+SUM(D26:D28)) -> -146368 | E29: =+SUM(E23+SUM(E26:E28)) -> -75217 | F29: =+SUM(F23+SUM(F26:F28)) -> -71941 | H29: =+SUM(H23+SUM(H26:H28)) -> -21434 | I29: =+SUM(I23+SUM(I26:I28)) -> -71372 | J29: =+SUM(J23+SUM(J26:J28)) -> -19021 | K29: =+SUM(K23+SUM(K26:K28)) -> -34124 | L29: =+SUM(L23+SUM(L26:L28)) -> -4439 | M29: =+SUM(M23+SUM(M26:M28)) -> -26435 | N29: =+SUM(N23+SUM(N26:N28)) -> -19741 | O29: =+SUM(O23+SUM(O26:O28)) -> -24602 | ... U29: =+SUM(U23+SUM(U26:U28)) -> -19314 | W29: =+SUM(W23+SUM(W26:W27)) -> -145951 | X29: =+SUM(X23+SUM(X26:X27)) -> -128956 | Y29: =+SUM(Y23+SUM(Y26:Y27)) -> -84118 | Z29: =+SUM(Z23+SUM(Z26:Z27)) -> -84973 | AA29: =+SUM(AA23+SUM(AA26:AA27)) -> -75477 | AB29: =+SUM(AB23+SUM(AB26:AB27)) -> -89778 | AC29: =+SUM(AC23+SUM(AC26:AC28)) -> -63467 | AD29: =+SUM(AD23+SUM(AD26:AD28)) -> -63153 | AE29: =+SUM(AE23+SUM(AE26:AE28)) -> -71941 | AF29: =+SUM(AF23+SUM(AF26:AF28)) -> -136667 | AG29: =+SUM(AG23+SUM(AG26:AG28)) -> -155657 | AI29: =SUM(AG29/AC29)-1 -> 1.4525659
B30: Adj. EBITDA Margin (%) | C30: =C29/C9 -> -93.942201 | D30: =D29/D9 -> -93.525879 | E30: =E29/E9 -> #DIV/0! | F30: =F29/F9 -> #DIV/0! | H30: =H29/H9 -> -91.991416 | I30: =I29/I9 -> -54.859339 | J30: =J29/J9 -> -613.58065 | K30: =K29/K9 -> #DIV/0! | L30: =L29/L9 -> #DIV/0! | M30: =M29/M9 -> #DIV/0! | N30: =N29/N9 -> #DIV/0! | O30: =O29/O9 -> #DIV/0! | ... U30: =U29/U9 -> -64.166113 | W30: =W29/W9 -> -93.259425 | X30: =X29/X9 -> -96.813814 | Y30: =Y29/Y9 -> -2713.4839 | Z30: =Z29/Z9 -> #DIV/0! | AA30: =AA29/AA9 -> #DIV/0! | AB30: =AB29/AB9 -> #DIV/0! | AC30: =AC29/AC9 -> #DIV/0! | AD30: =AD29/AD9 -> #DIV/0! | ... AG30: =AG29/AG9 -> -190.28973 | AI30: =SUM(AG30-AC30)*10000 -> #DIV/0!
B32: (-) Capital Expenditures | C32: ='Base Financials'!C103 -> -220 | D32: ='Base Financials'!D103 -> -1048 | E32: ='Base Financials'!E103 -> -2280 | F32: ='Base Financials'!F103 -> -1572 | H32: ='Base Financials'!H103 -> -22 | I32: ='Base Financials'!I103 -> -134 | J32: ='Base Financials'!J103 -> -211 | K32: ='Base Financials'!K103 -> -681 | L32: ='Base Financials'!L103 -> -1152 | M32: ='Base Financials'!M103 -> -485 | N32: ='Base Financials'!N103 -> -493 | O32: ='Base Financials'!O103 -> -150 | ... U32: ='Base Financials'!U103 -> -568 | W32: =SUM(H32:K32) -> -1048 | X32: =SUM(I32:L32) -> -2178 | Y32: =SUM(J32:M32) -> -2529 | Z32: =SUM(K32:N32) -> -2811 | AA32: =SUM(L32:O32) -> -2280 | AB32: =SUM(M32:P32) -> -1519 | AC32: =SUM(N32:Q32) -> -1218 | AD32: =SUM(O32:R32) -> -1659 | ... AG32: =SUM(R32:U32) -> -1793 | AI32: =SUM(AG32/AC32)-1 -> 0.47208539
B33: (-) Cash Interest | C33: ='Base Financials'!C21 -> -4348 | D33: ='Base Financials'!D21 -> -6200 | E33: ='Base Financials'!E21 -> -6599 | F33: ='Base Financials'!F21 -> -9277 | H33: ='Base Financials'!H21 -> -1432 | I33: ='Base Financials'!I21 -> -1488 | J33: ='Base Financials'!J21 -> -1641 | K33: ='Base Financials'!K21 -> -1639 | L33: ='Base Financials'!L21 -> -1699 | M33: ='Base Financials'!M21 -> -1710 | N33: ='Base Financials'!N21 -> -1463 | O33: ='Base Financials'!O21 -> -1727 | ... U33: ='Base Financials'!U21 -> -2545 | W33: =SUM(H33:K33) -> -6200 | X33: =SUM(I33:L33) -> -6467 | Y33: =SUM(J33:M33) -> -6689 | Z33: =SUM(K33:N33) -> -6511 | AA33: =SUM(L33:O33) -> -6599 | AB33: =SUM(M33:P33) -> -6716 | AC33: =SUM(N33:Q33) -> -7521 | AD33: =SUM(O33:R33) -> -8496 | ... AG33: =SUM(R33:U33) -> -10491 | AI33: =SUM(AG33/AC33)-1 -> 0.3948943
B34: (-) Cash Taxes | C34: 0 | D34: 0 | E34: 0 | F34: 0 | H34: 0 | I34: 0 | J34: 0 | K34: 0 | L34: 0 | M34: 0 | N34: 0 | O34: 0 | P34: 0 | Q34: 0 | R34: 0 | S34: 0 | T34: 0 | U34: 0 | W34: =SUM(H34:K34) -> 0 | X34: =SUM(I34:L34) -> 0 | Y34: =SUM(J34:M34) -> 0 | Z34: =SUM(K34:N34) -> 0 | AA34: =SUM(L34:O34) -> 0 | AB34: =SUM(M34:P34) -> 0 | AC34: =SUM(N34:Q34) -> 0 | AD34: =SUM(O34:R34) -> 0 | ... AG34: =SUM(R34:U34) -> 0 | AI34: =SUM(AG34/AC34)-1 -> #DIV/0!
B35: (-) Mandatory Amortization | C35: 0 | D35: 0 | E35: 0 | F35: 0 | H35: 0 | I35: 0 | J35: 0 | K35: 0 | L35: 0 | M35: 0 | N35: 0 | O35: 0 | P35: 0 | Q35: 0 | R35: 0 | S35: 0 | T35: 0 | U35: 0 | W35: =SUM(H35:K35) -> 0 | X35: =SUM(I35:L35) -> 0 | Y35: =SUM(J35:M35) -> 0 | Z35: =SUM(K35:N35) -> 0 | AA35: =SUM(L35:O35) -> 0 | AB35: =SUM(M35:P35) -> 0 | AC35: =SUM(N35:Q35) -> 0 | AD35: =SUM(O35:R35) -> 0 | ... AG35: =SUM(R35:U35) -> 0 | AI35: =SUM(AG35/AC35)-1 -> #DIV/0!
B36: (+/-) Changes in NWC | C36: =SUM('Base Financials'!C95:C99) -> -557 | D36: =SUM('Base Financials'!D95:D99) -> 1029 | E36: =SUM('Base Financials'!E95:E99) -> 6571 | F36: =SUM('Base Financials'!F95:F99) -> 311 | H36: =SUM('Base Financials'!H95:H99) -> 391 | I36: =SUM('Base Financials'!I95:I99) -> -767 | J36: =SUM('Base Financials'!J95:J99) -> 3485 | K36: =SUM('Base Financials'!K95:K99) -> -2080 | L36: =SUM('Base Financials'!L95:L99) -> -159 | M36: =SUM('Base Financials'!M95:M99) -> -3452 | N36: =SUM('Base Financials'!N95:N99) -> 7051 | O36: =SUM('Base Financials'!O95:O99) -> 3131 | ... U36: =SUM('Base Financials'!U95:U99) -> -1398 | W36: =SUM(H36:K36) -> 1029 | X36: =SUM(I36:L36) -> 479 | Y36: =SUM(J36:M36) -> -2206 | Z36: =SUM(K36:N36) -> 1360 | AA36: =SUM(L36:O36) -> 6571 | AB36: =SUM(M36:P36) -> 2070 | AC36: =SUM(N36:Q36) -> 9580 | AD36: =SUM(O36:R36) -> 5943 | ... AG36: =SUM(R36:U36) -> -10049 | AI36: =SUM(AG36/AC36)-1 -> -2.0489562
B37: Discretionary Cash-Flows | C37: =SUM(C29+SUM(C32:C36)) -> -123774 | D37: =SUM(D29+SUM(D32:D36)) -> -152587 | E37: =SUM(E29+SUM(E32:E36)) -> -77525 | F37: =SUM(F29+SUM(F32:F36)) -> -82479 | H37: =SUM(H29+SUM(H32:H36)) -> -22497 | I37: =SUM(I29+SUM(I32:I36)) -> -73761 | J37: =SUM(J29+SUM(J32:J36)) -> -17388 | K37: =SUM(K29+SUM(K32:K36)) -> -38524 | L37: =SUM(L29+SUM(L32:L36)) -> -7449 | M37: =SUM(M29+SUM(M32:M36)) -> -32082 | N37: =SUM(N29+SUM(N32:N36)) -> -14646 | O37: =SUM(O29+SUM(O32:O36)) -> -23348 | ... U37: =SUM(U29+SUM(U32:U36)) -> -23825 | W37: =SUM(W29+SUM(W32:W36)) -> -152170 | X37: =SUM(X29+SUM(X32:X36)) -> -137122 | Y37: =SUM(Y29+SUM(Y32:Y36)) -> -95542 | Z37: =SUM(Z29+SUM(Z32:Z36)) -> -92935 | AA37: =SUM(AA29+SUM(AA32:AA36)) -> -77785 | AB37: =SUM(AB29+SUM(AB32:AB36)) -> -95943 | AC37: =SUM(AC29+SUM(AC32:AC36)) -> -62626 | AD37: =SUM(AD29+SUM(AD32:AD36)) -> -67365 | ... AG37: =SUM(AG29+SUM(AG32:AG36)) -> -177990 | AI37: =SUM(AG37/AC37)-1 -> 1.8421103
B39: (+/-) Net Equity Issuances / (Share Repurchases) | C39: ='Base Financials'!C108 -> 598 | D39: ='Base Financials'!D108 -> 535 | E39: ='Base Financials'!E108 -> 566 | F39: ='Base Financials'!F108 -> 97022 | H39: ='Base Financials'!H108 -> 1 | I39: ='Base Financials'!I108 -> 11 | J39: ='Base Financials'!J108 -> 217 | K39: ='Base Financials'!K108 -> 306 | L39: ='Base Financials'!L108 -> 119 | M39: ='Base Financials'!M108 -> 95 | N39: ='Base Financials'!N108 -> 99 | O39: ='Base Financials'!O108 -> 253 | ... U39: ='Base Financials'!U108 -> 2893 | W39: =SUM(H39:K39) -> 535 | X39: =SUM(I39:L39) -> 653 | Y39: =SUM(J39:M39) -> 737 | Z39: =SUM(K39:N39) -> 619 | AA39: =SUM(L39:O39) -> 566 | AB39: =SUM(M39:P39) -> 43845 | AC39: =SUM(N39:Q39) -> 44187 | AD39: =SUM(O39:R39) -> 45596 | ... AG39: =SUM(R39:U39) -> 103506 | AI39: =SUM(AG39/AC39)-1 -> 1.3424537
B40: (+/-) Net Issuance / (Repayment) of Debt | C40: ='Base Financials'!C109 -> 27930 | D40: ='Base Financials'!D109 -> -1981 | E40: ='Base Financials'!E109 -> -34066 | F40: ='Base Financials'!F109 -> -2579 | H40: ='Base Financials'!H109 -> -462 | I40: ='Base Financials'!I109 -> -495 | J40: ='Base Financials'!J109 -> -506 | K40: ='Base Financials'!K109 -> -518 | L40: ='Base Financials'!L109 -> -528 | M40: ='Base Financials'!M109 -> -32373 | N40: ='Base Financials'!N109 -> -577 | O40: ='Base Financials'!O109 -> -588 | ... U40: ='Base Financials'!U109 -> -727 | W40: =SUM(H40:K40) -> -1981 | X40: =SUM(I40:L40) -> -2047 | Y40: =SUM(J40:M40) -> -33925 | Z40: =SUM(K40:N40) -> -33996 | AA40: =SUM(L40:O40) -> -34066 | AB40: =SUM(M40:P40) -> -34141 | AC40: =SUM(N40:Q40) -> -2412 | AD40: =SUM(O40:R40) -> -2494 | ... AG40: =SUM(R40:U40) -> -2746 | AI40: =SUM(AG40/AC40)-1 -> 0.1384743
B41: (+/-) Net Divestitures / (Acquisitions) | C41: ='Base Financials'!C110 -> 238455 | D41: ='Base Financials'!D110 -> 0 | E41: ='Base Financials'!E110 -> 0 | F41: ='Base Financials'!F110 -> 0 | H41: ='Base Financials'!H110 -> 0 | I41: ='Base Financials'!I110 -> 0 | J41: ='Base Financials'!J110 -> 0 | K41: ='Base Financials'!K110 -> 0 | L41: ='Base Financials'!L110 -> 0 | M41: ='Base Financials'!M110 -> 0 | N41: ='Base Financials'!N110 -> 0 | O41: ='Base Financials'!O110 -> 0 | ... U41: ='Base Financials'!U110 -> 0 | W41: =SUM(H41:K41) -> 0 | X41: =SUM(I41:L41) -> 0 | Y41: =SUM(J41:M41) -> 0 | Z41: =SUM(K41:N41) -> 0 | AA41: =SUM(L41:O41) -> 0 | AB41: =SUM(M41:P41) -> 0 | AC41: =SUM(N41:Q41) -> 0 | AD41: =SUM(O41:R41) -> 0 | ... AG41: =SUM(R41:U41) -> 0 | AI41: =SUM(AG41/AC41)-1 -> #DIV/0!
B42: (+/-) Proceeds / (Payments) with Revenue Interest Purchase Agreement | C42: ='Base Financials'!C111 -> 0 | D42: ='Base Financials'!D111 -> 0 | E42: ='Base Financials'!E111 -> 37927 | F42: ='Base Financials'!F111 -> 19500 | H42: ='Base Financials'!H111 -> 0 | I42: ='Base Financials'!I111 -> 0 | J42: ='Base Financials'!J111 -> 0 | K42: ='Base Financials'!K111 -> 0 | L42: ='Base Financials'!L111 -> 0 | M42: ='Base Financials'!M111 -> 38213 | N42: ='Base Financials'!N111 -> -286 | O42: ='Base Financials'!O111 -> 0 | ... U42: ='Base Financials'!U111 -> 0 | W42: =SUM(H42:K42) -> 0 | X42: =SUM(I42:L42) -> 0 | Y42: =SUM(J42:M42) -> 38213 | Z42: =SUM(K42:N42) -> 37927 | AA42: =SUM(L42:O42) -> 37927 | AB42: =SUM(M42:P42) -> 57927 | AC42: =SUM(N42:Q42) -> 19214 | AD42: =SUM(O42:R42) -> 19500 | ... AG42: =SUM(R42:U42) -> 0 | AI42: =SUM(AG42/AC42)-1 -> -1
B43: (+/-) Proceeds from JDRF Agreement | C43: ='Base Financials'!C112 -> 0 | D43: ='Base Financials'!D112 -> 0 | E43: ='Base Financials'!E112 -> 80 | F43: ='Base Financials'!F112 -> 240 | H43: ='Base Financials'!H112 -> 0 | I43: ='Base Financials'!I112 -> 0 | J43: ='Base Financials'!J112 -> 0 | K43: ='Base Financials'!K112 -> 0 | L43: ='Base Financials'!L112 -> 0 | M43: ='Base Financials'!M112 -> 80 | N43: ='Base Financials'!N112 -> 0 | O43: ='Base Financials'!O112 -> 0 | ... U43: ='Base Financials'!U112 -> 0 | W43: =SUM(H43:K43) -> 0 | X43: =SUM(I43:L43) -> 0 | Y43: =SUM(J43:M43) -> 80 | Z43: =SUM(K43:N43) -> 80 | AA43: =SUM(L43:O43) -> 80 | AB43: =SUM(M43:P43) -> 80 | AC43: =SUM(N43:Q43) -> 240 | AD43: =SUM(O43:R43) -> 240 | ... AG43: =SUM(R43:U43) -> 0 | AI43: =SUM(AG43/AC43)-1 -> -1
B44: (+/-) Other Adjustments | C44: =SUM(C37:C43)-C49 -> -74293 | D44: =SUM(D49-C49)-SUM(D37:D43) -> 86303 | E44: =SUM(E49-D49)-SUM(E37:E43) -> 3694 | F44: =SUM(F49-E49)-SUM(F37:F43) -> -67215 | H44: =SUM(H49-C49)-SUM(H37:H43) -> 3678 | I44: =SUM(I49-H49)-SUM(I37:I43) -> 57058 | J44: =SUM(J49-I49)-SUM(J37:J43) -> 373 | K44: =SUM(K49-J49)-SUM(K37:K43) -> 24777 | L44: =SUM(L49-K49)-SUM(L37:L43) -> -12344 | M44: =SUM(M49-L49)-SUM(M37:M43) -> 11101 | N44: =SUM(N49-M49)-SUM(N37:N43) -> 792 | O44: =SUM(O49-N49)-SUM(O37:O43) -> 4145 | P44: =SUM(P49-O49)-SUM(P37:P43) -> -2071 | ... U44: =SUM(U49-T49)-SUM(U37:U43) -> -3156 | W44: =SUM(H44:K44) -> 85886 | X44: =SUM(I44:L44) -> 69864 | Y44: =SUM(J44:M44) -> 23907 | Z44: =SUM(K44:N44) -> 24326 | AA44: =SUM(L44:O44) -> 3694 | AB44: =SUM(M44:P44) -> 13967 | AC44: =SUM(N44:Q44) -> -19644 | AD44: =SUM(O44:R44) -> -74892 | ... AG44: =SUM(R44:U44) -> 21699 | AI44: =SUM(AG44/AC44)-1 -> -2.1046121
B45: Free-Cash Flows | C45: =SUM(C37:C44) -> 68916 | D45: =SUM(D37+SUM(D39:D44)) -> -67730 | E45: =SUM(E37+SUM(E39:E44)) -> -69324 | F45: =SUM(F37+SUM(F39:F44)) -> -35511 | H45: =SUM(H37+SUM(H39:H44)) -> -19280 | I45: =SUM(I37+SUM(I39:I44)) -> -17187 | J45: =SUM(J37+SUM(J39:J44)) -> -17304 | K45: =SUM(K37+SUM(K39:K44)) -> -13959 | L45: =SUM(L37+SUM(L39:L44)) -> -20202 | M45: =SUM(M37+SUM(M39:M44)) -> -14966 | N45: =SUM(N37+SUM(N39:N44)) -> -14618 | O45: =SUM(O37+SUM(O39:O44)) -> -19538 | ... U45: =SUM(U37+SUM(U39:U44)) -> -24815 | W45: =SUM(W37+SUM(W39:W44)) -> -67730 | X45: =SUM(X37+SUM(X39:X44)) -> -68652 | Y45: =SUM(Y37+SUM(Y39:Y44)) -> -66530 | Z45: =SUM(Z37+SUM(Z39:Z44)) -> -63979 | AA45: =SUM(AA37+SUM(AA39:AA44)) -> -69584 | AB45: =SUM(AB37+SUM(AB39:AB44)) -> -14265 | AC45: =SUM(AC37+SUM(AC39:AC44)) -> -21041 | AD45: =SUM(AD37+SUM(AD39:AD44)) -> -79415 | ... AG45: =SUM(AG37+SUM(AG39:AG44)) -> -55531 | AI45: =SUM(AG45/AC45)-1 -> 1.6391806
B47: Capitalization
B49: Cash & Cash Equivelants | C49: ='Base Financials'!C35 -> 217502 | D49: ='Base Financials'!D35 -> 149772 | E49: ='Base Financials'!E35 -> 80448 | F49: ='Base Financials'!F35 -> 44937 | H49: ='Base Financials'!H35 -> 198222 | I49: ='Base Financials'!I35 -> 181035 | J49: ='Base Financials'!J35 -> 163731 | K49: ='Base Financials'!K35 -> 149772 | L49: ='Base Financials'!L35 -> 129570 | M49: ='Base Financials'!M35 -> 114604 | N49: ='Base Financials'!N35 -> 99986 | O49: ='Base Financials'!O35 -> 80448 | ... U49: ='Base Financials'!U35 -> 38032 | W49: =K49 -> 149772 | X49: =L49 -> 129570 | Y49: =M49 -> 114604 | Z49: =N49 -> 99986 | AA49: =O49 -> 80448 | AB49: =P49 -> 115505 | AC49: =Q49 -> 93563 | AD49: =R49 -> 20571 | ... AG49: =U49 -> 38032
B50: Short-Term Investments | C50: ='Base Financials'!C37 -> 8000 | D50: ='Base Financials'!D37 -> 2107 | E50: ='Base Financials'!E37 -> 0 | F50: ='Base Financials'!F37 -> 0 | H50: ='Base Financials'!H37 -> 8000 | I50: ='Base Financials'!I37 -> 8000 | J50: ='Base Financials'!J37 -> 8000 | K50: ='Base Financials'!K37 -> 2107 | L50: ='Base Financials'!L37 -> 2107 | M50: ='Base Financials'!M37 -> 0 | N50: ='Base Financials'!N37 -> 0 | O50: ='Base Financials'!O37 -> 0 | ... U50: ='Base Financials'!U37 -> 0 | W50: =K50 -> 2107 | X50: =L50 -> 2107 | Y50: =M50 -> 0 | Z50: =N50 -> 0 | AA50: =O50 -> 0 | AB50: =P50 -> 0 | AC50: =Q50 -> 0 | AD50: =R50 -> 0 | ... AG50: =U50 -> 0
...

Sheet Cash Analysis
B2: Humacyte Inc (NASDAQ: HUMA) | C2: FYE | D2: FYE | H2: Quarterly | P2: Quarterly | Q2: Quarterly | W2: LTM | AA2: LTM | AC2: LTM
B3: Cash Analysis | C3: 2021 | D3: 2022 | E3: 2023 | F3: 2024 | H3: 1Q22 | I3: 2Q22 | J3: 3Q22 | K3: 4Q22 | L3: 1Q23 | M3: 2Q23 | N3: 3Q23 | O3: 4Q23 | P3: 1Q24 | Q3: 2Q24 | R3: 3Q24 | S3: 4Q24 | T3: 1Q25 | U3: 2Q25 | W3: =K3 -> 4Q22 | X3: =L3 -> 1Q23 | Y3: =M3 -> 2Q23 | Z3: =N3 -> 3Q23 | AA3: =O3 -> 4Q23 | AB3: =P3 -> 1Q24 | AC3: =Q3 -> 2Q24 | AD3: =R3 -> 3Q24 | ... AG3: =U3 -> 2Q25
B4: ($ In Thousands) | C4: 44561 | D4: 44926 | E4: 45291 | F4: 45657 | H4: 44651 | I4: 44742 | J4: 44834 | K4: 44926 | L4: 45016 | M4: 45107 | N4: 45199 | O4: 45291 | P4: 45382 | Q4: 45473 | R4: 45565 | S4: 45657 | T4: 45747 | U4: 45838 | W4: =K4 -> 44926 | X4: =L4 -> 45016 | Y4: =M4 -> 45107 | Z4: =N4 -> 45199 | AA4: =O4 -> 45291 | AB4: =P4 -> 45382 | AC4: =Q4 -> 45473 | AD4: =R4 -> 45565 | ... AG4: =U4 -> 45838
B6: Cash & Cash Equivelants | C6: ='Base Financials'!C35 -> 217502 | D6: ='Base Financials'!D35 -> 149772 | E6: ='Base Financials'!E35 -> 80448 | F6: ='Base Financials'!F35 -> 44937 | H6: ='Base Financials'!H35 -> 198222 | I6: ='Base Financials'!I35 -> 181035 | J6: ='Base Financials'!J35 -> 163731 | K6: ='Base Financials'!K35 -> 149772 | L6: ='Base Financials'!L35 -> 129570 | M6: ='Base Financials'!M35 -> 114604 | N6: ='Base Financials'!N35 -> 99986 | O6: ='Base Financials'!O35 -> 80448 | ... U6: ='Base Financials'!U35 -> 38032 | W6: =K6 -> 149772 | X6: =L6 -> 129570 | Y6: =M6 -> 114604 | Z6: =N6 -> 99986 | AA6: =O6 -> 80448 | AB6: =P6 -> 115505 | AC6: =Q6 -> 93563 | AD6: =R6 -> 20571 | ... AG6: =U6 -> 38032
B7: Total Liquidity (Exclusive of ST Investments) | C7: =SUM(C6:C6) -> 217502 | D7: =SUM(D6:D6) -> 149772 | E7: =SUM(E6:E6) -> 80448 | F7: =SUM(F6:F6) -> 44937 | H7: =SUM(H6:H6) -> 198222 | I7: =SUM(I6:I6) -> 181035 | J7: =SUM(J6:J6) -> 163731 | K7: =SUM(K6:K6) -> 149772 | L7: =SUM(L6:L6) -> 129570 | M7: =SUM(M6:M6) -> 114604 | N7: =SUM(N6:N6) -> 99986 | O7: =SUM(O6:O6) -> 80448 | ... U7: =SUM(U6:U6) -> 38032 | W7: =SUM(W6:W6) -> 149772 | X7: =SUM(X6:X6) -> 129570 | Y7: =SUM(Y6:Y6) -> 114604 | Z7: =SUM(Z6:Z6) -> 99986 | AA7: =SUM(AA6:AA6) -> 80448 | AB7: =SUM(AB6:AB6) -> 115505 | AC7: =SUM(AC6:AC6) -> 93563 | AD7: =SUM(AD6:AD6) -> 20571 | ... AG7: =SUM(AG6:AG6) -> 38032
B9: Cash Burn Rate
B10: CFO | C10: ='Base Financials'!C100 -> -81190 | D10: ='Base Financials'!D100 -> -71129 | E10: ='Base Financials'!E100 -> -73305 | F10: ='Base Financials'!F100 -> -98122 | H10: ='Base Financials'!H100 -> -18797 | I10: ='Base Financials'!I100 -> -16569 | J10: ='Base Financials'!J100 -> -16804 | K10: ='Base Financials'!K100 -> -18548 | L10: ='Base Financials'!L100 -> -18641 | M10: ='Base Financials'!M100 -> -22603 | N10: ='Base Financials'!N100 -> -15910 | O10: ='Base Financials'!O100 -> -16151 | ... U10: ='Base Financials'!U100 -> -26413 | W10: =SUM(H10:K10) -> -70718 | X10: =SUM(I10:L10) -> -70562 | Y10: =SUM(J10:M10) -> -76596 | Z10: =SUM(K10:N10) -> -75702 | AA10: =SUM(L10:O10) -> -73305 | AB10: =SUM(M10:P10) -> -82011 | AC10: =SUM(N10:Q10) -> -80699 | AD10: =SUM(O10:R10) -> -87696 | ... AG10: =SUM(R10:U10) -> -104498
B11: Capex | C11: ='Base Financials'!C103 -> -220 | D11: ='Base Financials'!D103 -> -1048 | E11: ='Base Financials'!E103 -> -2280 | F11: ='Base Financials'!F103 -> -1572 | H11: ='Base Financials'!H103 -> -22 | I11: ='Base Financials'!I103 -> -134 | J11: ='Base Financials'!J103 -> -211 | K11: ='Base Financials'!K103 -> -681 | L11: ='Base Financials'!L103 -> -1152 | M11: ='Base Financials'!M103 -> -485 | N11: ='Base Financials'!N103 -> -493 | O11: ='Base Financials'!O103 -> -150 | ... U11: ='Base Financials'!U103 -> -568 | W11: =SUM(H11:K11) -> -1048 | X11: =SUM(I11:L11) -> -2178 | Y11: =SUM(J11:M11) -> -2529 | Z11: =SUM(K11:N11) -> -2811 | AA11: =SUM(L11:O11) -> -2280 | AB11: =SUM(M11:P11) -> -1519 | AC11: =SUM(N11:Q11) -> -1218 | AD11: =SUM(O11:R11) -> -1659 | ... AG11: =SUM(R11:U11) -> -1793
B12: Total Cash Burn Rate | C12: =+SUM(C10:C11)/12 -> -6784.1667 | D12: =+SUM(D10:D11)/12 -> -6014.75 | E12: =+SUM(E10:E11)/12 -> -6298.75 | F12: =+SUM(F10:F11)/12 -> -8307.8333 | H12: =+SUM(H10:H11)/12 -> -1568.25 | I12: =+SUM(I10:I11)/12 -> -1391.9167 | J12: =+SUM(J10:J11)/12 -> -1417.9167 | K12: =+SUM(K10:K11)/12 -> -1602.4167 | L12: =+SUM(L10:L11)/12 -> -1649.4167 | M12: =+SUM(M10:M11)/12 -> -1924 | N12: =+SUM(N10:N11)/12 -> -1366.9167 | O12: =+SUM(O10:O11)/12 -> -1358.4167 | ... U12: =+SUM(U10:U11)/12 -> -2248.4167 | W12: =+SUM(W10:W11) -> -71766 | X12: =+SUM(X10:X11) -> -72740 | Y12: =+SUM(Y10:Y11) -> -79125 | Z12: =+SUM(Z10:Z11) -> -78513 | AA12: =+SUM(AA10:AA11) -> -75585 | AB12: =+SUM(AB10:AB11) -> -83530 | AC12: =+SUM(AC10:AC11)/12 -> -6826.4167 | AD12: =+SUM(AD10:AD11)/12 -> -7446.25 | AE12: =+SUM(AE10:AE11)/12 -> -8307.8333 | AF12: =+SUM(AF10:AF11)/12 -> -8398.75 | AG12: =+SUM(AG10:AG11)/12 -> -8857.5833
B14: Cash Runway
B15: Total Liquidity | C15: =C7 -> 217502 | D15: =D7 -> 149772 | E15: =E7 -> 80448 | F15: =F7 -> 44937 | H15: =H7 -> 198222 | I15: =I7 -> 181035 | J15: =J7 -> 163731 | K15: =K7 -> 149772 | L15: =L7 -> 129570 | M15: =M7 -> 114604 | N15: =N7 -> 99986 | O15: =O7 -> 80448 | ... U15: =U7 -> 38032 | W15: =W7 -> 149772 | X15: =X7 -> 129570 | Y15: =Y7 -> 114604 | Z15: =Z7 -> 99986 | AA15: =AA7 -> 80448 | AB15: =AB7 -> 115505 | AC15: =AC7 -> 93563 | AD15: =AD7 -> 20571 | ... AG15: =AG7 -> 38032
B16: Monthly Cash Burn Rate | C16: =C12 -> -6784.1667 | D16: =D12 -> -6014.75 | E16: =E12 -> -6298.75 | F16: =F12 -> -8307.8333 | H16: =H12 -> -1568.25 | I16: =I12 -> -1391.9167 | J16: =J12 -> -1417.9167 | K16: =K12 -> -1602.4167 | L16: =L12 -> -1649.4167 | M16: =M12 -> -1924 | N16: =N12 -> -1366.9167 | O16: =O12 -> -1358.4167 | ... U16: =U12 -> -2248.4167 | W16: =W12 -> -71766 | X16: =X12 -> -72740 | Y16: =Y12 -> -79125 | Z16: =Z12 -> -78513 | AA16: =AA12 -> -75585 | AB16: =AB12 -> -83530 | AC16: =AC12 -> -6826.4167 | AD16: =AD12 -> -7446.25 | ... AG16: =AG12 -> -8857.5833
B17: Cash Runway | C17: =C15/-C16 -> 32.060238 | D17: =D15/-D16 -> 24.900786 | E17: =E15/-E16 -> 12.772058 | F17: =F15/-F16 -> 5.4089915 | H17: =H15/-H16 -> 126.39694 | I17: =I15/-I16 -> 130.06167 | J17: =J15/-J16 -> 115.47294 | K17: =K15/-K16 -> 93.466327 | L17: =L15/-L16 -> 78.555045 | M17: =M15/-M16 -> 59.565489 | N17: =N15/-N16 -> 73.147107 | O17: =O15/-O16 -> 59.221888 | ... U17: =U15/-U16 -> 16.915014 | W17: =W15/-W16 -> 2.0869493 | X17: =X15/-X16 -> 1.7812758 | Y17: =Y15/-Y16 -> 1.4483918 | Z17: =Z15/-Z16 -> 1.2734961 | AA17: =AA15/-AA16 -> 1.0643382 | AB17: =AB15/-AB16 -> 1.3827966 | AC17: =AC15/-AC16 -> 13.70602 | AD17: =AD15/-AD16 -> 2.7625986 | ... AG17: =AG15/-AG16 -> 4.293722
B19: Cash Per Shares Outstanding, Diluted
B20: Weighted-average shares outstanding, Diluted | C20: ='Base Financials'!C27 -> 39970.398 | D20: ='Base Financials'!D27 -> 103051.37 | E20: ='Base Financials'!E27 -> 103420.24 | F20: ='Base Financials'!F27 -> 118479.1 | H20: ='Base Financials'!H27 -> 103004.09 | I20: ='Base Financials'!I27 -> 103908.44 | J20: ='Base Financials'!J27 -> 103031.98 | K20: ='Base Financials'!K27 -> 103051.37 | L20: ='Base Financials'!L27 -> 103263.53 | M20: ='Base Financials'!M27 -> 103361.5 | N20: ='Base Financials'!N27 -> 103444.25 | O20: ='Base Financials'!O27 -> 103420.24 | ... U20: ='Base Financials'!U27 -> 155437.28 | W20: =K20 -> 103051.37 | X20: =L20 -> 103263.53 | Y20: =M20 -> 103361.5 | Z20: =N20 -> 103444.25 | AA20: =O20 -> 103420.24 | AB20: =P20 -> 108246.01 | AC20: =Q20 -> 119174.68 | AD20: =R20 -> 119408.57 | ... AG20: =U20 -> 155437.28
B21: Cash Per Share | C21: =C6/C20 -> 5.441577 | D21: =D6/D20 -> 1.4533723 | E21: =E6/E20 -> 0.77787483 | F21: =F6/F20 -> 0.37928209 | H21: =H6/H20 -> 1.9244091 | I21: =I6/I20 -> 1.742255 | J21: =J6/J20 -> 1.589128 | K21: =K6/K20 -> 1.4533723 | L21: =L6/L20 -> 1.2547509 | M21: =M6/M20 -> 1.1087687 | N21: =N6/N20 -> 0.96656899 | O21: =O6/O20 -> 0.77787483 | ... U21: =U6/U20 -> 0.24467747 | W21: =W6/W20 -> 1.4533723 | X21: =X6/X20 -> 1.2547509 | Y21: =Y6/Y20 -> 1.1087687 | Z21: =Z6/Z20 -> 0.96656899 | AA21: =AA6/AA20 -> 0.77787483 | AB21: =AB6/AB20 -> 1.0670601 | AC21: =AC6/AC20 -> 0.78509126 | AD21: =AD6/AD20 -> 0.17227407 | ... AG21: =AG6/AG20 -> 0.24467747
