Workbook

Sheet Historical Financials
B2: Best Buy Co Inc (NASDAQ: BBY)
B3: Historical Financials
B4: $ in thousands except per share
A6: X | B6: Income Statement | C6: FYE | D6: FYE | E6: FYE | I6: Quarterly | S6: Quarterly | AD6: LTM | AJ6: Variance
B7: Fiscal Period | C7: 2020 | D7: 2021 | E7: 2022 | F7: 2023 | G7: 2024 | I7: 1Q22 | J7: 2Q22 | K7: 3Q22 | L7: 4Q22 | M7: 1Q23 | N7: 2Q23 | O7: 3Q23 | P7: 4Q23 | Q7: 1Q24 | R7: 2Q24 | S7: 3Q24 | T7: 4Q24 | U7: 1Q25 | V7: 2Q25 | X7: =L7 -> 4Q22 | Y7: =M7 -> 1Q23 | Z7: =N7 -> 2Q23 | AA7: =O7 -> 3Q23 | AB7: =P7 -> 4Q23 | AC7: =Q7 -> 1Q24 | AD7: =R7 -> 2Q24 | AE7: =S7 -> 3Q24 | ... AH7: =V7 -> 2Q25
B8: Fiscal Period End Date | C8: 44196 | D8: 44561 | E8: 44926 | F8: 45291 | G8: 45657 | I8: 44651 | J8: 44742 | K8: 44834 | L8: 44926 | M8: 45016 | N8: 45107 | O8: 45199 | P8: 45291 | Q8: 45382 | R8: 45473 | S8: 45565 | T8: 45657 | U8: 45747 | V8: 45838 | X8: =L8 -> 44926 | Y8: =M8 -> 45016 | Z8: =N8 -> 45107 | AA8: =O8 -> 45199 | AB8: =P8 -> 45291 | AC8: =Q8 -> 45382 | AD8: =R8 -> 45473 | AE8: =S8 -> 45565 | ... AH8: =V8 -> 45838
B10: Consolidated Revenue | C10: 43638 | D10: 47262 | E10: 51761 | F10: 46298 | G10: 43452 | L10: =SUM(E10-SUM(I10:K10)) -> 51761 | P10: =SUM(F10-SUM(M10:O10)) -> 46298 | T10: =SUM(G10-SUM(Q10:S10)) -> 43452 | X10: =SUM(I10:L10) -> 51761 | Y10: =SUM(J10:M10) -> 51761 | Z10: =SUM(K10:N10) -> 51761 | AA10: =SUM(L10:O10) -> 51761 | AB10: =SUM(M10:P10) -> 46298 | AC10: =SUM(N10:Q10) -> 46298 | AD10: =SUM(O10:R10) -> 46298 | AE10: =SUM(P10:S10) -> 46298 | ... AH10: =SUM(S10:V10) -> 43452 | AJ10: =SUM(AH10/AD10)-1 -> -0.061471338
B11: Total Revenue | C11: =+SUM(C10:C10) -> 43638 | D11: =+SUM(D10:D10) -> 47262 | E11: =+SUM(E10:E10) -> 51761 | F11: =+SUM(F10:F10) -> 46298 | G11: =+SUM(G10:G10) -> 43452 | I11: =+SUM(I10:I10) -> 0 | J11: =+SUM(J10:J10) -> 0 | K11: =+SUM(K10:K10) -> 0 | L11: =+SUM(L10:L10) -> 51761 | M11: =+SUM(M10:M10) -> 0 | N11: =+SUM(N10:N10) -> 0 | O11: =+SUM(O10:O10) -> 0 | P11: =+SUM(P10:P10) -> 46298 | ... V11: =+SUM(V10:V10) -> 0 | X11: =+SUM(X10:X10) -> 51761 | Y11: =+SUM(Y10:Y10) -> 51761 | Z11: =+SUM(Z10:Z10) -> 51761 | AA11: =+SUM(AA10:AA10) -> 51761 | AB11: =+SUM(AB10:AB10) -> 46298 | AC11: =+SUM(AC10:AC10) -> 46298 | AD11: =+SUM(AD10:AD10) -> 46298 | AE11: =+SUM(AE10:AE10) -> 46298 | ... AH11: =+SUM(AH10:AH10) -> 43452 | AJ11: =SUM(AH11/AD11)-1 -> -0.061471338
B13: Cost of Sales | C13: 33590 | D13: 36689 | E13: 40121 | F13: 36386 | G13: 33849 | L13: =SUM(E13-SUM(I13:K13)) -> 40121 | P13: =SUM(F13-SUM(M13:O13)) -> 36386 | T13: =SUM(G13-SUM(Q13:S13)) -> 33849 | X13: =SUM(J13:M13) -> 40121 | Y13: =SUM(K13:N13) -> 40121 | Z13: =SUM(L13:O13) -> 40121 | AA13: =SUM(M13:P13) -> 36386 | AB13: =SUM(N13:Q13) -> 36386 | AC13: =SUM(O13:R13) -> 36386 | AD13: =SUM(O13:R13) -> 36386 | AE13: =SUM(P13:S13) -> 36386 | AF13: =SUM(Q13:T13) -> 33849 | AG13: =SUM(R13:U13) -> 33849 | AH13: =SUM(S13:V13) -> 33849 | AJ13: =SUM(AH13/AD13)-1 -> -0.069724619
B14: Gross Profit | C14: =+SUM(C11+SUM(C13:C13)) -> 77228 | D14: =+SUM(D11+SUM(D13:D13)) -> 83951 | E14: =+SUM(E11+SUM(E13:E13)) -> 91882 | F14: =+SUM(F11+SUM(F13:F13)) -> 82684 | G14: =+SUM(G11+SUM(G13:G13)) -> 77301 | I14: =+SUM(I11+SUM(I13:I13)) -> 0 | J14: =+SUM(J11+SUM(J13:J13)) -> 0 | K14: =+SUM(K11+SUM(K13:K13)) -> 0 | L14: =+SUM(L11+SUM(L13:L13)) -> 91882 | M14: =+SUM(M11+SUM(M13:M13)) -> 0 | N14: =+SUM(N11+SUM(N13:N13)) -> 0 | O14: =+SUM(O11+SUM(O13:O13)) -> 0 | P14: =+SUM(P11+SUM(P13:P13)) -> 82684 | ... V14: =+SUM(V11+SUM(V13:V13)) -> 0 | X14: =+SUM(X11+SUM(X13:X13)) -> 91882 | Y14: =+SUM(Y11+SUM(Y13:Y13)) -> 91882 | Z14: =+SUM(Z11+SUM(Z13:Z13)) -> 91882 | AA14: =+SUM(AA11+SUM(AA13:AA13)) -> 88147 | AB14: =+SUM(AB11+SUM(AB13:AB13)) -> 82684 | AC14: =+SUM(AC11+SUM(AC13:AC13)) -> 82684 | AD14: =+SUM(AD11+SUM(AD13:AD13)) -> 82684 | AE14: =+SUM(AE11+SUM(AE13:AE13)) -> 82684 | ... AH14: =+SUM(AH11+SUM(AH13:AH13)) -> 77301 | AJ14: =SUM(AH14/AD14)-1 -> -0.065103285
B15: Gross Margin (%) | C15: =C14/C11 -> 1.769742 | D15: =D14/D11 -> 1.7762896 | E15: =E14/E11 -> 1.7751203 | F15: =F14/F11 -> 1.7859087 | G15: =G14/G11 -> 1.7789975 | I15: =I14/I11 -> #DIV/0! | J15: =J14/J11 -> #DIV/0! | K15: =K14/K11 -> #DIV/0! | L15: =L14/L11 -> 1.7751203 | M15: =M14/M11 -> #DIV/0! | N15: =N14/N11 -> #DIV/0! | O15: =O14/O11 -> #DIV/0! | P15: =P14/P11 -> 1.7859087 | ... V15: =V14/V11 -> #DIV/0! | X15: =X14/X11 -> 1.7751203 | Y15: =Y14/Y11 -> 1.7751203 | Z15: =Z14/Z11 -> 1.7751203 | AA15: =AA14/AA11 -> 1.7029617 | AB15: =AB14/AB11 -> 1.7859087 | AC15: =AC14/AC11 -> 1.7859087 | AD15: =AD14/AD11 -> 1.7859087 | AE15: =AE14/AE11 -> 1.7859087 | ... AH15: =AH14/AH11 -> 1.7789975 | AJ15: =SUM(AH15-AD15)*1000 -> -6.9111641
B17: Selling, general and administrative expenses | C17: 7998 | D17: 7928 | E17: 8635 | F17: 7970 | G17: 7876 | L17: =SUM(E17-SUM(I17:K17)) -> 8635 | P17: =SUM(F17-SUM(M17:O17)) -> 7970 | T17: =SUM(G17-SUM(Q17:S17)) -> 7876 | X17: =SUM(J17:M17) -> 8635 | Y17: =SUM(K17:N17) -> 8635 | Z17: =SUM(L17:O17) -> 8635 | AA17: =SUM(M17:P17) -> 7970 | AB17: =SUM(N17:Q17) -> 7970 | AC17: =SUM(O17:R17) -> 7970 | AD17: =SUM(O17:R17) -> 7970 | AE17: =SUM(P17:S17) -> 7970 | AF17: =SUM(Q17:T17) -> 7876 | AG17: =SUM(R17:U17) -> 7876 | AH17: =SUM(S17:V17) -> 7876 | AJ17: =SUM(AH17/AD17)-1 -> -0.011794228
B18: Restructuring charges | C18: 41 | D18: 254 | E18: -34 | F18: 147 | G18: 153 | L18: =SUM(E18-SUM(I18:K18)) -> -34 | P18: =SUM(F18-SUM(M18:O18)) -> 147 | T18: =SUM(G18-SUM(Q18:S18)) -> 153 | X18: =SUM(J18:M18) -> -34 | Y18: =SUM(K18:N18) -> -34 | Z18: =SUM(L18:O18) -> -34 | AA18: =SUM(M18:P18) -> 147 | AB18: =SUM(N18:Q18) -> 147 | AC18: =SUM(O18:R18) -> 147 | AD18: =SUM(O18:R18) -> 147 | AE18: =SUM(P18:S18) -> 147 | AF18: =SUM(Q18:T18) -> 153 | AG18: =SUM(R18:U18) -> 153 | AH18: =SUM(S18:V18) -> 153 | AJ18: =SUM(AH18/AD18)-1 -> 0.040816327
B19: Operating Profit | C19: =+SUM(C14+SUM(C17:C18)) -> 85267 | D19: =+SUM(D14+SUM(D17:D18)) -> 92133 | E19: =+SUM(E14+SUM(E17:E18)) -> 100483 | F19: =+SUM(F14+SUM(F17:F18)) -> 90801 | G19: =+SUM(G14+SUM(G17:G18)) -> 85330 | I19: =+SUM(I14+SUM(I17:I18)) -> 0 | J19: =+SUM(J14+SUM(J17:J18)) -> 0 | K19: =+SUM(K14+SUM(K17:K18)) -> 0 | L19: =+SUM(L14+SUM(L17:L18)) -> 100483 | M19: =+SUM(M14+SUM(M17:M18)) -> 0 | N19: =+SUM(N14+SUM(N17:N18)) -> 0 | O19: =+SUM(O14+SUM(O17:O18)) -> 0 | P19: =+SUM(P14+SUM(P17:P18)) -> 90801 | ... V19: =+SUM(V14+SUM(V17:V18)) -> 0 | X19: =+SUM(X14+SUM(X17:X18)) -> 100483 | Y19: =+SUM(Y14+SUM(Y17:Y18)) -> 100483 | Z19: =+SUM(Z14+SUM(Z17:Z18)) -> 100483 | AA19: =+SUM(AA14+SUM(AA17:AA18)) -> 96264 | AB19: =+SUM(AB14+SUM(AB17:AB18)) -> 90801 | AC19: =+SUM(AC14+SUM(AC17:AC18)) -> 90801 | AD19: =+SUM(AD14+SUM(AD17:AD18)) -> 90801 | AE19: =+SUM(AE14+SUM(AE17:AE18)) -> 90801 | ... AH19: =+SUM(AH14+SUM(AH17:AH18)) -> 85330 | AJ19: =SUM(AH19/AD19)-1 -> -0.06025264
B20: Operating Margin (%) | C20: =C19/C11 -> 1.9539621 | D20: =D19/D11 -> 1.9494097 | E20: =E19/E11 -> 1.9412878 | F20: =F19/F11 -> 1.9612294 | G20: =G19/G11 -> 1.9637761 | I20: =I19/I11 -> #DIV/0! | J20: =J19/J11 -> #DIV/0! | K20: =K19/K11 -> #DIV/0! | L20: =L19/L11 -> 1.9412878 | M20: =M19/M11 -> #DIV/0! | N20: =N19/N11 -> #DIV/0! | O20: =O19/O11 -> #DIV/0! | P20: =P19/P11 -> 1.9612294 | ... V20: =V19/V11 -> #DIV/0! | X20: =X19/X11 -> 1.9412878 | Y20: =Y19/Y11 -> 1.9412878 | Z20: =Z19/Z11 -> 1.9412878 | AA20: =AA19/AA11 -> 1.8597786 | AB20: =AB19/AB11 -> 1.9612294 | AC20: =AC19/AC11 -> 1.9612294 | AD20: =AD19/AD11 -> 1.9612294 | AE20: =AE19/AE11 -> 1.9612294 | ... AH20: =AH19/AH11 -> 1.9637761 | AJ20: =SUM(AH20-AD20)*1000 -> 2.546694
B22: Gain on sale of subsidiary, net | C22: 1 | D22: 1 | G22: 21 | L22: =SUM(E22-SUM(I22:K22)) -> #VALUE! | P22: =SUM(F22-SUM(M22:O22)) -> #VALUE! | T22: =SUM(G22-SUM(Q22:S22)) -> 21 | X22: =SUM(J22:M22) -> #VALUE! | Y22: =SUM(K22:N22) -> #VALUE! | Z22: =SUM(L22:O22) -> #VALUE! | AA22: =SUM(M22:P22) -> #VALUE! | AB22: =SUM(N22:Q22) -> #VALUE! | AC22: =SUM(O22:R22) -> #VALUE! | AD22: =SUM(O22:R22) -> #VALUE! | AE22: =SUM(P22:S22) -> #VALUE! | AF22: =SUM(Q22:T22) -> 21 | AG22: =SUM(R22:U22) -> 21 | AH22: =SUM(S22:V22) -> 21 | AJ22: =SUM(AH22/AD22)-1 -> #VALUE!
B23: Investment income and other | C23: 47 | D23: 37 | E23: 10 | F23: 28 | G23: 78 | L23: =SUM(E23-SUM(I23:K23)) -> 10 | P23: =SUM(F23-SUM(M23:O23)) -> 28 | T23: =SUM(G23-SUM(Q23:S23)) -> 78 | AD23: =SUM(O23:R23) -> 28 | AE23: =SUM(P23:S23) -> 28 | AF23: =SUM(Q23:T23) -> 78 | AG23: =SUM(R23:U23) -> 78 | AH23: =SUM(S23:V23) -> 78 | AJ23: =SUM(AH23/AD23)-1 -> 1.7857143
B24: Interest expense | C24: -64 | D24: -52 | E24: -25 | F24: -35 | G24: -52 | L24: =SUM(E24-SUM(I24:K24)) -> -25 | P24: =SUM(F24-SUM(M24:O24)) -> -35 | T24: =SUM(G24-SUM(Q24:S24)) -> -52 | AD24: =SUM(O24:R24) -> -35 | AE24: =SUM(P24:S24) -> -35 | AF24: =SUM(Q24:T24) -> -52 | AG24: =SUM(R24:U24) -> -52 | AH24: =SUM(S24:V24) -> -52 | AJ24: =SUM(AH24/AD24)-1 -> 0.48571429
B25: Earnings before income tax expense and equity in income of affiliates | C25: 1993 | D25: 2377 | E25: 3024 | F25: 1788 | G25: 1621 | L25: =SUM(E25-SUM(I25:K25)) -> 3024 | P25: =SUM(F25-SUM(M25:O25)) -> 1788 | T25: =SUM(G25-SUM(Q25:S25)) -> 1621 | AD25: =SUM(O25:R25) -> 1788 | AE25: =SUM(P25:S25) -> 1788 | AF25: =SUM(Q25:T25) -> 1621 | AG25: =SUM(R25:U25) -> 1621 | AH25: =SUM(S25:V25) -> 1621 | AJ25: =SUM(AH25/AD25)-1 -> -0.093400447
B26: Income tax expense | C26: 452 | D26: 579 | E26: 574 | F26: 370 | G26: 381 | L26: =SUM(E26-SUM(I26:K26)) -> 574 | P26: =SUM(F26-SUM(M26:O26)) -> 370
B27: Equity in income of affiliates | E27: 4 | F27: 1 | G27: 1 | L27: =SUM(E27-SUM(I27:K27)) -> 4 | P27: =SUM(F27-SUM(M27:O27)) -> 1
B28: Earning Before Taxes | C28: =SUM(C19+SUM(C22:C27)) -> 87696 | D28: =SUM(D19+SUM(D22:D27)) -> 95075 | E28: =SUM(E19+SUM(E22:E27)) -> 104070 | F28: =SUM(F19+SUM(F22:F27)) -> 92953 | G28: =SUM(G19+SUM(G22:G27)) -> 87380 | I28: =SUM(I19+SUM(I22:I27)) -> 0 | J28: =SUM(J19+SUM(J22:J27)) -> 0 | K28: =SUM(K19+SUM(K22:K27)) -> 0 | L28: =SUM(L19+SUM(L22:L27)) -> #VALUE! | M28: =SUM(M19+SUM(M22:M27)) -> 0 | N28: =SUM(N19+SUM(N22:N27)) -> 0 | O28: =SUM(O19+SUM(O22:O27)) -> 0 | P28: =SUM(P19+SUM(P22:P27)) -> #VALUE! | ... V28: =SUM(V19+SUM(V22:V27)) -> 0 | X28: =SUM(X19+SUM(X22:X27)) -> #VALUE! | Y28: =SUM(Y19+SUM(Y22:Y27)) -> #VALUE! | Z28: =SUM(Z19+SUM(Z22:Z27)) -> #VALUE! | AA28: =SUM(AA19+SUM(AA22:AA27)) -> #VALUE! | AB28: =SUM(AB19+SUM(AB22:AB27)) -> #VALUE! | AC28: =SUM(AC19+SUM(AC22:AC27)) -> #VALUE! | AD28: =SUM(AD19+SUM(AD22:AD27)) -> #VALUE! | AE28: =SUM(AE19+SUM(AE22:AE27)) -> #VALUE! | ... AH28: =SUM(AH19+SUM(AH22:AH27)) -> 86998 | AJ28: =SUM(AH28/AD28)-1 -> #VALUE!
B29: EBT Margin (%) | C29: =C28/C11 -> 2.0096246 | D29: =D28/D11 -> 2.0116584 | E29: =E28/E11 -> 2.0105871 | F29: =F28/F11 -> 2.0077109 | G29: =G28/G11 -> 2.0109546 | I29: =I28/I11 -> #DIV/0! | J29: =J28/J11 -> #DIV/0! | K29: =K28/K11 -> #DIV/0! | L29: =L28/L11 -> #VALUE! | M29: =M28/M11 -> #DIV/0! | N29: =N28/N11 -> #DIV/0! | O29: =O28/O11 -> #DIV/0! | P29: =P28/P11 -> #VALUE! | ... V29: =V28/V11 -> #DIV/0! | X29: =X28/X11 -> #VALUE! | Y29: =Y28/Y11 -> #VALUE! | Z29: =Z28/Z11 -> #VALUE! | AA29: =AA28/AA11 -> #VALUE! | AB29: =AB28/AB11 -> #VALUE! | AC29: =AC28/AC11 -> #VALUE! | AD29: =AD28/AD11 -> #VALUE! | AE29: =AE28/AE11 -> #VALUE! | ... AH29: =AH28/AH11 -> 2.0021633 | AJ29: =SUM(AH29-AD29)*1000 -> #VALUE!
B31: Provision for taxes | C31: 0 | D31: 0 | E31: 0 | F31: 0 | G31: 0 | I31: 0 | J31: 0 | K31: 0 | L31: =SUM(E31-SUM(I31:K31)) -> 0 | M31: 0 | N31: 0 | O31: 0 | P31: =SUM(F31-SUM(M31:O31)) -> 0 | Q31: 0 | R31: 0 | S31: 0 | T31: =SUM(G31-SUM(Q31:S31)) -> 0 | U31: 0 | X31: =SUM(J31:M31) -> 0 | Y31: =SUM(K31:N31) -> 0 | Z31: =SUM(L31:O31) -> 0 | AA31: =SUM(M31:P31) -> 0 | AB31: =SUM(N31:Q31) -> 0 | AC31: =SUM(O31:R31) -> 0 | AD31: =SUM(O31:R31) -> 0 | AE31: =SUM(P31:S31) -> 0 | AF31: =SUM(Q31:T31) -> 0 | AG31: =SUM(R31:U31) -> 0 | AH31: =SUM(S31:V31) -> 0 | AJ31: =SUM(AH31/AD31)-1 -> #DIV/0!
B32: Net loss | C32: =SUM(C28+C31) -> 87696 | D32: =SUM(D28+D31) -> 95075 | E32: =SUM(E28+E31) -> 104070 | F32: =SUM(F28+F31) -> 92953 | G32: =SUM(G28+G31) -> 87380 | I32: =SUM(I28+I31) -> 0 | J32: =SUM(J28+J31) -> 0 | K32: =SUM(K28+K31) -> 0 | L32: =SUM(L28+L31) -> #VALUE! | M32: =SUM(M28+M31) -> 0 | N32: =SUM(N28+N31) -> 0 | O32: =SUM(O28+O31) -> 0 | P32: =SUM(P28+P31) -> #VALUE! | ... V32: =SUM(V28+V31) -> 0 | X32: =SUM(X28+X31) -> #VALUE! | Y32: =SUM(Y28+Y31) -> #VALUE! | Z32: =SUM(Z28+Z31) -> #VALUE! | AA32: =SUM(AA28+AA31) -> #VALUE! | AB32: =SUM(AB28+AB31) -> #VALUE! | AC32: =SUM(AC28+AC31) -> #VALUE! | AD32: =SUM(AD28+AD31) -> #VALUE! | AE32: =SUM(AE28+AE31) -> #VALUE! | ... AH32: =SUM(AH28+AH31) -> 86998 | AJ32: =SUM(AH32/AD32)-1 -> #VALUE!
B33: Net Margin (%) | C33: =C32/C11 -> 2.0096246 | D33: =D32/D11 -> 2.0116584 | E33: =E32/E11 -> 2.0105871 | F33: =F32/F11 -> 2.0077109 | G33: =G32/G11 -> 2.0109546 | I33: =I32/I11 -> #DIV/0! | J33: =J32/J11 -> #DIV/0! | K33: =K32/K11 -> #DIV/0! | L33: =L32/L11 -> #VALUE! | M33: =M32/M11 -> #DIV/0! | N33: =N32/N11 -> #DIV/0! | O33: =O32/O11 -> #DIV/0! | P33: =P32/P11 -> #VALUE! | ... V33: =V32/V11 -> #DIV/0! | X33: =X32/X11 -> #VALUE! | Y33: =Y32/Y11 -> #VALUE! | Z33: =Z32/Z11 -> #VALUE! | AA33: =AA32/AA11 -> #VALUE! | AB33: =AB32/AB11 -> #VALUE! | AC33: =AC32/AC11 -> #VALUE! | AD33: =AD32/AD11 -> #VALUE! | AE33: =AE32/AE11 -> #VALUE! | ... AH33: =AH32/AH11 -> 2.0021633 | AJ33: =SUM(AH33-AD33)*1000 -> #VALUE!
B35: Basic shares | C35: 264.9 | D35: 259.6 | E35: 246.8 | F35: 224.8 | G35: 217.7 | L35: =E35 -> 246.8 | P35: =F35 -> 224.8 | T35: =G35 -> 217.7 | X35: =L35 -> 246.8 | Y35: =M35 -> 0 | Z35: =N35 -> 0 | AA35: =O35 -> 0 | AB35: =P35 -> 224.8 | AC35: =Q35 -> 0 | AD35: =R35 -> 0 | AE35: =S35 -> 0 | ... AH35: =V35 -> 0 | AJ35: =SUM(AH35/AD35)-1 -> #DIV/0!
B36: Basic EPS | C36: =C32/C35 -> 331.05323 | D36: =D32/D35 -> 366.23652 | E36: =E32/E35 -> 421.67747 | F36: =F32/F35 -> 413.49199 | G36: =G32/G35 -> 401.37804 | I36: =I32/I35 -> #DIV/0! | J36: =J32/J35 -> #DIV/0! | K36: =K32/K35 -> #DIV/0! | L36: =L32/L35 -> #VALUE! | M36: =M32/M35 -> #DIV/0! | N36: =N32/N35 -> #DIV/0! | O36: =O32/O35 -> #DIV/0! | P36: =P32/P35 -> #VALUE! | ... V36: =V32/V35 -> #DIV/0! | X36: =X32/X35 -> #VALUE! | Y36: =Y32/Y35 -> #VALUE! | Z36: =Z32/Z35 -> #VALUE! | AA36: =AA32/AA35 -> #VALUE! | AB36: =AB32/AB35 -> #VALUE! | AC36: =AC32/AC35 -> #VALUE! | AD36: =AD32/AD35 -> #VALUE! | AE36: =AE32/AE35 -> #VALUE! | ... AH36: =AH32/AH35 -> #DIV/0! | AJ36: =SUM(AH36/AD36)-1 -> #DIV/0!
B38: Fully Diluted Shares | C38: 268.1 | D38: 263 | E38: 249.3 | F38: 225.7 | G38: 218.5 | L38: =E38 -> 249.3 | P38: =F38 -> 225.7 | T38: =G38 -> 218.5 | X38: =M38 -> 0 | Y38: =N38 -> 0 | Z38: =O38 -> 0 | AA38: =P38 -> 225.7 | AB38: =Q38 -> 0 | AC38: =R38 -> 0 | AD38: =R38 -> 0 | AE38: =S38 -> 0 | AF38: =T38 -> 218.5 | AG38: =U38 -> 0 | AH38: =V38 -> 0 | AJ38: =SUM(AH38/AD38)-1 -> #DIV/0!
B39: Diluted EPS | C39: =C32/C38 -> 327.10183 | D39: =D32/D38 -> 361.5019 | E39: =E32/E38 -> 417.44886 | F39: =F32/F38 -> 411.84315 | G39: =G32/G38 -> 399.90847 | I39: =I32/I38 -> #DIV/0! | J39: =J32/J38 -> #DIV/0! | K39: =K32/K38 -> #DIV/0! | L39: =L32/L38 -> #VALUE! | M39: =M32/M38 -> #DIV/0! | N39: =N32/N38 -> #DIV/0! | O39: =O32/O38 -> #DIV/0! | P39: =P32/P38 -> #VALUE! | ... V39: =V32/V38 -> #DIV/0! | X39: =X32/X38 -> #VALUE! | Y39: =Y32/Y38 -> #VALUE! | Z39: =Z32/Z38 -> #VALUE! | AA39: =AA32/AA38 -> #VALUE! | AB39: =AB32/AB38 -> #VALUE! | AC39: =AC32/AC38 -> #VALUE! | AD39: =AD32/AD38 -> #VALUE! | AE39: =AE32/AE38 -> #VALUE! | ... AH39: =AH32/AH38 -> #DIV/0! | AJ39: =SUM(AH39/AD39)-1 -> #DIV/0!
A41: X | B41: Balance Sheet | C41: FYE | D41: FYE | E41: FYE | I41: Quarterly | S41: Quarterly | AD41: LTM | AJ41: Variance
B42: =B7 -> Fiscal Period | C42: =C7 -> 2020 | D42: =D7 -> 2021 | E42: =E7 -> 2022 | F42: =F7 -> 2023 | G42: =G7 -> 2024 | I42: =I7 -> 1Q22 | J42: =J7 -> 2Q22 | K42: =K7 -> 3Q22 | L42: =L7 -> 4Q22 | M42: =M7 -> 1Q23 | N42: =N7 -> 2Q23 | O42: =O7 -> 3Q23 | P42: =P7 -> 4Q23 | ... V42: =V7 -> 2Q25 | X42: =X7 -> 4Q22 | Y42: =Y7 -> 1Q23 | Z42: =Z7 -> 2Q23 | AA42: =AA7 -> 3Q23 | AB42: =AB7 -> 4Q23 | AC42: =AC7 -> 1Q24 | AD42: =AD7 -> 2Q24 | AE42: =AE7 -> 3Q24 | ... AH42: =AH7 -> 2Q25
B43: =B8 -> Fiscal Period End Date | C43: =C8 -> 44196 | D43: =D8 -> 44561 | E43: =E8 -> 44926 | F43: =F8 -> 45291 | G43: =G8 -> 45657 | I43: =I8 -> 44651 | J43: =J8 -> 44742 | K43: =K8 -> 44834 | L43: =L8 -> 44926 | M43: =M8 -> 45016 | N43: =N8 -> 45107 | O43: =O8 -> 45199 | P43: =P8 -> 45291 | ... V43: =V8 -> 45838 | X43: =X8 -> 44926 | Y43: =Y8 -> 45016 | Z43: =Z8 -> 45107 | AA43: =AA8 -> 45199 | AB43: =AB8 -> 45291 | AC43: =AC8 -> 45382 | AD43: =AD8 -> 45473 | AE43: =AE8 -> 45565 | ... AH43: =AH8 -> 45838
B45: Current Assets
B46: Cash and cash equivalents | C46: 2229 | D46: 5494 | E46: 2936 | F46: 1874 | G46: 1447 | L46: =E46 -> 2936 | P46: =F46 -> 1874 | T46: =G46 -> 1447 | X46: =L46 -> 2936 | Y46: =M46 -> 0 | Z46: =N46 -> 0 | AA46: =O46 -> 0 | AB46: =P46 -> 1874 | AC46: =Q46 -> 0 | AD46: =R46 -> 0 | AE46: =S46 -> 0 | ... AH46: =V46 -> 0 | AJ46: =SUM(AH46/AD46)-1 -> #DIV/0!
B47: Receivables, net | C47: 1149 | D47: 1061 | E47: 1042 | F47: 1141 | G47: 939 | L47: =E47 -> 1042 | P47: =F47 -> 1141 | T47: =G47 -> 939 | X47: =L47 -> 1042 | Y47: =M47 -> 0 | Z47: =N47 -> 0 | AA47: =O47 -> 0 | AB47: =P47 -> 1141 | AC47: =Q47 -> 0 | AD47: =R47 -> 0 | AE47: =S47 -> 0 | ... AH47: =V47 -> 0 | AJ47: =SUM(AH47/AD47)-1 -> #DIV/0!
B48: Merchandise inventories | C48: 5174 | D48: 5612 | E48: 5965 | F48: 5140 | G48: 4958 | L48: =E48 -> 5965 | P48: =F48 -> 5140 | T48: =G48 -> 4958 | X48: =L48 -> 5965 | Y48: =M48 -> 0 | Z48: =N48 -> 0 | AA48: =O48 -> 0 | AB48: =P48 -> 5140 | AC48: =Q48 -> 0 | AD48: =R48 -> 0 | AE48: =S48 -> 0 | ... AH48: =V48 -> 0 | AJ48: =SUM(AH48/AD48)-1 -> #DIV/0!
B49: Other current assets | C49: 305 | D49: 373 | E49: 596 | F49: 647 | G49: 553 | L49: =E49 -> 596 | P49: =F49 -> 647 | T49: =G49 -> 553 | X49: =L49 -> 596 | Y49: =M49 -> 0 | Z49: =N49 -> 0 | AA49: =O49 -> 0 | AB49: =P49 -> 647 | AC49: =Q49 -> 0 | AD49: =R49 -> 0 | AE49: =S49 -> 0 | ... AH49: =V49 -> 0 | AJ49: =SUM(AH49/AD49)-1 -> #DIV/0!
B50: Total Current Assets | C50: =SUM(C46:C49) -> 8857 | D50: =SUM(D46:D49) -> 12540 | E50: =SUM(E46:E49) -> 10539 | F50: =SUM(F46:F49) -> 8802 | G50: =SUM(G46:G49) -> 7897 | I50: =SUM(I46:I49) -> 0 | J50: =SUM(J46:J49) -> 0 | K50: =SUM(K46:K49) -> 0 | L50: =SUM(L46:L49) -> 10539 | M50: =SUM(M46:M49) -> 0 | N50: =SUM(N46:N49) -> 0 | O50: =SUM(O46:O49) -> 0 | P50: =SUM(P46:P49) -> 8802 | ... V50: =SUM(V46:V49) -> 0 | X50: =SUM(X46:X49) -> 10539 | Y50: =SUM(Y46:Y49) -> 0 | Z50: =SUM(Z46:Z49) -> 0 | AA50: =SUM(AA46:AA49) -> 0 | AB50: =SUM(AB46:AB49) -> 8802 | AC50: =SUM(AC46:AC49) -> 0 | AD50: =SUM(AD46:AD49) -> 0 | AE50: =SUM(AE46:AE49) -> 0 | ... AH50: =SUM(AH46:AH49) -> 0 | AJ50: =SUM(AH50/AD50)-1 -> #DIV/0!
B52: Non-Current Assets
...

Sheet Revenue Drivers
B2: Best Buy Co Inc (BBY) | H2: Quarterly | P2: Quarterly | Q2: Quarterly | W2: LTM | AA2: LTM | AC2: LTM
B3: Segment Anaysis | C3: ='Historical Financials'!#REF! -> #REF! | D3: ='Historical Financials'!E7 -> 2022 | E3: ='Historical Financials'!F7 -> 2023 | F3: ='Historical Financials'!G7 -> 2024 | H3: ='Historical Financials'!I7 -> 1Q22 | I3: ='Historical Financials'!J7 -> 2Q22 | J3: ='Historical Financials'!K7 -> 3Q22 | K3: ='Historical Financials'!L7 -> 4Q22 | L3: ='Historical Financials'!M7 -> 1Q23 | M3: ='Historical Financials'!N7 -> 2Q23 | N3: ='Historical Financials'!O7 -> 3Q23 | O3: ='Historical Financials'!P7 -> 4Q23 | ... U3: ='Historical Financials'!V7 -> 2Q25 | W3: =L3 -> 1Q23 | X3: =M3 -> 2Q23 | Y3: =N3 -> 3Q23 | Z3: =O3 -> 4Q23 | AA3: =P3 -> 1Q24 | AB3: =Q3 -> 2Q24 | AC3: =S3 -> 4Q24 | AD3: =T3 -> 1Q25 | AE3: =U3 -> 2Q25 | AF3: =#REF! -> #REF!
B4: $ in thousands except per share | C4: ='Historical Financials'!#REF! -> #REF! | D4: ='Historical Financials'!E8 -> 44926 | E4: ='Historical Financials'!F8 -> 45291 | F4: ='Historical Financials'!G8 -> 45657 | H4: ='Historical Financials'!I8 -> 44651 | I4: ='Historical Financials'!J8 -> 44742 | J4: ='Historical Financials'!K8 -> 44834 | K4: ='Historical Financials'!L8 -> 44926 | L4: ='Historical Financials'!M8 -> 45016 | M4: ='Historical Financials'!N8 -> 45107 | N4: ='Historical Financials'!O8 -> 45199 | O4: ='Historical Financials'!P8 -> 45291 | ... U4: ='Historical Financials'!V8 -> 45838 | W4: =L4 -> 45016 | X4: =M4 -> 45107 | Y4: =N4 -> 45199 | Z4: =O4 -> 45291 | AA4: =P4 -> 45382 | AB4: =Q4 -> 45473 | AC4: =S4 -> 45657 | AD4: =T4 -> 45747 | AE4: =U4 -> 45838 | AF4: =#REF! -> #REF!
A6: X | B6: Net Revenues by Channel
W7: =SUM(I7:L7) -> 0 | X7: =SUM(J7:M7) -> 0 | Y7: =SUM(K7:N7) -> 0 | Z7: =SUM(L7:O7) -> 0 | AA7: =SUM(M7:P7) -> 0 | AB7: =SUM(N7:Q7) -> 0 | AC7: =SUM(P7:S7) -> 0 | AD7: =SUM(Q7:T7) -> 0 | AE7: =SUM(R7:U7) -> 0 | AF7: =SUM(S7:U7) -> 0
W8: =SUM(I8:L8) -> 0 | X8: =SUM(J8:M8) -> 0 | Y8: =SUM(K8:N8) -> 0 | Z8: =SUM(L8:O8) -> 0 | AA8: =SUM(M8:P8) -> 0 | AB8: =SUM(N8:Q8) -> 0 | AC8: =SUM(P8:S8) -> 0 | AD8: =SUM(Q8:T8) -> 0 | AE8: =SUM(R8:U8) -> 0 | AF8: =SUM(S8:U8) -> 0
B9: Total Net Revenue | D9: =SUM(D7:D8) -> 0 | E9: =SUM(E7:E8) -> 0 | F9: =SUM(F7:F8) -> 0 | P9: =SUM(P7:P8) -> 0 | Q9: =SUM(Q7:Q8) -> 0 | R9: =SUM(R7:R8) -> 0 | S9: =SUM(S7:S8) -> 0 | T9: =SUM(T7:T8) -> 0 | U9: =SUM(U7:U8) -> 0 | W9: =SUM(W7:W8) -> 0 | X9: =SUM(X7:X8) -> 0 | Y9: =SUM(Y7:Y8) -> 0 | Z9: =SUM(Z7:Z8) -> 0 | AA9: =SUM(AA7:AA8) -> 0 | AB9: =SUM(AB7:AB8) -> 0 | AC9: =SUM(AC7:AC8) -> 0 | AD9: =SUM(AD7:AD8) -> 0 | ... AF9: =SUM(AF7:AF8) -> 0
B10: Balance Check | D10: =+D9-'Historical Financials'!E11 -> -51761 | E10: =+E9-'Historical Financials'!F11 -> -46298 | F10: =+F9-'Historical Financials'!G11 -> -43452 | P10: =+P9-'Historical Financials'!Q11 -> 0 | Q10: =+Q9-'Historical Financials'!R11 -> 0 | R10: =+R9-'Historical Financials'!S11 -> 0 | S10: =+S9-'Historical Financials'!T11 -> -43452 | T10: =+T9-'Historical Financials'!U11 -> 0 | U10: =+U9-'Historical Financials'!V11 -> 0 | W10: =W9-'Historical Financials'!X11 -> -51761 | X10: =X9-'Historical Financials'!Y11 -> -51761 | Y10: =Y9-'Historical Financials'!Z11 -> -51761 | Z10: =Z9-'Historical Financials'!AA11 -> -51761 | AA10: =AA9-'Historical Financials'!AB11 -> -46298 | AB10: =AB9-'Historical Financials'!AC11 -> -46298 | AC10: =AC9-'Historical Financials'!AE11 -> -46298 | AD10: =AD9-'Historical Financials'!AF11 -> -43452 | AE10: =AE9-'Historical Financials'!AG11 -> -43452 | AF10: =AF9-'Historical Financials'!AH11 -> -43452
A12: X | B12: Revenue by Channel
W13: =SUM(I13:L13) -> 0 | X13: =SUM(J13:M13) -> 0 | Y13: =SUM(K13:N13) -> 0 | Z13: =SUM(L13:O13) -> 0 | AA13: =SUM(M13:P13) -> 0 | AB13: =SUM(N13:Q13) -> 0 | AC13: =SUM(P13:S13) -> 0 | AD13: =SUM(Q13:T13) -> 0 | AE13: =SUM(R13:U13) -> 0 | AF13: =SUM(S13:U13) -> 0
W14: =SUM(I14:L14) -> 0 | X14: =SUM(J14:M14) -> 0 | Y14: =SUM(K14:N14) -> 0 | Z14: =SUM(L14:O14) -> 0 | AA14: =SUM(M14:P14) -> 0 | AB14: =SUM(N14:Q14) -> 0 | AC14: =SUM(P14:S14) -> 0 | AD14: =SUM(Q14:T14) -> 0 | AE14: =SUM(R14:U14) -> 0 | AF14: =SUM(S14:U14) -> 0
B15: Total Net U.S Revenue | D15: =SUM(D13:D14) -> 0 | E15: =SUM(E13:E14) -> 0 | F15: =SUM(F13:F14) -> 0 | P15: =SUM(P13:P14) -> 0 | Q15: =SUM(Q13:Q14) -> 0 | R15: =SUM(R13:R14) -> 0 | S15: =SUM(S13:S14) -> 0 | T15: =SUM(T13:T14) -> 0 | U15: =SUM(U13:U14) -> 0 | W15: =SUM(W13:W14) -> 0 | X15: =SUM(X13:X14) -> 0 | Y15: =SUM(Y13:Y14) -> 0 | Z15: =SUM(Z13:Z14) -> 0 | AA15: =SUM(AA13:AA14) -> 0 | AB15: =SUM(AB13:AB14) -> 0 | AC15: =SUM(AC13:AC14) -> 0 | AD15: =SUM(AD13:AD14) -> 0 | ... AF15: =SUM(AF13:AF14) -> 0
B16: Balance Check | D16: =+D15-D9 -> 0 | E16: =+E15-E9 -> 0 | F16: =+F15-F9 -> 0 | P16: =+P15-P9 -> 0 | Q16: =+Q15-Q9 -> 0 | R16: =+R15-R9 -> 0 | S16: =+S15-S9 -> 0 | T16: =+T15-T9 -> 0 | U16: =+U15-U9 -> 0 | W16: =W15-'Historical Financials'!X17 -> -8635 | X16: =X15-'Historical Financials'!Y17 -> -8635 | Y16: =Y15-'Historical Financials'!Z17 -> -8635 | Z16: =Z15-'Historical Financials'!AA17 -> -7970 | AA16: =AA15-'Historical Financials'!AB17 -> -7970 | AB16: =AB15-'Historical Financials'!AC17 -> -7970 | AC16: =+AC15-AC9 -> 0 | AD16: =+AD15-AD9 -> 0 | AE16: =+AE15-AE9 -> 0 | AF16: =+AF15-AF9 -> 0

Sheet FCF
B2: Best Buy Co Inc (BBY) | D2: FYE | H2: Quarterly | Q2: Quarterly | R2: Quarterly | X2: LTM | AE2: LTM | AK2: Variance
B3: FCF Analysis | C3: ='Historical Financials'!#REF! -> #REF! | D3: ='Historical Financials'!E7 -> 2022 | E3: ='Historical Financials'!F7 -> 2023 | F3: ='Historical Financials'!G7 -> 2024 | H3: ='Historical Financials'!I7 -> 1Q22 | I3: ='Historical Financials'!J7 -> 2Q22 | J3: ='Historical Financials'!K7 -> 3Q22 | K3: ='Historical Financials'!L7 -> 4Q22 | L3: ='Historical Financials'!M7 -> 1Q23 | M3: ='Historical Financials'!N7 -> 2Q23 | N3: ='Historical Financials'!O7 -> 3Q23 | O3: ='Historical Financials'!P7 -> 4Q23 | ... U3: ='Historical Financials'!V7 -> 2Q25 | V3: ='Historical Financials'!#REF! -> #REF! | X3: =K3 -> 4Q22 | Y3: =L3 -> 1Q23 | Z3: =M3 -> 2Q23 | AA3: =N3 -> 3Q23 | AB3: =O3 -> 4Q23 | AC3: =P3 -> 1Q24 | AD3: =Q3 -> 2Q24 | AE3: =R3 -> 3Q24 | ... AI3: =V3 -> #REF!
B4: $ in thousands except per share | C4: ='Historical Financials'!#REF! -> #REF! | D4: ='Historical Financials'!E8 -> 44926 | E4: ='Historical Financials'!F8 -> 45291 | F4: ='Historical Financials'!G8 -> 45657 | H4: ='Historical Financials'!I8 -> 44651 | I4: ='Historical Financials'!J8 -> 44742 | J4: ='Historical Financials'!K8 -> 44834 | K4: ='Historical Financials'!L8 -> 44926 | L4: ='Historical Financials'!M8 -> 45016 | M4: ='Historical Financials'!N8 -> 45107 | N4: ='Historical Financials'!O8 -> 45199 | O4: ='Historical Financials'!P8 -> 45291 | ... U4: ='Historical Financials'!V8 -> 45838 | V4: ='Historical Financials'!#REF! -> #REF! | X4: =K4 -> 44926 | Y4: =L4 -> 45016 | Z4: =M4 -> 45107 | AA4: =N4 -> 45199 | AB4: =O4 -> 45291 | AC4: =P4 -> 45382 | AD4: =Q4 -> 45473 | AE4: =R4 -> 45565 | ... AI4: =V4 -> #REF!
P6: ='Revenue Drivers'!P7 -> 0 | Q6: ='Revenue Drivers'!Q7 -> 0 | AC6: =SUM(M6:P6) -> 0 | AD6: =SUM(N6:Q6) -> 0 | AE6: =SUM(O6:R6) -> 0 | AF6: =SUM(P6:S6) -> 0 | AG6: =SUM(Q6:T6) -> 0 | AH6: =SUM(R6:U6) -> 0 | AI6: =SUM(S6:V6) -> 0 | AK6: =SUM(AI6/AE6)-1 -> #DIV/0!
P7: ='Revenue Drivers'!P8 -> 0 | Q7: ='Revenue Drivers'!Q8 -> 0 | AC7: =SUM(M7:P7) -> 0 | AD7: =SUM(N7:Q7) -> 0 | AE7: =SUM(O7:R7) -> 0 | AF7: =SUM(P7:S7) -> 0 | AG7: =SUM(Q7:T7) -> 0 | AH7: =SUM(R7:U7) -> 0 | AI7: =SUM(S7:V7) -> 0 | AK7: =SUM(AI7/AE7)-1 -> #DIV/0!
B8: Total Revenue | C8: ='Historical Financials'!#REF! -> #REF! | D8: =SUM(D6:D7) -> 0 | E8: =SUM(E6:E7) -> 0 | F8: =SUM(F6:F7) -> 0 | H8: ='Historical Financials'!I11 -> 0 | I8: ='Historical Financials'!J11 -> 0 | J8: ='Historical Financials'!K11 -> 0 | K8: ='Historical Financials'!L11 -> 51761 | L8: ='Historical Financials'!M11 -> 0 | M8: ='Historical Financials'!N11 -> 0 | N8: ='Historical Financials'!O11 -> 0 | O8: ='Historical Financials'!P11 -> 46298 | P8: =SUM(P6:P7) -> 0 | Q8: =SUM(Q6:Q7) -> 0 | R8: =SUM(R6:R7) -> 0 | S8: =SUM(S6:S7) -> 0 | T8: =SUM(T6:T7) -> 0 | U8: =SUM(U6:U7) -> 0 | V8: =SUM(V6:V7) -> 0 | X8: =SUM(H8:K8) -> 51761 | Y8: =SUM(I8:L8) -> 51761 | Z8: =SUM(J8:M8) -> 51761 | AA8: =SUM(K8:N8) -> 51761 | AB8: =SUM(L8:O8) -> 46298 | AC8: =SUM(AC6:AC7) -> 0 | AD8: =SUM(AD6:AD7) -> 0 | AE8: =SUM(AE6:AE7) -> 0 | AF8: =SUM(AF6:AF7) -> 0 | AG8: =SUM(AG6:AG7) -> 0 | AH8: =SUM(AH6:AH7) -> 0 | AI8: =SUM(AI6:AI7) -> 0 | AK8: =SUM(AI8/AE8)-1 -> #DIV/0!
B9: Y/Y Growth (%) | D9: =SUM(D8/C8)-1 -> #REF! | E9: =SUM(E8/D8)-1 -> #DIV/0! | F9: =SUM(F8/E8)-1 -> #DIV/0! | M9: =SUM(M8/I8)-1 -> #DIV/0! | N9: =SUM(N8/J8)-1 -> #DIV/0! | O9: =SUM(O8/K8)-1 -> -0.10554278 | P9: =SUM(P8/L8)-1 -> #DIV/0! | Q9: =SUM(Q8/M8)-1 -> #DIV/0! | R9: =SUM(R8/N8)-1 -> #DIV/0! | S9: =SUM(S8/O8)-1 -> -1 | T9: =SUM(T8/P8)-1 -> #DIV/0! | ... V9: =SUM(V8/R8)-1 -> #DIV/0! | AB9: =SUM(AB8/X8)-1 -> -0.10554278 | AC9: =SUM(AC8/Y8)-1 -> -1 | AD9: =SUM(AD8/Z8)-1 -> -1 | AE9: =SUM(AE8/AA8)-1 -> -1 | AF9: =SUM(AF8/AB8)-1 -> -1 | AG9: =SUM(AG8/AC8)-1 -> #DIV/0! | AH9: =SUM(AH8/AD8)-1 -> #DIV/0! | AI9: =SUM(AI8/AE8)-1 -> #DIV/0! | AK9: =SUM(AI9-AE9)*10000 -> #DIV/0!
B10: Q/Q Growth (%) | C10: N/A | D10: N/A | E10: N/A | F10: N/A | J10: =SUM(J8/I8)-1 -> #DIV/0! | K10: =SUM(K8/J8)-1 -> #DIV/0! | L10: =SUM(L8/K8)-1 -> -1 | M10: =SUM(M8/L8)-1 -> #DIV/0! | N10: =SUM(N8/M8)-1 -> #DIV/0! | O10: =SUM(O8/N8)-1 -> #DIV/0! | P10: =SUM(P8/O8)-1 -> -1 | Q10: =SUM(Q8/P8)-1 -> #DIV/0! | ... V10: =SUM(V8/U8)-1 -> #DIV/0! | X10: N/A | Y10: N/A | Z10: N/A | AA10: N/A | AB10: N/A | AC10: N/A | AD10: N/A | AE10: N/A | AF10: N/A | AG10: N/A | AH10: N/A | AI10: N/A
B12: (-) Cost of Sales | C12: ='Historical Financials'!#REF! -> #REF! | H12: ='Historical Financials'!I13 -> 0 | I12: ='Historical Financials'!J13 -> 0 | J12: ='Historical Financials'!K13 -> 0 | K12: ='Historical Financials'!L13 -> 40121 | L12: ='Historical Financials'!M13 -> 0 | M12: ='Historical Financials'!N13 -> 0 | N12: ='Historical Financials'!O13 -> 0 | O12: ='Historical Financials'!P13 -> 36386 | ... Q12: ='Historical Financials'!R13 -> 0 | X12: =SUM(G12:K12) -> 40121 | Y12: =SUM(I12:L12) -> 40121 | Z12: =SUM(J12:M12) -> 40121 | AA12: =SUM(K12:N12) -> 40121 | AB12: =SUM(L12:O12) -> 36386 | AC12: =SUM(M12:P12) -> 36386 | AD12: =SUM(N12:Q12) -> 36386 | AE12: =SUM(O12:R12) -> 36386 | AF12: =SUM(P12:S12) -> 0 | ... AI12: =SUM(S12:V12) -> 0 | AK12: =SUM(AI12/AE12)-1 -> -1
B13: Gross Profit | C13: =+C8+C12 -> #REF! | D13: =+D8+D12 -> 0 | E13: =+E8+E12 -> 0 | F13: =+F8+F12 -> 0 | H13: =+H8+H12 -> 0 | I13: =+I8+I12 -> 0 | J13: =+J8+J12 -> 0 | K13: =+K8+K12 -> 91882 | L13: =+L8+L12 -> 0 | M13: =+M8+M12 -> 0 | N13: =+N8+N12 -> 0 | O13: =+O8+O12 -> 82684 | ... V13: =+V8+V12 -> 0 | X13: =+X8+X12 -> 91882 | Y13: =+Y8+Y12 -> 91882 | Z13: =+Z8+Z12 -> 91882 | AA13: =+AA8+AA12 -> 91882 | AB13: =+AB8+AB12 -> 82684 | AC13: =+AC8+AC12 -> 36386 | AD13: =+AD8+AD12 -> 36386 | AE13: =+AE8+AE12 -> 36386 | ... AI13: =+AI8+AI12 -> 0 | AK13: =SUM(AI13/AE13)-1 -> -1
B14: Gross Margin (%) | C14: =C13/C8 -> #REF! | D14: =D13/D8 -> #DIV/0! | E14: =E13/E8 -> #DIV/0! | F14: =F13/F8 -> #DIV/0! | H14: =H13/H8 -> #DIV/0! | I14: =I13/I8 -> #DIV/0! | J14: =J13/J8 -> #DIV/0! | K14: =K13/K8 -> 1.7751203 | L14: =L13/L8 -> #DIV/0! | M14: =M13/M8 -> #DIV/0! | N14: =N13/N8 -> #DIV/0! | O14: =O13/O8 -> 1.7859087 | ... V14: =V13/V8 -> #DIV/0! | X14: =X13/X8 -> 1.7751203 | Y14: =Y13/Y8 -> 1.7751203 | Z14: =Z13/Z8 -> 1.7751203 | AA14: =AA13/AA8 -> 1.7751203 | AB14: =AB13/AB8 -> 1.7859087 | AC14: =AC13/AC8 -> #DIV/0! | AD14: =AD13/AD8 -> #DIV/0! | AE14: =AE13/AE8 -> #DIV/0! | ... AI14: =AI13/AI8 -> #DIV/0! | AK14: =SUM(AI14-AE14)*10000 -> #DIV/0!
B16: (-) Research and development | C16: ='Historical Financials'!#REF! -> #REF! | H16: ='Historical Financials'!I17 -> 0 | I16: ='Historical Financials'!J17 -> 0 | J16: ='Historical Financials'!K17 -> 0 | K16: ='Historical Financials'!L17 -> 8635 | L16: ='Historical Financials'!M17 -> 0 | M16: ='Historical Financials'!N17 -> 0 | N16: ='Historical Financials'!O17 -> 0 | O16: ='Historical Financials'!P17 -> 7970 | ... Q16: ='Historical Financials'!R17 -> 0 | X16: =SUM(G16:K16) -> 8635 | Y16: =SUM(I16:L16) -> 8635 | Z16: =SUM(J16:M16) -> 8635 | AA16: =SUM(K16:N16) -> 8635 | AB16: =SUM(L16:O16) -> 7970 | AC16: =SUM(M16:P16) -> 7970 | AD16: =SUM(N16:Q16) -> 7970 | AE16: =SUM(O16:R16) -> 7970 | AF16: =SUM(P16:S16) -> 0 | ... AI16: =SUM(S16:V16) -> 0 | AK16: =SUM(AI16/AE16)-1 -> -1
B17: (-) Sales and marketing | C17: ='Historical Financials'!#REF! -> #REF! | H17: ='Historical Financials'!I18 -> 0 | I17: ='Historical Financials'!J18 -> 0 | J17: ='Historical Financials'!K18 -> 0 | K17: ='Historical Financials'!L18 -> -34 | L17: ='Historical Financials'!M18 -> 0 | M17: ='Historical Financials'!N18 -> 0 | N17: ='Historical Financials'!O18 -> 0 | O17: ='Historical Financials'!P18 -> 147 | ... Q17: ='Historical Financials'!R18 -> 0 | X17: =SUM(G17:K17) -> -34 | Y17: =SUM(I17:L17) -> -34 | Z17: =SUM(J17:M17) -> -34 | AA17: =SUM(K17:N17) -> -34 | AB17: =SUM(L17:O17) -> 147 | AC17: =SUM(M17:P17) -> 147 | AD17: =SUM(N17:Q17) -> 147 | AE17: =SUM(O17:R17) -> 147 | AF17: =SUM(P17:S17) -> 0 | ... AI17: =SUM(S17:V17) -> 0 | AK17: =SUM(AI17/AE17)-1 -> -1
B18: (-) General and administrative | C18: ='Historical Financials'!#REF! -> #REF! | H18: ='Historical Financials'!#REF! -> #REF! | I18: ='Historical Financials'!#REF! -> #REF! | J18: ='Historical Financials'!#REF! -> #REF! | K18: ='Historical Financials'!#REF! -> #REF! | L18: ='Historical Financials'!#REF! -> #REF! | M18: ='Historical Financials'!#REF! -> #REF! | N18: ='Historical Financials'!#REF! -> #REF! | O18: ='Historical Financials'!#REF! -> #REF! | ... Q18: ='Historical Financials'!#REF! -> #REF! | X18: =SUM(G18:K18) -> #REF! | Y18: =SUM(I18:L18) -> #REF! | Z18: =SUM(J18:M18) -> #REF! | AA18: =SUM(K18:N18) -> #REF! | AB18: =SUM(L18:O18) -> #REF! | AC18: =SUM(M18:P18) -> #REF! | AD18: =SUM(N18:Q18) -> #REF! | AE18: =SUM(O18:R18) -> #REF! | AF18: =SUM(P18:S18) -> #REF! | ... AI18: =SUM(S18:V18) -> 0 | AK18: =SUM(AI18/AE18)-1 -> #REF!
B19: (-) Depreciation and amortization | C19: ='Historical Financials'!#REF! -> #REF! | H19: ='Historical Financials'!#REF! -> #REF! | I19: ='Historical Financials'!#REF! -> #REF! | J19: ='Historical Financials'!#REF! -> #REF! | K19: ='Historical Financials'!#REF! -> #REF! | L19: ='Historical Financials'!#REF! -> #REF! | M19: ='Historical Financials'!#REF! -> #REF! | N19: ='Historical Financials'!#REF! -> #REF! | O19: ='Historical Financials'!#REF! -> #REF! | ... Q19: ='Historical Financials'!#REF! -> #REF! | X19: =SUM(G19:K19) -> #REF! | Y19: =SUM(I19:L19) -> #REF! | Z19: =SUM(J19:M19) -> #REF! | AA19: =SUM(K19:N19) -> #REF! | AB19: =SUM(L19:O19) -> #REF! | AC19: =SUM(M19:P19) -> #REF! | AD19: =SUM(N19:Q19) -> #REF! | AE19: =SUM(O19:R19) -> #REF! | AF19: =SUM(P19:S19) -> #REF! | ... AI19: =SUM(S19:V19) -> 0 | AK19: =SUM(AI19/AE19)-1 -> #REF!
B20: Earning before Interest & Taxes (EBIT) | C20: =SUM(C13+SUM(C16:C19)) -> #REF! | D20: =SUM(D13+SUM(D16:D19)) -> 0 | E20: =SUM(E13+SUM(E16:E19)) -> 0 | F20: =SUM(F13+SUM(F16:F19)) -> 0 | H20: =SUM(H13+SUM(H16:H19)) -> #REF! | I20: =SUM(I13+SUM(I16:I19)) -> #REF! | J20: =SUM(J13+SUM(J16:J19)) -> #REF! | K20: =SUM(K13+SUM(K16:K19)) -> #REF! | L20: =SUM(L13+SUM(L16:L19)) -> #REF! | M20: =SUM(M13+SUM(M16:M19)) -> #REF! | N20: =SUM(N13+SUM(N16:N19)) -> #REF! | O20: =SUM(O13+SUM(O16:O19)) -> #REF! | ... V20: =SUM(V13+SUM(V16:V19)) -> 0 | X20: =SUM(X13+SUM(X16:X19)) -> #REF! | Y20: =SUM(Y13+SUM(Y16:Y19)) -> #REF! | Z20: =SUM(Z13+SUM(Z16:Z19)) -> #REF! | AA20: =SUM(AA13+SUM(AA16:AA19)) -> #REF! | AB20: =SUM(AB13+SUM(AB16:AB19)) -> #REF! | AC20: =SUM(AC13+SUM(AC16:AC19)) -> #REF! | AD20: =SUM(AD13+SUM(AD16:AD19)) -> #REF! | AE20: =SUM(AE13+SUM(AE16:AE19)) -> #REF! | ... AI20: =SUM(AI13+SUM(AI16:AI19)) -> 0 | AK20: =SUM(AI20/AE20)-1 -> #REF!
B21: Operating Margin (%) | C21: =C20/C8 -> #REF! | D21: =D20/D8 -> #DIV/0! | E21: =E20/E8 -> #DIV/0! | F21: =F20/F8 -> #DIV/0! | H21: =H20/H8 -> #REF! | I21: =I20/I8 -> #REF! | J21: =J20/J8 -> #REF! | K21: =K20/K8 -> #REF! | L21: =L20/L8 -> #REF! | M21: =M20/M8 -> #REF! | N21: =N20/N8 -> #REF! | O21: =O20/O8 -> #REF! | ... V21: =V20/V8 -> #DIV/0! | X21: =X20/X8 -> #REF! | Y21: =Y20/Y8 -> #REF! | Z21: =Z20/Z8 -> #REF! | AA21: =AA20/AA8 -> #REF! | AB21: =AB20/AB8 -> #REF! | AC21: =AC20/AC8 -> #REF! | AD21: =AD20/AD8 -> #REF! | AE21: =AE20/AE8 -> #REF! | ... AI21: =AI20/AI8 -> #DIV/0! | AK21: =SUM(AI21-AE21)*10000 -> #DIV/0!
B23: (+) Depreciation and Amortization | C23: =-C19 -> #REF! | H23: =-H19 -> #REF! | I23: =-I19 -> #REF! | J23: =-J19 -> #REF! | K23: =-K19 -> #REF! | L23: =-L19 -> #REF! | M23: =-M19 -> #REF! | N23: =-N19 -> #REF! | O23: =-O19 -> #REF! | ... Q23: =-Q19 -> #REF! | X23: =SUM(G23:K23) -> #REF! | Y23: =SUM(I23:L23) -> #REF! | Z23: =SUM(J23:M23) -> #REF! | AA23: =SUM(K23:N23) -> #REF! | AB23: =SUM(L23:O23) -> #REF! | AC23: =SUM(M23:P23) -> #REF! | AD23: =SUM(N23:Q23) -> #REF! | AE23: =SUM(O23:R23) -> #REF! | AF23: =SUM(P23:S23) -> #REF! | ... AI23: =SUM(S23:V23) -> 0 | AK23: =SUM(AI23/AE23)-1 -> #REF!
B24: EBITDA | C24: =SUM(C20+C23) -> #REF! | D24: =SUM(D20+D23) -> 0 | E24: =SUM(E20+E23) -> 0 | F24: =SUM(F20+F23) -> 0 | H24: =SUM(H20+H23) -> #REF! | I24: =SUM(I20+I23) -> #REF! | J24: =SUM(J20+J23) -> #REF! | K24: =SUM(K20+K23) -> #REF! | L24: =SUM(L20+L23) -> #REF! | M24: =SUM(M20+M23) -> #REF! | N24: =SUM(N20+N23) -> #REF! | O24: =SUM(O20+O23) -> #REF! | ... V24: =SUM(V20+V23) -> 0 | X24: =SUM(X20+X23) -> #REF! | Y24: =SUM(Y20+Y23) -> #REF! | Z24: =SUM(Z20+Z23) -> #REF! | AA24: =SUM(AA20+AA23) -> #REF! | AB24: =SUM(AB20+AB23) -> #REF! | AC24: =SUM(AC20+AC23) -> #REF! | AD24: =SUM(AD20+AD23) -> #REF! | AE24: =SUM(AE20+AE23) -> #REF! | ... AI24: =SUM(AI20+AI23) -> 0 | AK24: =SUM(AI24/AE24)-1 -> #REF!
B25: EBITDA Margin (%) | C25: =C24/C8 -> #REF! | D25: =D24/D8 -> #DIV/0! | E25: =E24/E8 -> #DIV/0! | F25: =F24/F8 -> #DIV/0! | H25: =H24/H8 -> #REF! | I25: =I24/I8 -> #REF! | J25: =J24/J8 -> #REF! | K25: =K24/K8 -> #REF! | L25: =L24/L8 -> #REF! | M25: =M24/M8 -> #REF! | N25: =N24/N8 -> #REF! | O25: =O24/O8 -> #REF! | ... V25: =V24/V8 -> #DIV/0! | X25: =X24/X8 -> #REF! | Y25: =Y24/Y8 -> #REF! | Z25: =Z24/Z8 -> #REF! | AA25: =AA24/AA8 -> #REF! | AB25: =AB24/AB8 -> #REF! | AC25: =AC24/AC8 -> #REF! | AD25: =AD24/AD8 -> #REF! | AE25: =AE24/AE8 -> #REF! | ... AI25: =AI24/AI8 -> #DIV/0! | AK25: =SUM(AI25-AE25)*10000 -> #DIV/0!
B27: (+) Share-based Compensation | C27: ='Historical Financials'!#REF! -> #REF! | H27: ='Historical Financials'!I95 -> 0 | I27: ='Historical Financials'!J95 -> 0 | J27: ='Historical Financials'!K95 -> 0 | K27: ='Historical Financials'!L95 -> -34 | L27: ='Historical Financials'!M95 -> 0 | M27: ='Historical Financials'!N95 -> 0 | N27: ='Historical Financials'!O95 -> 0 | O27: ='Historical Financials'!P95 -> 147 | ... Q27: ='Historical Financials'!R95 -> 0 | X27: =SUM(G27:K27) -> -34 | Y27: =SUM(I27:L27) -> -34 | Z27: =SUM(J27:M27) -> -34 | AA27: =SUM(K27:N27) -> -34 | AB27: =SUM(L27:O27) -> 147 | AC27: =SUM(M27:P27) -> 147 | AD27: =SUM(N27:Q27) -> 147 | AE27: =SUM(O27:R27) -> 147 | AF27: =SUM(P27:S27) -> 0 | ... AI27: =SUM(S27:V27) -> 0 | AK27: =SUM(AI27/AE27)-1 -> -1
B28: Adj. EBITDA | C28: =+SUM(C24+SUM(C27:C27)) -> #REF! | D28: =+SUM(D24+SUM(D27:D27)) -> 0 | E28: =+SUM(E24+SUM(E27:E27)) -> 0 | F28: =+SUM(F24+SUM(F27:F27)) -> 0 | H28: =+SUM(H24+SUM(H27:H27)) -> #REF! | I28: =+SUM(I24+SUM(I27:I27)) -> #REF! | J28: =+SUM(J24+SUM(J27:J27)) -> #REF! | K28: =+SUM(K24+SUM(K27:K27)) -> #REF! | L28: =+SUM(L24+SUM(L27:L27)) -> #REF! | M28: =+SUM(M24+SUM(M27:M27)) -> #REF! | N28: =+SUM(N24+SUM(N27:N27)) -> #REF! | O28: =+SUM(O24+SUM(O27:O27)) -> #REF! | ... V28: =+SUM(V24+SUM(V27:V27)) -> 0 | X28: =+SUM(X24+SUM(X27:X27)) -> #REF! | Y28: =+SUM(Y24+SUM(Y27:Y27)) -> #REF! | Z28: =+SUM(Z24+SUM(Z27:Z27)) -> #REF! | AA28: =+SUM(AA24+SUM(AA27:AA27)) -> #REF! | AB28: =+SUM(AB24+SUM(AB27:AB27)) -> #REF! | AC28: =+SUM(AC24+SUM(AC27:AC27)) -> #REF! | AD28: =+SUM(AD24+SUM(AD27:AD27)) -> #REF! | AE28: =+SUM(AE24+SUM(AE27:AE27)) -> #REF! | ... AI28: =+SUM(AI24+SUM(AI27:AI27)) -> 0 | AK28: =SUM(AI28/AE28)-1 -> #REF!
B29: Adj. EBITDA Margin (%) | C29: =C28/C8 -> #REF! | D29: =D28/D8 -> #DIV/0! | E29: =E28/E8 -> #DIV/0! | F29: =F28/F8 -> #DIV/0! | H29: =H28/H8 -> #REF! | I29: =I28/I8 -> #REF! | J29: =J28/J8 -> #REF! | K29: =K28/K8 -> #REF! | L29: =L28/L8 -> #REF! | M29: =M28/M8 -> #REF! | N29: =N28/N8 -> #REF! | O29: =O28/O8 -> #REF! | ... V29: =V28/V8 -> #DIV/0! | X29: =X28/X8 -> #REF! | Y29: =Y28/Y8 -> #REF! | Z29: =Z28/Z8 -> #REF! | AA29: =AA28/AA8 -> #REF! | AB29: =AB28/AB8 -> #REF! | AC29: =AC28/AC8 -> #REF! | AD29: =AD28/AD8 -> #REF! | AE29: =AE28/AE8 -> #REF! | ... AI29: =AI28/AI8 -> #DIV/0! | AK29: =SUM(AI29-AE29)*10000 -> #DIV/0!
B31: (-) Capital Expenditures | C31: =SUM('Historical Financials'!#REF!+'Historical Financials'!#REF!) -> #REF! | H31: =SUM('Historical Financials'!I111+'Historical Financials'!#REF!) -> #REF! | I31: =SUM('Historical Financials'!J111+'Historical Financials'!#REF!) -> #REF! | J31: =SUM('Historical Financials'!K111+'Historical Financials'!#REF!) -> #REF! | K31: =SUM('Historical Financials'!L111+'Historical Financials'!#REF!) -> #REF! | L31: =SUM('Historical Financials'!M111+'Historical Financials'!#REF!) -> #REF! | M31: =SUM('Historical Financials'!N111+'Historical Financials'!#REF!) -> #REF! | N31: =SUM('Historical Financials'!O111+'Historical Financials'!#REF!) -> #REF! | O31: =SUM('Historical Financials'!P111+'Historical Financials'!#REF!) -> #REF! | ... Q31: =SUM('Historical Financials'!R111+'Historical Financials'!#REF!) -> #REF! | X31: =SUM(G31:K31) -> #REF! | Y31: =SUM(I31:L31) -> #REF! | Z31: =SUM(J31:M31) -> #REF! | AA31: =SUM(K31:N31) -> #REF! | AB31: =SUM(L31:O31) -> #REF! | AC31: =SUM(M31:P31) -> #REF! | AD31: =SUM(N31:Q31) -> #REF! | AE31: =SUM(O31:R31) -> #REF! | AF31: =SUM(P31:S31) -> #REF! | ... AI31: =SUM(S31:V31) -> 0 | AK31: =SUM(AI31/AE31)-1 -> #REF!
B32: (-) Cash Taxes | C32: ='Historical Financials'!#REF! -> #REF! | H32: ='Historical Financials'!I31 -> 0 | I32: ='Historical Financials'!J31 -> 0 | J32: ='Historical Financials'!K31 -> 0 | K32: ='Historical Financials'!L31 -> 0 | L32: ='Historical Financials'!M31 -> 0 | M32: ='Historical Financials'!N31 -> 0 | N32: ='Historical Financials'!O31 -> 0 | O32: ='Historical Financials'!P31 -> 0 | ... Q32: ='Historical Financials'!R31 -> 0 | X32: =SUM(G32:K32) -> 0 | Y32: =SUM(I32:L32) -> 0 | Z32: =SUM(J32:M32) -> 0 | AA32: =SUM(K32:N32) -> 0 | AB32: =SUM(L32:O32) -> 0 | AC32: =SUM(M32:P32) -> 0 | AD32: =SUM(N32:Q32) -> 0 | AE32: =SUM(O32:R32) -> 0 | AF32: =SUM(P32:S32) -> 0 | ... AI32: =SUM(S32:V32) -> 0 | AK32: =SUM(AI32/AE32)-1 -> #DIV/0!
B33: (-) Cash Interest | C33: 0 | H33: 0 | I33: 0 | J33: 0 | K33: =D33 -> 0 | L33: 0 | M33: 0 | N33: 0 | O33: =E33 -> 0 | P33: 0 | Q33: 0 | X33: =SUM(G33:K33) -> 0 | Y33: =SUM(I33:L33) -> 0 | Z33: =SUM(J33:M33) -> 0 | AA33: =SUM(K33:N33) -> 0 | AB33: =SUM(L33:O33) -> 0 | AC33: =SUM(M33:P33) -> 0 | AD33: =SUM(N33:Q33) -> 0 | AE33: =SUM(O33:R33) -> 0 | AF33: =SUM(P33:S33) -> 0 | ... AI33: =SUM(S33:V33) -> 0 | AK33: =SUM(AI33/AE33)-1 -> #DIV/0!
B34: (+/-) Changes in NWC | C34: =SUM('Historical Financials'!#REF!) -> #REF! | H34: =SUM('Historical Financials'!I102:I107) -> 0 | I34: =SUM('Historical Financials'!J102:J107) -> 0 | J34: =SUM('Historical Financials'!K102:K107) -> 0 | K34: =SUM('Historical Financials'!L102:L107) -> -203 | L34: =SUM('Historical Financials'!M102:M107) -> 0 | M34: =SUM('Historical Financials'!N102:N107) -> 0 | N34: =SUM('Historical Financials'!O102:O107) -> 0 | O34: =SUM('Historical Financials'!P102:P107) -> -861 | ... Q34: =SUM('Historical Financials'!R102:R107) -> 0 | X34: =SUM(G34:K34) -> -203 | Y34: =SUM(I34:L34) -> -203 | Z34: =SUM(J34:M34) -> -203 | AA34: =SUM(K34:N34) -> -203 | AB34: =SUM(L34:O34) -> -861 | AC34: =SUM(M34:P34) -> -861 | AD34: =SUM(N34:Q34) -> -861 | AE34: =SUM(O34:R34) -> -861 | AF34: =SUM(P34:S34) -> 0 | ... AI34: =SUM(S34:V34) -> 0 | AK34: =SUM(AI34/AE34)-1 -> -1
B35: Discretionary Cash-Flows | C35: =SUM(C28+SUM(C31:C34)) -> #REF! | D35: =SUM(D28+SUM(D31:D34)) -> 0 | E35: =SUM(E28+SUM(E31:E34)) -> 0 | F35: =SUM(F28+SUM(F31:F34)) -> 0 | H35: =SUM(H28+SUM(H31:H34)) -> #REF! | I35: =SUM(I28+SUM(I31:I34)) -> #REF! | J35: =SUM(J28+SUM(J31:J34)) -> #REF! | K35: =SUM(K28+SUM(K31:K34)) -> #REF! | L35: =SUM(L28+SUM(L31:L34)) -> #REF! | M35: =SUM(M28+SUM(M31:M34)) -> #REF! | N35: =SUM(N28+SUM(N31:N34)) -> #REF! | O35: =SUM(O28+SUM(O31:O34)) -> #REF! | ... V35: =SUM(V28+SUM(V31:V34)) -> 0 | X35: =SUM(X28+SUM(X31:X34)) -> #REF! | Y35: =SUM(Y28+SUM(Y31:Y34)) -> #REF! | Z35: =SUM(Z28+SUM(Z31:Z34)) -> #REF! | AA35: =SUM(AA28+SUM(AA31:AA34)) -> #REF! | AB35: =SUM(AB28+SUM(AB31:AB34)) -> #REF! | AC35: =SUM(AC28+SUM(AC31:AC34)) -> #REF! | AD35: =SUM(AD28+SUM(AD31:AD34)) -> #REF! | AE35: =SUM(AE28+SUM(AE31:AE34)) -> #REF! | ... AI35: =SUM(AI28+SUM(AI31:AI34)) -> 0 | AK35: =SUM(AI35/AE35)-1 -> #REF!
B37: (+/-) Proceeds / (Purchases) of Equity, net | C37: ='Historical Financials'!#REF! -> #REF! | H37: ='Historical Financials'!#REF! -> #REF! | I37: ='Historical Financials'!#REF! -> #REF! | J37: ='Historical Financials'!#REF! -> #REF! | K37: ='Historical Financials'!#REF! -> #REF! | L37: ='Historical Financials'!#REF! -> #REF! | M37: ='Historical Financials'!#REF! -> #REF! | N37: ='Historical Financials'!#REF! -> #REF! | O37: ='Historical Financials'!#REF! -> #REF! | ... Q37: ='Historical Financials'!#REF! -> #REF! | X37: =SUM(G37:K37) -> #REF! | Y37: =SUM(I37:L37) -> #REF! | Z37: =SUM(J37:M37) -> #REF! | AA37: =SUM(K37:N37) -> #REF! | AB37: =SUM(L37:O37) -> #REF! | AC37: =SUM(M37:P37) -> #REF! | AD37: =SUM(N37:Q37) -> #REF! | AE37: =SUM(O37:R37) -> #REF! | AF37: =SUM(P37:S37) -> #REF! | ... AI37: =SUM(S37:V37) -> 0
B38: (+/-) Maturities / (Purchases) of available-for-sale securities | C38: =SUM('Historical Financials'!#REF!) -> #REF! | H38: =SUM('Historical Financials'!#REF!) -> #REF! | I38: =SUM('Historical Financials'!#REF!) -> #REF! | J38: =SUM('Historical Financials'!#REF!) -> #REF! | K38: =SUM('Historical Financials'!#REF!) -> #REF! | L38: =SUM('Historical Financials'!#REF!) -> #REF! | M38: =SUM('Historical Financials'!#REF!) -> #REF! | N38: =SUM('Historical Financials'!#REF!) -> #REF! | O38: =SUM('Historical Financials'!#REF!) -> #REF! | ... Q38: =SUM('Historical Financials'!#REF!) -> #REF! | X38: =SUM(G38:K38) -> #REF! | Y38: =SUM(I38:L38) -> #REF! | Z38: =SUM(J38:M38) -> #REF! | AA38: =SUM(K38:N38) -> #REF! | AB38: =SUM(L38:O38) -> #REF! | AC38: =SUM(M38:P38) -> #REF! | AD38: =SUM(N38:Q38) -> #REF! | AE38: =SUM(O38:R38) -> #REF! | AF38: =SUM(P38:S38) -> #REF! | ... AI38: =SUM(S38:V38) -> 0
B39: (+/-) Divestitures / (Acquisitions) | C39: ='Historical Financials'!#REF! -> #REF! | H39: ='Historical Financials'!#REF! -> #REF! | I39: ='Historical Financials'!#REF! -> #REF! | J39: ='Historical Financials'!#REF! -> #REF! | K39: ='Historical Financials'!#REF! -> #REF! | L39: ='Historical Financials'!#REF! -> #REF! | M39: ='Historical Financials'!#REF! -> #REF! | N39: ='Historical Financials'!#REF! -> #REF! | O39: ='Historical Financials'!#REF! -> #REF! | ... Q39: ='Historical Financials'!#REF! -> #REF! | X39: =SUM(G39:K39) -> #REF! | Y39: =SUM(I39:L39) -> #REF! | Z39: =SUM(J39:M39) -> #REF! | AA39: =SUM(K39:N39) -> #REF! | AB39: =SUM(L39:O39) -> #REF! | AC39: =SUM(M39:P39) -> #REF! | AD39: =SUM(N39:Q39) -> #REF! | AE39: =SUM(O39:R39) -> #REF! | AF39: =SUM(P39:S39) -> #REF! | ... AI39: =SUM(S39:V39) -> 0
B40: (+/-) Other Investing Activities | C40: ='Historical Financials'!#REF! -> #REF! | H40: ='Historical Financials'!#REF! -> #REF! | I40: ='Historical Financials'!#REF! -> #REF! | J40: ='Historical Financials'!#REF! -> #REF! | K40: ='Historical Financials'!#REF! -> #REF! | L40: ='Historical Financials'!#REF! -> #REF! | M40: ='Historical Financials'!#REF! -> #REF! | N40: ='Historical Financials'!#REF! -> #REF! | O40: ='Historical Financials'!#REF! -> #REF! | ... Q40: ='Historical Financials'!#REF! -> #REF! | X40: =SUM(G40:K40) -> #REF! | Y40: =SUM(I40:L40) -> #REF! | Z40: =SUM(J40:M40) -> #REF! | AA40: =SUM(K40:N40) -> #REF! | AB40: =SUM(L40:O40) -> #REF! | AC40: =SUM(M40:P40) -> #REF! | AD40: =SUM(N40:Q40) -> #REF! | AE40: =SUM(O40:R40) -> #REF! | AF40: =SUM(P40:S40) -> #REF! | ... AI40: =SUM(S40:V40) -> 0
B41: (+/-) Other Financing Activities | C41: ='Historical Financials'!#REF! -> #REF! | H41: ='Historical Financials'!#REF! -> #REF! | I41: ='Historical Financials'!#REF! -> #REF! | J41: ='Historical Financials'!#REF! -> #REF! | K41: ='Historical Financials'!#REF! -> #REF! | L41: ='Historical Financials'!#REF! -> #REF! | M41: ='Historical Financials'!#REF! -> #REF! | N41: ='Historical Financials'!#REF! -> #REF! | O41: ='Historical Financials'!#REF! -> #REF! | ... Q41: ='Historical Financials'!#REF! -> #REF! | X41: =SUM(G41:K41) -> #REF! | Y41: =SUM(I41:L41) -> #REF! | Z41: =SUM(J41:M41) -> #REF! | AA41: =SUM(K41:N41) -> #REF! | AB41: =SUM(L41:O41) -> #REF! | AC41: =SUM(M41:P41) -> #REF! | AD41: =SUM(N41:Q41) -> #REF! | AE41: =SUM(O41:R41) -> #REF! | AF41: =SUM(P41:S41) -> #REF! | ... AI41: =SUM(S41:V41) -> 0
B42: (+/-) Other Operating Activities | C42: ='Historical Financials'!#REF! -> #REF! | H42: ='Historical Financials'!#REF! -> #REF! | I42: ='Historical Financials'!#REF! -> #REF! | J42: ='Historical Financials'!#REF! -> #REF! | K42: ='Historical Financials'!#REF! -> #REF! | L42: ='Historical Financials'!#REF! -> #REF! | M42: ='Historical Financials'!#REF! -> #REF! | N42: ='Historical Financials'!#REF! -> #REF! | O42: ='Historical Financials'!#REF! -> #REF! | ... Q42: ='Historical Financials'!#REF! -> #REF! | X42: =SUM(G42:K42) -> #REF! | Y42: =SUM(I42:L42) -> #REF! | Z42: =SUM(J42:M42) -> #REF! | AA42: =SUM(K42:N42) -> #REF! | AB42: =SUM(L42:O42) -> #REF! | AC42: =SUM(M42:P42) -> #REF! | AD42: =SUM(N42:Q42) -> #REF! | AE42: =SUM(O42:R42) -> #REF! | AF42: =SUM(P42:S42) -> #REF! | ... AI42: =SUM(S42:V42) -> 0
B43: (+/-) Other | H43: =SUM(H48:H49)-SUM(C48:C49)-SUM(H35:H42) -> #REF! | I43: =SUM(I48:I49)-SUM(H48:H49)-SUM(I35:I42) -> #REF! | J43: =SUM(J48:J49)-SUM(I48:I49)-SUM(J35:J42) -> #REF! | K43: =SUM(K48:K49)-SUM(J48:J49)-SUM(K35:K42) -> #REF! | L43: =SUM(L48:L49)-SUM(K48:K49)-SUM(L35:L42) -> #REF! | M43: =SUM(M48:M49)-SUM(L48:L49)-SUM(M35:M42) -> #REF! | N43: =SUM(N48:N49)-SUM(M48:M49)-SUM(N35:N42) -> #REF! | O43: =SUM(O48:O49)-SUM(N48:N49)-SUM(O35:O42) -> #REF! | P43: =SUM(P48:P49)-SUM(O48:O49)-SUM(P35:P42) -> #REF! | Q43: =SUM(Q48:Q49)-SUM(P48:P49)-SUM(Q35:Q42) -> #REF! | X43: =SUM(G43:K43) -> #REF! | Y43: =SUM(I43:L43) -> #REF! | Z43: =SUM(J43:M43) -> #REF! | AA43: =SUM(K43:N43) -> #REF! | AB43: =SUM(L43:O43) -> #REF! | AC43: =SUM(M43:P43) -> #REF! | AD43: =SUM(N43:Q43) -> #REF! | AE43: =SUM(O43:R43) -> #REF! | AF43: =SUM(P43:S43) -> #REF! | ... AI43: =SUM(S43:V43) -> 0
B44: Free-Cash Flows | C44: =SUM(C35+SUM(C37:C43)) -> #REF! | D44: =SUM(D35+SUM(D37:D43)) -> 0 | E44: =SUM(E35+SUM(E37:E43)) -> 0 | F44: =SUM(F35+SUM(F37:F43)) -> 0 | H44: =SUM(H35+SUM(H37:H43)) -> #REF! | I44: =SUM(I35+SUM(I37:I43)) -> #REF! | J44: =SUM(J35+SUM(J37:J43)) -> #REF! | K44: =SUM(K35+SUM(K37:K43)) -> #REF! | L44: =SUM(L35+SUM(L37:L43)) -> #REF! | M44: =SUM(M35+SUM(M37:M43)) -> #REF! | N44: =SUM(N35+SUM(N37:N43)) -> #REF! | O44: =SUM(O35+SUM(O37:O43)) -> #REF! | ... V44: =SUM(V35+SUM(V37:V43)) -> 0 | X44: =SUM(X35+SUM(X37:X43)) -> #REF! | Y44: =SUM(Y35+SUM(Y37:Y43)) -> #REF! | Z44: =SUM(Z35+SUM(Z37:Z43)) -> #REF! | AA44: =SUM(AA35+SUM(AA37:AA43)) -> #REF! | AB44: =SUM(AB35+SUM(AB37:AB43)) -> #REF! | AC44: =SUM(AC35+SUM(AC37:AC43)) -> #REF! | AD44: =SUM(AD35+SUM(AD37:AD43)) -> #REF! | AE44: =SUM(AE35+SUM(AE37:AE43)) -> #REF! | ... AI44: =SUM(AI35+SUM(AI37:AI43)) -> 0
B46: Capitalization
B48: Cash & Cash Equivelants | C48: ='Historical Financials'!#REF! -> #REF! | H48: ='Historical Financials'!I46 -> 0 | I48: ='Historical Financials'!J46 -> 0 | J48: ='Historical Financials'!K46 -> 0 | K48: ='Historical Financials'!L46 -> 2936 | L48: ='Historical Financials'!M46 -> 0 | M48: ='Historical Financials'!N46 -> 0 | N48: ='Historical Financials'!O46 -> 0 | O48: ='Historical Financials'!P46 -> 1874 | ... Q48: ='Historical Financials'!R46 -> 0 | X48: =K48 -> 2936 | Y48: =L48 -> 0 | Z48: =M48 -> 0 | AA48: =N48 -> 0 | AB48: =O48 -> 1874 | AC48: =P48 -> 0 | AD48: =Q48 -> 0 | AE48: =R48 -> 0 | ... AI48: =V48 -> 0
B49: Restricted Cash | C49: ='Historical Financials'!#REF! -> #REF! | H49: ='Historical Financials'!I49 -> 0 | I49: ='Historical Financials'!J49 -> 0 | J49: ='Historical Financials'!K49 -> 0 | K49: ='Historical Financials'!L49 -> 596 | L49: ='Historical Financials'!M49 -> 0 | M49: ='Historical Financials'!N49 -> 0 | N49: ='Historical Financials'!O49 -> 0 | O49: ='Historical Financials'!P49 -> 647 | ... Q49: ='Historical Financials'!R49 -> 0 | X49: =K49 -> 596 | Y49: =L49 -> 0 | Z49: =M49 -> 0 | AA49: =N49 -> 0 | AB49: =O49 -> 647 | AC49: =P49 -> 0 | AD49: =Q49 -> 0 | AE49: =R49 -> 0 | ... AI49: =V49 -> 0
B50: Short-term Investments | C50: ='Historical Financials'!#REF! -> #REF! | H50: ='Historical Financials'!#REF! -> #REF! | I50: ='Historical Financials'!#REF! -> #REF! | J50: ='Historical Financials'!#REF! -> #REF! | K50: ='Historical Financials'!#REF! -> #REF! | L50: ='Historical Financials'!#REF! -> #REF! | M50: ='Historical Financials'!#REF! -> #REF! | N50: ='Historical Financials'!#REF! -> #REF! | O50: ='Historical Financials'!#REF! -> #REF! | ... Q50: ='Historical Financials'!#REF! -> #REF! | X50: =K50 -> #REF! | Y50: =L50 -> #REF! | Z50: =M50 -> #REF! | AA50: =N50 -> #REF! | AB50: =O50 -> #REF! | AC50: =P50 -> #REF! | AD50: =Q50 -> #REF! | AE50: =R50 -> 0 | ... AI50: =V50 -> 0
...
