Workbook

Sheet Historical Financials
B2: Crocs Inc (NASDAQ: CROX)
B3: Historical Financials
B4: ($ In Millions, except EPS)
A6: X | B6: Income Statement | C6: FYE | G6: Quarterly | M6: Quarterly | U6: LTM | AA6: Variance
B7: Fiscal Period | C7: 2022 | D7: 2023 | E7: 2024 | G7: 1Q23 | H7: 2Q23 | I7: 3Q23 | J7: 4Q23 | K7: 1Q24 | L7: 2Q24 | M7: 3Q24 | N7: 4Q24 | O7: 1Q25 | P7: 2Q25 | Q7: 3Q25 | S7: =K7 -> 1Q24 | T7: =L7 -> 2Q24 | U7: =M7 -> 3Q24 | V7: =N7 -> 4Q24 | W7: =O7 -> 1Q25 | X7: =P7 -> 2Q25 | Y7: =Q7 -> 3Q25
B8: Fiscal Period End Date | C8: 44926 | D8: 45291 | E8: 45657 | G8: 45016 | H8: 45107 | I8: 45199 | J8: =D8 -> 45291 | K8: 45382 | L8: 45473 | M8: 45565 | N8: =E8 -> 45657 | O8: 45747 | P8: 45838 | Q8: 45930 | S8: =K8 -> 45382 | T8: =L8 -> 45473 | U8: =M8 -> 45565 | V8: =N8 -> 45657 | W8: =O8 -> 45747 | X8: =P8 -> 45838 | Y8: =Q8 -> 45930
B10: Consolidated Revenue | C10: 3555 | D10: 3962.3 | E10: 4102.1 | G10: 884.2 | H10: 1072.4 | I10: 1045.7 | J10: =SUM(D10-SUM(G10:I10)) -> 960 | K10: 938.6 | L10: 1111.5 | M10: 1062.2 | N10: =SUM(E10-SUM(K10:M10)) -> 989.8 | O10: 937.3 | P10: 1149.4 | Q10: 996.301 | S10: =SUM(H10:K10) -> 4016.7 | T10: =SUM(I10:L10) -> 4055.8 | U10: =SUM(J10:M10) -> 4072.3 | V10: =SUM(K10:N10) -> 4102.1 | W10: =SUM(L10:O10) -> 4100.8 | X10: =SUM(M10:P10) -> 4138.7 | Y10: =SUM(N10:Q10) -> 4072.801 | AA10: =SUM(Y10/U10)-1 -> 0.0001230263
B11: Total Revenue | C11: =+SUM(C10:C10) -> 3555 | D11: =+SUM(D10:D10) -> 3962.3 | E11: =+SUM(E10:E10) -> 4102.1 | G11: =+SUM(G10:G10) -> 884.2 | H11: =+SUM(H10:H10) -> 1072.4 | I11: =+SUM(I10:I10) -> 1045.7 | J11: =+SUM(J10:J10) -> 960 | K11: =+SUM(K10:K10) -> 938.6 | L11: =+SUM(L10:L10) -> 1111.5 | M11: =+SUM(M10:M10) -> 1062.2 | N11: =+SUM(N10:N10) -> 989.8 | ... Q11: =+SUM(Q10:Q10) -> 996.301 | S11: =+SUM(S10:S10) -> 4016.7 | T11: =+SUM(T10:T10) -> 4055.8 | U11: =+SUM(U10:U10) -> 4072.3 | V11: =+SUM(V10:V10) -> 4102.1 | W11: =+SUM(W10:W10) -> 4100.8 | X11: =+SUM(X10:X10) -> 4138.7 | Y11: =+SUM(Y10:Y10) -> 4072.801 | AA11: =SUM(Y11/U11)-1 -> 0.0001230263
B13: Cost of Sales | C13: -1694.7 | D13: -1752.3 | E13: -1691.9 | G13: -407.8 | H13: -451.1 | I13: -464.1 | J13: =SUM(D13-SUM(G13:I13)) -> -429.3 | K13: -416.6 | L13: -429.6 | M13: -428.9 | N13: =SUM(E13-SUM(K13:M13)) -> -416.8 | O13: -395.8 | P13: -440.5 | Q13: -413.293 | S13: =SUM(H13:K13) -> -1761.1 | T13: =SUM(I13:L13) -> -1739.6 | U13: =SUM(J13:M13) -> -1704.4 | V13: =SUM(K13:N13) -> -1691.9 | W13: =SUM(L13:O13) -> -1671.1 | X13: =SUM(M13:P13) -> -1682 | Y13: =SUM(N13:Q13) -> -1666.393 | AA13: =SUM(Y13/U13)-1 -> -0.022299343
B14: Gross Profit | C14: =+SUM(C11+SUM(C13:C13)) -> 1860.3 | D14: =+SUM(D11+SUM(D13:D13)) -> 2210 | E14: =+SUM(E11+SUM(E13:E13)) -> 2410.2 | G14: =+SUM(G11+SUM(G13:G13)) -> 476.4 | H14: =+SUM(H11+SUM(H13:H13)) -> 621.3 | I14: =+SUM(I11+SUM(I13:I13)) -> 581.6 | J14: =+SUM(J11+SUM(J13:J13)) -> 530.7 | K14: =+SUM(K11+SUM(K13:K13)) -> 522 | L14: =+SUM(L11+SUM(L13:L13)) -> 681.9 | M14: =+SUM(M11+SUM(M13:M13)) -> 633.3 | N14: =+SUM(N11+SUM(N13:N13)) -> 573 | ... Q14: =+SUM(Q11+SUM(Q13:Q13)) -> 583.008 | S14: =+SUM(S11+SUM(S13:S13)) -> 2255.6 | T14: =+SUM(T11+SUM(T13:T13)) -> 2316.2 | U14: =+SUM(U11+SUM(U13:U13)) -> 2367.9 | V14: =+SUM(V11+SUM(V13:V13)) -> 2410.2 | W14: =+SUM(W11+SUM(W13:W13)) -> 2429.7 | X14: =+SUM(X11+SUM(X13:X13)) -> 2456.7 | Y14: =+SUM(Y11+SUM(Y13:Y13)) -> 2406.408 | AA14: =SUM(Y14/U14)-1 -> 0.016262511
B15: Gross Margin (%) | C15: =C14/C11 -> 0.52329114 | D15: =D14/D11 -> 0.55775686 | E15: =E14/E11 -> 0.58755272 | G15: =G14/G11 -> 0.53879213 | H15: =H14/H11 -> 0.57935472 | I15: =I14/I11 -> 0.55618246 | J15: =J14/J11 -> 0.5528125 | K15: =K14/K11 -> 0.55614745 | L15: =L14/L11 -> 0.61349528 | M15: =M14/M11 -> 0.5962154 | N15: =N14/N11 -> 0.57890483 | ... Q15: =Q14/Q11 -> 0.58517255 | S15: =S14/S11 -> 0.56155551 | T15: =T14/T11 -> 0.57108339 | U15: =U14/U11 -> 0.58146502 | V15: =V14/V11 -> 0.58755272 | W15: =W14/W11 -> 0.59249415 | X15: =X14/X11 -> 0.59359219 | Y15: =Y14/Y11 -> 0.59084841 | AA15: =SUM(Y15-U15)*1000 -> 9.3833914
B17: Selling, General, and Administrative | C17: -1009.5 | D17: -1173.2 | E17: -1388.3 | G17: -241.4 | H17: -302.8 | I17: -307.8 | J17: =SUM(D17-SUM(G17:I17)) -> -321.2 | K17: -295.6 | L17: -356.2 | M17: -363.5 | N17: =SUM(E17-SUM(K17:M17)) -> -373 | O17: -318.6 | P17: -398.2 | Q17: -375.348 | S17: =SUM(H17:K17) -> -1227.4 | T17: =SUM(I17:L17) -> -1280.8 | U17: =SUM(J17:M17) -> -1336.5 | V17: =SUM(K17:N17) -> -1388.3 | W17: =SUM(L17:O17) -> -1411.3 | X17: =SUM(M17:P17) -> -1453.3 | Y17: =SUM(N17:Q17) -> -1465.148 | AA17: =SUM(Y17/U17)-1 -> 0.096257389
B18: Asset Impairments | C18: 0 | D18: 0 | E18: 0 | G18: 0 | H18: 0 | I18: 0 | J18: =SUM(D18-SUM(G18:I18)) -> 0 | K18: 0 | L18: 0 | M18: 0 | N18: =SUM(E18-SUM(K18:M18)) -> 0 | O18: 0 | P18: -738.1 | Q18: 0 | S18: =SUM(H18:K18) -> 0 | T18: =SUM(I18:L18) -> 0 | U18: =SUM(J18:M18) -> 0 | V18: =SUM(K18:N18) -> 0 | W18: =SUM(L18:O18) -> 0 | X18: =SUM(M18:P18) -> -738.1 | Y18: =SUM(N18:Q18) -> -738.1 | AA18: =SUM(Y18/U18)-1 -> #DIV/0!
B19: Operating Profit | C19: =+SUM(C14+SUM(C17:C18)) -> 850.8 | D19: =+SUM(D14+SUM(D17:D18)) -> 1036.8 | E19: =+SUM(E14+SUM(E17:E18)) -> 1021.9 | G19: =+SUM(G14+SUM(G17:G18)) -> 235 | H19: =+SUM(H14+SUM(H17:H18)) -> 318.5 | I19: =+SUM(I14+SUM(I17:I18)) -> 273.8 | J19: =+SUM(J14+SUM(J17:J18)) -> 209.5 | K19: =+SUM(K14+SUM(K17:K18)) -> 226.4 | L19: =+SUM(L14+SUM(L17:L18)) -> 325.7 | M19: =+SUM(M14+SUM(M17:M18)) -> 269.8 | N19: =+SUM(N14+SUM(N17:N18)) -> 200 | ... Q19: =+SUM(Q14+SUM(Q17:Q18)) -> 207.66 | S19: =+SUM(S14+SUM(S17:S18)) -> 1028.2 | T19: =+SUM(T14+SUM(T17:T18)) -> 1035.4 | U19: =+SUM(U14+SUM(U17:U18)) -> 1031.4 | V19: =+SUM(V14+SUM(V17:V18)) -> 1021.9 | W19: =+SUM(W14+SUM(W17:W18)) -> 1018.4 | X19: =+SUM(X14+SUM(X17:X18)) -> 265.3 | Y19: =+SUM(Y14+SUM(Y17:Y18)) -> 203.16 | AA19: =SUM(Y19/U19)-1 -> -0.80302501
B20: Operating Margin (%) | C20: =C19/C11 -> 0.23932489 | D20: =D19/D11 -> 0.2616662 | E20: =E19/E11 -> 0.24911631 | G20: =G19/G11 -> 0.26577697 | H20: =H19/H11 -> 0.29699739 | I20: =I19/I11 -> 0.26183418 | J20: =J19/J11 -> 0.21822917 | K20: =K19/K11 -> 0.24121031 | L20: =L19/L11 -> 0.29302744 | M20: =M19/M11 -> 0.25400113 | N20: =N19/N11 -> 0.20206102 | ... Q20: =Q19/Q11 -> 0.20843099 | S20: =S19/S11 -> 0.25598128 | T20: =T19/T11 -> 0.25528872 | U20: =U19/U11 -> 0.25327211 | V20: =V19/V11 -> 0.24911631 | W20: =W19/W11 -> 0.24834179 | X20: =X19/X11 -> 0.064102254 | Y20: =Y19/Y11 -> 0.049882133 | AA20: =SUM(Y20-U20)*1000 -> -203.38997
B22: Foreign currency gains (losses), net | C22: 3.2 | D22: -1.2 | E22: -6.8 | G22: -0.4 | H22: 0.6 | I22: -1.8 | J22: =SUM(D22-SUM(G22:I22)) -> 0.4 | K22: -2.3 | L22: -1.3 | M22: -0.3 | N22: =SUM(E22-SUM(K22:M22)) -> -2.9 | O22: 4.9 | P22: 0.4 | Q22: 2.957 | S22: =SUM(H22:K22) -> -3.1 | T22: =SUM(I22:L22) -> -5 | U22: =SUM(J22:M22) -> -3.5 | V22: =SUM(K22:N22) -> -6.8 | W22: =SUM(L22:O22) -> 0.4 | X22: =SUM(M22:P22) -> 2.1 | Y22: =SUM(N22:Q22) -> 5.357 | AA22: =SUM(Y22/U22)-1 -> -2.5305714
B23: Interest Income | C23: 1 | D23: 2.4 | E23: 3.5 | G23: 0.2 | H23: 0.5 | I23: 0.5 | J23: =SUM(D23-SUM(G23:I23)) -> 1.2 | K23: 0.4 | L23: 1.1 | M23: 1.4 | N23: =SUM(E23-SUM(K23:M23)) -> 0.6 | O23: 0.3 | P23: 0.4 | Q23: 0.531 | S23: =SUM(H23:K23) -> 2.6 | T23: =SUM(I23:L23) -> 3.2 | U23: =SUM(J23:M23) -> 4.1 | V23: =SUM(K23:N23) -> 3.5 | W23: =SUM(L23:O23) -> 3.4 | X23: =SUM(M23:P23) -> 2.7 | Y23: =SUM(N23:Q23) -> 1.831 | AA23: =SUM(Y23/U23)-1 -> -0.55341463
B24: Interest Expenses | C24: -136.2 | D24: -161.4 | E24: -109.3 | G24: -42.6 | H24: -43.1 | I24: -39.2 | J24: =SUM(D24-SUM(G24:I24)) -> -36.5 | K24: -30.6 | L24: -29.2 | M24: -26.2 | N24: =SUM(E24-SUM(K24:M24)) -> -23.3 | O24: -22.8 | P24: -22.5 | Q24: -21.711 | S24: =SUM(H24:K24) -> -149.4 | T24: =SUM(I24:L24) -> -135.5 | U24: =SUM(J24:M24) -> -122.5 | V24: =SUM(K24:N24) -> -109.3 | W24: =SUM(L24:O24) -> -101.5 | X24: =SUM(M24:P24) -> -94.8 | Y24: =SUM(N24:Q24) -> -90.311 | AA24: =SUM(Y24/U24)-1 -> -0.26276735
B25: Other income, net | C25: -0.3 | D25: -0.3 | E25: 1.2 | G25: -0.3 | H25: 0.7 | I25: 0 | J25: =SUM(D25-SUM(G25:I25)) -> -0.7 | K25: 0 | L25: 0 | M25: 0.2 | N25: =SUM(E25-SUM(K25:M25)) -> 1 | O25: -0.5 | P25: 0.6 | Q25: -0.009 | S25: =SUM(H25:K25) -> 0 | T25: =SUM(I25:L25) -> -0.7 | U25: =SUM(J25:M25) -> -0.5 | V25: =SUM(K25:N25) -> 1.2 | W25: =SUM(L25:O25) -> 0.7 | X25: =SUM(M25:P25) -> 1.3 | Y25: =SUM(N25:Q25) -> 1.091 | AA25: =SUM(Y25/U25)-1 -> -3.182
B26: Earnings before Taxes | C26: =SUM(C22:C25)+C19 -> 718.5 | D26: =SUM(D22:D25)+D19 -> 876.3 | E26: =SUM(E22:E25)+E19 -> 910.5 | G26: =SUM(G22:G25)+G19 -> 191.9 | H26: =SUM(H22:H25)+H19 -> 277.2 | I26: =SUM(I22:I25)+I19 -> 233.3 | J26: =SUM(J22:J25)+J19 -> 173.9 | K26: =SUM(K22:K25)+K19 -> 193.9 | L26: =SUM(L22:L25)+L19 -> 296.3 | M26: =SUM(M22:M25)+M19 -> 244.9 | N26: =SUM(N22:N25)+N19 -> 175.4 | ... Q26: =SUM(Q22:Q25)+Q19 -> 189.428 | S26: =SUM(S22:S25)+S19 -> 878.3 | T26: =SUM(T22:T25)+T19 -> 897.4 | U26: =SUM(U22:U25)+U19 -> 909 | V26: =SUM(V22:V25)+V19 -> 910.5 | W26: =SUM(W22:W25)+W19 -> 921.4 | X26: =SUM(X22:X25)+X19 -> 176.6 | Y26: =SUM(Y22:Y25)+Y19 -> 121.128 | AA26: =SUM(Y26/U26)-1 -> -0.86674587
B27: EBT Margin (%) | C27: =C26/C11 -> 0.2021097 | D27: =D26/D11 -> 0.22115943 | E27: =E26/E11 -> 0.22195948 | G27: =G26/G11 -> 0.21703235 | H27: =H26/H11 -> 0.25848564 | I27: =I26/I11 -> 0.22310414 | J27: =J26/J11 -> 0.18114583 | K27: =K26/K11 -> 0.20658427 | L27: =L26/L11 -> 0.2665767 | M27: =M26/M11 -> 0.23055922 | N27: =N26/N11 -> 0.17720752 | ... Q27: =Q26/Q11 -> 0.1901313 | S27: =S26/S11 -> 0.21866209 | T27: =T26/T11 -> 0.22126338 | U27: =U26/U11 -> 0.22321538 | V27: =V26/V11 -> 0.22195948 | W27: =W26/W11 -> 0.22468787 | X27: =X26/X11 -> 0.042670404 | Y27: =Y26/Y11 -> 0.029740712 | AA27: =SUM(Y27-U27)*1000 -> -193.47467
B29: Income tax expense | C29: -178.3 | D29: -83.7 | E29: 39.5 | G29: -42.2 | H29: -64.8 | I29: -56.4 | J29: =SUM(D29-SUM(G29:I29)) -> 79.7 | K29: -41.6 | L29: -67.5 | M29: -45.1 | N29: =SUM(E29-SUM(K29:M29)) -> 193.7 | O29: -44.8 | P29: -43.7 | Q29: -43.612 | S29: =SUM(H29:K29) -> -83.1 | T29: =SUM(I29:L29) -> -85.8 | U29: =SUM(J29:M29) -> -74.5 | V29: =SUM(K29:N29) -> 39.5 | W29: =SUM(L29:O29) -> 36.3 | X29: =SUM(M29:P29) -> 60.1 | Y29: =SUM(N29:Q29) -> 61.588 | AA29: =SUM(Y29/U29)-1 -> -1.8266846
B30: Net loss | C30: =SUM(C26+SUM(C29:C29)) -> 540.2 | D30: =SUM(D26+SUM(D29:D29)) -> 792.6 | E30: =SUM(E26+SUM(E29:E29)) -> 950 | G30: =SUM(G26+SUM(G29:G29)) -> 149.7 | H30: =SUM(H26+SUM(H29:H29)) -> 212.4 | I30: =SUM(I26+SUM(I29:I29)) -> 176.9 | J30: =SUM(J26+SUM(J29:J29)) -> 253.6 | K30: =SUM(K26+SUM(K29:K29)) -> 152.3 | L30: =SUM(L26+SUM(L29:L29)) -> 228.8 | M30: =SUM(M26+SUM(M29:M29)) -> 199.8 | N30: =SUM(N26+SUM(N29:N29)) -> 369.1 | ... Q30: =SUM(Q26+SUM(Q29:Q29)) -> 145.816 | S30: =SUM(S26+SUM(S29:S29)) -> 795.2 | T30: =SUM(T26+SUM(T29:T29)) -> 811.6 | U30: =SUM(U26+SUM(U29:U29)) -> 834.5 | V30: =SUM(V26+SUM(V29:V29)) -> 950 | W30: =SUM(W26+SUM(W29:W29)) -> 957.7 | X30: =SUM(X26+SUM(X29:X29)) -> 236.7 | Y30: =SUM(Y26+SUM(Y29:Y29)) -> 182.716 | AA30: =SUM(Y30/U30)-1 -> -0.78104733
B31: Net Margin (%) | C31: =C30/C11 -> 0.15195499 | D31: =D30/D11 -> 0.20003533 | E31: =E30/E11 -> 0.2315887 | G31: =G30/G11 -> 0.16930559 | H31: =H30/H11 -> 0.19806043 | I31: =I30/I11 -> 0.16916898 | J31: =J30/J11 -> 0.26416667 | K31: =K30/K11 -> 0.16226294 | L31: =L30/L11 -> 0.20584795 | M31: =M30/M11 -> 0.18810017 | N31: =N30/N11 -> 0.37290362 | ... Q31: =Q30/Q11 -> 0.14635738 | S31: =S30/S11 -> 0.19797346 | T31: =T30/T11 -> 0.20010849 | U31: =U30/U11 -> 0.20492105 | V31: =V30/V11 -> 0.2315887 | W31: =W30/W11 -> 0.2335398 | X31: =X30/X11 -> 0.057191872 | Y31: =Y30/Y11 -> 0.044862491 | AA31: =SUM(Y31-U31)*1000 -> -160.05856
B33: Basic shares | C33: 61.22 | D33: 61.386 | E33: 59.381 | G33: 61.836 | H33: 62.037 | I33: 61.143 | J33: =D33 -> 61.386 | K33: 60.564 | L33: 60.32 | M33: 59.046 | N33: =E33 -> 59.381 | O33: 56.11 | P33: 55.783 | Q33: 53.641 | S33: =K33 -> 60.564 | T33: =L33 -> 60.32 | U33: =M33 -> 59.046 | V33: =N33 -> 59.381 | W33: =O33 -> 56.11 | X33: =P33 -> 55.783 | Y33: =Q33 -> 53.641 | AA33: =SUM(Y33/U33)-1 -> -0.0915388
B34: Basic EPS | C34: =C30/C33 -> 8.8239138 | D34: =D30/D33 -> 12.911739 | E34: =E30/E33 -> 15.998383 | G34: =G30/G33 -> 2.4209199 | H34: =H30/H33 -> 3.4237632 | I34: =I30/I33 -> 2.8932175 | J34: =J30/J33 -> 4.1312351 | K34: =K30/K33 -> 2.5146952 | L34: =L30/L33 -> 3.7931034 | M34: =M30/M33 -> 3.3838025 | N34: =N30/N33 -> 6.2157929 | ... Q34: =Q30/Q33 -> 2.7183684 | S34: =S30/S33 -> 13.129912 | T34: =T30/T33 -> 13.454907 | U34: =U30/U33 -> 14.133049 | V34: =V30/V33 -> 15.998383 | W34: =W30/W33 -> 17.068259 | X34: =X30/X33 -> 4.2432282 | Y34: =Y30/Y33 -> 3.4062751 | AA34: =SUM(Y34/U34)-1 -> -0.75898512
B36: Fully Diluted Shares | C36: 62.006 | D36: 61.952 | E36: 59.832 | G36: 62.629 | H36: 62.603 | I36: 61.615 | J36: =D36 -> 61.952 | K36: 61.054 | L36: 60.766 | M36: 59.501 | N36: =E36 -> 59.832 | O36: 56.502 | P36: 55.783 | Q36: 53.989 | S36: =K36 -> 61.054 | T36: =L36 -> 60.766 | U36: =M36 -> 59.501 | V36: =N36 -> 59.832 | W36: =O36 -> 56.502 | X36: =P36 -> 55.783 | Y36: =Q36 -> 53.989 | AA36: =SUM(Y36/U36)-1 -> -0.092637099
B37: Diluted EPS | C37: =C30/C36 -> 8.7120601 | D37: =D30/D36 -> 12.793776 | E37: =E30/E36 -> 15.877791 | G37: =G30/G36 -> 2.3902665 | H37: =H30/H36 -> 3.3928087 | I37: =I30/I36 -> 2.8710541 | J37: =J30/J36 -> 4.0934917 | K37: =K30/K36 -> 2.4945131 | L37: =L30/L36 -> 3.7652635 | M37: =M30/M36 -> 3.3579268 | N37: =N30/N36 -> 6.1689397 | ... Q37: =Q30/Q36 -> 2.7008465 | S37: =S30/S36 -> 13.024536 | T37: =T30/T36 -> 13.356153 | U37: =U30/U36 -> 14.024974 | V37: =V30/V36 -> 15.877791 | W37: =W30/W36 -> 16.949842 | X37: =X30/X36 -> 4.2432282 | Y37: =Y30/Y36 -> 3.384319 | AA37: =SUM(Y37/U37)-1 -> -0.75869339
A39: X | B39: Balance Sheet | C39: FYE | M39: Quarterly | U39: LTM | AA39: Variance
B40: =B7 -> Fiscal Period | C40: =C7 -> 2022 | D40: =D7 -> 2023 | E40: =E7 -> 2024 | G40: =G7 -> 1Q23 | H40: =H7 -> 2Q23 | I40: =I7 -> 3Q23 | J40: =J7 -> 4Q23 | K40: =K7 -> 1Q24 | L40: =L7 -> 2Q24 | M40: =M7 -> 3Q24 | N40: =N7 -> 4Q24 | ... Q40: =Q7 -> 3Q25 | S40: =S7 -> 1Q24 | T40: =T7 -> 2Q24 | U40: =U7 -> 3Q24 | V40: =V7 -> 4Q24 | W40: =W7 -> 1Q25 | X40: =X7 -> 2Q25 | Y40: =Y7 -> 3Q25
B41: =B8 -> Fiscal Period End Date | C41: =C8 -> 44926 | D41: =D8 -> 45291 | E41: =E8 -> 45657 | G41: =G8 -> 45016 | H41: =H8 -> 45107 | I41: =I8 -> 45199 | J41: =J8 -> 45291 | K41: =K8 -> 45382 | L41: =L8 -> 45473 | M41: =M8 -> 45565 | N41: =N8 -> 45657 | ... Q41: =Q8 -> 45930 | S41: =S8 -> 45382 | T41: =T8 -> 45473 | U41: =U8 -> 45565 | V41: =V8 -> 45657 | W41: =W8 -> 45747 | X41: =X8 -> 45838 | Y41: =Y8 -> 45930
B43: Current Assets
B44: Cash and cash equivalents | C44: 191.6 | D44: 149.3 | E44: 180.5 | G44: 125.7 | H44: 166.2 | I44: 127.3 | J44: =D44 -> 149.3 | K44: 159.3 | L44: 167.7 | M44: 186.1 | N44: =E44 -> 180.5 | O44: 166.5 | P44: 200.6 | Q44: 153.97 | S44: =K44 -> 159.3 | T44: =L44 -> 167.7 | U44: =M44 -> 186.1 | V44: =N44 -> 180.5 | W44: =O44 -> 166.5 | X44: =P44 -> 200.6 | Y44: =Q44 -> 153.97 | AA44: =SUM(Y44/U44)-1 -> -0.17264911
B45: Accounts receivable | C45: 295.6 | D45: 305.7 | E45: 257.7 | G45: 419 | H45: 409.6 | I45: 391.2 | J45: =D45 -> 305.7 | K45: 481.5 | L45: 420.2 | M45: 361.7 | N45: =E45 -> 257.7 | O45: 445.7 | P45: 417.4 | Q45: 335.317 | S45: =K45 -> 481.5 | T45: =L45 -> 420.2 | U45: =M45 -> 361.7 | V45: =N45 -> 257.7 | W45: =O45 -> 445.7 | X45: =P45 -> 417.4 | Y45: =Q45 -> 335.317 | AA45: =SUM(Y45/U45)-1 -> -0.072941664
B46: Inventories | C46: 471.6 | D46: 385.1 | E46: 356.3 | G46: 476.1 | H46: 436.3 | I46: 390.2 | J46: =D46 -> 385.1 | K46: 392 | L46: 376.6 | M46: 367.2 | N46: =E46 -> 356.3 | O46: 391.3 | P46: 405.1 | Q46: 397.073 | S46: =K46 -> 392 | T46: =L46 -> 376.6 | U46: =M46 -> 367.2 | V46: =N46 -> 356.3 | W46: =O46 -> 391.3 | X46: =P46 -> 405.1 | Y46: =Q46 -> 397.073 | AA46: =SUM(Y46/U46)-1 -> 0.081353486
B47: Income taxes receivable | C47: 14.8 | D47: 4.4 | E47: 4 | G47: 3.1 | H47: 2.3 | I47: 3 | J47: =D47 -> 4.4 | K47: 3 | L47: 2.5 | M47: 2.9 | N47: =E47 -> 4 | O47: 4.5 | P47: 6.5 | Q47: 6.437 | S47: =K47 -> 3 | T47: =L47 -> 2.5 | U47: =M47 -> 2.9 | V47: =N47 -> 4 | W47: =O47 -> 4.5 | X47: =P47 -> 6.5 | Y47: =Q47 -> 6.437 | AA47: =SUM(Y47/U47)-1 -> 1.2196552
B48: Other receivables | C48: 18.8 | D48: 21.1 | E48: 22.2 | G48: 31.5 | H48: 28 | I48: 23.4 | J48: =D48 -> 21.1 | K48: 26.4 | L48: 20.3 | M48: 21.6 | N48: =E48 -> 22.2 | O48: 19.7 | P48: 22.2 | Q48: 17.232 | S48: =K48 -> 26.4 | T48: =L48 -> 20.3 | U48: =M48 -> 21.6 | V48: =N48 -> 22.2 | W48: =O48 -> 19.7 | X48: =P48 -> 22.2 | Y48: =Q48 -> 17.232 | AA48: =SUM(Y48/U48)-1 -> -0.20222222
B49: Prepaid expenses and other assets | C49: 33.6 | D49: 45.1 | E49: 51.6 | G49: 59.3 | H49: 58.8 | I49: 44 | J49: =D49 -> 45.1 | K49: 44.3 | L49: 39.6 | M49: 50.9 | N49: =E49 -> 51.6 | O49: 46.3 | P49: 49.9 | Q49: 61.162 | S49: =K49 -> 44.3 | T49: =L49 -> 39.6 | U49: =M49 -> 50.9 | V49: =N49 -> 51.6 | W49: =O49 -> 46.3 | X49: =P49 -> 49.9 | Y49: =Q49 -> 61.162 | AA49: =SUM(Y49/U49)-1 -> 0.201611
B50: Total Current Assets | C50: =SUM(C44:C49) -> 1026 | D50: =SUM(D44:D49) -> 910.7 | E50: =SUM(E44:E49) -> 872.3 | G50: =SUM(G44:G49) -> 1114.7 | H50: =SUM(H44:H49) -> 1101.2 | I50: =SUM(I44:I49) -> 979.1 | J50: =SUM(J44:J49) -> 910.7 | K50: =SUM(K44:K49) -> 1106.5 | L50: =SUM(L44:L49) -> 1026.9 | M50: =SUM(M44:M49) -> 990.4 | N50: =SUM(N44:N49) -> 872.3 | ... Q50: =SUM(Q44:Q49) -> 971.191 | S50: =SUM(S44:S49) -> 1106.5 | T50: =SUM(T44:T49) -> 1026.9 | U50: =SUM(U44:U49) -> 990.4 | V50: =SUM(V44:V49) -> 872.3 | W50: =SUM(W44:W49) -> 1074 | X50: =SUM(X44:X49) -> 1101.7 | Y50: =SUM(Y44:Y49) -> 971.191 | AA50: =SUM(Y50/U50)-1 -> -0.019395194
B52: Non-Current Assets
...

Sheet Revenue Drivers
B2: ='Historical Financials'!B2 -> Crocs Inc (NASDAQ: CROX) | C2: FYE | M2: Quarterly | U2: LTM | AA2: Variance
B3: Segment Anaysis | C3: ='Historical Financials'!C7 -> 2022 | D3: ='Historical Financials'!D7 -> 2023 | E3: ='Historical Financials'!E7 -> 2024 | G3: ='Historical Financials'!G7 -> 1Q23 | H3: ='Historical Financials'!H7 -> 2Q23 | I3: ='Historical Financials'!I7 -> 3Q23 | J3: ='Historical Financials'!J7 -> 4Q23 | K3: ='Historical Financials'!K7 -> 1Q24 | L3: ='Historical Financials'!L7 -> 2Q24 | M3: ='Historical Financials'!M7 -> 3Q24 | N3: ='Historical Financials'!N7 -> 4Q24 | ... Q3: ='Historical Financials'!Q7 -> 3Q25 | S3: =J3 -> 4Q23 | T3: =K3 -> 1Q24 | U3: =L3 -> 2Q24 | V3: =M3 -> 3Q24 | W3: =N3 -> 4Q24 | X3: =O3 -> 1Q25 | Y3: =Q3 -> 3Q25
B4: ($ In Millions) | C4: ='Historical Financials'!C8 -> 44926 | D4: ='Historical Financials'!D8 -> 45291 | E4: ='Historical Financials'!E8 -> 45657 | G4: ='Historical Financials'!G8 -> 45016 | H4: ='Historical Financials'!H8 -> 45107 | I4: ='Historical Financials'!I8 -> 45199 | J4: ='Historical Financials'!J8 -> 45291 | K4: ='Historical Financials'!K8 -> 45382 | L4: ='Historical Financials'!L8 -> 45473 | M4: ='Historical Financials'!M8 -> 45565 | N4: ='Historical Financials'!N8 -> 45657 | ... Q4: ='Historical Financials'!Q8 -> 45930 | S4: =J4 -> 45291 | T4: =K4 -> 45382 | U4: =L4 -> 45473 | V4: =M4 -> 45565 | W4: =N4 -> 45657 | X4: =O4 -> 45747 | Y4: =Q4 -> 45930
A6: X | B6: Revenue by reportable segment
A8: X | B8: Revenue Segment Anaysis
B9: Crox Revenues | C9: =C20 -> 2659 | D9: =D20 -> 3013 | E9: =E20 -> 3278 | G9: =G20 -> 648.8 | H9: =H20 -> 832.9 | I9: =I20 -> 798.8 | J9: =J20 -> 732.5 | K9: =K20 -> 743.8 | L9: =L20 -> 914 | M9: =M20 -> 858.1 | N9: =N20 -> 762.1 | ... Q9: =Q20 -> 836.229 | S9: =SUM(H9:K9) -> 3108 | T9: =SUM(I9:L9) -> 3189.1 | U9: =SUM(J9:M9) -> 3248.4 | V9: =SUM(K9:N9) -> 3278 | W9: =SUM(L9:O9) -> 3295.8 | X9: =SUM(M9:P9) -> 3341.4 | Y9: =SUM(N9:Q9) -> 3319.529 | AA9: =SUM(Y9/U9)-1 -> 0.021896626
B10: HEYDUDE Revenues | C10: =C29 -> 896 | D10: =D29 -> 949 | E10: =E29 -> 824 | G10: =G29 -> 235.4 | H10: =H29 -> 239.4 | I10: =I29 -> 246.9 | J10: =J29 -> 227.3 | K10: =K29 -> 194.9 | L10: =L29 -> 197.5 | M10: =M29 -> 204.1 | N10: =N29 -> 227.5 | ... Q10: =Q29 -> 160.072 | S10: =SUM(H10:K10) -> 908.5 | T10: =SUM(I10:L10) -> 866.6 | U10: =SUM(J10:M10) -> 823.8 | V10: =SUM(K10:N10) -> 824 | W10: =SUM(L10:O10) -> 804.8 | X10: =SUM(M10:P10) -> 797.1 | Y10: =SUM(N10:Q10) -> 753.072 | AA10: =SUM(Y10/U10)-1 -> -0.08585579
B11: Total Net Revenue | C11: =SUM(C9:C10) -> 3555 | D11: =SUM(D9:D10) -> 3962 | E11: =SUM(E9:E10) -> 4102 | G11: =SUM(G9:G10) -> 884.2 | H11: =SUM(H9:H10) -> 1072.3 | I11: =SUM(I9:I10) -> 1045.7 | J11: =SUM(J9:J10) -> 959.8 | K11: =SUM(K9:K10) -> 938.7 | L11: =SUM(L9:L10) -> 1111.5 | M11: =SUM(M9:M10) -> 1062.2 | N11: =SUM(N9:N10) -> 989.6 | ... Q11: =SUM(Q9:Q10) -> 996.301 | S11: =SUM(S9:S10) -> 4016.5 | T11: =SUM(T9:T10) -> 4055.7 | U11: =SUM(U9:U10) -> 4072.2 | V11: =SUM(V9:V10) -> 4102 | W11: =SUM(W9:W10) -> 4100.6 | X11: =SUM(X9:X10) -> 4138.5 | Y11: =SUM(Y9:Y10) -> 4072.601 | AA11: =SUM(Y11/U11)-1 -> 9.847257e-05
B12: Variance Check | C12: =ROUND(C11-'Historical Financials'!C11,1) -> 0 | D12: =ROUND(D11-'Historical Financials'!D11,-1) -> 0 | E12: =ROUND(E11-'Historical Financials'!E11,-1) -> 0 | G12: =ROUND(G11-'Historical Financials'!G11,-1) -> 0 | H12: =ROUND(H11-'Historical Financials'!H11,-1) -> 0 | I12: =ROUND(I11-'Historical Financials'!I11,-1) -> 0 | J12: =ROUND(J11-'Historical Financials'!J11,-1) -> 0 | K12: =ROUND(K11-'Historical Financials'!K11,-1) -> 0 | L12: =ROUND(L11-'Historical Financials'!L11,-1) -> 0 | M12: =ROUND(M11-'Historical Financials'!M11,-1) -> 0 | N12: =ROUND(N11-'Historical Financials'!N11,-1) -> 0 | ... Q12: =ROUND(Q11-'Historical Financials'!Q11,-1) -> 0 | S12: =ROUND(S11-'Historical Financials'!S11,-1) -> 0 | T12: =ROUND(T11-'Historical Financials'!T11,-1) -> 0 | U12: =ROUND(U11-'Historical Financials'!U11,-1) -> 0 | V12: =ROUND(V11-'Historical Financials'!V11,-1) -> 0 | W12: =ROUND(W11-'Historical Financials'!W11,-1) -> 0 | X12: =ROUND(X11-'Historical Financials'!X11,-1) -> 0 | Y12: =ROUND(Y11-'Historical Financials'!Y11,-1) -> 0
B14: =B9&"(%)" -> Crox Revenues(%) | C14: =SUM(C9/C$11) -> 0.74796062 | D14: =SUM(D9/D$11) -> 0.76047451 | E14: =SUM(E9/E$11) -> 0.79912238 | G14: =SUM(G9/G$11) -> 0.73377064 | H14: =SUM(H9/H$11) -> 0.77674158 | I14: =SUM(I9/I$11) -> 0.76389022 | J14: =SUM(J9/J$11) -> 0.76317983 | K14: =SUM(K9/K$11) -> 0.79237243 | L14: =SUM(L9/L$11) -> 0.82231219 | M14: =SUM(M9/M$11) -> 0.80785163 | N14: =SUM(N9/N$11) -> 0.77010914 | ... Q14: =SUM(Q9/Q$11) -> 0.8393337 | S14: =K14 -> 0.79237243 | T14: =L14 -> 0.82231219 | U14: =M14 -> 0.80785163 | V14: =N14 -> 0.77010914 | W14: =O14 -> 0.81254668 | X14: =P14 -> 0.83487037 | Y14: =Q14 -> 0.8393337 | AA14: =SUM(Y14-U14)*10000 -> 314.82067
B15: =B10&"(%)" -> HEYDUDE Revenues(%) | C15: =SUM(C10/C$11) -> 0.25203938 | D15: =SUM(D10/D$11) -> 0.23952549 | E15: =SUM(E10/E$11) -> 0.20087762 | G15: =SUM(G10/G$11) -> 0.26622936 | H15: =SUM(H10/H$11) -> 0.22325842 | I15: =SUM(I10/I$11) -> 0.23610978 | J15: =SUM(J10/J$11) -> 0.23682017 | K15: =SUM(K10/K$11) -> 0.20762757 | L15: =SUM(L10/L$11) -> 0.17768781 | M15: =SUM(M10/M$11) -> 0.19214837 | N15: =SUM(N10/N$11) -> 0.22989086 | ... Q15: =SUM(Q10/Q$11) -> 0.1606663 | S15: =K15 -> 0.20762757 | T15: =L15 -> 0.17768781 | U15: =M15 -> 0.19214837 | V15: =N15 -> 0.22989086 | W15: =O15 -> 0.18745332 | X15: =P15 -> 0.16512963 | Y15: =Q15 -> 0.1606663 | AA15: =SUM(Y15-U15)*10000 -> -314.82067
A17: X | B17: Revenue: Crocs
B18: Crocs Wholesale | C18: 1377 | D18: 1778 | E18: 1608 | G18: 410.6 | H18: 407.3 | I18: 369.2 | J18: =SUM(D18-SUM(G18:I18)) -> 590.9 | K18: 382.9 | L18: 435.3 | M18: 395.6 | N18: =SUM(E18-SUM(K18:M18)) -> 394.2 | O18: 368.5 | P18: 464.7 | Q18: 364.356 | S18: =SUM(H18:K18) -> 1750.3 | T18: =SUM(I18:L18) -> 1778.3 | U18: =SUM(J18:M18) -> 1804.7 | V18: =SUM(K18:N18) -> 1608 | W18: =SUM(L18:O18) -> 1593.6 | X18: =SUM(M18:P18) -> 1623 | Y18: =SUM(N18:Q18) -> 1591.756 | AA18: =SUM(Y18/U18)-1 -> -0.11799413
B19: Crocs DTC | C19: 1282 | D19: 1235 | E19: 1670 | G19: 238.2 | H19: 425.6 | I19: 429.6 | J19: =SUM(D19-SUM(G19:I19)) -> 141.6 | K19: 360.9 | L19: 478.7 | M19: 462.5 | N19: =SUM(E19-SUM(K19:M19)) -> 367.9 | O19: 393.1 | P19: 494.9 | Q19: 471.873 | S19: =SUM(H19:K19) -> 1357.7 | T19: =SUM(I19:L19) -> 1410.8 | U19: =SUM(J19:M19) -> 1443.7 | V19: =SUM(K19:N19) -> 1670 | W19: =SUM(L19:O19) -> 1702.2 | X19: =SUM(M19:P19) -> 1718.4 | Y19: =SUM(N19:Q19) -> 1727.773 | AA19: =SUM(Y19/U19)-1 -> 0.19676733
B20: Total Net Revenue | C20: =SUM(C18:C19) -> 2659 | D20: =SUM(D18:D19) -> 3013 | E20: =SUM(E18:E19) -> 3278 | G20: =SUM(G18:G19) -> 648.8 | H20: =SUM(H18:H19) -> 832.9 | I20: =SUM(I18:I19) -> 798.8 | J20: =SUM(J18:J19) -> 732.5 | K20: =SUM(K18:K19) -> 743.8 | L20: =SUM(L18:L19) -> 914 | M20: =SUM(M18:M19) -> 858.1 | N20: =SUM(N18:N19) -> 762.1 | ... Q20: =SUM(Q18:Q19) -> 836.229 | S20: =SUM(S18:S19) -> 3108 | T20: =SUM(T18:T19) -> 3189.1 | U20: =SUM(U18:U19) -> 3248.4 | V20: =SUM(V18:V19) -> 3278 | W20: =SUM(W18:W19) -> 3295.8 | X20: =SUM(X18:X19) -> 3341.4 | Y20: =SUM(Y18:Y19) -> 3319.529 | AA20: =SUM(Y20/U20)-1 -> 0.021896626
B21: Variance Check | C21: =C20-C9 -> 0 | D21: =D20-D9 -> 0 | E21: =E20-E9 -> 0 | G21: =G20-G9 -> 0 | H21: =H20-H9 -> 0 | I21: =I20-I9 -> 0 | J21: =J20-J9 -> 0 | K21: =K20-K9 -> 0 | L21: =L20-L9 -> 0 | M21: =M20-M9 -> 0 | N21: =N20-N9 -> 0 | ... Q21: =Q20-Q9 -> 0 | S21: =S20-S9 -> 0 | T21: =T20-T9 -> 0 | U21: =U20-U9 -> 0 | V21: =V20-V9 -> 0 | W21: =W20-W9 -> 0 | X21: =X20-X9 -> 0 | Y21: =Y20-Y9 -> 0
B23: =B18&"(%)" -> Crocs Wholesale (%) | C23: =SUM(C18/C$11) -> 0.38734177 | D23: =SUM(D18/D$11) -> 0.44876325 | E23: =SUM(E18/E$11) -> 0.3920039 | G23: =SUM(G18/G$11) -> 0.46437458 | H23: =SUM(H18/H$11) -> 0.37983773 | I23: =SUM(I18/I$11) -> 0.35306493 | J23: =SUM(J18/J$11) -> 0.61564909 | K23: =SUM(K18/K$11) -> 0.40790455 | L23: =SUM(L18/L$11) -> 0.39163293 | M23: =SUM(M18/M$11) -> 0.37243457 | N23: =SUM(N18/N$11) -> 0.39834276 | ... Q23: =SUM(Q18/Q$11) -> 0.36570876 | S23: =K23 -> 0.40790455 | T23: =L23 -> 0.39163293 | U23: =M23 -> 0.37243457 | V23: =N23 -> 0.39834276 | W23: =O23 -> 0.39315054 | X23: =P23 -> 0.40429789 | Y23: =Q23 -> 0.36570876 | AA23: =SUM(Y23-U23)*10000 -> -67.258131
B24: =B19&"(%)" -> Crocs DTC (%) | C24: =SUM(C19/C$11) -> 0.36061885 | D24: =SUM(D19/D$11) -> 0.31171126 | E24: =SUM(E19/E$11) -> 0.40711848 | G24: =SUM(G19/G$11) -> 0.26939606 | H24: =SUM(H19/H$11) -> 0.39690385 | I24: =SUM(I19/I$11) -> 0.41082528 | J24: =SUM(J19/J$11) -> 0.14753074 | K24: =SUM(K19/K$11) -> 0.38446788 | L24: =SUM(L19/L$11) -> 0.43067926 | M24: =SUM(M19/M$11) -> 0.43541706 | N24: =SUM(N19/N$11) -> 0.37176637 | ... Q24: =SUM(Q19/Q$11) -> 0.47362494 | S24: =K24 -> 0.38446788 | T24: =L24 -> 0.43067926 | U24: =M24 -> 0.43541706 | V24: =N24 -> 0.37176637 | W24: =O24 -> 0.41939614 | X24: =P24 -> 0.43057247 | Y24: =Q24 -> 0.47362494 | AA24: =SUM(Y24-U24)*10000 -> 382.0788
A26: X | B26: Revenue: HEYDUDE
B27: HEYDUDE Wholesale | C27: 574 | D27: 567 | E27: 456 | G27: 167.9 | H27: 148.8 | I27: 146.5 | J27: =SUM(D27-SUM(G27:I27)) -> 103.8 | K27: 134.8 | L27: 113.8 | M27: 113 | N27: =SUM(E27-SUM(K27:M27)) -> 94.4 | O27: 110.7 | P27: 99.8 | Q27: 69.402 | S27: =SUM(H27:K27) -> 533.9 | T27: =SUM(I27:L27) -> 498.9 | U27: =SUM(J27:M27) -> 465.4 | V27: =SUM(K27:N27) -> 456 | W27: =SUM(L27:O27) -> 431.9 | X27: =SUM(M27:P27) -> 417.9 | Y27: =SUM(N27:Q27) -> 374.302 | AA27: =SUM(Y27/U27)-1 -> -0.1957413
B28: HEYDUDE DTC | C28: 322 | D28: 382 | E28: 368 | G28: 67.5 | H28: 90.6 | I28: 100.4 | J28: =SUM(D28-SUM(G28:I28)) -> 123.5 | K28: 60.1 | L28: 83.7 | M28: 91.1 | N28: =SUM(E28-SUM(K28:M28)) -> 133.1 | O28: 65 | P28: 90 | Q28: 90.67 | S28: =SUM(H28:K28) -> 374.6 | T28: =SUM(I28:L28) -> 367.7 | U28: =SUM(J28:M28) -> 358.4 | V28: =SUM(K28:N28) -> 368 | W28: =SUM(L28:O28) -> 372.9 | X28: =SUM(M28:P28) -> 379.2 | Y28: =SUM(N28:Q28) -> 378.77 | AA28: =SUM(Y28/U28)-1 -> 0.056835938
B29: Total Net Revenue | C29: =SUM(C27:C28) -> 896 | D29: =SUM(D27:D28) -> 949 | E29: =SUM(E27:E28) -> 824 | G29: =SUM(G27:G28) -> 235.4 | H29: =SUM(H27:H28) -> 239.4 | I29: =SUM(I27:I28) -> 246.9 | J29: =SUM(J27:J28) -> 227.3 | K29: =SUM(K27:K28) -> 194.9 | L29: =SUM(L27:L28) -> 197.5 | M29: =SUM(M27:M28) -> 204.1 | N29: =SUM(N27:N28) -> 227.5 | ... Q29: =SUM(Q27:Q28) -> 160.072 | S29: =SUM(S27:S28) -> 908.5 | T29: =SUM(T27:T28) -> 866.6 | U29: =SUM(U27:U28) -> 823.8 | V29: =SUM(V27:V28) -> 824 | W29: =SUM(W27:W28) -> 804.8 | X29: =SUM(X27:X28) -> 797.1 | Y29: =SUM(Y27:Y28) -> 753.072 | AA29: =SUM(Y29/U29)-1 -> -0.08585579
B30: Variance Check | C30: =C29-C10 -> 0 | D30: =D29-D10 -> 0 | E30: =E29-E10 -> 0 | G30: =G29-G10 -> 0 | H30: =H29-H10 -> 0 | I30: =I29-I10 -> 0 | J30: =J29-J10 -> 0 | K30: =K29-K10 -> 0 | L30: =L29-L10 -> 0 | M30: =M29-M10 -> 0 | N30: =N29-N10 -> 0 | ... Q30: =Q29-Q10 -> 0 | S30: =S29-S10 -> 0 | T30: =T29-T10 -> 0 | U30: =U29-U10 -> 0 | V30: =V29-V10 -> 0 | W30: =W29-W10 -> 0 | X30: =X29-X10 -> 0 | Y30: =Y29-Y10 -> 0
B32: =B27&"(%)" -> HEYDUDE Wholesale (%) | C32: =SUM(C27/C$11) -> 0.16146273 | D32: =SUM(D27/D$11) -> 0.14310954 | E32: =SUM(E27/E$11) -> 0.11116529 | G32: =SUM(G27/G$11) -> 0.18988917 | H32: =SUM(H27/H$11) -> 0.13876714 | I32: =SUM(I27/I$11) -> 0.14009754 | J32: =SUM(J27/J$11) -> 0.10814753 | K32: =SUM(K27/K$11) -> 0.14360286 | L32: =SUM(L27/L$11) -> 0.10238417 | M32: =SUM(M27/M$11) -> 0.10638298 | N32: =SUM(N27/N$11) -> 0.095392078 | ... Q32: =SUM(Q27/Q$11) -> 0.069659671 | S32: =K32 -> 0.14360286 | T32: =L32 -> 0.10238417 | U32: =M32 -> 0.10638298 | V32: =N32 -> 0.095392078 | W32: =O32 -> 0.1181052 | X32: =P32 -> 0.08682791 | Y32: =Q32 -> 0.069659671 | AA32: =SUM(Y32-U32)*10000 -> -367.23308
B33: =B28&"(%)" -> HEYDUDE DTC (%) | C33: =SUM(C28/C$11) -> 0.090576653 | D33: =SUM(D28/D$11) -> 0.096415952 | E33: =SUM(E28/E$11) -> 0.089712335 | G33: =SUM(G28/G$11) -> 0.076340195 | H33: =SUM(H28/H$11) -> 0.08449128 | I33: =SUM(I28/I$11) -> 0.096012241 | J33: =SUM(J28/J$11) -> 0.12867264 | K33: =SUM(K28/K$11) -> 0.064024715 | L33: =SUM(L28/L$11) -> 0.075303644 | M33: =SUM(M28/M$11) -> 0.085765393 | N33: =SUM(N28/N$11) -> 0.13449879 | ... Q33: =SUM(Q28/Q$11) -> 0.091006634 | S33: =K33 -> 0.064024715 | T33: =L33 -> 0.075303644 | U33: =M33 -> 0.085765393 | V33: =N33 -> 0.13449879 | W33: =O33 -> 0.069348128 | X33: =P33 -> 0.078301723 | Y33: =Q33 -> 0.091006634 | AA33: =SUM(Y33-U33)*10000 -> 52.41241

Sheet FCF
B2: ='Historical Financials'!B2 -> Crocs Inc (NASDAQ: CROX) | D2: FYE | G2: Quarterly | M2: Quarterly | U2: LTM | V2: LTM | AB2: Variance
B3: FCF Analysis | C3: ='Historical Financials'!C7 -> 2022 | D3: ='Historical Financials'!D7 -> 2023 | E3: ='Historical Financials'!E7 -> 2024 | G3: ='Historical Financials'!G7 -> 1Q23 | H3: ='Historical Financials'!H7 -> 2Q23 | I3: ='Historical Financials'!I7 -> 3Q23 | J3: ='Historical Financials'!J7 -> 4Q23 | K3: ='Historical Financials'!K7 -> 1Q24 | L3: ='Historical Financials'!L7 -> 2Q24 | M3: ='Historical Financials'!M7 -> 3Q24 | N3: ='Historical Financials'!N7 -> 4Q24 | ... Q3: ='Historical Financials'!Q7 -> 3Q25 | S3: =J3 -> 4Q23 | T3: =K3 -> 1Q24 | U3: =L3 -> 2Q24 | V3: =M3 -> 3Q24 | W3: =N3 -> 4Q24 | X3: =O3 -> 1Q25 | Y3: =P3 -> 2Q25 | Z3: =Q3 -> 3Q25
B4: ($ In Millions) | C4: ='Historical Financials'!C8 -> 44926 | D4: ='Historical Financials'!D8 -> 45291 | E4: ='Historical Financials'!E8 -> 45657 | G4: ='Historical Financials'!G8 -> 45016 | H4: ='Historical Financials'!H8 -> 45107 | I4: ='Historical Financials'!I8 -> 45199 | J4: ='Historical Financials'!J8 -> 45291 | K4: ='Historical Financials'!K8 -> 45382 | L4: ='Historical Financials'!L8 -> 45473 | M4: ='Historical Financials'!M8 -> 45565 | N4: ='Historical Financials'!N8 -> 45657 | ... Q4: ='Historical Financials'!Q8 -> 45930 | S4: =J4 -> 45291 | T4: =K4 -> 45382 | U4: =L4 -> 45473 | V4: =M4 -> 45565 | W4: =N4 -> 45657 | X4: =O4 -> 45747 | Y4: =P4 -> 45838 | Z4: =Q4 -> 45930
B6: ='Revenue Drivers'!B9 -> Crox Revenues | C6: ='Revenue Drivers'!C9 -> 2659 | D6: ='Revenue Drivers'!D9 -> 3013 | E6: ='Revenue Drivers'!E9 -> 3278 | G6: ='Revenue Drivers'!G9 -> 648.8 | H6: ='Revenue Drivers'!H9 -> 832.9 | I6: ='Revenue Drivers'!I9 -> 798.8 | J6: ='Revenue Drivers'!J9 -> 732.5 | K6: ='Revenue Drivers'!K9 -> 743.8 | L6: ='Revenue Drivers'!L9 -> 914 | M6: ='Revenue Drivers'!M9 -> 858.1 | N6: ='Revenue Drivers'!N9 -> 762.1 | ... Q6: ='Revenue Drivers'!Q9 -> 836.229 | S6: =SUM(G6:J6) -> 3013 | T6: =SUM(H6:K6) -> 3108 | U6: =SUM(I6:L6) -> 3189.1 | V6: =SUM(J6:M6) -> 3248.4 | W6: =SUM(K6:N6) -> 3278 | X6: =SUM(L6:O6) -> 3295.8 | Y6: =SUM(M6:P6) -> 3341.4 | Z6: =SUM(N6:Q6) -> 3319.529 | AB6: =SUM(Z6/V6)-1 -> 0.021896626
B7: ='Revenue Drivers'!B10 -> HEYDUDE Revenues | C7: ='Revenue Drivers'!C10 -> 896 | D7: ='Revenue Drivers'!D10 -> 949 | E7: ='Revenue Drivers'!E10 -> 824 | G7: ='Revenue Drivers'!G10 -> 235.4 | H7: ='Revenue Drivers'!H10 -> 239.4 | I7: ='Revenue Drivers'!I10 -> 246.9 | J7: ='Revenue Drivers'!J10 -> 227.3 | K7: ='Revenue Drivers'!K10 -> 194.9 | L7: ='Revenue Drivers'!L10 -> 197.5 | M7: ='Revenue Drivers'!M10 -> 204.1 | N7: ='Revenue Drivers'!N10 -> 227.5 | ... Q7: ='Revenue Drivers'!Q10 -> 160.072 | S7: =SUM(G7:J7) -> 949 | T7: =SUM(H7:K7) -> 908.5 | U7: =SUM(I7:L7) -> 866.6 | V7: =SUM(J7:M7) -> 823.8 | W7: =SUM(K7:N7) -> 824 | X7: =SUM(L7:O7) -> 804.8 | Y7: =SUM(M7:P7) -> 797.1 | Z7: =SUM(N7:Q7) -> 753.072 | AB7: =SUM(Z7/V7)-1 -> -0.08585579
B8: Total Revenue | C8: =SUM(C6:C7) -> 3555 | D8: =SUM(D6:D7) -> 3962 | E8: =SUM(E6:E7) -> 4102 | G8: =SUM(G6:G7) -> 884.2 | H8: =SUM(H6:H7) -> 1072.3 | I8: =SUM(I6:I7) -> 1045.7 | J8: =SUM(J6:J7) -> 959.8 | K8: =SUM(K6:K7) -> 938.7 | L8: =SUM(L6:L7) -> 1111.5 | M8: =SUM(M6:M7) -> 1062.2 | N8: =SUM(N6:N7) -> 989.6 | ... Q8: =SUM(Q6:Q7) -> 996.301 | S8: =SUM(S6:S7) -> 3962 | T8: =SUM(T6:T7) -> 4016.5 | U8: =SUM(U6:U7) -> 4055.7 | V8: =SUM(V6:V7) -> 4072.2 | W8: =SUM(W6:W7) -> 4102 | X8: =SUM(X6:X7) -> 4100.6 | Y8: =SUM(Y6:Y7) -> 4138.5 | Z8: =SUM(Z6:Z7) -> 4072.601 | AB8: =SUM(Z8/V8)-1 -> 9.847257e-05
B9: Y/Y Growth (%) | D9: =SUM(D8/C8)-1 -> 0.11448664 | E9: =SUM(E8/D8)-1 -> 0.035335689 | K9: =SUM(K8/G8)-1 -> 0.061637639 | L9: =SUM(L8/H8)-1 -> 0.036556934 | M9: =SUM(M8/I8)-1 -> 0.015778904 | N9: =SUM(N8/J8)-1 -> 0.031048135 | O9: =SUM(O8/K8)-1 -> -0.0014914243 | P9: =SUM(P8/L8)-1 -> 0.034098066 | Q9: =SUM(Q8/M8)-1 -> -0.062040105 | W9: =SUM(W8/S8)-1 -> 0.035335689 | X9: =SUM(X8/T8)-1 -> 0.020938628 | Y9: =SUM(Y8/U8)-1 -> 0.020415711 | Z9: =SUM(Z8/V8)-1 -> 9.847257e-05 | AB9: =SUM(Z9-V9)*10000 -> 0.9847257
B10: Q/Q Growth (%) | C10: N/A | D10: N/A | E10: N/A | H10: =SUM(H8/G8)-1 -> 0.21273468 | I10: =SUM(I8/H8)-1 -> -0.024806491 | J10: =SUM(J8/I8)-1 -> -0.082145931 | K10: =SUM(K8/J8)-1 -> -0.021983747 | L10: =SUM(L8/K8)-1 -> 0.18408437 | M10: =SUM(M8/L8)-1 -> -0.044354476 | N10: =SUM(N8/M8)-1 -> -0.06834871 | O10: =SUM(O8/N8)-1 -> -0.052849636 | ... Q10: =SUM(Q8/P8)-1 -> -0.13319906 | S10: N/A | T10: N/A | U10: N/A | V10: N/A | W10: N/A | X10: N/A | Y10: N/A | Z10: N/A
B12: (-) Cost of Sales | C12: ='Historical Financials'!C13 -> -1694.7 | D12: ='Historical Financials'!D13 -> -1752.3 | E12: ='Historical Financials'!E13 -> -1691.9 | G12: ='Historical Financials'!G13 -> -407.8 | H12: ='Historical Financials'!H13 -> -451.1 | I12: ='Historical Financials'!I13 -> -464.1 | J12: ='Historical Financials'!J13 -> -429.3 | K12: ='Historical Financials'!K13 -> -416.6 | L12: ='Historical Financials'!L13 -> -429.6 | M12: ='Historical Financials'!M13 -> -428.9 | N12: ='Historical Financials'!N13 -> -416.8 | ... Q12: ='Historical Financials'!Q13 -> -413.293 | S12: =SUM(G12:J12) -> -1752.3 | T12: =SUM(H12:K12) -> -1761.1 | U12: =SUM(I12:L12) -> -1739.6 | V12: =SUM(J12:M12) -> -1704.4 | W12: =SUM(K12:N12) -> -1691.9 | X12: =SUM(L12:O12) -> -1671.1 | Y12: =SUM(M12:P12) -> -1682 | Z12: =SUM(N12:Q12) -> -1666.393 | AB12: =SUM(Z12/V12)-1 -> -0.022299343
B13: Gross Profit | C13: =SUM(C8+SUM(C12:C12)) -> 1860.3 | D13: =SUM(D8+SUM(D12:D12)) -> 2209.7 | E13: =SUM(E8+SUM(E12:E12)) -> 2410.1 | G13: =SUM(G8+SUM(G12:G12)) -> 476.4 | H13: =SUM(H8+SUM(H12:H12)) -> 621.2 | I13: =SUM(I8+SUM(I12:I12)) -> 581.6 | J13: =SUM(J8+SUM(J12:J12)) -> 530.5 | K13: =SUM(K8+SUM(K12:K12)) -> 522.1 | L13: =SUM(L8+SUM(L12:L12)) -> 681.9 | M13: =SUM(M8+SUM(M12:M12)) -> 633.3 | N13: =SUM(N8+SUM(N12:N12)) -> 572.8 | ... Q13: =SUM(Q8+SUM(Q12:Q12)) -> 583.008 | S13: =SUM(S8+SUM(S12:S12)) -> 2209.7 | T13: =SUM(T8+SUM(T12:T12)) -> 2255.4 | U13: =SUM(U8+SUM(U12:U12)) -> 2316.1 | V13: =SUM(V8+SUM(V12:V12)) -> 2367.8 | W13: =SUM(W8+SUM(W12:W12)) -> 2410.1 | X13: =SUM(X8+SUM(X12:X12)) -> 2429.5 | Y13: =SUM(Y8+SUM(Y12:Y12)) -> 2456.5 | Z13: =SUM(Z8+SUM(Z12:Z12)) -> 2406.208 | AB13: =SUM(Z13/V13)-1 -> 0.016220965
B14: Gross Margin (%) | C14: =C13/C8 -> 0.52329114 | D14: =D13/D8 -> 0.55772337 | E14: =E13/E8 -> 0.58754266 | G14: =G13/G8 -> 0.53879213 | H14: =H13/H8 -> 0.57931549 | I14: =I13/I8 -> 0.55618246 | J14: =J13/J8 -> 0.55271932 | K14: =K13/K8 -> 0.55619474 | L14: =L13/L8 -> 0.61349528 | M14: =M13/M8 -> 0.5962154 | N14: =N13/N8 -> 0.57881973 | ... Q14: =Q13/Q8 -> 0.58517255 | S14: =S13/S8 -> 0.55772337 | T14: =T13/T8 -> 0.56153367 | U14: =U13/U8 -> 0.57107281 | V14: =V13/V8 -> 0.58145474 | W14: =W13/W8 -> 0.58754266 | X14: =X13/X8 -> 0.59247427 | Y14: =Y13/Y8 -> 0.59357255 | Z14: =Z13/Z8 -> 0.59082832 | AB14: =SUM(Z14-V14)*10000 -> 93.735764
B16: (-) Selling, General, and Administrative | C16: ='Historical Financials'!C17 -> -1009.5 | D16: ='Historical Financials'!D17 -> -1173.2 | E16: ='Historical Financials'!E17 -> -1388.3 | G16: ='Historical Financials'!G17 -> -241.4 | H16: ='Historical Financials'!H17 -> -302.8 | I16: ='Historical Financials'!I17 -> -307.8 | J16: ='Historical Financials'!J17 -> -321.2 | K16: ='Historical Financials'!K17 -> -295.6 | L16: ='Historical Financials'!L17 -> -356.2 | M16: ='Historical Financials'!M17 -> -363.5 | N16: ='Historical Financials'!N17 -> -373 | ... Q16: ='Historical Financials'!Q17 -> -375.348 | S16: =SUM(G16:J16) -> -1173.2 | T16: =SUM(H16:K16) -> -1227.4 | U16: =SUM(I16:L16) -> -1280.8 | V16: =SUM(J16:M16) -> -1336.5 | W16: =SUM(K16:N16) -> -1388.3 | X16: =SUM(L16:O16) -> -1411.3 | Y16: =SUM(M16:P16) -> -1453.3 | Z16: =SUM(N16:Q16) -> -1465.148 | AB16: =SUM(Z16/V16)-1 -> 0.096257389
B17: (-) Asset Impairments | C17: ='Historical Financials'!C18 -> 0 | D17: ='Historical Financials'!D18 -> 0 | E17: ='Historical Financials'!E18 -> 0 | G17: ='Historical Financials'!G18 -> 0 | H17: ='Historical Financials'!H18 -> 0 | I17: ='Historical Financials'!I18 -> 0 | J17: ='Historical Financials'!J18 -> 0 | K17: ='Historical Financials'!K18 -> 0 | L17: ='Historical Financials'!L18 -> 0 | M17: ='Historical Financials'!M18 -> 0 | N17: ='Historical Financials'!N18 -> 0 | ... Q17: ='Historical Financials'!Q18 -> 0 | S17: =SUM(G17:J17) -> 0 | T17: =SUM(H17:K17) -> 0 | U17: =SUM(I17:L17) -> 0 | V17: =SUM(J17:M17) -> 0 | W17: =SUM(K17:N17) -> 0 | X17: =SUM(L17:O17) -> 0 | Y17: =SUM(M17:P17) -> -738.1 | Z17: =SUM(N17:Q17) -> -738.1 | AB17: =SUM(Z17/V17)-1 -> #DIV/0!
B18: Earning before Interest & Taxes (EBIT) | C18: =SUM(C13+SUM(C16:C17)) -> 850.8 | D18: =SUM(D13+SUM(D16:D17)) -> 1036.5 | E18: =SUM(E13+SUM(E16:E17)) -> 1021.8 | G18: =SUM(G13+SUM(G16:G17)) -> 235 | H18: =SUM(H13+SUM(H16:H17)) -> 318.4 | I18: =SUM(I13+SUM(I16:I17)) -> 273.8 | J18: =SUM(J13+SUM(J16:J17)) -> 209.3 | K18: =SUM(K13+SUM(K16:K17)) -> 226.5 | L18: =SUM(L13+SUM(L16:L17)) -> 325.7 | M18: =SUM(M13+SUM(M16:M17)) -> 269.8 | N18: =SUM(N13+SUM(N16:N17)) -> 199.8 | ... Q18: =SUM(Q13+SUM(Q16:Q17)) -> 207.66 | S18: =SUM(S13+SUM(S16:S17)) -> 1036.5 | T18: =SUM(T13+SUM(T16:T17)) -> 1028 | U18: =SUM(U13+SUM(U16:U17)) -> 1035.3 | V18: =SUM(V13+SUM(V16:V17)) -> 1031.3 | W18: =SUM(W13+SUM(W16:W17)) -> 1021.8 | X18: =SUM(X13+SUM(X16:X17)) -> 1018.2 | Y18: =SUM(Y13+SUM(Y16:Y17)) -> 265.1 | Z18: =SUM(Z13+SUM(Z16:Z17)) -> 202.96 | AB18: =SUM(Z18/V18)-1 -> -0.80319984
B19: Operating Margin (%) | C19: =C18/C8 -> 0.23932489 | D19: =D18/D8 -> 0.2616103 | E19: =E18/E8 -> 0.249098 | G19: =G18/G8 -> 0.26577697 | H19: =H18/H8 -> 0.29693183 | I19: =I18/I8 -> 0.26183418 | J19: =J18/J8 -> 0.21806626 | K19: =K18/K8 -> 0.24129115 | L19: =L18/L8 -> 0.29302744 | M19: =M18/M8 -> 0.25400113 | N19: =N18/N8 -> 0.20189976 | ... Q19: =Q18/Q8 -> 0.20843099 | S19: =S18/S8 -> 0.2616103 | T19: =T18/T8 -> 0.25594423 | U19: =U18/U8 -> 0.25527036 | V19: =V18/V8 -> 0.25325377 | W19: =W18/W8 -> 0.249098 | X19: =X18/X8 -> 0.24830513 | Y19: =Y18/Y8 -> 0.064057025 | Z19: =Z18/Z8 -> 0.049835474 | AB19: =SUM(Z19-V19)*10000 -> -2034.183
B21: (+) Depreciation and Amortization (D&A) | C21: ='Historical Financials'!C97 -> 39.229 | D21: ='Historical Financials'!D97 -> 54.304 | E21: ='Historical Financials'!E97 -> 69.84 | G21: ='Historical Financials'!G97 -> 13.136 | H21: ='Historical Financials'!H97 -> 12.644 | I21: ='Historical Financials'!I97 -> 14.751 | J21: ='Historical Financials'!J97 -> 13.773 | K21: ='Historical Financials'!K97 -> 16.161 | L21: ='Historical Financials'!L97 -> 17.544 | M21: ='Historical Financials'!M97 -> 18.185 | N21: ='Historical Financials'!N97 -> 17.95 | ... Q21: ='Historical Financials'!Q97 -> 20.326 | S21: =SUM(G21:J21) -> 54.304 | T21: =SUM(H21:K21) -> 57.329 | U21: =SUM(I21:L21) -> 62.229 | V21: =SUM(J21:M21) -> 65.663 | W21: =SUM(K21:N21) -> 69.84 | X21: =SUM(L21:O21) -> 72.216 | Y21: =SUM(M21:P21) -> 74.146 | Z21: =SUM(N21:Q21) -> 76.287 | AB21: =SUM(Z21/V21)-1 -> 0.16179584
B22: EBITDA | C22: =SUM(C18+SUM(C21:C21)) -> 890.029 | D22: =SUM(D18+SUM(D21:D21)) -> 1090.804 | E22: =SUM(E18+SUM(E21:E21)) -> 1091.64 | G22: =SUM(G18+SUM(G21:G21)) -> 248.136 | H22: =SUM(H18+SUM(H21:H21)) -> 331.044 | I22: =SUM(I18+SUM(I21:I21)) -> 288.551 | J22: =SUM(J18+SUM(J21:J21)) -> 223.073 | K22: =SUM(K18+SUM(K21:K21)) -> 242.661 | L22: =SUM(L18+SUM(L21:L21)) -> 343.244 | M22: =SUM(M18+SUM(M21:M21)) -> 287.985 | N22: =SUM(N18+SUM(N21:N21)) -> 217.75 | ... Q22: =SUM(Q18+SUM(Q21:Q21)) -> 227.986 | S22: =SUM(S18+SUM(S21:S21)) -> 1090.804 | T22: =SUM(T18+SUM(T21:T21)) -> 1085.329 | U22: =SUM(U18+SUM(U21:U21)) -> 1097.529 | V22: =SUM(V18+SUM(V21:V21)) -> 1096.963 | W22: =SUM(W18+SUM(W21:W21)) -> 1091.64 | X22: =SUM(X18+SUM(X21:X21)) -> 1090.416 | Y22: =SUM(Y18+SUM(Y21:Y21)) -> 339.246 | Z22: =SUM(Z18+SUM(Z21:Z21)) -> 279.247 | AB22: =SUM(Z22/V22)-1 -> -0.74543626
B23: EBITDA Margin (%) | C23: =C22/C8 -> 0.25035977 | D23: =D22/D8 -> 0.27531651 | E23: =E22/E8 -> 0.26612384 | G23: =G22/G8 -> 0.28063334 | H23: =H22/H8 -> 0.30872331 | I23: =I22/I8 -> 0.27594052 | J23: =J22/J8 -> 0.23241613 | K23: =K22/K8 -> 0.25850751 | L23: =L22/L8 -> 0.30881152 | M23: =M22/M8 -> 0.27112126 | N23: =N22/N8 -> 0.2200384 | ... Q23: =Q22/Q8 -> 0.22883245 | S23: =S22/S8 -> 0.27531651 | T23: =T22/T8 -> 0.2702176 | U23: =U22/U8 -> 0.27061395 | V23: =V22/V8 -> 0.26937847 | W23: =W22/W8 -> 0.26612384 | X23: =X22/X8 -> 0.26591621 | Y23: =Y22/Y8 -> 0.081973179 | Z23: =Z22/Z8 -> 0.068567237 | AB23: =SUM(Z23-V23)*10000 -> -2008.1123
B25: (+) Stock-Based Compensation (SBC) | C25: ='Historical Financials'!C99 -> 31.303 | D25: ='Historical Financials'!D99 -> 29.072 | E25: ='Historical Financials'!E99 -> 33.053 | G25: ='Historical Financials'!G99 -> 7.464 | H25: ='Historical Financials'!H99 -> 8.388 | I25: ='Historical Financials'!I99 -> 7.655 | J25: ='Historical Financials'!J99 -> 5.565 | K25: ='Historical Financials'!K99 -> 7.582 | L25: ='Historical Financials'!L99 -> 10.162 | M25: ='Historical Financials'!M99 -> 6.633 | N25: ='Historical Financials'!N99 -> 8.676 | ... Q25: ='Historical Financials'!Q99 -> 8.476 | S25: =SUM(G25:J25) -> 29.072 | T25: =SUM(H25:K25) -> 29.19 | U25: =SUM(I25:L25) -> 30.964 | V25: =SUM(J25:M25) -> 29.942 | W25: =SUM(K25:N25) -> 33.053 | X25: =SUM(L25:O25) -> 34.248 | Y25: =SUM(M25:P25) -> 35.345 | Z25: =SUM(N25:Q25) -> 37.188 | AB25: =SUM(Z25/V25)-1 -> 0.2420012
B26: (+) Asset Impairments | C26: =-C17 -> 0 | D26: =-D17 -> 0 | E26: =-E17 -> 0 | G26: =-G17 -> 0 | H26: =-H17 -> 0 | I26: =-I17 -> 0 | J26: =-J17 -> 0 | K26: =-K17 -> 0 | L26: =-L17 -> 0 | M26: =-M17 -> 0 | N26: =-N17 -> 0 | ... Q26: =-Q17 -> 0 | S26: =SUM(G26:J26) -> 0 | T26: =SUM(H26:K26) -> 0 | U26: =SUM(I26:L26) -> 0 | V26: =SUM(J26:M26) -> 0 | W26: =SUM(K26:N26) -> 0 | X26: =SUM(L26:O26) -> 0 | Y26: =SUM(M26:P26) -> 738.1 | Z26: =SUM(N26:Q26) -> 738.1 | AB26: =SUM(Z26/V26)-1 -> #DIV/0!
B27: Adj. EBITDA | C27: =+SUM(C22+SUM(C25:C26)) -> 921.332 | D27: =+SUM(D22+SUM(D25:D26)) -> 1119.876 | E27: =+SUM(E22+SUM(E25:E26)) -> 1124.693 | G27: =+SUM(G22+SUM(G25:G26)) -> 255.6 | H27: =+SUM(H22+SUM(H25:H26)) -> 339.432 | I27: =+SUM(I22+SUM(I25:I26)) -> 296.206 | J27: =+SUM(J22+SUM(J25:J26)) -> 228.638 | K27: =+SUM(K22+SUM(K25:K26)) -> 250.243 | L27: =+SUM(L22+SUM(L25:L26)) -> 353.406 | M27: =+SUM(M22+SUM(M25:M26)) -> 294.618 | N27: =+SUM(N22+SUM(N25:N26)) -> 226.426 | ... Q27: =+SUM(Q22+SUM(Q25:Q26)) -> 236.462 | S27: =+SUM(S22+SUM(S25:S26)) -> 1119.876 | T27: =+SUM(T22+SUM(T25:T26)) -> 1114.519 | U27: =+SUM(U22+SUM(U25:U26)) -> 1128.493 | V27: =+SUM(V22+SUM(V25:V26)) -> 1126.905 | W27: =+SUM(W22+SUM(W25:W26)) -> 1124.693 | X27: =+SUM(X22+SUM(X25:X26)) -> 1124.664 | Y27: =+SUM(Y22+SUM(Y25:Y26)) -> 1112.691 | Z27: =+SUM(Z22+SUM(Z25:Z26)) -> 1054.535 | AB27: =SUM(Z27/V27)-1 -> -0.064220143
B28: Adj. EBITDA Margin (%) | C28: =C27/C8 -> 0.25916512 | D28: =D27/D8 -> 0.28265422 | E28: =E27/E8 -> 0.27418162 | G28: =G27/G8 -> 0.28907487 | H28: =H27/H8 -> 0.31654574 | I28: =I27/I8 -> 0.28326097 | J28: =J27/J8 -> 0.23821421 | K28: =K27/K8 -> 0.26658464 | L28: =L27/L8 -> 0.31795412 | M28: =M27/M8 -> 0.27736584 | N28: =N27/N8 -> 0.22880558 | ... Q28: =Q27/Q8 -> 0.23733992 | S28: =S27/S8 -> 0.28265422 | T28: =T27/T8 -> 0.27748512 | U28: =U27/U8 -> 0.27824864 | V28: =V27/V8 -> 0.27673125 | W28: =W27/W8 -> 0.27418162 | X28: =X27/X8 -> 0.27426816 | Y28: =Y27/Y8 -> 0.26886336 | Z28: =Z27/Z8 -> 0.25893403 | AB28: =SUM(Z28-V28)*10000 -> -177.97218
B30: (-) Capital Expenditures | C30: ='Historical Financials'!C117 -> -104.19 | D30: ='Historical Financials'!D117 -> -115.625 | E30: ='Historical Financials'!E117 -> -69.347 | G30: ='Historical Financials'!G117 -> -27.581 | H30: ='Historical Financials'!H117 -> -24.064 | I30: ='Historical Financials'!I117 -> -34.733 | J30: ='Historical Financials'!J117 -> -29.247 | K30: ='Historical Financials'!K117 -> -15.75 | L30: ='Historical Financials'!L117 -> -17.056 | M30: ='Historical Financials'!M117 -> -18.051 | N30: ='Historical Financials'!N117 -> -18.49 | ... Q30: ='Historical Financials'!Q117 -> -13.174 | S30: =SUM(G30:J30) -> -115.625 | T30: =SUM(H30:K30) -> -103.794 | U30: =SUM(I30:L30) -> -96.786 | V30: =SUM(J30:M30) -> -80.104 | W30: =SUM(K30:N30) -> -69.347 | X30: =SUM(L30:O30) -> -68.972 | Y30: =SUM(M30:P30) -> -68.487 | Z30: =SUM(N30:Q30) -> -63.61 | AB30: =SUM(Z30/V30)-1 -> -0.20590732
B31: (-) Cash Taxes | C31: =-'Historical Financials'!C142 -> -130.084 | D31: =-'Historical Financials'!D142 -> -179.721 | E31: =-'Historical Financials'!E142 -> -124.959 | G31: =-'Historical Financials'!G142 -> -8.011 | H31: =-'Historical Financials'!H142 -> -94.096 | I31: =-'Historical Financials'!I142 -> 6.922 | J31: =-'Historical Financials'!J142 -> -84.536 | K31: =-'Historical Financials'!K142 -> -18.122 | L31: =-'Historical Financials'!L142 -> -53.707 | M31: =-'Historical Financials'!M142 -> -23.356 | N31: =-'Historical Financials'!N142 -> -29.774 | ... Q31: =-'Historical Financials'!Q142 -> -19.613 | S31: =SUM(G31:J31) -> -179.721 | T31: =SUM(H31:K31) -> -189.832 | U31: =SUM(I31:L31) -> -149.443 | V31: =SUM(J31:M31) -> -179.721 | W31: =SUM(K31:N31) -> -124.959 | X31: =SUM(L31:O31) -> -120.801 | Y31: =SUM(M31:P31) -> -161.712 | Z31: =SUM(N31:Q31) -> -157.969 | AB31: =SUM(Z31/V31)-1 -> -0.12103204
B32: (-) Cash Interest | C32: =-'Historical Financials'!C141 -> -127.809 | D32: =-'Historical Financials'!D141 -> -151.621 | E32: =-'Historical Financials'!E141 -> -99.463 | G32: =-'Historical Financials'!G141 -> -47.729 | H32: =-'Historical Financials'!H141 -> -33.625 | I32: =-'Historical Financials'!I141 -> -4.688 | J32: =-'Historical Financials'!J141 -> -65.579 | K32: =-'Historical Financials'!K141 -> -35.054 | L32: =-'Historical Financials'!L141 -> -19.654 | M32: =-'Historical Financials'!M141 -> -31.334 | N32: =-'Historical Financials'!N141 -> -13.421 | ... Q32: =-'Historical Financials'!Q141 -> -26.48 | S32: =SUM(G32:J32) -> -151.621 | T32: =SUM(H32:K32) -> -138.946 | U32: =SUM(I32:L32) -> -124.975 | V32: =SUM(J32:M32) -> -151.621 | W32: =SUM(K32:N32) -> -99.463 | X32: =SUM(L32:O32) -> -91.247 | Y32: =SUM(M32:P32) -> -84.148 | Z32: =SUM(N32:Q32) -> -79.294 | AB32: =SUM(Z32/V32)-1 -> -0.47702495
B33: (-) Mandatory Outflows | C33: 0 | D33: 0 | E33: 0 | G33: 0 | H33: 0 | I33: 0 | J33: 0 | K33: 0 | L33: 0 | M33: 0 | N33: 0 | O33: 0 | P33: 0 | Q33: 0 | S33: =SUM(G33:J33) -> 0 | T33: =SUM(H33:K33) -> 0 | U33: =SUM(I33:L33) -> 0 | V33: =SUM(J33:M33) -> 0 | W33: =SUM(K33:N33) -> 0 | X33: =SUM(L33:O33) -> 0 | Y33: =SUM(M33:P33) -> 0 | Z33: =SUM(N33:Q33) -> 0 | AB33: =SUM(Z33/V33)-1 -> #DIV/0!
B34: (+/-) Changes in NWC | C34: =SUM('Historical Financials'!C108:C113) -> -91.682 | D34: =SUM('Historical Financials'!D108:D113) -> 366.525 | E34: =SUM('Historical Financials'!E108:E113) -> 68.43 | G34: =SUM('Historical Financials'!G108:G113) -> -178.794 | H34: =SUM('Historical Financials'!H108:H113) -> 68.459 | I34: =SUM('Historical Financials'!I108:I113) -> 23.752 | J34: =SUM('Historical Financials'!J108:J113) -> 453.108 | K34: =SUM('Historical Financials'!K108:K113) -> -260.046 | L34: =SUM('Historical Financials'!L108:L113) -> 117.646 | M34: =SUM('Historical Financials'!M108:M113) -> 43.117 | N34: =SUM('Historical Financials'!N108:N113) -> 167.713 | ... Q34: =SUM('Historical Financials'!Q108:Q113) -> 37.11 | S34: =SUM(G34:J34) -> 366.525 | T34: =SUM(H34:K34) -> 285.273 | U34: =SUM(I34:L34) -> 334.46 | V34: =SUM(J34:M34) -> 353.825 | W34: =SUM(K34:N34) -> 68.43 | X34: =SUM(L34:O34) -> 36.404 | Y34: =SUM(M34:P34) -> -106.71 | Z34: =SUM(N34:Q34) -> -112.717 | AB34: =SUM(Z34/V34)-1 -> -1.3185671
B35: Discretionary Cash-Flows | C35: =SUM(C27+SUM(C30:C34)) -> 467.567 | D35: =SUM(D27+SUM(D30:D34)) -> 1039.434 | E35: =SUM(E27+SUM(E30:E34)) -> 899.354 | G35: =SUM(G27+SUM(G30:G34)) -> -6.515 | H35: =SUM(H27+SUM(H30:H34)) -> 256.106 | I35: =SUM(I27+SUM(I30:I34)) -> 287.459 | J35: =SUM(J27+SUM(J30:J34)) -> 502.384 | K35: =SUM(K27+SUM(K30:K34)) -> -78.729 | L35: =SUM(L27+SUM(L30:L34)) -> 380.635 | M35: =SUM(M27+SUM(M30:M34)) -> 264.994 | N35: =SUM(N27+SUM(N30:N34)) -> 332.454 | ... Q35: =SUM(Q27+SUM(Q30:Q34)) -> 214.305 | S35: =SUM(S27+SUM(S30:S34)) -> 1039.434 | T35: =SUM(T27+SUM(T30:T34)) -> 967.22 | U35: =SUM(U27+SUM(U30:U34)) -> 1091.749 | V35: =SUM(V27+SUM(V30:V34)) -> 1069.284 | W35: =SUM(W27+SUM(W30:W34)) -> 899.354 | X35: =SUM(X27+SUM(X30:X34)) -> 880.048 | Y35: =SUM(Y27+SUM(Y30:Y34)) -> 691.634 | Z35: =SUM(Z27+SUM(Z30:Z34)) -> 640.945 | AB35: =SUM(Z35/V35)-1 -> -0.40058488
B37: (+/-) Divestitures / (Acquisitions) | C37: ='Historical Financials'!C118 -> -2046.881 | D37: ='Historical Financials'!D118 -> 0 | E37: ='Historical Financials'!E118 -> 0 | G37: ='Historical Financials'!G118 -> 0 | H37: ='Historical Financials'!H118 -> 0 | I37: ='Historical Financials'!I118 -> 0 | J37: ='Historical Financials'!J118 -> 0 | K37: ='Historical Financials'!K118 -> 0 | L37: ='Historical Financials'!L118 -> 0 | M37: ='Historical Financials'!M118 -> 0 | N37: ='Historical Financials'!N118 -> 0 | ... Q37: ='Historical Financials'!Q118 -> 0 | S37: =SUM(G37:J37) -> 0 | T37: =SUM(H37:K37) -> 0 | U37: =SUM(I37:L37) -> 0 | V37: =SUM(J37:M37) -> 0 | W37: =SUM(K37:N37) -> 0 | X37: =SUM(L37:O37) -> 0 | Y37: =SUM(M37:P37) -> 0 | Z37: =SUM(N37:Q37) -> 0
B38: (+/-) Proceeds / (Repayments) from borrowings, net | C38: ='Historical Financials'!C123 -> 1541.017 | D38: ='Historical Financials'!D123 -> -667.534 | E38: ='Historical Financials'!E123 -> -325.526 | G38: ='Historical Financials'!G123 -> -41.911 | H38: ='Historical Financials'!H123 -> -257.77 | I38: ='Historical Financials'!I123 -> -91.124 | J38: ='Historical Financials'!J123 -> -276.729 | K38: ='Historical Financials'!K123 -> 61.751 | L38: ='Historical Financials'!L123 -> -200 | M38: ='Historical Financials'!M123 -> -110 | N38: ='Historical Financials'!N123 -> -77.277 | ... Q38: ='Historical Financials'!Q123 -> -63 | S38: =SUM(G38:J38) -> -667.534 | T38: =SUM(H38:K38) -> -563.872 | U38: =SUM(I38:L38) -> -506.102 | V38: =SUM(J38:M38) -> -524.978 | W38: =SUM(K38:N38) -> -325.526 | X38: =SUM(L38:O38) -> -257.277 | Y38: =SUM(M38:P38) -> -162.277 | Z38: =SUM(N38:Q38) -> -115.277
B39: (+/-) Equity Issuances / (Repurchases), net | C39: ='Historical Financials'!C124 -> -11.477 | D39: ='Historical Financials'!D124 -> -192.105 | E39: ='Historical Financials'!E124 -> -560.69 | G39: ='Historical Financials'!G124 -> -10.395 | H39: ='Historical Financials'!H124 -> -1.241 | I39: ='Historical Financials'!I124 -> -155.411 | J39: ='Historical Financials'!J124 -> -25.058 | K39: ='Historical Financials'!K124 -> -5.913 | L39: ='Historical Financials'!L124 -> -175.011 | M39: ='Historical Financials'!M124 -> -153.496 | N39: ='Historical Financials'!N124 -> -226.27 | ... Q39: ='Historical Financials'!Q124 -> -208.157 | S39: =SUM(G39:J39) -> -192.105 | T39: =SUM(H39:K39) -> -187.623 | U39: =SUM(I39:L39) -> -361.393 | V39: =SUM(J39:M39) -> -359.478 | W39: =SUM(K39:N39) -> -560.69 | X39: =SUM(L39:O39) -> -618.953 | Y39: =SUM(M39:P39) -> -578.007 | Z39: =SUM(N39:Q39) -> -632.668
B40: (+/-) Other | D40: =SUM(D45:D46)-SUM(C45:C46)-SUM(D35:D39) -> -221.595 | E40: =SUM(E45:E46)-SUM(D45:D46)-SUM(E35:E39) -> 17.462 | G40: =SUM(G45:G46)-SUM(C45:C46)-SUM(G35:G39) -> -7.179 | H40: =SUM(H45:H46)-SUM(G45:G46)-SUM(H35:H39) -> 43.505 | I40: =SUM(I45:I46)-SUM(H45:H46)-SUM(I35:I39) -> -79.424 | J40: =SUM(J45:J46)-SUM(I45:I46)-SUM(J35:J39) -> -178.497 | K40: =SUM(K45:K46)-SUM(J45:J46)-SUM(K35:K39) -> 32.791 | L40: =SUM(L45:L46)-SUM(K45:K46)-SUM(L35:L39) -> 2.376 | M40: =SUM(M45:M46)-SUM(L45:L46)-SUM(M35:M39) -> 17.002 | N40: =SUM(N45:N46)-SUM(M45:M46)-SUM(N35:N39) -> -34.707 | O40: =SUM(O45:O46)-SUM(N45:N46)-SUM(O35:O39) -> 18.311 | ... Q40: =SUM(Q45:Q46)-SUM(P45:P46)-SUM(Q35:Q39) -> 10.175 | S40: =SUM(G40:J40) -> -221.595 | T40: =SUM(H40:K40) -> -181.625 | U40: =SUM(I40:L40) -> -222.754 | V40: =SUM(J40:M40) -> -126.328 | W40: =SUM(K40:N40) -> 17.462 | X40: =SUM(L40:O40) -> 2.982 | Y40: =SUM(M40:P40) -> 81.85 | Z40: =SUM(N40:Q40) -> 75.023
B41: Free-Cash Flows | C41: =SUM(C35+SUM(C37:C40)) -> -49.774 | D41: =SUM(D35+SUM(D37:D40)) -> -41.8 | E41: =SUM(E35+SUM(E37:E40)) -> 30.6 | G41: =SUM(G35+SUM(G37:G40)) -> -66 | H41: =SUM(H35+SUM(H37:H40)) -> 40.6 | I41: =SUM(I35+SUM(I37:I40)) -> -38.5 | J41: =SUM(J35+SUM(J37:J40)) -> 22.1 | K41: =SUM(K35+SUM(K37:K40)) -> 9.9 | L41: =SUM(L35+SUM(L37:L40)) -> 8 | M41: =SUM(M35+SUM(M37:M40)) -> 18.5 | N41: =SUM(N35+SUM(N37:N40)) -> -5.8 | ... Q41: =SUM(Q35+SUM(Q37:Q40)) -> -46.677 | S41: =SUM(S35+SUM(S37:S40)) -> -41.8 | T41: =SUM(T35+SUM(T37:T40)) -> 34.1 | U41: =SUM(U35+SUM(U37:U40)) -> 1.5 | V41: =SUM(V35+SUM(V37:V40)) -> 58.5 | W41: =SUM(W35+SUM(W37:W40)) -> 30.6 | X41: =SUM(X35+SUM(X37:X40)) -> 6.8 | Y41: =SUM(Y35+SUM(Y37:Y40)) -> 33.2 | Z41: =SUM(Z35+SUM(Z37:Z40)) -> -31.977
B43: Capitalization
B45: Cash & Cash Equivelants | C45: ='Historical Financials'!C44 -> 191.6 | D45: ='Historical Financials'!D44 -> 149.3 | E45: ='Historical Financials'!E44 -> 180.5 | G45: ='Historical Financials'!G44 -> 125.7 | H45: ='Historical Financials'!H44 -> 166.2 | I45: ='Historical Financials'!I44 -> 127.3 | J45: ='Historical Financials'!J44 -> 149.3 | K45: ='Historical Financials'!K44 -> 159.3 | L45: ='Historical Financials'!L44 -> 167.7 | M45: ='Historical Financials'!M44 -> 186.1 | N45: ='Historical Financials'!N44 -> 180.5 | ... Q45: ='Historical Financials'!Q44 -> 153.97 | S45: =J45 -> 149.3 | T45: =K45 -> 159.3 | U45: =L45 -> 167.7 | V45: =M45 -> 186.1 | W45: =N45 -> 180.5 | X45: =O45 -> 166.5 | Y45: =P45 -> 200.6 | Z45: =Q45 -> 153.97
B46: Restricted cash | C46: ='Historical Financials'!C57 -> 3.3 | D46: ='Historical Financials'!D57 -> 3.8 | E46: ='Historical Financials'!E57 -> 3.2 | G46: ='Historical Financials'!G57 -> 3.2 | H46: ='Historical Financials'!H57 -> 3.3 | I46: ='Historical Financials'!I57 -> 3.7 | J46: ='Historical Financials'!J57 -> 3.8 | K46: ='Historical Financials'!K57 -> 3.7 | L46: ='Historical Financials'!L57 -> 3.3 | M46: ='Historical Financials'!M57 -> 3.4 | N46: ='Historical Financials'!N57 -> 3.2 | ... Q46: ='Historical Financials'!Q57 -> 3.553 | S46: =J46 -> 3.8 | T46: =K46 -> 3.7 | U46: =L46 -> 3.3 | V46: =M46 -> 3.4 | W46: =N46 -> 3.2 | X46: =O46 -> 3.3 | Y46: =P46 -> 3.6 | Z46: =Q46 -> 3.553
B47: $15MM Asia Revolving Facility due 2027 | C47: =15-C51-C68 -> 10.7 | D47: =15-D51-D68 -> 10.7 | E47: =15-E51-E68 -> 11.7 | G47: =15-G51-G68 -> -2.3 | H47: =15-H51-H68 -> 10.7 | I47: =15-I51-I68 -> 10.7 | J47: =D47 -> 10.7 | K47: =15-K51-K68 -> 11.7 | L47: =15-L51-L68 -> 11.7 | M47: =15-M51-M68 -> 11.7 | N47: =E47 -> 11.7 | O47: =15-O51-O68 -> 15 | P47: =15-P51-P68 -> 15 | Q47: =15-Q51-Q68 -> 15 | S47: =J47 -> 10.7 | T47: =K47 -> 11.7 | U47: =L47 -> 11.7 | V47: =M47 -> 11.7 | W47: =N47 -> 11.7 | X47: =O47 -> 15 | Y47: =P47 -> 15 | Z47: =Q47 -> 15
B48: $1Bn Revolving Facility due 2027 | C48: =750-C50-C69 -> 748.7 | D48: =1000-D50-D69 -> 808.7 | E48: =1000-E50-E69 -> 809.4 | G48: =1000-G50-G69 -> 798.7 | H48: =1000-H50-H69 -> 798.7 | I48: =1000-I50-I69 -> 798.7 | J48: =D48 -> 808.7 | K48: =1000-K50-K69 -> 733.7 | L48: =1000-L50-L69 -> 808.7 | M48: =1000-M50-M69 -> 809.2 | N48: =E48 -> 809.4 | O48: =1000-O50-O69 -> 679.4 | P48: =1000-P50-P69 -> 784.4 | Q48: =1000-Q50-Q69 -> 847.4 | S48: =J48 -> 808.7 | T48: =K48 -> 733.7 | U48: =L48 -> 808.7 | V48: =M48 -> 809.2 | W48: =N48 -> 809.4 | X48: =O48 -> 679.4 | Y48: =P48 -> 784.4 | Z48: =Q48 -> 847.4
B49: Total Liquidity | C49: =SUM(C45:C48) -> 954.3 | D49: =SUM(D45:D48) -> 972.5 | E49: =SUM(E45:E48) -> 1004.8 | G49: =SUM(G45:G48) -> 925.3 | H49: =SUM(H45:H48) -> 978.9 | I49: =SUM(I45:I48) -> 940.4 | J49: =SUM(J45:J48) -> 972.5 | K49: =SUM(K45:K48) -> 908.4 | L49: =SUM(L45:L48) -> 991.4 | M49: =SUM(M45:M48) -> 1010.4 | N49: =SUM(N45:N48) -> 1004.8 | ... Q49: =SUM(Q45:Q48) -> 1019.923 | S49: =SUM(S45:S48) -> 972.5 | T49: =SUM(T45:T48) -> 908.4 | U49: =SUM(U45:U48) -> 991.4 | V49: =SUM(V45:V48) -> 1010.4 | W49: =SUM(W45:W48) -> 1004.8 | X49: =SUM(X45:X48) -> 864.2 | Y49: =SUM(Y45:Y48) -> 1003.6 | Z49: =SUM(Z45:Z48) -> 1019.923
B50: $1Bn RCF: Outstanding L/Cs | C50: 1.3 | D50: 1.3 | E50: 0.6 | G50: 1.3 | H50: 1.3 | I50: 1.3 | J50: =D50 -> 1.3 | K50: 1.3 | L50: 1.3 | M50: 0.8 | N50: =E50 -> 0.6 | O50: 0.6 | P50: 0.6 | Q50: 0.6 | S50: =J50 -> 1.3 | T50: =K50 -> 1.3 | U50: =L50 -> 1.3 | V50: =M50 -> 0.8 | W50: =N50 -> 0.6 | X50: =O50 -> 0.6 | Y50: =P50 -> 0.6 | Z50: =Q50 -> 0.6
...
