Workbook

Sheet Historical Financials
B2: Paramount Global (NASDAQ: PARA)
B3: Historical Financials
B4: ($ In Millions, except EPS)
A6: X | B6: Income Statement | D6: FYE | H6: Quarterly | N6: Quarterly | AA6: LTM | AG6: Variance
B7: Fiscal Period | C7: 2021 | D7: 2022 | E7: 2023 | F7: 2024 | H7: 1Q23 | I7: 2Q23 | J7: 3Q23 | K7: 4Q23 | L7: 1Q24 | M7: 2Q24 | N7: 3Q24 | O7: 4Q24 | P7: 1Q25 | Q7: 2Q25 | R7: 3Q25 | S7: 4Q25 | T7: 1Q26 | V7: =K7 -> 4Q23 | W7: =L7 -> 1Q24 | X7: =M7 -> 2Q24 | Y7: =N7 -> 3Q24 | Z7: =O7 -> 4Q24 | AA7: =P7 -> 1Q25 | AB7: =Q7 -> 2Q25 | AC7: =R7 -> 3Q25 | ... AE7: =T7 -> 1Q26
B8: Fiscal Period End Date | C8: 44561 | D8: 44926 | E8: 45291 | F8: 45657 | H8: XXX | I8: XXX | J8: XXX | K8: =D8 -> 44926 | L8: XXX | M8: XXX | N8: XXX | O8: =E8 -> 45291 | P8: XXX | Q8: XXX | R8: XXX | S8: =F8 -> 45657 | T8: XXX | V8: =K8 -> 44926 | W8: =L8 -> XXX | X8: =M8 -> XXX | Y8: =N8 -> XXX | Z8: =O8 -> 45291 | AA8: =P8 -> XXX | AB8: =Q8 -> XXX | AC8: =R8 -> XXX | ... AE8: =T8 -> XXX
B10: Consolidated Revenue | C10: 28586 | D10: 30154 | E10: 29652 | F10: 29213 | K10: =SUM(D10-SUM(H10:J10)) -> 30154 | O10: =SUM(E10-SUM(L10:N10)) -> 29652 | S10: =SUM(F10-SUM(P10:R10)) -> 29213 | V10: =SUM(H10:K10) -> 30154 | W10: =SUM(I10:L10) -> 30154 | X10: =SUM(J10:M10) -> 30154 | Y10: =SUM(K10:N10) -> 30154 | Z10: =SUM(L10:O10) -> 29652 | AA10: =SUM(M10:P10) -> 29652 | AB10: =SUM(N10:Q10) -> 29652 | AC10: =SUM(O10:R10) -> 29652 | ... AE10: =SUM(Q10:T10) -> 29213 | AG10: =SUM(AE10/AA10)-1 -> -0.014805072
B11: Total Revenue | C11: =+SUM(C10:C10) -> 28586 | D11: =+SUM(D10:D10) -> 30154 | E11: =+SUM(E10:E10) -> 29652 | F11: =+SUM(F10:F10) -> 29213 | H11: =+SUM(H10:H10) -> 0 | I11: =+SUM(I10:I10) -> 0 | J11: =+SUM(J10:J10) -> 0 | K11: =+SUM(K10:K10) -> 30154 | L11: =+SUM(L10:L10) -> 0 | M11: =+SUM(M10:M10) -> 0 | N11: =+SUM(N10:N10) -> 0 | O11: =+SUM(O10:O10) -> 29652 | ... T11: =+SUM(T10:T10) -> 0 | V11: =+SUM(V10:V10) -> 30154 | W11: =+SUM(W10:W10) -> 30154 | X11: =+SUM(X10:X10) -> 30154 | Y11: =+SUM(Y10:Y10) -> 30154 | Z11: =+SUM(Z10:Z10) -> 29652 | AA11: =+SUM(AA10:AA10) -> 29652 | AB11: =+SUM(AB10:AB10) -> 29652 | AC11: =+SUM(AC10:AC10) -> 29652 | ... AE11: =+SUM(AE10:AE10) -> 29213 | AG11: =SUM(AE11/AA11)-1 -> -0.014805072
B13: Operating | C13: -17744 | D13: -19845 | E13: -20017 | F13: -19437 | K13: =SUM(D13-SUM(H13:J13)) -> -19845 | O13: =SUM(E13-SUM(L13:N13)) -> -20017 | S13: =SUM(F13-SUM(P13:R13)) -> -19437 | V13: =SUM(H13:K13) -> -19845 | W13: =SUM(I13:L13) -> -19845 | X13: =SUM(J13:M13) -> -19845 | Y13: =SUM(K13:N13) -> -19845 | Z13: =SUM(L13:O13) -> -20017 | AA13: =SUM(M13:P13) -> -20017 | AB13: =SUM(N13:Q13) -> -20017 | AC13: =SUM(O13:R13) -> -20017 | ... AE13: =SUM(Q13:T13) -> -19437 | AG13: =SUM(AE13/AA13)-1 -> -0.028975371
B14: Programming charges | C14: 0 | D14: 0 | E14: -2371 | F14: -1118 | K14: =SUM(D14-SUM(H14:J14)) -> 0 | O14: =SUM(E14-SUM(L14:N14)) -> -2371 | S14: =SUM(F14-SUM(P14:R14)) -> -1118 | T14: 0 | V14: =SUM(H14:K14) -> 0 | W14: =SUM(I14:L14) -> 0 | X14: =SUM(J14:M14) -> 0 | Y14: =SUM(K14:N14) -> 0 | Z14: =SUM(L14:O14) -> -2371 | AA14: =SUM(M14:P14) -> -2371 | AB14: =SUM(N14:Q14) -> -2371 | AC14: =SUM(O14:R14) -> -2371 | ... AE14: =SUM(Q14:T14) -> -1118 | AG14: =SUM(AE14/AA14)-1 -> -0.528469
B15: Selling, general and administrative | C15: -6398 | D15: -7033 | E15: -7245 | F15: -6658 | K15: =SUM(D15-SUM(H15:J15)) -> -7033 | O15: =SUM(E15-SUM(L15:N15)) -> -7245 | S15: =SUM(F15-SUM(P15:R15)) -> -6658 | V15: =SUM(H15:K15) -> -7033 | W15: =SUM(I15:L15) -> -7033 | X15: =SUM(J15:M15) -> -7033 | Y15: =SUM(K15:N15) -> -7033 | Z15: =SUM(L15:O15) -> -7245 | AA15: =SUM(M15:P15) -> -7245 | AB15: =SUM(N15:Q15) -> -7245 | AC15: =SUM(O15:R15) -> -7245 | ... AE15: =SUM(Q15:T15) -> -6658 | AG15: =SUM(AE15/AA15)-1 -> -0.081021394
B16: Depreciation and amortization | C16: -390 | D16: -378 | E16: -418 | F16: -392 | K16: =SUM(D16-SUM(H16:J16)) -> -378 | O16: =SUM(E16-SUM(L16:N16)) -> -418 | S16: =SUM(F16-SUM(P16:R16)) -> -392 | V16: =SUM(H16:K16) -> -378 | W16: =SUM(I16:L16) -> -378 | X16: =SUM(J16:M16) -> -378 | Y16: =SUM(K16:N16) -> -378 | Z16: =SUM(L16:O16) -> -418 | AA16: =SUM(M16:P16) -> -418 | AB16: =SUM(N16:Q16) -> -418 | AC16: =SUM(O16:R16) -> -418 | ... AE16: =SUM(Q16:T16) -> -392 | AG16: =SUM(AE16/AA16)-1 -> -0.062200957
B17: Impairment charges | C17: 0 | D17: -27 | E17: -83 | F17: -6130 | K17: =SUM(D17-SUM(H17:J17)) -> -27 | O17: =SUM(E17-SUM(L17:N17)) -> -83 | S17: =SUM(F17-SUM(P17:R17)) -> -6130 | V17: =SUM(H17:K17) -> -27 | W17: =SUM(I17:L17) -> -27 | X17: =SUM(J17:M17) -> -27 | Y17: =SUM(K17:N17) -> -27 | Z17: =SUM(L17:O17) -> -83 | AA17: =SUM(M17:P17) -> -83 | AB17: =SUM(N17:Q17) -> -83 | AC17: =SUM(O17:R17) -> -83 | ... AE17: =SUM(Q17:T17) -> -6130 | AG17: =SUM(AE17/AA17)-1 -> 72.855422
B18: Restructuring, transaction-related items, and other corporate matters | C18: -100 | D18: -585 | E18: 31 | F18: -747 | K18: =SUM(D18-SUM(H18:J18)) -> -585 | O18: =SUM(E18-SUM(L18:N18)) -> 31 | S18: =SUM(F18-SUM(P18:R18)) -> -747 | V18: =SUM(H18:K18) -> -585 | W18: =SUM(I18:L18) -> -585 | X18: =SUM(J18:M18) -> -585 | Y18: =SUM(K18:N18) -> -585 | Z18: =SUM(L18:O18) -> 31 | AA18: =SUM(M18:P18) -> 31 | AB18: =SUM(N18:Q18) -> 31 | AC18: =SUM(O18:R18) -> 31 | ... AE18: =SUM(Q18:T18) -> -747 | AG18: =SUM(AE18/AA18)-1 -> -25.096774
B19: Gains on dispositions | C19: 2343 | D19: 56 | E19: 0 | F19: 0 | K19: =SUM(D19-SUM(H19:J19)) -> 56 | O19: =SUM(E19-SUM(L19:N19)) -> 0 | S19: =SUM(F19-SUM(P19:R19)) -> 0 | V19: =SUM(H19:K19) -> 56 | W19: =SUM(I19:L19) -> 56 | X19: =SUM(J19:M19) -> 56 | Y19: =SUM(K19:N19) -> 56 | Z19: =SUM(L19:O19) -> 0 | AA19: =SUM(M19:P19) -> 0 | AB19: =SUM(N19:Q19) -> 0 | AC19: =SUM(O19:R19) -> 0 | ... AE19: =SUM(Q19:T19) -> 0 | AG19: =SUM(AE19/AA19)-1 -> #DIV/0!
B20: Operating Profit | C20: =+SUM(C11+SUM(C13:C19)) -> 6297 | D20: =+SUM(D11+SUM(D13:D19)) -> 2342 | E20: =+SUM(E11+SUM(E13:E19)) -> -451 | F20: =+SUM(F11+SUM(F13:F19)) -> -5269 | H20: =+SUM(H11+SUM(H13:H19)) -> 0 | I20: =+SUM(I11+SUM(I13:I19)) -> 0 | J20: =+SUM(J11+SUM(J13:J19)) -> 0 | K20: =+SUM(K11+SUM(K13:K19)) -> 2342 | L20: =+SUM(L11+SUM(L13:L19)) -> 0 | M20: =+SUM(M11+SUM(M13:M19)) -> 0 | N20: =+SUM(N11+SUM(N13:N19)) -> 0 | O20: =+SUM(O11+SUM(O13:O19)) -> -451 | ... T20: =+SUM(T11+SUM(T13:T19)) -> 0 | V20: =+SUM(V11+SUM(V13:V19)) -> 2342 | W20: =+SUM(W11+SUM(W13:W19)) -> 2342 | X20: =+SUM(X11+SUM(X13:X19)) -> 2342 | Y20: =+SUM(Y11+SUM(Y13:Y19)) -> 2342 | Z20: =+SUM(Z11+SUM(Z13:Z19)) -> -451 | AA20: =+SUM(AA11+SUM(AA13:AA19)) -> -451 | AB20: =+SUM(AB11+SUM(AB13:AB19)) -> -451 | AC20: =+SUM(AC11+SUM(AC13:AC19)) -> -451 | ... AE20: =+SUM(AE11+SUM(AE13:AE19)) -> -5269 | AG20: =SUM(AE20/AA20)-1 -> 10.682927
B21: Operating Margin (%) | C21: =C20/C11 -> 0.22028266 | D21: =D20/D11 -> 0.077667971 | E21: =E20/E11 -> -0.015209767 | F21: =F20/F11 -> -0.18036491 | H21: =H20/H11 -> #DIV/0! | I21: =I20/I11 -> #DIV/0! | J21: =J20/J11 -> #DIV/0! | K21: =K20/K11 -> 0.077667971 | L21: =L20/L11 -> #DIV/0! | M21: =M20/M11 -> #DIV/0! | N21: =N20/N11 -> #DIV/0! | O21: =O20/O11 -> -0.015209767 | ... T21: =T20/T11 -> #DIV/0! | V21: =V20/V11 -> 0.077667971 | W21: =W20/W11 -> 0.077667971 | X21: =X20/X11 -> 0.077667971 | Y21: =Y20/Y11 -> 0.077667971 | Z21: =Z20/Z11 -> -0.015209767 | AA21: =AA20/AA11 -> -0.015209767 | AB21: =AB20/AB11 -> -0.015209767 | AC21: =AC20/AC11 -> -0.015209767 | ... AE21: =AE20/AE11 -> -0.18036491 | AG21: =SUM(AE21-AA21)*1000 -> -165.15514
B23: Interest expense | C23: -986 | D23: -931 | E23: -920 | F23: -860 | K23: =SUM(D23-SUM(H23:J23)) -> -931 | O23: =SUM(E23-SUM(L23:N23)) -> -920 | S23: =SUM(F23-SUM(P23:R23)) -> -860 | V23: =SUM(H23:K23) -> -931 | W23: =SUM(I23:L23) -> -931 | X23: =SUM(J23:M23) -> -931 | Y23: =SUM(K23:N23) -> -931 | Z23: =SUM(L23:O23) -> -920 | AA23: =SUM(M23:P23) -> -920 | AB23: =SUM(N23:Q23) -> -920 | AC23: =SUM(O23:R23) -> -920 | ... AE23: =SUM(Q23:T23) -> -860 | AG23: =SUM(AE23/AA23)-1 -> -0.065217391
B24: Interest income | C24: 53 | D24: 108 | E24: 137 | F24: 151 | K24: =SUM(D24-SUM(H24:J24)) -> 108 | O24: =SUM(E24-SUM(L24:N24)) -> 137 | S24: =SUM(F24-SUM(P24:R24)) -> 151 | V24: =SUM(H24:K24) -> 108 | W24: =SUM(I24:L24) -> 108 | X24: =SUM(J24:M24) -> 108 | Y24: =SUM(K24:N24) -> 108 | Z24: =SUM(L24:O24) -> 137 | AA24: =SUM(M24:P24) -> 137 | AB24: =SUM(N24:Q24) -> 137 | AC24: =SUM(O24:R24) -> 137 | ... AE24: =SUM(Q24:T24) -> 151 | AG24: =SUM(AE24/AA24)-1 -> 0.10218978
B25: Gain (loss) from investments | C25: 47 | D25: -9 | E25: 168 | F25: -17 | K25: =SUM(D25-SUM(H25:J25)) -> -9 | O25: =SUM(E25-SUM(L25:N25)) -> 168 | S25: =SUM(F25-SUM(P25:R25)) -> -17 | V25: =SUM(H25:K25) -> -9 | W25: =SUM(I25:L25) -> -9 | X25: =SUM(J25:M25) -> -9 | Y25: =SUM(K25:N25) -> -9 | Z25: =SUM(L25:O25) -> 168 | AA25: =SUM(M25:P25) -> 168 | AB25: =SUM(N25:Q25) -> 168 | AC25: =SUM(O25:R25) -> 168 | ... AE25: =SUM(Q25:T25) -> -17 | AG25: =SUM(AE25/AA25)-1 -> -1.1011905
B26: Gain (loss) on extinguishment of debt | C26: -128 | D26: -120 | E26: 29 | F26: 0 | K26: =SUM(D26-SUM(H26:J26)) -> -120 | O26: =SUM(E26-SUM(L26:N26)) -> 29 | S26: =SUM(F26-SUM(P26:R26)) -> 0 | V26: =SUM(H26:K26) -> -120 | W26: =SUM(I26:L26) -> -120 | X26: =SUM(J26:M26) -> -120 | Y26: =SUM(K26:N26) -> -120 | Z26: =SUM(L26:O26) -> 29 | AA26: =SUM(M26:P26) -> 29 | AB26: =SUM(N26:Q26) -> 29 | AC26: =SUM(O26:R26) -> 29 | ... AE26: =SUM(Q26:T26) -> 0 | AG26: =SUM(AE26/AA26)-1 -> -1
B27: Other items, net | C27: -77 | D27: -124 | E27: -216 | F27: -182 | K27: =SUM(D27-SUM(H27:J27)) -> -124 | O27: =SUM(E27-SUM(L27:N27)) -> -216 | S27: =SUM(F27-SUM(P27:R27)) -> -182 | V27: =SUM(H27:K27) -> -124 | W27: =SUM(I27:L27) -> -124 | X27: =SUM(J27:M27) -> -124 | Y27: =SUM(K27:N27) -> -124 | Z27: =SUM(L27:O27) -> -216 | AA27: =SUM(M27:P27) -> -216 | AB27: =SUM(N27:Q27) -> -216 | AC27: =SUM(O27:R27) -> -216 | ... AE27: =SUM(Q27:T27) -> -182 | AG27: =SUM(AE27/AA27)-1 -> -0.15740741
B28: Earnings (loss) from Continuing Operations before Taxes & Equity | C28: =SUM(C23:C27)+C20 -> 5206 | D28: =SUM(D23:D27)+D20 -> 1266 | E28: =SUM(E23:E27)+E20 -> -1253 | F28: =SUM(F23:F27)+F20 -> -6177 | H28: =SUM(H23:H27)+H20 -> 0 | I28: =SUM(I23:I27)+I20 -> 0 | J28: =SUM(J23:J27)+J20 -> 0 | K28: =SUM(K23:K27)+K20 -> 1266 | L28: =SUM(L23:L27)+L20 -> 0 | M28: =SUM(M23:M27)+M20 -> 0 | N28: =SUM(N23:N27)+N20 -> 0 | O28: =SUM(O23:O27)+O20 -> -1253 | ... T28: =SUM(T23:T27)+T20 -> 0 | V28: =SUM(V23:V27)+V20 -> 1266 | W28: =SUM(W23:W27)+W20 -> 1266 | X28: =SUM(X23:X27)+X20 -> 1266 | Y28: =SUM(Y23:Y27)+Y20 -> 1266 | Z28: =SUM(Z23:Z27)+Z20 -> -1253 | AA28: =SUM(AA23:AA27)+AA20 -> -1253 | AB28: =SUM(AB23:AB27)+AB20 -> -1253 | AC28: =SUM(AC23:AC27)+AC20 -> -1253 | ... AE28: =SUM(AE23:AE27)+AE20 -> -6177 | AG28: =SUM(AE28/AA28)-1 -> 3.9297686
B29: EBT Margin (%) | C29: =C28/C11 -> 0.18211712 | D29: =D28/D11 -> 0.04198448 | E29: =E28/E11 -> -0.042256846 | F29: =F28/F11 -> -0.21144696 | H29: =H28/H11 -> #DIV/0! | I29: =I28/I11 -> #DIV/0! | J29: =J28/J11 -> #DIV/0! | K29: =K28/K11 -> 0.04198448 | L29: =L28/L11 -> #DIV/0! | M29: =M28/M11 -> #DIV/0! | N29: =N28/N11 -> #DIV/0! | O29: =O28/O11 -> -0.042256846 | ... T29: =T28/T11 -> #DIV/0! | V29: =V28/V11 -> 0.04198448 | W29: =W28/W11 -> 0.04198448 | X29: =X28/X11 -> 0.04198448 | Y29: =Y28/Y11 -> 0.04198448 | Z29: =Z28/Z11 -> -0.042256846 | AA29: =AA28/AA11 -> -0.042256846 | AB29: =AB28/AB11 -> -0.042256846 | AC29: =AC28/AC11 -> -0.042256846 | ... AE29: =AE28/AE11 -> -0.21144696 | AG29: =SUM(AE29-AA29)*1000 -> -169.19011
B31: Income tax expense | C31: -646 | D31: -227 | E31: 361 | F31: 305 | K31: =SUM(D31-SUM(H31:J31)) -> -227 | O31: =SUM(E31-SUM(L31:N31)) -> 361 | S31: =SUM(F31-SUM(P31:R31)) -> 305 | V31: =SUM(H31:K31) -> -227 | W31: =SUM(I31:L31) -> -227 | X31: =SUM(J31:M31) -> -227 | Y31: =SUM(K31:N31) -> -227 | Z31: =SUM(L31:O31) -> 361 | AA31: =SUM(M31:P31) -> 361 | AB31: =SUM(N31:Q31) -> 361 | AC31: =SUM(O31:R31) -> 361 | ... AE31: =SUM(Q31:T31) -> 305 | AG31: =SUM(AE31/AA31)-1 -> -0.15512465
B32: Equity in loss of investee companies, net of tax | C32: -91 | D32: -204 | E32: -360 | F32: -291 | K32: =SUM(D32-SUM(H32:J32)) -> -204 | O32: =SUM(E32-SUM(L32:N32)) -> -360 | S32: =SUM(F32-SUM(P32:R32)) -> -291 | V32: =SUM(H32:K32) -> -204 | W32: =SUM(I32:L32) -> -204 | X32: =SUM(J32:M32) -> -204 | Y32: =SUM(K32:N32) -> -204 | Z32: =SUM(L32:O32) -> -360 | AA32: =SUM(M32:P32) -> -360 | AB32: =SUM(N32:Q32) -> -360 | AC32: =SUM(O32:R32) -> -360 | ... AE32: =SUM(Q32:T32) -> -291
B33: Net earnings (loss) from continuing operations | C33: =SUM(C28+SUM(C31:C32)) -> 4469 | D33: =SUM(D28+SUM(D31:D32)) -> 835 | E33: =SUM(E28+SUM(E31:E32)) -> -1252 | F33: =SUM(F28+SUM(F31:F32)) -> -6163 | H33: =SUM(H28+SUM(H31:H32)) -> 0 | I33: =SUM(I28+SUM(I31:I32)) -> 0 | J33: =SUM(J28+SUM(J31:J32)) -> 0 | K33: =SUM(K28+SUM(K31:K32)) -> 835 | L33: =SUM(L28+SUM(L31:L32)) -> 0 | M33: =SUM(M28+SUM(M31:M32)) -> 0 | N33: =SUM(N28+SUM(N31:N32)) -> 0 | O33: =SUM(O28+SUM(O31:O32)) -> -1252 | ... T33: =SUM(T28+SUM(T31:T32)) -> 0 | V33: =SUM(V23+SUM(V31:V32)) -> -1362 | W33: =SUM(W23+SUM(W31:W32)) -> -1362 | X33: =SUM(X23+SUM(X31:X32)) -> -1362 | Y33: =SUM(Y23+SUM(Y31:Y32)) -> -1362 | Z33: =SUM(Z23+SUM(Z31:Z32)) -> -919 | AA33: =SUM(AA23+SUM(AA31:AA32)) -> -919 | AB33: =SUM(AB23+SUM(AB31:AB32)) -> -919 | AC33: =SUM(AC23+SUM(AC31:AC32)) -> -919 | ... AE33: =SUM(AE23+SUM(AE31:AE32)) -> -846 | AG33: =SUM(AE33/AA33)-1 -> -0.079434168
B35: Net earnings from discontinued operations, net of tax | C35: 162 | D35: 379 | E35: 676 | F35: 14 | K35: =SUM(D35-SUM(H35:J35)) -> 379 | O35: =SUM(E35-SUM(L35:N35)) -> 676 | S35: =SUM(F35-SUM(P35:R35)) -> 14 | V35: =SUM(H35:K35) -> 379 | W35: =SUM(I35:L35) -> 379 | X35: =SUM(J35:M35) -> 379 | Y35: =SUM(K35:N35) -> 379 | Z35: =SUM(L35:O35) -> 676 | AA35: =SUM(M35:P35) -> 676 | AB35: =SUM(N35:Q35) -> 676 | AC35: =SUM(O35:R35) -> 676 | ... AE35: =SUM(Q35:T35) -> 14 | AG35: =SUM(AE35/AA35)-1 -> -0.97928994
B36: Net earnings (loss) (Paramount and noncontrolling interests) | C36: =SUM(C33)+SUM(C35:C35) -> 4631 | D36: =SUM(D33)+SUM(D35:D35) -> 1214 | E36: =SUM(E33)+SUM(E35:E35) -> -576 | F36: =SUM(F33)+SUM(F35:F35) -> -6149 | H36: =SUM(H33)+SUM(H35:H35) -> 0 | I36: =SUM(I33)+SUM(I35:I35) -> 0 | J36: =SUM(J33)+SUM(J35:J35) -> 0 | K36: =SUM(K33)+SUM(K35:K35) -> 1214 | L36: =SUM(L33)+SUM(L35:L35) -> 0 | M36: =SUM(M33)+SUM(M35:M35) -> 0 | N36: =SUM(N33)+SUM(N35:N35) -> 0 | O36: =SUM(O33)+SUM(O35:O35) -> -576 | ... T36: =SUM(T33)+SUM(T35:T35) -> 0 | V36: =SUM(V33)+SUM(V35:V35) -> -983 | W36: =SUM(W33)+SUM(W35:W35) -> -983 | X36: =SUM(X33)+SUM(X35:X35) -> -983 | Y36: =SUM(Y33)+SUM(Y35:Y35) -> -983 | Z36: =SUM(Z33)+SUM(Z35:Z35) -> -243 | AA36: =SUM(AA33)+SUM(AA35:AA35) -> -243 | AB36: =SUM(AB33)+SUM(AB35:AB35) -> -243 | AC36: =SUM(AC33)+SUM(AC35:AC35) -> -243 | ... AE36: =SUM(AE33)+SUM(AE35:AE35) -> -832 | AG36: =SUM(AE36/AA36)-1 -> 2.4238683
B38: Net earnings attributable to noncontrolling interests | C38: -88 | D38: -110 | E38: -32 | F38: -41 | K38: =SUM(D38-SUM(H38:J38)) -> -110 | O38: =SUM(E38-SUM(L38:N38)) -> -32 | S38: =SUM(F38-SUM(P38:R38)) -> -41 | V38: =SUM(H38:K38) -> -110 | W38: =SUM(I38:L38) -> -110 | X38: =SUM(J38:M38) -> -110 | Y38: =SUM(K38:N38) -> -110 | Z38: =SUM(L38:O38) -> -32 | AA38: =SUM(M38:P38) -> -32 | AB38: =SUM(N38:Q38) -> -32 | AC38: =SUM(O38:R38) -> -32 | ... AE38: =SUM(Q38:T38) -> -41 | AG38: =SUM(AE38/AA38)-1 -> 0.28125
B39: Net earnings (loss) attributable to Paramount | C39: =SUM(C36+SUM(C38:C38)) -> 4543 | D39: =SUM(D36+SUM(D38:D38)) -> 1104 | E39: =SUM(E36+SUM(E38:E38)) -> -608 | F39: =SUM(F36+SUM(F38:F38)) -> -6190 | H39: =SUM(H36+SUM(H38:H38)) -> 0 | I39: =SUM(I36+SUM(I38:I38)) -> 0 | J39: =SUM(J36+SUM(J38:J38)) -> 0 | K39: =SUM(K36+SUM(K38:K38)) -> 1104 | L39: =SUM(L36+SUM(L38:L38)) -> 0 | M39: =SUM(M36+SUM(M38:M38)) -> 0 | N39: =SUM(N36+SUM(N38:N38)) -> 0 | O39: =SUM(O36+SUM(O38:O38)) -> -608 | ... T39: =SUM(T36+SUM(T38:T38)) -> 0 | V39: =SUM(V36+SUM(V38:V38)) -> -1093 | W39: =SUM(W36+SUM(W38:W38)) -> -1093 | X39: =SUM(X36+SUM(X38:X38)) -> -1093 | Y39: =SUM(Y36+SUM(Y38:Y38)) -> -1093 | Z39: =SUM(Z36+SUM(Z38:Z38)) -> -275 | AA39: =SUM(AA36+SUM(AA38:AA38)) -> -275 | AB39: =SUM(AB36+SUM(AB38:AB38)) -> -275 | AC39: =SUM(AC36+SUM(AC38:AC38)) -> -275 | ... AE39: =SUM(AE36+SUM(AE38:AE38)) -> -873 | AG39: =SUM(AE39/AA39)-1 -> 2.1745455
B40: Net Margin (%) | C40: =C39/C11 -> 0.15892395 | D40: =D39/D11 -> 0.036612058 | E40: =E39/E11 -> -0.020504519 | F40: =F39/F11 -> -0.21189197 | H40: =H39/H11 -> #DIV/0! | I40: =I39/I11 -> #DIV/0! | J40: =J39/J11 -> #DIV/0! | K40: =K39/K11 -> 0.036612058 | L40: =L39/L11 -> #DIV/0! | M40: =M39/M11 -> #DIV/0! | N40: =N39/N11 -> #DIV/0! | O40: =O39/O11 -> -0.020504519 | ... T40: =T39/T11 -> #DIV/0! | V40: =V39/V11 -> -0.036247264 | W40: =W39/W11 -> -0.036247264 | X40: =X39/X11 -> -0.036247264 | Y40: =Y39/Y11 -> -0.036247264 | Z40: =Z39/Z11 -> -0.0092742479 | AA40: =AA39/AA11 -> -0.0092742479 | AB40: =AB39/AB11 -> -0.0092742479 | AC40: =AC39/AC11 -> -0.0092742479 | ... AE40: =AE39/AE11 -> -0.029883956 | AG40: =SUM(AE40-AA40)*1000 -> -20.609708
B42: Basic shares | C42: 641 | K42: =D42 -> 0 | O42: =E42 -> 0 | S42: =F42 -> 0 | V42: =K42 -> 0 | W42: =L42 -> 0 | X42: =M42 -> 0 | Y42: =N42 -> 0 | Z42: =O42 -> 0 | AA42: =P42 -> 0 | AB42: =Q42 -> 0 | AC42: =R42 -> 0 | ... AE42: =T42 -> 0 | AG42: =SUM(AE42/AA42)-1 -> #DIV/0!
B43: Basic EPS | C43: =C39/C42 -> 7.0873635 | D43: =D39/D42 -> #DIV/0! | E43: =E39/E42 -> #DIV/0! | F43: =F39/F42 -> #DIV/0! | H43: =H39/H42 -> #DIV/0! | I43: =I39/I42 -> #DIV/0! | J43: =J39/J42 -> #DIV/0! | K43: =K39/K42 -> #DIV/0! | L43: =L39/L42 -> #DIV/0! | M43: =M39/M42 -> #DIV/0! | N43: =N39/N42 -> #DIV/0! | O43: =O39/O42 -> #DIV/0! | ... T43: =T39/T42 -> #DIV/0! | V43: =V39/V42 -> #DIV/0! | W43: =W39/W42 -> #DIV/0! | X43: =X39/X42 -> #DIV/0! | Y43: =Y39/Y42 -> #DIV/0! | Z43: =Z39/Z42 -> #DIV/0! | AA43: =AA39/AA42 -> #DIV/0! | AB43: =AB39/AB42 -> #DIV/0! | AC43: =AC39/AC42 -> #DIV/0! | ... AE43: =AE39/AE42 -> #DIV/0! | AG43: =SUM(AE43/AA43)-1 -> #DIV/0!
B45: Fully Diluted Shares | C45: 655 | K45: =D45 -> 0 | O45: =E45 -> 0 | S45: =F45 -> 0 | V45: =K45 -> 0 | W45: =L45 -> 0 | X45: =M45 -> 0 | Y45: =N45 -> 0 | Z45: =O45 -> 0 | AA45: =P45 -> 0 | AB45: =Q45 -> 0 | AC45: =R45 -> 0 | ... AE45: =T45 -> 0 | AG45: =SUM(AE45/AA45)-1 -> #DIV/0!
B46: Diluted EPS | C46: =C39/C45 -> 6.9358779 | D46: =D39/D45 -> #DIV/0! | E46: =E39/E45 -> #DIV/0! | F46: =F39/F45 -> #DIV/0! | H46: =H39/H45 -> #DIV/0! | I46: =I39/I45 -> #DIV/0! | J46: =J39/J45 -> #DIV/0! | K46: =K39/K45 -> #DIV/0! | L46: =L39/L45 -> #DIV/0! | M46: =M39/M45 -> #DIV/0! | N46: =N39/N45 -> #DIV/0! | O46: =O39/O45 -> #DIV/0! | ... T46: =T39/T45 -> #DIV/0! | V46: =V39/V45 -> #DIV/0! | W46: =W39/W45 -> #DIV/0! | X46: =X39/X45 -> #DIV/0! | Y46: =Y39/Y45 -> #DIV/0! | Z46: =Z39/Z45 -> #DIV/0! | AA46: =AA39/AA45 -> #DIV/0! | AB46: =AB39/AB45 -> #DIV/0! | AC46: =AC39/AC45 -> #DIV/0! | ... AE46: =AE39/AE45 -> #DIV/0! | AG46: =SUM(AE46/AA46)-1 -> #DIV/0!
A48: X | B48: Balance Sheet | C48: FYE | N48: Quarterly | AA48: LTM | AG48: Variance
B49: =B7 -> Fiscal Period | C49: =C7 -> 2021 | D49: =D7 -> 2022 | E49: =E7 -> 2023 | F49: =F7 -> 2024 | H49: =H7 -> 1Q23 | I49: =I7 -> 2Q23 | J49: =J7 -> 3Q23 | K49: =K7 -> 4Q23 | L49: =L7 -> 1Q24 | M49: =M7 -> 2Q24 | N49: =N7 -> 3Q24 | O49: =O7 -> 4Q24 | ... T49: =T7 -> 1Q26 | V49: =V7 -> 4Q23 | W49: =W7 -> 1Q24 | X49: =X7 -> 2Q24 | Y49: =Y7 -> 3Q24 | Z49: =Z7 -> 4Q24 | AA49: =AA7 -> 1Q25 | AB49: =AB7 -> 2Q25 | AC49: =AC7 -> 3Q25 | ... AE49: =AE7 -> 1Q26
B50: =B8 -> Fiscal Period End Date | C50: =C8 -> 44561 | D50: =D8 -> 44926 | E50: =E8 -> 45291 | F50: =F8 -> 45657 | H50: =H8 -> XXX | I50: =I8 -> XXX | J50: =J8 -> XXX | K50: =K8 -> 44926 | L50: =L8 -> XXX | M50: =M8 -> XXX | N50: =N8 -> XXX | O50: =O8 -> 45291 | ... T50: =T8 -> XXX | V50: =V8 -> 44926 | W50: =W8 -> XXX | X50: =X8 -> XXX | Y50: =Y8 -> XXX | Z50: =Z8 -> 45291 | AA50: =AA8 -> XXX | AB50: =AB8 -> XXX | AC50: =AC8 -> XXX | ... AE50: =AE8 -> XXX
B52: Current Assets
...

Sheet Revenue Drivers
B2: ='Historical Financials'!B2 -> Paramount Global (NASDAQ: PARA) | C2: FYE | N2: Quarterly | AA2: LTM
B3: Segment Anaysis | C3: ='Historical Financials'!C7 -> 2021 | D3: ='Historical Financials'!D7 -> 2022 | E3: ='Historical Financials'!E7 -> 2023 | F3: ='Historical Financials'!F7 -> 2024 | H3: ='Historical Financials'!H7 -> 1Q23 | I3: ='Historical Financials'!I7 -> 2Q23 | J3: ='Historical Financials'!J7 -> 3Q23 | K3: ='Historical Financials'!K7 -> 4Q23 | L3: ='Historical Financials'!L7 -> 1Q24 | M3: ='Historical Financials'!M7 -> 2Q24 | N3: ='Historical Financials'!N7 -> 3Q24 | O3: ='Historical Financials'!O7 -> 4Q24 | ... T3: ='Historical Financials'!T7 -> 1Q26 | V3: =K3 -> 4Q23 | W3: =L3 -> 1Q24 | X3: =M3 -> 2Q24 | Y3: =N3 -> 3Q24 | Z3: =O3 -> 4Q24 | AA3: =P3 -> 1Q25 | AB3: =Q3 -> 2Q25 | AC3: =R3 -> 3Q25 | ... AE3: =T3 -> 1Q26
B4: ($ In Millions) | C4: ='Historical Financials'!C8 -> 44561 | D4: ='Historical Financials'!D8 -> 44926 | E4: ='Historical Financials'!E8 -> 45291 | F4: ='Historical Financials'!F8 -> 45657 | H4: ='Historical Financials'!H8 -> XXX | I4: ='Historical Financials'!I8 -> XXX | J4: ='Historical Financials'!J8 -> XXX | K4: ='Historical Financials'!K8 -> 44926 | L4: ='Historical Financials'!L8 -> XXX | M4: ='Historical Financials'!M8 -> XXX | N4: ='Historical Financials'!N8 -> XXX | O4: ='Historical Financials'!O8 -> 45291 | ... T4: ='Historical Financials'!T8 -> XXX | V4: =K4 -> 44926 | W4: =L4 -> XXX | X4: =M4 -> XXX | Y4: =N4 -> XXX | Z4: =O4 -> 45291 | AA4: =P4 -> XXX | AB4: =Q4 -> XXX | AC4: =R4 -> XXX | ... AE4: =T4 -> XXX
A6: X | B6: Revenue by reportable segment
A8: X | B8: Revenue by Type
B9: Advertising | C9: 11412 | D9: 10890 | E9: 9989 | F9: 10295 | K9: =SUM(D9-SUM(H9:J9)) -> 10890 | O9: =SUM(E9-SUM(L9:N9)) -> 9989 | S9: =SUM(F9-SUM(P9:R9)) -> 10295 | V9: =SUM(H9:K9) -> 10890 | W9: =SUM(I9:L9) -> 10890 | X9: =SUM(J9:M9) -> 10890 | Y9: =SUM(K9:N9) -> 10890 | Z9: =SUM(L9:O9) -> 9989 | AA9: =SUM(M9:P9) -> 9989 | AB9: =SUM(N9:Q9) -> 9989 | AC9: =SUM(O9:R9) -> 9989 | ... AE9: =SUM(Q9:T9) -> 10295
B10: Affiliate and subscription | C10: 10442 | D10: 11551 | E10: 13018 | F10: 13153 | K10: =SUM(D10-SUM(H10:J10)) -> 11551 | O10: =SUM(E10-SUM(L10:N10)) -> 13018 | S10: =SUM(F10-SUM(P10:R10)) -> 13153 | V10: =SUM(H10:K10) -> 11551 | W10: =SUM(I10:L10) -> 11551 | X10: =SUM(J10:M10) -> 11551 | Y10: =SUM(K10:N10) -> 11551 | Z10: =SUM(L10:O10) -> 13018 | AA10: =SUM(M10:P10) -> 13018 | AB10: =SUM(N10:Q10) -> 13018 | AC10: =SUM(O10:R10) -> 13018 | ... AE10: =SUM(Q10:T10) -> 13153
B11: Theatrical | C11: 241 | D11: 1223 | E11: 813 | F11: 813 | K11: =SUM(D11-SUM(H11:J11)) -> 1223 | O11: =SUM(E11-SUM(L11:N11)) -> 813 | S11: =SUM(F11-SUM(P11:R11)) -> 813 | V11: =SUM(H11:K11) -> 1223 | W11: =SUM(I11:L11) -> 1223 | X11: =SUM(J11:M11) -> 1223 | Y11: =SUM(K11:N11) -> 1223 | Z11: =SUM(L11:O11) -> 813 | AA11: =SUM(M11:P11) -> 813 | AB11: =SUM(N11:Q11) -> 813 | AC11: =SUM(O11:R11) -> 813 | ... AE11: =SUM(Q11:T11) -> 813
B12: Licensing and other | C12: 6491 | D12: 6490 | E12: 5832 | F12: 4952 | K12: =SUM(D12-SUM(H12:J12)) -> 6490 | O12: =SUM(E12-SUM(L12:N12)) -> 5832 | S12: =SUM(F12-SUM(P12:R12)) -> 4952 | V12: =SUM(H12:K12) -> 6490 | W12: =SUM(I12:L12) -> 6490 | X12: =SUM(J12:M12) -> 6490 | Y12: =SUM(K12:N12) -> 6490 | Z12: =SUM(L12:O12) -> 5832 | AA12: =SUM(M12:P12) -> 5832 | AB12: =SUM(N12:Q12) -> 5832 | AC12: =SUM(O12:R12) -> 5832 | ... AE12: =SUM(Q12:T12) -> 4952
B13: Total Net Revenue | C13: =SUM(C9:C12) -> 28586 | D13: =SUM(D9:D12) -> 30154 | E13: =SUM(E9:E12) -> 29652 | F13: =SUM(F9:F12) -> 29213 | H13: =SUM(H9:H12) -> 0 | I13: =SUM(I9:I12) -> 0 | J13: =SUM(J9:J12) -> 0 | K13: =SUM(K9:K12) -> 30154 | L13: =SUM(L9:L12) -> 0 | M13: =SUM(M9:M12) -> 0 | N13: =SUM(N9:N12) -> 0 | O13: =SUM(O9:O12) -> 29652 | ... T13: =SUM(T9:T12) -> 0 | V13: =SUM(V9:V12) -> 30154 | W13: =SUM(W9:W12) -> 30154 | X13: =SUM(X9:X12) -> 30154 | Y13: =SUM(Y9:Y12) -> 30154 | Z13: =SUM(Z9:Z12) -> 29652 | AA13: =SUM(AA9:AA12) -> 29652 | AB13: =SUM(AB9:AB12) -> 29652 | AC13: =SUM(AC9:AC12) -> 29652 | ... AE13: =SUM(AE9:AE12) -> 29213
B14: Variance Check | C14: =+C13-'Historical Financials'!C11 -> 0 | D14: =+D13-'Historical Financials'!D11 -> 0 | E14: =+E13-'Historical Financials'!E11 -> 0 | F14: =+F13-'Historical Financials'!F11 -> 0 | H14: =+H13-'Historical Financials'!H11 -> 0 | I14: =+I13-'Historical Financials'!I11 -> 0 | J14: =+J13-'Historical Financials'!J11 -> 0 | K14: =+K13-'Historical Financials'!K11 -> 0 | L14: =+L13-'Historical Financials'!L11 -> 0 | M14: =+M13-'Historical Financials'!M11 -> 0 | N14: =+N13-'Historical Financials'!N11 -> 0 | O14: =+O13-'Historical Financials'!O11 -> 0 | ... T14: =+T13-'Historical Financials'!T11 -> 0 | V14: =+V13-'Historical Financials'!V11 -> 0 | W14: =+W13-'Historical Financials'!W11 -> 0 | X14: =+X13-'Historical Financials'!X11 -> 0 | Y14: =+Y13-'Historical Financials'!Y11 -> 0 | Z14: =+Z13-'Historical Financials'!Z11 -> 0 | AA14: =+AA13-'Historical Financials'!AA11 -> 0 | AB14: =+AB13-'Historical Financials'!AB11 -> 0 | AC14: =+AC13-'Historical Financials'!AC11 -> 0 | ... AE14: =+AE13-'Historical Financials'!AE11 -> 0
B16: =B9&"(%)" -> Advertising(%) | C16: =SUM(C9/C$13) -> 0.3992164 | D16: =SUM(D9/D$13) -> 0.36114612 | E16: =SUM(E9/E$13) -> 0.33687441 | F16: =SUM(F9/F$13) -> 0.3524116 | H16: =SUM(H9/H$13) -> #DIV/0! | I16: =SUM(I9/I$13) -> #DIV/0! | J16: =SUM(J9/J$13) -> #DIV/0! | K16: =SUM(K9/K$13) -> 0.36114612 | L16: =SUM(L9/L$13) -> #DIV/0! | M16: =SUM(M9/M$13) -> #DIV/0! | N16: =SUM(N9/N$13) -> #DIV/0! | O16: =SUM(O9/O$13) -> 0.33687441 | ... T16: =SUM(T9/T$13) -> #DIV/0! | V16: =I16 -> #DIV/0! | W16: =J16 -> #DIV/0! | X16: =K16 -> 0.36114612 | Y16: =L16 -> #DIV/0! | Z16: =M16 -> #DIV/0! | AA16: =N16 -> #DIV/0! | AB16: =O16 -> 0.33687441 | AC16: =P16 -> #DIV/0! | ... AE16: =R16 -> #DIV/0!
B17: =B10&"(%)" -> Affiliate and subscription(%) | C17: =SUM(C10/C$13) -> 0.36528371 | D17: =SUM(D10/D$13) -> 0.38306692 | E17: =SUM(E10/E$13) -> 0.43902604 | F17: =SUM(F10/F$13) -> 0.45024475 | H17: =SUM(H10/H$13) -> #DIV/0! | I17: =SUM(I10/I$13) -> #DIV/0! | J17: =SUM(J10/J$13) -> #DIV/0! | K17: =SUM(K10/K$13) -> 0.38306692 | L17: =SUM(L10/L$13) -> #DIV/0! | M17: =SUM(M10/M$13) -> #DIV/0! | N17: =SUM(N10/N$13) -> #DIV/0! | O17: =SUM(O10/O$13) -> 0.43902604 | ... T17: =SUM(T10/T$13) -> #DIV/0! | V17: =I17 -> #DIV/0! | W17: =J17 -> #DIV/0! | X17: =K17 -> 0.38306692 | Y17: =L17 -> #DIV/0! | Z17: =M17 -> #DIV/0! | AA17: =N17 -> #DIV/0! | AB17: =O17 -> 0.43902604 | AC17: =P17 -> #DIV/0! | ... AE17: =R17 -> #DIV/0!
B18: =B11&"(%)" -> Theatrical(%) | C18: =SUM(C11/C$13) -> 0.0084307003 | D18: =SUM(D11/D$13) -> 0.040558467 | E18: =SUM(E11/E$13) -> 0.027418049 | F18: =SUM(F11/F$13) -> 0.027830076 | H18: =SUM(H11/H$13) -> #DIV/0! | I18: =SUM(I11/I$13) -> #DIV/0! | J18: =SUM(J11/J$13) -> #DIV/0! | K18: =SUM(K11/K$13) -> 0.040558467 | L18: =SUM(L11/L$13) -> #DIV/0! | M18: =SUM(M11/M$13) -> #DIV/0! | N18: =SUM(N11/N$13) -> #DIV/0! | O18: =SUM(O11/O$13) -> 0.027418049 | ... T18: =SUM(T11/T$13) -> #DIV/0! | V18: =I18 -> #DIV/0! | W18: =J18 -> #DIV/0! | X18: =K18 -> 0.040558467 | Y18: =L18 -> #DIV/0! | Z18: =M18 -> #DIV/0! | AA18: =N18 -> #DIV/0! | AB18: =O18 -> 0.027418049 | AC18: =P18 -> #DIV/0! | ... AE18: =R18 -> #DIV/0!
B19: =B12&"(%)" -> Licensing and other(%) | C19: =SUM(C12/C$13) -> 0.22706919 | D19: =SUM(D12/D$13) -> 0.21522849 | E19: =SUM(E12/E$13) -> 0.19668151 | F19: =SUM(F12/F$13) -> 0.16951357 | H19: =SUM(H12/H$13) -> #DIV/0! | I19: =SUM(I12/I$13) -> #DIV/0! | J19: =SUM(J12/J$13) -> #DIV/0! | K19: =SUM(K12/K$13) -> 0.21522849 | L19: =SUM(L12/L$13) -> #DIV/0! | M19: =SUM(M12/M$13) -> #DIV/0! | N19: =SUM(N12/N$13) -> #DIV/0! | O19: =SUM(O12/O$13) -> 0.19668151 | ... T19: =SUM(T12/T$13) -> #DIV/0! | V19: =I19 -> #DIV/0! | W19: =J19 -> #DIV/0! | X19: =K19 -> 0.21522849 | Y19: =L19 -> #DIV/0! | Z19: =M19 -> #DIV/0! | AA19: =N19 -> #DIV/0! | AB19: =O19 -> 0.19668151 | AC19: =P19 -> #DIV/0! | ... AE19: =R19 -> #DIV/0!
A21: X | B21: Revenue by Type
B22: TV Media | C22: 22734 | D22: 21732 | E22: 20085 | F22: 18779 | K22: =SUM(D22-SUM(H22:J22)) -> 21732 | O22: =SUM(E22-SUM(L22:N22)) -> 20085 | S22: =SUM(F22-SUM(P22:R22)) -> 18779 | V22: =SUM(H22:K22) -> 21732 | W22: =SUM(I22:L22) -> 21732 | X22: =SUM(J22:M22) -> 21732 | Y22: =SUM(K22:N22) -> 21732 | Z22: =SUM(L22:O22) -> 20085 | AA22: =SUM(M22:P22) -> 20085 | AB22: =SUM(N22:Q22) -> 20085 | AC22: =SUM(O22:R22) -> 20085 | ... AE22: =SUM(Q22:T22) -> 18779
B23: Direct-to-Consumer | C23: 3327 | D23: 4904 | E23: 6736 | F23: 7632 | K23: =SUM(D23-SUM(H23:J23)) -> 4904 | O23: =SUM(E23-SUM(L23:N23)) -> 6736 | S23: =SUM(F23-SUM(P23:R23)) -> 7632 | V23: =SUM(H23:K23) -> 4904 | W23: =SUM(I23:L23) -> 4904 | X23: =SUM(J23:M23) -> 4904 | Y23: =SUM(K23:N23) -> 4904 | Z23: =SUM(L23:O23) -> 6736 | AA23: =SUM(M23:P23) -> 6736 | AB23: =SUM(N23:Q23) -> 6736 | AC23: =SUM(O23:R23) -> 6736 | ... AE23: =SUM(Q23:T23) -> 7632
B24: Filmed Entertainment | C24: 2687 | D24: 3706 | E24: 2957 | F24: 2955 | K24: =SUM(D24-SUM(H24:J24)) -> 3706 | O24: =SUM(E24-SUM(L24:N24)) -> 2957 | S24: =SUM(F24-SUM(P24:R24)) -> 2955 | V24: =SUM(H24:K24) -> 3706 | W24: =SUM(I24:L24) -> 3706 | X24: =SUM(J24:M24) -> 3706 | Y24: =SUM(K24:N24) -> 3706 | Z24: =SUM(L24:O24) -> 2957 | AA24: =SUM(M24:P24) -> 2957 | AB24: =SUM(N24:Q24) -> 2957 | AC24: =SUM(O24:R24) -> 2957 | ... AE24: =SUM(Q24:T24) -> 2955
B25: Eliminations | C25: -162 | D25: -188 | E25: -126 | F25: -153 | K25: =SUM(D25-SUM(H25:J25)) -> -188 | O25: =SUM(E25-SUM(L25:N25)) -> -126 | S25: =SUM(F25-SUM(P25:R25)) -> -153 | V25: =SUM(H25:K25) -> -188 | W25: =SUM(I25:L25) -> -188 | X25: =SUM(J25:M25) -> -188 | Y25: =SUM(K25:N25) -> -188 | Z25: =SUM(L25:O25) -> -126 | AA25: =SUM(M25:P25) -> -126 | AB25: =SUM(N25:Q25) -> -126 | AC25: =SUM(O25:R25) -> -126 | ... AE25: =SUM(Q25:T25) -> -153
B26: Total Net Revenue | C26: =SUM(C22:C25) -> 28586 | D26: =SUM(D22:D25) -> 30154 | E26: =SUM(E22:E25) -> 29652 | F26: =SUM(F22:F25) -> 29213 | H26: =SUM(H22:H25) -> 0 | I26: =SUM(I22:I25) -> 0 | J26: =SUM(J22:J25) -> 0 | K26: =SUM(K22:K25) -> 30154 | L26: =SUM(L22:L25) -> 0 | M26: =SUM(M22:M25) -> 0 | N26: =SUM(N22:N25) -> 0 | O26: =SUM(O22:O25) -> 29652 | ... T26: =SUM(T22:T25) -> 0 | V26: =SUM(V22:V25) -> 30154 | W26: =SUM(W22:W25) -> 30154 | X26: =SUM(X22:X25) -> 30154 | Y26: =SUM(Y22:Y25) -> 30154 | Z26: =SUM(Z22:Z25) -> 29652 | AA26: =SUM(AA22:AA25) -> 29652 | AB26: =SUM(AB22:AB25) -> 29652 | AC26: =SUM(AC22:AC25) -> 29652 | ... AE26: =SUM(AE22:AE25) -> 29213
B27: Variance Check | C27: =+C26-C13 -> 0 | D27: =+D26-D13 -> 0 | E27: =+E26-E13 -> 0 | F27: =+F26-F13 -> 0 | H27: =+H26-H13 -> 0 | I27: =+I26-I13 -> 0 | J27: =+J26-J13 -> 0 | K27: =+K26-K13 -> 0 | L27: =+L26-L13 -> 0 | M27: =+M26-M13 -> 0 | N27: =+N26-N13 -> 0 | O27: =+O26-O13 -> 0 | ... T27: =+T26-T13 -> 0 | V27: =+V26-V13 -> 0 | W27: =+W26-W13 -> 0 | X27: =+X26-X13 -> 0 | Y27: =+Y26-Y13 -> 0 | Z27: =+Z26-Z13 -> 0 | AA27: =+AA26-AA13 -> 0 | AB27: =+AB26-AB13 -> 0 | AC27: =+AC26-AC13 -> 0 | ... AE27: =+AE26-AE13 -> 0
B29: =B22&"(%)" -> TV Media(%) | C29: =SUM(C22/C$26) -> 0.7952844 | D29: =SUM(D22/D$26) -> 0.7207004 | E29: =SUM(E22/E$26) -> 0.67735735 | F29: =SUM(F22/F$26) -> 0.64283025 | H29: =SUM(H22/H$26) -> #DIV/0! | I29: =SUM(I22/I$26) -> #DIV/0! | J29: =SUM(J22/J$26) -> #DIV/0! | K29: =SUM(K22/K$26) -> 0.7207004 | L29: =SUM(L22/L$26) -> #DIV/0! | M29: =SUM(M22/M$26) -> #DIV/0! | N29: =SUM(N22/N$26) -> #DIV/0! | O29: =SUM(O22/O$26) -> 0.67735735 | ... T29: =SUM(T22/T$26) -> #DIV/0! | V29: =SUM(V22/V$26) -> 0.7207004 | W29: =SUM(W22/W$26) -> 0.7207004 | X29: =SUM(X22/X$26) -> 0.7207004 | Y29: =SUM(Y22/Y$26) -> 0.7207004 | Z29: =SUM(Z22/Z$26) -> 0.67735735 | AA29: =SUM(AA22/AA$26) -> 0.67735735 | AB29: =SUM(AB22/AB$26) -> 0.67735735 | AC29: =SUM(AC22/AC$26) -> 0.67735735 | ... AE29: =SUM(AE22/AE$26) -> 0.64283025
B30: =B23&"(%)" -> Direct-to-Consumer(%) | C30: =SUM(C23/C$26) -> 0.11638564 | D30: =SUM(D23/D$26) -> 0.16263182 | E30: =SUM(E23/E$26) -> 0.22716849 | F30: =SUM(F23/F$26) -> 0.26125355 | H30: =SUM(H23/H$26) -> #DIV/0! | I30: =SUM(I23/I$26) -> #DIV/0! | J30: =SUM(J23/J$26) -> #DIV/0! | K30: =SUM(K23/K$26) -> 0.16263182 | L30: =SUM(L23/L$26) -> #DIV/0! | M30: =SUM(M23/M$26) -> #DIV/0! | N30: =SUM(N23/N$26) -> #DIV/0! | O30: =SUM(O23/O$26) -> 0.22716849 | ... T30: =SUM(T23/T$26) -> #DIV/0! | V30: =SUM(V23/V$26) -> 0.16263182 | W30: =SUM(W23/W$26) -> 0.16263182 | X30: =SUM(X23/X$26) -> 0.16263182 | Y30: =SUM(Y23/Y$26) -> 0.16263182 | Z30: =SUM(Z23/Z$26) -> 0.22716849 | AA30: =SUM(AA23/AA$26) -> 0.22716849 | AB30: =SUM(AB23/AB$26) -> 0.22716849 | AC30: =SUM(AC23/AC$26) -> 0.22716849 | ... AE30: =SUM(AE23/AE$26) -> 0.26125355
B31: =B24&"(%)" -> Filmed Entertainment(%) | C31: =SUM(C24/C$26) -> 0.093997061 | D31: =SUM(D24/D$26) -> 0.12290243 | E31: =SUM(E24/E$26) -> 0.099723459 | F31: =SUM(F24/F$26) -> 0.1011536 | H31: =SUM(H24/H$26) -> #DIV/0! | I31: =SUM(I24/I$26) -> #DIV/0! | J31: =SUM(J24/J$26) -> #DIV/0! | K31: =SUM(K24/K$26) -> 0.12290243 | L31: =SUM(L24/L$26) -> #DIV/0! | M31: =SUM(M24/M$26) -> #DIV/0! | N31: =SUM(N24/N$26) -> #DIV/0! | O31: =SUM(O24/O$26) -> 0.099723459 | ... T31: =SUM(T24/T$26) -> #DIV/0! | V31: =SUM(V24/V$26) -> 0.12290243 | W31: =SUM(W24/W$26) -> 0.12290243 | X31: =SUM(X24/X$26) -> 0.12290243 | Y31: =SUM(Y24/Y$26) -> 0.12290243 | Z31: =SUM(Z24/Z$26) -> 0.099723459 | AA31: =SUM(AA24/AA$26) -> 0.099723459 | AB31: =SUM(AB24/AB$26) -> 0.099723459 | AC31: =SUM(AC24/AC$26) -> 0.099723459 | ... AE31: =SUM(AE24/AE$26) -> 0.1011536
A33: X | B33: Revenue by product category: Revenue by TV Media
A35: X | B35: Revenue by TV Media
B36: Advertising | C36: 10105 | D36: 9350 | E36: 8188 | F36: 8180 | K36: =SUM(D36-SUM(H36:J36)) -> 9350 | O36: =SUM(E36-SUM(L36:N36)) -> 8188 | S36: =SUM(F36-SUM(P36:R36)) -> 8180 | V36: =SUM(H36:K36) -> 9350 | W36: =SUM(I36:L36) -> 9350 | X36: =SUM(J36:M36) -> 9350 | Y36: =SUM(K36:N36) -> 9350 | Z36: =SUM(L36:O36) -> 8188 | AA36: =SUM(M36:P36) -> 8188 | AB36: =SUM(N36:Q36) -> 8188 | AC36: =SUM(O36:R36) -> 8188 | ... AE36: =SUM(Q36:T36) -> 8180
B37: Affiliate and subscription | C37: 8413 | D37: 8180 | E37: 8085 | F37: 7647 | K37: =SUM(D37-SUM(H37:J37)) -> 8180 | O37: =SUM(E37-SUM(L37:N37)) -> 8085 | S37: =SUM(F37-SUM(P37:R37)) -> 7647 | V37: =SUM(H37:K37) -> 8180 | W37: =SUM(I37:L37) -> 8180 | X37: =SUM(J37:M37) -> 8180 | Y37: =SUM(K37:N37) -> 8180 | Z37: =SUM(L37:O37) -> 8085 | AA37: =SUM(M37:P37) -> 8085 | AB37: =SUM(N37:Q37) -> 8085 | AC37: =SUM(O37:R37) -> 8085 | ... AE37: =SUM(Q37:T37) -> 7647
B38: Licensing and other | C38: 4216 | D38: 4202 | E38: 3812 | F38: 2952 | K38: =SUM(D38-SUM(H38:J38)) -> 4202 | O38: =SUM(E38-SUM(L38:N38)) -> 3812 | S38: =SUM(F38-SUM(P38:R38)) -> 2952 | V38: =SUM(H38:K38) -> 4202 | W38: =SUM(I38:L38) -> 4202 | X38: =SUM(J38:M38) -> 4202 | Y38: =SUM(K38:N38) -> 4202 | Z38: =SUM(L38:O38) -> 3812 | AA38: =SUM(M38:P38) -> 3812 | AB38: =SUM(N38:Q38) -> 3812 | AC38: =SUM(O38:R38) -> 3812 | ... AE38: =SUM(Q38:T38) -> 2952
B39: Total Revenue from TV Media | C39: =SUM(C36:C38) -> 22734 | D39: =SUM(D36:D38) -> 21732 | E39: =SUM(E36:E38) -> 20085 | F39: =SUM(F36:F38) -> 18779 | H39: =SUM(H36:H38) -> 0 | I39: =SUM(I36:I38) -> 0 | J39: =SUM(J36:J38) -> 0 | K39: =SUM(K36:K38) -> 21732 | L39: =SUM(L36:L38) -> 0 | M39: =SUM(M36:M38) -> 0 | N39: =SUM(N36:N38) -> 0 | O39: =SUM(O36:O38) -> 20085 | ... T39: =SUM(T36:T38) -> 0 | V39: =SUM(V36:V38) -> 21732 | W39: =SUM(W36:W38) -> 21732 | X39: =SUM(X36:X38) -> 21732 | Y39: =SUM(Y36:Y38) -> 21732 | Z39: =SUM(Z36:Z38) -> 20085 | AA39: =SUM(AA36:AA38) -> 20085 | AB39: =SUM(AB36:AB38) -> 20085 | AC39: =SUM(AC36:AC38) -> 20085 | ... AE39: =SUM(AE36:AE38) -> 18779
B40: Variance Check | C40: =+C39-C22 -> 0 | D40: =+D39-D22 -> 0 | E40: =+E39-E22 -> 0 | F40: =+F39-F22 -> 0 | H40: =+H39-H22 -> 0 | I40: =+I39-I22 -> 0 | J40: =+J39-J22 -> 0 | K40: =+K39-K22 -> 0 | L40: =+L39-L22 -> 0 | M40: =+M39-M22 -> 0 | N40: =+N39-N22 -> 0 | O40: =+O39-O22 -> 0 | ... T40: =+T39-T22 -> 0 | V40: =+V39-V22 -> 0 | W40: =+W39-W22 -> 0 | X40: =+X39-X22 -> 0 | Y40: =+Y39-Y22 -> 0 | Z40: =+Z39-Z22 -> 0 | AA40: =+AA39-AA22 -> 0 | AB40: =+AB39-AB22 -> 0 | AC40: =+AC39-AC22 -> 0 | ... AE40: =+AE39-AE22 -> 0
B42: =B36&"(%)" -> Advertising(%) | C42: =C36/C$39 -> 0.44448843 | D42: =D36/D$39 -> 0.43024112 | E42: =E36/E$39 -> 0.40766741 | F42: =F36/F$39 -> 0.43559295 | H42: =H36/H$39 -> #DIV/0! | I42: =I36/I$39 -> #DIV/0! | J42: =J36/J$39 -> #DIV/0! | K42: =K36/K$39 -> 0.43024112 | L42: =L36/L$39 -> #DIV/0! | M42: =M36/M$39 -> #DIV/0! | N42: =N36/N$39 -> #DIV/0! | O42: =O36/O$39 -> 0.40766741 | ... T42: =T36/T$39 -> #DIV/0! | V42: =V36/V$39 -> 0.43024112 | W42: =W36/W$39 -> 0.43024112 | X42: =X36/X$39 -> 0.43024112 | Y42: =Y36/Y$39 -> 0.43024112 | Z42: =Z36/Z$39 -> 0.40766741 | AA42: =AA36/AA$39 -> 0.40766741 | AB42: =AB36/AB$39 -> 0.40766741 | AC42: =AC36/AC$39 -> 0.40766741 | ... AE42: =AE36/AE$39 -> 0.43559295
B43: =B37&"(%)" -> Affiliate and subscription(%) | C43: =C37/C$39 -> 0.37006246 | D43: =D37/D$39 -> 0.37640346 | E43: =E37/E$39 -> 0.40253921 | F43: =F37/F$39 -> 0.40721018 | H43: =H37/H$39 -> #DIV/0! | I43: =I37/I$39 -> #DIV/0! | J43: =J37/J$39 -> #DIV/0! | K43: =K37/K$39 -> 0.37640346 | L43: =L37/L$39 -> #DIV/0! | M43: =M37/M$39 -> #DIV/0! | N43: =N37/N$39 -> #DIV/0! | O43: =O37/O$39 -> 0.40253921 | ... T43: =T37/T$39 -> #DIV/0! | V43: =V37/V$39 -> 0.37640346 | W43: =W37/W$39 -> 0.37640346 | X43: =X37/X$39 -> 0.37640346 | Y43: =Y37/Y$39 -> 0.37640346 | Z43: =Z37/Z$39 -> 0.40253921 | AA43: =AA37/AA$39 -> 0.40253921 | AB43: =AB37/AB$39 -> 0.40253921 | AC43: =AC37/AC$39 -> 0.40253921 | ... AE43: =AE37/AE$39 -> 0.40721018
B44: =B38&"(%)" -> Licensing and other(%) | C44: =C38/C$39 -> 0.18544911 | D44: =D38/D$39 -> 0.19335542 | E44: =E38/E$39 -> 0.18979338 | F44: =F38/F$39 -> 0.15719687 | H44: =H38/H$39 -> #DIV/0! | I44: =I38/I$39 -> #DIV/0! | J44: =J38/J$39 -> #DIV/0! | K44: =K38/K$39 -> 0.19335542 | L44: =L38/L$39 -> #DIV/0! | M44: =M38/M$39 -> #DIV/0! | N44: =N38/N$39 -> #DIV/0! | O44: =O38/O$39 -> 0.18979338 | ... T44: =T38/T$39 -> #DIV/0! | V44: =V38/V$39 -> 0.19335542 | W44: =W38/W$39 -> 0.19335542 | X44: =X38/X$39 -> 0.19335542 | Y44: =Y38/Y$39 -> 0.19335542 | Z44: =Z38/Z$39 -> 0.18979338 | AA44: =AA38/AA$39 -> 0.18979338 | AB44: =AB38/AB$39 -> 0.18979338 | AC44: =AC38/AC$39 -> 0.18979338 | ... AE44: =AE38/AE$39 -> 0.15719687
A46: X | B46: Revenue by product category: Direct to Consumer
A48: X | B48: Revenue by Direct-to-Consumer
B49: Advertising | C49: 1298 | D49: 1533 | E49: 1795 | F49: 2114 | K49: =SUM(D49-SUM(H49:J49)) -> 1533 | O49: =SUM(E49-SUM(L49:N49)) -> 1795 | S49: =SUM(F49-SUM(P49:R49)) -> 2114 | V49: =SUM(H49:K49) -> 1533 | W49: =SUM(I49:L49) -> 1533 | X49: =SUM(J49:M49) -> 1533 | Y49: =SUM(K49:N49) -> 1533 | Z49: =SUM(L49:O49) -> 1795 | AA49: =SUM(M49:P49) -> 1795 | AB49: =SUM(N49:Q49) -> 1795 | AC49: =SUM(O49:R49) -> 1795 | ... AE49: =SUM(Q49:T49) -> 2114
B50: Subscription & Licensing | C50: 2029 | D50: 3371 | E50: =4933+8 -> 4941 | F50: =5506+12 -> 5518 | K50: =SUM(D50-SUM(H50:J50)) -> 3371 | O50: =SUM(E50-SUM(L50:N50)) -> 4941 | S50: =SUM(F50-SUM(P50:R50)) -> 5518 | V50: =SUM(H50:K50) -> 3371 | W50: =SUM(I50:L50) -> 3371 | X50: =SUM(J50:M50) -> 3371 | Y50: =SUM(K50:N50) -> 3371 | Z50: =SUM(L50:O50) -> 4941 | AA50: =SUM(M50:P50) -> 4941 | AB50: =SUM(N50:Q50) -> 4941 | AC50: =SUM(O50:R50) -> 4941 | ... AE50: =SUM(Q50:T50) -> 5518
B51: Total Revenue from Direct-to-Consumer | C51: =SUM(C49:C50) -> 3327 | D51: =SUM(D49:D50) -> 4904 | E51: =SUM(E49:E50) -> 6736 | F51: =SUM(F49:F50) -> 7632 | H51: =SUM(H49:H50) -> 0 | I51: =SUM(I49:I50) -> 0 | J51: =SUM(J49:J50) -> 0 | K51: =SUM(K49:K50) -> 4904 | L51: =SUM(L49:L50) -> 0 | M51: =SUM(M49:M50) -> 0 | N51: =SUM(N49:N50) -> 0 | O51: =SUM(O49:O50) -> 6736 | ... T51: =SUM(T49:T50) -> 0 | V51: =SUM(V49:V50) -> 4904 | W51: =SUM(W49:W50) -> 4904 | X51: =SUM(X49:X50) -> 4904 | Y51: =SUM(Y49:Y50) -> 4904 | Z51: =SUM(Z49:Z50) -> 6736 | AA51: =SUM(AA49:AA50) -> 6736 | AB51: =SUM(AB49:AB50) -> 6736 | AC51: =SUM(AC49:AC50) -> 6736 | ... AE51: =SUM(AE49:AE50) -> 7632
...

Sheet FCF
B2: ='Historical Financials'!B2 -> Paramount Global (NASDAQ: PARA) | D2: FYE | H2: Quarterly | R2: Quarterly | Z2: LTM | AA2: LTM | AG2: Variance
B3: FCF Analysis | C3: ='Historical Financials'!C7 -> 2021 | D3: ='Historical Financials'!D7 -> 2022 | E3: ='Historical Financials'!E7 -> 2023 | F3: ='Historical Financials'!F7 -> 2024 | H3: ='Historical Financials'!H7 -> 1Q23 | I3: ='Historical Financials'!I7 -> 2Q23 | J3: ='Historical Financials'!J7 -> 3Q23 | K3: ='Historical Financials'!K7 -> 4Q23 | L3: ='Historical Financials'!L7 -> 1Q24 | M3: ='Historical Financials'!M7 -> 2Q24 | N3: ='Historical Financials'!N7 -> 3Q24 | O3: ='Historical Financials'!O7 -> 4Q24 | ... T3: ='Historical Financials'!T7 -> 1Q26 | V3: =K3 -> 4Q23 | W3: =L3 -> 1Q24 | X3: =M3 -> 2Q24 | Y3: =N3 -> 3Q24 | Z3: =O3 -> 4Q24 | AA3: =P3 -> 1Q25 | AB3: =Q3 -> 2Q25 | AC3: =R3 -> 3Q25 | ... AE3: =T3 -> 1Q26
B4: ($ In Millions) | C4: ='Historical Financials'!C8 -> 44561 | D4: ='Historical Financials'!D8 -> 44926 | E4: ='Historical Financials'!E8 -> 45291 | F4: ='Historical Financials'!F8 -> 45657 | H4: ='Historical Financials'!H8 -> XXX | I4: ='Historical Financials'!I8 -> XXX | J4: ='Historical Financials'!J8 -> XXX | K4: ='Historical Financials'!K8 -> 44926 | L4: ='Historical Financials'!L8 -> XXX | M4: ='Historical Financials'!M8 -> XXX | N4: ='Historical Financials'!N8 -> XXX | O4: ='Historical Financials'!O8 -> 45291 | ... T4: ='Historical Financials'!T8 -> XXX | V4: =K4 -> 44926 | W4: =L4 -> XXX | X4: =M4 -> XXX | Y4: =N4 -> XXX | Z4: =O4 -> 45291 | AA4: =P4 -> XXX | AB4: =Q4 -> XXX | AC4: =R4 -> XXX | ... AE4: =T4 -> XXX
B6: XXX | V6: =SUM(H6:K6) -> 0 | W6: =SUM(I6:L6) -> 0 | X6: =SUM(J6:M6) -> 0 | Y6: =SUM(K6:N6) -> 0 | Z6: =SUM(L6:O6) -> 0 | AA6: =SUM(M6:P6) -> 0 | AB6: =SUM(N6:Q6) -> 0 | AC6: =SUM(O6:R6) -> 0 | ... AE6: =SUM(Q6:T6) -> 0 | AG6: =SUM(AE6/AA6)-1 -> #DIV/0!
B7: XXX | V7: =SUM(H7:K7) -> 0 | W7: =SUM(I7:L7) -> 0 | X7: =SUM(J7:M7) -> 0 | Y7: =SUM(K7:N7) -> 0 | Z7: =SUM(L7:O7) -> 0 | AA7: =SUM(M7:P7) -> 0 | AB7: =SUM(N7:Q7) -> 0 | AC7: =SUM(O7:R7) -> 0 | ... AE7: =SUM(Q7:T7) -> 0 | AG7: =SUM(AE7/AA7)-1 -> #DIV/0!
B8: XXX | V8: =SUM(H8:K8) -> 0 | W8: =SUM(I8:L8) -> 0 | X8: =SUM(J8:M8) -> 0 | Y8: =SUM(K8:N8) -> 0 | Z8: =SUM(L8:O8) -> 0 | AA8: =SUM(M8:P8) -> 0 | AB8: =SUM(N8:Q8) -> 0 | AC8: =SUM(O8:R8) -> 0 | ... AE8: =SUM(Q8:T8) -> 0 | AG8: =SUM(AE8/AA8)-1 -> #DIV/0!
B9: XXX | V9: =SUM(H9:K9) -> 0 | W9: =SUM(I9:L9) -> 0 | X9: =SUM(J9:M9) -> 0 | Y9: =SUM(K9:N9) -> 0 | Z9: =SUM(L9:O9) -> 0 | AA9: =SUM(M9:P9) -> 0 | AB9: =SUM(N9:Q9) -> 0 | AC9: =SUM(O9:R9) -> 0 | ... AE9: =SUM(Q9:T9) -> 0 | AG9: =SUM(AE9/AA9)-1 -> #DIV/0!
B10: XXX | V10: =SUM(H10:K10) -> 0 | W10: =SUM(I10:L10) -> 0 | X10: =SUM(J10:M10) -> 0 | Y10: =SUM(K10:N10) -> 0 | Z10: =SUM(L10:O10) -> 0 | AA10: =SUM(M10:P10) -> 0 | AB10: =SUM(N10:Q10) -> 0 | AC10: =SUM(O10:R10) -> 0 | ... AE10: =SUM(Q10:T10) -> 0 | AG10: =SUM(AE10/AA10)-1 -> #DIV/0!
B11: XXX | V11: =SUM(H11:K11) -> 0 | W11: =SUM(I11:L11) -> 0 | X11: =SUM(J11:M11) -> 0 | Y11: =SUM(K11:N11) -> 0 | Z11: =SUM(L11:O11) -> 0 | AA11: =SUM(M11:P11) -> 0 | AB11: =SUM(N11:Q11) -> 0 | AC11: =SUM(O11:R11) -> 0 | ... AE11: =SUM(Q11:T11) -> 0 | AG11: =SUM(AE11/AA11)-1 -> #DIV/0!
B12: Total Revenue | C12: =SUM(C6:C11) -> 0 | D12: =SUM(D6:D11) -> 0 | E12: =SUM(E6:E11) -> 0 | F12: =SUM(F6:F11) -> 0 | H12: =SUM(H6:H11) -> 0 | I12: =SUM(I6:I11) -> 0 | J12: =SUM(J6:J11) -> 0 | K12: =SUM(K6:K11) -> 0 | L12: =SUM(L6:L11) -> 0 | M12: =SUM(M6:M11) -> 0 | N12: =SUM(N6:N11) -> 0 | O12: =SUM(O6:O11) -> 0 | ... T12: =SUM(T6:T11) -> 0 | V12: =SUM(V6:V11) -> 0 | W12: =SUM(W6:W11) -> 0 | X12: =SUM(X6:X11) -> 0 | Y12: =SUM(Y6:Y11) -> 0 | Z12: =SUM(Z6:Z11) -> 0 | AA12: =SUM(AA6:AA11) -> 0 | AB12: =SUM(AB6:AB11) -> 0 | AC12: =SUM(AC6:AC11) -> 0 | ... AE12: =SUM(AE6:AE11) -> 0 | AG12: =SUM(AE12/AA12)-1 -> #DIV/0!
B13: Y/Y Growth (%) | C13: =SUM(C12/#REF!)-1 -> #REF! | D13: =SUM(D12/C12)-1 -> #DIV/0! | E13: =SUM(E12/D12)-1 -> #DIV/0! | F13: =SUM(F12/E12)-1 -> #DIV/0! | L13: =SUM(L12/H12)-1 -> #DIV/0! | M13: =SUM(M12/I12)-1 -> #DIV/0! | N13: =SUM(N12/J12)-1 -> #DIV/0! | O13: =SUM(O12/K12)-1 -> #DIV/0! | P13: =SUM(P12/L12)-1 -> #DIV/0! | Q13: =SUM(Q12/M12)-1 -> #DIV/0! | R13: =SUM(R12/N12)-1 -> #DIV/0! | S13: =SUM(S12/O12)-1 -> #DIV/0! | T13: =SUM(T12/P12)-1 -> #DIV/0! | Z13: =SUM(Z12/V12)-1 -> #DIV/0! | AA13: =SUM(AA12/W12)-1 -> #DIV/0! | AB13: =SUM(AB12/X12)-1 -> #DIV/0! | AC13: =SUM(AC12/Y12)-1 -> #DIV/0! | AD13: =SUM(AD12/Z12)-1 -> #DIV/0! | AE13: =SUM(AE12/AA12)-1 -> #DIV/0! | AG13: =SUM(AE13-AA13)*10000 -> #DIV/0!
B14: Q/Q Growth (%) | C14: N/A | D14: N/A | E14: N/A | F14: N/A | I14: =SUM(I12/H12)-1 -> #DIV/0! | J14: =SUM(J12/I12)-1 -> #DIV/0! | K14: =SUM(K12/J12)-1 -> #DIV/0! | L14: =SUM(L12/K12)-1 -> #DIV/0! | M14: =SUM(M12/L12)-1 -> #DIV/0! | N14: =SUM(N12/M12)-1 -> #DIV/0! | O14: =SUM(O12/N12)-1 -> #DIV/0! | P14: =SUM(P12/O12)-1 -> #DIV/0! | ... T14: =SUM(T12/S12)-1 -> #DIV/0! | V14: N/A | W14: N/A | X14: N/A | Y14: N/A | Z14: N/A | AA14: N/A | AB14: N/A | AC14: N/A | AD14: N/A | AE14: N/A
B16: (-) Cost of Sales | V16: =SUM(H16:K16) -> 0 | W16: =SUM(I16:L16) -> 0 | X16: =SUM(J16:M16) -> 0 | Y16: =SUM(K16:N16) -> 0 | Z16: =SUM(L16:O16) -> 0 | AA16: =SUM(M16:P16) -> 0 | AB16: =SUM(N16:Q16) -> 0 | AC16: =SUM(O16:R16) -> 0 | ... AE16: =SUM(Q16:T16) -> 0 | AG16: =SUM(AE16/AA16)-1 -> #DIV/0!
B17: Gross Profit | C17: =SUM(C12+SUM(C16:C16)) -> 0 | D17: =SUM(D12+SUM(D16:D16)) -> 0 | E17: =SUM(E12+SUM(E16:E16)) -> 0 | F17: =SUM(F12+SUM(F16:F16)) -> 0 | H17: =SUM(H12+SUM(H16:H16)) -> 0 | I17: =SUM(I12+SUM(I16:I16)) -> 0 | J17: =SUM(J12+SUM(J16:J16)) -> 0 | K17: =SUM(K12+SUM(K16:K16)) -> 0 | L17: =SUM(L12+SUM(L16:L16)) -> 0 | M17: =SUM(M12+SUM(M16:M16)) -> 0 | N17: =SUM(N12+SUM(N16:N16)) -> 0 | O17: =SUM(O12+SUM(O16:O16)) -> 0 | ... T17: =SUM(T12+SUM(T16:T16)) -> 0 | V17: =SUM(V12+SUM(V16:V16)) -> 0 | W17: =SUM(W12+SUM(W16:W16)) -> 0 | X17: =SUM(X12+SUM(X16:X16)) -> 0 | Y17: =SUM(Y12+SUM(Y16:Y16)) -> 0 | Z17: =SUM(Z12+SUM(Z16:Z16)) -> 0 | AA17: =SUM(AA12+SUM(AA16:AA16)) -> 0 | AB17: =SUM(AB12+SUM(AB16:AB16)) -> 0 | AC17: =SUM(AC12+SUM(AC16:AC16)) -> 0 | ... AE17: =SUM(AE12+SUM(AE16:AE16)) -> 0 | AG17: =SUM(AE17/AA17)-1 -> #DIV/0!
B18: Gross Margin (%) | C18: =C17/C12 -> #DIV/0! | D18: =D17/D12 -> #DIV/0! | E18: =E17/E12 -> #DIV/0! | F18: =F17/F12 -> #DIV/0! | H18: =H17/H12 -> #DIV/0! | I18: =I17/I12 -> #DIV/0! | J18: =J17/J12 -> #DIV/0! | K18: =K17/K12 -> #DIV/0! | L18: =L17/L12 -> #DIV/0! | M18: =M17/M12 -> #DIV/0! | N18: =N17/N12 -> #DIV/0! | O18: =O17/O12 -> #DIV/0! | ... T18: =T17/T12 -> #DIV/0! | V18: =V17/V12 -> #DIV/0! | W18: =W17/W12 -> #DIV/0! | X18: =X17/X12 -> #DIV/0! | Y18: =Y17/Y12 -> #DIV/0! | Z18: =Z17/Z12 -> #DIV/0! | AA18: =AA17/AA12 -> #DIV/0! | AB18: =AB17/AB12 -> #DIV/0! | AC18: =AC17/AC12 -> #DIV/0! | ... AE18: =AE17/AE12 -> #DIV/0! | AG18: =SUM(AE18-AA18)*10000 -> #DIV/0!
B20: (-) XXX | V20: =SUM(H20:K20) -> 0 | W20: =SUM(I20:L20) -> 0 | X20: =SUM(J20:M20) -> 0 | Y20: =SUM(K20:N20) -> 0 | Z20: =SUM(L20:O20) -> 0 | AA20: =SUM(M20:P20) -> 0 | AB20: =SUM(N20:Q20) -> 0 | AC20: =SUM(O20:R20) -> 0 | ... AE20: =SUM(Q20:T20) -> 0 | AG20: =SUM(AE20/AA20)-1 -> #DIV/0!
B21: (-) XXX | V21: =SUM(H21:K21) -> 0 | W21: =SUM(I21:L21) -> 0 | X21: =SUM(J21:M21) -> 0 | Y21: =SUM(K21:N21) -> 0 | Z21: =SUM(L21:O21) -> 0 | AA21: =SUM(M21:P21) -> 0 | AB21: =SUM(N21:Q21) -> 0 | AC21: =SUM(O21:R21) -> 0 | ... AE21: =SUM(Q21:T21) -> 0 | AG21: =SUM(AE21/AA21)-1 -> #DIV/0!
B22: (-) XXX | V22: =SUM(H22:K22) -> 0 | W22: =SUM(I22:L22) -> 0 | X22: =SUM(J22:M22) -> 0 | Y22: =SUM(K22:N22) -> 0 | Z22: =SUM(L22:O22) -> 0 | AA22: =SUM(M22:P22) -> 0 | AB22: =SUM(N22:Q22) -> 0 | AC22: =SUM(O22:R22) -> 0 | ... AE22: =SUM(Q22:T22) -> 0 | AG22: =SUM(AE22/AA22)-1 -> #DIV/0!
B23: (-) XXX | V23: =SUM(H23:K23) -> 0 | W23: =SUM(I23:L23) -> 0 | X23: =SUM(J23:M23) -> 0 | Y23: =SUM(K23:N23) -> 0 | Z23: =SUM(L23:O23) -> 0 | AA23: =SUM(M23:P23) -> 0 | AB23: =SUM(N23:Q23) -> 0 | AC23: =SUM(O23:R23) -> 0 | ... AE23: =SUM(Q23:T23) -> 0 | AG23: =SUM(AE23/AA23)-1 -> #DIV/0!
B24: (-) XXX | V24: =SUM(H24:K24) -> 0 | W24: =SUM(I24:L24) -> 0 | X24: =SUM(J24:M24) -> 0 | Y24: =SUM(K24:N24) -> 0 | Z24: =SUM(L24:O24) -> 0 | AA24: =SUM(M24:P24) -> 0 | AB24: =SUM(N24:Q24) -> 0 | AC24: =SUM(O24:R24) -> 0 | ... AE24: =SUM(Q24:T24) -> 0 | AG24: =SUM(AE24/AA24)-1 -> #DIV/0!
B25: Earning before Interest & Taxes (EBIT) | C25: =SUM(C17+SUM(C20:C24)) -> 0 | D25: =SUM(D17+SUM(D20:D24)) -> 0 | E25: =SUM(E17+SUM(E20:E24)) -> 0 | F25: =SUM(F17+SUM(F20:F24)) -> 0 | H25: =SUM(H17+SUM(H20:H24)) -> 0 | I25: =SUM(I17+SUM(I20:I24)) -> 0 | J25: =SUM(J17+SUM(J20:J24)) -> 0 | K25: =SUM(K17+SUM(K20:K24)) -> 0 | L25: =SUM(L17+SUM(L20:L24)) -> 0 | M25: =SUM(M17+SUM(M20:M24)) -> 0 | N25: =SUM(N17+SUM(N20:N24)) -> 0 | O25: =SUM(O17+SUM(O20:O24)) -> 0 | ... T25: =SUM(T17+SUM(T20:T24)) -> 0 | V25: =SUM(V17+SUM(V20:V24)) -> 0 | W25: =SUM(W17+SUM(W20:W24)) -> 0 | X25: =SUM(X17+SUM(X20:X24)) -> 0 | Y25: =SUM(Y17+SUM(Y20:Y24)) -> 0 | Z25: =SUM(Z17+SUM(Z20:Z24)) -> 0 | AA25: =SUM(AA17+SUM(AA20:AA24)) -> 0 | AB25: =SUM(AB17+SUM(AB20:AB24)) -> 0 | AC25: =SUM(AC17+SUM(AC20:AC24)) -> 0 | ... AE25: =SUM(AE17+SUM(AE20:AE24)) -> 0 | AG25: =SUM(AE25/AA25)-1 -> #DIV/0!
B26: Operating Margin (%) | C26: =C25/C12 -> #DIV/0! | D26: =D25/D12 -> #DIV/0! | E26: =E25/E12 -> #DIV/0! | F26: =F25/F12 -> #DIV/0! | H26: =H25/H12 -> #DIV/0! | I26: =I25/I12 -> #DIV/0! | J26: =J25/J12 -> #DIV/0! | K26: =K25/K12 -> #DIV/0! | L26: =L25/L12 -> #DIV/0! | M26: =M25/M12 -> #DIV/0! | N26: =N25/N12 -> #DIV/0! | O26: =O25/O12 -> #DIV/0! | ... T26: =T25/T12 -> #DIV/0! | V26: =V25/V12 -> #DIV/0! | W26: =W25/W12 -> #DIV/0! | X26: =X25/X12 -> #DIV/0! | Y26: =Y25/Y12 -> #DIV/0! | Z26: =Z25/Z12 -> #DIV/0! | AA26: =AA25/AA12 -> #DIV/0! | AB26: =AB25/AB12 -> #DIV/0! | AC26: =AC25/AC12 -> #DIV/0! | ... AE26: =AE25/AE12 -> #DIV/0! | AG26: =SUM(AE26-AA26)*10000 -> #DIV/0!
B28: (+) Depreciation and Amortization (D&A) | V28: =SUM(H28:K28) -> 0 | W28: =SUM(I28:L28) -> 0 | X28: =SUM(J28:M28) -> 0 | Y28: =SUM(K28:N28) -> 0 | Z28: =SUM(L28:O28) -> 0 | AA28: =SUM(M28:P28) -> 0 | AB28: =SUM(N28:Q28) -> 0 | AC28: =SUM(O28:R28) -> 0 | ... AE28: =SUM(Q28:T28) -> 0 | AG28: =SUM(AE28/AA28)-1 -> #DIV/0!
B29: EBITDA | C29: =SUM(C25+SUM(C28:C28)) -> 0 | D29: =SUM(D25+SUM(D28:D28)) -> 0 | E29: =SUM(E25+SUM(E28:E28)) -> 0 | F29: =SUM(F25+SUM(F28:F28)) -> 0 | H29: =SUM(H25+SUM(H28:H28)) -> 0 | I29: =SUM(I25+SUM(I28:I28)) -> 0 | J29: =SUM(J25+SUM(J28:J28)) -> 0 | K29: =SUM(K25+SUM(K28:K28)) -> 0 | L29: =SUM(L25+SUM(L28:L28)) -> 0 | M29: =SUM(M25+SUM(M28:M28)) -> 0 | N29: =SUM(N25+SUM(N28:N28)) -> 0 | O29: =SUM(O25+SUM(O28:O28)) -> 0 | ... T29: =SUM(T25+SUM(T28:T28)) -> 0 | V29: =SUM(V25+SUM(V28:V28)) -> 0 | W29: =SUM(W25+SUM(W28:W28)) -> 0 | X29: =SUM(X25+SUM(X28:X28)) -> 0 | Y29: =SUM(Y25+SUM(Y28:Y28)) -> 0 | Z29: =SUM(Z25+SUM(Z28:Z28)) -> 0 | AA29: =SUM(AA25+SUM(AA28:AA28)) -> 0 | AB29: =SUM(AB25+SUM(AB28:AB28)) -> 0 | AC29: =SUM(AC25+SUM(AC28:AC28)) -> 0 | ... AE29: =SUM(AE25+SUM(AE28:AE28)) -> 0 | AG29: =SUM(AE29/AA29)-1 -> #DIV/0!
B30: EBITDA Margin (%) | C30: =C29/C12 -> #DIV/0! | D30: =D29/D12 -> #DIV/0! | E30: =E29/E12 -> #DIV/0! | F30: =F29/F12 -> #DIV/0! | H30: =H29/H12 -> #DIV/0! | I30: =I29/I12 -> #DIV/0! | J30: =J29/J12 -> #DIV/0! | K30: =K29/K12 -> #DIV/0! | L30: =L29/L12 -> #DIV/0! | M30: =M29/M12 -> #DIV/0! | N30: =N29/N12 -> #DIV/0! | O30: =O29/O12 -> #DIV/0! | ... T30: =T29/T12 -> #DIV/0! | V30: =V29/V12 -> #DIV/0! | W30: =W29/W12 -> #DIV/0! | X30: =X29/X12 -> #DIV/0! | Y30: =Y29/Y12 -> #DIV/0! | Z30: =Z29/Z12 -> #DIV/0! | AA30: =AA29/AA12 -> #DIV/0! | AB30: =AB29/AB12 -> #DIV/0! | AC30: =AC29/AC12 -> #DIV/0! | ... AE30: =AE29/AE12 -> #DIV/0! | AG30: =SUM(AE30-AA30)*10000 -> #DIV/0!
B32: (+) Stock-Based Compensation (SBC) | V32: =SUM(H32:K32) -> 0 | W32: =SUM(I32:L32) -> 0 | X32: =SUM(J32:M32) -> 0 | Y32: =SUM(K32:N32) -> 0 | Z32: =SUM(L32:O32) -> 0 | AA32: =SUM(M32:P32) -> 0 | AB32: =SUM(N32:Q32) -> 0 | AC32: =SUM(O32:R32) -> 0 | ... AE32: =SUM(Q32:T32) -> 0 | AG32: =SUM(AE32/AA32)-1 -> #DIV/0!
B33: (+) XXX | V33: =SUM(H33:K33) -> 0 | W33: =SUM(I33:L33) -> 0 | X33: =SUM(J33:M33) -> 0 | Y33: =SUM(K33:N33) -> 0 | Z33: =SUM(L33:O33) -> 0 | AA33: =SUM(M33:P33) -> 0 | AB33: =SUM(N33:Q33) -> 0 | AC33: =SUM(O33:R33) -> 0 | ... AE33: =SUM(Q33:T33) -> 0 | AG33: =SUM(AE33/AA33)-1 -> #DIV/0!
B34: Adj. EBITDA | C34: =+SUM(C29+SUM(C32:C32)) -> 0 | D34: =+SUM(D29+SUM(D32:D32)) -> 0 | E34: =+SUM(E29+SUM(E32:E32)) -> 0 | F34: =+SUM(F29+SUM(F32:F32)) -> 0 | H34: =+SUM(H29+SUM(H32:H32)) -> 0 | I34: =+SUM(I29+SUM(I32:I32)) -> 0 | J34: =+SUM(J29+SUM(J32:J32)) -> 0 | K34: =+SUM(K29+SUM(K32:K32)) -> 0 | L34: =+SUM(L29+SUM(L32:L32)) -> 0 | M34: =+SUM(M29+SUM(M32:M32)) -> 0 | N34: =+SUM(N29+SUM(N32:N32)) -> 0 | O34: =+SUM(O29+SUM(O32:O32)) -> 0 | ... T34: =+SUM(T29+SUM(T32:T32)) -> 0 | V34: =+SUM(V29+SUM(V32:V32)) -> 0 | W34: =+SUM(W29+SUM(W32:W32)) -> 0 | X34: =+SUM(X29+SUM(X32:X32)) -> 0 | Y34: =+SUM(Y29+SUM(Y32:Y32)) -> 0 | Z34: =+SUM(Z29+SUM(Z32:Z32)) -> 0 | AA34: =+SUM(AA29+SUM(AA32:AA32)) -> 0 | AB34: =+SUM(AB29+SUM(AB32:AB32)) -> 0 | AC34: =+SUM(AC29+SUM(AC32:AC32)) -> 0 | ... AE34: =+SUM(AE29+SUM(AE32:AE32)) -> 0 | AG34: =SUM(AE34/AA34)-1 -> #DIV/0!
B35: Adj. EBITDA Margin (%) | C35: =C34/C12 -> #DIV/0! | D35: =D34/D12 -> #DIV/0! | E35: =E34/E12 -> #DIV/0! | F35: =F34/F12 -> #DIV/0! | H35: =H34/H12 -> #DIV/0! | I35: =I34/I12 -> #DIV/0! | J35: =J34/J12 -> #DIV/0! | K35: =K34/K12 -> #DIV/0! | L35: =L34/L12 -> #DIV/0! | M35: =M34/M12 -> #DIV/0! | N35: =N34/N12 -> #DIV/0! | O35: =O34/O12 -> #DIV/0! | ... T35: =T34/T12 -> #DIV/0! | V35: =V34/V12 -> #DIV/0! | W35: =W34/W12 -> #DIV/0! | X35: =X34/X12 -> #DIV/0! | Y35: =Y34/Y12 -> #DIV/0! | Z35: =Z34/Z12 -> #DIV/0! | AA35: =AA34/AA12 -> #DIV/0! | AB35: =AB34/AB12 -> #DIV/0! | AC35: =AC34/AC12 -> #DIV/0! | ... AE35: =AE34/AE12 -> #DIV/0! | AG35: =SUM(AE35-AA35)*10000 -> #DIV/0!
B37: (-) Capital Expenditures | V37: =SUM(H37:K37) -> 0 | W37: =SUM(I37:L37) -> 0 | X37: =SUM(J37:M37) -> 0 | Y37: =SUM(K37:N37) -> 0 | Z37: =SUM(L37:O37) -> 0 | AA37: =SUM(M37:P37) -> 0 | AB37: =SUM(N37:Q37) -> 0 | AC37: =SUM(O37:R37) -> 0 | ... AE37: =SUM(Q37:T37) -> 0 | AG37: =SUM(AE37/AA37)-1 -> #DIV/0!
B38: (-) Cash Taxes | V38: =SUM(H38:K38) -> 0 | W38: =SUM(I38:L38) -> 0 | X38: =SUM(J38:M38) -> 0 | Y38: =SUM(K38:N38) -> 0 | Z38: =SUM(L38:O38) -> 0 | AA38: =SUM(M38:P38) -> 0 | AB38: =SUM(N38:Q38) -> 0 | AC38: =SUM(O38:R38) -> 0 | ... AE38: =SUM(Q38:T38) -> 0 | AG38: =SUM(AE38/AA38)-1 -> #DIV/0!
B39: (-) Cash Interest | V39: =SUM(H39:K39) -> 0 | W39: =SUM(I39:L39) -> 0 | X39: =SUM(J39:M39) -> 0 | Y39: =SUM(K39:N39) -> 0 | Z39: =SUM(L39:O39) -> 0 | AA39: =SUM(M39:P39) -> 0 | AB39: =SUM(N39:Q39) -> 0 | AC39: =SUM(O39:R39) -> 0 | ... AE39: =SUM(Q39:T39) -> 0 | AG39: =SUM(AE39/AA39)-1 -> #DIV/0!
B40: (-) Mandatory Outflows | V40: =SUM(H40:K40) -> 0 | W40: =SUM(I40:L40) -> 0 | X40: =SUM(J40:M40) -> 0 | Y40: =SUM(K40:N40) -> 0 | Z40: =SUM(L40:O40) -> 0 | AA40: =SUM(M40:P40) -> 0 | AB40: =SUM(N40:Q40) -> 0 | AC40: =SUM(O40:R40) -> 0 | ... AE40: =SUM(Q40:T40) -> 0 | AG40: =SUM(AE40/AA40)-1 -> #DIV/0!
B41: (+/-) Changes in NWC | V41: =SUM(H41:K41) -> 0 | W41: =SUM(I41:L41) -> 0 | X41: =SUM(J41:M41) -> 0 | Y41: =SUM(K41:N41) -> 0 | Z41: =SUM(L41:O41) -> 0 | AA41: =SUM(M41:P41) -> 0 | AB41: =SUM(N41:Q41) -> 0 | AC41: =SUM(O41:R41) -> 0 | ... AE41: =SUM(Q41:T41) -> 0 | AG41: =SUM(AE41/AA41)-1 -> #DIV/0!
B42: Discretionary Cash-Flows | C42: =SUM(C34+SUM(C37:C41)) -> 0 | D42: =SUM(D34+SUM(D37:D41)) -> 0 | E42: =SUM(E34+SUM(E37:E41)) -> 0 | F42: =SUM(F34+SUM(F37:F41)) -> 0 | H42: =SUM(H34+SUM(H37:H41)) -> 0 | I42: =SUM(I34+SUM(I37:I41)) -> 0 | J42: =SUM(J34+SUM(J37:J41)) -> 0 | K42: =SUM(K34+SUM(K37:K41)) -> 0 | L42: =SUM(L34+SUM(L37:L41)) -> 0 | M42: =SUM(M34+SUM(M37:M41)) -> 0 | N42: =SUM(N34+SUM(N37:N41)) -> 0 | O42: =SUM(O34+SUM(O37:O41)) -> 0 | ... T42: =SUM(T34+SUM(T37:T41)) -> 0 | V42: =SUM(V34+SUM(V37:V41)) -> 0 | W42: =SUM(W34+SUM(W37:W41)) -> 0 | X42: =SUM(X34+SUM(X37:X41)) -> 0 | Y42: =SUM(Y34+SUM(Y37:Y41)) -> 0 | Z42: =SUM(Z34+SUM(Z37:Z41)) -> 0 | AA42: =SUM(AA34+SUM(AA37:AA41)) -> 0 | AB42: =SUM(AB34+SUM(AB37:AB41)) -> 0 | AC42: =SUM(AC34+SUM(AC37:AC41)) -> 0 | ... AE42: =SUM(AE34+SUM(AE37:AE41)) -> 0 | AG42: =SUM(AE42/AA42)-1 -> #DIV/0!
B44: (+/-) XXX | V44: =SUM(H44:K44) -> 0 | W44: =SUM(I44:L44) -> 0 | X44: =SUM(J44:M44) -> 0 | Y44: =SUM(K44:N44) -> 0 | Z44: =SUM(L44:O44) -> 0 | AA44: =SUM(M44:P44) -> 0 | AB44: =SUM(N44:Q44) -> 0 | AC44: =SUM(O44:R44) -> 0 | ... AE44: =SUM(Q44:T44) -> 0
B45: (+/-) XXX | V45: =SUM(H45:K45) -> 0 | W45: =SUM(I45:L45) -> 0 | X45: =SUM(J45:M45) -> 0 | Y45: =SUM(K45:N45) -> 0 | Z45: =SUM(L45:O45) -> 0 | AA45: =SUM(M45:P45) -> 0 | AB45: =SUM(N45:Q45) -> 0 | AC45: =SUM(O45:R45) -> 0 | ... AE45: =SUM(Q45:T45) -> 0
B46: (+/-) XXX | V46: =SUM(H46:K46) -> 0 | W46: =SUM(I46:L46) -> 0 | X46: =SUM(J46:M46) -> 0 | Y46: =SUM(K46:N46) -> 0 | Z46: =SUM(L46:O46) -> 0 | AA46: =SUM(M46:P46) -> 0 | AB46: =SUM(N46:Q46) -> 0 | AC46: =SUM(O46:R46) -> 0 | ... AE46: =SUM(Q46:T46) -> 0
B47: (+/-) XXX | V47: =SUM(H47:K47) -> 0 | W47: =SUM(I47:L47) -> 0 | X47: =SUM(J47:M47) -> 0 | Y47: =SUM(K47:N47) -> 0 | Z47: =SUM(L47:O47) -> 0 | AA47: =SUM(M47:P47) -> 0 | AB47: =SUM(N47:Q47) -> 0 | AC47: =SUM(O47:R47) -> 0 | ... AE47: =SUM(Q47:T47) -> 0
B48: (+/-) XXX | V48: =SUM(H48:K48) -> 0 | W48: =SUM(I48:L48) -> 0 | X48: =SUM(J48:M48) -> 0 | Y48: =SUM(K48:N48) -> 0 | Z48: =SUM(L48:O48) -> 0 | AA48: =SUM(M48:P48) -> 0 | AB48: =SUM(N48:Q48) -> 0 | AC48: =SUM(O48:R48) -> 0 | ... AE48: =SUM(Q48:T48) -> 0
...
