Workbook

Sheet Base Financials
B2: Intel, Corporation. (NASDAQ: INTC) | C2: FYE | E2: FYE | I2: Quarterly | O2: Quarterly | R2: Quarterly | S2: Quarterly | AE2: LTM | AK2: Variance
B3: Base Financials | C3: 2020 | D3: 2021 | E3: 2022 | F3: 2023 | G3: 2024 | I3: 1Q22 | J3: 2Q22 | K3: 3Q22 | L3: 4Q22 | M3: 1Q23 | N3: 2Q23 | O3: 3Q23 | P3: 4Q23 | Q3: 1Q24 | R3: 2Q24 | S3: 3Q24 | T3: 4Q24 | U3: 1Q25 | V3: 2Q25 | W3: 3Q25 | Y3: =M3 -> 1Q23 | Z3: =N3 -> 2Q23 | AA3: =O3 -> 3Q23 | AB3: =P3 -> 4Q23 | AC3: =Q3 -> 1Q24 | AD3: =R3 -> 2Q24 | AE3: =S3 -> 3Q24 | AF3: =T3 -> 4Q24 | ... AI3: =W3 -> 3Q25
B4: ($ In Millions) | C4: 44191 | D4: 44555 | E4: 44926 | F4: 45290 | G4: 45654 | I4: 44653 | J4: 44744 | K4: 44835 | L4: =E4 -> 44926 | M4: 45017 | N4: 45108 | O4: 45199 | P4: =F4 -> 45290 | Q4: 45381 | R4: 45472 | S4: 45563 | T4: =G4 -> 45654 | U4: 45745 | V4: 45836 | W4: 45925 | Y4: =M4 -> 45017 | Z4: =N4 -> 45108 | AA4: =O4 -> 45199 | AB4: =P4 -> 45290 | AC4: =Q4 -> 45381 | AD4: =R4 -> 45472 | AE4: =S4 -> 45563 | AF4: =T4 -> 45654 | ... AI4: =W4 -> 45925
A6: X | B6: Income Statement
B8: Consolidated Revenue | C8: 77867 | D8: 79024 | E8: 63054 | F8: 54228 | G8: 53101 | I8: 18353 | J8: 15321 | K8: 15338 | L8: =SUM(E8-SUM(I8:K8)) -> 14042 | M8: 11715 | N8: 12949 | O8: 14158 | P8: =SUM(F8-SUM(M8:O8)) -> 15406 | Q8: 12724 | R8: 12833 | S8: 13284 | T8: =SUM(G8-SUM(Q8:S8)) -> 14260 | U8: 12667 | V8: 12859 | W8: 13653 | Y8: =SUM(J8:M8) -> 56416 | Z8: =SUM(K8:N8) -> 54044 | AA8: =SUM(L8:O8) -> 52864 | AB8: =SUM(M8:P8) -> 54228 | AC8: =SUM(N8:Q8) -> 55237 | AD8: =SUM(O8:R8) -> 55121 | AE8: =SUM(P8:S8) -> 54247 | AF8: =SUM(Q8:T8) -> 53101 | ... AI8: =SUM(T8:W8) -> 53439 | AK8: =SUM(AI8/AE8)-1 -> -0.014894833
B9: Total Revenue | C9: =+SUM(C8:C8) -> 77867 | D9: =+SUM(D8:D8) -> 79024 | E9: =+SUM(E8:E8) -> 63054 | F9: =+SUM(F8:F8) -> 54228 | G9: =+SUM(G8:G8) -> 53101 | I9: =+SUM(I8:I8) -> 18353 | J9: =+SUM(J8:J8) -> 15321 | K9: =+SUM(K8:K8) -> 15338 | L9: =+SUM(L8:L8) -> 14042 | M9: =+SUM(M8:M8) -> 11715 | N9: =+SUM(N8:N8) -> 12949 | O9: =+SUM(O8:O8) -> 14158 | P9: =+SUM(P8:P8) -> 15406 | ... W9: =+SUM(W8:W8) -> 13653 | Y9: =+SUM(Y8:Y8) -> 56416 | Z9: =+SUM(Z8:Z8) -> 54044 | AA9: =+SUM(AA8:AA8) -> 52864 | AB9: =+SUM(AB8:AB8) -> 54228 | AC9: =+SUM(AC8:AC8) -> 55237 | AD9: =+SUM(AD8:AD8) -> 55121 | AE9: =+SUM(AE8:AE8) -> 54247 | AF9: =+SUM(AF8:AF8) -> 53101 | ... AI9: =+SUM(AI8:AI8) -> 53439 | AK9: =SUM(AI9/AE9)-1 -> -0.014894833
B11: Cost of Sales | C11: -34255 | D11: -35209 | E11: -36188 | F11: -32517 | G11: -35756 | I11: -9109 | J11: -9734 | K11: -8803 | L11: =SUM(E11-SUM(I11:K11)) -> -8542 | M11: -7707 | N11: -8311 | O11: -8140 | P11: =SUM(F11-SUM(M11:O11)) -> -8359 | Q11: -7507 | R11: -8286 | S11: -11287 | T11: =SUM(G11-SUM(Q11:S11)) -> -8676 | U11: -7995 | V11: -9317 | W11: -8435 | Y11: =SUM(J11:M11) -> -34786 | Z11: =SUM(K11:N11) -> -33363 | AA11: =SUM(L11:O11) -> -32700 | AB11: =SUM(M11:P11) -> -32517 | AC11: =SUM(N11:Q11) -> -32317 | AD11: =SUM(O11:R11) -> -32292 | AE11: =SUM(P11:S11) -> -35439 | AF11: =SUM(Q11:T11) -> -35756 | ... AI11: =SUM(T11:W11) -> -34423 | AK11: =SUM(AI11/AE11)-1 -> -0.028668981
B12: Gross Profit | C12: =+SUM(C9+SUM(C11:C11)) -> 43612 | D12: =+SUM(D9+SUM(D11:D11)) -> 43815 | E12: =+SUM(E9+SUM(E11:E11)) -> 26866 | F12: =+SUM(F9+SUM(F11:F11)) -> 21711 | G12: =+SUM(G9+SUM(G11:G11)) -> 17345 | I12: =+SUM(I9+SUM(I11:I11)) -> 9244 | J12: =+SUM(J9+SUM(J11:J11)) -> 5587 | K12: =+SUM(K9+SUM(K11:K11)) -> 6535 | L12: =+SUM(L9+SUM(L11:L11)) -> 5500 | M12: =+SUM(M9+SUM(M11:M11)) -> 4008 | N12: =+SUM(N9+SUM(N11:N11)) -> 4638 | O12: =+SUM(O9+SUM(O11:O11)) -> 6018 | P12: =+SUM(P9+SUM(P11:P11)) -> 7047 | ... W12: =+SUM(W9+SUM(W11:W11)) -> 5218 | Y12: =+SUM(Y9+SUM(Y11:Y11)) -> 21630 | Z12: =+SUM(Z9+SUM(Z11:Z11)) -> 20681 | AA12: =+SUM(AA9+SUM(AA11:AA11)) -> 20164 | AB12: =+SUM(AB9+SUM(AB11:AB11)) -> 21711 | AC12: =+SUM(AC9+SUM(AC11:AC11)) -> 22920 | AD12: =+SUM(AD9+SUM(AD11:AD11)) -> 22829 | AE12: =+SUM(AE9+SUM(AE11:AE11)) -> 18808 | AF12: =+SUM(AF9+SUM(AF11:AF11)) -> 17345 | ... AI12: =+SUM(AI9+SUM(AI11:AI11)) -> 19016 | AK12: =SUM(AI12/AE12)-1 -> 0.011059124
B13: Gross Margin (%) | C13: =C12/C9 -> 0.56008322 | D13: =D12/D9 -> 0.55445181 | E13: =E12/E9 -> 0.42607923 | F13: =F12/F9 -> 0.40036513 | G13: =G12/G9 -> 0.32664168 | I13: =I12/I9 -> 0.50367787 | J13: =J12/J9 -> 0.36466288 | K13: =K12/K9 -> 0.42606598 | L13: =L12/L9 -> 0.3916821 | M13: =M12/M9 -> 0.34212548 | N13: =N12/N9 -> 0.35817438 | O13: =O12/O9 -> 0.42506004 | P13: =P12/P9 -> 0.45741919 | ... W13: =W12/W9 -> 0.38218707 | Y13: =Y12/Y9 -> 0.38340187 | Z13: =Z12/Z9 -> 0.38266968 | AA13: =AA12/AA9 -> 0.3814316 | AB13: =AB12/AB9 -> 0.40036513 | AC13: =AC12/AC9 -> 0.41493926 | AD13: =AD12/AD9 -> 0.41416157 | AE13: =AE12/AE9 -> 0.34671042 | AF13: =AF12/AF9 -> 0.32664168 | ... AI13: =AI12/AI9 -> 0.35584498 | AK13: =SUM(AI13-AE13)*1000 -> 9.134565
B15: Marketing, General, and Administrative (MG&A) | C15: -6180 | D15: -6543 | E15: -7002 | F15: -5634 | G15: -5507 | I15: -1752 | J15: -1800 | K15: -1744 | L15: =SUM(E15-SUM(I15:K15)) -> -1706 | M15: -1303 | N15: -1374 | O15: -1340 | P15: =SUM(F15-SUM(M15:O15)) -> -1617 | Q15: -1556 | R15: -1329 | S15: -1383 | T15: =SUM(G15-SUM(Q15:S15)) -> -1239 | U15: -1177 | V15: -1144 | W15: -1129 | Y15: =SUM(J15:M15) -> -6553 | Z15: =SUM(K15:N15) -> -6127 | AA15: =SUM(L15:O15) -> -5723 | AB15: =SUM(M15:P15) -> -5634 | AC15: =SUM(N15:Q15) -> -5887 | AD15: =SUM(O15:R15) -> -5842 | AE15: =SUM(P15:S15) -> -5885 | AF15: =SUM(Q15:T15) -> -5507 | ... AI15: =SUM(T15:W15) -> -4689 | AK15: =SUM(AI15/AE15)-1 -> -0.20322855
B16: Research and Development (R&D) | C16: -13556 | D16: -15190 | E16: -17528 | F16: -16046 | G16: -16546 | I16: -4362 | J16: -4400 | K16: -4302 | L16: =SUM(E16-SUM(I16:K16)) -> -4464 | M16: -4109 | N16: -4080 | O16: -3870 | P16: =SUM(F16-SUM(M16:O16)) -> -3987 | Q16: -4382 | R16: -4239 | S16: -4049 | T16: =SUM(G16-SUM(Q16:S16)) -> -3876 | U16: -3640 | V16: -3684 | W16: -3231 | Y16: =SUM(J16:M16) -> -17275 | Z16: =SUM(K16:N16) -> -16955 | AA16: =SUM(L16:O16) -> -16523 | AB16: =SUM(M16:P16) -> -16046 | AC16: =SUM(N16:Q16) -> -16319 | AD16: =SUM(O16:R16) -> -16478 | AE16: =SUM(P16:S16) -> -16657 | AF16: =SUM(Q16:T16) -> -16546 | ... AI16: =SUM(T16:W16) -> -14431 | AK16: =SUM(AI16/AE16)-1 -> -0.13363751
B17: Restructuring and Other Charges | C17: -198 | D17: -2626 | E17: -2 | F17: 62 | G17: -6970 | I17: 1211 | J17: -87 | K17: -664 | L17: =SUM(E17-SUM(I17:K17)) -> -462 | M17: -64 | N17: -200 | O17: -816 | P17: =SUM(F17-SUM(M17:O17)) -> 1142 | Q17: -348 | R17: -943 | S17: -5622 | T17: =SUM(G17-SUM(Q17:S17)) -> -57 | U17: -156 | V17: -1890 | W17: -175 | Y17: =SUM(J17:M17) -> -1277 | Z17: =SUM(K17:N17) -> -1390 | AA17: =SUM(L17:O17) -> -1542 | AB17: =SUM(M17:P17) -> 62 | AC17: =SUM(N17:Q17) -> -222 | AD17: =SUM(O17:R17) -> -965 | AE17: =SUM(P17:S17) -> -5771 | AF17: =SUM(Q17:T17) -> -6970 | ... AI17: =SUM(T17:W17) -> -2278 | AK17: =SUM(AI17/AE17)-1 -> -0.60526772
B18: Profit From Operations | C18: =SUM(C12+SUM(C15:C17)) -> 23678 | D18: =SUM(D12+SUM(D15:D17)) -> 19456 | E18: =SUM(E12+SUM(E15:E17)) -> 2334 | F18: =SUM(F12+SUM(F15:F17)) -> 93 | G18: =SUM(G12+SUM(G15:G17)) -> -11678 | I18: =SUM(I12+SUM(I15:I17)) -> 4341 | J18: =SUM(J12+SUM(J15:J17)) -> -700 | K18: =SUM(K12+SUM(K15:K17)) -> -175 | L18: =SUM(L12+SUM(L15:L17)) -> -1132 | M18: =SUM(M12+SUM(M15:M17)) -> -1468 | N18: =SUM(N12+SUM(N15:N17)) -> -1016 | O18: =SUM(O12+SUM(O15:O17)) -> -8 | P18: =SUM(P12+SUM(P15:P17)) -> 2585 | ... W18: =SUM(W12+SUM(W15:W17)) -> 683 | Y18: =SUM(Y12+SUM(Y15:Y17)) -> -3475 | Z18: =SUM(Z12+SUM(Z15:Z17)) -> -3791 | AA18: =SUM(AA12+SUM(AA15:AA17)) -> -3624 | AB18: =SUM(AB12+SUM(AB15:AB17)) -> 93 | AC18: =SUM(AC12+SUM(AC15:AC17)) -> 492 | AD18: =SUM(AD12+SUM(AD15:AD17)) -> -456 | AE18: =SUM(AE12+SUM(AE15:AE17)) -> -9505 | AF18: =SUM(AF12+SUM(AF15:AF17)) -> -11678 | ... AI18: =SUM(AI12+SUM(AI15:AI17)) -> -2382 | AK18: =SUM(AI18/AE18)-1 -> -0.74939506
B19: Operating Margin (%) | C19: =C18/C9 -> 0.3040826 | D19: =D18/D9 -> 0.24620368 | E19: =E18/E9 -> 0.037015891 | F19: =F18/F9 -> 0.0017149812 | G19: =G18/G9 -> -0.21992053 | I19: =I18/I9 -> 0.23652809 | J19: =J18/J9 -> -0.045688924 | K19: =K18/K9 -> -0.011409571 | L19: =L18/L9 -> -0.080615297 | M19: =M18/M9 -> -0.12530943 | N19: =N18/N9 -> -0.078461657 | O19: =O18/O9 -> -0.00056505156 | P19: =P18/P9 -> 0.16779177 | ... W19: =W18/W9 -> 0.050025635 | Y19: =Y18/Y9 -> -0.061596001 | Z19: =Z18/Z9 -> -0.070146547 | AA19: =AA18/AA9 -> -0.068553269 | AB19: =AB18/AB9 -> 0.0017149812 | AC19: =AC18/AC9 -> 0.0089070732 | AD19: =AD18/AD9 -> -0.0082727091 | AE19: =AE18/AE9 -> -0.17521706 | AF19: =AF18/AF9 -> -0.21992053 | ... AI19: =AI18/AI9 -> -0.044574187 | AK19: =SUM(AI19-AE19)*1000 -> 130.64288
B21: Interest and other, net | C21: -504 | D21: -482 | E21: 1166 | F21: 629 | G21: 226 | I21: 997 | J21: -119 | K21: 138 | L21: =SUM(E21-SUM(I21:K21)) -> 150 | M21: 141 | N21: 224 | O21: 147 | P21: =SUM(F21-SUM(M21:O21)) -> 117 | Q21: 145 | R21: 80 | S21: 130 | T21: =SUM(G21-SUM(Q21:S21)) -> -129 | U21: -173 | V21: -95 | W21: 3670 | Y21: =SUM(J21:M21) -> 310 | Z21: =SUM(K21:N21) -> 653 | AA21: =SUM(L21:O21) -> 662 | AB21: =SUM(M21:P21) -> 629 | AC21: =SUM(N21:Q21) -> 633 | AD21: =SUM(O21:R21) -> 489 | AE21: =SUM(P21:S21) -> 472 | AF21: =SUM(Q21:T21) -> 226 | ... AI21: =SUM(T21:W21) -> 3273 | AK21: =SUM(AI21/AE21)-1 -> 5.934322
B22: Gains (losses) on equity investments, net | C22: 1904 | D22: 2729 | E22: 4268 | F22: 40 | G22: 242 | I22: 4323 | J22: -90 | K22: -151 | L22: =SUM(E22-SUM(I22:K22)) -> 186 | M22: 169 | N22: -24 | O22: -191 | P22: =SUM(F22-SUM(M22:O22)) -> 86 | Q22: 205 | R22: -120 | S22: -159 | T22: =SUM(G22-SUM(Q22:S22)) -> 316 | U22: -112 | V22: 502 | W22: 221 | Y22: =SUM(J22:M22) -> 114 | Z22: =SUM(K22:N22) -> 180 | AA22: =SUM(L22:O22) -> 140 | AB22: =SUM(M22:P22) -> 40 | AC22: =SUM(N22:Q22) -> 76 | AD22: =SUM(O22:R22) -> -20 | AE22: =SUM(P22:S22) -> 12 | AF22: =SUM(Q22:T22) -> 242 | ... AI22: =SUM(T22:W22) -> 927 | AK22: =SUM(AI22/AE22)-1 -> 76.25
B23: Gains (losses) from divestitures | C23: 0 | D23: 0 | E23: 0 | F23: 0 | G23: 0 | I23: 0 | J23: 0 | K23: 0 | L23: =SUM(E23-SUM(I23:K23)) -> 0 | M23: 0 | N23: 0 | O23: 0 | P23: =SUM(F23-SUM(M23:O23)) -> 0 | Q23: 0 | R23: 0 | S23: 0 | T23: =SUM(G23-SUM(Q23:S23)) -> 0 | U23: 0 | V23: 0 | W23: 0 | Y23: =SUM(J23:M23) -> 0 | Z23: =SUM(K23:N23) -> 0 | AA23: =SUM(L23:O23) -> 0 | AB23: =SUM(M23:P23) -> 0 | AC23: =SUM(N23:Q23) -> 0 | AD23: =SUM(O23:R23) -> 0 | AE23: =SUM(P23:S23) -> 0 | AF23: =SUM(Q23:T23) -> 0 | ... AI23: =SUM(T23:W23) -> 0 | AK23: =SUM(AI23/AE23)-1 -> #DIV/0!
B24: Net loss before provision for income taxes | C24: =SUM(C21:C23)+C18 -> 25078 | D24: =SUM(D21:D23)+D18 -> 21703 | E24: =SUM(E21:E23)+E18 -> 7768 | F24: =SUM(F21:F23)+F18 -> 762 | G24: =SUM(G21:G23)+G18 -> -11210 | I24: =SUM(I21:I23)+I18 -> 9661 | J24: =SUM(J21:J23)+J18 -> -909 | K24: =SUM(K21:K23)+K18 -> -188 | L24: =SUM(L21:L23)+L18 -> -796 | M24: =SUM(M21:M23)+M18 -> -1158 | N24: =SUM(N21:N23)+N18 -> -816 | O24: =SUM(O21:O23)+O18 -> -52 | P24: =SUM(P21:P23)+P18 -> 2788 | ... W24: =SUM(W21:W23)+W18 -> 4574 | Y24: =SUM(Y21:Y23)+Y18 -> -3051 | Z24: =SUM(Z21:Z23)+Z18 -> -2958 | AA24: =SUM(AA21:AA23)+AA18 -> -2822 | AB24: =SUM(AB21:AB23)+AB18 -> 762 | AC24: =SUM(AC21:AC23)+AC18 -> 1201 | AD24: =SUM(AD21:AD23)+AD18 -> 13 | AE24: =SUM(AE21:AE23)+AE18 -> -9021 | AF24: =SUM(AF21:AF23)+AF18 -> -11210 | ... AI24: =SUM(AI21:AI23)+AI18 -> 1818 | AK24: =SUM(AI24/AE24)-1 -> -1.2015298
B26: Provision for taxes | C26: -4179 | D26: -1835 | E26: 249 | F26: 913 | G26: -8023 | I26: -1548 | J26: 455 | K26: 1207 | L26: =SUM(E26-SUM(I26:K26)) -> 135 | M26: -1610 | N26: 2289 | O26: 362 | P26: =SUM(F26-SUM(M26:O26)) -> -128 | Q26: 282 | R26: 350 | S26: -7903 | T26: =SUM(G26-SUM(Q26:S26)) -> -752 | U26: -301 | V26: -255 | W26: -304 | Y26: =SUM(J26:M26) -> 187 | Z26: =SUM(K26:N26) -> 2021 | AA26: =SUM(L26:O26) -> 1176 | AB26: =SUM(M26:P26) -> 913 | AC26: =SUM(N26:Q26) -> 2805 | AD26: =SUM(O26:R26) -> 866 | AE26: =SUM(P26:S26) -> -7399 | AF26: =SUM(Q26:T26) -> -8023 | ... AI26: =SUM(T26:W26) -> -1612 | AK26: =SUM(AI26/AE26)-1 -> -0.78213272
B27: Net loss | C27: =SUM(C24+C26) -> 20899 | D27: =SUM(D24+D26) -> 19868 | E27: =SUM(E24+E26) -> 8017 | F27: =SUM(F24+F26) -> 1675 | G27: =SUM(G24+G26) -> -19233 | I27: =SUM(I24+I26) -> 8113 | J27: =SUM(J24+J26) -> -454 | K27: =SUM(K24+K26) -> 1019 | L27: =SUM(L24+L26) -> -661 | M27: =SUM(M24+M26) -> -2768 | N27: =SUM(N24+N26) -> 1473 | O27: =SUM(O24+O26) -> 310 | P27: =SUM(P24+P26) -> 2660 | ... W27: =SUM(W24+W26) -> 4270 | Y27: =SUM(Y24+Y26) -> -2864 | Z27: =SUM(Z24+Z26) -> -937 | AA27: =SUM(AA24+AA26) -> -1646 | AB27: =SUM(AB24+AB26) -> 1675 | AC27: =SUM(AC24+AC26) -> 4006 | AD27: =SUM(AD24+AD26) -> 879 | AE27: =SUM(AE24+AE26) -> -16420 | AF27: =SUM(AF24+AF26) -> -19233 | ... AI27: =SUM(AI24+AI26) -> 206 | AK27: =SUM(AI27/AE27)-1 -> -1.0125457
B28: Net Margin (%) | C28: =C27/C9 -> 0.26839354 | D28: =D27/D9 -> 0.25141729 | E28: =E27/E9 -> 0.12714499 | F28: =F27/F9 -> 0.030888102 | G28: =G27/G9 -> -0.36219657 | I28: =I27/I9 -> 0.44205307 | J28: =J27/J9 -> -0.029632531 | K28: =K27/K9 -> 0.066436302 | L28: =L27/L9 -> -0.047073067 | M28: =M27/M9 -> -0.23627828 | N28: =N27/N9 -> 0.11375396 | O28: =O27/O9 -> 0.021895748 | P28: =P27/P9 -> 0.17266 | ... W28: =W27/W9 -> 0.31275178 | Y28: =Y27/Y9 -> -0.05076574 | Z28: =Z27/Z9 -> -0.017337725 | AA28: =AA27/AA9 -> -0.031136501 | AB28: =AB27/AB9 -> 0.030888102 | AC28: =AC27/AC9 -> 0.072523852 | AD28: =AD27/AD9 -> 0.015946735 | AE28: =AE27/AE9 -> -0.30268955 | AF28: =AF27/AF9 -> -0.36219657 | ... AI28: =AI27/AI9 -> 0.0038548626 | AK28: =SUM(AI28-AE28)*1000 -> 306.54441
B30: Basic shares | C30: 4198.5 | D30: 4058.75 | E30: 4107.5 | F30: 4190 | G30: 4280 | I30: 4079 | J30: 4100 | K30: 4118 | L30: 4133 | M30: 4154 | N30: 4182 | O30: 4202 | P30: 4222 | Q30: 4242 | R30: 4267 | S30: 4292 | T30: 4319 | U30: 4343 | V30: 4369 | W30: 4514 | AE30: =S30 -> 4292 | AF30: =T30 -> 4319 | AG30: =U30 -> 4343 | AH30: =V30 -> 4369 | AI30: =W30 -> 4514
B31: Basic EPS | C31: =C27/C30 -> 4.9777301 | D31: =D27/D30 -> 4.8951032 | E31: =E27/E30 -> 1.9517955 | F31: =F27/F30 -> 0.39976134 | G31: =G27/G30 -> -4.4936916 | I31: =I27/I30 -> 1.9889679 | J31: =J27/J30 -> -0.11073171 | K31: =K27/K30 -> 0.24745022 | L31: =L27/L30 -> -0.15993225 | M31: =M27/M30 -> -0.66634569 | N31: =N27/N30 -> 0.35222382 | O31: =O27/O30 -> 0.073774393 | P31: =P27/P30 -> 0.63003316 | ... W31: =W27/W30 -> 0.94594595 | Y31: =Y27/Y30 -> #DIV/0! | Z31: =Z27/Z30 -> #DIV/0! | AA31: =AA27/AA30 -> #DIV/0! | AB31: =AB27/AB30 -> #DIV/0! | AC31: =AC27/AC30 -> #DIV/0! | AD31: =AD27/AD30 -> #DIV/0! | AE31: =AE27/AE30 -> -3.8257223 | AF31: =AF27/AF30 -> -4.4531141 | ... AI31: =AI27/AI30 -> 0.0456358 | AK31: =SUM(AI31/AE31)-1 -> -1.0119287
B33: Fully Diluted Shares | C33: 4231.5 | D33: 4090.25 | E33: 4116.25 | F33: 4209.75 | G33: 4280 | I33: 4107 | J33: 4100 | K33: 4125 | L33: 4133 | M33: 4154 | N33: 4196 | O33: 4229 | P33: 4260 | Q33: 4242 | R33: 4267 | S33: 4292 | T33: 4319 | U33: 4343 | V33: 4369 | W33: 4531 | Y33: =M33 -> 4154 | Z33: =N33 -> 4196 | AA33: =O33 -> 4229 | AB33: =P33 -> 4260 | AC33: =Q33 -> 4242 | AD33: =R33 -> 4267 | AE33: =S33 -> 4292 | AF33: =T33 -> 4319 | ... AI33: =W33 -> 4531
B34: Diluted EPS | C34: =C27/C33 -> 4.9389106 | D34: =D27/D33 -> 4.8574048 | E34: =E27/E33 -> 1.9476465 | F34: =F27/F33 -> 0.39788586 | G34: =G27/G33 -> -4.4936916 | I34: =I27/I33 -> 1.9754078 | J34: =J27/J33 -> -0.11073171 | K34: =K27/K33 -> 0.2470303 | L34: =L27/L33 -> -0.15993225 | M34: =M27/M33 -> -0.66634569 | N34: =N27/N33 -> 0.35104862 | O34: =O27/O33 -> 0.073303381 | P34: =P27/P33 -> 0.62441315 | ... W34: =W27/W33 -> 0.94239682 | Y34: =Y27/Y33 -> -0.68945595 | Z34: =Z27/Z33 -> -0.22330791 | AA34: =AA27/AA33 -> -0.38921731 | AB34: =AB27/AB33 -> 0.39319249 | AC34: =AC27/AC33 -> 0.94436587 | AD34: =AD27/AD33 -> 0.20599953 | AE34: =AE27/AE33 -> -3.8257223 | AF34: =AF27/AF33 -> -4.4531141 | ... AI34: =AI27/AI33 -> 0.045464577 | AK34: =SUM(AI34/AE34)-1 -> -1.0118839
A36: X | B36: Balance Sheet Statement
B38: Cash and cash equivalents | C38: 5865 | D38: 4827 | E38: 11144 | F38: 7079 | G38: 8249 | I38: 6215 | J38: 4390 | K38: 4529 | L38: =E38 -> 11144 | M38: 8232 | N38: 8349 | O38: 7621 | P38: =F38 -> 7079 | Q38: 6923 | R38: 11287 | S38: 8785 | T38: =G38 -> 8249 | U38: 8947 | V38: 9643 | W38: 11141 | Y38: =M38 -> 8232 | Z38: =N38 -> 8349 | AA38: =O38 -> 7621 | AB38: =P38 -> 7079 | AC38: =Q38 -> 6923 | AD38: =R38 -> 11287 | AE38: =S38 -> 8785 | AF38: =T38 -> 8249 | ... AI38: =W38 -> 11141 | AK38: =SUM(AI38/AE38)-1 -> 0.26818441
B39: Short-term investments | C39: 2292 | D39: 2103 | E39: 0 | F39: 0 | G39: 0 | I39: 10998 | J39: 0 | K39: 0 | L39: =E39 -> 0 | M39: 0 | N39: 0 | O39: 0 | P39: =F39 -> 0 | Q39: 0 | R39: 0 | S39: 0 | T39: =G39 -> 0 | U39: 0 | V39: 0 | W39: 0 | Y39: =M39 -> 0 | Z39: =N39 -> 0 | AA39: =O39 -> 0 | AB39: =P39 -> 0 | AC39: =Q39 -> 0 | AD39: =R39 -> 0 | AE39: =S39 -> 0 | AF39: =T39 -> 0 | ... AI39: =W39 -> 0 | AK39: =SUM(AI39/AE39)-1 -> #DIV/0!
B40: Trading assets | C40: 15738 | D40: 21483 | E40: 17194 | F40: 17955 | G40: 13813 | I40: 21483 | J40: 22654 | K40: 18030 | L40: =E40 -> 17194 | M40: 19302 | N40: 15908 | O40: 17409 | P40: =F40 -> 17955 | Q40: 14388 | R40: 17986 | S40: 15301 | T40: =G40 -> 13813 | U40: 12101 | V40: 11563 | W40: 19794 | Y40: =M40 -> 19302 | Z40: =N40 -> 15908 | AA40: =O40 -> 17409 | AB40: =P40 -> 17955 | AC40: =Q40 -> 14388 | AD40: =R40 -> 17986 | AE40: =S40 -> 15301 | AF40: =T40 -> 13813 | ... AI40: =W40 -> 19794 | AK40: =SUM(AI40/AE40)-1 -> 0.29364094
B41: Accounts receivable, net | C41: 6782 | D41: 9457 | E41: 4133 | F41: 3402 | G41: 3478 | I41: 7074 | J41: 6063 | K41: 7469 | L41: =E41 -> 4133 | M41: 3847 | N41: 2996 | O41: 2843 | P41: =F41 -> 3402 | Q41: 3323 | R41: 3131 | S41: 3121 | T41: =G41 -> 3478 | U41: 3064 | V41: 2360 | W41: 3202 | Y41: =M41 -> 3847 | Z41: =N41 -> 2996 | AA41: =O41 -> 2843 | AB41: =P41 -> 3402 | AC41: =Q41 -> 3323 | AD41: =R41 -> 3131 | AE41: =S41 -> 3121 | AF41: =T41 -> 3478 | ... AI41: =W41 -> 3202 | AK41: =SUM(AI41/AE41)-1 -> 0.02595322
B42: Inventories | C42: 8427 | D42: 10776 | E42: 13224 | F42: 11127 | G42: 12198 | I42: 11935 | J42: 12174 | K42: 12831 | L42: 13224 | M42: 12993 | N42: 11984 | O42: 11466 | P42: 11127 | Q42: 11494 | R42: 11244 | S42: 12062 | T42: 12198 | U42: 12281 | V42: 11377 | W42: 11489 | Y42: =M42 -> 12993 | Z42: =N42 -> 11984 | AA42: =O42 -> 11466 | AB42: =P42 -> 11127 | AC42: =Q42 -> 11494 | AD42: =R42 -> 11244 | AE42: =S42 -> 12062 | AF42: =T42 -> 12198 | ... AI42: =W42 -> 11489 | AK42: =SUM(AI42/AE42)-1 -> -0.04750456
B43: Deferred tax assets | C43: 0 | D43: 0 | E43: 0 | F43: 0 | G43: 0 | I43: 0 | J43: 0 | K43: 0 | L43: =E43 -> 0 | M43: 0 | N43: 0 | O43: 0 | P43: =F43 -> 0 | Q43: 0 | R43: 0 | S43: 0 | T43: =G43 -> 0 | U43: 0 | V43: 0 | W43: 0 | Y43: =M43 -> 0 | Z43: =N43 -> 0 | AA43: =O43 -> 0 | AB43: =P43 -> 0 | AC43: =Q43 -> 0 | AD43: =R43 -> 0 | AE43: =S43 -> 0 | AF43: =T43 -> 0 | ... AI43: =W43 -> 0 | AK43: =SUM(AI43/AE43)-1 -> #DIV/0!
B44: Other current assets | C44: 8145 | D44: 9072 | E44: 4712 | F44: 3706 | G44: 9586 | I44: 4863 | J44: 5307 | K44: 6404 | L44: =E44 -> 4712 | M44: 3940 | N44: 4119 | O44: 4472 | P44: =F44 -> 3706 | Q44: 6480 | R44: 7181 | S44: 6868 | T44: =G44 -> 9586 | U44: 5741 | V44: 8432 | W44: 6105 | Y44: =M44 -> 3940 | Z44: =N44 -> 4119 | AA44: =O44 -> 4472 | AB44: =P44 -> 3706 | AC44: =Q44 -> 6480 | AD44: =R44 -> 7181 | AE44: =S44 -> 6868 | AF44: =T44 -> 9586 | ... AI44: =W44 -> 6105 | AK44: =SUM(AI44/AE44)-1 -> -0.11109493
B45: Total Current Assets | C45: =SUM(C38:C44) -> 47249 | D45: =SUM(D38:D44) -> 57718 | E45: =SUM(E38:E44) -> 50407 | F45: =SUM(F38:F44) -> 43269 | G45: =SUM(G38:G44) -> 47324 | I45: =SUM(I38:I44) -> 62568 | J45: =SUM(J38:J44) -> 50588 | K45: =SUM(K38:K44) -> 49263 | L45: =SUM(L38:L44) -> 50407 | M45: =SUM(M38:M44) -> 48314 | N45: =SUM(N38:N44) -> 43356 | O45: =SUM(O38:O44) -> 43811 | P45: =SUM(P38:P44) -> 43269 | ... W45: =SUM(W38:W44) -> 51731 | Y45: =SUM(Y38:Y44) -> 48314 | Z45: =SUM(Z38:Z44) -> 43356 | AA45: =SUM(AA38:AA44) -> 43811 | AB45: =SUM(AB38:AB44) -> 43269 | AC45: =SUM(AC38:AC44) -> 42608 | AD45: =SUM(AD38:AD44) -> 50829 | AE45: =SUM(AE38:AE44) -> 46137 | AF45: =SUM(AF38:AF44) -> 47324 | ... AI45: =SUM(AI38:AI44) -> 51731 | AK45: =SUM(AI45/AE45)-1 -> 0.12124759
B47: Property, plant and equipment | C47: 56584 | D47: 63245 | E47: 80860 | F47: 96647 | G47: 107919 | I47: 66718 | J47: 71660 | K47: 75763 | L47: =E47 -> 80860 | M47: 85734 | N47: 90945 | O47: 93352 | P47: =F47 -> 96647 | Q47: 99924 | R47: 103398 | S47: 104248 | T47: =G47 -> 107919 | U47: 109763 | V47: 109510 | W47: 105047 | Y47: =M47 -> 85734 | Z47: =N47 -> 90945 | AA47: =O47 -> 93352 | AB47: =P47 -> 96647 | AC47: =Q47 -> 99924 | AD47: =R47 -> 103398 | AE47: =S47 -> 104248 | AF47: =T47 -> 107919 | ... AI47: =W47 -> 105047 | AK47: =SUM(AI47/AE47)-1 -> 0.0076644156
B48: Marketable equity securities | C48: 5152 | D48: 6298 | E48: 5912 | F48: 5829 | G48: 5383 | I48: 6036 | J48: 5929 | K48: 5822 | L48: =E48 -> 5912 | M48: 6029 | N48: 5893 | O48: 5700 | P48: =F48 -> 5829 | Q48: 6139 | R48: 5824 | S48: 5496 | T48: =G48 -> 5383 | U48: 5027 | V48: 5383 | W48: 8667 | Y48: =M48 -> 6029 | Z48: =N48 -> 5893 | AA48: =O48 -> 5700 | AB48: =P48 -> 5829 | AC48: =Q48 -> 6139 | AD48: =R48 -> 5824 | AE48: =S48 -> 5496 | AF48: =T48 -> 5383 | ... AI48: =W48 -> 8667 | AK48: =SUM(AI48/AE48)-1 -> 0.57696507
B49: Other long-term investments | C49: 2192 | D49: 840 | E49: 0 | F49: 0 | G49: 0 | I49: 0 | J49: 0 | K49: 0 | L49: =E49 -> 0 | M49: 0 | N49: 0 | O49: 0 | P49: =F49 -> 0 | Q49: 0 | R49: 0 | S49: 0 | T49: =G49 -> 0 | U49: 0 | V49: 0 | W49: 0 | Y49: =M49 -> 0 | Z49: =N49 -> 0 | AA49: =O49 -> 0 | AB49: =P49 -> 0 | AC49: =Q49 -> 0 | AD49: =R49 -> 0 | AE49: =S49 -> 0 | AF49: =T49 -> 0 | ... AI49: =W49 -> 0 | AK49: =SUM(AI49/AE49)-1 -> #DIV/0!
B50: Goodwill & intangibles | C50: 35997 | D50: 26963 | E50: 27591 | F50: 27591 | G50: 24693 | I50: 27011 | J50: 27587 | K50: 27591 | L50: =E50 -> 27591 | M50: 27591 | N50: 27591 | O50: 27591 | P50: =F50 -> 27591 | Q50: 27440 | R50: 27442 | S50: 24680 | T50: =G50 -> 24693 | U50: 24693 | V50: 23912 | W50: 23912 | Y50: =M50 -> 27591 | Z50: =N50 -> 27591 | AA50: =O50 -> 27591 | AB50: =P50 -> 27591 | AC50: =Q50 -> 27440 | AD50: =R50 -> 27442 | AE50: =S50 -> 24680 | AF50: =T50 -> 24693 | ... AI50: =W50 -> 23912 | AK50: =SUM(AI50/AE50)-1 -> -0.031118314
B51: Other long-term assets | C51: 5917 | D51: 13342 | E51: 17333 | F51: 18236 | G51: 11166 | I51: 14023 | J51: 14654 | K51: 16402 | L51: =E51 -> 17333 | M51: 17635 | N51: 17844 | O51: 18383 | P51: =F51 -> 18236 | Q51: 16622 | R51: 18712 | S51: 12981 | T51: =G51 -> 11166 | U51: 10625 | V51: 10340 | W51: 15157 | Y51: =M51 -> 17635 | Z51: =N51 -> 17844 | AA51: =O51 -> 18383 | AB51: =P51 -> 18236 | AC51: =Q51 -> 16622 | AD51: =R51 -> 18712 | AE51: =S51 -> 12981 | AF51: =T51 -> 11166 | ... AI51: =W51 -> 15157 | AK51: =SUM(AI51/AE51)-1 -> 0.16762961
B52: Total Assets | C52: =SUM(C47:C51)+C45 -> 153091 | D52: =SUM(D47:D51)+D45 -> 168406 | E52: =SUM(E47:E51)+E45 -> 182103 | F52: =SUM(F47:F51)+F45 -> 191572 | G52: =SUM(G47:G51)+G45 -> 196485 | I52: =SUM(I47:I51)+I45 -> 176356 | J52: =SUM(J47:J51)+J45 -> 170418 | K52: =SUM(K47:K51)+K45 -> 174841 | L52: =SUM(L47:L51)+L45 -> 182103 | M52: =SUM(M47:M51)+M45 -> 185303 | N52: =SUM(N47:N51)+N45 -> 185629 | O52: =SUM(O47:O51)+O45 -> 188837 | P52: =SUM(P47:P51)+P45 -> 191572 | ... W52: =SUM(W47:W51)+W45 -> 204514 | Y52: =SUM(Y47:Y51)+Y45 -> 185303 | Z52: =SUM(Z47:Z51)+Z45 -> 185629 | AA52: =SUM(AA47:AA51)+AA45 -> 188837 | AB52: =SUM(AB47:AB51)+AB45 -> 191572 | AC52: =SUM(AC47:AC51)+AC45 -> 192733 | AD52: =SUM(AD47:AD51)+AD45 -> 206205 | AE52: =SUM(AE47:AE51)+AE45 -> 193542 | AF52: =SUM(AF47:AF51)+AF45 -> 196485 | ... AI52: =SUM(AI47:AI51)+AI45 -> 204514 | AK52: =SUM(AI52/AE52)-1 -> 0.056690537
...

Sheet 3-Statement Model
C2: ="Financial Statement Model for "&D5 -> Financial Statement Model for Intel
C3: $ in thousands except per share
C5: Company name | D5: Intel | I5: Select an operating scenario: | L5: Base case
C6: Ticker | D6: INTC
C7: Circ break 1=off, 0=on | D7: 1
C8: Latest closing share price | D8: 293.65
C9: Latest closing share price date | D9: =NOW() -> 45956.565
C10: Latest fiscal year end date | D10: ='Base Financials'!G4 -> 45654
C11: Shares outstanding (millions) | D11: =4377*1000 -> 4377000
C13: INCOME STATEMENT
C14: Fiscal year | D14: =E14-1 -> 2021 | E14: =F14-1 -> 2022 | F14: =G14-1 -> 2023 | G14: =YEAR(D10) -> 2024 | H14: =G14+1 -> 2025 | I14: =H14+1 -> 2026 | J14: =I14+1 -> 2027 | K14: =J14+1 -> 2028 | L14: =K14+1 -> 2029
C15: Fiscal year end date | D15: =EOMONTH(E15,-12) -> 44561 | E15: =EOMONTH(F15,-12) -> 44926 | F15: =EOMONTH(G15,-12) -> 45291 | G15: =D10 -> 45654 | H15: =EOMONTH(G15,12) -> 46022 | I15: =EOMONTH(H15,12) -> 46387 | J15: =EOMONTH(I15,12) -> 46752 | K15: =EOMONTH(J15,12) -> 47118 | L15: =EOMONTH(K15,12) -> 47483 | N15: Comments
C17: Revenue | D17: ='Base Financials'!D8 -> 79024 | E17: ='Base Financials'!E8 -> 63054 | F17: ='Base Financials'!F8 -> 54228 | G17: ='Base Financials'!G8 -> 53101 | H17: =G17*(1+H37) -> 52038.98 | I17: =H17*(1+I37) -> 53652.188 | J17: =I17*(1+J37) -> 56012.885 | K17: =J17*(1+K37) -> 58813.529 | L17: =K17*(1+L37) -> 61401.324 | N17: Street Consensus
C18: (-) Cost of sales | D18: ='Base Financials'!C11 -> -34255 | E18: ='Base Financials'!D11 -> -35209 | F18: ='Base Financials'!E11 -> -36188 | G18: ='Base Financials'!F11 -> -32517 | H18: =H19-H17 -> -33334.745 | I18: =I19-I17 -> -33413.323 | J18: =J19-J17 -> -32691.279 | K18: =K19-K17 -> -34325.843 | L18: =L19-L17 -> -35836.18 | N18: Plug = Revenue - Gross Profit
C19: Gross Profit | D19: =SUM(D17:D18) -> 44769 | E19: =SUM(E17:E18) -> 27845 | F19: =SUM(F17:F18) -> 18040 | G19: =SUM(G17:G18) -> 20584 | H19: =H17*H38 -> 18704.235 | I19: =I17*I38 -> 20238.865 | J19: =J17*J38 -> 23321.605 | K19: =K17*K38 -> 24487.686 | L19: =L17*L38 -> 25565.144 | N19: Revenue x Gross Profit Margin forecast
C20: (-) Research & Development (R&D) | D20: ='Base Financials'!D16 -> -15190 | E20: ='Base Financials'!E16 -> -17528 | F20: ='Base Financials'!F16 -> -16046 | G20: ='Base Financials'!G16 -> -16546 | H20: =-H39*H17 -> -13826.648 | I20: =-I39*I17 -> -13168.534 | J20: =-J39*J17 -> -13210.932 | K20: =-K39*K17 -> -13871.479 | L20: =-L39*L17 -> -14481.824 | N20: Street Consensus
C21: (-) Marketing, General, and Administrative (MG&A) | D21: ='Base Financials'!D15 -> -6543 | E21: ='Base Financials'!E15 -> -7002 | F21: ='Base Financials'!F15 -> -5634 | G21: ='Base Financials'!G15 -> -5507 | H21: =-H17*H40 -> -4627.383 | I21: =-I17*I40 -> -4772.3425 | J21: =-J17*J40 -> -4880.1244 | K21: =-K17*K40 -> -5124.1307 | L21: =-L17*L40 -> -5349.5924 | N21: Street Consensus
C22: (-) Restructuring and Other Charges | D22: ='Base Financials'!D17 -> -2626 | E22: ='Base Financials'!E17 -> -2 | F22: ='Base Financials'!F17 -> 62 | G22: ='Base Financials'!G17 -> -6970 | H22: =AVERAGE(D22:G22) -> -2384 | I22: =H22 -> -2384 | J22: =I22 -> -2384 | K22: =J22 -> -2384 | L22: =K22 -> -2384 | N22: Average of Historical
C23: Operating profit (EBIT) | D23: =D19+D20+D21+D22 -> 20410 | E23: =E19+E20+E21+E22 -> 3313 | F23: =F19+F20+F21+F22 -> -3578 | G23: =G19+G20+G21+G22 -> -8439 | H23: =H19+H20+H21+H22 -> -2133.7956 | I23: =I19+I20+I21+I22 -> -86.011305 | J23: =J19+J20+J21+J22 -> 2846.5489 | K23: =K19+K20+K21+K22 -> 3108.0764 | L23: =L19+L20+L21+L22 -> 3349.7277 | N23: Gross Profit - R&D - SG&A
C24: (+) Interest income | D24: 144 | E24: 589 | F24: 1335 | G24: 1245 | H24: =H169 -> 0 | I24: =I169 -> 0 | J24: =J169 -> 0 | K24: =K169 -> 0 | L24: =L169 -> 0 | N24: Reference from interest on cash schedule
C25: (-) Interest expense | D25: -597 | E25: -496 | F25: -878 | G25: -1034 | H25: =-H155 -> #REF! | I25: =-I155 -> #REF! | J25: =-J155 -> #REF! | K25: =-K155 -> #REF! | L25: =-L155 -> #REF! | N25: Reference from interest expense schedule
C26: (-) Other expense, net | D26: -29 | E26: 1073 | F26: 172 | G26: 15 | H26: =G26 -> 15 | I26: =H26 -> 15 | J26: =I26 -> 15 | K26: =J26 -> 15 | L26: =K26 -> 15 | N26: Straight-line
C27: Pretax profit | D27: =SUM(D23:D26) -> 19928 | E27: =SUM(E23:E26) -> 4479 | F27: =SUM(F23:F26) -> -2949 | G27: =SUM(G23:G26) -> -8213 | H27: =SUM(H23:H26) -> #REF! | I27: =SUM(I23:I26) -> #REF! | J27: =SUM(J23:J26) -> #REF! | K27: =SUM(K23:K26) -> #REF! | L27: =SUM(L23:L26) -> #REF! | N27: EBIT + interest income less interest expense less other expense
C28: (-) Taxes | D28: ='Base Financials'!D26 -> -1835 | E28: ='Base Financials'!E26 -> 249 | F28: ='Base Financials'!F26 -> 913 | G28: ='Base Financials'!G26 -> -8023 | H28: =-H41*H27 -> #REF! | I28: =-I41*I27 -> #REF! | J28: =-J41*J27 -> #REF! | K28: =-K41*K27 -> #REF! | L28: =-L41*L27 -> #REF! | N28: Street Consensus
C29: Net income | D29: =SUM(D27:D28) -> 18093 | E29: =SUM(E27:E28) -> 4728 | F29: =SUM(F27:F28) -> -2036 | G29: =SUM(G27:G28) -> -16236 | H29: =SUM(H27:H28) -> #REF! | I29: =SUM(I27:I28) -> #REF! | J29: =SUM(J27:J28) -> #REF! | K29: =SUM(K27:K28) -> #REF! | L29: =SUM(L27:L28) -> #REF! | N29: Pre-tax Profit less taxes
C31: Depreciation & amortization | D31: ='Base Financials'!D85+'Base Financials'!D92 -> 11792 | E31: ='Base Financials'!E85+'Base Financials'!E92 -> 13035 | F31: ='Base Financials'!F85+'Base Financials'!F92 -> 9602 | G31: ='Base Financials'!G85+'Base Financials'!G92 -> 11379 | H31: =H119 -> 11151.42 | I31: =I119 -> 11737.114 | J31: =J119 -> 12482.987 | K31: =K119 -> 13323.136 | L31: =L119 -> 14117.674 | N31: Reference from D&A schedule
C32: EBITDA | D32: =D23+D31 -> 32202 | E32: =E23+E31 -> 16348 | F32: =F23+F31 -> 6024 | G32: =G23+G31 -> 2940 | H32: =H23+H31 -> 9017.6244 | I32: =I23+I31 -> 11651.103 | J32: =J23+J31 -> 15329.536 | K32: =K23+K31 -> 16431.213 | L32: =L23+L31 -> 17467.402 | N32: EBIT + D&A
C33: Stock based compensation | D33: ='Base Financials'!D88 -> 2036 | E33: ='Base Financials'!E88 -> 3128 | F33: ='Base Financials'!F88 -> 3229 | G33: ='Base Financials'!G88 -> 3410 | H33: =G33*(1+H37) -> 3341.8 | I33: =H33*(1+I37) -> 3445.3958 | J33: =I33*(1+J37) -> 3596.9932 | K33: =J33*(1+K37) -> 3776.8429 | L33: =K33*(1+L37) -> 3943.024 | N33: WSP assumption: grow SBC in-line with revenue growth
C34: Adjusted EBITDA | D34: =SUM(D32:D33) -> 34238 | E34: =SUM(E32:E33) -> 19476 | F34: =SUM(F32:F33) -> 9253 | G34: =SUM(G32:G33) -> 6350 | H34: =SUM(H32:H33) -> 12359.424 | I34: =SUM(I32:I33) -> 15096.499 | J34: =SUM(J32:J33) -> 18926.529 | K34: =SUM(K32:K33) -> 20208.056 | L34: =SUM(L32:L33) -> 21410.426 | N34: EBITDA + Stock-based compensation
C36: Growth rates & margins
C37: Revenue growth | E37: =E17/D17-1 -> -0.2020905 | F37: =F17/E17-1 -> -0.13997526 | G37: =G17/F17-1 -> -0.020782622 | H37: ='Street Consensus'!C21 -> -0.02 | I37: ='Street Consensus'!D21 -> 0.031 | J37: ='Street Consensus'!E21 -> 0.044 | K37: ='Street Consensus'!F21 -> 0.05 | L37: ='Street Consensus'!G21 -> 0.044 | N37: Consensus estimates through 2021; straight-line growth rate thereafter
C38: Gross profit margin | D38: =D19/D17 -> 0.56652409 | E38: =E19/E17 -> 0.44160561 | F38: =F19/F17 -> 0.33266947 | G38: =G19/G17 -> 0.38763865 | H38: ='Street Consensus'!C38 -> 0.3594274 | I38: ='Street Consensus'!D38 -> 0.37722348 | J38: ='Street Consensus'!E38 -> 0.41636144 | K38: ='Street Consensus'!F38 -> 0.41636144 | L38: ='Street Consensus'!G38 -> 0.41636144 | N38: Straight line last historical year
C39: R&D % of sales | D39: =-D20/D17 -> 0.19222009 | E39: =-E20/E17 -> 0.27798395 | F39: =-F20/F17 -> 0.2958988 | G39: =-G20/G17 -> 0.31159489 | H39: ='Street Consensus'!C44 -> 0.26569791 | I39: ='Street Consensus'!D44 -> 0.24544262 | J39: ='Street Consensus'!E44 -> 0.23585523 | K39: ='Street Consensus'!F44 -> 0.23585523 | L39: ='Street Consensus'!G44 -> 0.23585523 | N39: Straight line last historical year
C40: SG&A % of sales | D40: =-D21/D17 -> 0.082797631 | E40: =-E21/E17 -> 0.11104767 | F40: =-F21/F17 -> 0.10389467 | G40: =-G21/G17 -> 0.10370803 | H40: ='Street Consensus'!C50 -> 0.088921477 | I40: ='Street Consensus'!D50 -> 0.088949633 | J40: ='Street Consensus'!E50 -> 0.087125033 | K40: ='Street Consensus'!F50 -> 0.087125033 | L40: ='Street Consensus'!G50 -> 0.087125033 | N40: Straight line last historical year
C41: Tax rate | D41: =-(D28/D27) -> 0.092081493 | E41: =-(E28/E27) -> -0.055592766 | F41: =-(F28/F27) -> 0.30959647 | G41: =-(G28/G27) -> -0.97686594 | H41: ='Street Consensus'!C55 -> 0.12 | I41: ='Street Consensus'!D55 -> 0.12 | J41: ='Street Consensus'!E55 -> 0.12 | K41: ='Street Consensus'!F55 -> 0.12 | L41: ='Street Consensus'!G55 -> 0.12 | N41: Straight line last historical year
C43: BALANCE SHEET
C44: =C14 -> Fiscal year | D44: =D14 -> 2021 | E44: =E14 -> 2022 | F44: =F14 -> 2023 | G44: =G14 -> 2024 | H44: =H14 -> 2025 | I44: =I14 -> 2026 | J44: =J14 -> 2027 | ... L44: =L14 -> 2029
C45: =C15 -> Fiscal year end date | D45: =D15 -> 44561 | E45: =E15 -> 44926 | F45: =F15 -> 45291 | G45: =G15 -> 45654 | H45: =H15 -> 46022 | I45: =I15 -> 46387 | J45: =J15 -> 46752 | ... L45: =L15 -> 47483
C47: Cash & equivalents, ST Marketable Securities | D47: =+SUM('Base Financials'!D38+'Base Financials'!D39) -> 6930 | E47: =+SUM('Base Financials'!E38+'Base Financials'!E39) -> 11144 | F47: =+SUM('Base Financials'!F38+'Base Financials'!F39) -> 7079 | G47: =+SUM('Base Financials'!G38+'Base Financials'!G39) -> 8249 | H47: =H103+G47 -> #REF! | I47: =I103+H47 -> #REF! | J47: =J103+I47 -> #REF! | K47: =K103+J47 -> #REF! | L47: =L103+K47 -> #REF! | N47: Reference from 'net change in cash' line on the cash flow statement
C48: Trading Assets | D48: ='Base Financials'!D40 -> 21483 | E48: ='Base Financials'!E40 -> 17194 | F48: ='Base Financials'!F40 -> 17955 | G48: ='Base Financials'!G40 -> 13813 | H48: =G48*(1+H37) -> 13536.74 | I48: =H48*(1+I37) -> 13956.379 | J48: =I48*(1+J37) -> 14570.46 | K48: =J48*(1+K37) -> 15298.983 | L48: =K48*(1+L37) -> 15972.138 | N48: Grow in-line with revenue growth
...

Sheet FCF
B2: Intel, Corporation. (NASDAQ: INTC) | C2: FYE | I2: Quarterly | Q2: Quarterly | R2: Quarterly | Y2: LTM | AC2: LTM | AK2: Variance
B3: FCF Analysis | C3: ='Base Financials'!C3 -> 2020 | D3: ='Base Financials'!D3 -> 2021 | E3: ='Base Financials'!E3 -> 2022 | F3: ='Base Financials'!F3 -> 2023 | G3: ='Base Financials'!G3 -> 2024 | I3: ='Base Financials'!I3 -> 1Q22 | J3: ='Base Financials'!J3 -> 2Q22 | K3: ='Base Financials'!K3 -> 3Q22 | L3: ='Base Financials'!L3 -> 4Q22 | M3: ='Base Financials'!M3 -> 1Q23 | N3: ='Base Financials'!N3 -> 2Q23 | O3: ='Base Financials'!O3 -> 3Q23 | P3: ='Base Financials'!P3 -> 4Q23 | ... W3: ='Base Financials'!W3 -> 3Q25 | Y3: =L3 -> 4Q22 | Z3: =M3 -> 1Q23 | AA3: =N3 -> 2Q23 | AB3: =O3 -> 3Q23 | AC3: =P3 -> 4Q23 | AD3: =Q3 -> 1Q24 | AE3: =R3 -> 2Q24 | AF3: =S3 -> 3Q24 | ... AI3: =V3 -> 2Q25
B4: ($ In Thousands) | C4: ='Base Financials'!C4 -> 44191 | D4: ='Base Financials'!D4 -> 44555 | E4: ='Base Financials'!E4 -> 44926 | F4: ='Base Financials'!F4 -> 45290 | G4: ='Base Financials'!G4 -> 45654 | I4: ='Base Financials'!I4 -> 44653 | J4: ='Base Financials'!J4 -> 44744 | K4: ='Base Financials'!K4 -> 44835 | L4: ='Base Financials'!L4 -> 44926 | M4: ='Base Financials'!M4 -> 45017 | N4: ='Base Financials'!N4 -> 45108 | O4: ='Base Financials'!O4 -> 45199 | P4: ='Base Financials'!P4 -> 45290 | ... W4: ='Base Financials'!W4 -> 45925 | Y4: =L4 -> 44926 | Z4: =M4 -> 45017 | AA4: =N4 -> 45108 | AB4: =O4 -> 45199 | AC4: =P4 -> 45290 | AD4: =Q4 -> 45381 | AE4: =R4 -> 45472 | AF4: =S4 -> 45563 | ... AI4: =V4 -> 45836
B6: ='Revenue Drivers'!B7 -> Intel Products | C6: ='Revenue Drivers'!C7 -> 71080 | D6: ='Revenue Drivers'!D7 -> 69532 | E6: ='Revenue Drivers'!E7 -> 57038 | F6: ='Revenue Drivers'!F7 -> 47667 | G6: ='Revenue Drivers'!G7 -> 48949 | I6: ='Revenue Drivers'!I7 -> 17467 | J6: ='Revenue Drivers'!J7 -> 14073 | K6: ='Revenue Drivers'!K7 -> 13881 | L6: ='Revenue Drivers'!L7 -> 11617 | M6: ='Revenue Drivers'!M7 -> 10157 | N6: ='Revenue Drivers'!N7 -> 11299 | O6: ='Revenue Drivers'!O7 -> 12393 | P6: ='Revenue Drivers'!P7 -> 13818 | ... W6: ='Revenue Drivers'!W7 -> 12652 | Y6: =SUM(I6:L6) -> 57038 | Z6: =SUM(J6:M6) -> 49728 | AA6: =SUM(K6:N6) -> 46954 | AB6: =SUM(L6:O6) -> 45466 | AC6: =SUM(M6:P6) -> 47667 | AD6: =SUM(N6:Q6) -> 49443 | AE6: =SUM(O6:R6) -> 49943 | AF6: =SUM(P6:S6) -> 49740 | ... AI6: =SUM(S6:V6) -> 48782 | AK6: =SUM(AI6/AE6)-1 -> -0.023246501
B7: ='Revenue Drivers'!B8 -> Intel Foundry | C7: ='Revenue Drivers'!C8 -> 715 | D7: ='Revenue Drivers'!D8 -> 22849 | E7: ='Revenue Drivers'!E8 -> 27491.2 | F7: ='Revenue Drivers'!F8 -> 18910 | G7: ='Revenue Drivers'!G8 -> 17543 | I7: ='Revenue Drivers'!I8 -> 6958.517 | J7: ='Revenue Drivers'!J8 -> 7324.9181 | K7: ='Revenue Drivers'!K8 -> 6651.167 | L7: ='Revenue Drivers'!L8 -> 6556.5979 | M7: ='Revenue Drivers'!M8 -> 4831 | N7: ='Revenue Drivers'!N8 -> 4172 | O7: ='Revenue Drivers'!O8 -> 4732 | P7: ='Revenue Drivers'!P8 -> 5175 | ... W7: ='Revenue Drivers'!W8 -> 4235 | Y7: =SUM(I7:L7) -> 27491.2 | Z7: =SUM(J7:M7) -> 25363.683 | AA7: =SUM(K7:N7) -> 22210.765 | AB7: =SUM(L7:O7) -> 20291.598 | AC7: =SUM(M7:P7) -> 18910 | AD7: =SUM(N7:Q7) -> 18448 | AE7: =SUM(O7:R7) -> 18596 | AF7: =SUM(P7:S7) -> 18216 | ... AI7: =SUM(S7:V7) -> 17938 | AK7: =SUM(AI7/AE7)-1 -> -0.035383954
B8: ='Revenue Drivers'!B9 -> All Other | C8: ='Revenue Drivers'!C9 -> 6709 | D8: ='Revenue Drivers'!D9 -> 9137 | E8: ='Revenue Drivers'!E9 -> 5529.8 | F8: ='Revenue Drivers'!F9 -> 5608 | G8: ='Revenue Drivers'!G9 -> 3824 | I8: ='Revenue Drivers'!I9 -> 1121.0484 | J8: ='Revenue Drivers'!J9 -> 1160.0163 | K8: ='Revenue Drivers'!K9 -> 1499.9821 | L8: ='Revenue Drivers'!L9 -> 1748.7532 | M8: ='Revenue Drivers'!M9 -> 1440 | N8: ='Revenue Drivers'!N9 -> 1419 | O8: ='Revenue Drivers'!O9 -> 1452 | P8: ='Revenue Drivers'!P9 -> 1297 | ... W8: ='Revenue Drivers'!W9 -> 993 | Y8: =SUM(I8:L8) -> 5529.8 | Z8: =SUM(J8:M8) -> 5848.7516 | AA8: =SUM(K8:N8) -> 6107.7353 | AB8: =SUM(L8:O8) -> 6059.7532 | AC8: =SUM(M8:P8) -> 5608 | AD8: =SUM(N8:Q8) -> 4943 | AE8: =SUM(O8:R8) -> 4492 | AF8: =SUM(P8:S8) -> 4079 | ... AI8: =SUM(S8:V8) -> 4077 | AK8: =SUM(AI8/AE8)-1 -> -0.092386465
B9: Intersegment Elimination | C9: ='Revenue Drivers'!C12 -> -637 | D9: ='Revenue Drivers'!D12 -> -22494 | E9: ='Revenue Drivers'!E12 -> -27005 | F9: ='Revenue Drivers'!F12 -> -17957 | G9: ='Revenue Drivers'!G12 -> -17215 | I9: ='Revenue Drivers'!I12 -> -6797.517 | J9: ='Revenue Drivers'!J12 -> -7263.9181 | K9: ='Revenue Drivers'!K12 -> -6569.167 | L9: ='Revenue Drivers'!L12 -> -6374.3979 | M9: ='Revenue Drivers'!M12 -> -4713 | N9: ='Revenue Drivers'!N12 -> -3941 | O9: ='Revenue Drivers'!O12 -> -4419 | P9: ='Revenue Drivers'!P12 -> -4884 | ... W9: ='Revenue Drivers'!W12 -> -4227 | Y9: =SUM(I9:L9) -> -27005 | Z9: =SUM(J9:M9) -> -24920.483 | AA9: =SUM(K9:N9) -> -21597.565 | AB9: =SUM(L9:O9) -> -19447.398 | AC9: =SUM(M9:P9) -> -17957 | AD9: =SUM(N9:Q9) -> -17597 | AE9: =SUM(O9:R9) -> -17910 | AF9: =SUM(P9:S9) -> -17788 | ... AI9: =SUM(S9:V9) -> -17727 | AK9: =SUM(AI9/AE9)-1 -> -0.010217755
B10: Total Revenue | C10: =SUM(C6:C9) -> 77867 | D10: =SUM(D6:D9) -> 79024 | E10: =SUM(E6:E9) -> 63054 | F10: =SUM(F6:F9) -> 54228 | G10: =SUM(G6:G9) -> 53101 | I10: =SUM(I6:I9) -> 18749.048 | J10: =SUM(J6:J9) -> 15294.016 | K10: =SUM(K6:K9) -> 15462.982 | L10: =SUM(L6:L9) -> 13547.953 | M10: =SUM(M6:M9) -> 11715 | N10: =SUM(N6:N9) -> 12949 | O10: =SUM(O6:O9) -> 14158 | P10: =SUM(P6:P9) -> 15406 | ... W10: =SUM(W6:W9) -> 13653 | Y10: =SUM(Y6:Y9) -> 63054 | Z10: =SUM(Z6:Z9) -> 56019.952 | AA10: =SUM(AA6:AA9) -> 53674.935 | AB10: =SUM(AB6:AB9) -> 52369.953 | AC10: =SUM(AC6:AC9) -> 54228 | AD10: =SUM(AD6:AD9) -> 55237 | AE10: =SUM(AE6:AE9) -> 55121 | AF10: =SUM(AF6:AF9) -> 54247 | ... AI10: =SUM(AI6:AI9) -> 53070 | AK10: =SUM(AI10/AE10)-1 -> -0.037209049
B11: Y/Y Growth (%) | D11: =SUM(D10/C10)-1 -> 0.014858669 | E11: =SUM(E10/D10)-1 -> -0.2020905 | F11: =SUM(F10/E10)-1 -> -0.13997526 | G11: =SUM(G10/F10)-1 -> -0.020782622 | M11: =SUM(M10/I10)-1 -> -0.37516829 | N11: =SUM(N10/J10)-1 -> -0.15332901 | O11: =SUM(O10/K10)-1 -> -0.084393949 | P11: =SUM(P10/L10)-1 -> 0.13714594 | Q11: =SUM(Q10/M10)-1 -> 0.086128895 | R11: =SUM(R10/N10)-1 -> -0.0089582207 | S11: =SUM(S10/O10)-1 -> -0.061731883 | T11: =SUM(T10/P10)-1 -> -0.074386603 | ... W11: =SUM(W10/S10)-1 -> 0.027777778 | AC11: =SUM(AC10/Y10)-1 -> -0.13997526 | AD11: =SUM(AD10/Z10)-1 -> -0.013976299 | AE11: =SUM(AE10/AA10)-1 -> 0.026941154 | AF11: =SUM(AF10/AB10)-1 -> 0.035842057 | AG11: =SUM(AG10/AC10)-1 -> -0.020782622 | AH11: =SUM(AH10/AD10)-1 -> -0.039701649 | AI11: =SUM(AI10/AE10)-1 -> -0.037209049 | AK11: =SUM(AI11-AE11)*10000 -> -641.50203
B12: Q/Q Growth (%) | C12: N/A | D12: N/A | E12: N/A | F12: N/A | G12: N/A | J12: =SUM(J10/I10)-1 -> -0.18427773 | K12: =SUM(K10/J10)-1 -> 0.011047838 | L12: =SUM(L10/K10)-1 -> -0.12384603 | M12: =SUM(M10/L10)-1 -> -0.13529373 | N12: =SUM(N10/M10)-1 -> 0.10533504 | O12: =SUM(O10/N10)-1 -> 0.093366283 | P12: =SUM(P10/O10)-1 -> 0.088148044 | Q12: =SUM(Q10/P10)-1 -> -0.17408802 | ... W12: =SUM(W10/V10)-1 -> 0.061746637 | Y12: N/A | Z12: N/A | AA12: N/A | AB12: N/A | AC12: N/A | AD12: N/A | AE12: N/A | AF12: N/A | AG12: N/A | AH12: N/A | AI12: N/A
B14: (-) Cost of Sales | C14: ='Base Financials'!C11 -> -34255 | D14: ='Base Financials'!D11 -> -35209 | E14: ='Base Financials'!E11 -> -36188 | F14: ='Base Financials'!F11 -> -32517 | G14: ='Base Financials'!G11 -> -35756 | I14: ='Base Financials'!I11 -> -9109 | J14: ='Base Financials'!J11 -> -9734 | K14: ='Base Financials'!K11 -> -8803 | L14: ='Base Financials'!L11 -> -8542 | M14: ='Base Financials'!M11 -> -7707 | N14: ='Base Financials'!N11 -> -8311 | O14: ='Base Financials'!O11 -> -8140 | P14: ='Base Financials'!P11 -> -8359 | ... W14: ='Base Financials'!W11 -> -8435 | Y14: =SUM(I14:L14) -> -36188 | Z14: =SUM(J14:M14) -> -34786 | AA14: =SUM(K14:N14) -> -33363 | AB14: =SUM(L14:O14) -> -32700 | AC14: =SUM(M14:P14) -> -32517 | AD14: =SUM(N14:Q14) -> -32317 | AE14: =SUM(O14:R14) -> -32292 | AF14: =SUM(P14:S14) -> -35439 | ... AI14: =SUM(S14:V14) -> -37275 | AK14: =SUM(AI14/AE14)-1 -> 0.15431067
B15: Gross Profit | C15: =+C10+C14 -> 43612 | D15: =+D10+D14 -> 43815 | E15: =+E10+E14 -> 26866 | F15: =+F10+F14 -> 21711 | G15: =+G10+G14 -> 17345 | I15: =+I10+I14 -> 9640.0484 | J15: =+J10+J14 -> 5560.0163 | K15: =+K10+K14 -> 6659.9821 | L15: =+L10+L14 -> 5005.9532 | M15: =+M10+M14 -> 4008 | N15: =+N10+N14 -> 4638 | O15: =+O10+O14 -> 6018 | P15: =+P10+P14 -> 7047 | ... W15: =+W10+W14 -> 5218 | Y15: =+Y10+Y14 -> 26866 | Z15: =+Z10+Z14 -> 21233.952 | AA15: =+AA10+AA14 -> 20311.935 | AB15: =+AB10+AB14 -> 19669.953 | AC15: =+AC10+AC14 -> 21711 | AD15: =+AD10+AD14 -> 22920 | AE15: =+AE10+AE14 -> 22829 | AF15: =+AF10+AF14 -> 18808 | ... AI15: =+AI10+AI14 -> 15795 | AK15: =SUM(AI15/AE15)-1 -> -0.30811687
B16: Gross Margin (%) | C16: =C15/C10 -> 0.56008322 | D16: =D15/D10 -> 0.55445181 | E16: =E15/E10 -> 0.42607923 | F16: =F15/F10 -> 0.40036513 | G16: =G15/G10 -> 0.32664168 | I16: =I15/I10 -> 0.51416201 | J16: =J15/J10 -> 0.36354194 | K16: =K15/K10 -> 0.4307049 | L16: =L15/L10 -> 0.36949885 | M16: =M15/M10 -> 0.34212548 | N16: =N15/N10 -> 0.35817438 | O16: =O15/O10 -> 0.42506004 | P16: =P15/P10 -> 0.45741919 | ... W16: =W15/W10 -> 0.38218707 | Y16: =Y15/Y10 -> 0.42607923 | Z16: =Z15/Z10 -> 0.37904266 | AA16: =AA15/AA10 -> 0.37842496 | AB16: =AB15/AB10 -> 0.37559616 | AC16: =AC15/AC10 -> 0.40036513 | AD16: =AD15/AD10 -> 0.41493926 | AE16: =AE15/AE10 -> 0.41416157 | AF16: =AF15/AF10 -> 0.34671042 | ... AI16: =AI15/AI10 -> 0.29762578 | AK16: =SUM(AI16-AE16)*10000 -> -1165.3579
B18: (-) Marketing, General, and Administrative (MG&A) | C18: ='Base Financials'!C15 -> -6180 | D18: ='Base Financials'!D15 -> -6543 | E18: ='Base Financials'!E15 -> -7002 | F18: ='Base Financials'!F15 -> -5634 | G18: ='Base Financials'!G15 -> -5507 | I18: ='Base Financials'!I15 -> -1752 | J18: ='Base Financials'!J15 -> -1800 | K18: ='Base Financials'!K15 -> -1744 | L18: ='Base Financials'!L15 -> -1706 | M18: ='Base Financials'!M15 -> -1303 | N18: ='Base Financials'!N15 -> -1374 | O18: ='Base Financials'!O15 -> -1340 | P18: ='Base Financials'!P15 -> -1617 | ... W18: ='Base Financials'!W15 -> -1129 | Y18: =SUM(I18:L18) -> -7002 | Z18: =SUM(J18:M18) -> -6553 | AA18: =SUM(K18:N18) -> -6127 | AB18: =SUM(L18:O18) -> -5723 | AC18: =SUM(M18:P18) -> -5634 | AD18: =SUM(N18:Q18) -> -5887 | AE18: =SUM(O18:R18) -> -5842 | AF18: =SUM(P18:S18) -> -5885 | ... AI18: =SUM(S18:V18) -> -4943 | AK18: =SUM(AI18/AE18)-1 -> -0.15388566
B19: (-) Research and Development (R&D) | C19: ='Base Financials'!C16 -> -13556 | D19: ='Base Financials'!D16 -> -15190 | E19: ='Base Financials'!E16 -> -17528 | F19: ='Base Financials'!F16 -> -16046 | G19: ='Base Financials'!G16 -> -16546 | I19: ='Base Financials'!I16 -> -4362 | J19: ='Base Financials'!J16 -> -4400 | K19: ='Base Financials'!K16 -> -4302 | L19: ='Base Financials'!L16 -> -4464 | M19: ='Base Financials'!M16 -> -4109 | N19: ='Base Financials'!N16 -> -4080 | O19: ='Base Financials'!O16 -> -3870 | P19: ='Base Financials'!P16 -> -3987 | ... W19: ='Base Financials'!W16 -> -3231 | Y19: =SUM(I19:L19) -> -17528 | Z19: =SUM(J19:M19) -> -17275 | AA19: =SUM(K19:N19) -> -16955 | AB19: =SUM(L19:O19) -> -16523 | AC19: =SUM(M19:P19) -> -16046 | AD19: =SUM(N19:Q19) -> -16319 | AE19: =SUM(O19:R19) -> -16478 | AF19: =SUM(P19:S19) -> -16657 | ... AI19: =SUM(S19:V19) -> -15249 | AK19: =SUM(AI19/AE19)-1 -> -0.074584294
B20: (-) Restructuring and Other Charges | C20: ='Base Financials'!C17 -> -198 | D20: ='Base Financials'!D17 -> -2626 | E20: ='Base Financials'!E17 -> -2 | F20: ='Base Financials'!F17 -> 62 | G20: ='Base Financials'!G17 -> -6970 | I20: ='Base Financials'!I17 -> 1211 | J20: ='Base Financials'!J17 -> -87 | K20: ='Base Financials'!K17 -> -664 | L20: ='Base Financials'!L17 -> -462 | M20: ='Base Financials'!M17 -> -64 | N20: ='Base Financials'!N17 -> -200 | O20: ='Base Financials'!O17 -> -816 | P20: ='Base Financials'!P17 -> 1142 | ... W20: ='Base Financials'!W17 -> -175 | Y20: =SUM(I20:L20) -> -2 | Z20: =SUM(J20:M20) -> -1277 | AA20: =SUM(K20:N20) -> -1390 | AB20: =SUM(L20:O20) -> -1542 | AC20: =SUM(M20:P20) -> 62 | AD20: =SUM(N20:Q20) -> -222 | AE20: =SUM(O20:R20) -> -965 | AF20: =SUM(P20:S20) -> -5771 | ... AI20: =SUM(S20:V20) -> -7725 | AK20: =SUM(AI20/AE20)-1 -> 7.0051813
B21: Earning before Interest & Taxes (EBIT) | C21: =SUM(C15+SUM(C18:C20)) -> 23678 | D21: =SUM(D15+SUM(D18:D20)) -> 19456 | E21: =SUM(E15+SUM(E18:E20)) -> 2334 | F21: =SUM(F15+SUM(F18:F20)) -> 93 | G21: =SUM(G15+SUM(G18:G20)) -> -11678 | I21: =SUM(I15+SUM(I18:I20)) -> 4737.0484 | J21: =SUM(J15+SUM(J18:J20)) -> -726.98369 | K21: =SUM(K15+SUM(K18:K20)) -> -50.01787 | L21: =SUM(L15+SUM(L18:L20)) -> -1626.0468 | M21: =SUM(M15+SUM(M18:M20)) -> -1468 | N21: =SUM(N15+SUM(N18:N20)) -> -1016 | O21: =SUM(O15+SUM(O18:O20)) -> -8 | P21: =SUM(P15+SUM(P18:P20)) -> 2585 | ... W21: =SUM(W15+SUM(W18:W20)) -> 683 | Y21: =SUM(Y15+SUM(Y18:Y20)) -> 2334 | Z21: =SUM(Z15+SUM(Z18:Z20)) -> -3871.0484 | AA21: =SUM(AA15+SUM(AA18:AA20)) -> -4160.0647 | AB21: =SUM(AB15+SUM(AB18:AB20)) -> -4118.0468 | AC21: =SUM(AC15+SUM(AC18:AC20)) -> 93 | AD21: =SUM(AD15+SUM(AD18:AD20)) -> 492 | AE21: =SUM(AE15+SUM(AE18:AE20)) -> -456 | AF21: =SUM(AF15+SUM(AF18:AF20)) -> -9505 | ... AI21: =SUM(AI15+SUM(AI18:AI20)) -> -12122 | AK21: =SUM(AI21/AE21)-1 -> 25.583333
B22: Operating Margin (%) | C22: =C21/C10 -> 0.3040826 | D22: =D21/D10 -> 0.24620368 | E22: =E21/E10 -> 0.037015891 | F22: =F21/F10 -> 0.0017149812 | G22: =G21/G10 -> -0.21992053 | I22: =I21/I10 -> 0.2526554 | J22: =J21/J10 -> -0.047533864 | K22: =K21/K10 -> -0.0032346846 | L22: =L21/L10 -> -0.12002159 | M22: =M21/M10 -> -0.12530943 | N22: =N21/N10 -> -0.078461657 | O22: =O21/O10 -> -0.00056505156 | P22: =P21/P10 -> 0.16779177 | ... W22: =W21/W10 -> 0.050025635 | Y22: =Y21/Y10 -> 0.037015891 | Z22: =Z21/Z10 -> -0.069101245 | AA22: =AA21/AA10 -> -0.077504792 | AB22: =AB21/AB10 -> -0.07863377 | AC22: =AC21/AC10 -> 0.0017149812 | AD22: =AD21/AD10 -> 0.0089070732 | AE22: =AE21/AE10 -> -0.0082727091 | AF22: =AF21/AF10 -> -0.17521706 | ... AI22: =AI21/AI10 -> -0.2284153 | AK22: =SUM(AI22-AE22)*10000 -> -2201.4259
B24: (+) Depreciation and Amortization | C24: ='Base Financials'!C85+'Base Financials'!C87+'Base Financials'!C92 -> 12239 | D24: ='Base Financials'!D85+'Base Financials'!D87+'Base Financials'!D92 -> 11792 | E24: ='Base Financials'!E85+'Base Financials'!E87+'Base Financials'!E92 -> 13035 | F24: ='Base Financials'!F85+'Base Financials'!F87+'Base Financials'!F92 -> 9602 | G24: ='Base Financials'!G85+'Base Financials'!G87+'Base Financials'!G92 -> 11379 | I24: ='Base Financials'!I85+'Base Financials'!I87+'Base Financials'!I92 -> 3348 | J24: ='Base Financials'!J85+'Base Financials'!J87+'Base Financials'!J92 -> 3148 | K24: ='Base Financials'!K85+'Base Financials'!K87+'Base Financials'!K92 -> 3252 | L24: ='Base Financials'!L85+'Base Financials'!L87+'Base Financials'!L92 -> 3287 | M24: ='Base Financials'!M85+'Base Financials'!M87+'Base Financials'!M92 -> 2366 | N24: ='Base Financials'!N85+'Base Financials'!N87+'Base Financials'!N92 -> 2276 | O24: ='Base Financials'!O85+'Base Financials'!O87+'Base Financials'!O92 -> 2447 | P24: ='Base Financials'!P85+'Base Financials'!P87+'Base Financials'!P92 -> 2513 | ... W24: ='Base Financials'!W85+'Base Financials'!W87+'Base Financials'!W92 -> 2992 | Y24: =SUM(I24:L24) -> 13035 | Z24: =SUM(J24:M24) -> 12053 | AA24: =SUM(K24:N24) -> 11181 | AB24: =SUM(L24:O24) -> 10376 | AC24: =SUM(M24:P24) -> 9602 | AD24: =SUM(N24:Q24) -> 9787 | AE24: =SUM(O24:R24) -> 10080 | AF24: =SUM(P24:S24) -> 11245 | ... AI24: =SUM(S24:V24) -> 11946 | AK24: =SUM(AI24/AE24)-1 -> 0.18511905
B25: EBITDA | C25: =SUM(C21+C24) -> 35917 | D25: =SUM(D21+D24) -> 31248 | E25: =SUM(E21+E24) -> 15369 | F25: =SUM(F21+F24) -> 9695 | G25: =SUM(G21+G24) -> -299 | I25: =SUM(I21+I24) -> 8085.0484 | J25: =SUM(J21+J24) -> 2421.0163 | K25: =SUM(K21+K24) -> 3201.9821 | L25: =SUM(L21+L24) -> 1660.9532 | M25: =SUM(M21+M24) -> 898 | N25: =SUM(N21+N24) -> 1260 | O25: =SUM(O21+O24) -> 2439 | P25: =SUM(P21+P24) -> 5098 | ... W25: =SUM(W21+W24) -> 3675 | Y25: =SUM(Y21+Y24) -> 15369 | Z25: =SUM(Z21+Z24) -> 8181.9516 | AA25: =SUM(AA21+AA24) -> 7020.9353 | AB25: =SUM(AB21+AB24) -> 6257.9532 | AC25: =SUM(AC21+AC24) -> 9695 | AD25: =SUM(AD21+AD24) -> 10279 | AE25: =SUM(AE21+AE24) -> 9624 | AF25: =SUM(AF21+AF24) -> 1740 | ... AI25: =SUM(AI21+AI24) -> -176 | AK25: =SUM(AI25/AE25)-1 -> -1.0182876
B26: EBITDA Margin (%) | C26: =C25/C10 -> 0.46126087 | D26: =D25/D10 -> 0.39542417 | E26: =E25/E10 -> 0.24374346 | F26: =F25/F10 -> 0.17878218 | G26: =G25/G10 -> -0.0056307791 | I26: =I25/I10 -> 0.43122447 | J26: =J25/J10 -> 0.15829827 | K26: =K25/K10 -> 0.20707404 | L26: =L25/L10 -> 0.12259809 | M26: =M25/M10 -> 0.076653863 | N26: =N25/N10 -> 0.097304811 | O26: =O25/O10 -> 0.17227009 | P26: =P25/P10 -> 0.33091004 | ... W26: =W25/W10 -> 0.26917161 | Y26: =Y25/Y10 -> 0.24374346 | Z26: =Z25/Z10 -> 0.14605424 | AA26: =AA25/AA10 -> 0.13080473 | AB26: =AB25/AB10 -> 0.11949511 | AC26: =AC25/AC10 -> 0.17878218 | AD26: =AD25/AD10 -> 0.18608903 | AE26: =AE25/AE10 -> 0.1745977 | AF26: =AF25/AF10 -> 0.032075506 | ... AI26: =AI25/AI10 -> -0.0033163746 | AK26: =SUM(AI26-AE26)*10000 -> -1779.1408
B28: (+) Share-based Compensation | C28: ='Base Financials'!C88 -> 1854 | D28: ='Base Financials'!D88 -> 2036 | E28: ='Base Financials'!E88 -> 3128 | F28: ='Base Financials'!F88 -> 3229 | G28: ='Base Financials'!G88 -> 3410 | I28: ='Base Financials'!I88 -> 707 | J28: ='Base Financials'!J88 -> 892 | K28: ='Base Financials'!K88 -> 793 | L28: ='Base Financials'!L88 -> 736 | M28: ='Base Financials'!M88 -> 739 | N28: ='Base Financials'!N88 -> 922 | O28: ='Base Financials'!O88 -> 772 | P28: ='Base Financials'!P88 -> 796 | ... W28: ='Base Financials'!W88 -> 548 | Y28: =SUM(I28:L28) -> 3128 | Z28: =SUM(J28:M28) -> 3160 | AA28: =SUM(K28:N28) -> 3190 | AB28: =SUM(L28:O28) -> 3169 | AC28: =SUM(M28:P28) -> 3229 | AD28: =SUM(N28:Q28) -> 3669 | AE28: =SUM(O28:R28) -> 3527 | AF28: =SUM(P28:S28) -> 3555 | ... AI28: =SUM(S28:V28) -> 2799 | AK28: =SUM(AI28/AE28)-1 -> -0.20640771
B29: (+/-) Restructuring, asset impairment, and Other | C29: ='Base Financials'!C89 -> 0 | D29: ='Base Financials'!D89 -> 2626 | E29: ='Base Financials'!E89 -> 1074 | F29: ='Base Financials'!F89 -> -424 | G29: ='Base Financials'!G89 -> 3491 | I29: ='Base Financials'!I89 -> 17 | J29: ='Base Financials'!J89 -> 56 | K29: ='Base Financials'!K89 -> 592 | L29: ='Base Financials'!L89 -> 409 | M29: ='Base Financials'!M89 -> 55 | N29: ='Base Financials'!N89 -> 200 | O29: ='Base Financials'!O89 -> 463 | P29: ='Base Financials'!P89 -> -1142 | ... W29: ='Base Financials'!W89 -> -10 | Y29: =SUM(I29:L29) -> 1074 | Z29: =SUM(J29:M29) -> 1112 | AA29: =SUM(K29:N29) -> 1256 | AB29: =SUM(L29:O29) -> 1127 | AC29: =SUM(M29:P29) -> -424 | AD29: =SUM(N29:Q29) -> -131 | AE29: =SUM(O29:R29) -> 612 | AF29: =SUM(P29:S29) -> 2484 | ... AI29: =SUM(S29:V29) -> 2582 | AK29: =SUM(AI29/AE29)-1 -> 3.2189542
B30: (+/-) (Gains) losses on equity method investments | C30: ='Base Financials'!C94 -> -1757 | D30: ='Base Financials'!D94 -> -1458 | E30: ='Base Financials'!E94 -> -4254 | F30: ='Base Financials'!F94 -> -42 | G30: ='Base Financials'!G94 -> -246 | I30: ='Base Financials'!I94 -> -4325 | J30: ='Base Financials'!J94 -> 95 | K30: ='Base Financials'!K94 -> 155 | L30: ='Base Financials'!L94 -> -179 | M30: ='Base Financials'!M94 -> -167 | N30: ='Base Financials'!N94 -> 21 | O30: ='Base Financials'!O94 -> 193 | P30: ='Base Financials'!P94 -> -89 | ... W30: ='Base Financials'!W94 -> -221 | AE30: =SUM(O30:R30) -> 20 | AF30: =SUM(P30:S30) -> -14 | AG30: =SUM(Q30:T30) -> -246 | AH30: =SUM(R30:U30) -> 74 | AI30: =SUM(S30:V30) -> -552
B31: (+/-) (Gains) losses on divestitures | C31: ='Base Financials'!C96 -> -30 | D31: ='Base Financials'!D96 -> 0 | E31: ='Base Financials'!E96 -> -1059 | F31: ='Base Financials'!F96 -> 0 | G31: ='Base Financials'!G96 -> 0 | I31: ='Base Financials'!I96 -> -1121 | J31: ='Base Financials'!J96 -> 49 | K31: ='Base Financials'!K96 -> 0 | L31: ='Base Financials'!L96 -> 13 | M31: ='Base Financials'!M96 -> 0 | N31: ='Base Financials'!N96 -> 0 | O31: ='Base Financials'!O96 -> 0 | P31: ='Base Financials'!P96 -> 0 | ... W31: ='Base Financials'!W96 -> -5355 | AE31: =SUM(O31:R31) -> 0 | AF31: =SUM(P31:S31) -> 0 | AG31: =SUM(Q31:T31) -> 0 | AH31: =SUM(R31:U31) -> 0 | AI31: =SUM(S31:V31) -> 0
B32: Adj. EBITDA | C32: =+SUM(C25+SUM(C28:C31)) -> 35984 | D32: =+SUM(D25+SUM(D28:D31)) -> 34452 | E32: =+SUM(E25+SUM(E28:E31)) -> 14258 | F32: =+SUM(F25+SUM(F28:F31)) -> 12458 | G32: =+SUM(G25+SUM(G28:G31)) -> 6356 | I32: =+SUM(I25+SUM(I28:I31)) -> 3363.0484 | J32: =+SUM(J25+SUM(J28:J31)) -> 3513.0163 | K32: =+SUM(K25+SUM(K28:K31)) -> 4741.9821 | L32: =+SUM(L25+SUM(L28:L31)) -> 2639.9532 | M32: =+SUM(M25+SUM(M28:M31)) -> 1525 | N32: =+SUM(N25+SUM(N28:N31)) -> 2403 | O32: =+SUM(O25+SUM(O28:O31)) -> 3867 | P32: =+SUM(P25+SUM(P28:P31)) -> 4663 | ... W32: =+SUM(W25+SUM(W28:W31)) -> -1363 | Y32: =+SUM(Y25+SUM(Y28:Y29)) -> 19571 | Z32: =+SUM(Z25+SUM(Z28:Z29)) -> 12453.952 | AA32: =+SUM(AA25+SUM(AA28:AA29)) -> 11466.935 | AB32: =+SUM(AB25+SUM(AB28:AB29)) -> 10553.953 | AC32: =+SUM(AC25+SUM(AC28:AC29)) -> 12500 | AD32: =+SUM(AD25+SUM(AD28:AD29)) -> 13817 | AE32: =+SUM(AE25+SUM(AE28:AE31)) -> 13783 | AF32: =+SUM(AF25+SUM(AF28:AF31)) -> 7765 | AG32: =+SUM(AG25+SUM(AG28:AG31)) -> 6356 | AH32: =+SUM(AH25+SUM(AH28:AH31)) -> 6724 | AI32: =+SUM(AI25+SUM(AI28:AI31)) -> 4653 | AK32: =SUM(AI32/AE32)-1 -> -0.66241022
B33: Adj. EBITDA Margin (%) | C33: =C32/C10 -> 0.46212131 | D33: =D32/D10 -> 0.43596882 | E33: =E32/E10 -> 0.22612364 | F33: =F32/F10 -> 0.22973372 | G33: =G32/G10 -> 0.11969643 | I33: =I32/I10 -> 0.17937168 | J33: =J32/J10 -> 0.22969874 | K33: =K32/K10 -> 0.30666673 | L33: =L32/L10 -> 0.19485993 | M33: =M32/M10 -> 0.13017499 | N33: =N32/N10 -> 0.18557418 | O33: =O32/O10 -> 0.2731318 | P33: =P32/P10 -> 0.30267428 | ... W33: =W32/W10 -> -0.099831539 | Y33: =Y32/Y10 -> 0.31038475 | Z33: =Z32/Z10 -> 0.22231279 | AA33: =AA32/AA10 -> 0.21363669 | AB33: =AB32/AB10 -> 0.20152688 | AC33: =AC32/AC10 -> 0.23050822 | AD33: =AD32/AD10 -> 0.2501403 | AE33: =AE32/AE10 -> 0.25004989 | AF33: =AF32/AF10 -> 0.14314156 | ... AI33: =AI32/AI10 -> 0.087676653 | AK33: =SUM(AI33-AE33)*10000 -> -1623.7324
B35: (-) Capital Expenditures | C35: ='Base Financials'!C112 -> -14259 | D35: ='Base Financials'!D112 -> -18733 | E35: ='Base Financials'!E112 -> -24844 | F35: ='Base Financials'!F112 -> -25750 | G35: ='Base Financials'!G112 -> -23944 | I35: ='Base Financials'!I112 -> -4604 | J35: ='Base Financials'!J112 -> -7242 | K35: ='Base Financials'!K112 -> -7299 | L35: ='Base Financials'!L112 -> -5699 | M35: ='Base Financials'!M112 -> -7413 | N35: ='Base Financials'!N112 -> -5888 | O35: ='Base Financials'!O112 -> -5753 | P35: ='Base Financials'!P112 -> -6696 | ... W35: ='Base Financials'!W112 -> -2425 | Y35: =SUM(I35:L35) -> -24844 | Z35: =SUM(J35:M35) -> -27653 | AA35: =SUM(K35:N35) -> -26299 | AB35: =SUM(L35:O35) -> -24753 | AC35: =SUM(M35:P35) -> -25750 | AD35: =SUM(N35:Q35) -> -24307 | AE35: =SUM(O35:R35) -> -24101 | AF35: =SUM(P35:S35) -> -24806 | ... AI35: =SUM(S35:V35) -> -21025 | AK35: =SUM(AI35/AE35)-1 -> -0.12762956
B36: (-) Cash Interest | C36: =-('Base Financials'!C147) -> -594 | D36: =-('Base Financials'!D147) -> -545 | E36: =-('Base Financials'!E147) -> -459 | F36: =-('Base Financials'!F147) -> -613 | G36: =-('Base Financials'!G147) -> -987 | I36: =-('Base Financials'!I147) -> -177 | J36: =-('Base Financials'!J147) -> -37 | K36: =-('Base Financials'!K147) -> -101 | L36: =-('Base Financials'!L147) -> -144 | M36: =-('Base Financials'!M147) -> -239 | N36: =-('Base Financials'!N147) -> 78 | O36: =-('Base Financials'!O147) -> -502 | P36: =-('Base Financials'!P147) -> 50 | ... W36: =-('Base Financials'!W147) -> 121 | Y36: =SUM(I36:L36) -> -459 | Z36: =SUM(J36:M36) -> -521 | AA36: =SUM(K36:N36) -> -406 | AB36: =SUM(L36:O36) -> -807 | AC36: =SUM(M36:P36) -> -613 | AD36: =SUM(N36:Q36) -> -914 | AE36: =SUM(O36:R36) -> -940 | AF36: =SUM(P36:S36) -> -1049 | ... AI36: =SUM(S36:V36) -> -1013 | AK36: =SUM(AI36/AE36)-1 -> 0.077659574
B37: (-) Cash Taxes | C37: =-('Base Financials'!C148) -> -2436 | D37: =-('Base Financials'!D148) -> -2263 | E37: =-('Base Financials'!E148) -> -4282 | F37: =-('Base Financials'!F148) -> -2621 | G37: =-('Base Financials'!G148) -> -2202 | I37: =-('Base Financials'!I148) -> -335 | J37: =-('Base Financials'!J148) -> -2991 | K37: =-('Base Financials'!K148) -> -634 | L37: =-('Base Financials'!L148) -> -322 | M37: =-('Base Financials'!M148) -> -267 | N37: =-('Base Financials'!N148) -> -1253 | O37: =-('Base Financials'!O148) -> -129 | P37: =-('Base Financials'!P148) -> -972 | ... W37: =-('Base Financials'!W148) -> -1572 | Y37: =SUM(I37:L37) -> -4282 | Z37: =SUM(J37:M37) -> -4214 | AA37: =SUM(K37:N37) -> -2476 | AB37: =SUM(L37:O37) -> -1971 | AC37: =SUM(M37:P37) -> -2621 | AD37: =SUM(N37:Q37) -> -2669 | AE37: =SUM(O37:R37) -> -2656 | AF37: =SUM(P37:S37) -> -2852 | ... AI37: =SUM(S37:V37) -> -2440 | AK37: =SUM(AI37/AE37)-1 -> -0.081325301
B38: (-) Mandatory Amortization | C38: 0 | D38: 0 | E38: 0 | F38: 0 | G38: 0 | I38: 0 | J38: 0 | K38: 0 | L38: 0 | M38: 0 | N38: 0 | O38: 0 | P38: 0 | Q38: 0 | R38: 0 | S38: 0 | T38: 0 | U38: 0 | V38: 0 | W38: 0 | Y38: =SUM(I38:L38) -> 0 | Z38: =SUM(J38:M38) -> 0 | AA38: =SUM(K38:N38) -> 0 | AB38: =SUM(L38:O38) -> 0 | AC38: =SUM(M38:P38) -> 0 | AD38: =SUM(N38:Q38) -> 0 | AE38: =SUM(O38:R38) -> 0 | AF38: =SUM(P38:S38) -> 0 | ... AI38: =SUM(S38:V38) -> 0 | AK38: =SUM(AI38/AE38)-1 -> #DIV/0!
