Workbook

Sheet Historical Financials
B2: Talen Energy Corporation (NASDAQ: TLN)
B3: Historical Financials
B4: ($ In Millions, except EPS)
A6: X | B6: Income Statement | D6: FYE | I6: Quarterly | P6: LTM | V6: Variance
B7: Fiscal Period | C7: 2022 | D7: 2023 | E7: 2024 | G7: 1Q24 | H7: 2Q24 | I7: 3Q24 | J7: 4Q24 | K7: 1Q25 | L7: 2Q25 | M7: 3Q25 | O7: =H7 -> 2Q24 | P7: =I7 -> 3Q24 | Q7: =J7 -> 4Q24 | R7: =K7 -> 1Q25 | S7: =L7 -> 2Q25 | T7: =M7 -> 3Q25
B8: Fiscal Period End Date | C8: XXX | D8: XXX | E8: XXX | G8: XXX | H8: XXX | I8: XXX | J8: =E8 -> XXX | K8: XXX | L8: XXX | M8: XXX | O8: =H8 -> XXX | P8: =I8 -> XXX | Q8: =J8 -> XXX | R8: =K8 -> XXX | S8: =L8 -> XXX | T8: =M8 -> XXX
B10: Consolidated Revenue | E10: 2115 | G10: 509 | H10: 489 | I10: 650 | J10: =SUM(E10-SUM(G10:I10)) -> 467 | K10: 390 | L10: 630 | M10: 812 | O10: =SUM(G10:G10) -> 509 | P10: =SUM(G10:H10) -> 998 | Q10: =SUM(G10:I10) -> 1648 | R10: =SUM(G10:J10) -> 2115 | S10: =SUM(H10:K10) -> 1996 | T10: =SUM(I10:L10) -> 2137 | V10: =SUM(T10/P10)-1 -> 1.1412826
B11: Total Revenue | C11: =+SUM(C10:C10) -> 0 | D11: =+SUM(D10:D10) -> 0 | E11: =+SUM(E10:E10) -> 2115 | G11: =+SUM(G10:G10) -> 509 | H11: =+SUM(H10:H10) -> 489 | I11: =+SUM(I10:I10) -> 650 | J11: =+SUM(J10:J10) -> 467 | K11: =+SUM(K10:K10) -> 390 | L11: =+SUM(L10:L10) -> 630 | M11: =+SUM(M10:M10) -> 812 | O11: =+SUM(O10:O10) -> 509 | P11: =+SUM(P10:P10) -> 998 | Q11: =+SUM(Q10:Q10) -> 1648 | R11: =+SUM(R10:R10) -> 2115 | S11: =+SUM(S10:S10) -> 1996 | T11: =+SUM(T10:T10) -> 2137 | V11: =SUM(T11/P11)-1 -> 1.1412826
B13: Fuel & Energy Purchases | E13: -694 | G13: -150 | H13: -163 | I13: -222 | J13: =SUM(E13-SUM(G13:I13)) -> -159 | K13: -268 | L13: -150 | M13: -259 | O13: =SUM(G13:G13) -> -150 | P13: =SUM(G13:H13) -> -313 | Q13: =SUM(G13:I13) -> -535 | R13: =SUM(G13:J13) -> -694 | S13: =SUM(H13:K13) -> -812 | T13: =SUM(I13:L13) -> -799 | V13: =SUM(T13/P13)-1 -> 1.5527157
B14: Nuclear Fuel Amortization | E14: -123 | G14: -35 | H14: -28 | I14: -30 | J14: =SUM(E14-SUM(G14:I14)) -> -30 | K14: -26 | L14: -18 | M14: -27 | O14: =SUM(G14:G14) -> -35 | P14: =SUM(G14:H14) -> -63 | Q14: =SUM(G14:I14) -> -93 | R14: =SUM(G14:J14) -> -123 | S14: =SUM(H14:K14) -> -114 | T14: =SUM(I14:L14) -> -104 | V14: =SUM(T14/P14)-1 -> 0.65079365
B15: G/L on Derivatives | E15: 20 | G15: -27 | H15: 15 | I15: 7 | J15: =SUM(E15-SUM(G15:I15)) -> 25 | K15: 59 | L15: -84 | M15: -6 | O15: =SUM(G15:G15) -> -27 | P15: =SUM(G15:H15) -> -12 | Q15: =SUM(G15:I15) -> -5 | R15: =SUM(G15:J15) -> 20 | S15: =SUM(H15:K15) -> 106 | T15: =SUM(I15:L15) -> 7 | V15: =SUM(T15/P15)-1 -> -1.5833333
B16: Gross Profit | C16: =+SUM(C11+SUM(C13:C15)) -> 0 | D16: =+SUM(D11+SUM(D13:D15)) -> 0 | E16: =+SUM(E11+SUM(E13:E15)) -> 1318 | G16: =+SUM(G11+SUM(G13:G15)) -> 297 | H16: =+SUM(H11+SUM(H13:H15)) -> 313 | I16: =+SUM(I11+SUM(I13:I15)) -> 405 | J16: =+SUM(J11+SUM(J13:J15)) -> 303 | K16: =+SUM(K11+SUM(K13:K15)) -> 155 | L16: =+SUM(L11+SUM(L13:L15)) -> 378 | M16: =+SUM(M11+SUM(M13:M15)) -> 520 | O16: =+SUM(O11+SUM(O13:O15)) -> 297 | P16: =+SUM(P11+SUM(P13:P15)) -> 610 | Q16: =+SUM(Q11+SUM(Q13:Q15)) -> 1015 | R16: =+SUM(R11+SUM(R13:R15)) -> 1318 | S16: =+SUM(S11+SUM(S13:S15)) -> 1176 | T16: =+SUM(T11+SUM(T13:T15)) -> 1241 | V16: =SUM(T16/P16)-1 -> 1.0344262
B17: Gross Margin (%) | C17: =C16/C11 -> #DIV/0! | D17: =D16/D11 -> #DIV/0! | E17: =E16/E11 -> 0.62316785 | G17: =G16/G11 -> 0.58349705 | H17: =H16/H11 -> 0.6400818 | I17: =I16/I11 -> 0.62307692 | J17: =J16/J11 -> 0.64882227 | K17: =K16/K11 -> 0.3974359 | L17: =L16/L11 -> 0.6 | M17: =M16/M11 -> 0.64039409 | O17: =O16/O11 -> 0.58349705 | P17: =P16/P11 -> 0.61122244 | Q17: =Q16/Q11 -> 0.61589806 | R17: =R16/R11 -> 0.62316785 | S17: =S16/S11 -> 0.58917836 | T17: =T16/T11 -> 0.58072064 | V17: =SUM(T17-P17)*1000 -> -30.501808
B19: Operations Maintenance & Development | E19: -592 | G19: -154 | H19: -164 | I19: -127 | J19: =SUM(E19-SUM(G19:I19)) -> -147 | K19: -146 | L19: -192 | M19: -131 | O19: =SUM(G19:G19) -> -154 | P19: =SUM(G19:H19) -> -318 | Q19: =SUM(G19:I19) -> -445 | R19: =SUM(G19:J19) -> -592 | S19: =SUM(H19:K19) -> -584 | T19: =SUM(I19:L19) -> -612 | V19: =SUM(T19/P19)-1 -> 0.9245283
B20: G&A | E20: -163 | G20: -43 | H20: -40 | I20: -38 | J20: =SUM(E20-SUM(G20:I20)) -> -42 | K20: -34 | L20: -41 | M20: -38 | O20: =SUM(G20:G20) -> -43 | P20: =SUM(G20:H20) -> -83 | Q20: =SUM(G20:I20) -> -121 | R20: =SUM(G20:J20) -> -163 | S20: =SUM(H20:K20) -> -154 | T20: =SUM(I20:L20) -> -155 | V20: =SUM(T20/P20)-1 -> 0.86746988
B21: Depreciation, Ammortization & Accretion | E21: -298 | G21: -75 | H21: -75 | I21: -75 | J21: =SUM(E21-SUM(G21:I21)) -> -73 | K21: -74 | L21: -70 | M21: -61 | O21: =SUM(G21:G21) -> -75 | P21: =SUM(G21:H21) -> -150 | Q21: =SUM(G21:I21) -> -225 | R21: =SUM(G21:J21) -> -298 | S21: =SUM(H21:K21) -> -297 | T21: =SUM(I21:L21) -> -292 | V21: =SUM(T21/P21)-1 -> 0.94666667
B22: Impairment | E22: -1 | G22: 0 | H22: 0 | I22: 0 | J22: =SUM(E22-SUM(G22:I22)) -> -1 | K22: 0 | L22: 0 | M22: 0 | O22: =SUM(G22:G22) -> 0 | P22: =SUM(G22:H22) -> 0 | Q22: =SUM(G22:I22) -> 0 | R22: =SUM(G22:J22) -> -1 | S22: =SUM(H22:K22) -> -1 | T22: =SUM(I22:L22) -> -1 | V22: =SUM(T22/P22)-1 -> #DIV/0!
B23: Operational Restructuring | E23: 0 | G23: 0 | H23: 0 | I23: 0 | J23: =SUM(E23-SUM(G23:I23)) -> 0 | K23: 0 | L23: 0 | M23: 0 | O23: =SUM(G23:G23) -> 0 | P23: =SUM(G23:H23) -> 0 | Q23: =SUM(G23:I23) -> 0 | R23: =SUM(G23:J23) -> 0 | S23: =SUM(H23:K23) -> 0 | T23: =SUM(I23:L23) -> 0 | V23: =SUM(T23/P23)-1 -> #DIV/0!
B24: Operating Profit | C24: =+SUM(C16+SUM(C19:C23)) -> 0 | D24: =+SUM(D16+SUM(D19:D23)) -> 0 | E24: =+SUM(E16+SUM(E19:E23)) -> 264 | G24: =+SUM(G16+SUM(G19:G23)) -> 25 | H24: =+SUM(H16+SUM(H19:H23)) -> 34 | I24: =+SUM(I16+SUM(I19:I23)) -> 165 | J24: =+SUM(J16+SUM(J19:J23)) -> 40 | K24: =+SUM(K16+SUM(K19:K23)) -> -99 | L24: =+SUM(L16+SUM(L19:L23)) -> 75 | M24: =+SUM(M16+SUM(M19:M23)) -> 290 | O24: =+SUM(O16+SUM(O19:O23)) -> 25 | P24: =+SUM(P16+SUM(P19:P23)) -> 59 | Q24: =+SUM(Q16+SUM(Q19:Q23)) -> 224 | R24: =+SUM(R16+SUM(R19:R23)) -> 264 | S24: =+SUM(S16+SUM(S19:S23)) -> 140 | T24: =+SUM(T16+SUM(T19:T23)) -> 181 | V24: =SUM(T24/P24)-1 -> 2.0677966
B25: Operating Margin (%) | C25: =C24/C11 -> #DIV/0! | D25: =D24/D11 -> #DIV/0! | E25: =E24/E11 -> 0.1248227 | G25: =G24/G11 -> 0.049115914 | H25: =H24/H11 -> 0.069529652 | I25: =I24/I11 -> 0.25384615 | J25: =J24/J11 -> 0.085653105 | K25: =K24/K11 -> -0.25384615 | L25: =L24/L11 -> 0.11904762 | M25: =M24/M11 -> 0.35714286 | O25: =O24/O11 -> 0.049115914 | P25: =P24/P11 -> 0.059118236 | Q25: =Q24/Q11 -> 0.13592233 | R25: =R24/R11 -> 0.1248227 | S25: =S24/S11 -> 0.070140281 | T25: =T24/T11 -> 0.084698175 | V25: =SUM(T25-P25)*1000 -> 25.579939
B27: Nuclear Decommissioning Fund Income | E27: 178 | G27: 75 | H27: 27 | I27: 67 | J27: 9 | K27: -12 | L27: 80 | M27: 81 | O27: =SUM(G27:G27) -> 75 | P27: =SUM(G27:H27) -> 102 | Q27: =SUM(G27:I27) -> 169 | R27: =SUM(G27:J27) -> 178 | S27: =SUM(H27:K27) -> 91 | T27: =SUM(I27:L27) -> 144 | V27: =SUM(T27/P27)-1 -> 0.41176471
B28: Interest Expenses | E28: -238 | G28: -59 | H28: -62 | I28: -66 | J28: -51 | K28: -74 | L28: -62 | M28: -67 | O28: =SUM(G28:G28) -> -59 | P28: =SUM(G28:H28) -> -121 | Q28: =SUM(G28:I28) -> -187 | R28: =SUM(G28:J28) -> -238 | S28: =SUM(H28:K28) -> -253 | T28: =SUM(I28:L28) -> -253 | V28: =SUM(T28/P28)-1 -> 1.0909091
B29: Reorganization Income | E29: 0 | G29: 324 | H29: 561 | I29: 0 | J29: -885 | K29: 2 | L29: 9 | M29: 25 | O29: =SUM(G29:G29) -> 324 | P29: =SUM(G29:H29) -> 885 | Q29: =SUM(G29:I29) -> 885 | R29: =SUM(G29:J29) -> 0 | S29: =SUM(H29:K29) -> -322 | T29: =SUM(I29:L29) -> -874 | V29: =SUM(T29/P29)-1 -> -1.9875706
B30: G/L on Sale of Income | E30: 884 | G30: 0 | H30: 0 | I30: 0 | J30: 884 | K30: 0 | L30: 0 | M30: 0 | O30: =SUM(G30:G30) -> 0 | P30: =SUM(G30:H30) -> 0 | Q30: =SUM(G30:I30) -> 0 | R30: =SUM(G30:J30) -> 884 | S30: =SUM(H30:K30) -> 884 | T30: =SUM(I30:L30) -> 884 | V30: =SUM(T30/P30)-1 -> #DIV/0!
B31: Other Income | E31: 61 | G31: 23 | H31: 17 | I31: 20 | J31: 1 | K31: 3 | L31: 4 | M31: 2 | O31: =SUM(G31:G31) -> 23 | P31: =SUM(G31:H31) -> 40 | Q31: =SUM(G31:I31) -> 60 | R31: =SUM(G31:J31) -> 61 | S31: =SUM(H31:K31) -> 41 | T31: =SUM(I31:L31) -> 28 | V31: =SUM(T31/P31)-1 -> -0.3
B32: Earnings before Taxes | C32: =SUM(C27:C31)+C24 -> 0 | D32: =SUM(D27:D31)+D24 -> 0 | E32: =SUM(E27:E31)+E24 -> 1149 | G32: =SUM(G27:G31)+G24 -> 388 | H32: =SUM(H27:H31)+H24 -> 577 | I32: =SUM(I27:I31)+I24 -> 186 | J32: =SUM(J27:J31)+J24 -> -2 | K32: =SUM(K27:K31)+K24 -> -180 | L32: =SUM(L27:L31)+L24 -> 106 | M32: =SUM(M27:M31)+M24 -> 331 | O32: =SUM(O27:O31)+O24 -> 388 | P32: =SUM(P27:P31)+P24 -> 965 | Q32: =SUM(Q27:Q31)+Q24 -> 1151 | R32: =SUM(R27:R31)+R24 -> 1149 | S32: =SUM(S27:S31)+S24 -> 581 | T32: =SUM(T27:T31)+T24 -> 110 | V32: =SUM(T32/P32)-1 -> -0.88601036
B33: EBT Margin (%) | C33: =C32/C11 -> #DIV/0! | D33: =D32/D11 -> #DIV/0! | E33: =E32/E11 -> 0.54326241 | G33: =G32/G11 -> 0.76227898 | H33: =H32/H11 -> 1.1799591 | I33: =I32/I11 -> 0.28615385 | J33: =J32/J11 -> -0.0042826552 | K33: =K32/K11 -> -0.46153846 | L33: =L32/L11 -> 0.16825397 | M33: =M32/M11 -> 0.40763547 | O33: =O32/O11 -> 0.76227898 | P33: =P32/P11 -> 0.96693387 | Q33: =Q32/Q11 -> 0.69842233 | R33: =R32/R11 -> 0.54326241 | S33: =S32/S11 -> 0.29108216 | T33: =T32/T11 -> 0.051474029 | V33: =SUM(T33-P33)*1000 -> -915.45984
B35: Income tax expense | E35: -98 | G35: -69 | H35: -112 | I35: -10 | J35: 93 | K35: 52 | L35: -25 | M35: -97 | O35: =SUM(G35:G35) -> -69 | P35: =SUM(G35:H35) -> -181 | Q35: =SUM(G35:I35) -> -191 | R35: =SUM(G35:J35) -> -98 | S35: =SUM(H35:K35) -> 23 | T35: =SUM(I35:L35) -> 110 | V35: =SUM(T35/P35)-1 -> -1.6077348
B36: Net loss | C36: =SUM(C32+SUM(C35:C35)) -> 0 | D36: =SUM(D32+SUM(D35:D35)) -> 0 | E36: =SUM(E32+SUM(E35:E35)) -> 1051 | G36: =SUM(G32+SUM(G35:G35)) -> 319 | H36: =SUM(H32+SUM(H35:H35)) -> 465 | I36: =SUM(I32+SUM(I35:I35)) -> 176 | J36: =SUM(J32+SUM(J35:J35)) -> 91 | K36: =SUM(K32+SUM(K35:K35)) -> -128 | L36: =SUM(L32+SUM(L35:L35)) -> 81 | M36: =SUM(M32+SUM(M35:M35)) -> 234 | O36: =SUM(O32+SUM(O35:O35)) -> 319 | P36: =SUM(P32+SUM(P35:P35)) -> 784 | Q36: =SUM(Q32+SUM(Q35:Q35)) -> 960 | R36: =SUM(R32+SUM(R35:R35)) -> 1051 | S36: =SUM(S32+SUM(S35:S35)) -> 604 | T36: =SUM(T32+SUM(T35:T35)) -> 220 | V36: =SUM(T36/P36)-1 -> -0.71938776
B37: Net Margin (%) | C37: =C36/C11 -> #DIV/0! | D37: =D36/D11 -> #DIV/0! | E37: =E36/E11 -> 0.49692671 | G37: =G36/G11 -> 0.62671906 | H37: =H36/H11 -> 0.95092025 | I37: =I36/I11 -> 0.27076923 | J37: =J36/J11 -> 0.19486081 | K37: =K36/K11 -> -0.32820513 | L37: =L36/L11 -> 0.12857143 | M37: =M36/M11 -> 0.28817734 | O37: =O36/O11 -> 0.62671906 | P37: =P36/P11 -> 0.78557114 | Q37: =Q36/Q11 -> 0.58252427 | R37: =R36/R11 -> 0.49692671 | S37: =S36/S11 -> 0.30260521 | T37: =T36/T11 -> 0.10294806 | V37: =SUM(T37-P37)*1000 -> -682.62308
B39: Basic shares | J39: =E39 -> 0 | O39: =G39 -> 0 | P39: =H39 -> 0 | Q39: =I39 -> 0 | R39: =J39 -> 0 | S39: =K39 -> 0 | T39: =L39 -> 0 | V39: =SUM(T39/P39)-1 -> #DIV/0!
B40: Basic EPS | C40: =C36/C39 -> #DIV/0! | D40: =D36/D39 -> #DIV/0! | E40: =E36/E39 -> #DIV/0! | G40: =G36/G39 -> #DIV/0! | H40: =H36/H39 -> #DIV/0! | I40: =I36/I39 -> #DIV/0! | J40: =J36/J39 -> #DIV/0! | K40: =K36/K39 -> #DIV/0! | L40: =L36/L39 -> #DIV/0! | M40: =M36/M39 -> #DIV/0! | O40: =O36/O39 -> #DIV/0! | P40: =P36/P39 -> #DIV/0! | Q40: =Q36/Q39 -> #DIV/0! | R40: =R36/R39 -> #DIV/0! | S40: =S36/S39 -> #DIV/0! | T40: =T36/T39 -> #DIV/0! | V40: =SUM(T40/P40)-1 -> #DIV/0!
B42: Fully Diluted Shares | J42: =E42 -> 0 | O42: =G42 -> 0 | P42: =H42 -> 0 | Q42: =I42 -> 0 | R42: =J42 -> 0 | S42: =K42 -> 0 | T42: =L42 -> 0 | V42: =SUM(T42/P42)-1 -> #DIV/0!
B43: Diluted EPS | C43: =C36/C42 -> #DIV/0! | D43: =D36/D42 -> #DIV/0! | E43: =E36/E42 -> #DIV/0! | G43: =G36/G42 -> #DIV/0! | H43: =H36/H42 -> #DIV/0! | I43: =I36/I42 -> #DIV/0! | J43: =J36/J42 -> #DIV/0! | K43: =K36/K42 -> #DIV/0! | L43: =L36/L42 -> #DIV/0! | M43: =M36/M42 -> #DIV/0! | O43: =O36/O42 -> #DIV/0! | P43: =P36/P42 -> #DIV/0! | Q43: =Q36/Q42 -> #DIV/0! | R43: =R36/R42 -> #DIV/0! | S43: =S36/S42 -> #DIV/0! | T43: =T36/T42 -> #DIV/0! | V43: =SUM(T43/P43)-1 -> #DIV/0!
A45: X | B45: Balance Sheet | C45: FYE | I45: Quarterly | P45: LTM | V45: Variance
B46: =B7 -> Fiscal Period | C46: =C7 -> 2022 | D46: =D7 -> 2023 | E46: =E7 -> 2024 | G46: =G7 -> 1Q24 | H46: =H7 -> 2Q24 | I46: =I7 -> 3Q24 | J46: =J7 -> 4Q24 | K46: =K7 -> 1Q25 | L46: =L7 -> 2Q25 | M46: =M7 -> 3Q25 | O46: =O7 -> 2Q24 | P46: =P7 -> 3Q24 | Q46: =Q7 -> 4Q24 | R46: =R7 -> 1Q25 | S46: =S7 -> 2Q25 | T46: =T7 -> 3Q25
B47: =B8 -> Fiscal Period End Date | C47: =C8 -> XXX | D47: =D8 -> XXX | E47: =E8 -> XXX | G47: =G8 -> XXX | H47: =H8 -> XXX | I47: =I8 -> XXX | J47: =J8 -> XXX | K47: =K8 -> XXX | L47: =L8 -> XXX | M47: =M8 -> XXX | O47: =O8 -> XXX | P47: =P8 -> XXX | Q47: =Q8 -> XXX | R47: =R8 -> XXX | S47: =S8 -> XXX | T47: =T8 -> XXX
B49: Current Assets
B50: Cash & CEs | E50: 328 | J50: =E50 -> 328 | K50: 295 | L50: 122 | M50: 497 | O50: =G50 -> 0 | P50: =H50 -> 0 | Q50: =I50 -> 0 | R50: =J50 -> 328 | S50: =K50 -> 295 | T50: =L50 -> 122 | V50: =SUM(T50/P50)-1 -> #DIV/0!
B51: Restricted Cash | E51: 37 | J51: =E51 -> 37 | K51: 25 | L51: 13 | M51: 0 | O51: =G51 -> 0 | P51: =H51 -> 0 | Q51: =I51 -> 0 | R51: =J51 -> 37 | S51: =K51 -> 25 | T51: =L51 -> 13 | V51: =SUM(T51/P51)-1 -> #DIV/0!
...

Sheet Revenue Drivers
B2: ='Historical Financials'!B2 -> Talen Energy Corporation (NASDAQ: TLN) | C2: FYE | I2: Quarterly | P2: LTM
B3: Segment Anaysis | C3: ='Historical Financials'!C7 -> 2022 | D3: ='Historical Financials'!D7 -> 2023 | E3: ='Historical Financials'!E7 -> 2024 | G3: ='Historical Financials'!G7 -> 1Q24 | H3: ='Historical Financials'!H7 -> 2Q24 | I3: ='Historical Financials'!I7 -> 3Q24 | J3: ='Historical Financials'!J7 -> 4Q24 | K3: ='Historical Financials'!K7 -> 1Q25 | L3: ='Historical Financials'!L7 -> 2Q25 | M3: ='Historical Financials'!M7 -> 3Q25 | O3: =G3 -> 1Q24 | P3: =H3 -> 2Q24 | Q3: =I3 -> 3Q24 | R3: =J3 -> 4Q24 | S3: =K3 -> 1Q25 | T3: =L3 -> 2Q25
B4: ($ In Millions) | C4: ='Historical Financials'!C8 -> XXX | D4: ='Historical Financials'!D8 -> XXX | E4: ='Historical Financials'!E8 -> XXX | G4: ='Historical Financials'!G8 -> XXX | H4: ='Historical Financials'!H8 -> XXX | I4: ='Historical Financials'!I8 -> XXX | J4: ='Historical Financials'!J8 -> XXX | K4: ='Historical Financials'!K8 -> XXX | L4: ='Historical Financials'!L8 -> XXX | M4: ='Historical Financials'!M8 -> XXX | O4: =G4 -> XXX | P4: =H4 -> XXX | Q4: =I4 -> XXX | R4: =J4 -> XXX | S4: =K4 -> XXX | T4: =L4 -> XXX
A6: X | B6: Revenue by reportable segment
A8: X | B8: Revenue Segment Anaysis
B9: Customer Contract Revenues | C9: =C24 -> 0 | D9: =D24 -> 0 | E9: =E24 -> 1574 | G9: =G24 -> 416 | H9: =H24 -> 346 | I9: =I24 -> 459 | J9: =J24 -> 353 | K9: =K24 -> 654 | L9: =L24 -> 409 | M9: =M24 -> 697 | O9: =SUM(G9:G9) -> 416 | P9: =SUM(G9:H9) -> 762 | Q9: =SUM(G9:I9) -> 1221 | R9: =SUM(G9:J9) -> 1574 | S9: =SUM(H9:K9) -> 1812 | T9: =SUM(I9:L9) -> 1875
B10: Realized / Unrealized on Derivatives | E10: 307 | G10: 57 | H10: 100 | I10: 119 | J10: =SUM(E10-SUM(G10:I10)) -> 31 | K10: -268 | L10: 218 | M10: 115 | O10: =SUM(G10:G10) -> 57 | P10: =SUM(G10:H10) -> 157 | Q10: =SUM(G10:I10) -> 276 | R10: =SUM(G10:J10) -> 307 | S10: =SUM(H10:K10) -> -18 | T10: =SUM(I10:L10) -> 100
B11: Nuclear PTC and Other Revenues | E11: 234 | G11: 36 | H11: 43 | I11: 72 | J11: =SUM(E11-SUM(G11:I11)) -> 83 | K11: 4 | L11: 3 | M11: 0 | O11: =SUM(G11:G11) -> 36 | P11: =SUM(G11:H11) -> 79 | Q11: =SUM(G11:I11) -> 151 | R11: =SUM(G11:J11) -> 234 | S11: =SUM(H11:K11) -> 202 | T11: =SUM(I11:L11) -> 162
B12: Total Net Revenue | C12: =SUM(C9:C11) -> 0 | D12: =SUM(D9:D11) -> 0 | E12: =SUM(E9:E11) -> 2115 | G12: =SUM(G9:G11) -> 509 | H12: =SUM(H9:H11) -> 489 | I12: =SUM(I9:I11) -> 650 | J12: =SUM(J9:J11) -> 467 | K12: =SUM(K9:K11) -> 390 | L12: =SUM(L9:L11) -> 630 | M12: =SUM(M9:M11) -> 812 | O12: =SUM(O9:O11) -> 509 | P12: =SUM(P9:P11) -> 998 | Q12: =SUM(Q9:Q11) -> 1648 | R12: =SUM(R9:R11) -> 2115 | S12: =SUM(S9:S11) -> 1996 | T12: =SUM(T9:T11) -> 2137
B13: Balance Check | C13: =+C12-'Historical Financials'!C11 -> 0 | D13: =+D12-'Historical Financials'!D11 -> 0 | E13: =+E12-'Historical Financials'!E11 -> 0 | G13: =+G12-'Historical Financials'!G11 -> 0 | H13: =+H12-'Historical Financials'!H11 -> 0 | I13: =+I12-'Historical Financials'!I11 -> 0 | J13: =+J12-'Historical Financials'!J11 -> 0 | K13: =+K12-'Historical Financials'!K11 -> 0 | L13: =+L12-'Historical Financials'!L11 -> 0 | M13: =+M12-'Historical Financials'!M11 -> 0 | O13: =+O12-'Historical Financials'!O11 -> 0 | P13: =+P12-'Historical Financials'!P11 -> 0 | Q13: =+Q12-'Historical Financials'!Q11 -> 0 | R13: =+R12-'Historical Financials'!R11 -> 0 | S13: =+S12-'Historical Financials'!S11 -> 0 | T13: =+T12-'Historical Financials'!T11 -> 0
B15: =B9&"(%)" -> Customer Contract Revenues (%) | C15: =SUM(C9/C$12) -> #DIV/0! | D15: =SUM(D9/D$12) -> #DIV/0! | E15: =SUM(E9/E$12) -> 0.74420804 | G15: =SUM(G9/G$12) -> 0.8172888 | H15: =SUM(H9/H$12) -> 0.70756646 | I15: =SUM(I9/I$12) -> 0.70615385 | J15: =SUM(J9/J$12) -> 0.75588865 | K15: =SUM(K9/K$12) -> 1.6769231 | L15: =SUM(L9/L$12) -> 0.64920635 | M15: =SUM(M9/M$12) -> 0.85837438 | O15: =H15 -> 0.70756646 | P15: =I15 -> 0.70615385 | Q15: =J15 -> 0.75588865 | R15: =K15 -> 1.6769231 | S15: =L15 -> 0.64920635 | T15: =#REF! -> #REF!
B16: =B10&"(%)" -> Realized / Unrealized on Derivatives(%) | C16: =SUM(C10/C$12) -> #DIV/0! | D16: =SUM(D10/D$12) -> #DIV/0! | E16: =SUM(E10/E$12) -> 0.14515366 | G16: =SUM(G10/G$12) -> 0.11198428 | H16: =SUM(H10/H$12) -> 0.20449898 | I16: =SUM(I10/I$12) -> 0.18307692 | J16: =SUM(J10/J$12) -> 0.066381156 | K16: =SUM(K10/K$12) -> -0.68717949 | L16: =SUM(L10/L$12) -> 0.34603175 | M16: =SUM(M10/M$12) -> 0.14162562 | O16: =H16 -> 0.20449898 | P16: =I16 -> 0.18307692 | Q16: =J16 -> 0.066381156 | R16: =K16 -> -0.68717949 | S16: =L16 -> 0.34603175 | T16: =#REF! -> #REF!
B17: =B11&"(%)" -> Nuclear PTC and Other Revenues(%) | C17: =SUM(C11/C$12) -> #DIV/0! | D17: =SUM(D11/D$12) -> #DIV/0! | E17: =SUM(E11/E$12) -> 0.1106383 | G17: =SUM(G11/G$12) -> 0.070726916 | H17: =SUM(H11/H$12) -> 0.08793456 | I17: =SUM(I11/I$12) -> 0.11076923 | J17: =SUM(J11/J$12) -> 0.17773019 | K17: =SUM(K11/K$12) -> 0.01025641 | L17: =SUM(L11/L$12) -> 0.0047619048 | M17: =SUM(M11/M$12) -> 0 | O17: =H17 -> 0.08793456 | P17: =I17 -> 0.11076923 | Q17: =J17 -> 0.17773019 | R17: =K17 -> 0.01025641 | S17: =L17 -> 0.0047619048 | T17: =#REF! -> #REF!
A19: X | B19: Revenue: Customer Contract Revenues
B20: Capacity Revenues | E20: 192 | G20: 45 | H20: 46 | I20: 50 | J20: =SUM(E20-SUM(G20:I20)) -> 51 | K20: 49 | L20: 88 | M20: 166 | O20: =SUM(G20:G20) -> 45 | P20: =SUM(G20:H20) -> 91 | Q20: =SUM(G20:I20) -> 141 | R20: =SUM(G20:J20) -> 192 | S20: =SUM(H20:K20) -> 196 | T20: =SUM(I20:L20) -> 238
B21: Electricity Sales & Ancillary Service Revenues ISO/RTO | E21: 1144 | G21: 265 | H21: 249 | I21: 351 | J21: =SUM(E21-SUM(G21:I21)) -> 279 | K21: 582 | L21: 307 | M21: 496 | O21: =SUM(G21:G21) -> 265 | P21: =SUM(G21:H21) -> 514 | Q21: =SUM(G21:I21) -> 865 | R21: =SUM(G21:J21) -> 1144 | S21: =SUM(H21:K21) -> 1461 | T21: =SUM(I21:L21) -> 1519
B22: Physical Electricity Sales, Bilateral Contracts, other | E22: 147 | G22: 64 | H22: 22 | I22: 38 | J22: =SUM(E22-SUM(G22:I22)) -> 23 | K22: 23 | L22: 14 | M22: 35 | O22: =SUM(G22:G22) -> 64 | P22: =SUM(G22:H22) -> 86 | Q22: =SUM(G22:I22) -> 124 | R22: =SUM(G22:J22) -> 147 | S22: =SUM(H22:K22) -> 106 | T22: =SUM(I22:L22) -> 98
B23: Other Customer Revenues | E23: 91 | G23: 42 | H23: 29 | I23: 20 | J23: =SUM(E23-SUM(G23:I23)) -> 0 | K23: 0 | L23: 0 | M23: 0 | O23: =SUM(G23:G23) -> 42 | P23: =SUM(G23:H23) -> 71 | Q23: =SUM(G23:I23) -> 91 | R23: =SUM(G23:J23) -> 91 | S23: =SUM(H23:K23) -> 49 | T23: =SUM(I23:L23) -> 20
B24: Total Net Revenue | C24: =SUM(C20:C23) -> 0 | D24: =SUM(D20:D23) -> 0 | E24: =SUM(E20:E23) -> 1574 | G24: =SUM(G20:G23) -> 416 | H24: =SUM(H20:H23) -> 346 | I24: =SUM(I20:I23) -> 459 | J24: =SUM(J20:J23) -> 353 | K24: =SUM(K20:K23) -> 654 | L24: =SUM(L20:L23) -> 409 | M24: =SUM(M20:M23) -> 697 | O24: =SUM(O20:O23) -> 416 | P24: =SUM(P20:P23) -> 762 | Q24: =SUM(Q20:Q23) -> 1221 | R24: =SUM(R20:R23) -> 1574 | S24: =SUM(S20:S23) -> 1812 | T24: =SUM(T20:T23) -> 1875
B25: Balance Check | C25: =C24-C9 -> 0 | D25: =D24-D9 -> 0 | E25: =E24-E9 -> 0 | G25: =G24-G9 -> 0 | H25: =H24-H9 -> 0 | I25: =I24-I9 -> 0 | J25: =J24-J9 -> 0 | K25: =K24-K9 -> 0 | L25: =L24-L9 -> 0 | M25: =M24-M9 -> 0 | O25: =O24-#REF! -> #REF! | P25: =P24-#REF! -> #REF! | Q25: =Q24-#REF! -> #REF! | R25: =R24-#REF! -> #REF! | S25: =S24-#REF! -> #REF! | T25: =T24-#REF! -> #REF!
B27: =B20&"(%)" -> Capacity Revenues(%) | C27: =SUM(C20/C$12) -> #DIV/0! | D27: =SUM(D20/D$12) -> #DIV/0! | E27: =SUM(E20/E$12) -> 0.090780142 | G27: =SUM(G20/G$12) -> 0.088408644 | H27: =SUM(H20/H$12) -> 0.09406953 | I27: =SUM(I20/I$12) -> 0.076923077 | J27: =SUM(J20/J$12) -> 0.10920771 | K27: =SUM(K20/K$12) -> 0.12564103 | L27: =SUM(L20/L$12) -> 0.13968254 | M27: =SUM(M20/M$12) -> 0.2044335 | O27: =H27 -> 0.09406953 | P27: =I27 -> 0.076923077 | Q27: =J27 -> 0.10920771 | R27: =K27 -> 0.12564103 | S27: =L27 -> 0.13968254 | T27: =#REF! -> #REF!
B28: =B21&"(%)" -> Electricity Sales & Ancillary Service Revenues ISO/RTO(%) | C28: =SUM(C21/C$12) -> #DIV/0! | D28: =SUM(D21/D$12) -> #DIV/0! | E28: =SUM(E21/E$12) -> 0.54089835 | G28: =SUM(G21/G$12) -> 0.52062868 | H28: =SUM(H21/H$12) -> 0.50920245 | I28: =SUM(I21/I$12) -> 0.54 | J28: =SUM(J21/J$12) -> 0.59743041 | K28: =SUM(K21/K$12) -> 1.4923077 | L28: =SUM(L21/L$12) -> 0.48730159 | M28: =SUM(M21/M$12) -> 0.61083744 | O28: =H28 -> 0.50920245 | P28: =I28 -> 0.54 | Q28: =J28 -> 0.59743041 | R28: =K28 -> 1.4923077 | S28: =L28 -> 0.48730159 | T28: =#REF! -> #REF!
B29: =B22&"(%)" -> Physical Electricity Sales, Bilateral Contracts, other(%) | C29: =SUM(C22/C$12) -> #DIV/0! | D29: =SUM(D22/D$12) -> #DIV/0! | E29: =SUM(E22/E$12) -> 0.069503546 | G29: =SUM(G22/G$12) -> 0.12573674 | H29: =SUM(H22/H$12) -> 0.044989775 | I29: =SUM(I22/I$12) -> 0.058461538 | J29: =SUM(J22/J$12) -> 0.049250535 | K29: =SUM(K22/K$12) -> 0.058974359 | L29: =SUM(L22/L$12) -> 0.022222222 | M29: =SUM(M22/M$12) -> 0.043103448 | O29: =H29 -> 0.044989775 | P29: =I29 -> 0.058461538 | Q29: =J29 -> 0.049250535 | R29: =K29 -> 0.058974359 | S29: =L29 -> 0.022222222 | T29: =#REF! -> #REF!
B30: =B23&"(%)" -> Other Customer Revenues(%) | C30: =SUM(C23/C$12) -> #DIV/0! | D30: =SUM(D23/D$12) -> #DIV/0! | E30: =SUM(E23/E$12) -> 0.043026005 | G30: =SUM(G23/G$12) -> 0.082514735 | H30: =SUM(H23/H$12) -> 0.059304703 | I30: =SUM(I23/I$12) -> 0.030769231 | J30: =SUM(J23/J$12) -> 0 | K30: =SUM(K23/K$12) -> 0 | L30: =SUM(L23/L$12) -> 0 | M30: =SUM(M23/M$12) -> 0 | O30: =H30 -> 0.059304703 | P30: =I30 -> 0.030769231 | Q30: =J30 -> 0 | R30: =K30 -> 0 | S30: =L30 -> 0 | T30: =#REF! -> #REF!

Sheet FCF
B2: ='Historical Financials'!B2 -> Talen Energy Corporation (NASDAQ: TLN) | D2: FYE | H2: Quarterly | R2: Quarterly | Z2: LTM | AA2: LTM | AG2: Variance
B3: FCF Analysis | C3: ='Historical Financials'!C7 -> 2022 | D3: ='Historical Financials'!D7 -> 2023 | E3: ='Historical Financials'!E7 -> 2024 | F3: ='Historical Financials'!#REF! -> #REF! | H3: ='Historical Financials'!#REF! -> #REF! | I3: ='Historical Financials'!#REF! -> #REF! | J3: ='Historical Financials'!#REF! -> #REF! | K3: ='Historical Financials'!#REF! -> #REF! | L3: ='Historical Financials'!G7 -> 1Q24 | M3: ='Historical Financials'!H7 -> 2Q24 | N3: ='Historical Financials'!I7 -> 3Q24 | O3: ='Historical Financials'!J7 -> 4Q24 | P3: ='Historical Financials'!K7 -> 1Q25 | Q3: ='Historical Financials'!L7 -> 2Q25 | R3: ='Historical Financials'!#REF! -> #REF! | S3: ='Historical Financials'!#REF! -> #REF! | T3: ='Historical Financials'!#REF! -> #REF! | V3: =K3 -> #REF! | W3: =L3 -> 1Q24 | X3: =M3 -> 2Q24 | Y3: =N3 -> 3Q24 | Z3: =O3 -> 4Q24 | AA3: =P3 -> 1Q25 | AB3: =Q3 -> 2Q25 | AC3: =R3 -> #REF! | ... AE3: =T3 -> #REF!
B4: ($ In Millions) | C4: ='Historical Financials'!C8 -> XXX | D4: ='Historical Financials'!D8 -> XXX | E4: ='Historical Financials'!E8 -> XXX | F4: ='Historical Financials'!#REF! -> #REF! | H4: ='Historical Financials'!#REF! -> #REF! | I4: ='Historical Financials'!#REF! -> #REF! | J4: ='Historical Financials'!#REF! -> #REF! | K4: ='Historical Financials'!#REF! -> #REF! | L4: ='Historical Financials'!G8 -> XXX | M4: ='Historical Financials'!H8 -> XXX | N4: ='Historical Financials'!I8 -> XXX | O4: ='Historical Financials'!J8 -> XXX | P4: ='Historical Financials'!K8 -> XXX | Q4: ='Historical Financials'!L8 -> XXX | R4: ='Historical Financials'!#REF! -> #REF! | S4: ='Historical Financials'!#REF! -> #REF! | T4: ='Historical Financials'!#REF! -> #REF! | V4: =K4 -> #REF! | W4: =L4 -> XXX | X4: =M4 -> XXX | Y4: =N4 -> XXX | Z4: =O4 -> XXX | AA4: =P4 -> XXX | AB4: =Q4 -> XXX | AC4: =R4 -> #REF! | ... AE4: =T4 -> #REF!
B6: XXX | V6: =SUM(H6:K6) -> 0 | W6: =SUM(I6:L6) -> 0 | X6: =SUM(J6:M6) -> 0 | Y6: =SUM(K6:N6) -> 0 | Z6: =SUM(L6:O6) -> 0 | AA6: =SUM(M6:P6) -> 0 | AB6: =SUM(N6:Q6) -> 0 | AC6: =SUM(O6:R6) -> 0 | ... AE6: =SUM(Q6:T6) -> 0 | AG6: =SUM(AE6/AA6)-1 -> #DIV/0!
B7: XXX | V7: =SUM(H7:K7) -> 0 | W7: =SUM(I7:L7) -> 0 | X7: =SUM(J7:M7) -> 0 | Y7: =SUM(K7:N7) -> 0 | Z7: =SUM(L7:O7) -> 0 | AA7: =SUM(M7:P7) -> 0 | AB7: =SUM(N7:Q7) -> 0 | AC7: =SUM(O7:R7) -> 0 | ... AE7: =SUM(Q7:T7) -> 0 | AG7: =SUM(AE7/AA7)-1 -> #DIV/0!
B8: XXX | V8: =SUM(H8:K8) -> 0 | W8: =SUM(I8:L8) -> 0 | X8: =SUM(J8:M8) -> 0 | Y8: =SUM(K8:N8) -> 0 | Z8: =SUM(L8:O8) -> 0 | AA8: =SUM(M8:P8) -> 0 | AB8: =SUM(N8:Q8) -> 0 | AC8: =SUM(O8:R8) -> 0 | ... AE8: =SUM(Q8:T8) -> 0 | AG8: =SUM(AE8/AA8)-1 -> #DIV/0!
B9: XXX | V9: =SUM(H9:K9) -> 0 | W9: =SUM(I9:L9) -> 0 | X9: =SUM(J9:M9) -> 0 | Y9: =SUM(K9:N9) -> 0 | Z9: =SUM(L9:O9) -> 0 | AA9: =SUM(M9:P9) -> 0 | AB9: =SUM(N9:Q9) -> 0 | AC9: =SUM(O9:R9) -> 0 | ... AE9: =SUM(Q9:T9) -> 0 | AG9: =SUM(AE9/AA9)-1 -> #DIV/0!
B10: XXX | V10: =SUM(H10:K10) -> 0 | W10: =SUM(I10:L10) -> 0 | X10: =SUM(J10:M10) -> 0 | Y10: =SUM(K10:N10) -> 0 | Z10: =SUM(L10:O10) -> 0 | AA10: =SUM(M10:P10) -> 0 | AB10: =SUM(N10:Q10) -> 0 | AC10: =SUM(O10:R10) -> 0 | ... AE10: =SUM(Q10:T10) -> 0 | AG10: =SUM(AE10/AA10)-1 -> #DIV/0!
B11: XXX | V11: =SUM(H11:K11) -> 0 | W11: =SUM(I11:L11) -> 0 | X11: =SUM(J11:M11) -> 0 | Y11: =SUM(K11:N11) -> 0 | Z11: =SUM(L11:O11) -> 0 | AA11: =SUM(M11:P11) -> 0 | AB11: =SUM(N11:Q11) -> 0 | AC11: =SUM(O11:R11) -> 0 | ... AE11: =SUM(Q11:T11) -> 0 | AG11: =SUM(AE11/AA11)-1 -> #DIV/0!
B12: Total Revenue | C12: =SUM(C6:C11) -> 0 | D12: =SUM(D6:D11) -> 0 | E12: =SUM(E6:E11) -> 0 | F12: =SUM(F6:F11) -> 0 | H12: =SUM(H6:H11) -> 0 | I12: =SUM(I6:I11) -> 0 | J12: =SUM(J6:J11) -> 0 | K12: =SUM(K6:K11) -> 0 | L12: =SUM(L6:L11) -> 0 | M12: =SUM(M6:M11) -> 0 | N12: =SUM(N6:N11) -> 0 | O12: =SUM(O6:O11) -> 0 | ... T12: =SUM(T6:T11) -> 0 | V12: =SUM(V6:V11) -> 0 | W12: =SUM(W6:W11) -> 0 | X12: =SUM(X6:X11) -> 0 | Y12: =SUM(Y6:Y11) -> 0 | Z12: =SUM(Z6:Z11) -> 0 | AA12: =SUM(AA6:AA11) -> 0 | AB12: =SUM(AB6:AB11) -> 0 | AC12: =SUM(AC6:AC11) -> 0 | ... AE12: =SUM(AE6:AE11) -> 0 | AG12: =SUM(AE12/AA12)-1 -> #DIV/0!
B13: Y/Y Growth (%) | C13: =SUM(C12/#REF!)-1 -> #REF! | D13: =SUM(D12/C12)-1 -> #DIV/0! | E13: =SUM(E12/D12)-1 -> #DIV/0! | F13: =SUM(F12/E12)-1 -> #DIV/0! | L13: =SUM(L12/H12)-1 -> #DIV/0! | M13: =SUM(M12/I12)-1 -> #DIV/0! | N13: =SUM(N12/J12)-1 -> #DIV/0! | O13: =SUM(O12/K12)-1 -> #DIV/0! | P13: =SUM(P12/L12)-1 -> #DIV/0! | Q13: =SUM(Q12/M12)-1 -> #DIV/0! | R13: =SUM(R12/N12)-1 -> #DIV/0! | S13: =SUM(S12/O12)-1 -> #DIV/0! | T13: =SUM(T12/P12)-1 -> #DIV/0! | Z13: =SUM(Z12/V12)-1 -> #DIV/0! | AA13: =SUM(AA12/W12)-1 -> #DIV/0! | AB13: =SUM(AB12/X12)-1 -> #DIV/0! | AC13: =SUM(AC12/Y12)-1 -> #DIV/0! | AD13: =SUM(AD12/Z12)-1 -> #DIV/0! | AE13: =SUM(AE12/AA12)-1 -> #DIV/0! | AG13: =SUM(AE13-AA13)*10000 -> #DIV/0!
B14: Q/Q Growth (%) | C14: N/A | D14: N/A | E14: N/A | F14: N/A | I14: =SUM(I12/H12)-1 -> #DIV/0! | J14: =SUM(J12/I12)-1 -> #DIV/0! | K14: =SUM(K12/J12)-1 -> #DIV/0! | L14: =SUM(L12/K12)-1 -> #DIV/0! | M14: =SUM(M12/L12)-1 -> #DIV/0! | N14: =SUM(N12/M12)-1 -> #DIV/0! | O14: =SUM(O12/N12)-1 -> #DIV/0! | P14: =SUM(P12/O12)-1 -> #DIV/0! | ... T14: =SUM(T12/S12)-1 -> #DIV/0! | V14: N/A | W14: N/A | X14: N/A | Y14: N/A | Z14: N/A | AA14: N/A | AB14: N/A | AC14: N/A | AD14: N/A | AE14: N/A
B16: (-) Cost of Sales | V16: =SUM(H16:K16) -> 0 | W16: =SUM(I16:L16) -> 0 | X16: =SUM(J16:M16) -> 0 | Y16: =SUM(K16:N16) -> 0 | Z16: =SUM(L16:O16) -> 0 | AA16: =SUM(M16:P16) -> 0 | AB16: =SUM(N16:Q16) -> 0 | AC16: =SUM(O16:R16) -> 0 | ... AE16: =SUM(Q16:T16) -> 0 | AG16: =SUM(AE16/AA16)-1 -> #DIV/0!
B17: Gross Profit | C17: =SUM(C12+SUM(C16:C16)) -> 0 | D17: =SUM(D12+SUM(D16:D16)) -> 0 | E17: =SUM(E12+SUM(E16:E16)) -> 0 | F17: =SUM(F12+SUM(F16:F16)) -> 0 | H17: =SUM(H12+SUM(H16:H16)) -> 0 | I17: =SUM(I12+SUM(I16:I16)) -> 0 | J17: =SUM(J12+SUM(J16:J16)) -> 0 | K17: =SUM(K12+SUM(K16:K16)) -> 0 | L17: =SUM(L12+SUM(L16:L16)) -> 0 | M17: =SUM(M12+SUM(M16:M16)) -> 0 | N17: =SUM(N12+SUM(N16:N16)) -> 0 | O17: =SUM(O12+SUM(O16:O16)) -> 0 | ... T17: =SUM(T12+SUM(T16:T16)) -> 0 | V17: =SUM(V12+SUM(V16:V16)) -> 0 | W17: =SUM(W12+SUM(W16:W16)) -> 0 | X17: =SUM(X12+SUM(X16:X16)) -> 0 | Y17: =SUM(Y12+SUM(Y16:Y16)) -> 0 | Z17: =SUM(Z12+SUM(Z16:Z16)) -> 0 | AA17: =SUM(AA12+SUM(AA16:AA16)) -> 0 | AB17: =SUM(AB12+SUM(AB16:AB16)) -> 0 | AC17: =SUM(AC12+SUM(AC16:AC16)) -> 0 | ... AE17: =SUM(AE12+SUM(AE16:AE16)) -> 0 | AG17: =SUM(AE17/AA17)-1 -> #DIV/0!
B18: Gross Margin (%) | C18: =C17/C12 -> #DIV/0! | D18: =D17/D12 -> #DIV/0! | E18: =E17/E12 -> #DIV/0! | F18: =F17/F12 -> #DIV/0! | H18: =H17/H12 -> #DIV/0! | I18: =I17/I12 -> #DIV/0! | J18: =J17/J12 -> #DIV/0! | K18: =K17/K12 -> #DIV/0! | L18: =L17/L12 -> #DIV/0! | M18: =M17/M12 -> #DIV/0! | N18: =N17/N12 -> #DIV/0! | O18: =O17/O12 -> #DIV/0! | ... T18: =T17/T12 -> #DIV/0! | V18: =V17/V12 -> #DIV/0! | W18: =W17/W12 -> #DIV/0! | X18: =X17/X12 -> #DIV/0! | Y18: =Y17/Y12 -> #DIV/0! | Z18: =Z17/Z12 -> #DIV/0! | AA18: =AA17/AA12 -> #DIV/0! | AB18: =AB17/AB12 -> #DIV/0! | AC18: =AC17/AC12 -> #DIV/0! | ... AE18: =AE17/AE12 -> #DIV/0! | AG18: =SUM(AE18-AA18)*10000 -> #DIV/0!
B20: (-) XXX | V20: =SUM(H20:K20) -> 0 | W20: =SUM(I20:L20) -> 0 | X20: =SUM(J20:M20) -> 0 | Y20: =SUM(K20:N20) -> 0 | Z20: =SUM(L20:O20) -> 0 | AA20: =SUM(M20:P20) -> 0 | AB20: =SUM(N20:Q20) -> 0 | AC20: =SUM(O20:R20) -> 0 | ... AE20: =SUM(Q20:T20) -> 0 | AG20: =SUM(AE20/AA20)-1 -> #DIV/0!
B21: (-) XXX | V21: =SUM(H21:K21) -> 0 | W21: =SUM(I21:L21) -> 0 | X21: =SUM(J21:M21) -> 0 | Y21: =SUM(K21:N21) -> 0 | Z21: =SUM(L21:O21) -> 0 | AA21: =SUM(M21:P21) -> 0 | AB21: =SUM(N21:Q21) -> 0 | AC21: =SUM(O21:R21) -> 0 | ... AE21: =SUM(Q21:T21) -> 0 | AG21: =SUM(AE21/AA21)-1 -> #DIV/0!
B22: (-) XXX | V22: =SUM(H22:K22) -> 0 | W22: =SUM(I22:L22) -> 0 | X22: =SUM(J22:M22) -> 0 | Y22: =SUM(K22:N22) -> 0 | Z22: =SUM(L22:O22) -> 0 | AA22: =SUM(M22:P22) -> 0 | AB22: =SUM(N22:Q22) -> 0 | AC22: =SUM(O22:R22) -> 0 | ... AE22: =SUM(Q22:T22) -> 0 | AG22: =SUM(AE22/AA22)-1 -> #DIV/0!
B23: (-) XXX | V23: =SUM(H23:K23) -> 0 | W23: =SUM(I23:L23) -> 0 | X23: =SUM(J23:M23) -> 0 | Y23: =SUM(K23:N23) -> 0 | Z23: =SUM(L23:O23) -> 0 | AA23: =SUM(M23:P23) -> 0 | AB23: =SUM(N23:Q23) -> 0 | AC23: =SUM(O23:R23) -> 0 | ... AE23: =SUM(Q23:T23) -> 0 | AG23: =SUM(AE23/AA23)-1 -> #DIV/0!
B24: (-) XXX | V24: =SUM(H24:K24) -> 0 | W24: =SUM(I24:L24) -> 0 | X24: =SUM(J24:M24) -> 0 | Y24: =SUM(K24:N24) -> 0 | Z24: =SUM(L24:O24) -> 0 | AA24: =SUM(M24:P24) -> 0 | AB24: =SUM(N24:Q24) -> 0 | AC24: =SUM(O24:R24) -> 0 | ... AE24: =SUM(Q24:T24) -> 0 | AG24: =SUM(AE24/AA24)-1 -> #DIV/0!
B25: Earning before Interest & Taxes (EBIT) | C25: =SUM(C17+SUM(C20:C24)) -> 0 | D25: =SUM(D17+SUM(D20:D24)) -> 0 | E25: =SUM(E17+SUM(E20:E24)) -> 0 | F25: =SUM(F17+SUM(F20:F24)) -> 0 | H25: =SUM(H17+SUM(H20:H24)) -> 0 | I25: =SUM(I17+SUM(I20:I24)) -> 0 | J25: =SUM(J17+SUM(J20:J24)) -> 0 | K25: =SUM(K17+SUM(K20:K24)) -> 0 | L25: =SUM(L17+SUM(L20:L24)) -> 0 | M25: =SUM(M17+SUM(M20:M24)) -> 0 | N25: =SUM(N17+SUM(N20:N24)) -> 0 | O25: =SUM(O17+SUM(O20:O24)) -> 0 | ... T25: =SUM(T17+SUM(T20:T24)) -> 0 | V25: =SUM(V17+SUM(V20:V24)) -> 0 | W25: =SUM(W17+SUM(W20:W24)) -> 0 | X25: =SUM(X17+SUM(X20:X24)) -> 0 | Y25: =SUM(Y17+SUM(Y20:Y24)) -> 0 | Z25: =SUM(Z17+SUM(Z20:Z24)) -> 0 | AA25: =SUM(AA17+SUM(AA20:AA24)) -> 0 | AB25: =SUM(AB17+SUM(AB20:AB24)) -> 0 | AC25: =SUM(AC17+SUM(AC20:AC24)) -> 0 | ... AE25: =SUM(AE17+SUM(AE20:AE24)) -> 0 | AG25: =SUM(AE25/AA25)-1 -> #DIV/0!
B26: Operating Margin (%) | C26: =C25/C12 -> #DIV/0! | D26: =D25/D12 -> #DIV/0! | E26: =E25/E12 -> #DIV/0! | F26: =F25/F12 -> #DIV/0! | H26: =H25/H12 -> #DIV/0! | I26: =I25/I12 -> #DIV/0! | J26: =J25/J12 -> #DIV/0! | K26: =K25/K12 -> #DIV/0! | L26: =L25/L12 -> #DIV/0! | M26: =M25/M12 -> #DIV/0! | N26: =N25/N12 -> #DIV/0! | O26: =O25/O12 -> #DIV/0! | ... T26: =T25/T12 -> #DIV/0! | V26: =V25/V12 -> #DIV/0! | W26: =W25/W12 -> #DIV/0! | X26: =X25/X12 -> #DIV/0! | Y26: =Y25/Y12 -> #DIV/0! | Z26: =Z25/Z12 -> #DIV/0! | AA26: =AA25/AA12 -> #DIV/0! | AB26: =AB25/AB12 -> #DIV/0! | AC26: =AC25/AC12 -> #DIV/0! | ... AE26: =AE25/AE12 -> #DIV/0! | AG26: =SUM(AE26-AA26)*10000 -> #DIV/0!
B28: (+) Depreciation and Amortization (D&A) | V28: =SUM(H28:K28) -> 0 | W28: =SUM(I28:L28) -> 0 | X28: =SUM(J28:M28) -> 0 | Y28: =SUM(K28:N28) -> 0 | Z28: =SUM(L28:O28) -> 0 | AA28: =SUM(M28:P28) -> 0 | AB28: =SUM(N28:Q28) -> 0 | AC28: =SUM(O28:R28) -> 0 | ... AE28: =SUM(Q28:T28) -> 0 | AG28: =SUM(AE28/AA28)-1 -> #DIV/0!
B29: EBITDA | C29: =SUM(C25+SUM(C28:C28)) -> 0 | D29: =SUM(D25+SUM(D28:D28)) -> 0 | E29: =SUM(E25+SUM(E28:E28)) -> 0 | F29: =SUM(F25+SUM(F28:F28)) -> 0 | H29: =SUM(H25+SUM(H28:H28)) -> 0 | I29: =SUM(I25+SUM(I28:I28)) -> 0 | J29: =SUM(J25+SUM(J28:J28)) -> 0 | K29: =SUM(K25+SUM(K28:K28)) -> 0 | L29: =SUM(L25+SUM(L28:L28)) -> 0 | M29: =SUM(M25+SUM(M28:M28)) -> 0 | N29: =SUM(N25+SUM(N28:N28)) -> 0 | O29: =SUM(O25+SUM(O28:O28)) -> 0 | ... T29: =SUM(T25+SUM(T28:T28)) -> 0 | V29: =SUM(V25+SUM(V28:V28)) -> 0 | W29: =SUM(W25+SUM(W28:W28)) -> 0 | X29: =SUM(X25+SUM(X28:X28)) -> 0 | Y29: =SUM(Y25+SUM(Y28:Y28)) -> 0 | Z29: =SUM(Z25+SUM(Z28:Z28)) -> 0 | AA29: =SUM(AA25+SUM(AA28:AA28)) -> 0 | AB29: =SUM(AB25+SUM(AB28:AB28)) -> 0 | AC29: =SUM(AC25+SUM(AC28:AC28)) -> 0 | ... AE29: =SUM(AE25+SUM(AE28:AE28)) -> 0 | AG29: =SUM(AE29/AA29)-1 -> #DIV/0!
B30: EBITDA Margin (%) | C30: =C29/C12 -> #DIV/0! | D30: =D29/D12 -> #DIV/0! | E30: =E29/E12 -> #DIV/0! | F30: =F29/F12 -> #DIV/0! | H30: =H29/H12 -> #DIV/0! | I30: =I29/I12 -> #DIV/0! | J30: =J29/J12 -> #DIV/0! | K30: =K29/K12 -> #DIV/0! | L30: =L29/L12 -> #DIV/0! | M30: =M29/M12 -> #DIV/0! | N30: =N29/N12 -> #DIV/0! | O30: =O29/O12 -> #DIV/0! | ... T30: =T29/T12 -> #DIV/0! | V30: =V29/V12 -> #DIV/0! | W30: =W29/W12 -> #DIV/0! | X30: =X29/X12 -> #DIV/0! | Y30: =Y29/Y12 -> #DIV/0! | Z30: =Z29/Z12 -> #DIV/0! | AA30: =AA29/AA12 -> #DIV/0! | AB30: =AB29/AB12 -> #DIV/0! | AC30: =AC29/AC12 -> #DIV/0! | ... AE30: =AE29/AE12 -> #DIV/0! | AG30: =SUM(AE30-AA30)*10000 -> #DIV/0!
B32: (+) Stock-Based Compensation (SBC) | V32: =SUM(H32:K32) -> 0 | W32: =SUM(I32:L32) -> 0 | X32: =SUM(J32:M32) -> 0 | Y32: =SUM(K32:N32) -> 0 | Z32: =SUM(L32:O32) -> 0 | AA32: =SUM(M32:P32) -> 0 | AB32: =SUM(N32:Q32) -> 0 | AC32: =SUM(O32:R32) -> 0 | ... AE32: =SUM(Q32:T32) -> 0 | AG32: =SUM(AE32/AA32)-1 -> #DIV/0!
B33: (+) XXX | V33: =SUM(H33:K33) -> 0 | W33: =SUM(I33:L33) -> 0 | X33: =SUM(J33:M33) -> 0 | Y33: =SUM(K33:N33) -> 0 | Z33: =SUM(L33:O33) -> 0 | AA33: =SUM(M33:P33) -> 0 | AB33: =SUM(N33:Q33) -> 0 | AC33: =SUM(O33:R33) -> 0 | ... AE33: =SUM(Q33:T33) -> 0 | AG33: =SUM(AE33/AA33)-1 -> #DIV/0!
B34: Adj. EBITDA | C34: =+SUM(C29+SUM(C32:C32)) -> 0 | D34: =+SUM(D29+SUM(D32:D32)) -> 0 | E34: =+SUM(E29+SUM(E32:E32)) -> 0 | F34: =+SUM(F29+SUM(F32:F32)) -> 0 | H34: =+SUM(H29+SUM(H32:H32)) -> 0 | I34: =+SUM(I29+SUM(I32:I32)) -> 0 | J34: =+SUM(J29+SUM(J32:J32)) -> 0 | K34: =+SUM(K29+SUM(K32:K32)) -> 0 | L34: =+SUM(L29+SUM(L32:L32)) -> 0 | M34: =+SUM(M29+SUM(M32:M32)) -> 0 | N34: =+SUM(N29+SUM(N32:N32)) -> 0 | O34: =+SUM(O29+SUM(O32:O32)) -> 0 | ... T34: =+SUM(T29+SUM(T32:T32)) -> 0 | V34: =+SUM(V29+SUM(V32:V32)) -> 0 | W34: =+SUM(W29+SUM(W32:W32)) -> 0 | X34: =+SUM(X29+SUM(X32:X32)) -> 0 | Y34: =+SUM(Y29+SUM(Y32:Y32)) -> 0 | Z34: =+SUM(Z29+SUM(Z32:Z32)) -> 0 | AA34: =+SUM(AA29+SUM(AA32:AA32)) -> 0 | AB34: =+SUM(AB29+SUM(AB32:AB32)) -> 0 | AC34: =+SUM(AC29+SUM(AC32:AC32)) -> 0 | ... AE34: =+SUM(AE29+SUM(AE32:AE32)) -> 0 | AG34: =SUM(AE34/AA34)-1 -> #DIV/0!
B35: Adj. EBITDA Margin (%) | C35: =C34/C12 -> #DIV/0! | D35: =D34/D12 -> #DIV/0! | E35: =E34/E12 -> #DIV/0! | F35: =F34/F12 -> #DIV/0! | H35: =H34/H12 -> #DIV/0! | I35: =I34/I12 -> #DIV/0! | J35: =J34/J12 -> #DIV/0! | K35: =K34/K12 -> #DIV/0! | L35: =L34/L12 -> #DIV/0! | M35: =M34/M12 -> #DIV/0! | N35: =N34/N12 -> #DIV/0! | O35: =O34/O12 -> #DIV/0! | ... T35: =T34/T12 -> #DIV/0! | V35: =V34/V12 -> #DIV/0! | W35: =W34/W12 -> #DIV/0! | X35: =X34/X12 -> #DIV/0! | Y35: =Y34/Y12 -> #DIV/0! | Z35: =Z34/Z12 -> #DIV/0! | AA35: =AA34/AA12 -> #DIV/0! | AB35: =AB34/AB12 -> #DIV/0! | AC35: =AC34/AC12 -> #DIV/0! | ... AE35: =AE34/AE12 -> #DIV/0! | AG35: =SUM(AE35-AA35)*10000 -> #DIV/0!
B37: (-) Capital Expenditures | V37: =SUM(H37:K37) -> 0 | W37: =SUM(I37:L37) -> 0 | X37: =SUM(J37:M37) -> 0 | Y37: =SUM(K37:N37) -> 0 | Z37: =SUM(L37:O37) -> 0 | AA37: =SUM(M37:P37) -> 0 | AB37: =SUM(N37:Q37) -> 0 | AC37: =SUM(O37:R37) -> 0 | ... AE37: =SUM(Q37:T37) -> 0 | AG37: =SUM(AE37/AA37)-1 -> #DIV/0!
B38: (-) Cash Taxes | V38: =SUM(H38:K38) -> 0 | W38: =SUM(I38:L38) -> 0 | X38: =SUM(J38:M38) -> 0 | Y38: =SUM(K38:N38) -> 0 | Z38: =SUM(L38:O38) -> 0 | AA38: =SUM(M38:P38) -> 0 | AB38: =SUM(N38:Q38) -> 0 | AC38: =SUM(O38:R38) -> 0 | ... AE38: =SUM(Q38:T38) -> 0 | AG38: =SUM(AE38/AA38)-1 -> #DIV/0!
B39: (-) Cash Interest | V39: =SUM(H39:K39) -> 0 | W39: =SUM(I39:L39) -> 0 | X39: =SUM(J39:M39) -> 0 | Y39: =SUM(K39:N39) -> 0 | Z39: =SUM(L39:O39) -> 0 | AA39: =SUM(M39:P39) -> 0 | AB39: =SUM(N39:Q39) -> 0 | AC39: =SUM(O39:R39) -> 0 | ... AE39: =SUM(Q39:T39) -> 0 | AG39: =SUM(AE39/AA39)-1 -> #DIV/0!
B40: (-) Mandatory Outflows | V40: =SUM(H40:K40) -> 0 | W40: =SUM(I40:L40) -> 0 | X40: =SUM(J40:M40) -> 0 | Y40: =SUM(K40:N40) -> 0 | Z40: =SUM(L40:O40) -> 0 | AA40: =SUM(M40:P40) -> 0 | AB40: =SUM(N40:Q40) -> 0 | AC40: =SUM(O40:R40) -> 0 | ... AE40: =SUM(Q40:T40) -> 0 | AG40: =SUM(AE40/AA40)-1 -> #DIV/0!
B41: (+/-) Changes in NWC | V41: =SUM(H41:K41) -> 0 | W41: =SUM(I41:L41) -> 0 | X41: =SUM(J41:M41) -> 0 | Y41: =SUM(K41:N41) -> 0 | Z41: =SUM(L41:O41) -> 0 | AA41: =SUM(M41:P41) -> 0 | AB41: =SUM(N41:Q41) -> 0 | AC41: =SUM(O41:R41) -> 0 | ... AE41: =SUM(Q41:T41) -> 0 | AG41: =SUM(AE41/AA41)-1 -> #DIV/0!
B42: Discretionary Cash-Flows | C42: =SUM(C34+SUM(C37:C41)) -> 0 | D42: =SUM(D34+SUM(D37:D41)) -> 0 | E42: =SUM(E34+SUM(E37:E41)) -> 0 | F42: =SUM(F34+SUM(F37:F41)) -> 0 | H42: =SUM(H34+SUM(H37:H41)) -> 0 | I42: =SUM(I34+SUM(I37:I41)) -> 0 | J42: =SUM(J34+SUM(J37:J41)) -> 0 | K42: =SUM(K34+SUM(K37:K41)) -> 0 | L42: =SUM(L34+SUM(L37:L41)) -> 0 | M42: =SUM(M34+SUM(M37:M41)) -> 0 | N42: =SUM(N34+SUM(N37:N41)) -> 0 | O42: =SUM(O34+SUM(O37:O41)) -> 0 | ... T42: =SUM(T34+SUM(T37:T41)) -> 0 | V42: =SUM(V34+SUM(V37:V41)) -> 0 | W42: =SUM(W34+SUM(W37:W41)) -> 0 | X42: =SUM(X34+SUM(X37:X41)) -> 0 | Y42: =SUM(Y34+SUM(Y37:Y41)) -> 0 | Z42: =SUM(Z34+SUM(Z37:Z41)) -> 0 | AA42: =SUM(AA34+SUM(AA37:AA41)) -> 0 | AB42: =SUM(AB34+SUM(AB37:AB41)) -> 0 | AC42: =SUM(AC34+SUM(AC37:AC41)) -> 0 | ... AE42: =SUM(AE34+SUM(AE37:AE41)) -> 0 | AG42: =SUM(AE42/AA42)-1 -> #DIV/0!
B44: (+/-) XXX | V44: =SUM(H44:K44) -> 0 | W44: =SUM(I44:L44) -> 0 | X44: =SUM(J44:M44) -> 0 | Y44: =SUM(K44:N44) -> 0 | Z44: =SUM(L44:O44) -> 0 | AA44: =SUM(M44:P44) -> 0 | AB44: =SUM(N44:Q44) -> 0 | AC44: =SUM(O44:R44) -> 0 | ... AE44: =SUM(Q44:T44) -> 0
B45: (+/-) XXX | V45: =SUM(H45:K45) -> 0 | W45: =SUM(I45:L45) -> 0 | X45: =SUM(J45:M45) -> 0 | Y45: =SUM(K45:N45) -> 0 | Z45: =SUM(L45:O45) -> 0 | AA45: =SUM(M45:P45) -> 0 | AB45: =SUM(N45:Q45) -> 0 | AC45: =SUM(O45:R45) -> 0 | ... AE45: =SUM(Q45:T45) -> 0
B46: (+/-) XXX | V46: =SUM(H46:K46) -> 0 | W46: =SUM(I46:L46) -> 0 | X46: =SUM(J46:M46) -> 0 | Y46: =SUM(K46:N46) -> 0 | Z46: =SUM(L46:O46) -> 0 | AA46: =SUM(M46:P46) -> 0 | AB46: =SUM(N46:Q46) -> 0 | AC46: =SUM(O46:R46) -> 0 | ... AE46: =SUM(Q46:T46) -> 0
B47: (+/-) XXX | V47: =SUM(H47:K47) -> 0 | W47: =SUM(I47:L47) -> 0 | X47: =SUM(J47:M47) -> 0 | Y47: =SUM(K47:N47) -> 0 | Z47: =SUM(L47:O47) -> 0 | AA47: =SUM(M47:P47) -> 0 | AB47: =SUM(N47:Q47) -> 0 | AC47: =SUM(O47:R47) -> 0 | ... AE47: =SUM(Q47:T47) -> 0
B48: (+/-) XXX | V48: =SUM(H48:K48) -> 0 | W48: =SUM(I48:L48) -> 0 | X48: =SUM(J48:M48) -> 0 | Y48: =SUM(K48:N48) -> 0 | Z48: =SUM(L48:O48) -> 0 | AA48: =SUM(M48:P48) -> 0 | AB48: =SUM(N48:Q48) -> 0 | AC48: =SUM(O48:R48) -> 0 | ... AE48: =SUM(Q48:T48) -> 0
...
