Workbook

Sheet Historical Financials
B2: Rigetti Computing Inc. (NASDAQ: RGTI)
B3: Historical Financials
B4: $ in thousands except per share
A6: X | B6: Income Statement | D6: FYE | H6: Quarterly | R6: Quarterly | AC6: LTM | AI6: Variance
B7: Fiscal Period | C7: 2021 | D7: 2022 | E7: 2023 | F7: 2024 | H7: 1Q22 | I7: 2Q22 | J7: 3Q22 | K7: 4Q22 | L7: 1Q23 | M7: 2Q23 | N7: 3Q23 | O7: 4Q23 | P7: 1Q24 | Q7: 2Q24 | R7: 3Q24 | S7: 4Q24 | T7: 1Q25 | U7: 2Q25 | W7: =K7 -> 4Q22 | X7: =L7 -> 1Q23 | Y7: =M7 -> 2Q23 | Z7: =N7 -> 3Q23 | AA7: =O7 -> 4Q23 | AB7: =P7 -> 1Q24 | AC7: =Q7 -> 2Q24 | AD7: =R7 -> 3Q24 | ... AG7: =U7 -> 2Q25
B8: Fiscal Period End Date | C8: 44561 | D8: 44926 | E8: 45291 | F8: 45657 | H8: 44651 | I8: 44742 | J8: 44834 | K8: 44926 | L8: 45016 | M8: 45107 | N8: 45199 | O8: 45291 | P8: 45382 | Q8: 45473 | R8: 45565 | S8: 45657 | T8: 45747 | U8: 45838 | W8: =K8 -> 44926 | X8: =L8 -> 45016 | Y8: =M8 -> 45107 | Z8: =N8 -> 45199 | AA8: =O8 -> 45291 | AB8: =P8 -> 45382 | AC8: =Q8 -> 45473 | AD8: =R8 -> 45565 | ... AG8: =U8 -> 45838
B10: Consolidated Revenue | C10: 8196 | D10: 13102 | E10: 12008 | F10: 10790 | H10: 2104 | I10: 2134 | J10: 2804 | K10: =SUM(D10-SUM(H10:J10)) -> 6060 | L10: 2201 | M10: 3327 | N10: 3105 | O10: =SUM(E10-SUM(L10:N10)) -> 3375 | P10: 3052 | Q10: 3086 | R10: 2378 | S10: =SUM(F10-SUM(P10:R10)) -> 2274 | T10: 1472 | U10: 1801 | W10: =SUM(H10:K10) -> 13102 | X10: =SUM(I10:L10) -> 13199 | Y10: =SUM(J10:M10) -> 14392 | Z10: =SUM(K10:N10) -> 14693 | AA10: =SUM(L10:O10) -> 12008 | AB10: =SUM(M10:P10) -> 12859 | AC10: =SUM(N10:Q10) -> 12618 | AD10: =SUM(O10:R10) -> 11891 | ... AG10: =SUM(R10:U10) -> 7925 | AI10: =SUM(AG10/AC10)-1 -> -0.37192899
B11: Total Revenue | C11: =+SUM(C10:C10) -> 8196 | D11: =+SUM(D10:D10) -> 13102 | E11: =+SUM(E10:E10) -> 12008 | F11: =+SUM(F10:F10) -> 10790 | H11: =+SUM(H10:H10) -> 2104 | I11: =+SUM(I10:I10) -> 2134 | J11: =+SUM(J10:J10) -> 2804 | K11: =+SUM(K10:K10) -> 6060 | L11: =+SUM(L10:L10) -> 2201 | M11: =+SUM(M10:M10) -> 3327 | N11: =+SUM(N10:N10) -> 3105 | O11: =+SUM(O10:O10) -> 3375 | ... U11: =+SUM(U10:U10) -> 1801 | W11: =+SUM(W10:W10) -> 13102 | X11: =+SUM(X10:X10) -> 13199 | Y11: =+SUM(Y10:Y10) -> 14392 | Z11: =+SUM(Z10:Z10) -> 14693 | AA11: =+SUM(AA10:AA10) -> 12008 | AB11: =+SUM(AB10:AB10) -> 12859 | AC11: =+SUM(AC10:AC10) -> 12618 | AD11: =+SUM(AD10:AD10) -> 11891 | ... AG11: =+SUM(AG10:AG10) -> 7925 | AI11: =SUM(AG11/AC11)-1 -> -0.37192899
B13: Cost of Sales | C13: -1623 | D13: -2873 | E13: -2800 | F13: -5093 | H13: -414 | I13: -873 | J13: -776 | K13: =SUM(D13-SUM(H13:J13)) -> -810 | L13: -510 | M13: -597 | N13: -834 | O13: =SUM(E13-SUM(L13:N13)) -> -859 | P13: -1552 | Q13: -1096 | R13: -1174 | S13: =SUM(F13-SUM(P13:R13)) -> -1271 | T13: -1030 | U13: -1235 | W13: =SUM(I13:L13) -> -2969 | X13: =SUM(J13:M13) -> -2693 | Y13: =SUM(K13:N13) -> -2751 | Z13: =SUM(L13:O13) -> -2800 | AA13: =SUM(M13:P13) -> -3842 | AB13: =SUM(N13:Q13) -> -4341 | AC13: =SUM(N13:Q13) -> -4341 | AD13: =SUM(O13:R13) -> -4681 | AE13: =SUM(P13:S13) -> -5093 | AF13: =SUM(Q13:T13) -> -4571 | AG13: =SUM(R13:U13) -> -4710 | AI13: =SUM(AG13/AC13)-1 -> 0.085003455
B14: Gross Profit | C14: =+SUM(C11+SUM(C13:C13)) -> 6573 | D14: =+SUM(D11+SUM(D13:D13)) -> 10229 | E14: =+SUM(E11+SUM(E13:E13)) -> 9208 | F14: =+SUM(F11+SUM(F13:F13)) -> 5697 | H14: =+SUM(H11+SUM(H13:H13)) -> 1690 | I14: =+SUM(I11+SUM(I13:I13)) -> 1261 | J14: =+SUM(J11+SUM(J13:J13)) -> 2028 | K14: =+SUM(K11+SUM(K13:K13)) -> 5250 | L14: =+SUM(L11+SUM(L13:L13)) -> 1691 | M14: =+SUM(M11+SUM(M13:M13)) -> 2730 | N14: =+SUM(N11+SUM(N13:N13)) -> 2271 | O14: =+SUM(O11+SUM(O13:O13)) -> 2516 | ... U14: =+SUM(U11+SUM(U13:U13)) -> 566 | W14: =+SUM(W11+SUM(W13:W13)) -> 10133 | X14: =+SUM(X11+SUM(X13:X13)) -> 10506 | Y14: =+SUM(Y11+SUM(Y13:Y13)) -> 11641 | Z14: =+SUM(Z11+SUM(Z13:Z13)) -> 11893 | AA14: =+SUM(AA11+SUM(AA13:AA13)) -> 8166 | AB14: =+SUM(AB11+SUM(AB13:AB13)) -> 8518 | AC14: =+SUM(AC11+SUM(AC13:AC13)) -> 8277 | AD14: =+SUM(AD11+SUM(AD13:AD13)) -> 7210 | ... AG14: =+SUM(AG11+SUM(AG13:AG13)) -> 3215 | AI14: =SUM(AG14/AC14)-1 -> -0.61157424
B15: Gross Margin (%) | C15: =C14/C11 -> 0.80197657 | D15: =D14/D11 -> 0.7807205 | E15: =E14/E11 -> 0.76682212 | F15: =F14/F11 -> 0.52798888 | H15: =H14/H11 -> 0.80323194 | I15: =I14/I11 -> 0.59090909 | J15: =J14/J11 -> 0.7232525 | K15: =K14/K11 -> 0.86633663 | L15: =L14/L11 -> 0.76828714 | M15: =M14/M11 -> 0.82055906 | N15: =N14/N11 -> 0.73140097 | O15: =O14/O11 -> 0.74548148 | ... U15: =U14/U11 -> 0.31426985 | W15: =W14/W11 -> 0.77339338 | X15: =X14/X11 -> 0.79596939 | Y15: =Y14/Y11 -> 0.80885214 | Z15: =Z14/Z11 -> 0.80943306 | AA15: =AA14/AA11 -> 0.68004664 | AB15: =AB14/AB11 -> 0.66241543 | AC15: =AC14/AC11 -> 0.65596767 | AD15: =AD14/AD11 -> 0.60634093 | ... AG15: =AG14/AG11 -> 0.40567823 | AI15: =SUM(AG15-AC15)*1000 -> -250.28943
B17: Research and development | C17: -26928 | D17: -59952 | E17: -52768 | F17: -49750 | H17: -12449 | I17: -12634 | J17: -17365 | K17: =SUM(D17-SUM(H17:J17)) -> -17504 | L17: -13707 | M17: -13219 | N17: -13056 | O17: =SUM(E17-SUM(L17:N17)) -> -12786 | P17: -11471 | Q17: -11870 | R17: -12752 | S17: =SUM(F17-SUM(P17:R17)) -> -13657 | T17: -15455 | U17: -13522 | W17: =SUM(I17:L17) -> -61210 | X17: =SUM(J17:M17) -> -61795 | Y17: =SUM(K17:N17) -> -57486 | Z17: =SUM(L17:O17) -> -52768 | AA17: =SUM(M17:P17) -> -50532 | AB17: =SUM(N17:Q17) -> -49183 | AC17: =SUM(N17:Q17) -> -49183 | AD17: =SUM(O17:R17) -> -48879 | AE17: =SUM(P17:S17) -> -49750 | AF17: =SUM(Q17:T17) -> -53734 | AG17: =SUM(R17:U17) -> -55386 | AI17: =SUM(AG17/AC17)-1 -> 0.12612081
B18: Selling, general and administrative | C18: -13774 | D18: -53980 | E18: -27744 | F18: -24457 | H18: =-11560-1475 -> -13035 | I18: =-12785-1487 -> -14272 | J18: -15987 | K18: =SUM(D18-SUM(H18:J18)) -> -10686 | L18: -9013 | M18: -5747 | N18: -6047 | O18: =SUM(E18-SUM(L18:N18)) -> -6937 | P18: -6614 | Q18: -6205 | R18: -5798 | S18: =SUM(F18-SUM(P18:R18)) -> -5840 | T18: -6619 | U18: -6926 | W18: =SUM(I18:L18) -> -49958 | X18: =SUM(J18:M18) -> -41433 | Y18: =SUM(K18:N18) -> -31493 | Z18: =SUM(L18:O18) -> -27744 | AA18: =SUM(M18:P18) -> -25345 | AB18: =SUM(N18:Q18) -> -25803 | AC18: =SUM(N18:Q18) -> -25803 | AD18: =SUM(O18:R18) -> -25554 | AE18: =SUM(P18:S18) -> -24457 | AF18: =SUM(Q18:T18) -> -24462 | AG18: =SUM(R18:U18) -> -25183 | AI18: =SUM(AG18/AC18)-1 -> -0.024028214
B19: Restructuring & Other Impairments | C19: 0 | D19: -5377 | E19: -991 | F19: 0 | H19: 0 | I19: 0 | J19: 0 | K19: =SUM(D19-SUM(H19:J19)) -> -5377 | L19: -991 | M19: 0 | N19: 0 | O19: =SUM(E19-SUM(L19:N19)) -> 0 | P19: 0 | Q19: 0 | R19: 0 | S19: =SUM(F19-SUM(P19:R19)) -> 0 | T19: 0 | U19: 0 | W19: =SUM(I19:L19) -> -6368 | X19: =SUM(J19:M19) -> -6368 | Y19: =SUM(K19:N19) -> -6368 | Z19: =SUM(L19:O19) -> -991 | AA19: =SUM(M19:P19) -> 0 | AB19: =SUM(N19:Q19) -> 0 | AC19: =SUM(N19:Q19) -> 0 | AD19: =SUM(O19:R19) -> 0 | AE19: =SUM(P19:S19) -> 0 | AF19: =SUM(Q19:T19) -> 0 | AG19: =SUM(R19:U19) -> 0 | AI19: =SUM(AG19/AC19)-1 -> #DIV/0!
B20: Operating Profit | C20: =+SUM(C14+SUM(C17:C19)) -> -34129 | D20: =+SUM(D14+SUM(D17:D19)) -> -109080 | E20: =+SUM(E14+SUM(E17:E19)) -> -72295 | F20: =+SUM(F14+SUM(F17:F19)) -> -68510 | H20: =+SUM(H14+SUM(H17:H19)) -> -23794 | I20: =+SUM(I14+SUM(I17:I19)) -> -25645 | J20: =+SUM(J14+SUM(J17:J19)) -> -31324 | K20: =+SUM(K14+SUM(K17:K19)) -> -28317 | L20: =+SUM(L14+SUM(L17:L19)) -> -22020 | M20: =+SUM(M14+SUM(M17:M19)) -> -16236 | N20: =+SUM(N14+SUM(N17:N19)) -> -16832 | O20: =+SUM(O14+SUM(O17:O19)) -> -17207 | ... U20: =+SUM(U14+SUM(U17:U19)) -> -19882 | W20: =+SUM(W14+SUM(W17:W19)) -> -107403 | X20: =+SUM(X14+SUM(X17:X19)) -> -99090 | Y20: =+SUM(Y14+SUM(Y17:Y19)) -> -83706 | Z20: =+SUM(Z14+SUM(Z17:Z19)) -> -69610 | AA20: =+SUM(AA14+SUM(AA17:AA19)) -> -67711 | AB20: =+SUM(AB14+SUM(AB17:AB19)) -> -66468 | AC20: =+SUM(AC14+SUM(AC17:AC19)) -> -66709 | AD20: =+SUM(AD14+SUM(AD17:AD19)) -> -67223 | ... AG20: =+SUM(AG14+SUM(AG17:AG19)) -> -77354 | AI20: =SUM(AG20/AC20)-1 -> 0.15957367
B21: Operating Margin (%) | C21: =C20/C11 -> -4.1641044 | D21: =D20/D11 -> -8.3254465 | E21: =E20/E11 -> -6.0205696 | F21: =F20/F11 -> -6.3493976 | H21: =H20/H11 -> -11.308935 | I21: =I20/I11 -> -12.017338 | J21: =J20/J11 -> -11.171184 | K21: =K20/K11 -> -4.6727723 | L21: =L20/L11 -> -10.004543 | M21: =M20/M11 -> -4.8800721 | N21: =N20/N11 -> -5.420934 | O21: =O20/O11 -> -5.0983704 | ... U21: =U20/U11 -> -11.039423 | W21: =W20/W11 -> -8.1974508 | X21: =X20/X11 -> -7.5073869 | Y21: =Y20/Y11 -> -5.8161479 | Z21: =Z20/Z11 -> -4.7376302 | AA21: =AA20/AA11 -> -5.6388241 | AB21: =AB20/AB11 -> -5.1689867 | AC21: =AC20/AC11 -> -5.2868125 | AD21: =AD20/AD11 -> -5.6532672 | ... AG21: =AG20/AG11 -> -9.7607571 | AI21: =SUM(AG21-AC21)*1000 -> -4473.9446
B23: Interest expense | C23: -2465 | D23: -5286 | E23: -5779 | F23: -3255 | H23: -1205 | I23: -1040 | J23: -1436 | K23: =SUM(D23-SUM(H23:J23)) -> -1605 | L23: -1464 | M23: -1574 | N23: -1473 | O23: =SUM(E23-SUM(L23:N23)) -> -1268 | P23: -1107 | Q23: -969 | R23: -733 | S23: =SUM(F23-SUM(P23:R23)) -> -446 | T23: 0 | U23: 0 | W23: =SUM(I23:L23) -> -5545 | X23: =SUM(J23:M23) -> -6079 | Y23: =SUM(K23:N23) -> -6116 | Z23: =SUM(L23:O23) -> -5779 | AA23: =SUM(M23:P23) -> -5422 | AB23: =SUM(N23:Q23) -> -4817 | AC23: =SUM(N23:Q23) -> -4817 | AD23: =SUM(O23:R23) -> -4077 | AE23: =SUM(P23:S23) -> -3255 | AF23: =SUM(Q23:T23) -> -2148 | AG23: =SUM(R23:U23) -> -1179 | AI23: =SUM(AG23/AC23)-1 -> -0.75524185
B24: Interest income | C24: 10 | D24: 2433 | E24: 5076 | F24: 5113 | H24: 0 | I24: 0 | J24: 1042 | K24: =SUM(D24-SUM(H24:J24)) -> 1391 | L24: 1284 | M24: 1199 | N24: 1263 | O24: =SUM(E24-SUM(L24:N24)) -> 1330 | P24: 1123 | Q24: 1218 | R24: 1226 | S24: =SUM(F24-SUM(P24:R24)) -> 1546 | T24: 2152 | U24: 3042 | AC24: =SUM(N24:Q24) -> 4934 | AD24: =SUM(O24:R24) -> 4897 | AE24: =SUM(P24:S24) -> 5113 | AF24: =SUM(Q24:T24) -> 6142 | AG24: =SUM(R24:U24) -> 7966 | AI24: =SUM(AG24/AC24)-1 -> 0.61451155
B25: Change in fair value of derivative warrant liabilities | C25: -1664 | D25: 22132 | E25: -1160 | F25: -90168 | H25: 5822 | I25: 8687 | J25: 8103 | K25: =SUM(D25-SUM(H25:J25)) -> -480 | L25: -873 | M25: -5 | N25: -3442 | O25: =SUM(E25-SUM(L25:N25)) -> 3160 | P25: -2583 | Q25: 2100 | R25: 1200 | S25: =SUM(F25-SUM(P25:R25)) -> -90885 | T25: 53262 | U25: -20557 | AC25: =SUM(N25:Q25) -> -765 | AD25: =SUM(O25:R25) -> 3877 | AE25: =SUM(P25:S25) -> -90168 | AF25: =SUM(Q25:T25) -> -34323 | AG25: =SUM(R25:U25) -> -56980 | AI25: =SUM(AG25/AC25)-1 -> 73.48366
B26: Change in fair value of earn-out liabilities | C26: 0 | D26: 19207 | E26: -949 | F26: -43742 | H26: 9634 | I26: 8024 | J26: 4860 | K26: =SUM(D26-SUM(H26:J26)) -> -3311 | L26: -281 | M26: -350 | N26: -1731 | O26: =SUM(E26-SUM(L26:N26)) -> 1413 | P26: -1621 | Q26: 1315 | R26: 820 | S26: =SUM(F26-SUM(P26:R26)) -> -44256 | T26: 8837 | U26: -2257 | AC26: =SUM(N26:Q26) -> -624 | AD26: =SUM(O26:R26) -> 1927 | AE26: =SUM(P26:S26) -> -43742 | AF26: =SUM(Q26:T26) -> -33284 | AG26: =SUM(R26:U26) -> -36856 | AI26: =SUM(AG26/AC26)-1 -> 58.064103
B27: Transaction costs | C27: 0 | D27: -927 | E27: 0 | F27: 0 | H27: -927 | I27: 0 | J27: 0 | K27: =SUM(D27-SUM(H27:J27)) -> 0 | L27: 0 | M27: 0 | N27: 0 | O27: =SUM(E27-SUM(L27:N27)) -> 0 | P27: 0 | Q27: 0 | R27: 0 | S27: =SUM(F27-SUM(P27:R27)) -> 0 | T27: 0 | U27: 0 | W27: =SUM(I27:L27) -> 0 | X27: =SUM(J27:M27) -> 0 | Y27: =SUM(K27:N27) -> 0 | Z27: =SUM(L27:O27) -> 0 | AA27: =SUM(M27:P27) -> 0 | AB27: =SUM(N27:Q27) -> 0 | AC27: =SUM(N27:Q27) -> 0 | AD27: =SUM(O27:R27) -> 0 | AE27: =SUM(P27:S27) -> 0 | AF27: =SUM(Q27:T27) -> 0 | AG27: =SUM(R27:U27) -> 0 | AI27: =SUM(AG27/AC27)-1 -> #DIV/0!
B28: Other Gains & Losses | C28: 7 | D28: 0 | E28: 0 | F28: -426 | H28: 0 | I28: 0 | J28: 0 | K28: =SUM(D28-SUM(H28:J28)) -> 0 | L28: 0 | M28: 0 | N28: 0 | O28: =SUM(E28-SUM(L28:N28)) -> 0 | P28: 0 | Q28: 0 | R28: 0 | S28: =SUM(F28-SUM(P28:R28)) -> -426 | T28: 0 | U28: 0 | W28: =SUM(I28:L28) -> 0 | X28: =SUM(J28:M28) -> 0 | Y28: =SUM(K28:N28) -> 0 | Z28: =SUM(L28:O28) -> 0 | AA28: =SUM(M28:P28) -> 0 | AB28: =SUM(N28:Q28) -> 0 | AC28: =SUM(N28:Q28) -> 0 | AD28: =SUM(O28:R28) -> 0 | AE28: =SUM(P28:S28) -> -426 | AF28: =SUM(Q28:T28) -> -426 | AG28: =SUM(R28:U28) -> -426 | AI28: =SUM(AG28/AC28)-1 -> #DIV/0!
B29: Earning Before Taxes | C29: =SUM(C20+SUM(C23:C28)) -> -38241 | D29: =SUM(D20+SUM(D23:D28)) -> -71521 | E29: =SUM(E20+SUM(E23:E28)) -> -75107 | F29: =SUM(F20+SUM(F23:F28)) -> -200988 | H29: =SUM(H20+SUM(H23:H28)) -> -10470 | I29: =SUM(I20+SUM(I23:I28)) -> -9974 | J29: =SUM(J20+SUM(J23:J28)) -> -18755 | K29: =SUM(K20+SUM(K23:K28)) -> -32322 | L29: =SUM(L20+SUM(L23:L28)) -> -23354 | M29: =SUM(M20+SUM(M23:M28)) -> -16966 | N29: =SUM(N20+SUM(N23:N28)) -> -22215 | O29: =SUM(O20+SUM(O23:O28)) -> -12572 | ... U29: =SUM(U20+SUM(U23:U28)) -> -39654 | W29: =SUM(W20+SUM(W23:W28)) -> -112948 | X29: =SUM(X20+SUM(X23:X28)) -> -105169 | Y29: =SUM(Y20+SUM(Y23:Y28)) -> -89822 | Z29: =SUM(Z20+SUM(Z23:Z28)) -> -75389 | AA29: =SUM(AA20+SUM(AA23:AA28)) -> -73133 | AB29: =SUM(AB20+SUM(AB23:AB28)) -> -71285 | AC29: =SUM(AC20+SUM(AC23:AC28)) -> -67981 | AD29: =SUM(AD20+SUM(AD23:AD28)) -> -60599 | ... AG29: =SUM(AG20+SUM(AG23:AG28)) -> -164829 | AI29: =SUM(AG29/AC29)-1 -> 1.4246334
B30: EBT Margin (%) | C30: =C29/C11 -> -4.6658126 | D30: =D29/D11 -> -5.4587849 | E30: =E29/E11 -> -6.2547468 | F30: =F29/F11 -> -18.627247 | H30: =H29/H11 -> -4.9762357 | I30: =I29/I11 -> -4.6738519 | J30: =J29/J11 -> -6.6886591 | K30: =K29/K11 -> -5.3336634 | L30: =L29/L11 -> -10.610632 | M30: =M29/M11 -> -5.099489 | N30: =N29/N11 -> -7.1545894 | O30: =O29/O11 -> -3.725037 | ... U30: =U29/U11 -> -22.017768 | W30: =W29/W11 -> -8.6206686 | X30: =X29/X11 -> -7.9679521 | Y30: =Y29/Y11 -> -6.2411062 | Z30: =Z29/Z11 -> -5.1309467 | AA30: =AA29/AA11 -> -6.0903564 | AB30: =AB29/AB11 -> -5.5435881 | AC30: =AC29/AC11 -> -5.3876209 | AD30: =AD29/AD11 -> -5.0962072 | ... AG30: =AG29/AG11 -> -20.798612 | AI30: =SUM(AG30-AC30)*1000 -> -15410.991
B32: Provision for taxes | C32: 0 | D32: 0 | E32: 0 | F32: 0 | H32: 0 | I32: 0 | J32: 0 | K32: =SUM(D32-SUM(H32:J32)) -> 0 | L32: 0 | M32: 0 | N32: 0 | O32: =SUM(E32-SUM(L32:N32)) -> 0 | P32: 0 | Q32: 0 | R32: 0 | S32: =SUM(F32-SUM(P32:R32)) -> 0 | T32: 0 | W32: =SUM(I32:L32) -> 0 | X32: =SUM(J32:M32) -> 0 | Y32: =SUM(K32:N32) -> 0 | Z32: =SUM(L32:O32) -> 0 | AA32: =SUM(M32:P32) -> 0 | AB32: =SUM(N32:Q32) -> 0 | AC32: =SUM(N32:Q32) -> 0 | AD32: =SUM(O32:R32) -> 0 | AE32: =SUM(P32:S32) -> 0 | AF32: =SUM(Q32:T32) -> 0 | AG32: =SUM(R32:U32) -> 0 | AI32: =SUM(AG32/AC32)-1 -> #DIV/0!
B33: Net loss | C33: =SUM(C29+C32) -> -38241 | D33: =SUM(D29+D32) -> -71521 | E33: =SUM(E29+E32) -> -75107 | F33: =SUM(F29+F32) -> -200988 | H33: =SUM(H29+H32) -> -10470 | I33: =SUM(I29+I32) -> -9974 | J33: =SUM(J29+J32) -> -18755 | K33: =SUM(K29+K32) -> -32322 | L33: =SUM(L29+L32) -> -23354 | M33: =SUM(M29+M32) -> -16966 | N33: =SUM(N29+N32) -> -22215 | O33: =SUM(O29+O32) -> -12572 | ... U33: =SUM(U29+U32) -> -39654 | W33: =SUM(W29+W32) -> -112948 | X33: =SUM(X29+X32) -> -105169 | Y33: =SUM(Y29+Y32) -> -89822 | Z33: =SUM(Z29+Z32) -> -75389 | AA33: =SUM(AA29+AA32) -> -73133 | AB33: =SUM(AB29+AB32) -> -71285 | AC33: =SUM(AC29+AC32) -> -67981 | AD33: =SUM(AD29+AD32) -> -60599 | ... AG33: =SUM(AG29+AG32) -> -164829 | AI33: =SUM(AG33/AC33)-1 -> 1.4246334
B34: Net Margin (%) | C34: =C33/C11 -> -4.6658126 | D34: =D33/D11 -> -5.4587849 | E34: =E33/E11 -> -6.2547468 | F34: =F33/F11 -> -18.627247 | H34: =H33/H11 -> -4.9762357 | I34: =I33/I11 -> -4.6738519 | J34: =J33/J11 -> -6.6886591 | K34: =K33/K11 -> -5.3336634 | L34: =L33/L11 -> -10.610632 | M34: =M33/M11 -> -5.099489 | N34: =N33/N11 -> -7.1545894 | O34: =O33/O11 -> -3.725037 | ... U34: =U33/U11 -> -22.017768 | W34: =W33/W11 -> -8.6206686 | X34: =X33/X11 -> -7.9679521 | Y34: =Y33/Y11 -> -6.2411062 | Z34: =Z33/Z11 -> -5.1309467 | AA34: =AA33/AA11 -> -6.0903564 | AB34: =AB33/AB11 -> -5.5435881 | AC34: =AC33/AC11 -> -5.3876209 | AD34: =AD33/AD11 -> -5.0962072 | ... AG34: =AG33/AG11 -> -20.798612 | AI34: =SUM(AG34-AC34)*1000 -> -15410.991
B36: Basic shares | C36: 8625 | D36: 128754.27 | E36: 158881.02 | F36: 285828.05 | H36: 113820.97 | I36: 118244.45 | J36: 123030.05 | K36: =D36 -> 128754.27 | L36: 129822.69 | M36: 132989.74 | N36: 140581.38 | O36: =E36 -> 158881.02 | P36: 171919.3 | Q36: 191243.49 | R36: 192295.81 | S36: =F36 -> 285828.05 | T36: 290322.89 | U36: 324165.17 | W36: =K36 -> 128754.27 | X36: =L36 -> 129822.69 | Y36: =M36 -> 132989.74 | Z36: =N36 -> 140581.38 | AA36: =O36 -> 158881.02 | AB36: =P36 -> 171919.3 | AC36: =Q36 -> 191243.49 | AD36: =R36 -> 192295.81 | ... AG36: =U36 -> 324165.17 | AI36: =SUM(AG36/AC36)-1 -> 0.69503896
B37: Basic EPS | C37: =C33/C36 -> -4.4337391 | D37: =D33/D36 -> -0.5554845 | E37: =E33/E36 -> -0.4727248 | F37: =F33/F36 -> -0.70317802 | H37: =H33/H36 -> -0.091986565 | I37: =I33/I36 -> -0.084350681 | J37: =J33/J36 -> -0.15244243 | K37: =K33/K36 -> -0.25103634 | L37: =L33/L36 -> -0.17989152 | M37: =M33/M36 -> -0.12757375 | N37: =N33/N36 -> -0.15802235 | O37: =O33/O36 -> -0.079128393 | ... U37: =U33/U36 -> -0.12232653 | W37: =W33/W36 -> -0.87723695 | X37: =X33/X36 -> -0.81009724 | Y37: =Y33/Y36 -> -0.67540547 | Z37: =Z33/Z36 -> -0.53626591 | AA37: =AA33/AA36 -> -0.46030041 | AB37: =AB33/AB36 -> -0.41464223 | AC37: =AC33/AC36 -> -0.35546831 | AD37: =AD33/AD36 -> -0.31513427 | ... AG37: =AG33/AG36 -> -0.50847227 | AI37: =SUM(AG37/AC37)-1 -> 0.43042928
B39: Fully Diluted Shares | C39: 23337.127 | D39: 102300.85 | E39: 131977 | F39: 184666 | H39: 53691.948 | I39: 114096.39 | J39: 118571.29 | K39: =D39 -> 102300.85 | L39: 124778 | M39: 128515 | N39: 133866 | O39: =E39 -> 131977 | P39: 151855 | Q39: 171903 | R39: 188389 | S39: =F39 -> 184666 | T39: 301595 | U39: 298254 | W39: =L39 -> 124778 | X39: =M39 -> 128515 | Y39: =N39 -> 133866 | Z39: =O39 -> 131977 | AA39: =P39 -> 151855 | AB39: =Q39 -> 171903 | AC39: =Q39 -> 171903 | AD39: =R39 -> 188389 | AE39: =S39 -> 184666 | AF39: =T39 -> 301595 | AG39: =U39 -> 298254 | AI39: =SUM(AG39/AC39)-1 -> 0.73501335
B40: Diluted EPS | C40: =C33/C39 -> -1.6386336 | D40: =D33/D39 -> -0.69912419 | E40: =E33/E39 -> -0.56909158 | F40: =F33/F39 -> -1.0883866 | H40: =H33/H39 -> -0.19500131 | I40: =I33/I39 -> -0.087417314 | J40: =J33/J39 -> -0.15817488 | K40: =K33/K39 -> -0.31595045 | L40: =L33/L39 -> -0.1871644 | M40: =M33/M39 -> -0.13201572 | N40: =N33/N39 -> -0.16594953 | O40: =O33/O39 -> -0.095259022 | ... U40: =U33/U39 -> -0.13295379 | W40: =W33/W39 -> -0.90519162 | X40: =X33/X39 -> -0.81834027 | Y40: =Y33/Y39 -> -0.67098442 | Z40: =Z33/Z39 -> -0.57122832 | AA40: =AA33/AA39 -> -0.48159758 | AB40: =AB33/AB39 -> -0.41468154 | AC40: =AC33/AC39 -> -0.39546139 | AD40: =AD33/AD39 -> -0.32166952 | ... AG40: =AG33/AG39 -> -0.5526464 | AI40: =SUM(AG40/AC40)-1 -> 0.39747245
A42: X | B42: Balance Sheet | D42: FYE | H42: Quarterly | R42: Quarterly | AC42: LTM | AI42: Variance
B43: =B7 -> Fiscal Period | C43: =C7 -> 2021 | D43: =D7 -> 2022 | E43: =E7 -> 2023 | F43: =F7 -> 2024 | H43: =H7 -> 1Q22 | I43: =I7 -> 2Q22 | J43: =J7 -> 3Q22 | K43: =K7 -> 4Q22 | L43: =L7 -> 1Q23 | M43: =M7 -> 2Q23 | N43: =N7 -> 3Q23 | O43: =O7 -> 4Q23 | ... U43: =U7 -> 2Q25 | W43: =W7 -> 4Q22 | X43: =X7 -> 1Q23 | Y43: =Y7 -> 2Q23 | Z43: =Z7 -> 3Q23 | AA43: =AA7 -> 4Q23 | AB43: =AB7 -> 1Q24 | AC43: =AC7 -> 2Q24 | AD43: =AD7 -> 3Q24 | ... AG43: =AG7 -> 2Q25
B44: =B8 -> Fiscal Period End Date | C44: =C8 -> 44561 | D44: =D8 -> 44926 | E44: =E8 -> 45291 | F44: =F8 -> 45657 | H44: =H8 -> 44651 | I44: =I8 -> 44742 | J44: =J8 -> 44834 | K44: =K8 -> 44926 | L44: =L8 -> 45016 | M44: =M8 -> 45107 | N44: =N8 -> 45199 | O44: =O8 -> 45291 | ... U44: =U8 -> 45838 | W44: =W8 -> 44926 | X44: =X8 -> 45016 | Y44: =Y8 -> 45107 | Z44: =Z8 -> 45199 | AA44: =AA8 -> 45291 | AB44: =AB8 -> 45382 | AC44: =AC8 -> 45473 | AD44: =AD8 -> 45565 | ... AG44: =AG8 -> 45838
B46: Current Assets
B47: Cash and cash equivalents | C47: 11729 | D47: 57888 | E47: 21392 | F47: 67674 | H47: 206626 | I47: 184020 | J47: 73837 | K47: =D47 -> 57888 | L47: 26117 | M47: 21712 | N47: 41757 | O47: =E47 -> 21392 | P47: 35098 | Q47: 20684 | R47: 20286 | S47: =F47 -> 67674 | T47: 37162 | U47: 57183 | W47: =K47 -> 57888 | X47: =L47 -> 26117 | Y47: =M47 -> 21712 | Z47: =N47 -> 41757 | AA47: =O47 -> 21392 | AB47: =P47 -> 35098 | AC47: =Q47 -> 20684 | AD47: =R47 -> 20286 | ... AG47: =U47 -> 57183 | AI47: =SUM(AG47/AC47)-1 -> 1.7646007
B48: Available-for-sale investments | C48: 0 | D48: 84923 | E48: 78537 | F48: 124420 | H48: 0 | I48: 0 | J48: 87186 | K48: =D48 -> 84923 | L48: 95849 | M48: 83765 | N48: 68470 | O48: =E48 -> 78537 | P48: 67661 | Q48: 79792 | R48: 72294 | S48: =F48 -> 124420 | T48: 171966 | U48: 368556 | W48: =K48 -> 84923 | X48: =L48 -> 95849 | Y48: =M48 -> 83765 | Z48: =N48 -> 68470 | AA48: =O48 -> 78537 | AB48: =P48 -> 67661 | AC48: =Q48 -> 79792 | AD48: =R48 -> 72294 | ... AG48: =U48 -> 368556 | AI48: =SUM(AG48/AC48)-1 -> 3.6189593
B49: Accounts receivable | C49: 1543 | D49: 6235 | E49: 5029 | F49: 2427 | H49: 1261 | I49: 2572 | J49: 2295 | K49: =D49 -> 6235 | L49: 5320 | M49: 7629 | N49: 2996 | O49: =E49 -> 5029 | P49: 4706 | Q49: 5232 | R49: 6384 | S49: =F49 -> 2427 | T49: 1068 | U49: 1753 | W49: =K49 -> 6235 | X49: =L49 -> 5320 | Y49: =M49 -> 7629 | Z49: =N49 -> 2996 | AA49: =O49 -> 5029 | AB49: =P49 -> 4706 | AC49: =Q49 -> 5232 | AD49: =R49 -> 6384 | ... AG49: =U49 -> 1753 | AI49: =SUM(AG49/AC49)-1 -> -0.66494648
B50: Prepaid expenses and other current assets (1) | C50: =1351+3449 -> 4800 | D50: =2450+2229+742 -> 5421 | E50: 2709 | F50: =3156+9081 -> 12237 | H50: =4405+2740+151 -> 7296 | I50: =4248+1543 -> 5791 | J50: =3633+742 -> 4375 | K50: =D50 -> 5421 | L50: =1756+1129+94 -> 2979 | M50: =3338+1085 -> 4423 | N50: 3473 | O50: =E50 -> 2709 | P50: 2579 | Q50: 3959 | R50: 4902 | S50: =F50 -> 12237 | T50: =2124+2041 -> 4165 | U50: =3056+3031 -> 6087 | W50: =K50 -> 5421 | X50: =L50 -> 2979 | Y50: =M50 -> 4423 | Z50: =N50 -> 3473 | AA50: =O50 -> 2709 | AB50: =P50 -> 2579 | AC50: =Q50 -> 3959 | AD50: =R50 -> 4902 | ... AG50: =U50 -> 6087 | AI50: =SUM(AG50/AC50)-1 -> 0.53750947
B51: Total Current Assets | C51: =SUM(C47:C50) -> 18072 | D51: =SUM(D47:D50) -> 154467 | E51: =SUM(E47:E50) -> 107667 | F51: =SUM(F47:F50) -> 206758 | H51: =SUM(H47:H50) -> 215183 | I51: =SUM(I47:I50) -> 192383 | J51: =SUM(J47:J50) -> 167693 | K51: =SUM(K47:K50) -> 154467 | L51: =SUM(L47:L50) -> 130265 | M51: =SUM(M47:M50) -> 117529 | N51: =SUM(N47:N50) -> 116696 | O51: =SUM(O47:O50) -> 107667 | ... U51: =SUM(U47:U50) -> 433579 | W51: =SUM(W47:W50) -> 154467 | X51: =SUM(X47:X50) -> 130265 | Y51: =SUM(Y47:Y50) -> 117529 | Z51: =SUM(Z47:Z50) -> 116696 | AA51: =SUM(AA47:AA50) -> 107667 | AB51: =SUM(AB47:AB50) -> 110044 | AC51: =SUM(AC47:AC50) -> 109667 | AD51: =SUM(AD47:AD50) -> 103866 | ... AG51: =SUM(AG47:AG50) -> 433579 | AI51: =SUM(AG51/AC51)-1 -> 2.9535959
...

Sheet Revenue Drivers
B2: Rigetti Computing Inc. (NASDAQ: RGTI) | H2: Quarterly | P2: Quarterly | Q2: Quarterly | W2: LTM | AA2: LTM | AC2: LTM
B3: Segment Anaysis | C3: ='Historical Financials'!C7 -> 2021 | D3: ='Historical Financials'!D7 -> 2022 | E3: ='Historical Financials'!E7 -> 2023 | F3: ='Historical Financials'!F7 -> 2024 | H3: ='Historical Financials'!H7 -> 1Q22 | I3: ='Historical Financials'!I7 -> 2Q22 | J3: ='Historical Financials'!J7 -> 3Q22 | K3: ='Historical Financials'!K7 -> 4Q22 | L3: ='Historical Financials'!L7 -> 1Q23 | M3: ='Historical Financials'!M7 -> 2Q23 | N3: ='Historical Financials'!N7 -> 3Q23 | O3: ='Historical Financials'!O7 -> 4Q23 | ... U3: ='Historical Financials'!U7 -> 2Q25 | W3: =L3 -> 1Q23 | X3: =M3 -> 2Q23 | Y3: =N3 -> 3Q23 | Z3: =O3 -> 4Q23 | AA3: =P3 -> 1Q24 | AB3: =Q3 -> 2Q24 | AC3: =S3 -> 4Q24 | AD3: =T3 -> 1Q25 | AE3: =U3 -> 2Q25 | AF3: =#REF! -> #REF!
B4: $ in thousands except per share | C4: ='Historical Financials'!C8 -> 44561 | D4: ='Historical Financials'!D8 -> 44926 | E4: ='Historical Financials'!E8 -> 45291 | F4: ='Historical Financials'!F8 -> 45657 | H4: ='Historical Financials'!H8 -> 44651 | I4: ='Historical Financials'!I8 -> 44742 | J4: ='Historical Financials'!J8 -> 44834 | K4: ='Historical Financials'!K8 -> 44926 | L4: ='Historical Financials'!L8 -> 45016 | M4: ='Historical Financials'!M8 -> 45107 | N4: ='Historical Financials'!N8 -> 45199 | O4: ='Historical Financials'!O8 -> 45291 | ... U4: ='Historical Financials'!U8 -> 45838 | W4: =L4 -> 45016 | X4: =M4 -> 45107 | Y4: =N4 -> 45199 | Z4: =O4 -> 45291 | AA4: =P4 -> 45382 | AB4: =Q4 -> 45473 | AC4: =S4 -> 45657 | AD4: =T4 -> 45747 | AE4: =U4 -> 45838 | AF4: =#REF! -> #REF!
A6: X | B6: Net Revenues by Channel
B7: Quantum computing and networking hardware | W7: =SUM(I7:L7) -> 0 | X7: =SUM(J7:M7) -> 0 | Y7: =SUM(K7:N7) -> 0 | Z7: =SUM(L7:O7) -> 0 | AA7: =SUM(M7:P7) -> 0 | AB7: =SUM(N7:Q7) -> 0 | AC7: =SUM(P7:S7) -> 0 | AD7: =SUM(Q7:T7) -> 0 | AE7: =SUM(R7:U7) -> 0 | AF7: =SUM(S7:U7) -> 0
B8: Platform, consulting and support services | W8: =SUM(I8:L8) -> 0 | X8: =SUM(J8:M8) -> 0 | Y8: =SUM(K8:N8) -> 0 | Z8: =SUM(L8:O8) -> 0 | AA8: =SUM(M8:P8) -> 0 | AB8: =SUM(N8:Q8) -> 0 | AC8: =SUM(P8:S8) -> 0 | AD8: =SUM(Q8:T8) -> 0 | AE8: =SUM(R8:U8) -> 0 | AF8: =SUM(S8:U8) -> 0
B9: Total Net Revenue | D9: =SUM(D7:D8) -> 0 | E9: =SUM(E7:E8) -> 0 | F9: =SUM(F7:F8) -> 0 | P9: =SUM(P7:P8) -> 0 | Q9: =SUM(Q7:Q8) -> 0 | R9: =SUM(R7:R8) -> 0 | S9: =SUM(S7:S8) -> 0 | T9: =SUM(T7:T8) -> 0 | U9: =SUM(U7:U8) -> 0 | W9: =SUM(W7:W8) -> 0 | X9: =SUM(X7:X8) -> 0 | Y9: =SUM(Y7:Y8) -> 0 | Z9: =SUM(Z7:Z8) -> 0 | AA9: =SUM(AA7:AA8) -> 0 | AB9: =SUM(AB7:AB8) -> 0 | AC9: =SUM(AC7:AC8) -> 0 | AD9: =SUM(AD7:AD8) -> 0 | ... AF9: =SUM(AF7:AF8) -> 0
B10: Balance Check | D10: =+D9-'Historical Financials'!D11 -> -13102 | E10: =+E9-'Historical Financials'!E11 -> -12008 | F10: =+F9-'Historical Financials'!F11 -> -10790 | P10: =+P9-'Historical Financials'!P11 -> -3052 | Q10: =+Q9-'Historical Financials'!Q11 -> -3086 | R10: =+R9-'Historical Financials'!R11 -> -2378 | S10: =+S9-'Historical Financials'!S11 -> -2274 | T10: =+T9-'Historical Financials'!T11 -> -1472 | U10: =+U9-'Historical Financials'!U11 -> -1801 | W10: =W9-'Historical Financials'!W11 -> -13102 | X10: =X9-'Historical Financials'!X11 -> -13199 | Y10: =Y9-'Historical Financials'!Y11 -> -14392 | Z10: =Z9-'Historical Financials'!Z11 -> -14693 | AA10: =AA9-'Historical Financials'!AA11 -> -12008 | AB10: =AB9-'Historical Financials'!AB11 -> -12859 | AC10: =AC9-'Historical Financials'!AD11 -> -11891 | AD10: =AD9-'Historical Financials'!AE11 -> -10790 | AE10: =AE9-'Historical Financials'!AF11 -> -9210 | AF10: =AF9-'Historical Financials'!AG11 -> -7925
A12: X | B12: Revenue by Channel: U.S
B13: United States | W13: =SUM(I13:L13) -> 0 | X13: =SUM(J13:M13) -> 0 | Y13: =SUM(K13:N13) -> 0 | Z13: =SUM(L13:O13) -> 0 | AA13: =SUM(M13:P13) -> 0 | AB13: =SUM(N13:Q13) -> 0 | AC13: =SUM(P13:S13) -> 0 | AD13: =SUM(Q13:T13) -> 0 | AE13: =SUM(R13:U13) -> 0 | AF13: =SUM(S13:U13) -> 0
B14: International | W14: =SUM(I14:L14) -> 0 | X14: =SUM(J14:M14) -> 0 | Y14: =SUM(K14:N14) -> 0 | Z14: =SUM(L14:O14) -> 0 | AA14: =SUM(M14:P14) -> 0 | AB14: =SUM(N14:Q14) -> 0 | AC14: =SUM(P14:S14) -> 0 | AD14: =SUM(Q14:T14) -> 0 | AE14: =SUM(R14:U14) -> 0 | AF14: =SUM(S14:U14) -> 0
B15: Total Net U.S Revenue | D15: =SUM(D13:D14) -> 0 | E15: =SUM(E13:E14) -> 0 | F15: =SUM(F13:F14) -> 0 | P15: =SUM(P13:P14) -> 0 | Q15: =SUM(Q13:Q14) -> 0 | R15: =SUM(R13:R14) -> 0 | S15: =SUM(S13:S14) -> 0 | T15: =SUM(T13:T14) -> 0 | U15: =SUM(U13:U14) -> 0 | W15: =SUM(W13:W14) -> 0 | X15: =SUM(X13:X14) -> 0 | Y15: =SUM(Y13:Y14) -> 0 | Z15: =SUM(Z13:Z14) -> 0 | AA15: =SUM(AA13:AA14) -> 0 | AB15: =SUM(AB13:AB14) -> 0 | AC15: =SUM(AC13:AC14) -> 0 | AD15: =SUM(AD13:AD14) -> 0 | ... AF15: =SUM(AF13:AF14) -> 0
B16: Balance Check | D16: =+D15-D9 -> 0 | E16: =+E15-E9 -> 0 | F16: =+F15-F9 -> 0 | P16: =+P15-P9 -> 0 | Q16: =+Q15-Q9 -> 0 | R16: =+R15-R9 -> 0 | S16: =+S15-S9 -> 0 | T16: =+T15-T9 -> 0 | U16: =+U15-U9 -> 0 | W16: =W15-'Historical Financials'!W17 -> 61210 | X16: =X15-'Historical Financials'!X17 -> 61795 | Y16: =Y15-'Historical Financials'!Y17 -> 57486 | Z16: =Z15-'Historical Financials'!Z17 -> 52768 | AA16: =AA15-'Historical Financials'!AA17 -> 50532 | AB16: =AB15-'Historical Financials'!AB17 -> 49183 | AC16: =+AC15-AC9 -> 0 | AD16: =+AD15-AD9 -> 0 | AE16: =+AE15-AE9 -> 0 | AF16: =+AF15-AF9 -> 0

Sheet FCF
B2: IonQ, Inc. (NASDAQ: IONQ) | D2: FYE | H2: Quarterly | Q2: Quarterly | R2: Quarterly | X2: LTM | AE2: LTM | AK2: Variance
B3: FCF Analysis | C3: ='Historical Financials'!C7 -> 2021 | D3: ='Historical Financials'!D7 -> 2022 | E3: ='Historical Financials'!E7 -> 2023 | F3: ='Historical Financials'!F7 -> 2024 | H3: ='Historical Financials'!H7 -> 1Q22 | I3: ='Historical Financials'!I7 -> 2Q22 | J3: ='Historical Financials'!J7 -> 3Q22 | K3: ='Historical Financials'!K7 -> 4Q22 | L3: ='Historical Financials'!L7 -> 1Q23 | M3: ='Historical Financials'!M7 -> 2Q23 | N3: ='Historical Financials'!N7 -> 3Q23 | O3: ='Historical Financials'!O7 -> 4Q23 | ... U3: ='Historical Financials'!U7 -> 2Q25 | V3: ='Historical Financials'!#REF! -> #REF! | X3: =K3 -> 4Q22 | Y3: =L3 -> 1Q23 | Z3: =M3 -> 2Q23 | AA3: =N3 -> 3Q23 | AB3: =O3 -> 4Q23 | AC3: =P3 -> 1Q24 | AD3: =Q3 -> 2Q24 | AE3: =R3 -> 3Q24 | ... AI3: =V3 -> #REF!
B4: $ in thousands except per share | C4: ='Historical Financials'!C8 -> 44561 | D4: ='Historical Financials'!D8 -> 44926 | E4: ='Historical Financials'!E8 -> 45291 | F4: ='Historical Financials'!F8 -> 45657 | H4: ='Historical Financials'!H8 -> 44651 | I4: ='Historical Financials'!I8 -> 44742 | J4: ='Historical Financials'!J8 -> 44834 | K4: ='Historical Financials'!K8 -> 44926 | L4: ='Historical Financials'!L8 -> 45016 | M4: ='Historical Financials'!M8 -> 45107 | N4: ='Historical Financials'!N8 -> 45199 | O4: ='Historical Financials'!O8 -> 45291 | ... U4: ='Historical Financials'!U8 -> 45838 | V4: ='Historical Financials'!#REF! -> #REF! | X4: =K4 -> 44926 | Y4: =L4 -> 45016 | Z4: =M4 -> 45107 | AA4: =N4 -> 45199 | AB4: =O4 -> 45291 | AC4: =P4 -> 45382 | AD4: =Q4 -> 45473 | AE4: =R4 -> 45565 | ... AI4: =V4 -> #REF!
B6: ='Revenue Drivers'!B7 -> Quantum computing and networking hardware | D6: ='Revenue Drivers'!D7 -> 0 | E6: ='Revenue Drivers'!E7 -> 0 | F6: ='Revenue Drivers'!F7 -> 0 | P6: ='Revenue Drivers'!P7 -> 0 | Q6: ='Revenue Drivers'!Q7 -> 0 | R6: ='Revenue Drivers'!R7 -> 0 | S6: ='Revenue Drivers'!S7 -> 0 | T6: ='Revenue Drivers'!T7 -> 0 | U6: ='Revenue Drivers'!U7 -> 0 | V6: ='Revenue Drivers'!#REF! -> #REF! | AC6: =SUM(M6:P6) -> 0 | AD6: =SUM(N6:Q6) -> 0 | AE6: =SUM(O6:R6) -> 0 | AF6: =SUM(P6:S6) -> 0 | AG6: =SUM(Q6:T6) -> 0 | AH6: =SUM(R6:U6) -> 0 | AI6: =SUM(S6:V6) -> #REF! | AK6: =SUM(AI6/AE6)-1 -> #REF!
B7: ='Revenue Drivers'!B8 -> Platform, consulting and support services | D7: ='Revenue Drivers'!D8 -> 0 | E7: ='Revenue Drivers'!E8 -> 0 | F7: ='Revenue Drivers'!F8 -> 0 | P7: ='Revenue Drivers'!P8 -> 0 | Q7: ='Revenue Drivers'!Q8 -> 0 | R7: ='Revenue Drivers'!R8 -> 0 | S7: ='Revenue Drivers'!S8 -> 0 | T7: ='Revenue Drivers'!T8 -> 0 | U7: ='Revenue Drivers'!U8 -> 0 | V7: ='Revenue Drivers'!#REF! -> #REF! | AC7: =SUM(M7:P7) -> 0 | AD7: =SUM(N7:Q7) -> 0 | AE7: =SUM(O7:R7) -> 0 | AF7: =SUM(P7:S7) -> 0 | AG7: =SUM(Q7:T7) -> 0 | AH7: =SUM(R7:U7) -> 0 | AI7: =SUM(S7:V7) -> #REF! | AK7: =SUM(AI7/AE7)-1 -> #REF!
B8: Total Revenue | C8: ='Historical Financials'!C11 -> 8196 | D8: =SUM(D6:D7) -> 0 | E8: =SUM(E6:E7) -> 0 | F8: =SUM(F6:F7) -> 0 | H8: ='Historical Financials'!H11 -> 2104 | I8: ='Historical Financials'!I11 -> 2134 | J8: ='Historical Financials'!J11 -> 2804 | K8: ='Historical Financials'!K11 -> 6060 | L8: ='Historical Financials'!L11 -> 2201 | M8: ='Historical Financials'!M11 -> 3327 | N8: ='Historical Financials'!N11 -> 3105 | O8: ='Historical Financials'!O11 -> 3375 | P8: =SUM(P6:P7) -> 0 | Q8: =SUM(Q6:Q7) -> 0 | R8: =SUM(R6:R7) -> 0 | S8: =SUM(S6:S7) -> 0 | T8: =SUM(T6:T7) -> 0 | U8: =SUM(U6:U7) -> 0 | V8: =SUM(V6:V7) -> #REF! | X8: =SUM(H8:K8) -> 13102 | Y8: =SUM(I8:L8) -> 13199 | Z8: =SUM(J8:M8) -> 14392 | AA8: =SUM(K8:N8) -> 14693 | AB8: =SUM(L8:O8) -> 12008 | AC8: =SUM(AC6:AC7) -> 0 | AD8: =SUM(AD6:AD7) -> 0 | AE8: =SUM(AE6:AE7) -> 0 | AF8: =SUM(AF6:AF7) -> 0 | AG8: =SUM(AG6:AG7) -> 0 | AH8: =SUM(AH6:AH7) -> 0 | AI8: =SUM(AI6:AI7) -> #REF! | AK8: =SUM(AI8/AE8)-1 -> #REF!
B9: Y/Y Growth (%) | D9: =SUM(D8/C8)-1 -> -1 | E9: =SUM(E8/D8)-1 -> #DIV/0! | F9: =SUM(F8/E8)-1 -> #DIV/0! | M9: =SUM(M8/I8)-1 -> 0.55904405 | N9: =SUM(N8/J8)-1 -> 0.10734665 | O9: =SUM(O8/K8)-1 -> -0.44306931 | P9: =SUM(P8/L8)-1 -> -1 | Q9: =SUM(Q8/M8)-1 -> -1 | R9: =SUM(R8/N8)-1 -> -1 | S9: =SUM(S8/O8)-1 -> -1 | T9: =SUM(T8/P8)-1 -> #DIV/0! | ... V9: =SUM(V8/R8)-1 -> #REF! | AB9: =SUM(AB8/X8)-1 -> -0.083498702 | AC9: =SUM(AC8/Y8)-1 -> -1 | AD9: =SUM(AD8/Z8)-1 -> -1 | AE9: =SUM(AE8/AA8)-1 -> -1 | AF9: =SUM(AF8/AB8)-1 -> -1 | AG9: =SUM(AG8/AC8)-1 -> #DIV/0! | AH9: =SUM(AH8/AD8)-1 -> #DIV/0! | AI9: =SUM(AI8/AE8)-1 -> #REF! | AK9: =SUM(AI9-AE9)*10000 -> #REF!
B10: Q/Q Growth (%) | C10: N/A | D10: N/A | E10: N/A | F10: N/A | J10: =SUM(J8/I8)-1 -> 0.31396439 | K10: =SUM(K8/J8)-1 -> 1.1611983 | L10: =SUM(L8/K8)-1 -> -0.63679868 | M10: =SUM(M8/L8)-1 -> 0.51158564 | N10: =SUM(N8/M8)-1 -> -0.066726781 | O10: =SUM(O8/N8)-1 -> 0.086956522 | P10: =SUM(P8/O8)-1 -> -1 | Q10: =SUM(Q8/P8)-1 -> #DIV/0! | ... V10: =SUM(V8/U8)-1 -> #REF! | X10: N/A | Y10: N/A | Z10: N/A | AA10: N/A | AB10: N/A | AC10: N/A | AD10: N/A | AE10: N/A | AF10: N/A | AG10: N/A | AH10: N/A | AI10: N/A
B12: (-) Cost of Sales | C12: ='Historical Financials'!C13 -> -1623 | D12: ='Historical Financials'!D13 -> -2873 | E12: ='Historical Financials'!E13 -> -2800 | F12: ='Historical Financials'!F13 -> -5093 | H12: ='Historical Financials'!H13 -> -414 | I12: ='Historical Financials'!I13 -> -873 | J12: ='Historical Financials'!J13 -> -776 | K12: ='Historical Financials'!K13 -> -810 | L12: ='Historical Financials'!L13 -> -510 | M12: ='Historical Financials'!M13 -> -597 | N12: ='Historical Financials'!N13 -> -834 | O12: ='Historical Financials'!O13 -> -859 | ... U12: ='Historical Financials'!U13 -> -1235 | V12: ='Historical Financials'!#REF! -> #REF! | X12: =SUM(G12:K12) -> -2873 | Y12: =SUM(I12:L12) -> -2969 | Z12: =SUM(J12:M12) -> -2693 | AA12: =SUM(K12:N12) -> -2751 | AB12: =SUM(L12:O12) -> -2800 | AC12: =SUM(M12:P12) -> -3842 | AD12: =SUM(N12:Q12) -> -4341 | AE12: =SUM(O12:R12) -> -4681 | AF12: =SUM(P12:S12) -> -5093 | ... AI12: =SUM(S12:V12) -> #REF! | AK12: =SUM(AI12/AE12)-1 -> #REF!
B13: Gross Profit | C13: =+C8+C12 -> 6573 | D13: =+D8+D12 -> -2873 | E13: =+E8+E12 -> -2800 | F13: =+F8+F12 -> -5093 | H13: =+H8+H12 -> 1690 | I13: =+I8+I12 -> 1261 | J13: =+J8+J12 -> 2028 | K13: =+K8+K12 -> 5250 | L13: =+L8+L12 -> 1691 | M13: =+M8+M12 -> 2730 | N13: =+N8+N12 -> 2271 | O13: =+O8+O12 -> 2516 | ... V13: =+V8+V12 -> #REF! | X13: =+X8+X12 -> 10229 | Y13: =+Y8+Y12 -> 10230 | Z13: =+Z8+Z12 -> 11699 | AA13: =+AA8+AA12 -> 11942 | AB13: =+AB8+AB12 -> 9208 | AC13: =+AC8+AC12 -> -3842 | AD13: =+AD8+AD12 -> -4341 | AE13: =+AE8+AE12 -> -4681 | ... AI13: =+AI8+AI12 -> #REF! | AK13: =SUM(AI13/AE13)-1 -> #REF!
B14: Gross Margin (%) | C14: =C13/C8 -> 0.80197657 | D14: =D13/D8 -> #DIV/0! | E14: =E13/E8 -> #DIV/0! | F14: =F13/F8 -> #DIV/0! | H14: =H13/H8 -> 0.80323194 | I14: =I13/I8 -> 0.59090909 | J14: =J13/J8 -> 0.7232525 | K14: =K13/K8 -> 0.86633663 | L14: =L13/L8 -> 0.76828714 | M14: =M13/M8 -> 0.82055906 | N14: =N13/N8 -> 0.73140097 | O14: =O13/O8 -> 0.74548148 | ... V14: =V13/V8 -> #REF! | X14: =X13/X8 -> 0.7807205 | Y14: =Y13/Y8 -> 0.77505872 | Z14: =Z13/Z8 -> 0.81288216 | AA14: =AA13/AA8 -> 0.81276798 | AB14: =AB13/AB8 -> 0.76682212 | AC14: =AC13/AC8 -> #DIV/0! | AD14: =AD13/AD8 -> #DIV/0! | AE14: =AE13/AE8 -> #DIV/0! | ... AI14: =AI13/AI8 -> #REF! | AK14: =SUM(AI14-AE14)*10000 -> #REF!
B16: (-) Research and development | C16: ='Historical Financials'!C17 -> -26928 | D16: ='Historical Financials'!D17 -> -59952 | E16: ='Historical Financials'!E17 -> -52768 | F16: ='Historical Financials'!F17 -> -49750 | H16: ='Historical Financials'!H17 -> -12449 | I16: ='Historical Financials'!I17 -> -12634 | J16: ='Historical Financials'!J17 -> -17365 | K16: ='Historical Financials'!K17 -> -17504 | L16: ='Historical Financials'!L17 -> -13707 | M16: ='Historical Financials'!M17 -> -13219 | N16: ='Historical Financials'!N17 -> -13056 | O16: ='Historical Financials'!O17 -> -12786 | ... U16: ='Historical Financials'!U17 -> -13522 | V16: ='Historical Financials'!#REF! -> #REF! | X16: =SUM(G16:K16) -> -59952 | Y16: =SUM(I16:L16) -> -61210 | Z16: =SUM(J16:M16) -> -61795 | AA16: =SUM(K16:N16) -> -57486 | AB16: =SUM(L16:O16) -> -52768 | AC16: =SUM(M16:P16) -> -50532 | AD16: =SUM(N16:Q16) -> -49183 | AE16: =SUM(O16:R16) -> -48879 | AF16: =SUM(P16:S16) -> -49750 | ... AI16: =SUM(S16:V16) -> #REF! | AK16: =SUM(AI16/AE16)-1 -> #REF!
B17: (-) Sales and marketing | C17: ='Historical Financials'!C18 -> -13774 | D17: ='Historical Financials'!D18 -> -53980 | E17: ='Historical Financials'!E18 -> -27744 | F17: ='Historical Financials'!F18 -> -24457 | H17: ='Historical Financials'!H18 -> -13035 | I17: ='Historical Financials'!I18 -> -14272 | J17: ='Historical Financials'!J18 -> -15987 | K17: ='Historical Financials'!K18 -> -10686 | L17: ='Historical Financials'!L18 -> -9013 | M17: ='Historical Financials'!M18 -> -5747 | N17: ='Historical Financials'!N18 -> -6047 | O17: ='Historical Financials'!O18 -> -6937 | ... U17: ='Historical Financials'!U18 -> -6926 | V17: ='Historical Financials'!#REF! -> #REF! | X17: =SUM(G17:K17) -> -53980 | Y17: =SUM(I17:L17) -> -49958 | Z17: =SUM(J17:M17) -> -41433 | AA17: =SUM(K17:N17) -> -31493 | AB17: =SUM(L17:O17) -> -27744 | AC17: =SUM(M17:P17) -> -25345 | AD17: =SUM(N17:Q17) -> -25803 | AE17: =SUM(O17:R17) -> -25554 | AF17: =SUM(P17:S17) -> -24457 | ... AI17: =SUM(S17:V17) -> #REF! | AK17: =SUM(AI17/AE17)-1 -> #REF!
B18: (-) General and administrative | C18: ='Historical Financials'!#REF! -> #REF! | D18: ='Historical Financials'!#REF! -> #REF! | E18: ='Historical Financials'!#REF! -> #REF! | F18: ='Historical Financials'!#REF! -> #REF! | H18: ='Historical Financials'!#REF! -> #REF! | I18: ='Historical Financials'!#REF! -> #REF! | J18: ='Historical Financials'!#REF! -> #REF! | K18: ='Historical Financials'!#REF! -> #REF! | L18: ='Historical Financials'!#REF! -> #REF! | M18: ='Historical Financials'!#REF! -> #REF! | N18: ='Historical Financials'!#REF! -> #REF! | O18: ='Historical Financials'!#REF! -> #REF! | ... V18: ='Historical Financials'!#REF! -> #REF! | X18: =SUM(G18:K18) -> #REF! | Y18: =SUM(I18:L18) -> #REF! | Z18: =SUM(J18:M18) -> #REF! | AA18: =SUM(K18:N18) -> #REF! | AB18: =SUM(L18:O18) -> #REF! | AC18: =SUM(M18:P18) -> #REF! | AD18: =SUM(N18:Q18) -> #REF! | AE18: =SUM(O18:R18) -> #REF! | AF18: =SUM(P18:S18) -> #REF! | ... AI18: =SUM(S18:V18) -> #REF! | AK18: =SUM(AI18/AE18)-1 -> #REF!
B19: (-) Depreciation and amortization | C19: ='Historical Financials'!C19 -> 0 | D19: ='Historical Financials'!D19 -> -5377 | E19: ='Historical Financials'!E19 -> -991 | F19: ='Historical Financials'!F19 -> 0 | H19: ='Historical Financials'!H19 -> 0 | I19: ='Historical Financials'!I19 -> 0 | J19: ='Historical Financials'!J19 -> 0 | K19: ='Historical Financials'!K19 -> -5377 | L19: ='Historical Financials'!L19 -> -991 | M19: ='Historical Financials'!M19 -> 0 | N19: ='Historical Financials'!N19 -> 0 | O19: ='Historical Financials'!O19 -> 0 | ... U19: ='Historical Financials'!U19 -> 0 | V19: ='Historical Financials'!#REF! -> #REF! | X19: =SUM(G19:K19) -> -5377 | Y19: =SUM(I19:L19) -> -6368 | Z19: =SUM(J19:M19) -> -6368 | AA19: =SUM(K19:N19) -> -6368 | AB19: =SUM(L19:O19) -> -991 | AC19: =SUM(M19:P19) -> 0 | AD19: =SUM(N19:Q19) -> 0 | AE19: =SUM(O19:R19) -> 0 | AF19: =SUM(P19:S19) -> 0 | ... AI19: =SUM(S19:V19) -> #REF! | AK19: =SUM(AI19/AE19)-1 -> #REF!
B20: Earning before Interest & Taxes (EBIT) | C20: =SUM(C13+SUM(C16:C19)) -> #REF! | D20: =SUM(D13+SUM(D16:D19)) -> #REF! | E20: =SUM(E13+SUM(E16:E19)) -> #REF! | F20: =SUM(F13+SUM(F16:F19)) -> #REF! | H20: =SUM(H13+SUM(H16:H19)) -> #REF! | I20: =SUM(I13+SUM(I16:I19)) -> #REF! | J20: =SUM(J13+SUM(J16:J19)) -> #REF! | K20: =SUM(K13+SUM(K16:K19)) -> #REF! | L20: =SUM(L13+SUM(L16:L19)) -> #REF! | M20: =SUM(M13+SUM(M16:M19)) -> #REF! | N20: =SUM(N13+SUM(N16:N19)) -> #REF! | O20: =SUM(O13+SUM(O16:O19)) -> #REF! | ... V20: =SUM(V13+SUM(V16:V19)) -> #REF! | X20: =SUM(X13+SUM(X16:X19)) -> #REF! | Y20: =SUM(Y13+SUM(Y16:Y19)) -> #REF! | Z20: =SUM(Z13+SUM(Z16:Z19)) -> #REF! | AA20: =SUM(AA13+SUM(AA16:AA19)) -> #REF! | AB20: =SUM(AB13+SUM(AB16:AB19)) -> #REF! | AC20: =SUM(AC13+SUM(AC16:AC19)) -> #REF! | AD20: =SUM(AD13+SUM(AD16:AD19)) -> #REF! | AE20: =SUM(AE13+SUM(AE16:AE19)) -> #REF! | ... AI20: =SUM(AI13+SUM(AI16:AI19)) -> #REF! | AK20: =SUM(AI20/AE20)-1 -> #REF!
B21: Operating Margin (%) | C21: =C20/C8 -> #REF! | D21: =D20/D8 -> #REF! | E21: =E20/E8 -> #REF! | F21: =F20/F8 -> #REF! | H21: =H20/H8 -> #REF! | I21: =I20/I8 -> #REF! | J21: =J20/J8 -> #REF! | K21: =K20/K8 -> #REF! | L21: =L20/L8 -> #REF! | M21: =M20/M8 -> #REF! | N21: =N20/N8 -> #REF! | O21: =O20/O8 -> #REF! | ... V21: =V20/V8 -> #REF! | X21: =X20/X8 -> #REF! | Y21: =Y20/Y8 -> #REF! | Z21: =Z20/Z8 -> #REF! | AA21: =AA20/AA8 -> #REF! | AB21: =AB20/AB8 -> #REF! | AC21: =AC20/AC8 -> #REF! | AD21: =AD20/AD8 -> #REF! | AE21: =AE20/AE8 -> #REF! | ... AI21: =AI20/AI8 -> #REF! | AK21: =SUM(AI21-AE21)*10000 -> #REF!
B23: (+) Depreciation and Amortization | C23: =-C19 -> 0 | D23: =-D19 -> 5377 | E23: =-E19 -> 991 | F23: =-F19 -> 0 | H23: =-H19 -> 0 | I23: =-I19 -> 0 | J23: =-J19 -> 0 | K23: =-K19 -> 5377 | L23: =-L19 -> 991 | M23: =-M19 -> 0 | N23: =-N19 -> 0 | O23: =-O19 -> 0 | ... V23: =-V19 -> #REF! | X23: =SUM(G23:K23) -> 5377 | Y23: =SUM(I23:L23) -> 6368 | Z23: =SUM(J23:M23) -> 6368 | AA23: =SUM(K23:N23) -> 6368 | AB23: =SUM(L23:O23) -> 991 | AC23: =SUM(M23:P23) -> 0 | AD23: =SUM(N23:Q23) -> 0 | AE23: =SUM(O23:R23) -> 0 | AF23: =SUM(P23:S23) -> 0 | ... AI23: =SUM(S23:V23) -> #REF! | AK23: =SUM(AI23/AE23)-1 -> #REF!
B24: EBITDA | C24: =SUM(C20+C23) -> #REF! | D24: =SUM(D20+D23) -> #REF! | E24: =SUM(E20+E23) -> #REF! | F24: =SUM(F20+F23) -> #REF! | H24: =SUM(H20+H23) -> #REF! | I24: =SUM(I20+I23) -> #REF! | J24: =SUM(J20+J23) -> #REF! | K24: =SUM(K20+K23) -> #REF! | L24: =SUM(L20+L23) -> #REF! | M24: =SUM(M20+M23) -> #REF! | N24: =SUM(N20+N23) -> #REF! | O24: =SUM(O20+O23) -> #REF! | ... V24: =SUM(V20+V23) -> #REF! | X24: =SUM(X20+X23) -> #REF! | Y24: =SUM(Y20+Y23) -> #REF! | Z24: =SUM(Z20+Z23) -> #REF! | AA24: =SUM(AA20+AA23) -> #REF! | AB24: =SUM(AB20+AB23) -> #REF! | AC24: =SUM(AC20+AC23) -> #REF! | AD24: =SUM(AD20+AD23) -> #REF! | AE24: =SUM(AE20+AE23) -> #REF! | ... AI24: =SUM(AI20+AI23) -> #REF! | AK24: =SUM(AI24/AE24)-1 -> #REF!
B25: EBITDA Margin (%) | C25: =C24/C8 -> #REF! | D25: =D24/D8 -> #REF! | E25: =E24/E8 -> #REF! | F25: =F24/F8 -> #REF! | H25: =H24/H8 -> #REF! | I25: =I24/I8 -> #REF! | J25: =J24/J8 -> #REF! | K25: =K24/K8 -> #REF! | L25: =L24/L8 -> #REF! | M25: =M24/M8 -> #REF! | N25: =N24/N8 -> #REF! | O25: =O24/O8 -> #REF! | ... V25: =V24/V8 -> #REF! | X25: =X24/X8 -> #REF! | Y25: =Y24/Y8 -> #REF! | Z25: =Z24/Z8 -> #REF! | AA25: =AA24/AA8 -> #REF! | AB25: =AB24/AB8 -> #REF! | AC25: =AC24/AC8 -> #REF! | AD25: =AD24/AD8 -> #REF! | AE25: =AE24/AE8 -> #REF! | ... AI25: =AI24/AI8 -> #REF! | AK25: =SUM(AI25-AE25)*10000 -> #REF!
B27: (+) Share-based Compensation | C27: ='Historical Financials'!C102 -> 1765 | D27: ='Historical Financials'!D102 -> 44812 | E27: ='Historical Financials'!E102 -> 12409 | F27: ='Historical Financials'!F102 -> 13069 | H27: ='Historical Financials'!H102 -> 11481 | I27: ='Historical Financials'!I102 -> 11041 | J27: ='Historical Financials'!J102 -> 15121 | K27: ='Historical Financials'!K102 -> 7169 | L27: ='Historical Financials'!L102 -> 1703 | M27: ='Historical Financials'!M102 -> 3355 | N27: ='Historical Financials'!N102 -> 3669 | O27: ='Historical Financials'!O102 -> 3682 | ... U27: ='Historical Financials'!U102 -> 3554 | V27: ='Historical Financials'!#REF! -> #REF! | X27: =SUM(G27:K27) -> 44812 | Y27: =SUM(I27:L27) -> 35034 | Z27: =SUM(J27:M27) -> 27348 | AA27: =SUM(K27:N27) -> 15896 | AB27: =SUM(L27:O27) -> 12409 | AC27: =SUM(M27:P27) -> 13697 | AD27: =SUM(N27:Q27) -> 13629 | AE27: =SUM(O27:R27) -> 13387 | AF27: =SUM(P27:S27) -> 13069 | ... AI27: =SUM(S27:V27) -> #REF! | AK27: =SUM(AI27/AE27)-1 -> #REF!
B28: Adj. EBITDA | C28: =+SUM(C24+SUM(C27:C27)) -> #REF! | D28: =+SUM(D24+SUM(D27:D27)) -> #REF! | E28: =+SUM(E24+SUM(E27:E27)) -> #REF! | F28: =+SUM(F24+SUM(F27:F27)) -> #REF! | H28: =+SUM(H24+SUM(H27:H27)) -> #REF! | I28: =+SUM(I24+SUM(I27:I27)) -> #REF! | J28: =+SUM(J24+SUM(J27:J27)) -> #REF! | K28: =+SUM(K24+SUM(K27:K27)) -> #REF! | L28: =+SUM(L24+SUM(L27:L27)) -> #REF! | M28: =+SUM(M24+SUM(M27:M27)) -> #REF! | N28: =+SUM(N24+SUM(N27:N27)) -> #REF! | O28: =+SUM(O24+SUM(O27:O27)) -> #REF! | ... V28: =+SUM(V24+SUM(V27:V27)) -> #REF! | X28: =+SUM(X24+SUM(X27:X27)) -> #REF! | Y28: =+SUM(Y24+SUM(Y27:Y27)) -> #REF! | Z28: =+SUM(Z24+SUM(Z27:Z27)) -> #REF! | AA28: =+SUM(AA24+SUM(AA27:AA27)) -> #REF! | AB28: =+SUM(AB24+SUM(AB27:AB27)) -> #REF! | AC28: =+SUM(AC24+SUM(AC27:AC27)) -> #REF! | AD28: =+SUM(AD24+SUM(AD27:AD27)) -> #REF! | AE28: =+SUM(AE24+SUM(AE27:AE27)) -> #REF! | ... AI28: =+SUM(AI24+SUM(AI27:AI27)) -> #REF! | AK28: =SUM(AI28/AE28)-1 -> #REF!
B29: Adj. EBITDA Margin (%) | C29: =C28/C8 -> #REF! | D29: =D28/D8 -> #REF! | E29: =E28/E8 -> #REF! | F29: =F28/F8 -> #REF! | H29: =H28/H8 -> #REF! | I29: =I28/I8 -> #REF! | J29: =J28/J8 -> #REF! | K29: =K28/K8 -> #REF! | L29: =L28/L8 -> #REF! | M29: =M28/M8 -> #REF! | N29: =N28/N8 -> #REF! | O29: =O28/O8 -> #REF! | ... V29: =V28/V8 -> #REF! | X29: =X28/X8 -> #REF! | Y29: =Y28/Y8 -> #REF! | Z29: =Z28/Z8 -> #REF! | AA29: =AA28/AA8 -> #REF! | AB29: =AB28/AB8 -> #REF! | AC29: =AC28/AC8 -> #REF! | AD29: =AD28/AD8 -> #REF! | AE29: =AE28/AE8 -> #REF! | ... AI29: =AI28/AI8 -> #REF! | AK29: =SUM(AI29-AE29)*10000 -> #REF!
B31: (-) Capital Expenditures | C31: =SUM('Historical Financials'!C124+'Historical Financials'!C125) -> -7008 | D31: =SUM('Historical Financials'!D124+'Historical Financials'!D125) -> -107024 | E31: =SUM('Historical Financials'!E124+'Historical Financials'!E125) -> 773 | F31: =SUM('Historical Financials'!F124+'Historical Financials'!F125) -> -78362 | H31: =SUM('Historical Financials'!H124+'Historical Financials'!H125) -> -2836 | I31: =SUM('Historical Financials'!I124+'Historical Financials'!I125) -> 13472 | J31: =SUM('Historical Financials'!J124+'Historical Financials'!J125) -> -117116 | K31: =SUM('Historical Financials'!K124+'Historical Financials'!K125) -> -544 | L31: =SUM('Historical Financials'!L124+'Historical Financials'!L125) -> -14986 | M31: =SUM('Historical Financials'!M124+'Historical Financials'!M125) -> 12221 | N31: =SUM('Historical Financials'!N124+'Historical Financials'!N125) -> 14289 | O31: =SUM('Historical Financials'!O124+'Historical Financials'!O125) -> -10751 | ... U31: =SUM('Historical Financials'!U124+'Historical Financials'!U125) -> -346123 | V31: =SUM('Historical Financials'!#REF!+'Historical Financials'!#REF!) -> #REF! | X31: =SUM(G31:K31) -> -107024 | Y31: =SUM(I31:L31) -> -119174 | Z31: =SUM(J31:M31) -> -120425 | AA31: =SUM(K31:N31) -> 10980 | AB31: =SUM(L31:O31) -> 773 | AC31: =SUM(M31:P31) -> 21979 | AD31: =SUM(N31:Q31) -> -3495 | AE31: =SUM(O31:R31) -> -11519 | AF31: =SUM(P31:S31) -> -78362 | ... AI31: =SUM(S31:V31) -> #REF! | AK31: =SUM(AI31/AE31)-1 -> #REF!
B32: (-) Cash Taxes | C32: ='Historical Financials'!C32 -> 0 | D32: ='Historical Financials'!D32 -> 0 | E32: ='Historical Financials'!E32 -> 0 | F32: ='Historical Financials'!F32 -> 0 | H32: ='Historical Financials'!H32 -> 0 | I32: ='Historical Financials'!I32 -> 0 | J32: ='Historical Financials'!J32 -> 0 | K32: ='Historical Financials'!K32 -> 0 | L32: ='Historical Financials'!L32 -> 0 | M32: ='Historical Financials'!M32 -> 0 | N32: ='Historical Financials'!N32 -> 0 | O32: ='Historical Financials'!O32 -> 0 | ... U32: ='Historical Financials'!U32 -> 0 | V32: ='Historical Financials'!#REF! -> #REF! | X32: =SUM(G32:K32) -> 0 | Y32: =SUM(I32:L32) -> 0 | Z32: =SUM(J32:M32) -> 0 | AA32: =SUM(K32:N32) -> 0 | AB32: =SUM(L32:O32) -> 0 | AC32: =SUM(M32:P32) -> 0 | AD32: =SUM(N32:Q32) -> 0 | AE32: =SUM(O32:R32) -> 0 | AF32: =SUM(P32:S32) -> 0 | ... AI32: =SUM(S32:V32) -> #REF! | AK32: =SUM(AI32/AE32)-1 -> #REF!
B33: (-) Cash Interest | C33: 0 | D33: 0 | E33: 0 | F33: 0 | H33: 0 | I33: 0 | J33: 0 | K33: =D33 -> 0 | L33: 0 | M33: 0 | N33: 0 | O33: =E33 -> 0 | P33: 0 | Q33: 0 | R33: 0 | S33: =F33 -> 0 | T33: 0 | U33: 0 | V33: 0 | X33: =SUM(G33:K33) -> 0 | Y33: =SUM(I33:L33) -> 0 | Z33: =SUM(J33:M33) -> 0 | AA33: =SUM(K33:N33) -> 0 | AB33: =SUM(L33:O33) -> 0 | AC33: =SUM(M33:P33) -> 0 | AD33: =SUM(N33:Q33) -> 0 | AE33: =SUM(O33:R33) -> 0 | AF33: =SUM(P33:S33) -> 0 | ... AI33: =SUM(S33:V33) -> 0 | AK33: =SUM(AI33/AE33)-1 -> #DIV/0!
B34: (+/-) Changes in NWC | C34: =SUM('Historical Financials'!C115:C120) -> 158 | D34: =SUM('Historical Financials'!D115:D120) -> -2327 | E34: =SUM('Historical Financials'!E115:E120) -> -495 | F34: =SUM('Historical Financials'!F115:F120) -> -3081 | H34: =SUM('Historical Financials'!H115:H120) -> -25 | I34: =SUM('Historical Financials'!I115:I120) -> -3539 | J34: =SUM('Historical Financials'!J115:J120) -> 3307 | K34: =SUM('Historical Financials'!K115:K120) -> -2070 | L34: =SUM('Historical Financials'!L115:L120) -> 754 | M34: =SUM('Historical Financials'!M115:M120) -> -6722 | N34: =SUM('Historical Financials'!N115:N120) -> 5412 | O34: =SUM('Historical Financials'!O115:O120) -> 61 | ... U34: =SUM('Historical Financials'!U115:U120) -> -3196 | V34: =SUM('Historical Financials'!#REF!) -> #REF! | X34: =SUM(G34:K34) -> -2327 | Y34: =SUM(I34:L34) -> -1548 | Z34: =SUM(J34:M34) -> -4731 | AA34: =SUM(K34:N34) -> -2626 | AB34: =SUM(L34:O34) -> -495 | AC34: =SUM(M34:P34) -> -2431 | AD34: =SUM(N34:Q34) -> 2055 | AE34: =SUM(O34:R34) -> -7146 | AF34: =SUM(P34:S34) -> -3081 | ... AI34: =SUM(S34:V34) -> #REF! | AK34: =SUM(AI34/AE34)-1 -> #REF!
B35: Discretionary Cash-Flows | C35: =SUM(C28+SUM(C31:C34)) -> #REF! | D35: =SUM(D28+SUM(D31:D34)) -> #REF! | E35: =SUM(E28+SUM(E31:E34)) -> #REF! | F35: =SUM(F28+SUM(F31:F34)) -> #REF! | H35: =SUM(H28+SUM(H31:H34)) -> #REF! | I35: =SUM(I28+SUM(I31:I34)) -> #REF! | J35: =SUM(J28+SUM(J31:J34)) -> #REF! | K35: =SUM(K28+SUM(K31:K34)) -> #REF! | L35: =SUM(L28+SUM(L31:L34)) -> #REF! | M35: =SUM(M28+SUM(M31:M34)) -> #REF! | N35: =SUM(N28+SUM(N31:N34)) -> #REF! | O35: =SUM(O28+SUM(O31:O34)) -> #REF! | ... V35: =SUM(V28+SUM(V31:V34)) -> #REF! | X35: =SUM(X28+SUM(X31:X34)) -> #REF! | Y35: =SUM(Y28+SUM(Y31:Y34)) -> #REF! | Z35: =SUM(Z28+SUM(Z31:Z34)) -> #REF! | AA35: =SUM(AA28+SUM(AA31:AA34)) -> #REF! | AB35: =SUM(AB28+SUM(AB31:AB34)) -> #REF! | AC35: =SUM(AC28+SUM(AC31:AC34)) -> #REF! | AD35: =SUM(AD28+SUM(AD31:AD34)) -> #REF! | AE35: =SUM(AE28+SUM(AE31:AE34)) -> #REF! | ... AI35: =SUM(AI28+SUM(AI31:AI34)) -> #REF! | AK35: =SUM(AI35/AE35)-1 -> #REF!
B37: (+/-) Proceeds / (Purchases) of Equity, net | C37: ='Historical Financials'!#REF! -> #REF! | D37: ='Historical Financials'!#REF! -> #REF! | E37: ='Historical Financials'!#REF! -> #REF! | F37: ='Historical Financials'!#REF! -> #REF! | H37: ='Historical Financials'!#REF! -> #REF! | I37: ='Historical Financials'!#REF! -> #REF! | J37: ='Historical Financials'!#REF! -> #REF! | K37: ='Historical Financials'!#REF! -> #REF! | L37: ='Historical Financials'!#REF! -> #REF! | M37: ='Historical Financials'!#REF! -> #REF! | N37: ='Historical Financials'!#REF! -> #REF! | O37: ='Historical Financials'!#REF! -> #REF! | ... V37: ='Historical Financials'!#REF! -> #REF! | X37: =SUM(G37:K37) -> #REF! | Y37: =SUM(I37:L37) -> #REF! | Z37: =SUM(J37:M37) -> #REF! | AA37: =SUM(K37:N37) -> #REF! | AB37: =SUM(L37:O37) -> #REF! | AC37: =SUM(M37:P37) -> #REF! | AD37: =SUM(N37:Q37) -> #REF! | AE37: =SUM(O37:R37) -> #REF! | AF37: =SUM(P37:S37) -> #REF! | ... AI37: =SUM(S37:V37) -> #REF!
B38: (+/-) Maturities / (Purchases) of available-for-sale securities | C38: =SUM('Historical Financials'!#REF!) -> #REF! | D38: =SUM('Historical Financials'!#REF!) -> #REF! | E38: =SUM('Historical Financials'!#REF!) -> #REF! | F38: =SUM('Historical Financials'!#REF!) -> #REF! | H38: =SUM('Historical Financials'!#REF!) -> #REF! | I38: =SUM('Historical Financials'!#REF!) -> #REF! | J38: =SUM('Historical Financials'!#REF!) -> #REF! | K38: =SUM('Historical Financials'!#REF!) -> #REF! | L38: =SUM('Historical Financials'!#REF!) -> #REF! | M38: =SUM('Historical Financials'!#REF!) -> #REF! | N38: =SUM('Historical Financials'!#REF!) -> #REF! | O38: =SUM('Historical Financials'!#REF!) -> #REF! | ... V38: =SUM('Historical Financials'!#REF!) -> #REF! | X38: =SUM(G38:K38) -> #REF! | Y38: =SUM(I38:L38) -> #REF! | Z38: =SUM(J38:M38) -> #REF! | AA38: =SUM(K38:N38) -> #REF! | AB38: =SUM(L38:O38) -> #REF! | AC38: =SUM(M38:P38) -> #REF! | AD38: =SUM(N38:Q38) -> #REF! | AE38: =SUM(O38:R38) -> #REF! | AF38: =SUM(P38:S38) -> #REF! | ... AI38: =SUM(S38:V38) -> #REF!
B39: (+/-) Divestitures / (Acquisitions) | C39: ='Historical Financials'!#REF! -> #REF! | D39: ='Historical Financials'!#REF! -> #REF! | E39: ='Historical Financials'!#REF! -> #REF! | F39: ='Historical Financials'!#REF! -> #REF! | H39: ='Historical Financials'!#REF! -> #REF! | I39: ='Historical Financials'!#REF! -> #REF! | J39: ='Historical Financials'!#REF! -> #REF! | K39: ='Historical Financials'!#REF! -> #REF! | L39: ='Historical Financials'!#REF! -> #REF! | M39: ='Historical Financials'!#REF! -> #REF! | N39: ='Historical Financials'!#REF! -> #REF! | O39: ='Historical Financials'!#REF! -> #REF! | ... V39: ='Historical Financials'!#REF! -> #REF! | X39: =SUM(G39:K39) -> #REF! | Y39: =SUM(I39:L39) -> #REF! | Z39: =SUM(J39:M39) -> #REF! | AA39: =SUM(K39:N39) -> #REF! | AB39: =SUM(L39:O39) -> #REF! | AC39: =SUM(M39:P39) -> #REF! | AD39: =SUM(N39:Q39) -> #REF! | AE39: =SUM(O39:R39) -> #REF! | AF39: =SUM(P39:S39) -> #REF! | ... AI39: =SUM(S39:V39) -> #REF!
B40: (+/-) Other Investing Activities | C40: ='Historical Financials'!#REF! -> #REF! | D40: ='Historical Financials'!#REF! -> #REF! | E40: ='Historical Financials'!#REF! -> #REF! | F40: ='Historical Financials'!#REF! -> #REF! | H40: ='Historical Financials'!#REF! -> #REF! | I40: ='Historical Financials'!#REF! -> #REF! | J40: ='Historical Financials'!#REF! -> #REF! | K40: ='Historical Financials'!#REF! -> #REF! | L40: ='Historical Financials'!#REF! -> #REF! | M40: ='Historical Financials'!#REF! -> #REF! | N40: ='Historical Financials'!#REF! -> #REF! | O40: ='Historical Financials'!#REF! -> #REF! | ... V40: ='Historical Financials'!#REF! -> #REF! | X40: =SUM(G40:K40) -> #REF! | Y40: =SUM(I40:L40) -> #REF! | Z40: =SUM(J40:M40) -> #REF! | AA40: =SUM(K40:N40) -> #REF! | AB40: =SUM(L40:O40) -> #REF! | AC40: =SUM(M40:P40) -> #REF! | AD40: =SUM(N40:Q40) -> #REF! | AE40: =SUM(O40:R40) -> #REF! | AF40: =SUM(P40:S40) -> #REF! | ... AI40: =SUM(S40:V40) -> #REF!
B41: (+/-) Other Financing Activities | C41: ='Historical Financials'!#REF! -> #REF! | D41: ='Historical Financials'!#REF! -> #REF! | E41: ='Historical Financials'!#REF! -> #REF! | F41: ='Historical Financials'!#REF! -> #REF! | H41: ='Historical Financials'!#REF! -> #REF! | I41: ='Historical Financials'!#REF! -> #REF! | J41: ='Historical Financials'!#REF! -> #REF! | K41: ='Historical Financials'!#REF! -> #REF! | L41: ='Historical Financials'!#REF! -> #REF! | M41: ='Historical Financials'!#REF! -> #REF! | N41: ='Historical Financials'!#REF! -> #REF! | O41: ='Historical Financials'!#REF! -> #REF! | ... V41: ='Historical Financials'!#REF! -> #REF! | X41: =SUM(G41:K41) -> #REF! | Y41: =SUM(I41:L41) -> #REF! | Z41: =SUM(J41:M41) -> #REF! | AA41: =SUM(K41:N41) -> #REF! | AB41: =SUM(L41:O41) -> #REF! | AC41: =SUM(M41:P41) -> #REF! | AD41: =SUM(N41:Q41) -> #REF! | AE41: =SUM(O41:R41) -> #REF! | AF41: =SUM(P41:S41) -> #REF! | ... AI41: =SUM(S41:V41) -> #REF!
B42: (+/-) Other Operating Activities | C42: ='Historical Financials'!#REF! -> #REF! | D42: ='Historical Financials'!#REF! -> #REF! | E42: ='Historical Financials'!#REF! -> #REF! | F42: ='Historical Financials'!#REF! -> #REF! | H42: ='Historical Financials'!#REF! -> #REF! | I42: ='Historical Financials'!#REF! -> #REF! | J42: ='Historical Financials'!#REF! -> #REF! | K42: ='Historical Financials'!#REF! -> #REF! | L42: ='Historical Financials'!#REF! -> #REF! | M42: ='Historical Financials'!#REF! -> #REF! | N42: ='Historical Financials'!#REF! -> #REF! | O42: ='Historical Financials'!#REF! -> #REF! | ... V42: ='Historical Financials'!#REF! -> #REF! | X42: =SUM(G42:K42) -> #REF! | Y42: =SUM(I42:L42) -> #REF! | Z42: =SUM(J42:M42) -> #REF! | AA42: =SUM(K42:N42) -> #REF! | AB42: =SUM(L42:O42) -> #REF! | AC42: =SUM(M42:P42) -> #REF! | AD42: =SUM(N42:Q42) -> #REF! | AE42: =SUM(O42:R42) -> #REF! | AF42: =SUM(P42:S42) -> #REF! | ... AI42: =SUM(S42:V42) -> #REF!
B43: (+/-) Other | D43: =SUM(D48:D49)-SUM(C48:C49)-SUM(D35:D42) -> #REF! | E43: =SUM(E48:E49)-SUM(D48:D49)-SUM(E35:E42) -> #REF! | F43: =SUM(F48:F49)-SUM(E48:E49)-SUM(F35:F42) -> #REF! | H43: =SUM(H48:H49)-SUM(C48:C49)-SUM(H35:H42) -> #REF! | I43: =SUM(I48:I49)-SUM(H48:H49)-SUM(I35:I42) -> #REF! | J43: =SUM(J48:J49)-SUM(I48:I49)-SUM(J35:J42) -> #REF! | K43: =SUM(K48:K49)-SUM(J48:J49)-SUM(K35:K42) -> #REF! | L43: =SUM(L48:L49)-SUM(K48:K49)-SUM(L35:L42) -> #REF! | M43: =SUM(M48:M49)-SUM(L48:L49)-SUM(M35:M42) -> #REF! | N43: =SUM(N48:N49)-SUM(M48:M49)-SUM(N35:N42) -> #REF! | O43: =SUM(O48:O49)-SUM(N48:N49)-SUM(O35:O42) -> #REF! | P43: =SUM(P48:P49)-SUM(O48:O49)-SUM(P35:P42) -> #REF! | ... V43: =SUM(V48:V49)-SUM(U48:U49)-SUM(V35:V42) -> #REF! | X43: =SUM(G43:K43) -> #REF! | Y43: =SUM(I43:L43) -> #REF! | Z43: =SUM(J43:M43) -> #REF! | AA43: =SUM(K43:N43) -> #REF! | AB43: =SUM(L43:O43) -> #REF! | AC43: =SUM(M43:P43) -> #REF! | AD43: =SUM(N43:Q43) -> #REF! | AE43: =SUM(O43:R43) -> #REF! | AF43: =SUM(P43:S43) -> #REF! | ... AI43: =SUM(S43:V43) -> #REF!
B44: Free-Cash Flows | C44: =SUM(C35+SUM(C37:C43)) -> #REF! | D44: =SUM(D35+SUM(D37:D43)) -> #REF! | E44: =SUM(E35+SUM(E37:E43)) -> #REF! | F44: =SUM(F35+SUM(F37:F43)) -> #REF! | H44: =SUM(H35+SUM(H37:H43)) -> #REF! | I44: =SUM(I35+SUM(I37:I43)) -> #REF! | J44: =SUM(J35+SUM(J37:J43)) -> #REF! | K44: =SUM(K35+SUM(K37:K43)) -> #REF! | L44: =SUM(L35+SUM(L37:L43)) -> #REF! | M44: =SUM(M35+SUM(M37:M43)) -> #REF! | N44: =SUM(N35+SUM(N37:N43)) -> #REF! | O44: =SUM(O35+SUM(O37:O43)) -> #REF! | ... V44: =SUM(V35+SUM(V37:V43)) -> #REF! | X44: =SUM(X35+SUM(X37:X43)) -> #REF! | Y44: =SUM(Y35+SUM(Y37:Y43)) -> #REF! | Z44: =SUM(Z35+SUM(Z37:Z43)) -> #REF! | AA44: =SUM(AA35+SUM(AA37:AA43)) -> #REF! | AB44: =SUM(AB35+SUM(AB37:AB43)) -> #REF! | AC44: =SUM(AC35+SUM(AC37:AC43)) -> #REF! | AD44: =SUM(AD35+SUM(AD37:AD43)) -> #REF! | AE44: =SUM(AE35+SUM(AE37:AE43)) -> #REF! | ... AI44: =SUM(AI35+SUM(AI37:AI43)) -> #REF!
B46: Capitalization
B48: Cash & Cash Equivelants | C48: ='Historical Financials'!C47 -> 11729 | D48: ='Historical Financials'!D47 -> 57888 | E48: ='Historical Financials'!E47 -> 21392 | F48: ='Historical Financials'!F47 -> 67674 | H48: ='Historical Financials'!H47 -> 206626 | I48: ='Historical Financials'!I47 -> 184020 | J48: ='Historical Financials'!J47 -> 73837 | K48: ='Historical Financials'!K47 -> 57888 | L48: ='Historical Financials'!L47 -> 26117 | M48: ='Historical Financials'!M47 -> 21712 | N48: ='Historical Financials'!N47 -> 41757 | O48: ='Historical Financials'!O47 -> 21392 | ... U48: ='Historical Financials'!U47 -> 57183 | V48: ='Historical Financials'!#REF! -> #REF! | X48: =K48 -> 57888 | Y48: =L48 -> 26117 | Z48: =M48 -> 21712 | AA48: =N48 -> 41757 | AB48: =O48 -> 21392 | AC48: =P48 -> 35098 | AD48: =Q48 -> 20684 | AE48: =R48 -> 20286 | ... AI48: =V48 -> #REF!
