Workbook

Sheet Historical Financials
B2: Coca-Cola Co (NASDAQ: KO)
B3: Historical Financials
B4: ($ In Millions, except EPS)
A6: X | B6: Income Statement | D6: FYE | G6: Quarterly | M6: Quarterly | V6: LTM | AB6: Variance
B7: Fiscal Period | C7: 2022 | D7: 2023 | E7: 2024 | G7: 1Q23 | H7: 2Q23 | I7: 3Q23 | J7: 4Q23 | K7: 1Q24 | L7: 2Q24 | M7: 3Q24 | N7: 4Q24 | O7: 1Q25 | P7: 2Q25 | Q7: 3Q25 | S7: =J7 -> 4Q23 | T7: =K7 -> 1Q24 | U7: =L7 -> 2Q24 | V7: =M7 -> 3Q24 | W7: =N7 -> 4Q24 | X7: =O7 -> 1Q25 | Y7: =P7 -> 2Q25 | Z7: =Q7 -> 3Q25
B8: Fiscal Period End Date | C8: 44926 | D8: 45291 | E8: 45657 | G8: 45016 | H8: 45107 | I8: 45199 | J8: =D8 -> 45291 | K8: 45382 | L8: 45473 | M8: 45565 | N8: =E8 -> 45657 | O8: 45747 | P8: 45838 | Q8: 45930 | S8: =J8 -> 45291 | T8: =K8 -> 45382 | U8: =L8 -> 45473 | V8: =M8 -> 45565 | W8: =N8 -> 45657 | X8: =O8 -> 45747 | Y8: =P8 -> 45838 | Z8: =Q8 -> 45930
B10: Consolidated Revenue | C10: 43004 | D10: 45754 | E10: 47061 | G10: 10980 | H10: 11972 | I10: 11953 | J10: =SUM(D10-SUM(G10:I10)) -> 10849 | K10: 11300 | L10: 12363 | M10: 11854 | N10: =SUM(E10-SUM(K10:M10)) -> 11544 | O10: 11129 | S10: =SUM(G10:J10) -> 45754 | T10: =SUM(H10:K10) -> 46074 | U10: =SUM(I10:L10) -> 46465 | V10: =SUM(J10:M10) -> 46366 | W10: =SUM(K10:N10) -> 47061 | X10: =SUM(L10:O10) -> 46890 | Y10: =SUM(M10:P10) -> 34527 | Z10: =SUM(N10:Q10) -> 22673 | AB10: =SUM(Z10/V10)-1 -> -0.51099944
B11: Total Revenue | C11: =+SUM(C10:C10) -> 43004 | D11: =+SUM(D10:D10) -> 45754 | E11: =+SUM(E10:E10) -> 47061 | G11: =+SUM(G10:G10) -> 10980 | H11: =+SUM(H10:H10) -> 11972 | I11: =+SUM(I10:I10) -> 11953 | J11: =+SUM(J10:J10) -> 10849 | K11: =+SUM(K10:K10) -> 11300 | L11: =+SUM(L10:L10) -> 12363 | M11: =+SUM(M10:M10) -> 11854 | N11: =+SUM(N10:N10) -> 11544 | ... Q11: =+SUM(Q10:Q10) -> 0 | S11: =+SUM(S10:S10) -> 45754 | T11: =+SUM(T10:T10) -> 46074 | U11: =+SUM(U10:U10) -> 46465 | V11: =+SUM(V10:V10) -> 46366 | W11: =+SUM(W10:W10) -> 47061 | X11: =+SUM(X10:X10) -> 46890 | Y11: =+SUM(Y10:Y10) -> 34527 | Z11: =+SUM(Z10:Z10) -> 22673 | AB11: =SUM(Z11/V11)-1 -> -0.51099944
B13: Cost of Sales | C13: -18000 | D13: -18520 | E13: -18324 | G13: -4317 | H13: -4912 | I13: -4657 | J13: =SUM(D13-SUM(G13:I13)) -> -4634 | K13: -4235 | L13: -4812 | M13: -4664 | N13: =SUM(E13-SUM(K13:M13)) -> -4613 | O13: -4163 | S13: =SUM(G13:J13) -> -18520 | T13: =SUM(H13:K13) -> -18438 | U13: =SUM(I13:L13) -> -18338 | V13: =SUM(J13:M13) -> -18345 | W13: =SUM(K13:N13) -> -18324 | X13: =SUM(L13:O13) -> -18252 | Y13: =SUM(M13:P13) -> -13440 | Z13: =SUM(N13:Q13) -> -8776 | AB13: =SUM(Z13/V13)-1 -> -0.52161352
B14: Gross Profit | C14: =+SUM(C11+SUM(C13:C13)) -> 25004 | D14: =+SUM(D11+SUM(D13:D13)) -> 27234 | E14: =+SUM(E11+SUM(E13:E13)) -> 28737 | G14: =+SUM(G11+SUM(G13:G13)) -> 6663 | H14: =+SUM(H11+SUM(H13:H13)) -> 7060 | I14: =+SUM(I11+SUM(I13:I13)) -> 7296 | J14: =+SUM(J11+SUM(J13:J13)) -> 6215 | K14: =+SUM(K11+SUM(K13:K13)) -> 7065 | L14: =+SUM(L11+SUM(L13:L13)) -> 7551 | M14: =+SUM(M11+SUM(M13:M13)) -> 7190 | N14: =+SUM(N11+SUM(N13:N13)) -> 6931 | ... Q14: =+SUM(Q11+SUM(Q13:Q13)) -> 0 | S14: =+SUM(S11+SUM(S13:S13)) -> 27234 | T14: =+SUM(T11+SUM(T13:T13)) -> 27636 | U14: =+SUM(U11+SUM(U13:U13)) -> 28127 | V14: =+SUM(V11+SUM(V13:V13)) -> 28021 | W14: =+SUM(W11+SUM(W13:W13)) -> 28737 | X14: =+SUM(X11+SUM(X13:X13)) -> 28638 | Y14: =+SUM(Y11+SUM(Y13:Y13)) -> 21087 | Z14: =+SUM(Z11+SUM(Z13:Z13)) -> 13897 | AB14: =SUM(Z14/V14)-1 -> -0.50405053
B15: Gross Margin (%) | C15: =C14/C11 -> 0.58143429 | D15: =D14/D11 -> 0.59522665 | E15: =E14/E11 -> 0.61063301 | G15: =G14/G11 -> 0.6068306 | H15: =H14/H11 -> 0.58970932 | I15: =I14/I11 -> 0.6103907 | J15: =J14/J11 -> 0.57286386 | K15: =K14/K11 -> 0.62522124 | L15: =L14/L11 -> 0.61077408 | M15: =M14/M11 -> 0.60654631 | N15: =N14/N11 -> 0.60039848 | ... Q15: =Q14/Q11 -> #DIV/0! | S15: =S14/S11 -> 0.59522665 | T15: =T14/T11 -> 0.59981768 | U15: =U14/U11 -> 0.60533735 | V15: =V14/V11 -> 0.6043437 | W15: =W14/W11 -> 0.61063301 | X15: =X14/X11 -> 0.61074856 | Y15: =Y14/Y11 -> 0.61073942 | Z15: =Z14/Z11 -> 0.61293168 | AB15: =SUM(Z15-V15)*1000 -> 8.5879807
B17: Selling, general and administrative expenses | C17: -12880 | D17: -13972 | E17: -14582 | G17: -3185 | H17: -3321 | I17: -3667 | J17: =SUM(D17-SUM(G17:I17)) -> -3799 | K17: -3351 | L17: -3549 | M17: -3636 | N17: =SUM(E17-SUM(K17:M17)) -> -4046 | O17: -3234 | S17: =SUM(G17:J17) -> -13972 | T17: =SUM(H17:K17) -> -14138 | U17: =SUM(I17:L17) -> -14366 | V17: =SUM(J17:M17) -> -14335 | W17: =SUM(K17:N17) -> -14582 | X17: =SUM(L17:O17) -> -14465 | Y17: =SUM(M17:P17) -> -10916 | Z17: =SUM(N17:Q17) -> -7280 | AB17: =SUM(Z17/V17)-1 -> -0.49215208
B18: Other operating charges | C18: -1215 | D18: -1951 | E18: -4163 | G18: -111 | H18: -1338 | I18: -359 | J18: =SUM(D18-SUM(G18:I18)) -> -143 | K18: -1573 | L18: -1370 | M18: -1044 | N18: =SUM(E18-SUM(K18:M18)) -> -176 | O18: -73 | S18: =SUM(G18:J18) -> -1951 | T18: =SUM(H18:K18) -> -3413 | U18: =SUM(I18:L18) -> -3445 | V18: =SUM(J18:M18) -> -4130 | W18: =SUM(K18:N18) -> -4163 | X18: =SUM(L18:O18) -> -2663 | Y18: =SUM(M18:P18) -> -1293 | Z18: =SUM(N18:Q18) -> -249 | AB18: =SUM(Z18/V18)-1 -> -0.93970944
B19: Operating Profit | C19: =+SUM(C14+SUM(C17:C18)) -> 10909 | D19: =+SUM(D14+SUM(D17:D18)) -> 11311 | E19: =+SUM(E14+SUM(E17:E18)) -> 9992 | G19: =+SUM(G14+SUM(G17:G18)) -> 3367 | H19: =+SUM(H14+SUM(H17:H18)) -> 2401 | I19: =+SUM(I14+SUM(I17:I18)) -> 3270 | J19: =+SUM(J14+SUM(J17:J18)) -> 2273 | K19: =+SUM(K14+SUM(K17:K18)) -> 2141 | L19: =+SUM(L14+SUM(L17:L18)) -> 2632 | M19: =+SUM(M14+SUM(M17:M18)) -> 2510 | N19: =+SUM(N14+SUM(N17:N18)) -> 2709 | ... Q19: =+SUM(Q14+SUM(Q17:Q18)) -> 0 | S19: =+SUM(S14+SUM(S17:S18)) -> 11311 | T19: =+SUM(T14+SUM(T17:T18)) -> 10085 | U19: =+SUM(U14+SUM(U17:U18)) -> 10316 | V19: =+SUM(V14+SUM(V17:V18)) -> 9556 | W19: =+SUM(W14+SUM(W17:W18)) -> 9992 | X19: =+SUM(X14+SUM(X17:X18)) -> 11510 | Y19: =+SUM(Y14+SUM(Y17:Y18)) -> 8878 | Z19: =+SUM(Z14+SUM(Z17:Z18)) -> 6368 | AB19: =SUM(Z19/V19)-1 -> -0.33361239
B20: Operating Margin (%) | C20: =C19/C11 -> 0.25367408 | D20: =D19/D11 -> 0.24721336 | E20: =E19/E11 -> 0.21232018 | G20: =G19/G11 -> 0.30664845 | H20: =H19/H11 -> 0.20055129 | I20: =I19/I11 -> 0.27357149 | J20: =J19/J11 -> 0.2095124 | K20: =K19/K11 -> 0.18946903 | L20: =L19/L11 -> 0.21289331 | M20: =M19/M11 -> 0.21174287 | N20: =N19/N11 -> 0.23466736 | ... Q20: =Q19/Q11 -> #DIV/0! | S20: =S19/S11 -> 0.24721336 | T20: =T19/T11 -> 0.21888701 | U20: =U19/U11 -> 0.22201657 | V20: =V19/V11 -> 0.2060993 | W20: =W19/W11 -> 0.21232018 | X20: =X19/X11 -> 0.24546812 | Y20: =Y19/Y11 -> 0.2571321 | Z20: =Z19/Z11 -> 0.2808627 | AB20: =SUM(Z20-V20)*1000 -> 74.763403
B22: Interest Income | C22: 449 | D22: 907 | E22: 988 | G22: 168 | H22: 224 | I22: 248 | J22: =SUM(D22-SUM(G22:I22)) -> 267 | K22: 246 | L22: 275 | M22: 263 | N22: =SUM(E22-SUM(K22:M22)) -> 204 | O22: 180 | S22: =SUM(G22:J22) -> 907 | T22: =SUM(H22:K22) -> 985 | U22: =SUM(I22:L22) -> 1036 | V22: =SUM(J22:M22) -> 1051 | W22: =SUM(K22:N22) -> 988 | X22: =SUM(L22:O22) -> 922 | Y22: =SUM(M22:P22) -> 647 | Z22: =SUM(N22:Q22) -> 384 | AB22: =SUM(Z22/V22)-1 -> -0.63463368
B23: Interest expense | C23: -882 | D23: -1527 | E23: -1656 | G23: -372 | H23: -374 | I23: -368 | J23: =SUM(D23-SUM(G23:I23)) -> -413 | K23: -382 | L23: -418 | M23: -425 | N23: =SUM(E23-SUM(K23:M23)) -> -431 | O23: -387 | S23: =SUM(G23:J23) -> -1527 | T23: =SUM(H23:K23) -> -1537 | U23: =SUM(I23:L23) -> -1581 | V23: =SUM(J23:M23) -> -1638 | W23: =SUM(K23:N23) -> -1656 | X23: =SUM(L23:O23) -> -1661 | Y23: =SUM(M23:P23) -> -1243 | Z23: =SUM(N23:Q23) -> -818 | AB23: =SUM(Z23/V23)-1 -> -0.5006105
B24: Equity Income (Loss) | C24: 1472 | D24: 1691 | E24: 1770 | G24: 275 | H24: 538 | I24: 517 | J24: =SUM(D24-SUM(G24:I24)) -> 361 | K24: 354 | L24: 537 | M24: 541 | N24: =SUM(E24-SUM(K24:M24)) -> 338 | O24: 351 | S24: =SUM(G24:J24) -> 1691 | T24: =SUM(H24:K24) -> 1770 | U24: =SUM(I24:L24) -> 1769 | V24: =SUM(J24:M24) -> 1793 | W24: =SUM(K24:N24) -> 1770 | X24: =SUM(L24:O24) -> 1767 | Y24: =SUM(M24:P24) -> 1230 | Z24: =SUM(N24:Q24) -> 689 | AB24: =SUM(Z24/V24)-1 -> -0.61572783
B25: Other Income (Loss) | C25: -262 | D25: 570 | E25: 1992 | G25: 615 | H25: 91 | I25: -130 | J25: =SUM(D25-SUM(G25:I25)) -> -6 | K25: 1513 | L25: 2 | M25: 491 | N25: =SUM(E25-SUM(K25:M25)) -> -14 | O25: 254 | S25: =SUM(G25:J25) -> 570 | T25: =SUM(H25:K25) -> 1468 | U25: =SUM(I25:L25) -> 1379 | V25: =SUM(J25:M25) -> 2000 | W25: =SUM(K25:N25) -> 1992 | X25: =SUM(L25:O25) -> 733 | Y25: =SUM(M25:P25) -> 731 | Z25: =SUM(N25:Q25) -> 240 | AB25: =SUM(Z25/V25)-1 -> -0.88
B26: Earnings before Taxes | C26: =SUM(C22:C25)+C19 -> 11686 | D26: =SUM(D22:D25)+D19 -> 12952 | E26: =SUM(E22:E25)+E19 -> 13086 | G26: =SUM(G22:G25)+G19 -> 4053 | H26: =SUM(H22:H25)+H19 -> 2880 | I26: =SUM(I22:I25)+I19 -> 3537 | J26: =SUM(J22:J25)+J19 -> 2482 | K26: =SUM(K22:K25)+K19 -> 3872 | L26: =SUM(L22:L25)+L19 -> 3028 | M26: =SUM(M22:M25)+M19 -> 3380 | N26: =SUM(N22:N25)+N19 -> 2806 | ... Q26: =SUM(Q22:Q25)+Q19 -> 0 | S26: =SUM(S22:S25)+S19 -> 12952 | T26: =SUM(T22:T25)+T19 -> 12771 | U26: =SUM(U22:U25)+U19 -> 12919 | V26: =SUM(V22:V25)+V19 -> 12762 | W26: =SUM(W22:W25)+W19 -> 13086 | X26: =SUM(X22:X25)+X19 -> 13271 | Y26: =SUM(Y22:Y25)+Y19 -> 10243 | Z26: =SUM(Z22:Z25)+Z19 -> 6863 | AB26: =SUM(Z26/V26)-1 -> -0.46223163
B27: EBT Margin (%) | C27: =C26/C11 -> 0.27174216 | D27: =D26/D11 -> 0.28307908 | E27: =E26/E11 -> 0.27806464 | G27: =G26/G11 -> 0.36912568 | H27: =H26/H11 -> 0.24056131 | I27: =I26/I11 -> 0.29590898 | J27: =J26/J11 -> 0.22877685 | K27: =K26/K11 -> 0.34265487 | L27: =L26/L11 -> 0.24492437 | M27: =M26/M11 -> 0.28513582 | N27: =N26/N11 -> 0.24306999 | ... Q27: =Q26/Q11 -> #DIV/0! | S27: =S26/S11 -> 0.28307908 | T27: =T26/T11 -> 0.27718453 | U27: =U26/U11 -> 0.27803723 | V27: =V26/V11 -> 0.27524479 | W27: =W26/W11 -> 0.27806464 | X27: =X26/X11 -> 0.2830241 | Y27: =Y26/Y11 -> 0.29666638 | Z27: =Z26/Z11 -> 0.30269484 | AB27: =SUM(Z27-V27)*1000 -> 27.450044
B29: Income tax expense | C29: -2115 | D29: -2249 | E29: -2437 | G29: -940 | H29: -359 | I29: -454 | J29: =SUM(D29-SUM(G29:I29)) -> -496 | K29: -687 | L29: -627 | M29: -530 | N29: =SUM(E29-SUM(K29:M29)) -> -593 | O29: -722 | S29: =SUM(G29:J29) -> -2249 | T29: =SUM(H29:K29) -> -1996 | U29: =SUM(I29:L29) -> -2264 | V29: =SUM(J29:M29) -> -2340 | W29: =SUM(K29:N29) -> -2437 | X29: =SUM(L29:O29) -> -2472 | Y29: =SUM(M29:P29) -> -1845 | Z29: =SUM(N29:Q29) -> -1315 | AB29: =SUM(Z29/V29)-1 -> -0.43803419
B30: Net Income | C30: =SUM(C26+SUM(C29:C29)) -> 9571 | D30: =SUM(D26+SUM(D29:D29)) -> 10703 | E30: =SUM(E26+SUM(E29:E29)) -> 10649 | G30: =SUM(G26+SUM(G29:G29)) -> 3113 | H30: =SUM(H26+SUM(H29:H29)) -> 2521 | I30: =SUM(I26+SUM(I29:I29)) -> 3083 | J30: =SUM(J26+SUM(J29:J29)) -> 1986 | K30: =SUM(K26+SUM(K29:K29)) -> 3185 | L30: =SUM(L26+SUM(L29:L29)) -> 2401 | M30: =SUM(M26+SUM(M29:M29)) -> 2850 | N30: =SUM(N26+SUM(N29:N29)) -> 2213 | ... Q30: =SUM(Q26+SUM(Q29:Q29)) -> 0 | S30: =SUM(S26+SUM(S29:S29)) -> 10703 | T30: =SUM(T26+SUM(T29:T29)) -> 10775 | U30: =SUM(U26+SUM(U29:U29)) -> 10655 | V30: =SUM(V26+SUM(V29:V29)) -> 10422 | W30: =SUM(W26+SUM(W29:W29)) -> 10649 | X30: =SUM(X26+SUM(X29:X29)) -> 10799 | Y30: =SUM(Y26+SUM(Y29:Y29)) -> 8398 | Z30: =SUM(Z26+SUM(Z29:Z29)) -> 5548 | AB30: =SUM(Z30/V30)-1 -> -0.46766456
B32: Net Income (Loss) Attributable to Noncontrolling Interest | C32: -29 | D32: 11 | E32: -18 | G32: -6 | H32: 26 | I32: 4 | J32: =SUM(D32-SUM(G32:I32)) -> -13 | K32: -8 | L32: 10 | M32: -2 | N32: =SUM(E32-SUM(K32:M32)) -> -18 | O32: -5 | S32: =SUM(G32:J32) -> 11 | T32: =SUM(H32:K32) -> 9 | U32: =SUM(I32:L32) -> -7 | V32: =SUM(J32:M32) -> -13 | W32: =SUM(K32:N32) -> -18 | X32: =SUM(L32:O32) -> -15 | Y32: =SUM(M32:P32) -> -25 | Z32: =SUM(N32:Q32) -> -23 | AB32: =SUM(Z32/V32)-1 -> 0.76923077
B33: Net Income Attributable to Shareowners of The Coca-Cola Company | C33: =+C30+C32 -> 9542 | D33: =+D30+D32 -> 10714 | E33: =E30+E32 -> 10631 | G33: =SUM(G30+SUM(G32:G32)) -> 3107 | H33: =SUM(H30+SUM(H32:H32)) -> 2547 | I33: =SUM(I30+SUM(I32:I32)) -> 3087 | J33: =SUM(J30+SUM(J32:J32)) -> 1973 | K33: =SUM(K30+SUM(K32:K32)) -> 3177 | L33: =SUM(L30+SUM(L32:L32)) -> 2411 | M33: =SUM(M30+SUM(M32:M32)) -> 2848 | N33: =SUM(N30+SUM(N32:N32)) -> 2195 | ... Q33: =SUM(Q30+SUM(Q32:Q32)) -> 0 | S33: =SUM(S30+SUM(S32:S32)) -> 10714 | T33: =SUM(T30+SUM(T32:T32)) -> 10784 | U33: =SUM(U30+SUM(U32:U32)) -> 10648 | V33: =SUM(V30+SUM(V32:V32)) -> 10409 | W33: =SUM(W30+SUM(W32:W32)) -> 10631 | X33: =SUM(X30+SUM(X32:X32)) -> 10784 | Y33: =SUM(Y30+SUM(Y32:Y32)) -> 8373 | Z33: =SUM(Z30+SUM(Z32:Z32)) -> 5525 | AB33: =SUM(Z33/V33)-1 -> -0.46920934
B34: Net Margin (%) | C34: =C33/C11 -> 0.22188634 | D34: =D33/D11 -> 0.23416532 | E34: =E33/E11 -> 0.2258983 | G34: =G33/G11 -> 0.28296903 | H34: =H33/H11 -> 0.21274641 | I34: =I33/I11 -> 0.25826152 | J34: =J33/J11 -> 0.18186008 | K34: =K33/K11 -> 0.28115044 | L34: =L33/L11 -> 0.19501739 | M34: =M33/M11 -> 0.24025645 | N34: =N33/N11 -> 0.19014207 | ... Q34: =Q33/Q11 -> #DIV/0! | S34: =S33/S11 -> 0.23416532 | T34: =T33/T11 -> 0.23405825 | U34: =U33/U11 -> 0.22916173 | V34: =V33/V11 -> 0.2244964 | W34: =W33/W11 -> 0.2258983 | X34: =X33/X11 -> 0.22998507 | Y34: =Y33/Y11 -> 0.24250586 | Z34: =Z33/Z11 -> 0.24368191 | AB34: =SUM(Z34-V34)*1000 -> 19.185514
B36: Basic shares | C36: 4328 | D36: 4323 | E36: 4309 | J36: =D36 -> 4323 | N36: =E36 -> 4309 | S36: =J36 -> 4323 | T36: =K36 -> 0 | U36: =L36 -> 0 | V36: =M36 -> 0 | W36: =N36 -> 4309 | X36: =O36 -> 0 | Y36: =P36 -> 0 | Z36: =Q36 -> 0 | AB36: =SUM(Z36/V36)-1 -> #DIV/0!
B37: Basic EPS | C37: =C33/C36 -> 2.2047135 | D37: =D33/D36 -> 2.4783715 | E37: =E33/E36 -> 2.4671618 | G37: =G33/G36 -> #DIV/0! | H37: =H33/H36 -> #DIV/0! | I37: =I33/I36 -> #DIV/0! | J37: =J33/J36 -> 0.45639602 | K37: =K33/K36 -> #DIV/0! | L37: =L33/L36 -> #DIV/0! | M37: =M33/M36 -> #DIV/0! | N37: =N33/N36 -> 0.50939893 | ... Q37: =Q33/Q36 -> #DIV/0! | S37: =S33/S36 -> 2.4783715 | T37: =T33/T36 -> #DIV/0! | U37: =U33/U36 -> #DIV/0! | V37: =V33/V36 -> #DIV/0! | W37: =W33/W36 -> 2.4671618 | X37: =X33/X36 -> #DIV/0! | Y37: =Y33/Y36 -> #DIV/0! | Z37: =Z33/Z36 -> #DIV/0! | AB37: =SUM(Z37/V37)-1 -> #DIV/0!
B39: Fully Diluted Shares | C39: 4350 | D39: 4339 | E39: 4320 | J39: =D39 -> 4339 | N39: =E39 -> 4320 | S39: =J39 -> 4339 | T39: =K39 -> 0 | U39: =L39 -> 0 | V39: =M39 -> 0 | W39: =N39 -> 4320 | X39: =O39 -> 0 | Y39: =P39 -> 0 | Z39: =Q39 -> 0 | AB39: =SUM(Z39/V39)-1 -> #DIV/0!
B40: Diluted EPS | C40: =C33/C39 -> 2.1935632 | D40: =D33/D39 -> 2.4692325 | E40: =E33/E39 -> 2.4608796 | G40: =G33/G39 -> #DIV/0! | H40: =H33/H39 -> #DIV/0! | I40: =I33/I39 -> #DIV/0! | J40: =J33/J39 -> 0.45471307 | K40: =K33/K39 -> #DIV/0! | L40: =L33/L39 -> #DIV/0! | M40: =M33/M39 -> #DIV/0! | N40: =N33/N39 -> 0.50810185 | ... Q40: =Q33/Q39 -> #DIV/0! | S40: =S33/S39 -> 2.4692325 | T40: =T33/T39 -> #DIV/0! | U40: =U33/U39 -> #DIV/0! | V40: =V33/V39 -> #DIV/0! | W40: =W33/W39 -> 2.4608796 | X40: =X33/X39 -> #DIV/0! | Y40: =Y33/Y39 -> #DIV/0! | Z40: =Z33/Z39 -> #DIV/0! | AB40: =SUM(Z40/V40)-1 -> #DIV/0!
A42: X | B42: Balance Sheet | C42: FYE | M42: Quarterly | V42: LTM | AB42: Variance
B43: =B7 -> Fiscal Period | C43: =C7 -> 2022 | D43: =D7 -> 2023 | E43: =E7 -> 2024 | G43: =G7 -> 1Q23 | H43: =H7 -> 2Q23 | I43: =I7 -> 3Q23 | J43: =J7 -> 4Q23 | K43: =K7 -> 1Q24 | L43: =L7 -> 2Q24 | M43: =M7 -> 3Q24 | N43: =N7 -> 4Q24 | ... Q43: =Q7 -> 3Q25 | S43: =S7 -> 4Q23 | T43: =T7 -> 1Q24 | U43: =U7 -> 2Q24 | V43: =V7 -> 3Q24 | W43: =W7 -> 4Q24 | X43: =X7 -> 1Q25 | Y43: =Y7 -> 2Q25 | Z43: =Z7 -> 3Q25
B44: =B8 -> Fiscal Period End Date | C44: =C8 -> 44926 | D44: =D8 -> 45291 | E44: =E8 -> 45657 | G44: =G8 -> 45016 | H44: =H8 -> 45107 | I44: =I8 -> 45199 | J44: =J8 -> 45291 | K44: =K8 -> 45382 | L44: =L8 -> 45473 | M44: =M8 -> 45565 | N44: =N8 -> 45657 | ... Q44: =Q8 -> 45930 | S44: =S8 -> 45291 | T44: =T8 -> 45382 | U44: =U8 -> 45473 | V44: =V8 -> 45565 | W44: =W8 -> 45657 | X44: =X8 -> 45747 | Y44: =Y8 -> 45838 | Z44: =Z8 -> 45930
B46: Current Assets
B47: Cash and cash equivalents | C47: 9519 | D47: 9366 | E47: 10828 | G47: 12004 | H47: 12564 | I47: 11883 | J47: =D47 -> 9366 | K47: 10443 | L47: 13708 | M47: 13938 | N47: =E47 -> 10828 | O47: 8417 | S47: =J47 -> 9366 | T47: =K47 -> 10443 | U47: =L47 -> 13708 | V47: =M47 -> 13938 | W47: =N47 -> 10828 | X47: =O47 -> 8417 | Y47: =P47 -> 0 | Z47: =Q47 -> 0 | AB47: =SUM(Z47/V47)-1 -> -1
B48: Marketable securities | C48: 1069 | D48: 1300 | E48: 1723 | G48: 1125 | H48: 1263 | I48: 1220 | J48: =D48 -> 1300 | K48: 1716 | L48: 1594 | M48: 1787 | N48: =E48 -> 1723 | O48: 1791 | S48: =J48 -> 1300 | T48: =K48 -> 1716 | U48: =L48 -> 1594 | V48: =M48 -> 1787 | W48: =N48 -> 1723 | X48: =O48 -> 1791 | Y48: =P48 -> 0 | Z48: =Q48 -> 0 | AB48: =SUM(Z48/V48)-1 -> -1
B49: Inventories | C49: 4233 | D49: 4424 | E49: 4728 | G49: 4727 | H49: 4646 | I49: 4252 | J49: =D49 -> 4424 | K49: 4961 | L49: 4763 | M49: 4714 | N49: =E49 -> 4728 | O49: 5102 | S49: =J49 -> 4424 | T49: =K49 -> 4961 | U49: =L49 -> 4763 | V49: =M49 -> 4714 | W49: =N49 -> 4728 | X49: =O49 -> 5102 | Y49: =P49 -> 0 | Z49: =Q49 -> 0 | AB49: =SUM(Z49/V49)-1 -> -1
B50: Trade accounts receivable | C50: 3487 | D50: 3410 | E50: 3569 | G50: 4599 | H50: 3970 | I50: 3495 | J50: =D50 -> 3410 | K50: 4244 | L50: 4545 | M50: 4233 | N50: =E50 -> 3569 | O50: 4091 | S50: =J50 -> 3410 | T50: =K50 -> 4244 | U50: =L50 -> 4545 | V50: =M50 -> 4233 | W50: =N50 -> 3569 | X50: =O50 -> 4091 | Y50: =P50 -> 0 | Z50: =Q50 -> 0 | AB50: =SUM(Z50/V50)-1 -> -1
B51: Short-term investments | C51: 1043 | D51: 2997 | E51: 2020 | G51: 1166 | H51: 1867 | I51: 2332 | J51: =D51 -> 2997 | K51: 4760 | L51: 3691 | M51: 2439 | N51: =E51 -> 2020 | O51: 3579 | S51: =J51 -> 2997 | T51: =K51 -> 4760 | U51: =L51 -> 3691 | V51: =M51 -> 2439 | W51: =N51 -> 2020 | X51: =O51 -> 3579 | Y51: =P51 -> 0 | Z51: =Q51 -> 0 | AB51: =SUM(Z51/V51)-1 -> -1
B52: Prepaid expenses and other current assets | C52: 3240 | D52: 5235 | E52: 3129 | G52: 3259 | H52: 3281 | I52: 4685 | J52: =D52 -> 5235 | K52: 3338 | L52: 3298 | M52: 3177 | N52: =E52 -> 3129 | O52: 3198 | S52: =J52 -> 5235 | T52: =K52 -> 3338 | U52: =L52 -> 3298 | V52: =M52 -> 3177 | W52: =N52 -> 3129 | X52: =O52 -> 3198 | Y52: =P52 -> 0 | Z52: =Q52 -> 0 | AB52: =SUM(Z52/V52)-1 -> -1
...

Sheet Revenue Drivers
B2: ='Historical Financials'!B2 -> Coca-Cola Co (NASDAQ: KO) | C2: FYE | M2: Quarterly | V2: LTM
B3: Segment Anaysis | C3: ='Historical Financials'!C7 -> 2022 | D3: ='Historical Financials'!D7 -> 2023 | E3: ='Historical Financials'!E7 -> 2024 | G3: ='Historical Financials'!G7 -> 1Q23 | H3: ='Historical Financials'!H7 -> 2Q23 | I3: ='Historical Financials'!I7 -> 3Q23 | J3: ='Historical Financials'!J7 -> 4Q23 | K3: ='Historical Financials'!K7 -> 1Q24 | L3: ='Historical Financials'!L7 -> 2Q24 | M3: ='Historical Financials'!M7 -> 3Q24 | N3: ='Historical Financials'!N7 -> 4Q24 | ... Q3: ='Historical Financials'!Q7 -> 3Q25 | S3: =J3 -> 4Q23 | T3: =K3 -> 1Q24 | U3: =L3 -> 2Q24 | V3: =M3 -> 3Q24 | W3: =N3 -> 4Q24 | X3: =O3 -> 1Q25 | Y3: =P3 -> 2Q25 | Z3: =Q3 -> 3Q25
B4: ($ In Millions) | C4: ='Historical Financials'!C8 -> 44926 | D4: ='Historical Financials'!D8 -> 45291 | E4: ='Historical Financials'!E8 -> 45657 | G4: ='Historical Financials'!G8 -> 45016 | H4: ='Historical Financials'!H8 -> 45107 | I4: ='Historical Financials'!I8 -> 45199 | J4: ='Historical Financials'!J8 -> 45291 | K4: ='Historical Financials'!K8 -> 45382 | L4: ='Historical Financials'!L8 -> 45473 | M4: ='Historical Financials'!M8 -> 45565 | N4: ='Historical Financials'!N8 -> 45657 | ... Q4: ='Historical Financials'!Q8 -> 45930 | S4: =J4 -> 45291 | T4: =K4 -> 45382 | U4: =L4 -> 45473 | V4: =M4 -> 45565 | W4: =N4 -> 45657 | X4: =O4 -> 45747 | Y4: =P4 -> 45838 | Z4: =Q4 -> 45930
A6: X | B6: Revenue by reportable segment
A8: X | B8: Revenue Segment Anaysis
B9: Concentrate Operations | C9: 24071 | D9: 26539 | E9: 27725 | G9: 6333 | H9: 7050 | I9: 7212 | J9: =SUM(D9-SUM(G9:I9)) -> 5944 | K9: 6655 | L9: 7494 | M9: 7058 | N9: =SUM(E9-SUM(K9:M9)) -> 6518 | O9: 7183 | S9: =SUM(G9:J9) -> 26539 | T9: =SUM(H9:K9) -> 26861 | U9: =SUM(I9:L9) -> 27305 | V9: =SUM(J9:M9) -> 27151 | W9: =SUM(K9:N9) -> 27725 | X9: =SUM(L9:O9) -> 28253 | Y9: =SUM(M9:P9) -> 20759 | Z9: =SUM(N9:Q9) -> 13701
B10: Finished Product Operations | C10: 18933 | D10: 19215 | E10: 19336 | G10: 4647 | H10: 4922 | I10: 4741 | J10: =SUM(D10-SUM(G10:I10)) -> 4905 | K10: 4645 | L10: 4869 | M10: 4796 | N10: =SUM(E10-SUM(K10:M10)) -> 5026 | O10: 3946 | S10: =SUM(G10:J10) -> 19215 | T10: =SUM(H10:K10) -> 19213 | U10: =SUM(I10:L10) -> 19160 | V10: =SUM(J10:M10) -> 19215 | W10: =SUM(K10:N10) -> 19336 | X10: =SUM(L10:O10) -> 18637 | Y10: =SUM(M10:P10) -> 13768 | Z10: =SUM(N10:Q10) -> 8972
B11: Total Net Revenue | C11: =SUM(C9:C10) -> 43004 | D11: =SUM(D9:D10) -> 45754 | E11: =SUM(E9:E10) -> 47061 | G11: =SUM(G9:G10) -> 10980 | H11: =SUM(H9:H10) -> 11972 | I11: =SUM(I9:I10) -> 11953 | J11: =SUM(J9:J10) -> 10849 | K11: =SUM(K9:K10) -> 11300 | L11: =SUM(L9:L10) -> 12363 | M11: =SUM(M9:M10) -> 11854 | N11: =SUM(N9:N10) -> 11544 | ... Q11: =SUM(Q9:Q10) -> 0 | S11: =SUM(S9:S10) -> 45754 | T11: =SUM(T9:T10) -> 46074 | U11: =SUM(U9:U10) -> 46465 | V11: =SUM(V9:V10) -> 46366 | W11: =SUM(W9:W10) -> 47061 | X11: =SUM(X9:X10) -> 46890 | Y11: =SUM(Y9:Y10) -> 34527 | Z11: =SUM(Z9:Z10) -> 22673
B12: Balance Check | C12: =+C11-'Historical Financials'!C11 -> 0 | D12: =+D11-'Historical Financials'!D11 -> 0 | E12: =+E11-'Historical Financials'!E11 -> 0 | G12: =+G11-'Historical Financials'!G11 -> 0 | H12: =+H11-'Historical Financials'!H11 -> 0 | I12: =+I11-'Historical Financials'!I11 -> 0 | J12: =+J11-'Historical Financials'!J11 -> 0 | K12: =+K11-'Historical Financials'!K11 -> 0 | L12: =+L11-'Historical Financials'!L11 -> 0 | M12: =+M11-'Historical Financials'!M11 -> 0 | N12: =+N11-'Historical Financials'!N11 -> 0 | ... Q12: =+Q11-'Historical Financials'!Q11 -> 0 | S12: =+S11-'Historical Financials'!S11 -> 0 | T12: =+T11-'Historical Financials'!T11 -> 0 | U12: =+U11-'Historical Financials'!U11 -> 0 | V12: =+V11-'Historical Financials'!V11 -> 0 | W12: =+W11-'Historical Financials'!W11 -> 0 | X12: =+X11-'Historical Financials'!X11 -> 0 | Y12: =+Y11-'Historical Financials'!Y11 -> 0 | Z12: =+Z11-'Historical Financials'!Z11 -> 0
B14: =B9&"(%)" -> Concentrate Operations(%) | C14: =SUM(C9/C$11) -> 0.55973863 | D14: =SUM(D9/D$11) -> 0.58003672 | E14: =SUM(E9/E$11) -> 0.589129 | G14: =SUM(G9/G$11) -> 0.57677596 | H14: =SUM(H9/H$11) -> 0.58887404 | I14: =SUM(I9/I$11) -> 0.60336317 | J14: =SUM(J9/J$11) -> 0.5478846 | K14: =SUM(K9/K$11) -> 0.58893805 | L14: =SUM(L9/L$11) -> 0.60616355 | M14: =SUM(M9/M$11) -> 0.59541083 | N14: =SUM(N9/N$11) -> 0.56462231 | ... Q14: =SUM(Q9/Q$11) -> #DIV/0! | S14: =J14 -> 0.5478846 | T14: =K14 -> 0.58893805 | U14: =L14 -> 0.60616355 | V14: =M14 -> 0.59541083 | W14: =N14 -> 0.56462231 | X14: =O14 -> 0.64543086 | Y14: =P14 -> #DIV/0! | Z14: =Q14 -> #DIV/0!
B15: =B10&"(%)" -> Finished Product Operations(%) | C15: =SUM(C10/C$11) -> 0.44026137 | D15: =SUM(D10/D$11) -> 0.41996328 | E15: =SUM(E10/E$11) -> 0.410871 | G15: =SUM(G10/G$11) -> 0.42322404 | H15: =SUM(H10/H$11) -> 0.41112596 | I15: =SUM(I10/I$11) -> 0.39663683 | J15: =SUM(J10/J$11) -> 0.4521154 | K15: =SUM(K10/K$11) -> 0.41106195 | L15: =SUM(L10/L$11) -> 0.39383645 | M15: =SUM(M10/M$11) -> 0.40458917 | N15: =SUM(N10/N$11) -> 0.43537769 | ... Q15: =SUM(Q10/Q$11) -> #DIV/0! | S15: =J15 -> 0.4521154 | T15: =K15 -> 0.41106195 | U15: =L15 -> 0.39383645 | V15: =M15 -> 0.40458917 | W15: =N15 -> 0.43537769 | X15: =O15 -> 0.35456914 | Y15: =P15 -> #DIV/0! | Z15: =Q15 -> #DIV/0!
A17: X | B17: Revenue by Geography
A19: X | B19: Revenue by XXX
B20: U.S. Revenues | C20: 15413 | D20: 16550 | E20: 18362 | G20: 3849 | H20: 4302 | I20: 4411 | J20: =SUM(D20-SUM(G20:I20)) -> 3988 | K20: 4118 | L20: 4740 | M20: 4903 | N20: =SUM(E20-SUM(K20:M20)) -> 4601 | O20: 4253 | S20: =SUM(I20:L20) -> 17257 | T20: =SUM(J20:M20) -> 17749 | U20: =SUM(K20:N20) -> 18362 | V20: =SUM(L20:O20) -> 18497 | W20: =SUM(M20:P20) -> 13757 | X20: =SUM(N20:Q20) -> 8854 | Y20: =SUM(O20:Q20) -> 4253 | Z20: =SUM(P20:Q20) -> 0
B21: International Revenues | C21: 27591 | D21: 29204 | E21: 28699 | G21: 7131 | H21: 7670 | I21: 7542 | J21: =SUM(D21-SUM(G21:I21)) -> 6861 | K21: 7182 | L21: 7623 | M21: 6951 | N21: =SUM(E21-SUM(K21:M21)) -> 6943 | O21: 6876 | S21: =SUM(I21:L21) -> 29208 | T21: =SUM(J21:M21) -> 28617 | U21: =SUM(K21:N21) -> 28699 | V21: =SUM(L21:O21) -> 28393 | W21: =SUM(M21:P21) -> 20770 | X21: =SUM(N21:Q21) -> 13819 | Y21: =SUM(O21:Q21) -> 6876 | Z21: =SUM(P21:Q21) -> 0
B22: Total Revenue | C22: =SUM(C20:C21) -> 43004 | D22: =SUM(D20:D21) -> 45754 | E22: =SUM(E20:E21) -> 47061 | G22: =SUM(G20:G21) -> 10980 | H22: =SUM(H20:H21) -> 11972 | I22: =SUM(I20:I21) -> 11953 | J22: =SUM(J20:J21) -> 10849 | K22: =SUM(K20:K21) -> 11300 | L22: =SUM(L20:L21) -> 12363 | M22: =SUM(M20:M21) -> 11854 | N22: =SUM(N20:N21) -> 11544 | ... Q22: =SUM(Q20:Q21) -> 0 | S22: =SUM(S20:S21) -> 46465 | T22: =SUM(T20:T21) -> 46366 | U22: =SUM(U20:U21) -> 47061 | V22: =SUM(V20:V21) -> 46890 | W22: =SUM(W20:W21) -> 34527 | X22: =SUM(X20:X21) -> 22673 | Y22: =SUM(Y20:Y21) -> 11129 | Z22: =SUM(Z20:Z21) -> 0
B23: Balance Check | C23: =+C22-C11 -> 0 | D23: =+D22-D11 -> 0 | E23: =+E22-E11 -> 0 | G23: =+G22-G11 -> 0 | H23: =+H22-H11 -> 0 | I23: =+I22-I11 -> 0 | J23: =+J22-J11 -> 0 | K23: =+K22-K11 -> 0 | L23: =+L22-L11 -> 0 | M23: =+M22-M11 -> 0 | N23: =+N22-N11 -> 0 | ... Q23: =+Q22-Q11 -> 0 | S23: =+S22-S11 -> 711 | T23: =+T22-T11 -> 292 | U23: =+U22-U11 -> 596 | V23: =+V22-V11 -> 524 | W23: =+W22-W11 -> -12534 | X23: =+X22-X11 -> -24217 | Y23: =+Y22-Y11 -> -23398 | Z23: =+Z22-Z11 -> -22673
B25: =B20&"(%)" -> U.S. Revenues (%) | C25: =C20/C$22 -> 0.35840852 | D25: =D20/D$22 -> 0.36171701 | E25: =E20/E$22 -> 0.39017445 | G25: =G20/G$22 -> 0.35054645 | H25: =H20/H$22 -> 0.35933846 | I25: =I20/I$22 -> 0.3690287 | J25: =J20/J$22 -> 0.36759148 | K25: =K20/K$22 -> 0.36442478 | L25: =L20/L$22 -> 0.38340209 | M25: =M20/M$22 -> 0.41361566 | N25: =N20/N$22 -> 0.39856202 | ... Q25: =Q20/Q$22 -> #DIV/0! | S25: =S20/S$22 -> 0.37139783 | T25: =T20/T$22 -> 0.38280205 | U25: =U20/U$22 -> 0.39017445 | V25: =V20/V$22 -> 0.39447643 | W25: =W20/W$22 -> 0.3984418 | X25: =X20/X$22 -> 0.39050853 | Y25: =Y20/Y$22 -> 0.38215473 | Z25: =Z20/Z$22 -> #DIV/0!
B26: =B21&"(%)" -> International Revenues (%) | C26: =C21/C$22 -> 0.64159148 | D26: =D21/D$22 -> 0.63828299 | E26: =E21/E$22 -> 0.60982555 | G26: =G21/G$22 -> 0.64945355 | H26: =H21/H$22 -> 0.64066154 | I26: =I21/I$22 -> 0.6309713 | J26: =J21/J$22 -> 0.63240852 | K26: =K21/K$22 -> 0.63557522 | L26: =L21/L$22 -> 0.61659791 | M26: =M21/M$22 -> 0.58638434 | N26: =N21/N$22 -> 0.60143798 | ... Q26: =Q21/Q$22 -> #DIV/0! | S26: =S21/S$22 -> 0.62860217 | T26: =T21/T$22 -> 0.61719795 | U26: =U21/U$22 -> 0.60982555 | V26: =V21/V$22 -> 0.60552357 | W26: =W21/W$22 -> 0.6015582 | X26: =X21/X$22 -> 0.60949147 | Y26: =Y21/Y$22 -> 0.61784527 | Z26: =Z21/Z$22 -> #DIV/0!

Sheet FCF
B2: ='Historical Financials'!B2 -> Coca-Cola Co (NASDAQ: KO) | D2: FYE | G2: Quarterly | Q2: Quarterly | W2: LTM | X2: LTM | AD2: Variance
B3: FCF Analysis | C3: ='Historical Financials'!C7 -> 2022 | D3: ='Historical Financials'!D7 -> 2023 | E3: ='Historical Financials'!E7 -> 2024 | G3: ='Historical Financials'!G7 -> 1Q23 | H3: ='Historical Financials'!H7 -> 2Q23 | I3: ='Historical Financials'!I7 -> 3Q23 | J3: ='Historical Financials'!J7 -> 4Q23 | K3: ='Historical Financials'!K7 -> 1Q24 | L3: ='Historical Financials'!L7 -> 2Q24 | M3: ='Historical Financials'!M7 -> 3Q24 | N3: ='Historical Financials'!N7 -> 4Q24 | ... Q3: ='Historical Financials'!Q7 -> 3Q25 | S3: =H3 -> 2Q23 | T3: =I3 -> 3Q23 | U3: =J3 -> 4Q23 | V3: =K3 -> 1Q24 | W3: =L3 -> 2Q24 | X3: =M3 -> 3Q24 | Y3: =N3 -> 4Q24 | Z3: =O3 -> 1Q25 | ... AB3: =Q3 -> 3Q25
B4: ($ In Millions) | C4: ='Historical Financials'!C8 -> 44926 | D4: ='Historical Financials'!D8 -> 45291 | E4: ='Historical Financials'!E8 -> 45657 | G4: ='Historical Financials'!G8 -> 45016 | H4: ='Historical Financials'!H8 -> 45107 | I4: ='Historical Financials'!I8 -> 45199 | J4: ='Historical Financials'!J8 -> 45291 | K4: ='Historical Financials'!K8 -> 45382 | L4: ='Historical Financials'!L8 -> 45473 | M4: ='Historical Financials'!M8 -> 45565 | N4: ='Historical Financials'!N8 -> 45657 | ... Q4: ='Historical Financials'!Q8 -> 45930 | S4: =H4 -> 45107 | T4: =I4 -> 45199 | U4: =J4 -> 45291 | V4: =K4 -> 45382 | W4: =L4 -> 45473 | X4: =M4 -> 45565 | Y4: =N4 -> 45657 | Z4: =O4 -> 45747 | ... AB4: =Q4 -> 45930
B6: ='Revenue Drivers'!B9 -> Concentrate Operations | C6: ='Revenue Drivers'!C9 -> 24071 | D6: ='Revenue Drivers'!D9 -> 26539 | E6: ='Revenue Drivers'!E9 -> 27725 | G6: ='Revenue Drivers'!G9 -> 6333 | H6: ='Revenue Drivers'!H9 -> 7050 | I6: ='Revenue Drivers'!I9 -> 7212 | J6: ='Revenue Drivers'!J9 -> 5944 | K6: ='Revenue Drivers'!K9 -> 6655 | L6: ='Revenue Drivers'!L9 -> 7494 | M6: ='Revenue Drivers'!M9 -> 7058 | N6: ='Revenue Drivers'!N9 -> 6518 | ... Q6: ='Revenue Drivers'!Q9 -> 0 | S6: =SUM(E6:H6) -> 41108 | T6: =SUM(F6:I6) -> 20595 | U6: =SUM(G6:J6) -> 26539 | V6: =SUM(H6:K6) -> 26861 | W6: =SUM(I6:L6) -> 27305 | X6: =SUM(J6:M6) -> 27151 | Y6: =SUM(K6:N6) -> 27725 | Z6: =SUM(L6:O6) -> 28253 | ... AB6: =SUM(N6:Q6) -> 13701 | AD6: =SUM(AB6/X6)-1 -> -0.4953777
B7: ='Revenue Drivers'!B10 -> Finished Product Operations | C7: ='Revenue Drivers'!C10 -> 18933 | D7: ='Revenue Drivers'!D10 -> 19215 | E7: ='Revenue Drivers'!E10 -> 19336 | G7: ='Revenue Drivers'!G10 -> 4647 | H7: ='Revenue Drivers'!H10 -> 4922 | I7: ='Revenue Drivers'!I10 -> 4741 | J7: ='Revenue Drivers'!J10 -> 4905 | K7: ='Revenue Drivers'!K10 -> 4645 | L7: ='Revenue Drivers'!L10 -> 4869 | M7: ='Revenue Drivers'!M10 -> 4796 | N7: ='Revenue Drivers'!N10 -> 5026 | ... Q7: ='Revenue Drivers'!Q10 -> 0 | S7: =SUM(E7:H7) -> 28905 | T7: =SUM(F7:I7) -> 14310 | U7: =SUM(G7:J7) -> 19215 | V7: =SUM(H7:K7) -> 19213 | W7: =SUM(I7:L7) -> 19160 | X7: =SUM(J7:M7) -> 19215 | Y7: =SUM(K7:N7) -> 19336 | Z7: =SUM(L7:O7) -> 18637 | ... AB7: =SUM(N7:Q7) -> 8972 | AD7: =SUM(AB7/X7)-1 -> -0.53307312
B8: Total Revenue | C8: =SUM(C6:C7) -> 43004 | D8: =SUM(D6:D7) -> 45754 | E8: =SUM(E6:E7) -> 47061 | G8: =SUM(G6:G7) -> 10980 | H8: =SUM(H6:H7) -> 11972 | I8: =SUM(I6:I7) -> 11953 | J8: =SUM(J6:J7) -> 10849 | K8: =SUM(K6:K7) -> 11300 | L8: =SUM(L6:L7) -> 12363 | M8: =SUM(M6:M7) -> 11854 | N8: =SUM(N6:N7) -> 11544 | ... Q8: =SUM(Q6:Q7) -> 0 | S8: =SUM(S6:S7) -> 70013 | T8: =SUM(T6:T7) -> 34905 | U8: =SUM(U6:U7) -> 45754 | V8: =SUM(V6:V7) -> 46074 | W8: =SUM(W6:W7) -> 46465 | X8: =SUM(X6:X7) -> 46366 | Y8: =SUM(Y6:Y7) -> 47061 | Z8: =SUM(Z6:Z7) -> 46890 | ... AB8: =SUM(AB6:AB7) -> 22673 | AD8: =SUM(AB8/X8)-1 -> -0.51099944
B9: Y/Y Growth (%) | D9: =SUM(D8/C8)-1 -> 0.06394754 | E9: =SUM(E8/D8)-1 -> 0.028565808 | K9: =SUM(K8/G8)-1 -> 0.029143898 | L9: =SUM(L8/H8)-1 -> 0.032659539 | M9: =SUM(M8/I8)-1 -> -0.0082824396 | N9: =SUM(N8/J8)-1 -> 0.064061204 | O9: =SUM(O8/K8)-1 -> -0.015132743 | P9: =SUM(P8/L8)-1 -> -1 | Q9: =SUM(Q8/M8)-1 -> -1 | W9: =SUM(W8/S8)-1 -> -0.33633754 | X9: =SUM(X8/T8)-1 -> 0.32834837 | Y9: =SUM(Y8/U8)-1 -> 0.028565808 | Z9: =SUM(Z8/V8)-1 -> 0.017710639 | AA9: =SUM(AA8/W8)-1 -> -0.25692457 | AB9: =SUM(AB8/X8)-1 -> -0.51099944 | AD9: =SUM(AB9-X9)*10000 -> -8393.4781
B10: Q/Q Growth (%) | C10: N/A | D10: N/A | E10: N/A | H10: =SUM(H8/G8)-1 -> 0.090346084 | I10: =SUM(I8/H8)-1 -> -0.0015870364 | J10: =SUM(J8/I8)-1 -> -0.09236175 | K10: =SUM(K8/J8)-1 -> 0.041570652 | L10: =SUM(L8/K8)-1 -> 0.094070796 | M10: =SUM(M8/L8)-1 -> -0.041171237 | N10: =SUM(N8/M8)-1 -> -0.02615151 | O10: =SUM(O8/N8)-1 -> -0.035949411 | ... Q10: =SUM(Q8/P8)-1 -> #DIV/0! | S10: N/A | T10: N/A | U10: N/A | V10: N/A | W10: N/A | X10: N/A | Y10: N/A | Z10: N/A | AA10: N/A | AB10: N/A
B12: (-) Cost of Sales | C12: ='Historical Financials'!C13 -> -18000 | D12: ='Historical Financials'!D13 -> -18520 | E12: ='Historical Financials'!E13 -> -18324 | G12: ='Historical Financials'!G13 -> -4317 | H12: ='Historical Financials'!H13 -> -4912 | I12: ='Historical Financials'!I13 -> -4657 | J12: ='Historical Financials'!J13 -> -4634 | K12: ='Historical Financials'!K13 -> -4235 | L12: ='Historical Financials'!L13 -> -4812 | M12: ='Historical Financials'!M13 -> -4664 | N12: ='Historical Financials'!N13 -> -4613 | ... Q12: ='Historical Financials'!Q13 -> 0 | S12: =SUM(E12:H12) -> -27553 | T12: =SUM(F12:I12) -> -13886 | U12: =SUM(G12:J12) -> -18520 | V12: =SUM(H12:K12) -> -18438 | W12: =SUM(I12:L12) -> -18338 | X12: =SUM(J12:M12) -> -18345 | Y12: =SUM(K12:N12) -> -18324 | Z12: =SUM(L12:O12) -> -18252 | ... AB12: =SUM(N12:Q12) -> -8776 | AD12: =SUM(AB12/X12)-1 -> -0.52161352
B13: Gross Profit | C13: =SUM(C8+SUM(C12:C12)) -> 25004 | D13: =SUM(D8+SUM(D12:D12)) -> 27234 | E13: =SUM(E8+SUM(E12:E12)) -> 28737 | G13: =SUM(G8+SUM(G12:G12)) -> 6663 | H13: =SUM(H8+SUM(H12:H12)) -> 7060 | I13: =SUM(I8+SUM(I12:I12)) -> 7296 | J13: =SUM(J8+SUM(J12:J12)) -> 6215 | K13: =SUM(K8+SUM(K12:K12)) -> 7065 | L13: =SUM(L8+SUM(L12:L12)) -> 7551 | M13: =SUM(M8+SUM(M12:M12)) -> 7190 | N13: =SUM(N8+SUM(N12:N12)) -> 6931 | ... Q13: =SUM(Q8+SUM(Q12:Q12)) -> 0 | S13: =SUM(S8+SUM(S12:S12)) -> 42460 | T13: =SUM(T8+SUM(T12:T12)) -> 21019 | U13: =SUM(U8+SUM(U12:U12)) -> 27234 | V13: =SUM(V8+SUM(V12:V12)) -> 27636 | W13: =SUM(W8+SUM(W12:W12)) -> 28127 | X13: =SUM(X8+SUM(X12:X12)) -> 28021 | Y13: =SUM(Y8+SUM(Y12:Y12)) -> 28737 | Z13: =SUM(Z8+SUM(Z12:Z12)) -> 28638 | ... AB13: =SUM(AB8+SUM(AB12:AB12)) -> 13897 | AD13: =SUM(AB13/X13)-1 -> -0.50405053
B14: Gross Margin (%) | C14: =C13/C8 -> 0.58143429 | D14: =D13/D8 -> 0.59522665 | E14: =E13/E8 -> 0.61063301 | G14: =G13/G8 -> 0.6068306 | H14: =H13/H8 -> 0.58970932 | I14: =I13/I8 -> 0.6103907 | J14: =J13/J8 -> 0.57286386 | K14: =K13/K8 -> 0.62522124 | L14: =L13/L8 -> 0.61077408 | M14: =M13/M8 -> 0.60654631 | N14: =N13/N8 -> 0.60039848 | ... Q14: =Q13/Q8 -> #DIV/0! | S14: =S13/S8 -> 0.6064588 | T14: =T13/T8 -> 0.60217734 | U14: =U13/U8 -> 0.59522665 | V14: =V13/V8 -> 0.59981768 | W14: =W13/W8 -> 0.60533735 | X14: =X13/X8 -> 0.6043437 | Y14: =Y13/Y8 -> 0.61063301 | Z14: =Z13/Z8 -> 0.61074856 | ... AB14: =AB13/AB8 -> 0.61293168 | AD14: =SUM(AB14-X14)*10000 -> 85.879807
B16: (-) XXX | S16: =SUM(E16:H16) -> 0 | T16: =SUM(F16:I16) -> 0 | U16: =SUM(G16:J16) -> 0 | V16: =SUM(H16:K16) -> 0 | W16: =SUM(I16:L16) -> 0 | X16: =SUM(J16:M16) -> 0 | Y16: =SUM(K16:N16) -> 0 | Z16: =SUM(L16:O16) -> 0 | ... AB16: =SUM(N16:Q16) -> 0 | AD16: =SUM(AB16/X16)-1 -> #DIV/0!
B17: (-) XXX | S17: =SUM(E17:H17) -> 0 | T17: =SUM(F17:I17) -> 0 | U17: =SUM(G17:J17) -> 0 | V17: =SUM(H17:K17) -> 0 | W17: =SUM(I17:L17) -> 0 | X17: =SUM(J17:M17) -> 0 | Y17: =SUM(K17:N17) -> 0 | Z17: =SUM(L17:O17) -> 0 | ... AB17: =SUM(N17:Q17) -> 0 | AD17: =SUM(AB17/X17)-1 -> #DIV/0!
B18: (-) XXX | S18: =SUM(E18:H18) -> 0 | T18: =SUM(F18:I18) -> 0 | U18: =SUM(G18:J18) -> 0 | V18: =SUM(H18:K18) -> 0 | W18: =SUM(I18:L18) -> 0 | X18: =SUM(J18:M18) -> 0 | Y18: =SUM(K18:N18) -> 0 | Z18: =SUM(L18:O18) -> 0 | ... AB18: =SUM(N18:Q18) -> 0 | AD18: =SUM(AB18/X18)-1 -> #DIV/0!
B19: (-) XXX | S19: =SUM(E19:H19) -> 0 | T19: =SUM(F19:I19) -> 0 | U19: =SUM(G19:J19) -> 0 | V19: =SUM(H19:K19) -> 0 | W19: =SUM(I19:L19) -> 0 | X19: =SUM(J19:M19) -> 0 | Y19: =SUM(K19:N19) -> 0 | Z19: =SUM(L19:O19) -> 0 | ... AB19: =SUM(N19:Q19) -> 0 | AD19: =SUM(AB19/X19)-1 -> #DIV/0!
B20: (-) XXX | S20: =SUM(E20:H20) -> 0 | T20: =SUM(F20:I20) -> 0 | U20: =SUM(G20:J20) -> 0 | V20: =SUM(H20:K20) -> 0 | W20: =SUM(I20:L20) -> 0 | X20: =SUM(J20:M20) -> 0 | Y20: =SUM(K20:N20) -> 0 | Z20: =SUM(L20:O20) -> 0 | ... AB20: =SUM(N20:Q20) -> 0 | AD20: =SUM(AB20/X20)-1 -> #DIV/0!
B21: Earning before Interest & Taxes (EBIT) | C21: =SUM(C13+SUM(C16:C20)) -> 25004 | D21: =SUM(D13+SUM(D16:D20)) -> 27234 | E21: =SUM(E13+SUM(E16:E20)) -> 28737 | G21: =SUM(G13+SUM(G16:G20)) -> 6663 | H21: =SUM(H13+SUM(H16:H20)) -> 7060 | I21: =SUM(I13+SUM(I16:I20)) -> 7296 | J21: =SUM(J13+SUM(J16:J20)) -> 6215 | K21: =SUM(K13+SUM(K16:K20)) -> 7065 | L21: =SUM(L13+SUM(L16:L20)) -> 7551 | M21: =SUM(M13+SUM(M16:M20)) -> 7190 | N21: =SUM(N13+SUM(N16:N20)) -> 6931 | ... Q21: =SUM(Q13+SUM(Q16:Q20)) -> 0 | S21: =SUM(S13+SUM(S16:S20)) -> 42460 | T21: =SUM(T13+SUM(T16:T20)) -> 21019 | U21: =SUM(U13+SUM(U16:U20)) -> 27234 | V21: =SUM(V13+SUM(V16:V20)) -> 27636 | W21: =SUM(W13+SUM(W16:W20)) -> 28127 | X21: =SUM(X13+SUM(X16:X20)) -> 28021 | Y21: =SUM(Y13+SUM(Y16:Y20)) -> 28737 | Z21: =SUM(Z13+SUM(Z16:Z20)) -> 28638 | ... AB21: =SUM(AB13+SUM(AB16:AB20)) -> 13897 | AD21: =SUM(AB21/X21)-1 -> -0.50405053
B22: Operating Margin (%) | C22: =C21/C8 -> 0.58143429 | D22: =D21/D8 -> 0.59522665 | E22: =E21/E8 -> 0.61063301 | G22: =G21/G8 -> 0.6068306 | H22: =H21/H8 -> 0.58970932 | I22: =I21/I8 -> 0.6103907 | J22: =J21/J8 -> 0.57286386 | K22: =K21/K8 -> 0.62522124 | L22: =L21/L8 -> 0.61077408 | M22: =M21/M8 -> 0.60654631 | N22: =N21/N8 -> 0.60039848 | ... Q22: =Q21/Q8 -> #DIV/0! | S22: =S21/S8 -> 0.6064588 | T22: =T21/T8 -> 0.60217734 | U22: =U21/U8 -> 0.59522665 | V22: =V21/V8 -> 0.59981768 | W22: =W21/W8 -> 0.60533735 | X22: =X21/X8 -> 0.6043437 | Y22: =Y21/Y8 -> 0.61063301 | Z22: =Z21/Z8 -> 0.61074856 | ... AB22: =AB21/AB8 -> 0.61293168 | AD22: =SUM(AB22-X22)*10000 -> 85.879807
B24: (+) Depreciation and Amortization (D&A) | S24: =SUM(E24:H24) -> 0 | T24: =SUM(F24:I24) -> 0 | U24: =SUM(G24:J24) -> 0 | V24: =SUM(H24:K24) -> 0 | W24: =SUM(I24:L24) -> 0 | X24: =SUM(J24:M24) -> 0 | Y24: =SUM(K24:N24) -> 0 | Z24: =SUM(L24:O24) -> 0 | ... AB24: =SUM(N24:Q24) -> 0 | AD24: =SUM(AB24/X24)-1 -> #DIV/0!
B25: EBITDA | C25: =SUM(C21+SUM(C24:C24)) -> 25004 | D25: =SUM(D21+SUM(D24:D24)) -> 27234 | E25: =SUM(E21+SUM(E24:E24)) -> 28737 | G25: =SUM(G21+SUM(G24:G24)) -> 6663 | H25: =SUM(H21+SUM(H24:H24)) -> 7060 | I25: =SUM(I21+SUM(I24:I24)) -> 7296 | J25: =SUM(J21+SUM(J24:J24)) -> 6215 | K25: =SUM(K21+SUM(K24:K24)) -> 7065 | L25: =SUM(L21+SUM(L24:L24)) -> 7551 | M25: =SUM(M21+SUM(M24:M24)) -> 7190 | N25: =SUM(N21+SUM(N24:N24)) -> 6931 | ... Q25: =SUM(Q21+SUM(Q24:Q24)) -> 0 | S25: =SUM(S21+SUM(S24:S24)) -> 42460 | T25: =SUM(T21+SUM(T24:T24)) -> 21019 | U25: =SUM(U21+SUM(U24:U24)) -> 27234 | V25: =SUM(V21+SUM(V24:V24)) -> 27636 | W25: =SUM(W21+SUM(W24:W24)) -> 28127 | X25: =SUM(X21+SUM(X24:X24)) -> 28021 | Y25: =SUM(Y21+SUM(Y24:Y24)) -> 28737 | Z25: =SUM(Z21+SUM(Z24:Z24)) -> 28638 | ... AB25: =SUM(AB21+SUM(AB24:AB24)) -> 13897 | AD25: =SUM(AB25/X25)-1 -> -0.50405053
B26: EBITDA Margin (%) | C26: =C25/C8 -> 0.58143429 | D26: =D25/D8 -> 0.59522665 | E26: =E25/E8 -> 0.61063301 | G26: =G25/G8 -> 0.6068306 | H26: =H25/H8 -> 0.58970932 | I26: =I25/I8 -> 0.6103907 | J26: =J25/J8 -> 0.57286386 | K26: =K25/K8 -> 0.62522124 | L26: =L25/L8 -> 0.61077408 | M26: =M25/M8 -> 0.60654631 | N26: =N25/N8 -> 0.60039848 | ... Q26: =Q25/Q8 -> #DIV/0! | S26: =S25/S8 -> 0.6064588 | T26: =T25/T8 -> 0.60217734 | U26: =U25/U8 -> 0.59522665 | V26: =V25/V8 -> 0.59981768 | W26: =W25/W8 -> 0.60533735 | X26: =X25/X8 -> 0.6043437 | Y26: =Y25/Y8 -> 0.61063301 | Z26: =Z25/Z8 -> 0.61074856 | ... AB26: =AB25/AB8 -> 0.61293168 | AD26: =SUM(AB26-X26)*10000 -> 85.879807
B28: (+) Stock-Based Compensation (SBC) | S28: =SUM(E28:H28) -> 0 | T28: =SUM(F28:I28) -> 0 | U28: =SUM(G28:J28) -> 0 | V28: =SUM(H28:K28) -> 0 | W28: =SUM(I28:L28) -> 0 | X28: =SUM(J28:M28) -> 0 | Y28: =SUM(K28:N28) -> 0 | Z28: =SUM(L28:O28) -> 0 | ... AB28: =SUM(N28:Q28) -> 0 | AD28: =SUM(AB28/X28)-1 -> #DIV/0!
B29: (+) XXX | S29: =SUM(E29:H29) -> 0 | T29: =SUM(F29:I29) -> 0 | U29: =SUM(G29:J29) -> 0 | V29: =SUM(H29:K29) -> 0 | W29: =SUM(I29:L29) -> 0 | X29: =SUM(J29:M29) -> 0 | Y29: =SUM(K29:N29) -> 0 | Z29: =SUM(L29:O29) -> 0 | ... AB29: =SUM(N29:Q29) -> 0 | AD29: =SUM(AB29/X29)-1 -> #DIV/0!
B30: Adj. EBITDA | C30: =+SUM(C25+SUM(C28:C28)) -> 25004 | D30: =+SUM(D25+SUM(D28:D28)) -> 27234 | E30: =+SUM(E25+SUM(E28:E28)) -> 28737 | G30: =+SUM(G25+SUM(G28:G28)) -> 6663 | H30: =+SUM(H25+SUM(H28:H28)) -> 7060 | I30: =+SUM(I25+SUM(I28:I28)) -> 7296 | J30: =+SUM(J25+SUM(J28:J28)) -> 6215 | K30: =+SUM(K25+SUM(K28:K28)) -> 7065 | L30: =+SUM(L25+SUM(L28:L28)) -> 7551 | M30: =+SUM(M25+SUM(M28:M28)) -> 7190 | N30: =+SUM(N25+SUM(N28:N28)) -> 6931 | ... Q30: =+SUM(Q25+SUM(Q28:Q28)) -> 0 | S30: =+SUM(S25+SUM(S28:S28)) -> 42460 | T30: =+SUM(T25+SUM(T28:T28)) -> 21019 | U30: =+SUM(U25+SUM(U28:U28)) -> 27234 | V30: =+SUM(V25+SUM(V28:V28)) -> 27636 | W30: =+SUM(W25+SUM(W28:W28)) -> 28127 | X30: =+SUM(X25+SUM(X28:X28)) -> 28021 | Y30: =+SUM(Y25+SUM(Y28:Y28)) -> 28737 | Z30: =+SUM(Z25+SUM(Z28:Z28)) -> 28638 | ... AB30: =+SUM(AB25+SUM(AB28:AB28)) -> 13897 | AD30: =SUM(AB30/X30)-1 -> -0.50405053
B31: Adj. EBITDA Margin (%) | C31: =C30/C8 -> 0.58143429 | D31: =D30/D8 -> 0.59522665 | E31: =E30/E8 -> 0.61063301 | G31: =G30/G8 -> 0.6068306 | H31: =H30/H8 -> 0.58970932 | I31: =I30/I8 -> 0.6103907 | J31: =J30/J8 -> 0.57286386 | K31: =K30/K8 -> 0.62522124 | L31: =L30/L8 -> 0.61077408 | M31: =M30/M8 -> 0.60654631 | N31: =N30/N8 -> 0.60039848 | ... Q31: =Q30/Q8 -> #DIV/0! | S31: =S30/S8 -> 0.6064588 | T31: =T30/T8 -> 0.60217734 | U31: =U30/U8 -> 0.59522665 | V31: =V30/V8 -> 0.59981768 | W31: =W30/W8 -> 0.60533735 | X31: =X30/X8 -> 0.6043437 | Y31: =Y30/Y8 -> 0.61063301 | Z31: =Z30/Z8 -> 0.61074856 | ... AB31: =AB30/AB8 -> 0.61293168 | AD31: =SUM(AB31-X31)*10000 -> 85.879807
B33: (-) Capital Expenditures | S33: =SUM(E33:H33) -> 0 | T33: =SUM(F33:I33) -> 0 | U33: =SUM(G33:J33) -> 0 | V33: =SUM(H33:K33) -> 0 | W33: =SUM(I33:L33) -> 0 | X33: =SUM(J33:M33) -> 0 | Y33: =SUM(K33:N33) -> 0 | Z33: =SUM(L33:O33) -> 0 | ... AB33: =SUM(N33:Q33) -> 0 | AD33: =SUM(AB33/X33)-1 -> #DIV/0!
B34: (-) Cash Taxes | S34: =SUM(E34:H34) -> 0 | T34: =SUM(F34:I34) -> 0 | U34: =SUM(G34:J34) -> 0 | V34: =SUM(H34:K34) -> 0 | W34: =SUM(I34:L34) -> 0 | X34: =SUM(J34:M34) -> 0 | Y34: =SUM(K34:N34) -> 0 | Z34: =SUM(L34:O34) -> 0 | ... AB34: =SUM(N34:Q34) -> 0 | AD34: =SUM(AB34/X34)-1 -> #DIV/0!
B35: (-) Cash Interest | S35: =SUM(E35:H35) -> 0 | T35: =SUM(F35:I35) -> 0 | U35: =SUM(G35:J35) -> 0 | V35: =SUM(H35:K35) -> 0 | W35: =SUM(I35:L35) -> 0 | X35: =SUM(J35:M35) -> 0 | Y35: =SUM(K35:N35) -> 0 | Z35: =SUM(L35:O35) -> 0 | ... AB35: =SUM(N35:Q35) -> 0 | AD35: =SUM(AB35/X35)-1 -> #DIV/0!
B36: (-) Mandatory Outflows | S36: =SUM(E36:H36) -> 0 | T36: =SUM(F36:I36) -> 0 | U36: =SUM(G36:J36) -> 0 | V36: =SUM(H36:K36) -> 0 | W36: =SUM(I36:L36) -> 0 | X36: =SUM(J36:M36) -> 0 | Y36: =SUM(K36:N36) -> 0 | Z36: =SUM(L36:O36) -> 0 | ... AB36: =SUM(N36:Q36) -> 0 | AD36: =SUM(AB36/X36)-1 -> #DIV/0!
B37: (+/-) Changes in NWC | S37: =SUM(E37:H37) -> 0 | T37: =SUM(F37:I37) -> 0 | U37: =SUM(G37:J37) -> 0 | V37: =SUM(H37:K37) -> 0 | W37: =SUM(I37:L37) -> 0 | X37: =SUM(J37:M37) -> 0 | Y37: =SUM(K37:N37) -> 0 | Z37: =SUM(L37:O37) -> 0 | ... AB37: =SUM(N37:Q37) -> 0 | AD37: =SUM(AB37/X37)-1 -> #DIV/0!
B38: Discretionary Cash-Flows | C38: =SUM(C30+SUM(C33:C37)) -> 25004 | D38: =SUM(D30+SUM(D33:D37)) -> 27234 | E38: =SUM(E30+SUM(E33:E37)) -> 28737 | G38: =SUM(G30+SUM(G33:G37)) -> 6663 | H38: =SUM(H30+SUM(H33:H37)) -> 7060 | I38: =SUM(I30+SUM(I33:I37)) -> 7296 | J38: =SUM(J30+SUM(J33:J37)) -> 6215 | K38: =SUM(K30+SUM(K33:K37)) -> 7065 | L38: =SUM(L30+SUM(L33:L37)) -> 7551 | M38: =SUM(M30+SUM(M33:M37)) -> 7190 | N38: =SUM(N30+SUM(N33:N37)) -> 6931 | ... Q38: =SUM(Q30+SUM(Q33:Q37)) -> 0 | S38: =SUM(S30+SUM(S33:S37)) -> 42460 | T38: =SUM(T30+SUM(T33:T37)) -> 21019 | U38: =SUM(U30+SUM(U33:U37)) -> 27234 | V38: =SUM(V30+SUM(V33:V37)) -> 27636 | W38: =SUM(W30+SUM(W33:W37)) -> 28127 | X38: =SUM(X30+SUM(X33:X37)) -> 28021 | Y38: =SUM(Y30+SUM(Y33:Y37)) -> 28737 | Z38: =SUM(Z30+SUM(Z33:Z37)) -> 28638 | ... AB38: =SUM(AB30+SUM(AB33:AB37)) -> 13897 | AD38: =SUM(AB38/X38)-1 -> -0.50405053
B40: (+/-) XXX | S40: =SUM(E40:H40) -> 0 | T40: =SUM(F40:I40) -> 0 | U40: =SUM(G40:J40) -> 0 | V40: =SUM(H40:K40) -> 0 | W40: =SUM(I40:L40) -> 0 | X40: =SUM(J40:M40) -> 0 | Y40: =SUM(K40:N40) -> 0 | Z40: =SUM(L40:O40) -> 0 | ... AB40: =SUM(N40:Q40) -> 0
B41: (+/-) XXX | S41: =SUM(E41:H41) -> 0 | T41: =SUM(F41:I41) -> 0 | U41: =SUM(G41:J41) -> 0 | V41: =SUM(H41:K41) -> 0 | W41: =SUM(I41:L41) -> 0 | X41: =SUM(J41:M41) -> 0 | Y41: =SUM(K41:N41) -> 0 | Z41: =SUM(L41:O41) -> 0 | ... AB41: =SUM(N41:Q41) -> 0
B42: (+/-) XXX | S42: =SUM(E42:H42) -> 0 | T42: =SUM(F42:I42) -> 0 | U42: =SUM(G42:J42) -> 0 | V42: =SUM(H42:K42) -> 0 | W42: =SUM(I42:L42) -> 0 | X42: =SUM(J42:M42) -> 0 | Y42: =SUM(K42:N42) -> 0 | Z42: =SUM(L42:O42) -> 0 | ... AB42: =SUM(N42:Q42) -> 0
B43: (+/-) XXX | S43: =SUM(E43:H43) -> 0 | T43: =SUM(F43:I43) -> 0 | U43: =SUM(G43:J43) -> 0 | V43: =SUM(H43:K43) -> 0 | W43: =SUM(I43:L43) -> 0 | X43: =SUM(J43:M43) -> 0 | Y43: =SUM(K43:N43) -> 0 | Z43: =SUM(L43:O43) -> 0 | ... AB43: =SUM(N43:Q43) -> 0
B44: (+/-) XXX | S44: =SUM(E44:H44) -> 0 | T44: =SUM(F44:I44) -> 0 | U44: =SUM(G44:J44) -> 0 | V44: =SUM(H44:K44) -> 0 | W44: =SUM(I44:L44) -> 0 | X44: =SUM(J44:M44) -> 0 | Y44: =SUM(K44:N44) -> 0 | Z44: =SUM(L44:O44) -> 0 | ... AB44: =SUM(N44:Q44) -> 0
B45: (+/-) Other | D45: =SUM(D50)-SUM(C50)-SUM(D38:D44) -> -27234 | E45: =SUM(E50)-SUM(D50)-SUM(E38:E44) -> -28737 | G45: =SUM(G50)-SUM(C50)-SUM(G38:G44) -> -6663 | H45: =SUM(H50)-SUM(G50)-SUM(H38:H44) -> -7060 | I45: =SUM(I50)-SUM(H50)-SUM(I38:I44) -> -7296 | J45: =SUM(J50)-SUM(I50)-SUM(J38:J44) -> -6215 | K45: =SUM(K50)-SUM(J50)-SUM(K38:K44) -> -7065 | L45: =SUM(L50)-SUM(K50)-SUM(L38:L44) -> -7551 | M45: =SUM(M50)-SUM(L50)-SUM(M38:M44) -> -7190 | N45: =SUM(N50)-SUM(M50)-SUM(N38:N44) -> -6931 | O45: =SUM(O50)-SUM(N50)-SUM(O38:O44) -> -6966 | ... Q45: =SUM(Q50)-SUM(P50)-SUM(Q38:Q44) -> 0 | S45: =SUM(E45:H45) -> -42460 | T45: =SUM(F45:I45) -> -21019 | U45: =SUM(G45:J45) -> -27234 | V45: =SUM(H45:K45) -> -27636 | W45: =SUM(I45:L45) -> -28127 | X45: =SUM(J45:M45) -> -28021 | Y45: =SUM(K45:N45) -> -28737 | Z45: =SUM(L45:O45) -> -28638 | ... AB45: =SUM(N45:Q45) -> -13897
B46: Free-Cash Flows | C46: =SUM(C38+SUM(C40:C45)) -> 25004 | D46: =SUM(D38+SUM(D40:D45)) -> 0 | E46: =SUM(E38+SUM(E40:E45)) -> 0 | G46: =SUM(G38+SUM(G40:G45)) -> 0 | H46: =SUM(H38+SUM(H40:H45)) -> 0 | I46: =SUM(I38+SUM(I40:I45)) -> 0 | J46: =SUM(J38+SUM(J40:J45)) -> 0 | K46: =SUM(K38+SUM(K40:K45)) -> 0 | L46: =SUM(L38+SUM(L40:L45)) -> 0 | M46: =SUM(M38+SUM(M40:M45)) -> 0 | N46: =SUM(N38+SUM(N40:N45)) -> 0 | ... Q46: =SUM(Q38+SUM(Q40:Q45)) -> 0 | S46: =SUM(S38+SUM(S40:S45)) -> 0 | T46: =SUM(T38+SUM(T40:T45)) -> 0 | U46: =SUM(U38+SUM(U40:U45)) -> 0 | V46: =SUM(V38+SUM(V40:V45)) -> 0 | W46: =SUM(W38+SUM(W40:W45)) -> 0 | X46: =SUM(X38+SUM(X40:X45)) -> 0 | Y46: =SUM(Y38+SUM(Y40:Y45)) -> 0 | Z46: =SUM(Z38+SUM(Z40:Z45)) -> 0 | ... AB46: =SUM(AB38+SUM(AB40:AB45)) -> 0
B48: Capitalization
B50: Cash & Cash Equivelants | S50: =H50 -> 0 | T50: =I50 -> 0 | U50: =J50 -> 0 | V50: =K50 -> 0 | W50: =L50 -> 0 | X50: =M50 -> 0 | Y50: =N50 -> 0 | Z50: =O50 -> 0 | ... AB50: =Q50 -> 0
...
