Workbook

Sheet Historical Financials
B2: Anavex Life Sciences Corp. (AVXL)
B3: Historical Financials
B4: $ in thousands except per share
A6: X | B6: Income Statement | C6: FYE | H6: Quarterly | R6: Quarterly | AC6: LTM | AI6: Variance
B7: Fiscal Period | C7: 2021 | D7: 2022 | E7: 2023 | F7: 2024 | H7: 1Q22 | I7: 2Q22 | J7: 3Q22 | K7: 4Q22 | L7: 1Q23 | M7: 2Q23 | N7: 3Q23 | O7: 4Q23 | P7: 1Q24 | Q7: 2Q24 | R7: 3Q24 | S7: 4Q24 | T7: 1Q25 | U7: 2Q25 | W7: =K7 -> 4Q22 | X7: =L7 -> 1Q23 | Y7: =M7 -> 2Q23 | Z7: =N7 -> 3Q23 | AA7: =O7 -> 4Q23 | AB7: =P7 -> 1Q24 | AC7: =Q7 -> 2Q24 | AD7: =R7 -> 3Q24 | ... AG7: =U7 -> 2Q25
B8: Fiscal Period End Date | C8: 44561 | D8: 44926 | E8: 45291 | F8: 45657 | H8: 44651 | I8: 44742 | J8: 44834 | K8: 44926 | L8: 45016 | M8: 45107 | N8: 45199 | O8: 45291 | P8: 45382 | Q8: 45473 | R8: 45565 | S8: 45657 | T8: 45747 | U8: 45838 | W8: =K8 -> 44926 | X8: =L8 -> 45016 | Y8: =M8 -> 45107 | Z8: =N8 -> 45199 | AA8: =O8 -> 45291 | AB8: =P8 -> 45382 | AC8: =Q8 -> 45473 | AD8: =R8 -> 45565 | ... AG8: =U8 -> 45838
B10: Consolidated Revenue | C10: 0 | D10: 0 | E10: 0 | F10: 0 | H10: 0 | I10: 0 | J10: 0 | K10: =SUM(D10-SUM(H10:J10)) -> 0 | L10: 0 | M10: 0 | N10: 0 | O10: =SUM(E10-SUM(L10:N10)) -> 0 | P10: 0 | Q10: 0 | R10: 0 | S10: =SUM(F10-SUM(P10:R10)) -> 0 | W10: =SUM(H10:K10) -> 0 | X10: =SUM(I10:L10) -> 0 | Y10: =SUM(J10:M10) -> 0 | Z10: =SUM(K10:N10) -> 0 | AA10: =SUM(L10:O10) -> 0 | AB10: =SUM(M10:P10) -> 0 | AC10: =SUM(N10:Q10) -> 0 | AD10: =SUM(O10:R10) -> 0 | ... AG10: =SUM(R10:U10) -> 0 | AI10: =SUM(AG10/AC10)-1 -> #DIV/0!
B11: Total Revenue | C11: =+SUM(C10:C10) -> 0 | D11: =+SUM(D10:D10) -> 0 | E11: =+SUM(E10:E10) -> 0 | F11: =+SUM(F10:F10) -> 0 | H11: =+SUM(H10:H10) -> 0 | I11: =+SUM(I10:I10) -> 0 | J11: =+SUM(J10:J10) -> 0 | K11: =+SUM(K10:K10) -> 0 | L11: =+SUM(L10:L10) -> 0 | M11: =+SUM(M10:M10) -> 0 | N11: =+SUM(N10:N10) -> 0 | O11: =+SUM(O10:O10) -> 0 | ... U11: =+SUM(U10:U10) -> 0 | W11: =+SUM(W10:W10) -> 0 | X11: =+SUM(X10:X10) -> 0 | Y11: =+SUM(Y10:Y10) -> 0 | Z11: =+SUM(Z10:Z10) -> 0 | AA11: =+SUM(AA10:AA10) -> 0 | AB11: =+SUM(AB10:AB10) -> 0 | AC11: =+SUM(AC10:AC10) -> 0 | AD11: =+SUM(AD10:AD10) -> 0 | ... AG11: =+SUM(AG10:AG10) -> 0 | AI11: =SUM(AG11/AC11)-1 -> #DIV/0!
B13: Cost of Sales | C13: 0 | D13: 0 | E13: 0 | F13: 0 | K13: =SUM(D13-SUM(H13:J13)) -> 0 | O13: =SUM(E13-SUM(L13:N13)) -> 0 | S13: =SUM(F13-SUM(P13:R13)) -> 0 | W13: =SUM(I13:L13) -> 0 | X13: =SUM(J13:M13) -> 0 | Y13: =SUM(K13:N13) -> 0 | Z13: =SUM(L13:O13) -> 0 | AA13: =SUM(M13:P13) -> 0 | AB13: =SUM(N13:Q13) -> 0 | AC13: =SUM(N13:Q13) -> 0 | AD13: =SUM(O13:R13) -> 0 | AE13: =SUM(P13:S13) -> 0 | AF13: =SUM(Q13:T13) -> 0 | AG13: =SUM(R13:U13) -> 0 | AI13: =SUM(AG13/AC13)-1 -> #DIV/0!
B14: Gross Profit | C14: =+SUM(C11+SUM(C13:C13)) -> 0 | D14: =+SUM(D11+SUM(D13:D13)) -> 0 | E14: =+SUM(E11+SUM(E13:E13)) -> 0 | F14: =+SUM(F11+SUM(F13:F13)) -> 0 | H14: =+SUM(H11+SUM(H13:H13)) -> 0 | I14: =+SUM(I11+SUM(I13:I13)) -> 0 | J14: =+SUM(J11+SUM(J13:J13)) -> 0 | K14: =+SUM(K11+SUM(K13:K13)) -> 0 | L14: =+SUM(L11+SUM(L13:L13)) -> 0 | M14: =+SUM(M11+SUM(M13:M13)) -> 0 | N14: =+SUM(N11+SUM(N13:N13)) -> 0 | O14: =+SUM(O11+SUM(O13:O13)) -> 0 | ... U14: =+SUM(U11+SUM(U13:U13)) -> 0 | W14: =+SUM(W11+SUM(W13:W13)) -> 0 | X14: =+SUM(X11+SUM(X13:X13)) -> 0 | Y14: =+SUM(Y11+SUM(Y13:Y13)) -> 0 | Z14: =+SUM(Z11+SUM(Z13:Z13)) -> 0 | AA14: =+SUM(AA11+SUM(AA13:AA13)) -> 0 | AB14: =+SUM(AB11+SUM(AB13:AB13)) -> 0 | AC14: =+SUM(AC11+SUM(AC13:AC13)) -> 0 | AD14: =+SUM(AD11+SUM(AD13:AD13)) -> 0 | ... AG14: =+SUM(AG11+SUM(AG13:AG13)) -> 0 | AI14: =SUM(AG14/AC14)-1 -> #DIV/0!
B15: Gross Margin (%) | C15: =C14/C11 -> #DIV/0! | D15: =D14/D11 -> #DIV/0! | E15: =E14/E11 -> #DIV/0! | F15: =F14/F11 -> #DIV/0! | H15: =H14/H11 -> #DIV/0! | I15: =I14/I11 -> #DIV/0! | J15: =J14/J11 -> #DIV/0! | K15: =K14/K11 -> #DIV/0! | L15: =L14/L11 -> #DIV/0! | M15: =M14/M11 -> #DIV/0! | N15: =N14/N11 -> #DIV/0! | O15: =O14/O11 -> #DIV/0! | ... U15: =U14/U11 -> #DIV/0! | W15: =W14/W11 -> #DIV/0! | X15: =X14/X11 -> #DIV/0! | Y15: =Y14/Y11 -> #DIV/0! | Z15: =Z14/Z11 -> #DIV/0! | AA15: =AA14/AA11 -> #DIV/0! | AB15: =AB14/AB11 -> #DIV/0! | AC15: =AC14/AC11 -> #DIV/0! | AD15: =AD14/AD11 -> #DIV/0! | ... AG15: =AG14/AG11 -> #DIV/0! | AI15: =SUM(AG15-AC15)*1000 -> #DIV/0!
B17: General and administrative | C17: -9018 | D17: -13070 | E17: -12039 | F17: -11039 | H17: -3066.951 | I17: -2915.158 | J17: -3185.451 | K17: =SUM(D17-SUM(H17:J17)) -> -3902.44 | L17: -3317.036 | M17: -2882.568 | N17: -3247.843 | O17: =SUM(E17-SUM(L17:N17)) -> -2591.553 | P17: -2609 | Q17: -2790 | R17: -2859 | S17: =SUM(F17-SUM(P17:R17)) -> -2781 | W17: =SUM(I17:L17) -> -13320.085 | X17: =SUM(J17:M17) -> -13287.495 | Y17: =SUM(K17:N17) -> -13349.887 | Z17: =SUM(L17:O17) -> -12039 | AA17: =SUM(M17:P17) -> -11330.964 | AB17: =SUM(N17:Q17) -> -11238.396 | AC17: =SUM(N17:Q17) -> -11238.396 | AD17: =SUM(O17:R17) -> -10849.553 | AE17: =SUM(P17:S17) -> -11039 | AF17: =SUM(Q17:T17) -> -8430 | AG17: =SUM(R17:U17) -> -5640 | AI17: =SUM(AG17/AC17)-1 -> -0.49814902
B18: Research and development | C18: -32984 | D18: -37916 | E18: -43717 | F18: -41838 | H18: -8656.439 | I18: -8604.589 | J18: -9273.269 | K18: =SUM(D18-SUM(H18:J18)) -> -11381.703 | L18: -12066.919 | M18: -11306.591 | N18: -10282.854 | O18: =SUM(E18-SUM(L18:N18)) -> -10060.636 | P18: -8684 | Q18: -9729 | R18: -11870 | S18: =SUM(F18-SUM(P18:R18)) -> -11555 | W18: =SUM(I18:L18) -> -41326.48 | X18: =SUM(J18:M18) -> -44028.482 | Y18: =SUM(K18:N18) -> -45038.067 | Z18: =SUM(L18:O18) -> -43717 | AA18: =SUM(M18:P18) -> -40334.081 | AB18: =SUM(N18:Q18) -> -38756.49 | AC18: =SUM(N18:Q18) -> -38756.49 | AD18: =SUM(O18:R18) -> -40343.636 | AE18: =SUM(P18:S18) -> -41838 | AF18: =SUM(Q18:T18) -> -33154 | AG18: =SUM(R18:U18) -> -23425 | AI18: =SUM(AG18/AC18)-1 -> -0.3955851
B19: Operating Profit | C19: =+SUM(C14+SUM(C17:C18)) -> -42002 | D19: =+SUM(D14+SUM(D17:D18)) -> -50986 | E19: =+SUM(E14+SUM(E17:E18)) -> -55756 | F19: =+SUM(F14+SUM(F17:F18)) -> -52877 | H19: =+SUM(H14+SUM(H17:H18)) -> -11723.39 | I19: =+SUM(I14+SUM(I17:I18)) -> -11519.747 | J19: =+SUM(J14+SUM(J17:J18)) -> -12458.72 | K19: =+SUM(K14+SUM(K17:K18)) -> -15284.143 | L19: =+SUM(L14+SUM(L17:L18)) -> -15383.955 | M19: =+SUM(M14+SUM(M17:M18)) -> -14189.159 | N19: =+SUM(N14+SUM(N17:N18)) -> -13530.697 | O19: =+SUM(O14+SUM(O17:O18)) -> -12652.189 | ... U19: =+SUM(U14+SUM(U17:U18)) -> 0 | W19: =+SUM(W14+SUM(W17:W18)) -> -54646.565 | X19: =+SUM(X14+SUM(X17:X18)) -> -57315.977 | Y19: =+SUM(Y14+SUM(Y17:Y18)) -> -58387.954 | Z19: =+SUM(Z14+SUM(Z17:Z18)) -> -55756 | AA19: =+SUM(AA14+SUM(AA17:AA18)) -> -51665.045 | AB19: =+SUM(AB14+SUM(AB17:AB18)) -> -49994.886 | AC19: =+SUM(AC14+SUM(AC17:AC18)) -> -49994.886 | AD19: =+SUM(AD14+SUM(AD17:AD18)) -> -51193.189 | ... AG19: =+SUM(AG14+SUM(AG17:AG18)) -> -29065 | AI19: =SUM(AG19/AC19)-1 -> -0.41864054
B20: Operating Margin (%) | C20: =C19/C11 -> #DIV/0! | D20: =D19/D11 -> #DIV/0! | E20: =E19/E11 -> #DIV/0! | F20: =F19/F11 -> #DIV/0! | H20: =H19/H11 -> #DIV/0! | I20: =I19/I11 -> #DIV/0! | J20: =J19/J11 -> #DIV/0! | K20: =K19/K11 -> #DIV/0! | L20: =L19/L11 -> #DIV/0! | M20: =M19/M11 -> #DIV/0! | N20: =N19/N11 -> #DIV/0! | O20: =O19/O11 -> #DIV/0! | ... U20: =U19/U11 -> #DIV/0! | W20: =W19/W11 -> #DIV/0! | X20: =X19/X11 -> #DIV/0! | Y20: =Y19/Y11 -> #DIV/0! | Z20: =Z19/Z11 -> #DIV/0! | AA20: =AA19/AA11 -> #DIV/0! | AB20: =AB19/AB11 -> #DIV/0! | AC20: =AC19/AC11 -> #DIV/0! | AD20: =AD19/AD11 -> #DIV/0! | ... AG20: =AG19/AG11 -> #DIV/0! | AI20: =SUM(AG20-AC20)*1000 -> #DIV/0!
B22: Grant income | C22: 54 | E22: 25 | F22: 75 | K22: =SUM(D22-SUM(H22:J22)) -> 0 | L22: 25 | O22: =SUM(E22-SUM(L22:N22)) -> 0 | Q22: 0 | R22: 0 | S22: =SUM(F22-SUM(P22:R22)) -> 75 | W22: =SUM(I22:L22) -> 25 | X22: =SUM(J22:M22) -> 25 | Y22: =SUM(K22:N22) -> 25 | Z22: =SUM(L22:O22) -> 25 | AA22: =SUM(M22:P22) -> 0 | AB22: =SUM(N22:Q22) -> 0 | AC22: =SUM(N22:Q22) -> 0 | AD22: =SUM(O22:R22) -> 0 | AE22: =SUM(P22:S22) -> 75 | AF22: =SUM(Q22:T22) -> 75 | AG22: =SUM(R22:U22) -> 75 | AI22: =SUM(AG22/AC22)-1 -> #DIV/0!
B23: Research and development incentive income | C23: 4547 | D23: 3323 | E23: 2718 | F23: 2291 | H23: 810.73 | I23: 835.513 | J23: 682.432 | K23: =SUM(D23-SUM(H23:J23)) -> 994.325 | L23: 733.59 | M23: 749.681 | N23: 564.842 | O23: =SUM(E23-SUM(L23:N23)) -> 669.887 | P23: 592 | Q23: 472 | R23: 526 | S23: =SUM(F23-SUM(P23:R23)) -> 701 | AC23: =SUM(N23:Q23) -> 2298.729 | AD23: =SUM(O23:R23) -> 2259.887 | AE23: =SUM(P23:S23) -> 2291 | AF23: =SUM(Q23:T23) -> 1699 | AG23: =SUM(R23:U23) -> 1227 | AI23: =SUM(AG23/AC23)-1 -> -0.46622677
B24: Interest income (expense), net | C24: 26 | D24: 947 | E24: 6519 | F24: 7320 | H24: 4.91 | I24: 7.578 | J24: 229.917 | K24: =SUM(D24-SUM(H24:J24)) -> 704.595 | L24: 1267.618 | M24: 1465.221 | N24: 1827.945 | O24: =SUM(E24-SUM(L24:N24)) -> 1958.216 | P24: 2008 | Q24: 1756 | R24: 1796 | S24: =SUM(F24-SUM(P24:R24)) -> 1760 | AC24: =SUM(N24:Q24) -> 7550.161 | AD24: =SUM(O24:R24) -> 7518.216 | AE24: =SUM(P24:S24) -> 7320 | AF24: =SUM(Q24:T24) -> 5312 | AG24: =SUM(R24:U24) -> 3556 | AI24: =SUM(AG24/AC24)-1 -> -0.52901667
B25: Other financing expense | E25: -964 | F25: 0 | K25: =SUM(D25-SUM(H25:J25)) -> 0 | M25: -964.344 | O25: =SUM(E25-SUM(L25:N25)) -> 0.344 | P25: 0 | Q25: 0 | R25: 0 | S25: =SUM(F25-SUM(P25:R25)) -> 0 | AC25: =SUM(N25:Q25) -> 0.344 | AD25: =SUM(O25:R25) -> 0.344 | AE25: =SUM(P25:S25) -> 0 | AF25: =SUM(Q25:T25) -> 0 | AG25: =SUM(R25:U25) -> 0 | AI25: =SUM(AG25/AC25)-1 -> -1
B26: Foreign exchange gain (loss) | C26: -266 | D26: -904 | E26: -40 | F26: 189 | H26: 55.363 | I26: 268.645 | J26: -732.549 | K26: =SUM(D26-SUM(H26:J26)) -> -495.459 | L26: 365.983 | M26: -118.678 | N26: -101.066 | O26: =SUM(E26-SUM(L26:N26)) -> -186.239 | P26: 156 | Q26: -150 | R26: 67 | S26: =SUM(F26-SUM(P26:R26)) -> 116 | W26: =SUM(I26:L26) -> -593.38 | X26: =SUM(J26:M26) -> -980.703 | Y26: =SUM(K26:N26) -> -349.22 | Z26: =SUM(L26:O26) -> -40 | AA26: =SUM(M26:P26) -> -249.983 | AB26: =SUM(N26:Q26) -> -281.305 | AC26: =SUM(N26:Q26) -> -281.305 | AD26: =SUM(O26:R26) -> -113.239 | AE26: =SUM(P26:S26) -> 189 | AF26: =SUM(Q26:T26) -> 33 | AG26: =SUM(R26:U26) -> 183 | AI26: =SUM(AG26/AC26)-1 -> -1.6505395
B27: Gain on settlement of accounts payable | K27: =SUM(D27-SUM(H27:J27)) -> 0 | O27: =SUM(E27-SUM(L27:N27)) -> 0 | R27: 59 | S27: =SUM(F27-SUM(P27:R27)) -> -59 | W27: =SUM(I27:L27) -> 0 | X27: =SUM(J27:M27) -> 0 | Y27: =SUM(K27:N27) -> 0 | Z27: =SUM(L27:O27) -> 0 | AA27: =SUM(M27:P27) -> 0 | AB27: =SUM(N27:Q27) -> 0 | AC27: =SUM(N27:Q27) -> 0 | AD27: =SUM(O27:R27) -> 59 | AE27: =SUM(P27:S27) -> 0 | AF27: =SUM(Q27:T27) -> 0 | AG27: =SUM(R27:U27) -> 0 | AI27: =SUM(AG27/AC27)-1 -> #DIV/0!
B28: Earning Before Taxes | C28: =SUM(C19+SUM(C22:C27)) -> -37641 | D28: =SUM(D19+SUM(D22:D27)) -> -47620 | E28: =SUM(E19+SUM(E22:E27)) -> -47498 | F28: =SUM(F19+SUM(F22:F27)) -> -43002 | H28: =SUM(H19+SUM(H22:H27)) -> -10852.387 | I28: =SUM(I19+SUM(I22:I27)) -> -10408.011 | J28: =SUM(J19+SUM(J22:J27)) -> -12278.92 | K28: =SUM(K19+SUM(K22:K27)) -> -14080.682 | L28: =SUM(L19+SUM(L22:L27)) -> -12991.764 | M28: =SUM(M19+SUM(M22:M27)) -> -13057.279 | N28: =SUM(N19+SUM(N22:N27)) -> -11238.976 | O28: =SUM(O19+SUM(O22:O27)) -> -10209.981 | ... U28: =SUM(U19+SUM(U22:U27)) -> 0 | W28: =SUM(W19+SUM(W22:W27)) -> -55214.945 | X28: =SUM(X19+SUM(X22:X27)) -> -58271.68 | Y28: =SUM(Y19+SUM(Y22:Y27)) -> -58712.174 | Z28: =SUM(Z19+SUM(Z22:Z27)) -> -55771 | AA28: =SUM(AA19+SUM(AA22:AA27)) -> -51915.028 | AB28: =SUM(AB19+SUM(AB22:AB27)) -> -50276.191 | AC28: =SUM(AC19+SUM(AC22:AC27)) -> -40426.957 | AD28: =SUM(AD19+SUM(AD22:AD27)) -> -41468.981 | ... AG28: =SUM(AG19+SUM(AG22:AG27)) -> -24024 | AI28: =SUM(AG28/AC28)-1 -> -0.40574305
B29: EBT Margin (%) | C29: =C28/C11 -> #DIV/0! | D29: =D28/D11 -> #DIV/0! | E29: =E28/E11 -> #DIV/0! | F29: =F28/F11 -> #DIV/0! | H29: =H28/H11 -> #DIV/0! | I29: =I28/I11 -> #DIV/0! | J29: =J28/J11 -> #DIV/0! | K29: =K28/K11 -> #DIV/0! | L29: =L28/L11 -> #DIV/0! | M29: =M28/M11 -> #DIV/0! | N29: =N28/N11 -> #DIV/0! | O29: =O28/O11 -> #DIV/0! | ... U29: =U28/U11 -> #DIV/0! | W29: =W28/W11 -> #DIV/0! | X29: =X28/X11 -> #DIV/0! | Y29: =Y28/Y11 -> #DIV/0! | Z29: =Z28/Z11 -> #DIV/0! | AA29: =AA28/AA11 -> #DIV/0! | AB29: =AB28/AB11 -> #DIV/0! | AC29: =AC28/AC11 -> #DIV/0! | AD29: =AD28/AD11 -> #DIV/0! | ... AG29: =AG28/AG11 -> #DIV/0! | AI29: =SUM(AG29-AC29)*1000 -> #DIV/0!
B31: Provision for taxes | C31: -268 | D31: -358 | E31: -7 | F31: 0 | H31: -29.98 | I31: -29.8 | J31: -88.421 | K31: =SUM(D31-SUM(H31:J31)) -> -209.799 | L31: 20.046 | M31: -50 | N31: -41 | O31: =SUM(E31-SUM(L31:N31)) -> 63.954 | P31: -85 | Q31: -105 | R31: 67 | S31: =SUM(F31-SUM(P31:R31)) -> 123 | T31: 0 | W31: =SUM(I31:L31) -> -307.974 | X31: =SUM(J31:M31) -> -328.174 | Y31: =SUM(K31:N31) -> -280.753 | Z31: =SUM(L31:O31) -> -7 | AA31: =SUM(M31:P31) -> -112.046 | AB31: =SUM(N31:Q31) -> -167.046 | AC31: =SUM(N31:Q31) -> -167.046 | AD31: =SUM(O31:R31) -> -59.046 | AE31: =SUM(P31:S31) -> 0 | AF31: =SUM(Q31:T31) -> 85 | AG31: =SUM(R31:U31) -> 190 | AI31: =SUM(AG31/AC31)-1 -> -2.1374113
B32: Net loss | C32: =SUM(C28+C31) -> -37909 | D32: =SUM(D28+D31) -> -47978 | E32: =SUM(E28+E31) -> -47505 | F32: =SUM(F28+F31) -> -43002 | H32: =SUM(H28+H31) -> -10882.367 | I32: =SUM(I28+I31) -> -10437.811 | J32: =SUM(J28+J31) -> -12367.341 | K32: =SUM(K28+K31) -> -14290.481 | L32: =SUM(L28+L31) -> -12971.718 | M32: =SUM(M28+M31) -> -13107.279 | N32: =SUM(N28+N31) -> -11279.976 | O32: =SUM(O28+O31) -> -10146.027 | ... U32: =SUM(U28+U31) -> 0 | W32: =SUM(W28+W31) -> -55522.919 | X32: =SUM(X28+X31) -> -58599.854 | Y32: =SUM(Y28+Y31) -> -58992.927 | Z32: =SUM(Z28+Z31) -> -55778 | AA32: =SUM(AA28+AA31) -> -52027.074 | AB32: =SUM(AB28+AB31) -> -50443.237 | AC32: =SUM(AC28+AC31) -> -40594.003 | AD32: =SUM(AD28+AD31) -> -41528.027 | ... AG32: =SUM(AG28+AG31) -> -23834 | AI32: =SUM(AG32/AC32)-1 -> -0.41286894
B33: Net Margin (%) | C33: =C32/C11 -> #DIV/0! | D33: =D32/D11 -> #DIV/0! | E33: =E32/E11 -> #DIV/0! | F33: =F32/F11 -> #DIV/0! | H33: =H32/H11 -> #DIV/0! | I33: =I32/I11 -> #DIV/0! | J33: =J32/J11 -> #DIV/0! | K33: =K32/K11 -> #DIV/0! | L33: =L32/L11 -> #DIV/0! | M33: =M32/M11 -> #DIV/0! | N33: =N32/N11 -> #DIV/0! | O33: =O32/O11 -> #DIV/0! | ... U33: =U32/U11 -> #DIV/0! | W33: =W32/W11 -> #DIV/0! | X33: =X32/X11 -> #DIV/0! | Y33: =Y32/Y11 -> #DIV/0! | Z33: =Z32/Z11 -> #DIV/0! | AA33: =AA32/AA11 -> #DIV/0! | AB33: =AB32/AB11 -> #DIV/0! | AC33: =AC32/AC11 -> #DIV/0! | AD33: =AD32/AD11 -> #DIV/0! | ... AG33: =AG32/AG11 -> #DIV/0! | AI33: =SUM(AG33-AC33)*1000 -> #DIV/0!
B35: Basic shares | K35: =D35 -> 0 | O35: =E35 -> 0 | S35: =F35 -> 0 | W35: =K35 -> 0 | X35: =L35 -> 0 | Y35: =M35 -> 0 | Z35: =N35 -> 0 | AA35: =O35 -> 0 | AB35: =P35 -> 0 | AC35: =Q35 -> 0 | AD35: =R35 -> 0 | ... AG35: =U35 -> 0 | AI35: =SUM(AG35/AC35)-1 -> #DIV/0!
B36: Basic EPS | C36: =C32/C35 -> #DIV/0! | D36: =D32/D35 -> #DIV/0! | E36: =E32/E35 -> #DIV/0! | F36: =F32/F35 -> #DIV/0! | H36: =H32/H35 -> #DIV/0! | I36: =I32/I35 -> #DIV/0! | J36: =J32/J35 -> #DIV/0! | K36: =K32/K35 -> #DIV/0! | L36: =L32/L35 -> #DIV/0! | M36: =M32/M35 -> #DIV/0! | N36: =N32/N35 -> #DIV/0! | O36: =O32/O35 -> #DIV/0! | ... U36: =U32/U35 -> #DIV/0! | W36: =W32/W35 -> #DIV/0! | X36: =X32/X35 -> #DIV/0! | Y36: =Y32/Y35 -> #DIV/0! | Z36: =Z32/Z35 -> #DIV/0! | AA36: =AA32/AA35 -> #DIV/0! | AB36: =AB32/AB35 -> #DIV/0! | AC36: =AC32/AC35 -> #DIV/0! | AD36: =AD32/AD35 -> #DIV/0! | ... AG36: =AG32/AG35 -> #DIV/0! | AI36: =SUM(AG36/AC36)-1 -> #DIV/0!
B38: Fully Diluted Shares | E38: 79787.596 | F38: 83468.049 | H38: 75997.738 | I38: 76248.603 | J38: 77442.236 | K38: =D38 -> 0 | M38: 78304.363 | N38: 80875.235 | O38: =E38 -> 79787.596 | Q38: 82464.226 | R38: 84535.328 | S38: =F38 -> 83468.049 | W38: =L38 -> 0 | X38: =M38 -> 78304.363 | Y38: =N38 -> 80875.235 | Z38: =O38 -> 79787.596 | AA38: =P38 -> 0 | AB38: =Q38 -> 82464.226 | AC38: =Q38 -> 82464.226 | AD38: =R38 -> 84535.328 | AE38: =S38 -> 83468.049 | AF38: =T38 -> 0 | AG38: =U38 -> 0 | AI38: =SUM(AG38/AC38)-1 -> -1
B39: Diluted EPS | C39: =C32/C38 -> #DIV/0! | D39: =D32/D38 -> #DIV/0! | E39: =E32/E38 -> -0.5953933 | F39: =F32/F38 -> -0.51519115 | H39: =H32/H38 -> -0.1431933 | I39: =I32/I38 -> -0.13689183 | J39: =J32/J38 -> -0.15969762 | K39: =K32/K38 -> #DIV/0! | L39: =L32/L38 -> #DIV/0! | M39: =M32/M38 -> -0.16738887 | N39: =N32/N38 -> -0.1394738 | O39: =O32/O38 -> -0.12716296 | ... U39: =U32/U38 -> #DIV/0! | W39: =W32/W38 -> #DIV/0! | X39: =X32/X38 -> -0.74836001 | Y39: =Y32/Y38 -> -0.72943129 | Z39: =Z32/Z38 -> -0.6990811 | AA39: =AA32/AA38 -> #DIV/0! | AB39: =AB32/AB38 -> -0.61169842 | AC39: =AC32/AC38 -> -0.49226198 | AD39: =AD32/AD38 -> -0.49125056 | ... AG39: =AG32/AG38 -> #DIV/0! | AI39: =SUM(AG39/AC39)-1 -> #DIV/0!
A41: X | B41: Balance Sheet | C41: FYE | D41: FYE | H41: Quarterly | R41: Quarterly | AC41: LTM | AI41: Variance
B42: =B7 -> Fiscal Period | C42: =C7 -> 2021 | D42: =D7 -> 2022 | E42: =E7 -> 2023 | F42: =F7 -> 2024 | H42: =H7 -> 1Q22 | I42: =I7 -> 2Q22 | J42: =J7 -> 3Q22 | K42: =K7 -> 4Q22 | L42: =L7 -> 1Q23 | M42: =M7 -> 2Q23 | N42: =N7 -> 3Q23 | O42: =O7 -> 4Q23 | ... U42: =U7 -> 2Q25 | W42: =W7 -> 4Q22 | X42: =X7 -> 1Q23 | Y42: =Y7 -> 2Q23 | Z42: =Z7 -> 3Q23 | AA42: =AA7 -> 4Q23 | AB42: =AB7 -> 1Q24 | AC42: =AC7 -> 2Q24 | AD42: =AD7 -> 3Q24 | ... AG42: =AG7 -> 2Q25
B43: =B8 -> Fiscal Period End Date | C43: =C8 -> 44561 | D43: =D8 -> 44926 | E43: =E8 -> 45291 | F43: =F8 -> 45657 | H43: =H8 -> 44651 | I43: =I8 -> 44742 | J43: =J8 -> 44834 | K43: =K8 -> 44926 | L43: =L8 -> 45016 | M43: =M8 -> 45107 | N43: =N8 -> 45199 | O43: =O8 -> 45291 | ... U43: =U8 -> 45838 | W43: =W8 -> 44926 | X43: =X8 -> 45016 | Y43: =Y8 -> 45107 | Z43: =Z8 -> 45199 | AA43: =AA8 -> 45291 | AB43: =AB8 -> 45382 | AC43: =AC8 -> 45473 | AD43: =AD8 -> 45565 | ... AG43: =AG8 -> 45838
B45: Total Assets
B46: Cash and cash equivalents | C46: 152107.74 | D46: 149158 | E46: 151024 | F46: 132187 | H46: 151146.36 | I46: 153342.56 | J46: 153199.35 | K46: =D46 -> 149158 | L46: 143621.85 | M46: 153466.96 | N46: 154817.16 | O46: =E46 -> 151024 | P46: 143765 | Q46: 139386 | R46: 138756 | S46: =F46 -> 132187 | W46: =K46 -> 149158 | X46: =L46 -> 143621.85 | Y46: =M46 -> 153466.96 | Z46: =N46 -> 154817.16 | AA46: =O46 -> 151024 | AB46: =P46 -> 143765 | AC46: =Q46 -> 139386 | AD46: =R46 -> 138756 | ... AG46: =U46 -> 0 | AI46: =SUM(AG46/AC46)-1 -> -1
B47: Incentive and tax receivables | C47: 9136.831 | D47: 3193 | E47: 2709 | F47: 2449 | H47: 5372.153 | I47: 6468.987 | J47: 6559.829 | K47: =D47 -> 3193 | L47: 4094.431 | M47: 4737.661 | N47: 2165.127 | O47: =E47 -> 2709 | P47: 3549 | Q47: 3785 | R47: 1720 | S47: =F47 -> 2449 | W47: =K47 -> 3193 | X47: =L47 -> 4094.431 | Y47: =M47 -> 4737.661 | Z47: =N47 -> 2165.127 | AA47: =O47 -> 2709 | AB47: =P47 -> 3549 | AC47: =Q47 -> 3785 | AD47: =R47 -> 1720 | ... AG47: =U47 -> 0 | AI47: =SUM(AG47/AC47)-1 -> -1
B48: Prepaid expenses and other current assets | C48: 371.914 | D48: 354 | E48: 653 | F48: 931 | H48: 377.86 | I48: 464.605 | J48: 461.963 | K48: =D48 -> 354 | L48: 655.643 | M48: 981.774 | N48: 827.572 | O48: =E48 -> 653 | P48: 756 | Q48: 1345 | R48: 1059 | S48: =F48 -> 931 | W48: =K48 -> 354 | X48: =L48 -> 655.643 | Y48: =M48 -> 981.774 | Z48: =N48 -> 827.572 | AA48: =O48 -> 653 | AB48: =P48 -> 756 | AC48: =Q48 -> 1345 | AD48: =R48 -> 1059 | ... AG48: =U48 -> 0 | AI48: =SUM(AG48/AC48)-1 -> -1
B49: Total Assets | C49: =SUM(C46:C48) -> 161616.49 | D49: =SUM(D46:D48) -> 152705 | E49: =SUM(E46:E48) -> 154386 | F49: =SUM(F46:F48) -> 135567 | H49: =SUM(H46:H48) -> 156896.37 | I49: =SUM(I46:I48) -> 160276.15 | J49: =SUM(J46:J48) -> 160221.14 | K49: =SUM(K46:K48) -> 152705 | L49: =SUM(L46:L48) -> 148371.92 | M49: =SUM(M46:M48) -> 159186.4 | N49: =SUM(N46:N48) -> 157809.86 | O49: =SUM(O46:O48) -> 154386 | ... U49: =SUM(U46:U48) -> 0 | W49: =SUM(W46:W48) -> 152705 | X49: =SUM(X46:X48) -> 148371.92 | Y49: =SUM(Y46:Y48) -> 159186.4 | Z49: =SUM(Z46:Z48) -> 157809.86 | AA49: =SUM(AA46:AA48) -> 154386 | AB49: =SUM(AB46:AB48) -> 148070 | AC49: =SUM(AC46:AC48) -> 144516 | AD49: =SUM(AD46:AD48) -> 141535 | ... AG49: =SUM(AG46:AG48) -> 0 | AI49: =SUM(AG49/AC49)-1 -> -1
B51: Total Liabilities
B52: Accounts payable | C52: 4739.781 | D52: 3825 | E52: 4322 | F52: 9627 | H52: 4634.791 | I52: 2631.888 | J52: 3126.892 | K52: =D52 -> 3825 | L52: 5288.261 | M52: 6281.742 | N52: 4152.846 | O52: =E52 -> 4322 | P52: 4292 | Q52: 3726 | R52: 3503 | S52: =F52 -> 9627 | W52: =K52 -> 3825 | X52: =L52 -> 5288.261 | Y52: =M52 -> 6281.742 | Z52: =N52 -> 4152.846 | AA52: =O52 -> 4322 | AB52: =P52 -> 4292 | AC52: =Q52 -> 3726 | AD52: =R52 -> 3503 | ... AG52: =U52 -> 0 | AI52: =SUM(AG52/AC52)-1 -> -1
...

Sheet Revenue Drivers
B2: Anavex Life Sciences Corp. (AVXL) | H2: Quarterly | P2: Quarterly | Q2: Quarterly | W2: LTM | AA2: LTM | AC2: LTM
B3: Segment Anaysis | C3: ='Historical Financials'!#REF! -> #REF! | D3: ='Historical Financials'!D7 -> 2022 | E3: ='Historical Financials'!E7 -> 2023 | F3: ='Historical Financials'!F7 -> 2024 | H3: ='Historical Financials'!H7 -> 1Q22 | I3: ='Historical Financials'!I7 -> 2Q22 | J3: ='Historical Financials'!J7 -> 3Q22 | K3: ='Historical Financials'!K7 -> 4Q22 | L3: ='Historical Financials'!L7 -> 1Q23 | M3: ='Historical Financials'!M7 -> 2Q23 | N3: ='Historical Financials'!N7 -> 3Q23 | O3: ='Historical Financials'!O7 -> 4Q23 | ... U3: ='Historical Financials'!U7 -> 2Q25 | W3: =L3 -> 1Q23 | X3: =M3 -> 2Q23 | Y3: =N3 -> 3Q23 | Z3: =O3 -> 4Q23 | AA3: =P3 -> 1Q24 | AB3: =Q3 -> 2Q24 | AC3: =S3 -> 4Q24 | AD3: =T3 -> 1Q25 | AE3: =U3 -> 2Q25 | AF3: =#REF! -> #REF!
B4: $ in thousands except per share | C4: ='Historical Financials'!#REF! -> #REF! | D4: ='Historical Financials'!D8 -> 44926 | E4: ='Historical Financials'!E8 -> 45291 | F4: ='Historical Financials'!F8 -> 45657 | H4: ='Historical Financials'!H8 -> 44651 | I4: ='Historical Financials'!I8 -> 44742 | J4: ='Historical Financials'!J8 -> 44834 | K4: ='Historical Financials'!K8 -> 44926 | L4: ='Historical Financials'!L8 -> 45016 | M4: ='Historical Financials'!M8 -> 45107 | N4: ='Historical Financials'!N8 -> 45199 | O4: ='Historical Financials'!O8 -> 45291 | ... U4: ='Historical Financials'!U8 -> 45838 | W4: =L4 -> 45016 | X4: =M4 -> 45107 | Y4: =N4 -> 45199 | Z4: =O4 -> 45291 | AA4: =P4 -> 45382 | AB4: =Q4 -> 45473 | AC4: =S4 -> 45657 | AD4: =T4 -> 45747 | AE4: =U4 -> 45838 | AF4: =#REF! -> #REF!
A6: X | B6: Net Revenues by Channel
W7: =SUM(I7:L7) -> 0 | X7: =SUM(J7:M7) -> 0 | Y7: =SUM(K7:N7) -> 0 | Z7: =SUM(L7:O7) -> 0 | AA7: =SUM(M7:P7) -> 0 | AB7: =SUM(N7:Q7) -> 0 | AC7: =SUM(P7:S7) -> 0 | AD7: =SUM(Q7:T7) -> 0 | AE7: =SUM(R7:U7) -> 0 | AF7: =SUM(S7:U7) -> 0
W8: =SUM(I8:L8) -> 0 | X8: =SUM(J8:M8) -> 0 | Y8: =SUM(K8:N8) -> 0 | Z8: =SUM(L8:O8) -> 0 | AA8: =SUM(M8:P8) -> 0 | AB8: =SUM(N8:Q8) -> 0 | AC8: =SUM(P8:S8) -> 0 | AD8: =SUM(Q8:T8) -> 0 | AE8: =SUM(R8:U8) -> 0 | AF8: =SUM(S8:U8) -> 0
B9: Total Net Revenue | D9: =SUM(D7:D8) -> 0 | E9: =SUM(E7:E8) -> 0 | F9: =SUM(F7:F8) -> 0 | P9: =SUM(P7:P8) -> 0 | Q9: =SUM(Q7:Q8) -> 0 | R9: =SUM(R7:R8) -> 0 | S9: =SUM(S7:S8) -> 0 | T9: =SUM(T7:T8) -> 0 | U9: =SUM(U7:U8) -> 0 | W9: =SUM(W7:W8) -> 0 | X9: =SUM(X7:X8) -> 0 | Y9: =SUM(Y7:Y8) -> 0 | Z9: =SUM(Z7:Z8) -> 0 | AA9: =SUM(AA7:AA8) -> 0 | AB9: =SUM(AB7:AB8) -> 0 | AC9: =SUM(AC7:AC8) -> 0 | AD9: =SUM(AD7:AD8) -> 0 | ... AF9: =SUM(AF7:AF8) -> 0
B10: Balance Check | D10: =+D9-'Historical Financials'!D11 -> 0 | E10: =+E9-'Historical Financials'!E11 -> 0 | F10: =+F9-'Historical Financials'!F11 -> 0 | P10: =+P9-'Historical Financials'!P11 -> 0 | Q10: =+Q9-'Historical Financials'!Q11 -> 0 | R10: =+R9-'Historical Financials'!R11 -> 0 | S10: =+S9-'Historical Financials'!S11 -> 0 | T10: =+T9-'Historical Financials'!T11 -> 0 | U10: =+U9-'Historical Financials'!U11 -> 0 | W10: =W9-'Historical Financials'!W11 -> 0 | X10: =X9-'Historical Financials'!X11 -> 0 | Y10: =Y9-'Historical Financials'!Y11 -> 0 | Z10: =Z9-'Historical Financials'!Z11 -> 0 | AA10: =AA9-'Historical Financials'!AA11 -> 0 | AB10: =AB9-'Historical Financials'!AB11 -> 0 | AC10: =AC9-'Historical Financials'!AD11 -> 0 | AD10: =AD9-'Historical Financials'!AE11 -> 0 | AE10: =AE9-'Historical Financials'!AF11 -> 0 | AF10: =AF9-'Historical Financials'!AG11 -> 0
A12: X | B12: Revenue by Channel
W13: =SUM(I13:L13) -> 0 | X13: =SUM(J13:M13) -> 0 | Y13: =SUM(K13:N13) -> 0 | Z13: =SUM(L13:O13) -> 0 | AA13: =SUM(M13:P13) -> 0 | AB13: =SUM(N13:Q13) -> 0 | AC13: =SUM(P13:S13) -> 0 | AD13: =SUM(Q13:T13) -> 0 | AE13: =SUM(R13:U13) -> 0 | AF13: =SUM(S13:U13) -> 0
W14: =SUM(I14:L14) -> 0 | X14: =SUM(J14:M14) -> 0 | Y14: =SUM(K14:N14) -> 0 | Z14: =SUM(L14:O14) -> 0 | AA14: =SUM(M14:P14) -> 0 | AB14: =SUM(N14:Q14) -> 0 | AC14: =SUM(P14:S14) -> 0 | AD14: =SUM(Q14:T14) -> 0 | AE14: =SUM(R14:U14) -> 0 | AF14: =SUM(S14:U14) -> 0
B15: Total Net U.S Revenue | D15: =SUM(D13:D14) -> 0 | E15: =SUM(E13:E14) -> 0 | F15: =SUM(F13:F14) -> 0 | P15: =SUM(P13:P14) -> 0 | Q15: =SUM(Q13:Q14) -> 0 | R15: =SUM(R13:R14) -> 0 | S15: =SUM(S13:S14) -> 0 | T15: =SUM(T13:T14) -> 0 | U15: =SUM(U13:U14) -> 0 | W15: =SUM(W13:W14) -> 0 | X15: =SUM(X13:X14) -> 0 | Y15: =SUM(Y13:Y14) -> 0 | Z15: =SUM(Z13:Z14) -> 0 | AA15: =SUM(AA13:AA14) -> 0 | AB15: =SUM(AB13:AB14) -> 0 | AC15: =SUM(AC13:AC14) -> 0 | AD15: =SUM(AD13:AD14) -> 0 | ... AF15: =SUM(AF13:AF14) -> 0
B16: Balance Check | D16: =+D15-D9 -> 0 | E16: =+E15-E9 -> 0 | F16: =+F15-F9 -> 0 | P16: =+P15-P9 -> 0 | Q16: =+Q15-Q9 -> 0 | R16: =+R15-R9 -> 0 | S16: =+S15-S9 -> 0 | T16: =+T15-T9 -> 0 | U16: =+U15-U9 -> 0 | W16: =W15-'Historical Financials'!W17 -> 13320.085 | X16: =X15-'Historical Financials'!X17 -> 13287.495 | Y16: =Y15-'Historical Financials'!Y17 -> 13349.887 | Z16: =Z15-'Historical Financials'!Z17 -> 12039 | AA16: =AA15-'Historical Financials'!AA17 -> 11330.964 | AB16: =AB15-'Historical Financials'!AB17 -> 11238.396 | AC16: =+AC15-AC9 -> 0 | AD16: =+AD15-AD9 -> 0 | AE16: =+AE15-AE9 -> 0 | AF16: =+AF15-AF9 -> 0

Sheet FCF
B2: Anavex Life Sciences Corp. (AVXL) | D2: FYE | H2: Quarterly | Q2: Quarterly | R2: Quarterly | X2: LTM | AE2: LTM | AK2: Variance
B3: FCF Analysis | C3: ='Historical Financials'!#REF! -> #REF! | D3: ='Historical Financials'!D7 -> 2022 | E3: ='Historical Financials'!E7 -> 2023 | F3: ='Historical Financials'!F7 -> 2024 | H3: ='Historical Financials'!H7 -> 1Q22 | I3: ='Historical Financials'!I7 -> 2Q22 | J3: ='Historical Financials'!J7 -> 3Q22 | K3: ='Historical Financials'!K7 -> 4Q22 | L3: ='Historical Financials'!L7 -> 1Q23 | M3: ='Historical Financials'!M7 -> 2Q23 | N3: ='Historical Financials'!N7 -> 3Q23 | O3: ='Historical Financials'!O7 -> 4Q23 | ... U3: ='Historical Financials'!U7 -> 2Q25 | V3: ='Historical Financials'!#REF! -> #REF! | X3: =K3 -> 4Q22 | Y3: =L3 -> 1Q23 | Z3: =M3 -> 2Q23 | AA3: =N3 -> 3Q23 | AB3: =O3 -> 4Q23 | AC3: =P3 -> 1Q24 | AD3: =Q3 -> 2Q24 | AE3: =R3 -> 3Q24 | ... AI3: =V3 -> #REF!
B4: $ in thousands except per share | C4: ='Historical Financials'!#REF! -> #REF! | D4: ='Historical Financials'!D8 -> 44926 | E4: ='Historical Financials'!E8 -> 45291 | F4: ='Historical Financials'!F8 -> 45657 | H4: ='Historical Financials'!H8 -> 44651 | I4: ='Historical Financials'!I8 -> 44742 | J4: ='Historical Financials'!J8 -> 44834 | K4: ='Historical Financials'!K8 -> 44926 | L4: ='Historical Financials'!L8 -> 45016 | M4: ='Historical Financials'!M8 -> 45107 | N4: ='Historical Financials'!N8 -> 45199 | O4: ='Historical Financials'!O8 -> 45291 | ... U4: ='Historical Financials'!U8 -> 45838 | V4: ='Historical Financials'!#REF! -> #REF! | X4: =K4 -> 44926 | Y4: =L4 -> 45016 | Z4: =M4 -> 45107 | AA4: =N4 -> 45199 | AB4: =O4 -> 45291 | AC4: =P4 -> 45382 | AD4: =Q4 -> 45473 | AE4: =R4 -> 45565 | ... AI4: =V4 -> #REF!
P6: ='Revenue Drivers'!P7 -> 0 | Q6: ='Revenue Drivers'!Q7 -> 0 | AC6: =SUM(M6:P6) -> 0 | AD6: =SUM(N6:Q6) -> 0 | AE6: =SUM(O6:R6) -> 0 | AF6: =SUM(P6:S6) -> 0 | AG6: =SUM(Q6:T6) -> 0 | AH6: =SUM(R6:U6) -> 0 | AI6: =SUM(S6:V6) -> 0 | AK6: =SUM(AI6/AE6)-1 -> #DIV/0!
P7: ='Revenue Drivers'!P8 -> 0 | Q7: ='Revenue Drivers'!Q8 -> 0 | AC7: =SUM(M7:P7) -> 0 | AD7: =SUM(N7:Q7) -> 0 | AE7: =SUM(O7:R7) -> 0 | AF7: =SUM(P7:S7) -> 0 | AG7: =SUM(Q7:T7) -> 0 | AH7: =SUM(R7:U7) -> 0 | AI7: =SUM(S7:V7) -> 0 | AK7: =SUM(AI7/AE7)-1 -> #DIV/0!
B8: Total Revenue | C8: ='Historical Financials'!#REF! -> #REF! | D8: =SUM(D6:D7) -> 0 | E8: =SUM(E6:E7) -> 0 | F8: =SUM(F6:F7) -> 0 | H8: ='Historical Financials'!H11 -> 0 | I8: ='Historical Financials'!I11 -> 0 | J8: ='Historical Financials'!J11 -> 0 | K8: ='Historical Financials'!K11 -> 0 | L8: ='Historical Financials'!L11 -> 0 | M8: ='Historical Financials'!M11 -> 0 | N8: ='Historical Financials'!N11 -> 0 | O8: ='Historical Financials'!O11 -> 0 | P8: =SUM(P6:P7) -> 0 | Q8: =SUM(Q6:Q7) -> 0 | R8: =SUM(R6:R7) -> 0 | S8: =SUM(S6:S7) -> 0 | T8: =SUM(T6:T7) -> 0 | U8: =SUM(U6:U7) -> 0 | V8: =SUM(V6:V7) -> 0 | X8: =SUM(H8:K8) -> 0 | Y8: =SUM(I8:L8) -> 0 | Z8: =SUM(J8:M8) -> 0 | AA8: =SUM(K8:N8) -> 0 | AB8: =SUM(L8:O8) -> 0 | AC8: =SUM(AC6:AC7) -> 0 | AD8: =SUM(AD6:AD7) -> 0 | AE8: =SUM(AE6:AE7) -> 0 | AF8: =SUM(AF6:AF7) -> 0 | AG8: =SUM(AG6:AG7) -> 0 | AH8: =SUM(AH6:AH7) -> 0 | AI8: =SUM(AI6:AI7) -> 0 | AK8: =SUM(AI8/AE8)-1 -> #DIV/0!
B9: Y/Y Growth (%) | D9: =SUM(D8/C8)-1 -> #REF! | E9: =SUM(E8/D8)-1 -> #DIV/0! | F9: =SUM(F8/E8)-1 -> #DIV/0! | M9: =SUM(M8/I8)-1 -> #DIV/0! | N9: =SUM(N8/J8)-1 -> #DIV/0! | O9: =SUM(O8/K8)-1 -> #DIV/0! | P9: =SUM(P8/L8)-1 -> #DIV/0! | Q9: =SUM(Q8/M8)-1 -> #DIV/0! | R9: =SUM(R8/N8)-1 -> #DIV/0! | S9: =SUM(S8/O8)-1 -> #DIV/0! | T9: =SUM(T8/P8)-1 -> #DIV/0! | ... V9: =SUM(V8/R8)-1 -> #DIV/0! | AB9: =SUM(AB8/X8)-1 -> #DIV/0! | AC9: =SUM(AC8/Y8)-1 -> #DIV/0! | AD9: =SUM(AD8/Z8)-1 -> #DIV/0! | AE9: =SUM(AE8/AA8)-1 -> #DIV/0! | AF9: =SUM(AF8/AB8)-1 -> #DIV/0! | AG9: =SUM(AG8/AC8)-1 -> #DIV/0! | AH9: =SUM(AH8/AD8)-1 -> #DIV/0! | AI9: =SUM(AI8/AE8)-1 -> #DIV/0! | AK9: =SUM(AI9-AE9)*10000 -> #DIV/0!
B10: Q/Q Growth (%) | C10: N/A | D10: N/A | E10: N/A | F10: N/A | J10: =SUM(J8/I8)-1 -> #DIV/0! | K10: =SUM(K8/J8)-1 -> #DIV/0! | L10: =SUM(L8/K8)-1 -> #DIV/0! | M10: =SUM(M8/L8)-1 -> #DIV/0! | N10: =SUM(N8/M8)-1 -> #DIV/0! | O10: =SUM(O8/N8)-1 -> #DIV/0! | P10: =SUM(P8/O8)-1 -> #DIV/0! | Q10: =SUM(Q8/P8)-1 -> #DIV/0! | ... V10: =SUM(V8/U8)-1 -> #DIV/0! | X10: N/A | Y10: N/A | Z10: N/A | AA10: N/A | AB10: N/A | AC10: N/A | AD10: N/A | AE10: N/A | AF10: N/A | AG10: N/A | AH10: N/A | AI10: N/A
B12: (-) Cost of Sales | C12: ='Historical Financials'!#REF! -> #REF! | H12: ='Historical Financials'!H13 -> 0 | I12: ='Historical Financials'!I13 -> 0 | J12: ='Historical Financials'!J13 -> 0 | K12: ='Historical Financials'!K13 -> 0 | L12: ='Historical Financials'!L13 -> 0 | M12: ='Historical Financials'!M13 -> 0 | N12: ='Historical Financials'!N13 -> 0 | O12: ='Historical Financials'!O13 -> 0 | ... Q12: ='Historical Financials'!Q13 -> 0 | X12: =SUM(G12:K12) -> 0 | Y12: =SUM(I12:L12) -> 0 | Z12: =SUM(J12:M12) -> 0 | AA12: =SUM(K12:N12) -> 0 | AB12: =SUM(L12:O12) -> 0 | AC12: =SUM(M12:P12) -> 0 | AD12: =SUM(N12:Q12) -> 0 | AE12: =SUM(O12:R12) -> 0 | AF12: =SUM(P12:S12) -> 0 | ... AI12: =SUM(S12:V12) -> 0 | AK12: =SUM(AI12/AE12)-1 -> #DIV/0!
B13: Gross Profit | C13: =+C8+C12 -> #REF! | D13: =+D8+D12 -> 0 | E13: =+E8+E12 -> 0 | F13: =+F8+F12 -> 0 | H13: =+H8+H12 -> 0 | I13: =+I8+I12 -> 0 | J13: =+J8+J12 -> 0 | K13: =+K8+K12 -> 0 | L13: =+L8+L12 -> 0 | M13: =+M8+M12 -> 0 | N13: =+N8+N12 -> 0 | O13: =+O8+O12 -> 0 | ... V13: =+V8+V12 -> 0 | X13: =+X8+X12 -> 0 | Y13: =+Y8+Y12 -> 0 | Z13: =+Z8+Z12 -> 0 | AA13: =+AA8+AA12 -> 0 | AB13: =+AB8+AB12 -> 0 | AC13: =+AC8+AC12 -> 0 | AD13: =+AD8+AD12 -> 0 | AE13: =+AE8+AE12 -> 0 | ... AI13: =+AI8+AI12 -> 0 | AK13: =SUM(AI13/AE13)-1 -> #DIV/0!
B14: Gross Margin (%) | C14: =C13/C8 -> #REF! | D14: =D13/D8 -> #DIV/0! | E14: =E13/E8 -> #DIV/0! | F14: =F13/F8 -> #DIV/0! | H14: =H13/H8 -> #DIV/0! | I14: =I13/I8 -> #DIV/0! | J14: =J13/J8 -> #DIV/0! | K14: =K13/K8 -> #DIV/0! | L14: =L13/L8 -> #DIV/0! | M14: =M13/M8 -> #DIV/0! | N14: =N13/N8 -> #DIV/0! | O14: =O13/O8 -> #DIV/0! | ... V14: =V13/V8 -> #DIV/0! | X14: =X13/X8 -> #DIV/0! | Y14: =Y13/Y8 -> #DIV/0! | Z14: =Z13/Z8 -> #DIV/0! | AA14: =AA13/AA8 -> #DIV/0! | AB14: =AB13/AB8 -> #DIV/0! | AC14: =AC13/AC8 -> #DIV/0! | AD14: =AD13/AD8 -> #DIV/0! | AE14: =AE13/AE8 -> #DIV/0! | ... AI14: =AI13/AI8 -> #DIV/0! | AK14: =SUM(AI14-AE14)*10000 -> #DIV/0!
B16: (-) Research and development | C16: ='Historical Financials'!#REF! -> #REF! | H16: ='Historical Financials'!H17 -> -3066.951 | I16: ='Historical Financials'!I17 -> -2915.158 | J16: ='Historical Financials'!J17 -> -3185.451 | K16: ='Historical Financials'!K17 -> -3902.44 | L16: ='Historical Financials'!L17 -> -3317.036 | M16: ='Historical Financials'!M17 -> -2882.568 | N16: ='Historical Financials'!N17 -> -3247.843 | O16: ='Historical Financials'!O17 -> -2591.553 | ... Q16: ='Historical Financials'!Q17 -> -2790 | X16: =SUM(G16:K16) -> -13070 | Y16: =SUM(I16:L16) -> -13320.085 | Z16: =SUM(J16:M16) -> -13287.495 | AA16: =SUM(K16:N16) -> -13349.887 | AB16: =SUM(L16:O16) -> -12039 | AC16: =SUM(M16:P16) -> -11330.964 | AD16: =SUM(N16:Q16) -> -11238.396 | AE16: =SUM(O16:R16) -> -7990.553 | AF16: =SUM(P16:S16) -> -5399 | ... AI16: =SUM(S16:V16) -> 0 | AK16: =SUM(AI16/AE16)-1 -> -1
B17: (-) Sales and marketing | C17: ='Historical Financials'!#REF! -> #REF! | H17: ='Historical Financials'!H18 -> -8656.439 | I17: ='Historical Financials'!I18 -> -8604.589 | J17: ='Historical Financials'!J18 -> -9273.269 | K17: ='Historical Financials'!K18 -> -11381.703 | L17: ='Historical Financials'!L18 -> -12066.919 | M17: ='Historical Financials'!M18 -> -11306.591 | N17: ='Historical Financials'!N18 -> -10282.854 | O17: ='Historical Financials'!O18 -> -10060.636 | ... Q17: ='Historical Financials'!Q18 -> -9729 | X17: =SUM(G17:K17) -> -37916 | Y17: =SUM(I17:L17) -> -41326.48 | Z17: =SUM(J17:M17) -> -44028.482 | AA17: =SUM(K17:N17) -> -45038.067 | AB17: =SUM(L17:O17) -> -43717 | AC17: =SUM(M17:P17) -> -40334.081 | AD17: =SUM(N17:Q17) -> -38756.49 | AE17: =SUM(O17:R17) -> -28473.636 | AF17: =SUM(P17:S17) -> -18413 | ... AI17: =SUM(S17:V17) -> 0 | AK17: =SUM(AI17/AE17)-1 -> -1
B18: (-) General and administrative | C18: ='Historical Financials'!#REF! -> #REF! | H18: ='Historical Financials'!#REF! -> #REF! | I18: ='Historical Financials'!#REF! -> #REF! | J18: ='Historical Financials'!#REF! -> #REF! | K18: ='Historical Financials'!#REF! -> #REF! | L18: ='Historical Financials'!#REF! -> #REF! | M18: ='Historical Financials'!#REF! -> #REF! | N18: ='Historical Financials'!#REF! -> #REF! | O18: ='Historical Financials'!#REF! -> #REF! | ... Q18: ='Historical Financials'!#REF! -> #REF! | X18: =SUM(G18:K18) -> #REF! | Y18: =SUM(I18:L18) -> #REF! | Z18: =SUM(J18:M18) -> #REF! | AA18: =SUM(K18:N18) -> #REF! | AB18: =SUM(L18:O18) -> #REF! | AC18: =SUM(M18:P18) -> #REF! | AD18: =SUM(N18:Q18) -> #REF! | AE18: =SUM(O18:R18) -> #REF! | AF18: =SUM(P18:S18) -> #REF! | ... AI18: =SUM(S18:V18) -> 0 | AK18: =SUM(AI18/AE18)-1 -> #REF!
B19: (-) Depreciation and amortization | C19: ='Historical Financials'!#REF! -> #REF! | H19: ='Historical Financials'!#REF! -> #REF! | I19: ='Historical Financials'!#REF! -> #REF! | J19: ='Historical Financials'!#REF! -> #REF! | K19: ='Historical Financials'!#REF! -> #REF! | L19: ='Historical Financials'!#REF! -> #REF! | M19: ='Historical Financials'!#REF! -> #REF! | N19: ='Historical Financials'!#REF! -> #REF! | O19: ='Historical Financials'!#REF! -> #REF! | ... Q19: ='Historical Financials'!#REF! -> #REF! | X19: =SUM(G19:K19) -> #REF! | Y19: =SUM(I19:L19) -> #REF! | Z19: =SUM(J19:M19) -> #REF! | AA19: =SUM(K19:N19) -> #REF! | AB19: =SUM(L19:O19) -> #REF! | AC19: =SUM(M19:P19) -> #REF! | AD19: =SUM(N19:Q19) -> #REF! | AE19: =SUM(O19:R19) -> #REF! | AF19: =SUM(P19:S19) -> #REF! | ... AI19: =SUM(S19:V19) -> 0 | AK19: =SUM(AI19/AE19)-1 -> #REF!
B20: Earning before Interest & Taxes (EBIT) | C20: =SUM(C13+SUM(C16:C19)) -> #REF! | D20: =SUM(D13+SUM(D16:D19)) -> 0 | E20: =SUM(E13+SUM(E16:E19)) -> 0 | F20: =SUM(F13+SUM(F16:F19)) -> 0 | H20: =SUM(H13+SUM(H16:H19)) -> #REF! | I20: =SUM(I13+SUM(I16:I19)) -> #REF! | J20: =SUM(J13+SUM(J16:J19)) -> #REF! | K20: =SUM(K13+SUM(K16:K19)) -> #REF! | L20: =SUM(L13+SUM(L16:L19)) -> #REF! | M20: =SUM(M13+SUM(M16:M19)) -> #REF! | N20: =SUM(N13+SUM(N16:N19)) -> #REF! | O20: =SUM(O13+SUM(O16:O19)) -> #REF! | ... V20: =SUM(V13+SUM(V16:V19)) -> 0 | X20: =SUM(X13+SUM(X16:X19)) -> #REF! | Y20: =SUM(Y13+SUM(Y16:Y19)) -> #REF! | Z20: =SUM(Z13+SUM(Z16:Z19)) -> #REF! | AA20: =SUM(AA13+SUM(AA16:AA19)) -> #REF! | AB20: =SUM(AB13+SUM(AB16:AB19)) -> #REF! | AC20: =SUM(AC13+SUM(AC16:AC19)) -> #REF! | AD20: =SUM(AD13+SUM(AD16:AD19)) -> #REF! | AE20: =SUM(AE13+SUM(AE16:AE19)) -> #REF! | ... AI20: =SUM(AI13+SUM(AI16:AI19)) -> 0 | AK20: =SUM(AI20/AE20)-1 -> #REF!
B21: Operating Margin (%) | C21: =C20/C8 -> #REF! | D21: =D20/D8 -> #DIV/0! | E21: =E20/E8 -> #DIV/0! | F21: =F20/F8 -> #DIV/0! | H21: =H20/H8 -> #REF! | I21: =I20/I8 -> #REF! | J21: =J20/J8 -> #REF! | K21: =K20/K8 -> #REF! | L21: =L20/L8 -> #REF! | M21: =M20/M8 -> #REF! | N21: =N20/N8 -> #REF! | O21: =O20/O8 -> #REF! | ... V21: =V20/V8 -> #DIV/0! | X21: =X20/X8 -> #REF! | Y21: =Y20/Y8 -> #REF! | Z21: =Z20/Z8 -> #REF! | AA21: =AA20/AA8 -> #REF! | AB21: =AB20/AB8 -> #REF! | AC21: =AC20/AC8 -> #REF! | AD21: =AD20/AD8 -> #REF! | AE21: =AE20/AE8 -> #REF! | ... AI21: =AI20/AI8 -> #DIV/0! | AK21: =SUM(AI21-AE21)*10000 -> #DIV/0!
B23: (+) Depreciation and Amortization | C23: =-C19 -> #REF! | H23: =-H19 -> #REF! | I23: =-I19 -> #REF! | J23: =-J19 -> #REF! | K23: =-K19 -> #REF! | L23: =-L19 -> #REF! | M23: =-M19 -> #REF! | N23: =-N19 -> #REF! | O23: =-O19 -> #REF! | ... Q23: =-Q19 -> #REF! | X23: =SUM(G23:K23) -> #REF! | Y23: =SUM(I23:L23) -> #REF! | Z23: =SUM(J23:M23) -> #REF! | AA23: =SUM(K23:N23) -> #REF! | AB23: =SUM(L23:O23) -> #REF! | AC23: =SUM(M23:P23) -> #REF! | AD23: =SUM(N23:Q23) -> #REF! | AE23: =SUM(O23:R23) -> #REF! | AF23: =SUM(P23:S23) -> #REF! | ... AI23: =SUM(S23:V23) -> 0 | AK23: =SUM(AI23/AE23)-1 -> #REF!
B24: EBITDA | C24: =SUM(C20+C23) -> #REF! | D24: =SUM(D20+D23) -> 0 | E24: =SUM(E20+E23) -> 0 | F24: =SUM(F20+F23) -> 0 | H24: =SUM(H20+H23) -> #REF! | I24: =SUM(I20+I23) -> #REF! | J24: =SUM(J20+J23) -> #REF! | K24: =SUM(K20+K23) -> #REF! | L24: =SUM(L20+L23) -> #REF! | M24: =SUM(M20+M23) -> #REF! | N24: =SUM(N20+N23) -> #REF! | O24: =SUM(O20+O23) -> #REF! | ... V24: =SUM(V20+V23) -> 0 | X24: =SUM(X20+X23) -> #REF! | Y24: =SUM(Y20+Y23) -> #REF! | Z24: =SUM(Z20+Z23) -> #REF! | AA24: =SUM(AA20+AA23) -> #REF! | AB24: =SUM(AB20+AB23) -> #REF! | AC24: =SUM(AC20+AC23) -> #REF! | AD24: =SUM(AD20+AD23) -> #REF! | AE24: =SUM(AE20+AE23) -> #REF! | ... AI24: =SUM(AI20+AI23) -> 0 | AK24: =SUM(AI24/AE24)-1 -> #REF!
B25: EBITDA Margin (%) | C25: =C24/C8 -> #REF! | D25: =D24/D8 -> #DIV/0! | E25: =E24/E8 -> #DIV/0! | F25: =F24/F8 -> #DIV/0! | H25: =H24/H8 -> #REF! | I25: =I24/I8 -> #REF! | J25: =J24/J8 -> #REF! | K25: =K24/K8 -> #REF! | L25: =L24/L8 -> #REF! | M25: =M24/M8 -> #REF! | N25: =N24/N8 -> #REF! | O25: =O24/O8 -> #REF! | ... V25: =V24/V8 -> #DIV/0! | X25: =X24/X8 -> #REF! | Y25: =Y24/Y8 -> #REF! | Z25: =Z24/Z8 -> #REF! | AA25: =AA24/AA8 -> #REF! | AB25: =AB24/AB8 -> #REF! | AC25: =AC24/AC8 -> #REF! | AD25: =AD24/AD8 -> #REF! | AE25: =AE24/AE8 -> #REF! | ... AI25: =AI24/AI8 -> #DIV/0! | AK25: =SUM(AI25-AE25)*10000 -> #DIV/0!
B27: (+) Share-based Compensation | C27: ='Historical Financials'!#REF! -> #REF! | H27: ='Historical Financials'!H78 -> 0 | I27: ='Historical Financials'!I78 -> 0 | J27: ='Historical Financials'!J78 -> 0 | K27: ='Historical Financials'!K78 -> 0 | L27: ='Historical Financials'!L78 -> 0 | M27: ='Historical Financials'!M78 -> 0 | N27: ='Historical Financials'!N78 -> 0 | O27: ='Historical Financials'!O78 -> 0 | ... Q27: ='Historical Financials'!Q78 -> 0 | X27: =SUM(G27:K27) -> 0 | Y27: =SUM(I27:L27) -> 0 | Z27: =SUM(J27:M27) -> 0 | AA27: =SUM(K27:N27) -> 0 | AB27: =SUM(L27:O27) -> 0 | AC27: =SUM(M27:P27) -> 0 | AD27: =SUM(N27:Q27) -> 0 | AE27: =SUM(O27:R27) -> 0 | AF27: =SUM(P27:S27) -> 0 | ... AI27: =SUM(S27:V27) -> 0 | AK27: =SUM(AI27/AE27)-1 -> #DIV/0!
B28: Adj. EBITDA | C28: =+SUM(C24+SUM(C27:C27)) -> #REF! | D28: =+SUM(D24+SUM(D27:D27)) -> 0 | E28: =+SUM(E24+SUM(E27:E27)) -> 0 | F28: =+SUM(F24+SUM(F27:F27)) -> 0 | H28: =+SUM(H24+SUM(H27:H27)) -> #REF! | I28: =+SUM(I24+SUM(I27:I27)) -> #REF! | J28: =+SUM(J24+SUM(J27:J27)) -> #REF! | K28: =+SUM(K24+SUM(K27:K27)) -> #REF! | L28: =+SUM(L24+SUM(L27:L27)) -> #REF! | M28: =+SUM(M24+SUM(M27:M27)) -> #REF! | N28: =+SUM(N24+SUM(N27:N27)) -> #REF! | O28: =+SUM(O24+SUM(O27:O27)) -> #REF! | ... V28: =+SUM(V24+SUM(V27:V27)) -> 0 | X28: =+SUM(X24+SUM(X27:X27)) -> #REF! | Y28: =+SUM(Y24+SUM(Y27:Y27)) -> #REF! | Z28: =+SUM(Z24+SUM(Z27:Z27)) -> #REF! | AA28: =+SUM(AA24+SUM(AA27:AA27)) -> #REF! | AB28: =+SUM(AB24+SUM(AB27:AB27)) -> #REF! | AC28: =+SUM(AC24+SUM(AC27:AC27)) -> #REF! | AD28: =+SUM(AD24+SUM(AD27:AD27)) -> #REF! | AE28: =+SUM(AE24+SUM(AE27:AE27)) -> #REF! | ... AI28: =+SUM(AI24+SUM(AI27:AI27)) -> 0 | AK28: =SUM(AI28/AE28)-1 -> #REF!
B29: Adj. EBITDA Margin (%) | C29: =C28/C8 -> #REF! | D29: =D28/D8 -> #DIV/0! | E29: =E28/E8 -> #DIV/0! | F29: =F28/F8 -> #DIV/0! | H29: =H28/H8 -> #REF! | I29: =I28/I8 -> #REF! | J29: =J28/J8 -> #REF! | K29: =K28/K8 -> #REF! | L29: =L28/L8 -> #REF! | M29: =M28/M8 -> #REF! | N29: =N28/N8 -> #REF! | O29: =O28/O8 -> #REF! | ... V29: =V28/V8 -> #DIV/0! | X29: =X28/X8 -> #REF! | Y29: =Y28/Y8 -> #REF! | Z29: =Z28/Z8 -> #REF! | AA29: =AA28/AA8 -> #REF! | AB29: =AB28/AB8 -> #REF! | AC29: =AC28/AC8 -> #REF! | AD29: =AD28/AD8 -> #REF! | AE29: =AE28/AE8 -> #REF! | ... AI29: =AI28/AI8 -> #DIV/0! | AK29: =SUM(AI29-AE29)*10000 -> #DIV/0!
B31: (-) Capital Expenditures | C31: =SUM('Historical Financials'!#REF!+'Historical Financials'!#REF!) -> #REF! | H31: =SUM('Historical Financials'!#REF!+'Historical Financials'!#REF!) -> #REF! | I31: =SUM('Historical Financials'!#REF!+'Historical Financials'!#REF!) -> #REF! | J31: =SUM('Historical Financials'!#REF!+'Historical Financials'!#REF!) -> #REF! | K31: =SUM('Historical Financials'!#REF!+'Historical Financials'!#REF!) -> #REF! | L31: =SUM('Historical Financials'!#REF!+'Historical Financials'!#REF!) -> #REF! | M31: =SUM('Historical Financials'!#REF!+'Historical Financials'!#REF!) -> #REF! | N31: =SUM('Historical Financials'!#REF!+'Historical Financials'!#REF!) -> #REF! | O31: =SUM('Historical Financials'!#REF!+'Historical Financials'!#REF!) -> #REF! | ... Q31: =SUM('Historical Financials'!#REF!+'Historical Financials'!#REF!) -> #REF! | X31: =SUM(G31:K31) -> #REF! | Y31: =SUM(I31:L31) -> #REF! | Z31: =SUM(J31:M31) -> #REF! | AA31: =SUM(K31:N31) -> #REF! | AB31: =SUM(L31:O31) -> #REF! | AC31: =SUM(M31:P31) -> #REF! | AD31: =SUM(N31:Q31) -> #REF! | AE31: =SUM(O31:R31) -> #REF! | AF31: =SUM(P31:S31) -> #REF! | ... AI31: =SUM(S31:V31) -> 0 | AK31: =SUM(AI31/AE31)-1 -> #REF!
B32: (-) Cash Taxes | C32: ='Historical Financials'!#REF! -> #REF! | H32: ='Historical Financials'!H31 -> -29.98 | I32: ='Historical Financials'!I31 -> -29.8 | J32: ='Historical Financials'!J31 -> -88.421 | K32: ='Historical Financials'!K31 -> -209.799 | L32: ='Historical Financials'!L31 -> 20.046 | M32: ='Historical Financials'!M31 -> -50 | N32: ='Historical Financials'!N31 -> -41 | O32: ='Historical Financials'!O31 -> 63.954 | ... Q32: ='Historical Financials'!Q31 -> -105 | X32: =SUM(G32:K32) -> -358 | Y32: =SUM(I32:L32) -> -307.974 | Z32: =SUM(J32:M32) -> -328.174 | AA32: =SUM(K32:N32) -> -280.753 | AB32: =SUM(L32:O32) -> -7 | AC32: =SUM(M32:P32) -> -112.046 | AD32: =SUM(N32:Q32) -> -167.046 | AE32: =SUM(O32:R32) -> -126.046 | AF32: =SUM(P32:S32) -> -190 | ... AI32: =SUM(S32:V32) -> 0 | AK32: =SUM(AI32/AE32)-1 -> -1
B33: (-) Cash Interest | C33: 0 | H33: 0 | I33: 0 | J33: 0 | K33: =D33 -> 0 | L33: 0 | M33: 0 | N33: 0 | O33: =E33 -> 0 | P33: 0 | Q33: 0 | X33: =SUM(G33:K33) -> 0 | Y33: =SUM(I33:L33) -> 0 | Z33: =SUM(J33:M33) -> 0 | AA33: =SUM(K33:N33) -> 0 | AB33: =SUM(L33:O33) -> 0 | AC33: =SUM(M33:P33) -> 0 | AD33: =SUM(N33:Q33) -> 0 | AE33: =SUM(O33:R33) -> 0 | AF33: =SUM(P33:S33) -> 0 | ... AI33: =SUM(S33:V33) -> 0 | AK33: =SUM(AI33/AE33)-1 -> #DIV/0!
B34: (+/-) Changes in NWC | C34: =SUM('Historical Financials'!#REF!) -> #REF! | H34: =SUM('Historical Financials'!H82:H86) -> 3472.641 | I34: =SUM('Historical Financials'!I82:I86) -> -3641.132 | J34: =SUM('Historical Financials'!J82:J86) -> 1325.237 | K34: =SUM('Historical Financials'!K82:K86) -> 4204.254 | L34: =SUM('Historical Financials'!L82:L86) -> 1830.953 | M34: =SUM('Historical Financials'!M82:M86) -> -195.864 | N34: =SUM('Historical Financials'!N82:N86) -> -1164.0477 | O34: =SUM('Historical Financials'!O82:O86) -> 2033.9587 | ... Q34: =SUM('Historical Financials'!Q82:Q86) -> -3762 | X34: =SUM(G34:K34) -> 5361 | Y34: =SUM(I34:L34) -> 3719.312 | Z34: =SUM(J34:M34) -> 7164.58 | AA34: =SUM(K34:N34) -> 4675.2953 | AB34: =SUM(L34:O34) -> 2505 | AC34: =SUM(M34:P34) -> -307.953 | AD34: =SUM(N34:Q34) -> -3874.089 | AE34: =SUM(O34:R34) -> -2710.0413 | AF34: =SUM(P34:S34) -> -4744 | ... AI34: =SUM(S34:V34) -> 0 | AK34: =SUM(AI34/AE34)-1 -> -1
B35: Discretionary Cash-Flows | C35: =SUM(C28+SUM(C31:C34)) -> #REF! | D35: =SUM(D28+SUM(D31:D34)) -> 0 | E35: =SUM(E28+SUM(E31:E34)) -> 0 | F35: =SUM(F28+SUM(F31:F34)) -> 0 | H35: =SUM(H28+SUM(H31:H34)) -> #REF! | I35: =SUM(I28+SUM(I31:I34)) -> #REF! | J35: =SUM(J28+SUM(J31:J34)) -> #REF! | K35: =SUM(K28+SUM(K31:K34)) -> #REF! | L35: =SUM(L28+SUM(L31:L34)) -> #REF! | M35: =SUM(M28+SUM(M31:M34)) -> #REF! | N35: =SUM(N28+SUM(N31:N34)) -> #REF! | O35: =SUM(O28+SUM(O31:O34)) -> #REF! | ... V35: =SUM(V28+SUM(V31:V34)) -> 0 | X35: =SUM(X28+SUM(X31:X34)) -> #REF! | Y35: =SUM(Y28+SUM(Y31:Y34)) -> #REF! | Z35: =SUM(Z28+SUM(Z31:Z34)) -> #REF! | AA35: =SUM(AA28+SUM(AA31:AA34)) -> #REF! | AB35: =SUM(AB28+SUM(AB31:AB34)) -> #REF! | AC35: =SUM(AC28+SUM(AC31:AC34)) -> #REF! | AD35: =SUM(AD28+SUM(AD31:AD34)) -> #REF! | AE35: =SUM(AE28+SUM(AE31:AE34)) -> #REF! | ... AI35: =SUM(AI28+SUM(AI31:AI34)) -> 0 | AK35: =SUM(AI35/AE35)-1 -> #REF!
B37: (+/-) Proceeds / (Purchases) of Equity, net | C37: ='Historical Financials'!#REF! -> #REF! | H37: ='Historical Financials'!#REF! -> #REF! | I37: ='Historical Financials'!#REF! -> #REF! | J37: ='Historical Financials'!#REF! -> #REF! | K37: ='Historical Financials'!#REF! -> #REF! | L37: ='Historical Financials'!#REF! -> #REF! | M37: ='Historical Financials'!#REF! -> #REF! | N37: ='Historical Financials'!#REF! -> #REF! | O37: ='Historical Financials'!#REF! -> #REF! | ... Q37: ='Historical Financials'!#REF! -> #REF! | X37: =SUM(G37:K37) -> #REF! | Y37: =SUM(I37:L37) -> #REF! | Z37: =SUM(J37:M37) -> #REF! | AA37: =SUM(K37:N37) -> #REF! | AB37: =SUM(L37:O37) -> #REF! | AC37: =SUM(M37:P37) -> #REF! | AD37: =SUM(N37:Q37) -> #REF! | AE37: =SUM(O37:R37) -> #REF! | AF37: =SUM(P37:S37) -> #REF! | ... AI37: =SUM(S37:V37) -> 0
B38: (+/-) Maturities / (Purchases) of available-for-sale securities | C38: =SUM('Historical Financials'!#REF!) -> #REF! | H38: =SUM('Historical Financials'!#REF!) -> #REF! | I38: =SUM('Historical Financials'!#REF!) -> #REF! | J38: =SUM('Historical Financials'!#REF!) -> #REF! | K38: =SUM('Historical Financials'!#REF!) -> #REF! | L38: =SUM('Historical Financials'!#REF!) -> #REF! | M38: =SUM('Historical Financials'!#REF!) -> #REF! | N38: =SUM('Historical Financials'!#REF!) -> #REF! | O38: =SUM('Historical Financials'!#REF!) -> #REF! | ... Q38: =SUM('Historical Financials'!#REF!) -> #REF! | X38: =SUM(G38:K38) -> #REF! | Y38: =SUM(I38:L38) -> #REF! | Z38: =SUM(J38:M38) -> #REF! | AA38: =SUM(K38:N38) -> #REF! | AB38: =SUM(L38:O38) -> #REF! | AC38: =SUM(M38:P38) -> #REF! | AD38: =SUM(N38:Q38) -> #REF! | AE38: =SUM(O38:R38) -> #REF! | AF38: =SUM(P38:S38) -> #REF! | ... AI38: =SUM(S38:V38) -> 0
B39: (+/-) Divestitures / (Acquisitions) | C39: ='Historical Financials'!#REF! -> #REF! | H39: ='Historical Financials'!#REF! -> #REF! | I39: ='Historical Financials'!#REF! -> #REF! | J39: ='Historical Financials'!#REF! -> #REF! | K39: ='Historical Financials'!#REF! -> #REF! | L39: ='Historical Financials'!#REF! -> #REF! | M39: ='Historical Financials'!#REF! -> #REF! | N39: ='Historical Financials'!#REF! -> #REF! | O39: ='Historical Financials'!#REF! -> #REF! | ... Q39: ='Historical Financials'!#REF! -> #REF! | X39: =SUM(G39:K39) -> #REF! | Y39: =SUM(I39:L39) -> #REF! | Z39: =SUM(J39:M39) -> #REF! | AA39: =SUM(K39:N39) -> #REF! | AB39: =SUM(L39:O39) -> #REF! | AC39: =SUM(M39:P39) -> #REF! | AD39: =SUM(N39:Q39) -> #REF! | AE39: =SUM(O39:R39) -> #REF! | AF39: =SUM(P39:S39) -> #REF! | ... AI39: =SUM(S39:V39) -> 0
B40: (+/-) Other Investing Activities | C40: ='Historical Financials'!#REF! -> #REF! | H40: ='Historical Financials'!#REF! -> #REF! | I40: ='Historical Financials'!#REF! -> #REF! | J40: ='Historical Financials'!#REF! -> #REF! | K40: ='Historical Financials'!#REF! -> #REF! | L40: ='Historical Financials'!#REF! -> #REF! | M40: ='Historical Financials'!#REF! -> #REF! | N40: ='Historical Financials'!#REF! -> #REF! | O40: ='Historical Financials'!#REF! -> #REF! | ... Q40: ='Historical Financials'!#REF! -> #REF! | X40: =SUM(G40:K40) -> #REF! | Y40: =SUM(I40:L40) -> #REF! | Z40: =SUM(J40:M40) -> #REF! | AA40: =SUM(K40:N40) -> #REF! | AB40: =SUM(L40:O40) -> #REF! | AC40: =SUM(M40:P40) -> #REF! | AD40: =SUM(N40:Q40) -> #REF! | AE40: =SUM(O40:R40) -> #REF! | AF40: =SUM(P40:S40) -> #REF! | ... AI40: =SUM(S40:V40) -> 0
B41: (+/-) Other Financing Activities | C41: ='Historical Financials'!#REF! -> #REF! | H41: ='Historical Financials'!#REF! -> #REF! | I41: ='Historical Financials'!#REF! -> #REF! | J41: ='Historical Financials'!#REF! -> #REF! | K41: ='Historical Financials'!#REF! -> #REF! | L41: ='Historical Financials'!#REF! -> #REF! | M41: ='Historical Financials'!#REF! -> #REF! | N41: ='Historical Financials'!#REF! -> #REF! | O41: ='Historical Financials'!#REF! -> #REF! | ... Q41: ='Historical Financials'!#REF! -> #REF! | X41: =SUM(G41:K41) -> #REF! | Y41: =SUM(I41:L41) -> #REF! | Z41: =SUM(J41:M41) -> #REF! | AA41: =SUM(K41:N41) -> #REF! | AB41: =SUM(L41:O41) -> #REF! | AC41: =SUM(M41:P41) -> #REF! | AD41: =SUM(N41:Q41) -> #REF! | AE41: =SUM(O41:R41) -> #REF! | AF41: =SUM(P41:S41) -> #REF! | ... AI41: =SUM(S41:V41) -> 0
B42: (+/-) Other Operating Activities | C42: ='Historical Financials'!#REF! -> #REF! | H42: ='Historical Financials'!#REF! -> #REF! | I42: ='Historical Financials'!#REF! -> #REF! | J42: ='Historical Financials'!#REF! -> #REF! | K42: ='Historical Financials'!#REF! -> #REF! | L42: ='Historical Financials'!#REF! -> #REF! | M42: ='Historical Financials'!#REF! -> #REF! | N42: ='Historical Financials'!#REF! -> #REF! | O42: ='Historical Financials'!#REF! -> #REF! | ... Q42: ='Historical Financials'!#REF! -> #REF! | X42: =SUM(G42:K42) -> #REF! | Y42: =SUM(I42:L42) -> #REF! | Z42: =SUM(J42:M42) -> #REF! | AA42: =SUM(K42:N42) -> #REF! | AB42: =SUM(L42:O42) -> #REF! | AC42: =SUM(M42:P42) -> #REF! | AD42: =SUM(N42:Q42) -> #REF! | AE42: =SUM(O42:R42) -> #REF! | AF42: =SUM(P42:S42) -> #REF! | ... AI42: =SUM(S42:V42) -> 0
B43: (+/-) Other | H43: =SUM(H48:H49)-SUM(C48:C49)-SUM(H35:H42) -> #REF! | I43: =SUM(I48:I49)-SUM(H48:H49)-SUM(I35:I42) -> #REF! | J43: =SUM(J48:J49)-SUM(I48:I49)-SUM(J35:J42) -> #REF! | K43: =SUM(K48:K49)-SUM(J48:J49)-SUM(K35:K42) -> #REF! | L43: =SUM(L48:L49)-SUM(K48:K49)-SUM(L35:L42) -> #REF! | M43: =SUM(M48:M49)-SUM(L48:L49)-SUM(M35:M42) -> #REF! | N43: =SUM(N48:N49)-SUM(M48:M49)-SUM(N35:N42) -> #REF! | O43: =SUM(O48:O49)-SUM(N48:N49)-SUM(O35:O42) -> #REF! | P43: =SUM(P48:P49)-SUM(O48:O49)-SUM(P35:P42) -> #REF! | Q43: =SUM(Q48:Q49)-SUM(P48:P49)-SUM(Q35:Q42) -> #REF! | X43: =SUM(G43:K43) -> #REF! | Y43: =SUM(I43:L43) -> #REF! | Z43: =SUM(J43:M43) -> #REF! | AA43: =SUM(K43:N43) -> #REF! | AB43: =SUM(L43:O43) -> #REF! | AC43: =SUM(M43:P43) -> #REF! | AD43: =SUM(N43:Q43) -> #REF! | AE43: =SUM(O43:R43) -> #REF! | AF43: =SUM(P43:S43) -> #REF! | ... AI43: =SUM(S43:V43) -> 0
B44: Free-Cash Flows | C44: =SUM(C35+SUM(C37:C43)) -> #REF! | D44: =SUM(D35+SUM(D37:D43)) -> 0 | E44: =SUM(E35+SUM(E37:E43)) -> 0 | F44: =SUM(F35+SUM(F37:F43)) -> 0 | H44: =SUM(H35+SUM(H37:H43)) -> #REF! | I44: =SUM(I35+SUM(I37:I43)) -> #REF! | J44: =SUM(J35+SUM(J37:J43)) -> #REF! | K44: =SUM(K35+SUM(K37:K43)) -> #REF! | L44: =SUM(L35+SUM(L37:L43)) -> #REF! | M44: =SUM(M35+SUM(M37:M43)) -> #REF! | N44: =SUM(N35+SUM(N37:N43)) -> #REF! | O44: =SUM(O35+SUM(O37:O43)) -> #REF! | ... V44: =SUM(V35+SUM(V37:V43)) -> 0 | X44: =SUM(X35+SUM(X37:X43)) -> #REF! | Y44: =SUM(Y35+SUM(Y37:Y43)) -> #REF! | Z44: =SUM(Z35+SUM(Z37:Z43)) -> #REF! | AA44: =SUM(AA35+SUM(AA37:AA43)) -> #REF! | AB44: =SUM(AB35+SUM(AB37:AB43)) -> #REF! | AC44: =SUM(AC35+SUM(AC37:AC43)) -> #REF! | AD44: =SUM(AD35+SUM(AD37:AD43)) -> #REF! | AE44: =SUM(AE35+SUM(AE37:AE43)) -> #REF! | ... AI44: =SUM(AI35+SUM(AI37:AI43)) -> 0
B46: Capitalization
B48: Cash & Cash Equivelants | C48: ='Historical Financials'!#REF! -> #REF! | H48: ='Historical Financials'!H46 -> 151146.36 | I48: ='Historical Financials'!I46 -> 153342.56 | J48: ='Historical Financials'!J46 -> 153199.35 | K48: ='Historical Financials'!K46 -> 149158 | L48: ='Historical Financials'!L46 -> 143621.85 | M48: ='Historical Financials'!M46 -> 153466.96 | N48: ='Historical Financials'!N46 -> 154817.16 | O48: ='Historical Financials'!O46 -> 151024 | ... Q48: ='Historical Financials'!Q46 -> 139386 | X48: =K48 -> 149158 | Y48: =L48 -> 143621.85 | Z48: =M48 -> 153466.96 | AA48: =N48 -> 154817.16 | AB48: =O48 -> 151024 | AC48: =P48 -> 143765 | AD48: =Q48 -> 139386 | AE48: =R48 -> 0 | ... AI48: =V48 -> 0
B49: Restricted Cash | C49: ='Historical Financials'!#REF! -> #REF! | H49: ='Historical Financials'!#REF! -> #REF! | I49: ='Historical Financials'!#REF! -> #REF! | J49: ='Historical Financials'!#REF! -> #REF! | K49: ='Historical Financials'!#REF! -> #REF! | L49: ='Historical Financials'!#REF! -> #REF! | M49: ='Historical Financials'!#REF! -> #REF! | N49: ='Historical Financials'!#REF! -> #REF! | O49: ='Historical Financials'!#REF! -> #REF! | ... Q49: ='Historical Financials'!#REF! -> #REF! | X49: =K49 -> #REF! | Y49: =L49 -> #REF! | Z49: =M49 -> #REF! | AA49: =N49 -> #REF! | AB49: =O49 -> #REF! | AC49: =P49 -> #REF! | AD49: =Q49 -> #REF! | AE49: =R49 -> 0 | ... AI49: =V49 -> 0
B50: Short-term Investments | C50: ='Historical Financials'!#REF! -> #REF! | H50: ='Historical Financials'!#REF! -> #REF! | I50: ='Historical Financials'!#REF! -> #REF! | J50: ='Historical Financials'!#REF! -> #REF! | K50: ='Historical Financials'!#REF! -> #REF! | L50: ='Historical Financials'!#REF! -> #REF! | M50: ='Historical Financials'!#REF! -> #REF! | N50: ='Historical Financials'!#REF! -> #REF! | O50: ='Historical Financials'!#REF! -> #REF! | ... Q50: ='Historical Financials'!#REF! -> #REF! | X50: =K50 -> #REF! | Y50: =L50 -> #REF! | Z50: =M50 -> #REF! | AA50: =N50 -> #REF! | AB50: =O50 -> #REF! | AC50: =P50 -> #REF! | AD50: =Q50 -> #REF! | AE50: =R50 -> 0 | ... AI50: =V50 -> 0
...
