Workbook

Sheet Historical Financials
B2: Ulta Beauty Inc. (NASDAQ: ULTA)
B3: Historical Financials
B4: $ in thousands except per share
A6: X | B6: Income Statement | C6: FYE | F6: FYE | J6: Quarterly | T6: Quarterly | AF6: LTM | AG6: LTM | AM6: Variance
B7: Fiscal Period | C7: 2019 | D7: 2020 | E7: 2021 | F7: 2022 | G7: 2023 | H7: 2024 | J7: 1Q22 | K7: 2Q22 | L7: 3Q22 | M7: 4Q22 | N7: 1Q23 | O7: 2Q23 | P7: 3Q23 | Q7: 4Q23 | R7: 1Q24 | S7: 2Q24 | T7: 3Q24 | U7: 4Q24 | V7: 1Q25 | W7: 2Q25 | X7: 3Q25 | Z7: =M7 -> 4Q22 | AA7: =N7 -> 1Q23 | AB7: =O7 -> 2Q23 | AC7: =P7 -> 3Q23 | AD7: =Q7 -> 4Q23 | AE7: =R7 -> 1Q24 | AF7: =S7 -> 2Q24 | AG7: =T7 -> 3Q24 | ... AK7: =X7 -> 3Q25
B8: Fiscal Period End Date | C8: 43862 | D8: 44226 | E8: 44590 | F8: 44954 | G8: 45325 | H8: 45689 | J8: 44681 | K8: 44772 | L8: 44863 | M8: 44954 | N8: 45045 | O8: 45136 | P8: 45227 | Q8: 45325 | R8: 45416 | S8: 45507 | T8: 45598 | U8: 45689 | V8: 45780 | W8: 45871 | X8: 45962 | Z8: =M8 -> 44954 | AA8: =N8 -> 45045 | AB8: =O8 -> 45136 | AC8: =P8 -> 45227 | AD8: =Q8 -> 45325 | AE8: =R8 -> 45416 | AF8: =S8 -> 45507 | AG8: =T8 -> 45598 | ... AK8: =X8 -> 45962
B10: Consolidated Revenue | C10: 7398068 | D10: 6151953 | E10: 8630889 | F10: 10208580 | G10: 11207303 | H10: 11295654 | J10: 2345901 | K10: 2297113 | L10: 2338793 | M10: =SUM(F10-SUM(J10:L10)) -> 3226773 | N10: 2634263 | O10: 2529809 | P10: 2488933 | Q10: =SUM(G10-SUM(N10:P10)) -> 3554298 | R10: 2725848 | S10: 2552087 | T10: 2530100 | U10: =SUM(H10-SUM(R10:T10)) -> 3487619 | V10: 2848367 | W10: 2788469 | X10: 2857623 | Z10: =SUM(J10:M10) -> 10208580 | AA10: =SUM(K10:N10) -> 10496942 | AB10: =SUM(L10:O10) -> 10729638 | AC10: =SUM(M10:P10) -> 10879778 | AD10: =SUM(N10:Q10) -> 11207303 | AE10: =SUM(O10:R10) -> 11298888 | AF10: =SUM(P10:S10) -> 11321166 | AG10: =SUM(Q10:T10) -> 11362333 | ... AK10: =SUM(U10:X10) -> 11982078 | AM10: =SUM(AJ10/AF10)-1 -> 0.029448292
B11: Total Revenue | C11: =+SUM(C10:C10) -> 7398068 | D11: =+SUM(D10:D10) -> 6151953 | E11: =+SUM(E10:E10) -> 8630889 | F11: =+SUM(F10:F10) -> 10208580 | G11: =+SUM(G10:G10) -> 11207303 | H11: =+SUM(H10:H10) -> 11295654 | J11: =+SUM(J10:J10) -> 2345901 | K11: =+SUM(K10:K10) -> 2297113 | L11: =+SUM(L10:L10) -> 2338793 | M11: =+SUM(M10:M10) -> 3226773 | N11: =+SUM(N10:N10) -> 2634263 | O11: =+SUM(O10:O10) -> 2529809 | P11: =+SUM(P10:P10) -> 2488933 | Q11: =+SUM(Q10:Q10) -> 3554298 | ... X11: =+SUM(X10:X10) -> 2857623 | Z11: =+SUM(Z10:Z10) -> 10208580 | AA11: =+SUM(AA10:AA10) -> 10496942 | AB11: =+SUM(AB10:AB10) -> 10729638 | AC11: =+SUM(AC10:AC10) -> 10879778 | AD11: =+SUM(AD10:AD10) -> 11207303 | AE11: =+SUM(AE10:AE10) -> 11298888 | AF11: =+SUM(AF10:AF10) -> 11321166 | AG11: =+SUM(AG10:AG10) -> 11362333 | ... AK11: =+SUM(AK10:AK10) -> 11982078 | AM11: =SUM(AJ11/AF11)-1 -> 0.029448292
B13: Cost of Sales | C13: -4717004 | D13: -4202794 | E13: -5262335 | F13: -6164070 | G13: -6826203 | H13: -6908401 | J13: -1404875 | K13: -1368949 | L13: -1375976 | M13: =SUM(F13-SUM(J13:L13)) -> -2014270 | N13: -1579406 | O13: -1536197 | P13: -1496866 | Q13: =SUM(G13-SUM(N13:P13)) -> -2213734 | R13: -1656068 | S13: -1573910 | T13: -1524456 | U13: =SUM(H13-SUM(R13:T13)) -> -2153967 | V13: -1734148 | W13: -1696773 | X13: -1701958 | Z13: =SUM(K13:N13) -> -6338601 | AA13: =SUM(L13:O13) -> -6505849 | AB13: =SUM(M13:P13) -> -6626739 | AC13: =SUM(N13:Q13) -> -6826203 | AD13: =SUM(O13:R13) -> -6902865 | AE13: =SUM(P13:S13) -> -6940578 | AF13: =SUM(P13:S13) -> -6940578 | AG13: =SUM(Q13:T13) -> -6968168 | AH13: =SUM(R13:U13) -> -6908401 | AI13: =SUM(S13:V13) -> -6986481 | AJ13: =SUM(T13:W13) -> -7109344 | AK13: =SUM(U13:X13) -> -7286846 | AM13: =SUM(AJ13/AF13)-1 -> 0.024315842
B14: Gross Profit | C14: =+SUM(C11+SUM(C13:C13)) -> 2681064 | D14: =+SUM(D11+SUM(D13:D13)) -> 1949159 | E14: =+SUM(E11+SUM(E13:E13)) -> 3368554 | F14: =+SUM(F11+SUM(F13:F13)) -> 4044510 | G14: =+SUM(G11+SUM(G13:G13)) -> 4381100 | H14: =+SUM(H11+SUM(H13:H13)) -> 4387253 | J14: =+SUM(J11+SUM(J13:J13)) -> 941026 | K14: =+SUM(K11+SUM(K13:K13)) -> 928164 | L14: =+SUM(L11+SUM(L13:L13)) -> 962817 | M14: =+SUM(M11+SUM(M13:M13)) -> 1212503 | N14: =+SUM(N11+SUM(N13:N13)) -> 1054857 | O14: =+SUM(O11+SUM(O13:O13)) -> 993612 | P14: =+SUM(P11+SUM(P13:P13)) -> 992067 | Q14: =+SUM(Q11+SUM(Q13:Q13)) -> 1340564 | ... X14: =+SUM(X11+SUM(X13:X13)) -> 1155665 | Z14: =+SUM(Z11+SUM(Z13:Z13)) -> 3869979 | AA14: =+SUM(AA11+SUM(AA13:AA13)) -> 3991093 | AB14: =+SUM(AB11+SUM(AB13:AB13)) -> 4102899 | AC14: =+SUM(AC11+SUM(AC13:AC13)) -> 4053575 | AD14: =+SUM(AD11+SUM(AD13:AD13)) -> 4304438 | AE14: =+SUM(AE11+SUM(AE13:AE13)) -> 4358310 | AF14: =+SUM(AF11+SUM(AF13:AF13)) -> 4380588 | AG14: =+SUM(AG11+SUM(AG13:AG13)) -> 4394165 | ... AK14: =+SUM(AK11+SUM(AK13:AK13)) -> 4695232 | AM14: =SUM(AJ14/AF14)-1 -> 0.037580115
B15: Gross Margin (%) | C15: =C14/C11 -> 0.36240056 | D15: =D14/D11 -> 0.31683581 | E15: =E14/E11 -> 0.3902905 | F15: =F14/F11 -> 0.39618732 | G15: =G14/G11 -> 0.39091475 | H15: =H14/H11 -> 0.38840186 | J15: =J14/J11 -> 0.40113628 | K15: =K14/K11 -> 0.40405674 | L15: =L14/L11 -> 0.4116726 | M15: =M14/M11 -> 0.37576334 | N15: =N14/N11 -> 0.40043724 | O15: =O14/O11 -> 0.39276167 | P15: =P14/P11 -> 0.39859128 | Q15: =Q14/Q11 -> 0.37716702 | ... X15: =X14/X11 -> 0.40441479 | Z15: =Z14/Z11 -> 0.37909082 | AA15: =AA14/AA11 -> 0.38021483 | AB15: =AB14/AB11 -> 0.38238932 | AC15: =AC14/AC11 -> 0.37257883 | AD15: =AD14/AD11 -> 0.38407438 | AE15: =AE14/AE11 -> 0.38572911 | AF15: =AF14/AF11 -> 0.38693788 | AG15: =AG14/AG11 -> 0.38673088 | ... AK15: =AK14/AK11 -> 0.39185457 | AM15: =SUM(AJ15-AF15)*1000 -> 3.0565016
B17: Selling, general and administrative expenses | C17: -1760716 | D17: -1583017 | E17: -2061545 | F17: -2395299 | G17: -2694561 | H17: -2808592 | J17: -500970 | K17: -534459 | L17: -597164 | M17: =SUM(F17-SUM(J17:L17)) -> -762706 | N17: -612129 | O17: -600692 | P17: -661380 | Q17: =SUM(G17-SUM(N17:P17)) -> -820360 | R17: -665913 | S17: -644821 | T17: -682259 | U17: =SUM(H17-SUM(R17:T17)) -> -815599 | V17: -710613 | W17: -741737 | X17: -840920 | Z17: =SUM(K17:N17) -> -2506458 | AA17: =SUM(L17:O17) -> -2572691 | AB17: =SUM(M17:P17) -> -2636907 | AC17: =SUM(N17:Q17) -> -2694561 | AD17: =SUM(O17:R17) -> -2748345 | AE17: =SUM(P17:S17) -> -2792474 | AF17: =SUM(P17:S17) -> -2792474 | AG17: =SUM(Q17:T17) -> -2813353 | AH17: =SUM(R17:U17) -> -2808592 | AI17: =SUM(S17:V17) -> -2853292 | AJ17: =SUM(T17:W17) -> -2950208 | AK17: =SUM(U17:X17) -> -3108869 | AM17: =SUM(AJ17/AF17)-1 -> 0.056485396
B18: Pre-opening expenses | C18: -19254 | D18: -15000 | E18: -9517 | F18: -10601 | G18: -8510 | H18: -13689 | J18: -2348 | K18: -2277 | L18: -3797 | M18: =SUM(F18-SUM(J18:L18)) -> -2179 | N18: -658 | O18: -1278 | P18: -3460 | Q18: =SUM(G18-SUM(N18:P18)) -> -3114 | R18: -2919 | S18: -4155 | T18: -4883 | U18: =SUM(H18-SUM(R18:T18)) -> -1732 | V18: -1829 | W18: -5105 | X18: -5326 | Z18: =SUM(K18:N18) -> -8911 | AA18: =SUM(L18:O18) -> -7912 | AB18: =SUM(M18:P18) -> -7575 | AC18: =SUM(N18:Q18) -> -8510 | AD18: =SUM(O18:R18) -> -10771 | AE18: =SUM(P18:S18) -> -13648 | AF18: =SUM(P18:S18) -> -13648 | AG18: =SUM(Q18:T18) -> -15071 | AH18: =SUM(R18:U18) -> -13689 | AI18: =SUM(S18:V18) -> -12599 | AJ18: =SUM(T18:W18) -> -13549 | AK18: =SUM(U18:X18) -> -13992 | AM18: =SUM(AJ18/AF18)-1 -> -0.0072538101
B19: Impairment, restructuring and other costs | C19: 0 | D19: -114322 | E19: 0 | F19: 0 | G19: 0 | H19: 0 | J19: 0 | K19: 0 | L19: 0 | M19: =SUM(F19-SUM(J19:L19)) -> 0 | N19: 0 | O19: 0 | P19: 0 | Q19: =SUM(G19-SUM(N19:P19)) -> 0 | R19: 0 | S19: 0 | T19: 0 | U19: =SUM(H19-SUM(R19:T19)) -> 0 | V19: 0 | W19: 0 | X19: 0 | Z19: =SUM(K19:N19) -> 0 | AA19: =SUM(L19:O19) -> 0 | AB19: =SUM(M19:P19) -> 0 | AC19: =SUM(N19:Q19) -> 0 | AD19: =SUM(O19:R19) -> 0 | AE19: =SUM(P19:S19) -> 0 | AF19: =SUM(P19:S19) -> 0 | AG19: =SUM(Q19:T19) -> 0 | AH19: =SUM(R19:U19) -> 0 | AI19: =SUM(S19:V19) -> 0 | AJ19: =SUM(T19:W19) -> 0 | AK19: =SUM(U19:X19) -> 0 | AM19: =SUM(AJ19/AF19)-1 -> #DIV/0!
B20: Operating Profit | C20: =+SUM(C14+SUM(C17:C19)) -> 901094 | D20: =+SUM(D14+SUM(D17:D19)) -> 236820 | E20: =+SUM(E14+SUM(E17:E19)) -> 1297492 | F20: =+SUM(F14+SUM(F17:F19)) -> 1638610 | G20: =+SUM(G14+SUM(G17:G19)) -> 1678029 | H20: =+SUM(H14+SUM(H17:H19)) -> 1564972 | J20: =+SUM(J14+SUM(J17:J19)) -> 437708 | K20: =+SUM(K14+SUM(K17:K19)) -> 391428 | L20: =+SUM(L14+SUM(L17:L19)) -> 361856 | M20: =+SUM(M14+SUM(M17:M19)) -> 447618 | N20: =+SUM(N14+SUM(N17:N19)) -> 442070 | O20: =+SUM(O14+SUM(O17:O19)) -> 391642 | P20: =+SUM(P14+SUM(P17:P19)) -> 327227 | Q20: =+SUM(Q14+SUM(Q17:Q19)) -> 517090 | ... X20: =+SUM(X14+SUM(X17:X19)) -> 309419 | Z20: =+SUM(Z14+SUM(Z17:Z19)) -> 1354610 | AA20: =+SUM(AA14+SUM(AA17:AA19)) -> 1410490 | AB20: =+SUM(AB14+SUM(AB17:AB19)) -> 1458417 | AC20: =+SUM(AC14+SUM(AC17:AC19)) -> 1350504 | AD20: =+SUM(AD14+SUM(AD17:AD19)) -> 1545322 | AE20: =+SUM(AE14+SUM(AE17:AE19)) -> 1552188 | AF20: =+SUM(AF14+SUM(AF17:AF19)) -> 1574466 | AG20: =+SUM(AG14+SUM(AG17:AG19)) -> 1565741 | ... AK20: =+SUM(AK14+SUM(AK17:AK19)) -> 1572371 | AM20: =SUM(AJ20/AF20)-1 -> 0.0044383302
B21: Operating Margin (%) | C21: =C20/C11 -> 0.12180126 | D21: =D20/D11 -> 0.038495093 | E21: =E20/E11 -> 0.15033121 | F21: =F20/F11 -> 0.16051302 | G21: =G20/G11 -> 0.14972639 | H21: =H20/H11 -> 0.13854638 | J21: =J20/J11 -> 0.18658417 | K21: =K20/K11 -> 0.17039998 | L21: =L20/L11 -> 0.15471912 | M21: =M20/M11 -> 0.13872002 | N21: =N20/N11 -> 0.16781544 | O21: =O20/O11 -> 0.1548109 | P21: =P20/P11 -> 0.1314728 | Q21: =Q20/Q11 -> 0.14548302 | ... X21: =X20/X11 -> 0.10827845 | Z21: =Z20/Z11 -> 0.13269328 | AA21: =AA20/AA11 -> 0.13437152 | AB21: =AB20/AB11 -> 0.13592416 | AC21: =AC20/AC11 -> 0.12412974 | AD21: =AD20/AD11 -> 0.13788527 | AE21: =AE20/AE11 -> 0.13737529 | AF21: =AF20/AF11 -> 0.13907278 | AG21: =AG20/AG11 -> 0.13780101 | ... AK21: =AK20/AK11 -> 0.1312269 | AM21: =SUM(AJ21-AF21)*1000 -> -3.3787077
B23: Interest Income (Expense), net | C23: 5056 | D23: -5735 | E23: -1663 | F23: 4934 | G23: 17622 | H23: 15094 | J23: -401 | K23: 108 | L23: 849 | M23: =SUM(F23-SUM(J23:L23)) -> 4378 | N23: 7348 | O23: 4449 | P23: 2497 | Q23: =SUM(G23-SUM(N23:P23)) -> 3328 | R23: 6900 | S23: 4526 | T23: 1674 | U23: =SUM(H23-SUM(R23:T23)) -> 1994 | V23: 3547 | W23: 1413 | X23: -4123 | Z23: =SUM(K23:N23) -> 12683 | AA23: =SUM(L23:O23) -> 17024 | AB23: =SUM(M23:P23) -> 18672 | AC23: =SUM(N23:Q23) -> 17622 | AD23: =SUM(O23:R23) -> 17174 | AE23: =SUM(P23:S23) -> 17251 | AF23: =SUM(P23:S23) -> 17251 | AG23: =SUM(Q23:T23) -> 16428 | AH23: =SUM(R23:U23) -> 15094 | AI23: =SUM(S23:V23) -> 11741 | AJ23: =SUM(T23:W23) -> 8628 | AK23: =SUM(U23:X23) -> 2831 | AM23: =SUM(AJ23/AF23)-1 -> -0.49985508
B24: Earning Before Taxes | C24: =SUM(C20+SUM(C23:C23)) -> 906150 | D24: =SUM(D20+SUM(D23:D23)) -> 231085 | E24: =SUM(E20+SUM(E23:E23)) -> 1295829 | F24: =SUM(F20+SUM(F23:F23)) -> 1643544 | G24: =SUM(G20+SUM(G23:G23)) -> 1695651 | H24: =SUM(H20+SUM(H23:H23)) -> 1580066 | J24: =SUM(J20+SUM(J23:J23)) -> 437307 | K24: =SUM(K20+SUM(K23:K23)) -> 391536 | L24: =SUM(L20+SUM(L23:L23)) -> 362705 | M24: =SUM(M20+SUM(M23:M23)) -> 451996 | N24: =SUM(N20+SUM(N23:N23)) -> 449418 | O24: =SUM(O20+SUM(O23:O23)) -> 396091 | P24: =SUM(P20+SUM(P23:P23)) -> 329724 | Q24: =SUM(Q20+SUM(Q23:Q23)) -> 520418 | ... X24: =SUM(X20+SUM(X23:X23)) -> 305296 | Z24: =SUM(Z20+SUM(Z23:Z23)) -> 1367293 | AA24: =SUM(AA20+SUM(AA23:AA23)) -> 1427514 | AB24: =SUM(AB20+SUM(AB23:AB23)) -> 1477089 | AC24: =SUM(AC20+SUM(AC23:AC23)) -> 1368126 | AD24: =SUM(AD20+SUM(AD23:AD23)) -> 1562496 | AE24: =SUM(AE20+SUM(AE23:AE23)) -> 1569439 | AF24: =SUM(AF20+SUM(AF23:AF23)) -> 1591717 | AG24: =SUM(AG20+SUM(AG23:AG23)) -> 1582169 | ... AK24: =SUM(AK20+SUM(AK23:AK23)) -> 1575202 | AM24: =SUM(AJ24/AF24)-1 -> -0.0010271926
B25: EBT Margin (%) | C25: =C24/C11 -> 0.12248468 | D25: =D24/D11 -> 0.037562868 | E25: =E24/E11 -> 0.15013853 | F25: =F24/F11 -> 0.16099634 | G25: =G24/G11 -> 0.15129876 | H25: =H24/H11 -> 0.13988265 | J25: =J24/J11 -> 0.18641324 | K25: =K24/K11 -> 0.17044699 | L25: =L24/L11 -> 0.15508213 | M25: =M24/M11 -> 0.14007679 | N25: =N24/N11 -> 0.17060483 | O25: =O24/O11 -> 0.15656953 | P25: =P24/P11 -> 0.13247604 | Q25: =Q24/Q11 -> 0.14641935 | ... X25: =X24/X11 -> 0.10683565 | Z25: =Z24/Z11 -> 0.13393567 | AA25: =AA24/AA11 -> 0.13599332 | AB25: =AB24/AB11 -> 0.13766438 | AC25: =AC24/AC11 -> 0.12574944 | AD25: =AD24/AD11 -> 0.13941766 | AE25: =AE24/AE11 -> 0.13890208 | AF25: =AF24/AF11 -> 0.14059656 | AG25: =AG24/AG11 -> 0.13924684 | ... AK25: =AK24/AK11 -> 0.13146317 | AM25: =SUM(AJ25-AF25)*1000 -> -4.1621792
B27: Income tax expense | C27: -200205 | D27: -55250 | E27: -309992 | F27: -401136 | G27: -404646 | H27: -378948 | J27: -105912 | K27: -95859 | L27: -88120 | M27: =SUM(F27-SUM(J27:L27)) -> -111245 | N27: -102367 | O27: -95989 | P27: -80241 | Q27: =SUM(G27-SUM(N27:P27)) -> -126049 | R27: -94735 | S27: -81171 | T27: -77997 | U27: =SUM(H27-SUM(R27:T27)) -> -125045 | V27: -99644 | W27: -84795 | X27: -73436 | Z27: =SUM(K27:N27) -> -397591 | AA27: =SUM(L27:O27) -> -397721 | AB27: =SUM(M27:P27) -> -389842 | AC27: =SUM(N27:Q27) -> -404646 | AD27: =SUM(O27:R27) -> -397014 | AE27: =SUM(P27:S27) -> -382196 | AF27: =SUM(P27:S27) -> -382196 | AG27: =SUM(Q27:T27) -> -379952 | AH27: =SUM(R27:U27) -> -378948 | AI27: =SUM(S27:V27) -> -383857 | AJ27: =SUM(T27:W27) -> -387481 | AK27: =SUM(U27:X27) -> -382920 | AM27: =SUM(AJ27/AF27)-1 -> 0.013827984
B28: Income before equity net loss of affiliate | C28: =SUM(C24+C27) -> 705945 | D28: =SUM(D24+D27) -> 175835 | E28: =SUM(E24+E27) -> 985837 | F28: =SUM(F24+F27) -> 1242408 | G28: =SUM(G24+G27) -> 1291005 | H28: =SUM(H24+H27) -> 1201118 | J28: =SUM(J24+J27) -> 331395 | K28: =SUM(K24+K27) -> 295677 | L28: =SUM(L24+L27) -> 274585 | M28: =SUM(M24+M27) -> 340751 | N28: =SUM(N24+N27) -> 347051 | O28: =SUM(O24+O27) -> 300102 | P28: =SUM(P24+P27) -> 249483 | Q28: =SUM(Q24+Q27) -> 394369 | ... X28: =SUM(X24+X27) -> 231860 | Z28: =SUM(Z24+Z27) -> 969702 | AA28: =SUM(AA24+AA27) -> 1029793 | AB28: =SUM(AB24+AB27) -> 1087247 | AC28: =SUM(AC24+AC27) -> 963480 | AD28: =SUM(AD24+AD27) -> 1165482 | AE28: =SUM(AE24+AE27) -> 1187243 | AF28: =SUM(AF24+AF27) -> 1209521 | AG28: =SUM(AG24+AG27) -> 1202217 | ... AK28: =SUM(AK24+AK27) -> 1192282 | AM28: =SUM(AJ28/AF28)-1 -> -0.0057212731
B30: Equity net loss of affiliate | C30: 0 | D30: 0 | E30: 0 | F30: 0 | G30: 0 | H30: 0 | J30: 0 | K30: 0 | L30: 0 | M30: =SUM(F30-SUM(J30:L30)) -> 0 | N30: 0 | O30: 0 | P30: 0 | Q30: =SUM(G30-SUM(N30:P30)) -> 0 | R30: 0 | S30: 0 | T30: 0 | U30: =SUM(H30-SUM(R30:T30)) -> 0 | V30: -628 | W30: -597 | X30: -985 | Z30: =SUM(K30:N30) -> 0 | AA30: =SUM(L30:O30) -> 0 | AB30: =SUM(M30:P30) -> 0 | AC30: =SUM(N30:Q30) -> 0 | AD30: =SUM(O30:R30) -> 0 | AE30: =SUM(P30:S30) -> 0 | AF30: =SUM(P30:S30) -> 0 | AG30: =SUM(Q30:T30) -> 0 | AH30: =SUM(R30:U30) -> 0 | AI30: =SUM(S30:V30) -> -628 | AJ30: =SUM(T30:W30) -> -1225 | AK30: =SUM(U30:X30) -> -2210 | AM30: =SUM(AJ30/AF30)-1 -> #DIV/0!
B31: Net Income | C31: =SUM(C28+C30) -> 705945 | D31: =SUM(D28+D30) -> 175835 | E31: =SUM(E28+E30) -> 985837 | F31: =SUM(F28+F30) -> 1242408 | G31: =SUM(G28+G30) -> 1291005 | H31: =SUM(H28+H30) -> 1201118 | J31: =SUM(J28+J30) -> 331395 | K31: =SUM(K28+K30) -> 295677 | L31: =SUM(L28+L30) -> 274585 | M31: =SUM(M28+M30) -> 340751 | N31: =SUM(N28+N30) -> 347051 | O31: =SUM(O28+O30) -> 300102 | P31: =SUM(P28+P30) -> 249483 | Q31: =SUM(Q28+Q30) -> 394369 | ... X31: =SUM(X28+X30) -> 230875 | Z31: =SUM(Z28+Z30) -> 969702 | AA31: =SUM(AA28+AA30) -> 1029793 | AB31: =SUM(AB28+AB30) -> 1087247 | AC31: =SUM(AC28+AC30) -> 963480 | AD31: =SUM(AD28+AD30) -> 1165482 | AE31: =SUM(AE28+AE30) -> 1187243 | AF31: =SUM(AF28+AF30) -> 1209521 | AG31: =SUM(AG28+AG30) -> 1202217 | ... AK31: =SUM(AK28+AK30) -> 1190072 | AM31: =SUM(AJ31/AF31)-1 -> -0.0067340708
B32: Margin (%) | C32: =C31/C11 -> 0.095422886 | D32: =D31/D11 -> 0.02858198 | E32: =E31/E11 -> 0.11422195 | F32: =F31/F11 -> 0.12170233 | G32: =G31/G11 -> 0.11519319 | H32: =H31/H11 -> 0.10633452 | J32: =J31/J11 -> 0.14126555 | K32: =K31/K11 -> 0.12871678 | L32: =L31/L11 -> 0.11740458 | M32: =M31/M11 -> 0.10560117 | N32: =N31/N11 -> 0.13174501 | O32: =O31/O11 -> 0.11862635 | P32: =P31/P11 -> 0.10023693 | Q32: =Q31/Q11 -> 0.11095552 | ... X32: =X31/X11 -> 0.080792673 | Z32: =Z31/Z11 -> 0.094988921 | AA32: =AA31/AA11 -> 0.098104095 | AB32: =AB31/AB11 -> 0.10133119 | AC32: =AC31/AC11 -> 0.088556954 | AD32: =AD31/AD11 -> 0.10399308 | AE32: =AE31/AE11 -> 0.10507609 | AF32: =AF31/AF11 -> 0.10683714 | AG32: =AG31/AG11 -> 0.10580723 | ... AK32: =AK31/AK11 -> 0.099321003 | AM32: =SUM(AJ32-AF32)*1000 -> -3.7550406
B34: Basic shares | C34: 57840 | D34: 56351 | E34: 54482 | F34: 51403 | G34: 49304 | H34: 47207 | J34: 52250 | K34: 51607 | L34: 51131 | M34: =F34 -> 51403 | N34: 50153 | O34: 49617 | P34: 49007 | Q34: =G34 -> 49304 | R34: 48125 | S34: 47505 | T34: 46928 | U34: =H34 -> 47207 | V34: 45362 | W34: 44955 | X34: 44731 | Z34: =M34 -> 51403 | AA34: =N34 -> 50153 | AB34: =O34 -> 49617 | AC34: =P34 -> 49007 | AD34: =Q34 -> 49304 | AE34: =R34 -> 48125 | AF34: =S34 -> 47505 | AG34: =T34 -> 46928 | ... AK34: =X34 -> 44731 | AM34: =SUM(AJ34/AF34)-1 -> -0.05367856
B35: Basic EPS | C35: =C31/C34 -> 12.205135 | D35: =D31/D34 -> 3.1203528 | E35: =E31/E34 -> 18.094729 | F35: =F31/F34 -> 24.169951 | G35: =G31/G34 -> 26.184589 | H35: =H31/H34 -> 25.443642 | J35: =J31/J34 -> 6.342488 | K35: =K31/K34 -> 5.7293972 | L35: =L31/L34 -> 5.3702255 | M35: =M31/M34 -> 6.62901 | N35: =N31/N34 -> 6.9198453 | O35: =O31/O34 -> 6.0483705 | P35: =P31/P34 -> 5.0907625 | Q35: =Q31/Q34 -> 7.9987222 | ... X35: =X31/X34 -> 5.1614093 | Z35: =Z31/Z34 -> 18.864697 | AA35: =AA31/AA34 -> 20.533029 | AB35: =AB31/AB34 -> 21.912792 | AC35: =AC31/AC34 -> 19.660049 | AD35: =AD31/AD34 -> 23.638691 | AE35: =AE31/AE34 -> 24.669984 | AF35: =AF31/AF34 -> 25.46092 | AG35: =AG31/AG34 -> 25.61833 | ... AK35: =AK31/AK34 -> 26.605084 | AM35: =SUM(AJ35/AF35)-1 -> 0.04960734
B37: Fully Diluted Shares | C37: 58105 | D37: 56558 | E37: 54841 | F37: 51738 | G37: 49596 | H37: 47404 | J37: 52582 | K37: 51900 | L37: 51418 | M37: =F37 -> 51738 | N37: 50469 | O37: 49849 | P37: 49226 | Q37: =G37 -> 49596 | R37: 48381 | S37: 47667 | T37: 47092 | U37: =H37 -> 47404 | V37: 45508 | W37: 45112 | X37: 44895 | Z37: =N37 -> 50469 | AA37: =O37 -> 49849 | AB37: =P37 -> 49226 | AC37: =Q37 -> 49596 | AD37: =R37 -> 48381 | AE37: =S37 -> 47667 | AF37: =S37 -> 47667 | AG37: =T37 -> 47092 | AH37: =U37 -> 47404 | AI37: =V37 -> 45508 | AJ37: =W37 -> 45112 | AK37: =X37 -> 44895 | AM37: =SUM(AJ37/AF37)-1 -> -0.053601024
B38: Diluted EPS | C38: =C31/C37 -> 12.149471 | D38: =D31/D37 -> 3.1089324 | E38: =E31/E37 -> 17.976277 | F38: =F31/F37 -> 24.013452 | G38: =G31/G37 -> 26.030426 | H38: =H31/H37 -> 25.337904 | J38: =J31/J37 -> 6.3024419 | K38: =K31/K37 -> 5.697052 | L38: =L31/L37 -> 5.3402505 | M38: =M31/M37 -> 6.5860876 | N38: =N31/N37 -> 6.8765183 | O38: =O31/O37 -> 6.0202211 | P38: =P31/P37 -> 5.0681144 | Q38: =Q31/Q37 -> 7.9516292 | ... X38: =X31/X37 -> 5.1425549 | Z38: =Z31/Z37 -> 19.213814 | AA38: =AA31/AA37 -> 20.658248 | AB38: =AB31/AB37 -> 22.086844 | AC38: =AC31/AC37 -> 19.426567 | AD38: =AD31/AD37 -> 24.089663 | AE38: =AE31/AE37 -> 24.907022 | AF38: =AF31/AF37 -> 25.374389 | AG38: =AG31/AG37 -> 25.529113 | ... AK38: =AK31/AK37 -> 26.507896 | AM38: =SUM(AJ38/AF38)-1 -> 0.049521348
A40: X | B40: Balance Sheet | C40: FYE | F40: FYE | J40: Quarterly | T40: Quarterly | AF40: LTM | AM40: Variance
B41: =B7 -> Fiscal Period | C41: =C7 -> 2019 | D41: =D7 -> 2020 | E41: =E7 -> 2021 | F41: =F7 -> 2022 | G41: =G7 -> 2023 | H41: =H7 -> 2024 | J41: =J7 -> 1Q22 | K41: =K7 -> 2Q22 | L41: =L7 -> 3Q22 | M41: =M7 -> 4Q22 | N41: =N7 -> 1Q23 | O41: =O7 -> 2Q23 | P41: =P7 -> 3Q23 | Q41: =Q7 -> 4Q23 | ... X41: =X7 -> 3Q25 | Z41: =Z7 -> 4Q22 | AA41: =AA7 -> 1Q23 | AB41: =AB7 -> 2Q23 | AC41: =AC7 -> 3Q23 | AD41: =AD7 -> 4Q23 | AE41: =AE7 -> 1Q24 | AF41: =AF7 -> 2Q24 | AG41: =AG7 -> 3Q24 | ... AK41: =AK7 -> 3Q25
B42: =B8 -> Fiscal Period End Date | C42: =C8 -> 43862 | D42: =D8 -> 44226 | E42: =E8 -> 44590 | F42: =F8 -> 44954 | G42: =G8 -> 45325 | H42: =H8 -> 45689 | J42: =J8 -> 44681 | K42: =K8 -> 44772 | L42: =L8 -> 44863 | M42: =M8 -> 44954 | N42: =N8 -> 45045 | O42: =O8 -> 45136 | P42: =P8 -> 45227 | Q42: =Q8 -> 45325 | ... X42: =X8 -> 45962 | Z42: =Z8 -> 44954 | AA42: =AA8 -> 45045 | AB42: =AB8 -> 45136 | AC42: =AC8 -> 45227 | AD42: =AD8 -> 45325 | AE42: =AE8 -> 45416 | AF42: =AF8 -> 45507 | AG42: =AG8 -> 45598 | ... AK42: =AK8 -> 45962
B44: Current Assets
B45: Cash and cash equivalents | C45: 392325 | D45: 1046051 | E45: 431560 | F45: 737877 | G45: 766594 | H45: 703201 | J45: 654486 | K45: 434226 | L45: 250628 | M45: =F45 -> 737877 | N45: 636449 | O45: 388627 | P45: 121811 | Q45: =G45 -> 766594 | R45: 524596 | S45: 413962 | T45: 177782 | U45: =H45 -> 703201 | V45: 454629 | W45: 242745 | X45: 204921 | Z45: =M45 -> 737877 | AA45: =N45 -> 636449 | AB45: =O45 -> 388627 | AC45: =P45 -> 121811 | AD45: =Q45 -> 766594 | AE45: =R45 -> 524596 | AF45: =S45 -> 413962 | AG45: =T45 -> 177782 | ... AK45: =X45 -> 204921 | AM45: =SUM(AJ45/AF45)-1 -> -0.4136056
B46: Receivables, net | C46: 139337 | D46: 193109 | E46: 233682 | F46: 199422 | G46: 207939 | H46: 223334 | J46: 192754 | K46: 180514 | L46: 200304 | M46: =F46 -> 199422 | N46: 190282 | O46: 174444 | P46: 202868 | Q46: =G46 -> 207939 | R46: 203463 | S46: 200863 | T46: 213621 | U46: =H46 -> 223334 | V46: 225146 | W46: 224412 | X46: 237352 | Z46: =M46 -> 199422 | AA46: =N46 -> 190282 | AB46: =O46 -> 174444 | AC46: =P46 -> 202868 | AD46: =Q46 -> 207939 | AE46: =R46 -> 203463 | AF46: =S46 -> 200863 | AG46: =T46 -> 213621 | ... AK46: =X46 -> 237352 | AM46: =SUM(AJ46/AF46)-1 -> 0.11723911
B47: Merchandise inventories, net | C47: 1293701 | D47: 1168215 | E47: 1499218 | F47: 1603451 | G47: 1742136 | H47: 1968214 | J47: 1570552 | K47: 1666130 | L47: 2114669 | M47: =F47 -> 1603451 | N47: 1751235 | O47: 1815539 | P47: 2321306 | Q47: =G47 -> 1742136 | R47: 1906040 | S47: 1998286 | T47: 2365186 | U47: =H47 -> 1968214 | V47: 2121519 | W47: 2407051 | X47: 2743639 | Z47: =M47 -> 1603451 | AA47: =N47 -> 1751235 | AB47: =O47 -> 1815539 | AC47: =P47 -> 2321306 | AD47: =Q47 -> 1742136 | AE47: =R47 -> 1906040 | AF47: =S47 -> 1998286 | AG47: =T47 -> 2365186 | ... AK47: =X47 -> 2743639 | AM47: =SUM(AJ47/AF47)-1 -> 0.20455781
B48: Prepaid expenses and other current assets | C48: =103567+16387+110000 -> 229954 | D48: 107402 | E48: =110814+5909 -> 116723 | F48: =130246+38308 -> 168554 | G48: =115598+4251 -> 119849 | H48: =129113+4946 -> 134059 | J48: 114075 | K48: =123014+39029 -> 162043 | L48: =137642+42572 -> 180214 | M48: =F48 -> 168554 | N48: 108014 | O48: =110524+30114 -> 140638 | P48: =117282+28773 -> 146055 | Q48: =G48 -> 119849 | R48: 126529 | S48: =132023+53607 -> 185630 | T48: =135514+62759 -> 198273 | U48: =H48 -> 134059 | V48: 138396 | W48: =165963+28877 -> 194840 | X48: =158394+26465 -> 184859 | Z48: =M48 -> 168554 | AA48: =N48 -> 108014 | AB48: =O48 -> 140638 | AC48: =P48 -> 146055 | AD48: =Q48 -> 119849 | AE48: =R48 -> 126529 | AF48: =S48 -> 185630 | AG48: =T48 -> 198273 | ... AK48: =X48 -> 184859 | AM48: =SUM(AJ48/AF48)-1 -> 0.049614825
B49: Total Current Assets | C49: =SUM(C45:C48) -> 2055317 | D49: =SUM(D45:D48) -> 2514777 | E49: =SUM(E45:E48) -> 2281183 | F49: =SUM(F45:F48) -> 2709304 | G49: =SUM(G45:G48) -> 2836518 | H49: =SUM(H45:H48) -> 3028808 | J49: =SUM(J45:J48) -> 2531867 | K49: =SUM(K45:K48) -> 2442913 | L49: =SUM(L45:L48) -> 2745815 | M49: =SUM(M45:M48) -> 2709304 | N49: =SUM(N45:N48) -> 2685980 | O49: =SUM(O45:O48) -> 2519248 | P49: =SUM(P45:P48) -> 2792040 | Q49: =SUM(Q45:Q48) -> 2836518 | ... X49: =SUM(X45:X48) -> 3370771 | Z49: =SUM(Z45:Z48) -> 2709304 | AA49: =SUM(AA45:AA48) -> 2685980 | AB49: =SUM(AB45:AB48) -> 2519248 | AC49: =SUM(AC45:AC48) -> 2792040 | AD49: =SUM(AD45:AD48) -> 2836518 | AE49: =SUM(AE45:AE48) -> 2760628 | AF49: =SUM(AF45:AF48) -> 2798741 | AG49: =SUM(AG45:AG48) -> 2954862 | ... AK49: =SUM(AK45:AK48) -> 3370771 | AM49: =SUM(AJ49/AF49)-1 -> 0.096581642
B51: Non-Current Assets
B52: Property and equipment, net | C52: 1205524 | D52: 995795 | E52: 914476 | F52: 1009273 | G52: 1182335 | H52: 1239295 | J52: 909543 | K52: 912017 | L52: 967039 | M52: =F52 -> 1009273 | N52: 1019978 | O52: 1073144 | P52: 1117874 | Q52: =G52 -> 1182335 | R52: 1195658 | S52: 1225850 | T52: 1264419 | U52: =H52 -> 1239295 | V52: 1251287 | W52: 1332503 | X52: 1366504 | Z52: =M52 -> 1009273 | AA52: =N52 -> 1019978 | AB52: =O52 -> 1073144 | AC52: =P52 -> 1117874 | AD52: =Q52 -> 1182335 | AE52: =R52 -> 1195658 | AF52: =S52 -> 1225850 | AG52: =T52 -> 1264419 | ... AK52: =X52 -> 1366504 | AM52: =SUM(AJ52/AF52)-1 -> 0.087003304
B53: Operating lease assets | C53: 1537565 | D53: 1504614 | E53: 1482256 | F53: 1561263 | G53: 1574530 | H53: 1609870 | J53: 1488040 | K53: 1509246 | L53: 1556940 | M53: =F53 -> 1561263 | N53: 1559560 | O53: 1549146 | P53: 1578316 | Q53: =G53 -> 1574530 | R53: 1561767 | S53: 1599735 | T53: 1619055 | U53: =H53 -> 1609870 | V53: 1658834 | W53: 1682151 | X53: 1710804 | Z53: =M53 -> 1561263 | AA53: =N53 -> 1559560 | AB53: =O53 -> 1549146 | AC53: =P53 -> 1578316 | AD53: =Q53 -> 1574530 | AE53: =R53 -> 1561767 | AF53: =S53 -> 1599735 | AG53: =T53 -> 1619055 | ... AK53: =X53 -> 1710804 | AM53: =SUM(AJ53/AF53)-1 -> 0.051518533
...

Sheet Revenue Drivers
B2: Ulta Beauty Inc. (NASDAQ: ULTA) | C2: FYE | F2: FYE | J2: Quarterly | T2: Quarterly | AE2: LTM
B3: Segment Anaysis | C3: ='Historical Financials'!C7 -> 2019 | D3: ='Historical Financials'!D7 -> 2020 | E3: ='Historical Financials'!E7 -> 2021 | F3: ='Historical Financials'!F7 -> 2022 | G3: ='Historical Financials'!G7 -> 2023 | H3: ='Historical Financials'!H7 -> 2024 | J3: ='Historical Financials'!J7 -> 1Q22 | K3: ='Historical Financials'!K7 -> 2Q22 | L3: ='Historical Financials'!L7 -> 3Q22 | M3: ='Historical Financials'!M7 -> 4Q22 | N3: ='Historical Financials'!N7 -> 1Q23 | O3: ='Historical Financials'!O7 -> 2Q23 | P3: ='Historical Financials'!P7 -> 3Q23 | Q3: ='Historical Financials'!Q7 -> 4Q23 | ... X3: ='Historical Financials'!X7 -> 3Q25 | Z3: =O3 -> 2Q23 | AA3: =P3 -> 3Q23 | AB3: =Q3 -> 4Q23 | AC3: =R3 -> 1Q24 | AD3: =S3 -> 2Q24 | AE3: =T3 -> 3Q24 | AF3: =U3 -> 4Q24 | AG3: =V3 -> 1Q25 | ... AI3: =X3 -> 3Q25
B4: ($ In Thousands) | C4: ='Historical Financials'!C8 -> 43862 | D4: ='Historical Financials'!D8 -> 44226 | E4: ='Historical Financials'!E8 -> 44590 | F4: ='Historical Financials'!F8 -> 44954 | G4: ='Historical Financials'!G8 -> 45325 | H4: ='Historical Financials'!H8 -> 45689 | J4: ='Historical Financials'!J8 -> 44681 | K4: ='Historical Financials'!K8 -> 44772 | L4: ='Historical Financials'!L8 -> 44863 | M4: ='Historical Financials'!M8 -> 44954 | N4: ='Historical Financials'!N8 -> 45045 | O4: ='Historical Financials'!O8 -> 45136 | P4: ='Historical Financials'!P8 -> 45227 | Q4: ='Historical Financials'!Q8 -> 45325 | ... X4: ='Historical Financials'!X8 -> 45962 | Z4: =O4 -> 45136 | AA4: =P4 -> 45227 | AB4: =Q4 -> 45325 | AC4: =R4 -> 45416 | AD4: =S4 -> 45507 | AE4: =T4 -> 45598 | AF4: =U4 -> 45689 | AG4: =V4 -> 45780 | ... AI4: =X4 -> 45962
A6: X | B6: Revenue Segment Anaysis
B7: Cosmetics | C7: =C16*'Historical Financials'!$C$10 -> 3773014.7 | D7: =D16*'Historical Financials'!$D$10 -> 2768378.9 | E7: =E16*'Historical Financials'!$E$10 -> 3711282.3 | F7: =F16*'Historical Financials'!$F$10 -> 4287603.6 | G7: =G16*'Historical Financials'!$G$10 -> 4594994.2 | H7: =H16*'Historical Financials'!$H$10 -> 4405305.1 | J7: =J16*'Historical Financials'!$J$10 -> 1032196.4 | K7: =K16*'Historical Financials'!$K$10 -> 964787.46 | L7: =L16*'Historical Financials'!$L$10 -> 1029068.9 | M7: =M16*'Historical Financials'!$M$10 -> 1355244.7 | N7: =N16*'Historical Financials'!$N$10 -> 1159075.7 | O7: =O16*'Historical Financials'!$O$10 -> 1011923.6 | P7: =P16*'Historical Financials'!$P$10 -> 1045351.9 | Q7: =Q16*'Historical Financials'!$Q$10 -> 1457262.2 | R7: =R16*'Historical Financials'!$R$10 -> 1144856.2 | S7: =S16*'Historical Financials'!$S$10 -> 995313.93 | T7: =T16*'Historical Financials'!$T$10 -> 1037341 | U7: =U16*'Historical Financials'!$U$10 -> 1360171.4 | V7: =V16*'Historical Financials'!$V$10 -> 1139346.8 | W7: =W16*'Historical Financials'!$W$10 -> 1059618.2 | X7: =X16*'Historical Financials'!$X$10 -> 1171625.4 | Z7: =SUM(L7:O7) -> 4555312.9 | AA7: =SUM(M7:P7) -> 4571595.8 | AB7: =SUM(N7:Q7) -> 4673613.4 | AC7: =SUM(O7:R7) -> 4659393.8 | AD7: =SUM(P7:S7) -> 4642784.1 | AE7: =SUM(Q7:T7) -> 4634773.3 | AF7: =SUM(R7:U7) -> 4537682.5 | AG7: =SUM(S7:V7) -> 4532173.1 | ... AI7: =SUM(U7:X7) -> 4730761.9
B8: Haircare products and styling tools | C8: =C17*'Historical Financials'!$C$10 -> 1331652.2 | D8: =D17*'Historical Financials'!$D$10 -> 1230390.6 | E8: =E17*'Historical Financials'!$E$10 -> 1726177.8 | F8: =F17*'Historical Financials'!$F$10 -> 2143801.8 | G8: =G17*'Historical Financials'!$G$10 -> 2129387.6 | H8: =H17*'Historical Financials'!$H$10 -> 2598000.4 | J8: =J17*'Historical Financials'!$J$10 -> 469180.2 | K8: =K17*'Historical Financials'!$K$10 -> 505364.86 | L8: =L17*'Historical Financials'!$L$10 -> 491146.53 | M8: =M17*'Historical Financials'!$M$10 -> 677622.33 | N8: =N17*'Historical Financials'!$N$10 -> 474167.34 | O8: =O17*'Historical Financials'!$O$10 -> 531259.89 | P8: =P17*'Historical Financials'!$P$10 -> 472897.27 | Q8: =Q17*'Historical Financials'!$Q$10 -> 675316.62 | R8: =R17*'Historical Financials'!$R$10 -> 517911.12 | S8: =S17*'Historical Financials'!$S$10 -> 510417.4 | T8: =T17*'Historical Financials'!$T$10 -> 506020 | U8: =U17*'Historical Financials'!$U$10 -> 802152.37 | V8: =V17*'Historical Financials'!$V$10 -> 712091.75 | W8: =W17*'Historical Financials'!$W$10 -> 697117.25 | X8: =X17*'Historical Financials'!$X$10 -> 542948.37 | Z8: =SUM(L8:O8) -> 2174196.1 | AA8: =SUM(M8:P8) -> 2155946.8 | AB8: =SUM(N8:Q8) -> 2153641.1 | AC8: =SUM(O8:R8) -> 2197384.9 | AD8: =SUM(P8:S8) -> 2176542.4 | AE8: =SUM(Q8:T8) -> 2209665.1 | AF8: =SUM(R8:U8) -> 2336500.9 | AG8: =SUM(S8:V8) -> 2530681.5 | ... AI8: =SUM(U8:X8) -> 2754309.7
B9: Skincare | C9: =C18*'Historical Financials'!$C$10 -> 1035729.5 | D9: =D18*'Historical Financials'!$D$10 -> 984312.48 | E9: =E18*'Historical Financials'!$E$10 -> 1467251.1 | F9: =F18*'Historical Financials'!$F$10 -> 1735458.6 | G9: =G18*'Historical Financials'!$G$10 -> 2129387.6 | H9: =H18*'Historical Financials'!$H$10 -> 2146174.3 | J9: =J18*'Historical Financials'!$J$10 -> 422262.18 | K9: =K18*'Historical Financials'!$K$10 -> 390509.21 | L9: =L18*'Historical Financials'!$L$10 -> 374206.88 | M9: =M18*'Historical Financials'!$M$10 -> 548551.41 | N9: =N18*'Historical Financials'!$N$10 -> 500509.97 | O9: =O18*'Historical Financials'!$O$10 -> 505961.8 | P9: =P18*'Historical Financials'!$P$10 -> 472897.27 | Q9: =Q18*'Historical Financials'!$Q$10 -> 675316.62 | R9: =R18*'Historical Financials'!$R$10 -> 626945.04 | S9: =S18*'Historical Financials'!$S$10 -> 612500.88 | T9: =T18*'Historical Financials'!$T$10 -> 581923 | U9: =U18*'Historical Financials'!$U$10 -> 662647.61 | V9: =V18*'Historical Financials'!$V$10 -> 512706.06 | W9: =W18*'Historical Financials'!$W$10 -> 529809.11 | X9: =X18*'Historical Financials'!$X$10 -> 685829.52 | Z9: =SUM(L9:O9) -> 1929230.1 | AA9: =SUM(M9:P9) -> 2027920.5 | AB9: =SUM(N9:Q9) -> 2154685.7 | AC9: =SUM(O9:R9) -> 2281120.7 | AD9: =SUM(P9:S9) -> 2387659.8 | AE9: =SUM(Q9:T9) -> 2496685.5 | AF9: =SUM(R9:U9) -> 2484016.5 | AG9: =SUM(S9:V9) -> 2369777.5 | ... AI9: =SUM(U9:X9) -> 2390992.3
B10: Fragrance and bath | C10: =C19*'Historical Financials'!$C$10 -> 665826.12 | D10: =D19*'Historical Financials'!$D$10 -> 738234.36 | E10: =E19*'Historical Financials'!$E$10 -> 1208324.5 | F10: =F19*'Historical Financials'!$F$10 -> 1429201.2 | G10: =G19*'Historical Financials'!$G$10 -> 1681095.4 | H10: =H19*'Historical Financials'!$H$10 -> 1468435 | J10: =J19*'Historical Financials'!$J$10 -> 281508.12 | K10: =K19*'Historical Financials'!$K$10 -> 275653.56 | L10: =L19*'Historical Financials'!$L$10 -> 280655.16 | M10: =M19*'Historical Financials'!$M$10 -> 451748.22 | N10: =N19*'Historical Financials'!$N$10 -> 316111.56 | O10: =O19*'Historical Financials'!$O$10 -> 303577.08 | P10: =P19*'Historical Financials'!$P$10 -> 323561.29 | Q10: =Q19*'Historical Financials'!$Q$10 -> 533144.7 | R10: =R19*'Historical Financials'!$R$10 -> 272584.8 | S10: =S19*'Historical Financials'!$S$10 -> 280729.57 | T10: =T19*'Historical Financials'!$T$10 -> 253010 | U10: =U19*'Historical Financials'!$U$10 -> 453390.47 | V10: =V19*'Historical Financials'!$V$10 -> 313320.37 | W10: =W19*'Historical Financials'!$W$10 -> 334616.28 | X10: =X19*'Historical Financials'!$X$10 -> 314338.53 | Z10: =SUM(L10:O10) -> 1352092 | AA10: =SUM(M10:P10) -> 1394998.2 | AB10: =SUM(N10:Q10) -> 1476394.6 | AC10: =SUM(O10:R10) -> 1432867.9 | AD10: =SUM(P10:S10) -> 1410020.4 | AE10: =SUM(Q10:T10) -> 1339469.1 | AF10: =SUM(R10:U10) -> 1259714.8 | AG10: =SUM(S10:V10) -> 1300450.4 | ... AI10: =SUM(U10:X10) -> 1415665.7
B11: Services | C11: =C20*'Historical Financials'!$C$10 -> 369903.4 | D11: =D20*'Historical Financials'!$D$10 -> 184558.59 | E11: =E20*'Historical Financials'!$E$10 -> 258926.67 | F11: =F20*'Historical Financials'!$F$10 -> 306257.4 | G11: =G20*'Historical Financials'!$G$10 -> 336219.09 | H11: =H20*'Historical Financials'!$H$10 -> 451826.16 | J11: =J20*'Historical Financials'!$J$10 -> 70377.03 | K11: =K20*'Historical Financials'!$K$10 -> 91884.52 | L11: =L20*'Historical Financials'!$L$10 -> 93551.72 | M11: =M20*'Historical Financials'!$M$10 -> 96803.19 | N11: =N20*'Historical Financials'!$N$10 -> 105370.52 | O11: =O20*'Historical Financials'!$O$10 -> 101192.36 | P11: =P20*'Historical Financials'!$P$10 -> 99557.32 | Q11: =Q20*'Historical Financials'!$Q$10 -> 106628.94 | R11: =R20*'Historical Financials'!$R$10 -> 109033.92 | S11: =S20*'Historical Financials'!$S$10 -> 102083.48 | T11: =T20*'Historical Financials'!$T$10 -> 101204 | U11: =U20*'Historical Financials'!$U$10 -> 139504.76 | V11: =V20*'Historical Financials'!$V$10 -> 113934.68 | W11: =W20*'Historical Financials'!$W$10 -> 111538.76 | X11: =X20*'Historical Financials'!$X$10 -> 85728.69 | Z11: =SUM(L11:O11) -> 396917.79 | AA11: =SUM(M11:P11) -> 402923.39 | AB11: =SUM(N11:Q11) -> 412749.14 | AC11: =SUM(O11:R11) -> 416412.54 | AD11: =SUM(P11:S11) -> 417303.66 | AE11: =SUM(Q11:T11) -> 418950.34 | AF11: =SUM(R11:U11) -> 451826.16 | AG11: =SUM(S11:V11) -> 456726.92 | ... AI11: =SUM(U11:X11) -> 450706.89
B12: Accessories and other | C12: =C21*'Historical Financials'!$C$10 -> 221942.04 | D12: =D21*'Historical Financials'!$D$10 -> 246078.12 | E12: =E21*'Historical Financials'!$E$10 -> 258926.67 | F12: =F21*'Historical Financials'!$F$10 -> 306257.4 | G12: =G21*'Historical Financials'!$G$10 -> 336219.09 | H12: =H21*'Historical Financials'!$H$10 -> 225913.08 | J12: =J21*'Historical Financials'!$J$10 -> 70377.03 | K12: =K21*'Historical Financials'!$K$10 -> 68913.39 | L12: =L21*'Historical Financials'!$L$10 -> 70163.79 | M12: =M21*'Historical Financials'!$M$10 -> 96803.19 | N12: =N21*'Historical Financials'!$N$10 -> 79027.89 | O12: =O21*'Historical Financials'!$O$10 -> 75894.27 | P12: =P21*'Historical Financials'!$P$10 -> 74667.99 | Q12: =Q21*'Historical Financials'!$Q$10 -> 106628.94 | R12: =R21*'Historical Financials'!$R$10 -> 54516.96 | S12: =S21*'Historical Financials'!$S$10 -> 51041.74 | T12: =T21*'Historical Financials'!$T$10 -> 50602 | U12: =U21*'Historical Financials'!$U$10 -> 69752.38 | V12: =V21*'Historical Financials'!$V$10 -> 56967.34 | W12: =W21*'Historical Financials'!$W$10 -> 55769.38 | X12: =X21*'Historical Financials'!$X$10 -> 57152.46 | Z12: =SUM(L12:O12) -> 321889.14 | AA12: =SUM(M12:P12) -> 326393.34 | AB12: =SUM(N12:Q12) -> 336219.09 | AC12: =SUM(O12:R12) -> 311708.16 | AD12: =SUM(P12:S12) -> 286855.63 | AE12: =SUM(Q12:T12) -> 262789.64 | AF12: =SUM(R12:U12) -> 225913.08 | AG12: =SUM(S12:V12) -> 228363.46 | ... AI12: =SUM(U12:X12) -> 239641.56
B13: Total Net Revenue | C13: =SUM(C7:C12) -> 7398068 | D13: =SUM(D7:D12) -> 6151953 | E13: =SUM(E7:E12) -> 8630889 | F13: =SUM(F7:F12) -> 10208580 | G13: =SUM(G7:G12) -> 11207303 | H13: =SUM(H7:H12) -> 11295654 | J13: =SUM(J7:J12) -> 2345901 | K13: =SUM(K7:K12) -> 2297113 | L13: =SUM(L7:L12) -> 2338793 | M13: =SUM(M7:M12) -> 3226773 | N13: =SUM(N7:N12) -> 2634263 | O13: =SUM(O7:O12) -> 2529809 | P13: =SUM(P7:P12) -> 2488933 | Q13: =SUM(Q7:Q12) -> 3554298 | ... X13: =SUM(X7:X12) -> 2857623 | Z13: =SUM(Z7:Z12) -> 10729638 | AA13: =SUM(AA7:AA12) -> 10879778 | AB13: =SUM(AB7:AB12) -> 11207303 | AC13: =SUM(AC7:AC12) -> 11298888 | AD13: =SUM(AD7:AD12) -> 11321166 | AE13: =SUM(AE7:AE12) -> 11362333 | AF13: =SUM(AF7:AF12) -> 11295654 | AG13: =SUM(AG7:AG12) -> 11418173 | ... AI13: =SUM(AI7:AI12) -> 11982078
B14: Balance Check | C14: =C13-'Historical Financials'!C11 -> 0 | D14: =D13-'Historical Financials'!D11 -> 0 | E14: =E13-'Historical Financials'!E11 -> 0 | F14: =F13-'Historical Financials'!F11 -> 0 | G14: =G13-'Historical Financials'!G11 -> 0 | H14: =H13-'Historical Financials'!H11 -> 0 | J14: =J13-'Historical Financials'!J11 -> 0 | K14: =K13-'Historical Financials'!K11 -> 0 | L14: =L13-'Historical Financials'!L11 -> 0 | M14: =M13-'Historical Financials'!M11 -> 0 | N14: =N13-'Historical Financials'!N11 -> 0 | O14: =O13-'Historical Financials'!O11 -> 0 | P14: =P13-'Historical Financials'!P11 -> 0 | Q14: =Q13-'Historical Financials'!Q11 -> 0 | ... X14: =X13-'Historical Financials'!X11 -> 0 | Z14: =Z13-'Historical Financials'!AB11 -> 0 | AA14: =AA13-'Historical Financials'!AC11 -> 0 | AB14: =AB13-'Historical Financials'!AD11 -> 0 | AC14: =AC13-'Historical Financials'!AE11 -> 0 | AD14: =AD13-'Historical Financials'!AF11 -> 0 | AE14: =AE13-'Historical Financials'!AG11 -> 0 | AF14: =AF13-'Historical Financials'!AH11 -> 0 | AG14: =AG13-'Historical Financials'!AI11 -> 0 | ... AI14: =AI13-'Historical Financials'!AK11 -> 0
B16: =B7&"(%)" -> Cosmetics(%) | C16: 0.51 | D16: 0.45 | E16: 0.43 | F16: 0.42 | G16: 0.41 | H16: 0.39 | J16: 0.44 | K16: 0.42 | L16: 0.44 | M16: =F16 -> 0.42 | N16: 0.44 | O16: 0.4 | P16: 0.42 | Q16: =G16 -> 0.41 | R16: 0.42 | S16: 0.39 | T16: 0.41 | U16: =H16 -> 0.39 | V16: 0.4 | W16: 0.38 | X16: 0.41 | Z16: =O16 -> 0.4 | AA16: =P16 -> 0.42 | AB16: =Q16 -> 0.41 | AC16: =R16 -> 0.42 | AD16: =S16 -> 0.39 | AE16: =T16 -> 0.41 | AF16: =U16 -> 0.39 | AG16: =V16 -> 0.4 | ... AI16: =X16 -> 0.41
B17: =B8&"(%)" -> Haircare products and styling tools(%) | C17: 0.18 | D17: 0.2 | E17: 0.2 | F17: 0.21 | G17: 0.19 | H17: 0.23 | J17: 0.2 | K17: 0.22 | L17: 0.21 | M17: =F17 -> 0.21 | N17: 0.18 | O17: 0.21 | P17: 0.19 | Q17: =G17 -> 0.19 | R17: 0.19 | S17: 0.2 | T17: 0.2 | U17: =H17 -> 0.23 | V17: 0.25 | W17: 0.25 | X17: 0.19 | Z17: =O17 -> 0.21 | AA17: =P17 -> 0.19 | AB17: =Q17 -> 0.19 | AC17: =R17 -> 0.19 | AD17: =S17 -> 0.2 | AE17: =T17 -> 0.2 | AF17: =U17 -> 0.23 | AG17: =V17 -> 0.25 | ... AI17: =X17 -> 0.19
B18: =B9&"(%)" -> Skincare(%) | C18: 0.14 | D18: 0.16 | E18: 0.17 | F18: 0.17 | G18: 0.19 | H18: 0.19 | J18: 0.18 | K18: 0.17 | L18: 0.16 | M18: =F18 -> 0.17 | N18: 0.19 | O18: 0.2 | P18: 0.19 | Q18: =G18 -> 0.19 | R18: 0.23 | S18: 0.24 | T18: 0.23 | U18: =H18 -> 0.19 | V18: 0.18 | W18: 0.19 | X18: 0.24 | Z18: =O18 -> 0.2 | AA18: =P18 -> 0.19 | AB18: =Q18 -> 0.19 | AC18: =R18 -> 0.23 | AD18: =S18 -> 0.24 | AE18: =T18 -> 0.23 | AF18: =U18 -> 0.19 | AG18: =V18 -> 0.18 | ... AI18: =X18 -> 0.24
B19: =B10&"(%)" -> Fragrance and bath(%) | C19: 0.09 | D19: 0.12 | E19: 0.14 | F19: 0.14 | G19: 0.15 | H19: 0.13 | J19: 0.12 | K19: 0.12 | L19: 0.12 | M19: =F19 -> 0.14 | N19: 0.12 | O19: 0.12 | P19: 0.13 | Q19: =G19 -> 0.15 | R19: 0.1 | S19: 0.11 | T19: 0.1 | U19: =H19 -> 0.13 | V19: 0.11 | W19: 0.12 | X19: 0.11 | Z19: =O19 -> 0.12 | AA19: =P19 -> 0.13 | AB19: =Q19 -> 0.15 | AC19: =R19 -> 0.1 | AD19: =S19 -> 0.11 | AE19: =T19 -> 0.1 | AF19: =U19 -> 0.13 | AG19: =V19 -> 0.11 | ... AI19: =X19 -> 0.11
B20: =B11&"(%)" -> Services(%) | C20: 0.05 | D20: 0.03 | E20: 0.03 | F20: 0.03 | G20: 0.03 | H20: 0.04 | J20: 0.03 | K20: 0.04 | L20: 0.04 | M20: =F20 -> 0.03 | N20: 0.04 | O20: 0.04 | P20: 0.04 | Q20: =G20 -> 0.03 | R20: 0.04 | S20: 0.04 | T20: 0.04 | U20: =H20 -> 0.04 | V20: 0.04 | W20: 0.04 | X20: 0.03 | Z20: =O20 -> 0.04 | AA20: =P20 -> 0.04 | AB20: =Q20 -> 0.03 | AC20: =R20 -> 0.04 | AD20: =S20 -> 0.04 | AE20: =T20 -> 0.04 | AF20: =U20 -> 0.04 | AG20: =V20 -> 0.04 | ... AI20: =X20 -> 0.03
B21: =B12&"(%)" -> Accessories and other(%) | C21: 0.03 | D21: 0.04 | E21: 0.03 | F21: 0.03 | G21: 0.03 | H21: 0.02 | J21: 0.03 | K21: 0.03 | L21: 0.03 | M21: =F21 -> 0.03 | N21: 0.03 | O21: 0.03 | P21: 0.03 | Q21: =G21 -> 0.03 | R21: 0.02 | S21: 0.02 | T21: 0.02 | U21: =H21 -> 0.02 | V21: 0.02 | W21: 0.02 | X21: 0.02 | Z21: =O21 -> 0.03 | AA21: =P21 -> 0.03 | AB21: =Q21 -> 0.03 | AC21: =R21 -> 0.02 | AD21: =S21 -> 0.02 | AE21: =T21 -> 0.02 | AF21: =U21 -> 0.02 | AG21: =V21 -> 0.02 | ... AI21: =X21 -> 0.02

Sheet FCF
B2: ='Historical Financials'!B2 -> Ulta Beauty Inc. (NASDAQ: ULTA) | C2: FYE | F2: FYE | J2: Quarterly | N2: Quarterly | T2: Quarterly | Z2: LTM | AG2: LTM | AM2: Variance
B3: FCF Analysis | C3: ='Historical Financials'!C7 -> 2019 | D3: ='Historical Financials'!D7 -> 2020 | E3: ='Historical Financials'!E7 -> 2021 | F3: ='Historical Financials'!F7 -> 2022 | G3: ='Historical Financials'!G7 -> 2023 | H3: ='Historical Financials'!H7 -> 2024 | J3: ='Historical Financials'!J7 -> 1Q22 | K3: ='Historical Financials'!K7 -> 2Q22 | L3: ='Historical Financials'!L7 -> 3Q22 | M3: ='Historical Financials'!M7 -> 4Q22 | N3: ='Historical Financials'!N7 -> 1Q23 | O3: ='Historical Financials'!O7 -> 2Q23 | P3: ='Historical Financials'!P7 -> 3Q23 | Q3: ='Historical Financials'!Q7 -> 4Q23 | ... X3: ='Historical Financials'!X7 -> 3Q25 | Z3: =M3 -> 4Q22 | AA3: =N3 -> 1Q23 | AB3: =O3 -> 2Q23 | AC3: =P3 -> 3Q23 | AD3: =Q3 -> 4Q23 | AE3: =R3 -> 1Q24 | AF3: =S3 -> 2Q24 | AG3: =T3 -> 3Q24 | ... AK3: =X3 -> 3Q25
B4: ($ In Millions) | C4: ='Historical Financials'!C8 -> 43862 | D4: ='Historical Financials'!D8 -> 44226 | E4: ='Historical Financials'!E8 -> 44590 | F4: ='Historical Financials'!F8 -> 44954 | G4: ='Historical Financials'!G8 -> 45325 | H4: ='Historical Financials'!H8 -> 45689 | J4: ='Historical Financials'!J8 -> 44681 | K4: ='Historical Financials'!K8 -> 44772 | L4: ='Historical Financials'!L8 -> 44863 | M4: ='Historical Financials'!M8 -> 44954 | N4: ='Historical Financials'!N8 -> 45045 | O4: ='Historical Financials'!O8 -> 45136 | P4: ='Historical Financials'!P8 -> 45227 | Q4: ='Historical Financials'!Q8 -> 45325 | ... X4: ='Historical Financials'!X8 -> 45962 | Z4: =M4 -> 44954 | AA4: =N4 -> 45045 | AB4: =O4 -> 45136 | AC4: =P4 -> 45227 | AD4: =Q4 -> 45325 | AE4: =R4 -> 45416 | AF4: =S4 -> 45507 | AG4: =T4 -> 45598 | ... AK4: =X4 -> 45962
B6: ='Revenue Drivers'!B7 -> Cosmetics | C6: ='Revenue Drivers'!C7/1000 -> 3773.0147 | D6: ='Revenue Drivers'!D7/1000 -> 2768.3789 | E6: ='Revenue Drivers'!E7/1000 -> 3711.2823 | F6: ='Revenue Drivers'!F7/1000 -> 4287.6036 | G6: ='Revenue Drivers'!G7/1000 -> 4594.9942 | H6: ='Revenue Drivers'!H7/1000 -> 4405.3051 | J6: ='Revenue Drivers'!J7/1000 -> 1032.1964 | K6: ='Revenue Drivers'!K7/1000 -> 964.78746 | L6: ='Revenue Drivers'!L7/1000 -> 1029.0689 | M6: ='Revenue Drivers'!M7/1000 -> 1355.2447 | N6: ='Revenue Drivers'!N7/1000 -> 1159.0757 | O6: ='Revenue Drivers'!O7/1000 -> 1011.9236 | P6: ='Revenue Drivers'!P7/1000 -> 1045.3519 | Q6: ='Revenue Drivers'!Q7/1000 -> 1457.2622 | ... X6: ='Revenue Drivers'!X7/1000 -> 1171.6254 | Z6: =SUM(J6:M6) -> 4381.2975 | AA6: =SUM(K6:N6) -> 4508.1768 | AB6: =SUM(L6:O6) -> 4555.3129 | AC6: =SUM(M6:P6) -> 4571.5958 | AD6: =SUM(N6:Q6) -> 4673.6134 | AE6: =SUM(O6:R6) -> 4659.3938 | AF6: =SUM(P6:S6) -> 4642.7841 | AG6: =SUM(Q6:T6) -> 4634.7733 | ... AK6: =SUM(U6:X6) -> 4730.7619 | AM6: =SUM(AK6/AG6)-1 -> 0.020710526
B7: ='Revenue Drivers'!B8 -> Haircare products and styling tools | C7: ='Revenue Drivers'!C8/1000 -> 1331.6522 | D7: ='Revenue Drivers'!D8/1000 -> 1230.3906 | E7: ='Revenue Drivers'!E8/1000 -> 1726.1778 | F7: ='Revenue Drivers'!F8/1000 -> 2143.8018 | G7: ='Revenue Drivers'!G8/1000 -> 2129.3876 | H7: ='Revenue Drivers'!H8/1000 -> 2598.0004 | J7: ='Revenue Drivers'!J8/1000 -> 469.1802 | K7: ='Revenue Drivers'!K8/1000 -> 505.36486 | L7: ='Revenue Drivers'!L8/1000 -> 491.14653 | M7: ='Revenue Drivers'!M8/1000 -> 677.62233 | N7: ='Revenue Drivers'!N8/1000 -> 474.16734 | O7: ='Revenue Drivers'!O8/1000 -> 531.25989 | P7: ='Revenue Drivers'!P8/1000 -> 472.89727 | Q7: ='Revenue Drivers'!Q8/1000 -> 675.31662 | ... X7: ='Revenue Drivers'!X8/1000 -> 542.94837 | Z7: =SUM(J7:M7) -> 2143.3139 | AA7: =SUM(K7:N7) -> 2148.3011 | AB7: =SUM(L7:O7) -> 2174.1961 | AC7: =SUM(M7:P7) -> 2155.9468 | AD7: =SUM(N7:Q7) -> 2153.6411 | AE7: =SUM(O7:R7) -> 2197.3849 | AF7: =SUM(P7:S7) -> 2176.5424 | AG7: =SUM(Q7:T7) -> 2209.6651 | ... AK7: =SUM(U7:X7) -> 2754.3097 | AM7: =SUM(AK7/AG7)-1 -> 0.24648287
B8: ='Revenue Drivers'!B9 -> Skincare | C8: ='Revenue Drivers'!C9/1000 -> 1035.7295 | D8: ='Revenue Drivers'!D9/1000 -> 984.31248 | E8: ='Revenue Drivers'!E9/1000 -> 1467.2511 | F8: ='Revenue Drivers'!F9/1000 -> 1735.4586 | G8: ='Revenue Drivers'!G9/1000 -> 2129.3876 | H8: ='Revenue Drivers'!H9/1000 -> 2146.1743 | J8: ='Revenue Drivers'!J9/1000 -> 422.26218 | K8: ='Revenue Drivers'!K9/1000 -> 390.50921 | L8: ='Revenue Drivers'!L9/1000 -> 374.20688 | M8: ='Revenue Drivers'!M9/1000 -> 548.55141 | N8: ='Revenue Drivers'!N9/1000 -> 500.50997 | O8: ='Revenue Drivers'!O9/1000 -> 505.9618 | P8: ='Revenue Drivers'!P9/1000 -> 472.89727 | Q8: ='Revenue Drivers'!Q9/1000 -> 675.31662 | ... X8: ='Revenue Drivers'!X9/1000 -> 685.82952 | Z8: =SUM(J8:M8) -> 1735.5297 | AA8: =SUM(K8:N8) -> 1813.7775 | AB8: =SUM(L8:O8) -> 1929.2301 | AC8: =SUM(M8:P8) -> 2027.9205 | AD8: =SUM(N8:Q8) -> 2154.6857 | AE8: =SUM(O8:R8) -> 2281.1207 | AF8: =SUM(P8:S8) -> 2387.6598 | AG8: =SUM(Q8:T8) -> 2496.6855 | ... AK8: =SUM(U8:X8) -> 2390.9923 | AM8: =SUM(AK8/AG8)-1 -> -0.042333421
B9: ='Revenue Drivers'!B10 -> Fragrance and bath | C9: ='Revenue Drivers'!C10/1000 -> 665.82612 | D9: ='Revenue Drivers'!D10/1000 -> 738.23436 | E9: ='Revenue Drivers'!E10/1000 -> 1208.3245 | F9: ='Revenue Drivers'!F10/1000 -> 1429.2012 | G9: ='Revenue Drivers'!G10/1000 -> 1681.0954 | H9: ='Revenue Drivers'!H10/1000 -> 1468.435 | J9: ='Revenue Drivers'!J10/1000 -> 281.50812 | K9: ='Revenue Drivers'!K10/1000 -> 275.65356 | L9: ='Revenue Drivers'!L10/1000 -> 280.65516 | M9: ='Revenue Drivers'!M10/1000 -> 451.74822 | N9: ='Revenue Drivers'!N10/1000 -> 316.11156 | O9: ='Revenue Drivers'!O10/1000 -> 303.57708 | P9: ='Revenue Drivers'!P10/1000 -> 323.56129 | Q9: ='Revenue Drivers'!Q10/1000 -> 533.1447 | ... X9: ='Revenue Drivers'!X10/1000 -> 314.33853 | Z9: =SUM(J9:M9) -> 1289.5651 | AA9: =SUM(K9:N9) -> 1324.1685 | AB9: =SUM(L9:O9) -> 1352.092 | AC9: =SUM(M9:P9) -> 1394.9982 | AD9: =SUM(N9:Q9) -> 1476.3946 | AE9: =SUM(O9:R9) -> 1432.8679 | AF9: =SUM(P9:S9) -> 1410.0204 | AG9: =SUM(Q9:T9) -> 1339.4691 | ... AK9: =SUM(U9:X9) -> 1415.6656 | AM9: =SUM(AK9/AG9)-1 -> 0.056885658
B10: ='Revenue Drivers'!B11 -> Services | C10: ='Revenue Drivers'!C11/1000 -> 369.9034 | D10: ='Revenue Drivers'!D11/1000 -> 184.55859 | E10: ='Revenue Drivers'!E11/1000 -> 258.92667 | F10: ='Revenue Drivers'!F11/1000 -> 306.2574 | G10: ='Revenue Drivers'!G11/1000 -> 336.21909 | H10: ='Revenue Drivers'!H11/1000 -> 451.82616 | J10: ='Revenue Drivers'!J11/1000 -> 70.37703 | K10: ='Revenue Drivers'!K11/1000 -> 91.88452 | L10: ='Revenue Drivers'!L11/1000 -> 93.55172 | M10: ='Revenue Drivers'!M11/1000 -> 96.80319 | N10: ='Revenue Drivers'!N11/1000 -> 105.37052 | O10: ='Revenue Drivers'!O11/1000 -> 101.19236 | P10: ='Revenue Drivers'!P11/1000 -> 99.55732 | Q10: ='Revenue Drivers'!Q11/1000 -> 106.62894 | ... X10: ='Revenue Drivers'!X11/1000 -> 85.72869 | Z10: =SUM(J10:M10) -> 352.61646 | AA10: =SUM(K10:N10) -> 387.60995 | AB10: =SUM(L10:O10) -> 396.91779 | AC10: =SUM(M10:P10) -> 402.92339 | AD10: =SUM(N10:Q10) -> 412.74914 | AE10: =SUM(O10:R10) -> 416.41254 | AF10: =SUM(P10:S10) -> 417.30366 | AG10: =SUM(Q10:T10) -> 418.95034 | ... AK10: =SUM(U10:X10) -> 450.70689 | AM10: =SUM(AK10/AG10)-1 -> 0.075800273
B11: ='Revenue Drivers'!B12 -> Accessories and other | C11: ='Revenue Drivers'!C12/1000 -> 221.94204 | D11: ='Revenue Drivers'!D12/1000 -> 246.07812 | E11: ='Revenue Drivers'!E12/1000 -> 258.92667 | F11: ='Revenue Drivers'!F12/1000 -> 306.2574 | G11: ='Revenue Drivers'!G12/1000 -> 336.21909 | H11: ='Revenue Drivers'!H12/1000 -> 225.91308 | J11: ='Revenue Drivers'!J12/1000 -> 70.37703 | K11: ='Revenue Drivers'!K12/1000 -> 68.91339 | L11: ='Revenue Drivers'!L12/1000 -> 70.16379 | M11: ='Revenue Drivers'!M12/1000 -> 96.80319 | N11: ='Revenue Drivers'!N12/1000 -> 79.02789 | O11: ='Revenue Drivers'!O12/1000 -> 75.89427 | P11: ='Revenue Drivers'!P12/1000 -> 74.66799 | Q11: ='Revenue Drivers'!Q12/1000 -> 106.62894 | ... X11: ='Revenue Drivers'!X12/1000 -> 57.15246 | Z11: =SUM(J11:M11) -> 306.2574 | AA11: =SUM(K11:N11) -> 314.90826 | AB11: =SUM(L11:O11) -> 321.88914 | AC11: =SUM(M11:P11) -> 326.39334 | AD11: =SUM(N11:Q11) -> 336.21909 | AE11: =SUM(O11:R11) -> 311.70816 | AF11: =SUM(P11:S11) -> 286.85563 | AG11: =SUM(Q11:T11) -> 262.78964 | ... AK11: =SUM(U11:X11) -> 239.64156 | AM11: =SUM(AK11/AG11)-1 -> -0.088085969
B12: Total Revenue | C12: =SUM(C6:C11) -> 7398.068 | D12: =SUM(D6:D11) -> 6151.953 | E12: =SUM(E6:E11) -> 8630.889 | F12: =SUM(F6:F11) -> 10208.58 | G12: =SUM(G6:G11) -> 11207.303 | H12: =SUM(H6:H11) -> 11295.654 | J12: =SUM(J6:J11) -> 2345.901 | K12: =SUM(K6:K11) -> 2297.113 | L12: =SUM(L6:L11) -> 2338.793 | M12: =SUM(M6:M11) -> 3226.773 | N12: =SUM(N6:N11) -> 2634.263 | O12: =SUM(O6:O11) -> 2529.809 | P12: =SUM(P6:P11) -> 2488.933 | Q12: =SUM(Q6:Q11) -> 3554.298 | ... X12: =SUM(X6:X11) -> 2857.623 | Z12: =SUM(Z6:Z11) -> 10208.58 | AA12: =SUM(AA6:AA11) -> 10496.942 | AB12: =SUM(AB6:AB11) -> 10729.638 | AC12: =SUM(AC6:AC11) -> 10879.778 | AD12: =SUM(AD6:AD11) -> 11207.303 | AE12: =SUM(AE6:AE11) -> 11298.888 | AF12: =SUM(AF6:AF11) -> 11321.166 | AG12: =SUM(AG6:AG11) -> 11362.333 | ... AK12: =SUM(AK6:AK11) -> 11982.078 | AM12: =SUM(AK12/AG12)-1 -> 0.054543816
B13: Y/Y Growth (%) | D13: =SUM(D12/C12)-1 -> -0.16843789 | E13: =SUM(E12/D12)-1 -> 0.40295106 | F13: =SUM(F12/E12)-1 -> 0.18279589 | G13: =SUM(G12/F12)-1 -> 0.097831726 | H13: =SUM(H12/G12)-1 -> 0.0078833418 | N13: =SUM(N12/J12)-1 -> 0.12292164 | O13: =SUM(O12/K12)-1 -> 0.10129933 | P13: =SUM(P12/L12)-1 -> 0.064195506 | Q13: =SUM(Q12/M12)-1 -> 0.10150234 | R13: =SUM(R12/N12)-1 -> 0.03476684 | S13: =SUM(S12/O12)-1 -> 0.0088061984 | T13: =SUM(T12/P12)-1 -> 0.016540019 | U13: =SUM(U12/Q12)-1 -> -0.018760104 | ... X13: =SUM(X12/T12)-1 -> 0.12945061 | Z13: =SUM(Z12/W12)-1 -> 2.6609982 | AA13: =SUM(AA12/X12)-1 -> 2.6733124 | AB13: =SUM(AB12/Y12)-1 -> #DIV/0! | AC13: =SUM(AC12/#REF!)-1 -> #REF! | AD13: =SUM(AD12/Z12)-1 -> 0.097831726 | AE13: =SUM(AE12/AA12)-1 -> 0.07639806 | AF13: =SUM(AF12/AB12)-1 -> 0.055130285 | AG13: =SUM(AG12/AC12)-1 -> 0.044353387 | AH13: =SUM(AH12/AD12)-1 -> 0.0078833418 | AI13: =SUM(AI12/AE12)-1 -> 0.010557234 | AJ13: =SUM(AJ12/AF12)-1 -> 0.029448292 | AK13: =SUM(AK12/AG12)-1 -> 0.054543816 | AM13: =SUM(AK13-AG13)*10000 -> 101.90429
B14: Q/Q Growth (%) | C14: N/A | D14: N/A | E14: N/A | F14: N/A | G14: N/A | H14: N/A | K14: =SUM(K12/J12)-1 -> -0.020797127 | L14: =SUM(L12/K12)-1 -> 0.018144514 | M14: =SUM(M12/L12)-1 -> 0.37967447 | N14: =SUM(N12/M12)-1 -> -0.18362308 | O14: =SUM(O12/N12)-1 -> -0.039652077 | P14: =SUM(P12/O12)-1 -> -0.016157742 | Q14: =SUM(Q12/P12)-1 -> 0.42804085 | R14: =SUM(R12/Q12)-1 -> -0.233084 | ... X14: =SUM(X12/W12)-1 -> 0.024799989 | Z14: N/A | AA14: N/A | AB14: N/A | AC14: N/A | AD14: N/A | AE14: N/A | AF14: N/A | AG14: N/A | AH14: N/A | AI14: N/A | AJ14: N/A | AK14: N/A
B16: (-) Cost of Revenues | C16: ='Historical Financials'!C13/1000 -> -4717.004 | D16: ='Historical Financials'!D13/1000 -> -4202.794 | E16: ='Historical Financials'!E13/1000 -> -5262.335 | F16: ='Historical Financials'!F13/1000 -> -6164.07 | G16: ='Historical Financials'!G13/1000 -> -6826.203 | H16: ='Historical Financials'!H13/1000 -> -6908.401 | J16: ='Historical Financials'!J13/1000 -> -1404.875 | K16: ='Historical Financials'!K13/1000 -> -1368.949 | L16: ='Historical Financials'!L13/1000 -> -1375.976 | M16: ='Historical Financials'!M13/1000 -> -2014.27 | N16: ='Historical Financials'!N13/1000 -> -1579.406 | O16: ='Historical Financials'!O13/1000 -> -1536.197 | P16: ='Historical Financials'!P13/1000 -> -1496.866 | Q16: ='Historical Financials'!Q13/1000 -> -2213.734 | ... X16: ='Historical Financials'!X13/1000 -> -1701.958 | Z16: =SUM(J16:M16) -> -6164.07 | AA16: =SUM(K16:N16) -> -6338.601 | AB16: =SUM(L16:O16) -> -6505.849 | AC16: =SUM(M16:P16) -> -6626.739 | AD16: =SUM(N16:Q16) -> -6826.203 | AE16: =SUM(O16:R16) -> -6902.865 | AF16: =SUM(P16:S16) -> -6940.578 | AG16: =SUM(Q16:T16) -> -6968.168 | ... AK16: =SUM(U16:X16) -> -7286.846 | AM16: =SUM(AK16/AG16)-1 -> 0.045733398
B17: Gross Profit | C17: =SUM(C12+SUM(C16:C16)) -> 2681.064 | D17: =SUM(D12+SUM(D16:D16)) -> 1949.159 | E17: =SUM(E12+SUM(E16:E16)) -> 3368.554 | F17: =SUM(F12+SUM(F16:F16)) -> 4044.51 | G17: =SUM(G12+SUM(G16:G16)) -> 4381.1 | H17: =SUM(H12+SUM(H16:H16)) -> 4387.253 | J17: =SUM(J12+SUM(J16:J16)) -> 941.026 | K17: =SUM(K12+SUM(K16:K16)) -> 928.164 | L17: =SUM(L12+SUM(L16:L16)) -> 962.817 | M17: =SUM(M12+SUM(M16:M16)) -> 1212.503 | N17: =SUM(N12+SUM(N16:N16)) -> 1054.857 | O17: =SUM(O12+SUM(O16:O16)) -> 993.612 | P17: =SUM(P12+SUM(P16:P16)) -> 992.067 | Q17: =SUM(Q12+SUM(Q16:Q16)) -> 1340.564 | ... X17: =SUM(X12+SUM(X16:X16)) -> 1155.665 | Z17: =SUM(Z12+SUM(Z16:Z16)) -> 4044.51 | AA17: =SUM(AA12+SUM(AA16:AA16)) -> 4158.341 | AB17: =SUM(AB12+SUM(AB16:AB16)) -> 4223.789 | AC17: =SUM(AC12+SUM(AC16:AC16)) -> 4253.039 | AD17: =SUM(AD12+SUM(AD16:AD16)) -> 4381.1 | AE17: =SUM(AE12+SUM(AE16:AE16)) -> 4396.023 | AF17: =SUM(AF12+SUM(AF16:AF16)) -> 4380.588 | AG17: =SUM(AG12+SUM(AG16:AG16)) -> 4394.165 | ... AK17: =SUM(AK12+SUM(AK16:AK16)) -> 4695.232 | AM17: =SUM(AK17/AG17)-1 -> 0.068515179
B18: Gross Margin (%) | C18: =C17/C12 -> 0.36240056 | D18: =D17/D12 -> 0.31683581 | E18: =E17/E12 -> 0.3902905 | F18: =F17/F12 -> 0.39618732 | G18: =G17/G12 -> 0.39091475 | H18: =H17/H12 -> 0.38840186 | J18: =J17/J12 -> 0.40113628 | K18: =K17/K12 -> 0.40405674 | L18: =L17/L12 -> 0.4116726 | M18: =M17/M12 -> 0.37576334 | N18: =N17/N12 -> 0.40043724 | O18: =O17/O12 -> 0.39276167 | P18: =P17/P12 -> 0.39859128 | Q18: =Q17/Q12 -> 0.37716702 | ... X18: =X17/X12 -> 0.40441479 | Z18: =Z17/Z12 -> 0.39618732 | AA18: =AA17/AA12 -> 0.39614785 | AB18: =AB17/AB12 -> 0.39365624 | AC18: =AC17/AC12 -> 0.3909123 | AD18: =AD17/AD12 -> 0.39091475 | AE18: =AE17/AE12 -> 0.38906687 | AF18: =AF17/AF12 -> 0.38693788 | AG18: =AG17/AG12 -> 0.38673088 | ... AK18: =AK17/AK12 -> 0.39185457 | AM18: =SUM(AK18-AG18)*10000 -> 51.236916
B20: (-) Selling, general and administrative expenses | C20: ='Historical Financials'!C17/1000 -> -1760.716 | D20: ='Historical Financials'!D17/1000 -> -1583.017 | E20: ='Historical Financials'!E17/1000 -> -2061.545 | F20: ='Historical Financials'!F17/1000 -> -2395.299 | G20: ='Historical Financials'!G17/1000 -> -2694.561 | H20: ='Historical Financials'!H17/1000 -> -2808.592 | J20: ='Historical Financials'!J17/1000 -> -500.97 | K20: ='Historical Financials'!K17/1000 -> -534.459 | L20: ='Historical Financials'!L17/1000 -> -597.164 | M20: ='Historical Financials'!M17/1000 -> -762.706 | N20: ='Historical Financials'!N17/1000 -> -612.129 | O20: ='Historical Financials'!O17/1000 -> -600.692 | P20: ='Historical Financials'!P17/1000 -> -661.38 | Q20: ='Historical Financials'!Q17/1000 -> -820.36 | ... X20: ='Historical Financials'!X17/1000 -> -840.92 | Z20: =SUM(J20:M20) -> -2395.299 | AA20: =SUM(K20:N20) -> -2506.458 | AB20: =SUM(L20:O20) -> -2572.691 | AC20: =SUM(M20:P20) -> -2636.907 | AD20: =SUM(N20:Q20) -> -2694.561 | AE20: =SUM(O20:R20) -> -2748.345 | AF20: =SUM(P20:S20) -> -2792.474 | AG20: =SUM(Q20:T20) -> -2813.353 | ... AK20: =SUM(U20:X20) -> -3108.869 | AM20: =SUM(AK20/AG20)-1 -> 0.1050405
B21: (-) Pre-opening expenses | C21: ='Historical Financials'!C18/1000 -> -19.254 | D21: ='Historical Financials'!D18/1000 -> -15 | E21: ='Historical Financials'!E18/1000 -> -9.517 | F21: ='Historical Financials'!F18/1000 -> -10.601 | G21: ='Historical Financials'!G18/1000 -> -8.51 | H21: ='Historical Financials'!H18/1000 -> -13.689 | J21: ='Historical Financials'!J18/1000 -> -2.348 | K21: ='Historical Financials'!K18/1000 -> -2.277 | L21: ='Historical Financials'!L18/1000 -> -3.797 | M21: ='Historical Financials'!M18/1000 -> -2.179 | N21: ='Historical Financials'!N18/1000 -> -0.658 | O21: ='Historical Financials'!O18/1000 -> -1.278 | P21: ='Historical Financials'!P18/1000 -> -3.46 | Q21: ='Historical Financials'!Q18/1000 -> -3.114 | ... X21: ='Historical Financials'!X18/1000 -> -5.326 | Z21: =SUM(J21:M21) -> -10.601 | AA21: =SUM(K21:N21) -> -8.911 | AB21: =SUM(L21:O21) -> -7.912 | AC21: =SUM(M21:P21) -> -7.575 | AD21: =SUM(N21:Q21) -> -8.51 | AE21: =SUM(O21:R21) -> -10.771 | AF21: =SUM(P21:S21) -> -13.648 | AG21: =SUM(Q21:T21) -> -15.071 | ... AK21: =SUM(U21:X21) -> -13.992
B22: (-) Impairment, restructuring and other costs | C22: ='Historical Financials'!C19/1000 -> 0 | D22: ='Historical Financials'!D19/1000 -> -114.322 | E22: ='Historical Financials'!E19/1000 -> 0 | F22: ='Historical Financials'!F19/1000 -> 0 | G22: ='Historical Financials'!G19/1000 -> 0 | H22: ='Historical Financials'!H19/1000 -> 0 | J22: ='Historical Financials'!J19/1000 -> 0 | K22: ='Historical Financials'!K19/1000 -> 0 | L22: ='Historical Financials'!L19/1000 -> 0 | M22: ='Historical Financials'!M19/1000 -> 0 | N22: ='Historical Financials'!N19/1000 -> 0 | O22: ='Historical Financials'!O19/1000 -> 0 | P22: ='Historical Financials'!P19/1000 -> 0 | Q22: ='Historical Financials'!Q19/1000 -> 0 | ... X22: ='Historical Financials'!X19/1000 -> 0 | Z22: =SUM(J22:M22) -> 0 | AA22: =SUM(K22:N22) -> 0 | AB22: =SUM(L22:O22) -> 0 | AC22: =SUM(M22:P22) -> 0 | AD22: =SUM(N22:Q22) -> 0 | AE22: =SUM(O22:R22) -> 0 | AF22: =SUM(P22:S22) -> 0 | AG22: =SUM(Q22:T22) -> 0 | ... AK22: =SUM(U22:X22) -> 0 | AM22: =SUM(AK22/AG22)-1 -> #DIV/0!
B23: Earning before Interest & Taxes (EBIT) | C23: =SUM(C17+SUM(C20:C22)) -> 901.094 | D23: =SUM(D17+SUM(D20:D22)) -> 236.82 | E23: =SUM(E17+SUM(E20:E22)) -> 1297.492 | F23: =SUM(F17+SUM(F20:F22)) -> 1638.61 | G23: =SUM(G17+SUM(G20:G22)) -> 1678.029 | H23: =SUM(H17+SUM(H20:H22)) -> 1564.972 | J23: =SUM(J17+SUM(J20:J22)) -> 437.708 | K23: =SUM(K17+SUM(K20:K22)) -> 391.428 | L23: =SUM(L17+SUM(L20:L22)) -> 361.856 | M23: =SUM(M17+SUM(M20:M22)) -> 447.618 | N23: =SUM(N17+SUM(N20:N22)) -> 442.07 | O23: =SUM(O17+SUM(O20:O22)) -> 391.642 | P23: =SUM(P17+SUM(P20:P22)) -> 327.227 | Q23: =SUM(Q17+SUM(Q20:Q22)) -> 517.09 | ... X23: =SUM(X17+SUM(X20:X22)) -> 309.419 | Z23: =SUM(Z17+SUM(Z20:Z22)) -> 1638.61 | AA23: =SUM(AA17+SUM(AA20:AA22)) -> 1642.972 | AB23: =SUM(AB17+SUM(AB20:AB22)) -> 1643.186 | AC23: =SUM(AC17+SUM(AC20:AC22)) -> 1608.557 | AD23: =SUM(AD17+SUM(AD20:AD22)) -> 1678.029 | AE23: =SUM(AE17+SUM(AE20:AE22)) -> 1636.907 | AF23: =SUM(AF17+SUM(AF20:AF22)) -> 1574.466 | AG23: =SUM(AG17+SUM(AG20:AG22)) -> 1565.741 | ... AK23: =SUM(AK17+SUM(AK20:AK22)) -> 1572.371 | AM23: =SUM(AK23/AG23)-1 -> 0.0042344168
