Workbook

Sheet Historical Financials
B2: Snap Inc (NASDAQ: SNAP)
B3: Historical Financials
B4: ($ In Millions, except EPS)
A6: X | B6: Income Statement | D6: FYE | G6: Quarterly | M6: Quarterly | V6: LTM | AB6: Variance
B7: Fiscal Period | C7: 2022 | D7: 2023 | E7: 2024 | G7: 1Q23 | H7: 2Q23 | I7: 3Q23 | J7: 4Q23 | K7: 1Q24 | L7: 2Q24 | M7: 3Q24 | N7: 4Q24 | O7: 1Q25 | P7: 2Q25 | Q7: 3Q25 | S7: =J7 -> 4Q23 | T7: =K7 -> 1Q24 | U7: =L7 -> 2Q24 | V7: =M7 -> 3Q24 | W7: =N7 -> 4Q24 | X7: =O7 -> 1Q25 | Y7: =P7 -> 2Q25 | Z7: =Q7 -> 3Q25
B8: Fiscal Period End Date | C8: 44926 | D8: 45291 | E8: 45657 | G8: 45016 | H8: 45107 | I8: 45199 | J8: =D8 -> 45291 | K8: 45382 | L8: 45473 | M8: 45565 | N8: =E8 -> 45657 | O8: 45747 | P8: 45838 | Q8: 45930 | S8: =J8 -> 45291 | T8: =K8 -> 45382 | U8: =L8 -> 45473 | V8: =M8 -> 45565 | W8: =N8 -> 45657 | X8: =O8 -> 45747 | Y8: =P8 -> 45838 | Z8: =Q8 -> 45930
B10: Consolidated Revenue | C10: 4601.8 | D10: 4606.2 | E10: 5361.5 | G10: 988.608 | H10: 1067.669 | I10: 1188.551 | J10: =SUM(D10-SUM(G10:I10)) -> 1361.372 | K10: 1194.773 | L10: 1236.768 | M10: 1372.574 | N10: =SUM(E10-SUM(K10:M10)) -> 1557.385 | O10: 1363.217 | P10: 1344.93 | Q10: 1506.839 | S10: =SUM(G10:J10) -> 4606.2 | T10: =SUM(H10:K10) -> 4812.365 | U10: =SUM(I10:L10) -> 4981.464 | V10: =SUM(J10:M10) -> 5165.487 | W10: =SUM(K10:N10) -> 5361.5 | X10: =SUM(L10:O10) -> 5529.944 | Y10: =SUM(M10:P10) -> 5638.106 | Z10: =SUM(N10:Q10) -> 5772.371 | AB10: =SUM(Z10/V10)-1 -> 0.11748824
B11: Total Revenue | C11: =+SUM(C10:C10) -> 4601.8 | D11: =+SUM(D10:D10) -> 4606.2 | E11: =+SUM(E10:E10) -> 5361.5 | G11: =+SUM(G10:G10) -> 988.608 | H11: =+SUM(H10:H10) -> 1067.669 | I11: =+SUM(I10:I10) -> 1188.551 | J11: =+SUM(J10:J10) -> 1361.372 | K11: =+SUM(K10:K10) -> 1194.773 | L11: =+SUM(L10:L10) -> 1236.768 | M11: =+SUM(M10:M10) -> 1372.574 | N11: =+SUM(N10:N10) -> 1557.385 | ... Q11: =+SUM(Q10:Q10) -> 1506.839 | S11: =+SUM(S10:S10) -> 4606.2 | T11: =+SUM(T10:T10) -> 4812.365 | U11: =+SUM(U10:U10) -> 4981.464 | V11: =+SUM(V10:V10) -> 5165.487 | W11: =+SUM(W10:W10) -> 5361.5 | X11: =+SUM(X10:X10) -> 5529.944 | Y11: =+SUM(Y10:Y10) -> 5638.106 | Z11: =+SUM(Z10:Z10) -> 5772.371 | AB11: =SUM(Z11/V11)-1 -> 0.11748824
B13: Cost of Sales | C13: -1815.4 | D13: -2114.2 | E13: -2474.2 | G13: -439.986 | H13: -496.874 | I13: -555.753 | J13: =SUM(D13-SUM(G13:I13)) -> -621.587 | K13: -574.749 | L13: -588.921 | M13: -638.907 | N13: =SUM(E13-SUM(K13:M13)) -> -671.623 | O13: -639.579 | P13: -653.333 | Q13: -674.22 | S13: =SUM(G13:J13) -> -2114.2 | T13: =SUM(H13:K13) -> -2248.963 | U13: =SUM(I13:L13) -> -2341.01 | V13: =SUM(J13:M13) -> -2424.164 | W13: =SUM(K13:N13) -> -2474.2 | X13: =SUM(L13:O13) -> -2539.03 | Y13: =SUM(M13:P13) -> -2603.442 | Z13: =SUM(N13:Q13) -> -2638.755 | AB13: =SUM(Z13/V13)-1 -> 0.088521651
B14: Gross Profit | C14: =+SUM(C11+SUM(C13:C13)) -> 2786.4 | D14: =+SUM(D11+SUM(D13:D13)) -> 2492 | E14: =+SUM(E11+SUM(E13:E13)) -> 2887.3 | G14: =+SUM(G11+SUM(G13:G13)) -> 548.622 | H14: =+SUM(H11+SUM(H13:H13)) -> 570.795 | I14: =+SUM(I11+SUM(I13:I13)) -> 632.798 | J14: =+SUM(J11+SUM(J13:J13)) -> 739.785 | K14: =+SUM(K11+SUM(K13:K13)) -> 620.024 | L14: =+SUM(L11+SUM(L13:L13)) -> 647.847 | M14: =+SUM(M11+SUM(M13:M13)) -> 733.667 | N14: =+SUM(N11+SUM(N13:N13)) -> 885.762 | ... Q14: =+SUM(Q11+SUM(Q13:Q13)) -> 832.619 | S14: =+SUM(S11+SUM(S13:S13)) -> 2492 | T14: =+SUM(T11+SUM(T13:T13)) -> 2563.402 | U14: =+SUM(U11+SUM(U13:U13)) -> 2640.454 | V14: =+SUM(V11+SUM(V13:V13)) -> 2741.323 | W14: =+SUM(W11+SUM(W13:W13)) -> 2887.3 | X14: =+SUM(X11+SUM(X13:X13)) -> 2990.914 | Y14: =+SUM(Y11+SUM(Y13:Y13)) -> 3034.664 | Z14: =+SUM(Z11+SUM(Z13:Z13)) -> 3133.616 | AB14: =SUM(Z14/V14)-1 -> 0.14310353
B15: Gross Margin (%) | C15: =C14/C11 -> 0.60550219 | D15: =D14/D11 -> 0.54100994 | E15: =E14/E11 -> 0.53852467 | G15: =G14/G11 -> 0.55494392 | H15: =H14/H11 -> 0.53461794 | I15: =I14/I11 -> 0.53241131 | J15: =J14/J11 -> 0.54341135 | K15: =K14/K11 -> 0.51894711 | L15: =L14/L11 -> 0.52382258 | M15: =M14/M11 -> 0.53451909 | N15: =N14/N11 -> 0.56874954 | ... Q15: =Q14/Q11 -> 0.55256003 | S15: =S14/S11 -> 0.54100994 | T15: =T14/T11 -> 0.5326699 | U15: =U14/U11 -> 0.53005582 | V15: =V14/V11 -> 0.53069982 | W15: =W14/W11 -> 0.53852467 | X15: =X14/X11 -> 0.54085792 | Y15: =Y14/Y11 -> 0.53824174 | Z15: =Z14/Z11 -> 0.54286462 | AB15: =SUM(Z15-V15)*1000 -> 12.164806
B17: Research and development | C17: -2109.8 | D17: -1910.9 | E17: -1691.7 | G17: -455.112 | H17: -477.663 | I17: -494.6 | J17: =SUM(D17-SUM(G17:I17)) -> -483.525 | K17: -449.759 | L17: -406.196 | M17: -412.791 | N17: =SUM(E17-SUM(K17:M17)) -> -422.954 | O17: -424.165 | P17: -443.325 | Q17: -453.418 | S17: =SUM(G17:J17) -> -1910.9 | T17: =SUM(H17:K17) -> -1905.547 | U17: =SUM(I17:L17) -> -1834.08 | V17: =SUM(J17:M17) -> -1752.271 | W17: =SUM(K17:N17) -> -1691.7 | X17: =SUM(L17:O17) -> -1666.106 | Y17: =SUM(M17:P17) -> -1703.235 | Z17: =SUM(N17:Q17) -> -1743.862 | AB17: =SUM(Z17/V17)-1 -> -0.0047989152
B18: Sales and Marketing | C18: -1118.8 | D18: -1122 | E18: -1063.7 | G18: -268.433 | H18: -280.597 | I18: -297.2 | J18: =SUM(D18-SUM(G18:I18)) -> -275.77 | K18: -276.034 | L18: -266.32 | M18: -273.107 | N18: =SUM(E18-SUM(K18:M18)) -> -248.239 | O18: -257.957 | P18: -257.853 | Q18: -256.215 | S18: =SUM(G18:J18) -> -1122 | T18: =SUM(H18:K18) -> -1129.601 | U18: =SUM(I18:L18) -> -1115.324 | V18: =SUM(J18:M18) -> -1091.231 | W18: =SUM(K18:N18) -> -1063.7 | X18: =SUM(L18:O18) -> -1045.623 | Y18: =SUM(M18:P18) -> -1037.156 | Z18: =SUM(N18:Q18) -> -1020.264 | AB18: =SUM(Z18/V18)-1 -> -0.065033893
B19: General and Administrative | C19: -953.3 | D19: -857.5 | E19: -919.1 | G19: -190.341 | H19: -216.874 | I19: -221.1 | J19: =SUM(D19-SUM(G19:I19)) -> -229.185 | K19: -227.463 | L19: -229.306 | M19: -220.979 | N19: =SUM(E19-SUM(K19:M19)) -> -241.352 | O19: -235.362 | P19: -250.095 | Q19: -251.348 | S19: =SUM(G19:J19) -> -857.5 | T19: =SUM(H19:K19) -> -894.622 | U19: =SUM(I19:L19) -> -907.054 | V19: =SUM(J19:M19) -> -906.933 | W19: =SUM(K19:N19) -> -919.1 | X19: =SUM(L19:O19) -> -926.999 | Y19: =SUM(M19:P19) -> -947.788 | Z19: =SUM(N19:Q19) -> -978.157 | AB19: =SUM(Z19/V19)-1 -> 0.078532813
B20: Operating Profit | C20: =+SUM(C14+SUM(C17:C19)) -> -1395.5 | D20: =+SUM(D14+SUM(D17:D19)) -> -1398.4 | E20: =+SUM(E14+SUM(E17:E19)) -> -787.2 | G20: =+SUM(G14+SUM(G17:G19)) -> -365.264 | H20: =+SUM(H14+SUM(H17:H19)) -> -404.339 | I20: =+SUM(I14+SUM(I17:I19)) -> -380.102 | J20: =+SUM(J14+SUM(J17:J19)) -> -248.695 | K20: =+SUM(K14+SUM(K17:K19)) -> -333.232 | L20: =+SUM(L14+SUM(L17:L19)) -> -253.975 | M20: =+SUM(M14+SUM(M17:M19)) -> -173.21 | N20: =+SUM(N14+SUM(N17:N19)) -> -26.783 | ... Q20: =+SUM(Q14+SUM(Q17:Q19)) -> -128.362 | S20: =+SUM(S14+SUM(S17:S19)) -> -1398.4 | T20: =+SUM(T14+SUM(T17:T19)) -> -1366.368 | U20: =+SUM(U14+SUM(U17:U19)) -> -1216.004 | V20: =+SUM(V14+SUM(V17:V19)) -> -1009.112 | W20: =+SUM(W14+SUM(W17:W19)) -> -787.2 | X20: =+SUM(X14+SUM(X17:X19)) -> -647.814 | Y20: =+SUM(Y14+SUM(Y17:Y19)) -> -653.515 | Z20: =+SUM(Z14+SUM(Z17:Z19)) -> -608.667 | AB20: =SUM(Z20/V20)-1 -> -0.39682909
B21: Operating Margin (%) | C21: =C20/C11 -> -0.3032509 | D21: =D20/D11 -> -0.30359081 | E21: =E20/E11 -> -0.14682458 | G21: =G20/G11 -> -0.36947304 | H21: =H20/H11 -> -0.37871194 | I21: =I20/I11 -> -0.31980285 | J21: =J20/J11 -> -0.18267968 | K21: =K20/K11 -> -0.27890821 | L21: =L20/L11 -> -0.20535379 | M21: =M20/M11 -> -0.12619356 | N21: =N20/N11 -> -0.017197417 | ... Q21: =Q20/Q11 -> -0.085186274 | S21: =S20/S11 -> -0.30359081 | T21: =T20/T11 -> -0.28392859 | U21: =U20/U11 -> -0.24410575 | V21: =V20/V11 -> -0.1953566 | W21: =W20/W11 -> -0.14682458 | X21: =X20/X11 -> -0.11714658 | Y21: =Y20/Y11 -> -0.11591038 | Z21: =Z20/Z11 -> -0.10544489 | AB21: =SUM(Z21-V21)*1000 -> 89.911719
B23: Interest Income | C23: 58.597 | D23: 168.394 | E23: 153.466 | G23: 37.948 | H23: 43.144 | I23: 43.839 | J23: =SUM(D23-SUM(G23:I23)) -> 43.463 | K23: 39.898 | L23: 36.462 | M23: 38.533 | N23: =SUM(E23-SUM(K23:M23)) -> 38.573 | O23: 37.018 | P23: 33.199 | Q23: 32.255 | S23: =SUM(G23:J23) -> 168.394 | T23: =SUM(H23:K23) -> 170.344 | U23: =SUM(I23:L23) -> 163.662 | V23: =SUM(J23:M23) -> 158.356 | W23: =SUM(K23:N23) -> 153.466 | X23: =SUM(L23:O23) -> 150.586 | Y23: =SUM(M23:P23) -> 147.323 | Z23: =SUM(N23:Q23) -> 141.045 | AB23: =SUM(Z23/V23)-1 -> -0.10931698
B24: Interest Expenses | C24: -21.459 | D24: -22.024 | E24: -21.552 | G24: -5.885 | H24: -5.343 | I24: -5.521 | J24: =SUM(D24-SUM(G24:I24)) -> -5.275 | K24: -4.743 | L24: -5.113 | M24: -5.883 | N24: =SUM(E24-SUM(K24:M24)) -> -5.813 | O24: -23.399 | P24: -27.607 | Q24: -34.494 | S24: =SUM(G24:J24) -> -22.024 | T24: =SUM(H24:K24) -> -20.882 | U24: =SUM(I24:L24) -> -20.652 | V24: =SUM(J24:M24) -> -21.014 | W24: =SUM(K24:N24) -> -21.552 | X24: =SUM(L24:O24) -> -40.208 | Y24: =SUM(M24:P24) -> -62.702 | Z24: =SUM(N24:Q24) -> -91.313 | AB24: =SUM(Z24/V24)-1 -> 3.3453412
B25: Other Income | C25: -42.529 | D25: -42.414 | E25: -16.846 | G25: 11.372 | H25: 1.323 | I25: -20.662 | J25: =SUM(D25-SUM(G25:I25)) -> -34.447 | K25: -0.081 | L25: -20.792 | M25: -4.355 | N25: =SUM(E25-SUM(K25:M25)) -> 8.382 | O25: 49.069 | P25: -0.823 | Q25: 27.57 | S25: =SUM(G25:J25) -> -42.414 | T25: =SUM(H25:K25) -> -53.867 | U25: =SUM(I25:L25) -> -75.982 | V25: =SUM(J25:M25) -> -59.675 | W25: =SUM(K25:N25) -> -16.846 | X25: =SUM(L25:O25) -> 32.304 | Y25: =SUM(M25:P25) -> 52.273 | Z25: =SUM(N25:Q25) -> 84.198 | AB25: =SUM(Z25/V25)-1 -> -2.4109426
B26: Earnings before Taxes | C26: =SUM(C23:C25)+C20 -> -1400.891 | D26: =SUM(D23:D25)+D20 -> -1294.444 | E26: =SUM(E23:E25)+E20 -> -672.132 | G26: =SUM(G23:G25)+G20 -> -321.829 | H26: =SUM(H23:H25)+H20 -> -365.215 | I26: =SUM(I23:I25)+I20 -> -362.446 | J26: =SUM(J23:J25)+J20 -> -244.954 | K26: =SUM(K23:K25)+K20 -> -298.158 | L26: =SUM(L23:L25)+L20 -> -243.418 | M26: =SUM(M23:M25)+M20 -> -144.915 | N26: =SUM(N23:N25)+N20 -> 14.359 | ... Q26: =SUM(Q23:Q25)+Q20 -> -103.031 | S26: =SUM(S23:S25)+S20 -> -1294.444 | T26: =SUM(T23:T25)+T20 -> -1270.773 | U26: =SUM(U23:U25)+U20 -> -1148.976 | V26: =SUM(V23:V25)+V20 -> -931.445 | W26: =SUM(W23:W25)+W20 -> -672.132 | X26: =SUM(X23:X25)+X20 -> -505.132 | Y26: =SUM(Y23:Y25)+Y20 -> -516.621 | Z26: =SUM(Z23:Z25)+Z20 -> -474.737 | AB26: =SUM(Z26/V26)-1 -> -0.49032203
B27: EBT Margin (%) | C27: =C26/C11 -> -0.3044224 | D27: =D26/D11 -> -0.2810221 | E27: =E26/E11 -> -0.12536268 | G27: =G26/G11 -> -0.32553752 | H27: =H26/H11 -> -0.34206763 | I27: =I26/I11 -> -0.30494779 | J27: =J26/J11 -> -0.17993172 | K27: =K26/K11 -> -0.24955201 | L27: =L26/L11 -> -0.19681783 | M27: =M26/M11 -> -0.10557901 | N27: =N26/N11 -> 0.0092199424 | ... Q27: =Q26/Q11 -> -0.068375586 | S27: =S26/S11 -> -0.2810221 | T27: =T26/T11 -> -0.26406413 | U27: =U26/U11 -> -0.23065027 | V27: =V26/V11 -> -0.18032085 | W27: =W26/W11 -> -0.12536268 | X27: =X26/X11 -> -0.091344867 | Y27: =Y26/Y11 -> -0.091630239 | Z27: =Z26/Z11 -> -0.082242981 | AB27: =SUM(Z27-V27)*1000 -> 98.077867
B29: Income tax expense | C29: -28.9 | D29: -28 | E29: -25.6 | G29: -6.845 | H29: -12.093 | I29: -5.8 | J29: =SUM(D29-SUM(G29:I29)) -> -3.262 | K29: -6.932 | L29: -5.202 | M29: -8.332 | N29: =SUM(E29-SUM(K29:M29)) -> -5.134 | O29: -8.429 | P29: -7.663 | Q29: -0.51 | S29: =SUM(G29:J29) -> -28 | T29: =SUM(H29:K29) -> -28.087 | U29: =SUM(I29:L29) -> -21.196 | V29: =SUM(J29:M29) -> -23.728 | W29: =SUM(K29:N29) -> -25.6 | X29: =SUM(L29:O29) -> -27.097 | Y29: =SUM(M29:P29) -> -29.558 | Z29: =SUM(N29:Q29) -> -21.736 | AB29: =SUM(Z29/V29)-1 -> -0.08395145
B30: Net loss | C30: =SUM(C26+SUM(C29:C29)) -> -1429.791 | D30: =SUM(D26+SUM(D29:D29)) -> -1322.444 | E30: =SUM(E26+SUM(E29:E29)) -> -697.732 | G30: =SUM(G26+SUM(G29:G29)) -> -328.674 | H30: =SUM(H26+SUM(H29:H29)) -> -377.308 | I30: =SUM(I26+SUM(I29:I29)) -> -368.246 | J30: =SUM(J26+SUM(J29:J29)) -> -248.216 | K30: =SUM(K26+SUM(K29:K29)) -> -305.09 | L30: =SUM(L26+SUM(L29:L29)) -> -248.62 | M30: =SUM(M26+SUM(M29:M29)) -> -153.247 | N30: =SUM(N26+SUM(N29:N29)) -> 9.225 | ... Q30: =SUM(Q26+SUM(Q29:Q29)) -> -103.541 | S30: =SUM(S26+SUM(S29:S29)) -> -1322.444 | T30: =SUM(T26+SUM(T29:T29)) -> -1298.86 | U30: =SUM(U26+SUM(U29:U29)) -> -1170.172 | V30: =SUM(V26+SUM(V29:V29)) -> -955.173 | W30: =SUM(W26+SUM(W29:W29)) -> -697.732 | X30: =SUM(X26+SUM(X29:X29)) -> -532.229 | Y30: =SUM(Y26+SUM(Y29:Y29)) -> -546.179 | Z30: =SUM(Z26+SUM(Z29:Z29)) -> -496.473 | AB30: =SUM(Z30/V30)-1 -> -0.48022714
B31: Net Margin (%) | C31: =C30/C11 -> -0.31070255 | D31: =D30/D11 -> -0.28710086 | E31: =E30/E11 -> -0.13013746 | G31: =G30/G11 -> -0.3324614 | H31: =H30/H11 -> -0.35339417 | I31: =I30/I11 -> -0.30982768 | J31: =J30/J11 -> -0.18232783 | K31: =K30/K11 -> -0.25535395 | L31: =L30/L11 -> -0.20102396 | M31: =M30/M11 -> -0.11164935 | N31: =N30/N11 -> 0.0059233908 | ... Q31: =Q30/Q11 -> -0.068714043 | S31: =S30/S11 -> -0.28710086 | T31: =T30/T11 -> -0.26990056 | U31: =U30/U11 -> -0.23490524 | V31: =V30/V11 -> -0.18491441 | W31: =W30/W11 -> -0.13013746 | X31: =X30/X11 -> -0.096244917 | Y31: =Y30/Y11 -> -0.09687278 | Z31: =Z30/Z11 -> -0.086008505 | AB31: =SUM(Z31-V31)*1000 -> 98.905909
B33: Basic shares | C33: 1608.304 | D33: 1612.504 | E33: 1659.147 | G33: 1581.37 | H33: 1603.172 | I33: 1625.917 | J33: =D33 -> 1612.504 | K33: 1647.387 | L33: 1644.736 | M33: 1663.011 | N33: =E33 -> 1659.147 | O33: 1696.353 | P33: 1674.854 | Q33: 1696.542 | S33: =J33 -> 1612.504 | T33: =K33 -> 1647.387 | U33: =L33 -> 1644.736 | V33: =M33 -> 1663.011 | W33: =N33 -> 1659.147 | X33: =O33 -> 1696.353 | Y33: =P33 -> 1674.854 | Z33: =Q33 -> 1696.542 | AB33: =SUM(Z33/V33)-1 -> 0.020162825
B34: Basic EPS | C34: =C30/C33 -> -0.88900544 | D34: =D30/D33 -> -0.82011828 | E34: =E30/E33 -> -0.42053658 | G34: =G30/G33 -> -0.2078413 | H34: =H30/H33 -> -0.23535092 | I34: =I30/I33 -> -0.22648512 | J34: =J30/J33 -> -0.15393202 | K34: =K30/K33 -> -0.18519631 | L34: =L30/L33 -> -0.15116104 | M34: =M30/M33 -> -0.092150323 | N34: =N30/N33 -> 0.005560086 | ... Q34: =Q30/Q33 -> -0.061030614 | S34: =S30/S33 -> -0.82011828 | T34: =T30/T33 -> -0.78843648 | U34: =U30/U33 -> -0.71146494 | V34: =V30/V33 -> -0.57436361 | W34: =W30/W33 -> -0.42053658 | X34: =X30/X33 -> -0.31374897 | Y34: =Y30/Y33 -> -0.32610544 | Z34: =Z30/Z33 -> -0.2926382 | AB34: =SUM(Z34/V34)-1 -> -0.4905001
B36: Fully Diluted Shares | C36: 1608.304 | D36: 1612.504 | E36: 1659.147 | G36: 1581.37 | H36: 1603.172 | I36: 1625.917 | J36: =D36 -> 1612.504 | K36: 1647.387 | L36: 1644.736 | M36: 1663.011 | N36: =E36 -> 1659.147 | O36: 1696.353 | P36: 1674.854 | Q36: 1696.542 | S36: =J36 -> 1612.504 | T36: =K36 -> 1647.387 | U36: =L36 -> 1644.736 | V36: =M36 -> 1663.011 | W36: =N36 -> 1659.147 | X36: =O36 -> 1696.353 | Y36: =P36 -> 1674.854 | Z36: =Q36 -> 1696.542 | AB36: =SUM(Z36/V36)-1 -> 0.020162825
B37: Diluted EPS | C37: =C30/C36 -> -0.88900544 | D37: =D30/D36 -> -0.82011828 | E37: =E30/E36 -> -0.42053658 | G37: =G30/G36 -> -0.2078413 | H37: =H30/H36 -> -0.23535092 | I37: =I30/I36 -> -0.22648512 | J37: =J30/J36 -> -0.15393202 | K37: =K30/K36 -> -0.18519631 | L37: =L30/L36 -> -0.15116104 | M37: =M30/M36 -> -0.092150323 | N37: =N30/N36 -> 0.005560086 | ... Q37: =Q30/Q36 -> -0.061030614 | S37: =S30/S36 -> -0.82011828 | T37: =T30/T36 -> -0.78843648 | U37: =U30/U36 -> -0.71146494 | V37: =V30/V36 -> -0.57436361 | W37: =W30/W36 -> -0.42053658 | X37: =X30/X36 -> -0.31374897 | Y37: =Y30/Y36 -> -0.32610544 | Z37: =Z30/Z36 -> -0.2926382 | AB37: =SUM(Z37/V37)-1 -> -0.4905001
A39: X | B39: Balance Sheet | C39: FYE | M39: Quarterly | V39: LTM | AB39: Variance
B40: =B7 -> Fiscal Period | C40: =C7 -> 2022 | D40: =D7 -> 2023 | E40: =E7 -> 2024 | G40: =G7 -> 1Q23 | H40: =H7 -> 2Q23 | I40: =I7 -> 3Q23 | J40: =J7 -> 4Q23 | K40: =K7 -> 1Q24 | L40: =L7 -> 2Q24 | M40: =M7 -> 3Q24 | N40: =N7 -> 4Q24 | ... Q40: =Q7 -> 3Q25 | S40: =S7 -> 4Q23 | T40: =T7 -> 1Q24 | U40: =U7 -> 2Q24 | V40: =V7 -> 3Q24 | W40: =W7 -> 4Q24 | X40: =X7 -> 1Q25 | Y40: =Y7 -> 2Q25 | Z40: =Z7 -> 3Q25
B41: =B8 -> Fiscal Period End Date | C41: =C8 -> 44926 | D41: =D8 -> 45291 | E41: =E8 -> 45657 | G41: =G8 -> 45016 | H41: =H8 -> 45107 | I41: =I8 -> 45199 | J41: =J8 -> 45291 | K41: =K8 -> 45382 | L41: =L8 -> 45473 | M41: =M8 -> 45565 | N41: =N8 -> 45657 | ... Q41: =Q8 -> 45930 | S41: =S8 -> 45291 | T41: =T8 -> 45382 | U41: =U8 -> 45473 | V41: =V8 -> 45565 | W41: =W8 -> 45657 | X41: =X8 -> 45747 | Y41: =Y8 -> 45838 | Z41: =Z8 -> 45930
B43: Current Assets
B44: Cash and cash equivalents | C44: 1423.121 | D44: 1780.4 | E44: 1046.5 | G44: 1578.52 | H44: 1228.62 | I44: 1199.36 | J44: =D44 -> 1780.4 | K44: 1060.39 | L44: 1060.55 | M44: 964.96 | N44: =E44 -> 1046.5 | O44: 911.227 | P44: 925.973 | Q44: 953.317 | S44: =J44 -> 1780.4 | T44: =K44 -> 1060.39 | U44: =L44 -> 1060.55 | V44: =M44 -> 964.96 | W44: =N44 -> 1046.5 | X44: =O44 -> 911.227 | Y44: =P44 -> 925.973 | Z44: =Q44 -> 953.317 | AB44: =SUM(Z44/V44)-1 -> -0.012065785
B45: Marketable Securities | C45: 2516 | D45: 1763.68 | E45: 2329.745 | G45: 2524.9 | H45: 2460.64 | I45: 2414.13 | J45: =D45 -> 1763.68 | K45: 1850.62 | L45: 2020.72 | M45: 2227 | N45: =E45 -> 2329.745 | O45: 2295.66 | P45: 1967 | Q45: 2040.06 | S45: =J45 -> 1763.68 | T45: =K45 -> 1850.62 | U45: =L45 -> 2020.72 | V45: =M45 -> 2227 | W45: =N45 -> 2329.745 | X45: =O45 -> 2295.66 | Y45: =P45 -> 1967 | Z45: =Q45 -> 2040.06 | AB45: =SUM(Z45/V45)-1 -> -0.083942524
B46: Accounts receivable, net | C46: 1183.09 | D46: 1278.176 | E46: 1348.472 | G46: 892.511 | H46: 996.08 | I46: 1116.51 | J46: =D46 -> 1278.176 | K46: 1108.35 | L46: 1141.849 | M46: 1195.7 | N46: =E46 -> 1348.472 | O46: 1157.61 | P46: 1164.87 | Q46: 1248.01 | S46: =J46 -> 1278.176 | T46: =K46 -> 1108.35 | U46: =L46 -> 1141.849 | V46: =M46 -> 1195.7 | W46: =N46 -> 1348.472 | X46: =O46 -> 1157.61 | Y46: =P46 -> 1164.87 | Z46: =Q46 -> 1248.01 | AB46: =SUM(Z46/V46)-1 -> 0.043748432
B47: Prepaid expenses and other current assets | C47: 134.43 | D47: 153.587 | E47: 182 | G47: 146.973 | H47: 154.17 | I47: 144.25 | J47: =D47 -> 153.587 | K47: 167.38 | L47: 198.07 | M47: 200.9 | N47: =E47 -> 182 | O47: 212.53 | P47: 226.25 | Q47: 235.099 | S47: =J47 -> 153.587 | T47: =K47 -> 167.38 | U47: =L47 -> 198.07 | V47: =M47 -> 200.9 | W47: =N47 -> 182 | X47: =O47 -> 212.53 | Y47: =P47 -> 226.25 | Z47: =Q47 -> 235.099 | AB47: =SUM(Z47/V47)-1 -> 0.17022897
B48: Total Current Assets | C48: =SUM(C44:C47) -> 5256.641 | D48: =SUM(D44:D47) -> 4975.843 | E48: =SUM(E44:E47) -> 4906.717 | G48: =SUM(G44:G47) -> 5142.904 | H48: =SUM(H44:H47) -> 4839.51 | I48: =SUM(I44:I47) -> 4874.25 | J48: =SUM(J44:J47) -> 4975.843 | K48: =SUM(K44:K47) -> 4186.74 | L48: =SUM(L44:L47) -> 4421.189 | M48: =SUM(M44:M47) -> 4588.56 | N48: =SUM(N44:N47) -> 4906.717 | ... Q48: =SUM(Q44:Q47) -> 4476.486 | S48: =SUM(S44:S47) -> 4975.843 | T48: =SUM(T44:T47) -> 4186.74 | U48: =SUM(U44:U47) -> 4421.189 | V48: =SUM(V44:V47) -> 4588.56 | W48: =SUM(W44:W47) -> 4906.717 | X48: =SUM(X44:X47) -> 4577.027 | Y48: =SUM(Y44:Y47) -> 4284.093 | Z48: =SUM(Z44:Z47) -> 4476.486 | AB48: =SUM(Z48/V48)-1 -> -0.024424656
B50: Non-Current Assets
B51: Property and equipment, net | C51: 271.77 | D51: 410.326 | E51: 489.09 | G51: 303.02 | H51: 330.01 | I51: 377.32 | J51: =D51 -> 410.326 | K51: 426.363 | L51: 444.485 | M51: 466.39 | N51: =E51 -> 489.09 | O51: 501.353 | P51: 544.226 | Q51: 557.418 | S51: =J51 -> 410.326 | T51: =K51 -> 426.363 | U51: =L51 -> 444.485 | V51: =M51 -> 466.39 | W51: =N51 -> 489.09 | X51: =O51 -> 501.353 | Y51: =P51 -> 544.226 | Z51: =Q51 -> 557.418 | AB51: =SUM(Z51/V51)-1 -> 0.19517571
B52: Long-term operating lease Assets | C52: 370.95 | D52: 516.86 | E52: 530.44 | G52: 355.06 | H52: 348.97 | I52: 344.68 | J52: =D52 -> 516.86 | K52: 511.1 | L52: 521.1 | M52: 516.959 | N52: =E52 -> 530.44 | O52: 528.27 | P52: 534.084 | Q52: 520.187 | S52: =J52 -> 516.86 | T52: =K52 -> 511.1 | U52: =L52 -> 521.1 | V52: =M52 -> 516.959 | W52: =N52 -> 530.44 | X52: =O52 -> 528.27 | Y52: =P52 -> 534.084 | Z52: =Q52 -> 520.187 | AB52: =SUM(Z52/V52)-1 -> 0.0062442089
...

Sheet Revenue Drivers
B2: ='Historical Financials'!B2 -> Snap Inc (NASDAQ: SNAP) | C2: FYE | N2: Quarterly | AA2: LTM
B3: Segment Anaysis | C3: ='Historical Financials'!C7 -> 2022 | D3: ='Historical Financials'!D7 -> 2023 | E3: ='Historical Financials'!E7 -> 2024 | F3: ='Historical Financials'!#REF! -> #REF! | H3: ='Historical Financials'!G7 -> 1Q23 | I3: ='Historical Financials'!H7 -> 2Q23 | J3: ='Historical Financials'!I7 -> 3Q23 | K3: ='Historical Financials'!J7 -> 4Q23 | L3: ='Historical Financials'!K7 -> 1Q24 | M3: ='Historical Financials'!L7 -> 2Q24 | N3: ='Historical Financials'!M7 -> 3Q24 | O3: ='Historical Financials'!N7 -> 4Q24 | ... R3: ='Historical Financials'!Q7 -> 3Q25 | S3: ='Historical Financials'!#REF! -> #REF! | T3: ='Historical Financials'!#REF! -> #REF! | V3: =K3 -> 4Q23 | W3: =L3 -> 1Q24 | X3: =M3 -> 2Q24 | Y3: =N3 -> 3Q24 | Z3: =O3 -> 4Q24 | AA3: =P3 -> 1Q25 | AB3: =Q3 -> 2Q25 | AC3: =R3 -> 3Q25 | ... AE3: =T3 -> #REF!
B4: ($ In Millions) | C4: ='Historical Financials'!C8 -> 44926 | D4: ='Historical Financials'!D8 -> 45291 | E4: ='Historical Financials'!E8 -> 45657 | F4: ='Historical Financials'!#REF! -> #REF! | H4: ='Historical Financials'!G8 -> 45016 | I4: ='Historical Financials'!H8 -> 45107 | J4: ='Historical Financials'!I8 -> 45199 | K4: ='Historical Financials'!J8 -> 45291 | L4: ='Historical Financials'!K8 -> 45382 | M4: ='Historical Financials'!L8 -> 45473 | N4: ='Historical Financials'!M8 -> 45565 | O4: ='Historical Financials'!N8 -> 45657 | ... R4: ='Historical Financials'!Q8 -> 45930 | S4: ='Historical Financials'!#REF! -> #REF! | T4: ='Historical Financials'!#REF! -> #REF! | V4: =K4 -> 45291 | W4: =L4 -> 45382 | X4: =M4 -> 45473 | Y4: =N4 -> 45565 | Z4: =O4 -> 45657 | AA4: =P4 -> 45747 | AB4: =Q4 -> 45838 | AC4: =R4 -> 45930 | ... AE4: =T4 -> #REF!
A6: X | B6: Revenue by reportable segment
A8: X | B8: Revenue Segment Anaysis
B9: XXX | K9: =SUM(D9-SUM(H9:J9)) -> 0 | O9: =SUM(E9-SUM(L9:N9)) -> 0 | S9: =SUM(F9-SUM(P9:R9)) -> 0 | V9: =SUM(H9:K9) -> 0 | W9: =SUM(I9:L9) -> 0 | X9: =SUM(J9:M9) -> 0 | Y9: =SUM(K9:N9) -> 0 | Z9: =SUM(L9:O9) -> 0 | AA9: =SUM(M9:P9) -> 0 | AB9: =SUM(N9:Q9) -> 0 | AC9: =SUM(O9:R9) -> 0 | ... AE9: =SUM(Q9:T9) -> 0
B10: XXX | K10: =SUM(D10-SUM(H10:J10)) -> 0 | O10: =SUM(E10-SUM(L10:N10)) -> 0 | S10: =SUM(F10-SUM(P10:R10)) -> 0 | V10: =SUM(H10:K10) -> 0 | W10: =SUM(I10:L10) -> 0 | X10: =SUM(J10:M10) -> 0 | Y10: =SUM(K10:N10) -> 0 | Z10: =SUM(L10:O10) -> 0 | AA10: =SUM(M10:P10) -> 0 | AB10: =SUM(N10:Q10) -> 0 | AC10: =SUM(O10:R10) -> 0 | ... AE10: =SUM(Q10:T10) -> 0
B11: Total Net Revenue | C11: =SUM(C9:C10) -> 0 | D11: =SUM(D9:D10) -> 0 | E11: =SUM(E9:E10) -> 0 | F11: =SUM(F9:F10) -> 0 | H11: =SUM(H9:H10) -> 0 | I11: =SUM(I9:I10) -> 0 | J11: =SUM(J9:J10) -> 0 | K11: =SUM(K9:K10) -> 0 | L11: =SUM(L9:L10) -> 0 | M11: =SUM(M9:M10) -> 0 | N11: =SUM(N9:N10) -> 0 | O11: =SUM(O9:O10) -> 0 | ... T11: =SUM(T9:T10) -> 0 | V11: =SUM(V9:V10) -> 0 | W11: =SUM(W9:W10) -> 0 | X11: =SUM(X9:X10) -> 0 | Y11: =SUM(Y9:Y10) -> 0 | Z11: =SUM(Z9:Z10) -> 0 | AA11: =SUM(AA9:AA10) -> 0 | AB11: =SUM(AB9:AB10) -> 0 | AC11: =SUM(AC9:AC10) -> 0 | ... AE11: =SUM(AE9:AE10) -> 0
B12: Balance Check | C12: =+C11-'Historical Financials'!C11 -> -4601.8 | D12: =+D11-'Historical Financials'!D11 -> -4606.2 | E12: =+E11-'Historical Financials'!E11 -> -5361.5 | F12: =+F11-'Historical Financials'!#REF! -> #REF! | H12: =+H11-'Historical Financials'!G11 -> -988.608 | I12: =+I11-'Historical Financials'!H11 -> -1067.669 | J12: =+J11-'Historical Financials'!I11 -> -1188.551 | K12: =+K11-'Historical Financials'!J11 -> -1361.372 | L12: =+L11-'Historical Financials'!K11 -> -1194.773 | M12: =+M11-'Historical Financials'!L11 -> -1236.768 | N12: =+N11-'Historical Financials'!M11 -> -1372.574 | O12: =+O11-'Historical Financials'!N11 -> -1557.385 | ... R12: =+R11-'Historical Financials'!Q11 -> -1506.839 | S12: =+S11-'Historical Financials'!#REF! -> #REF! | T12: =+T11-'Historical Financials'!#REF! -> #REF! | V12: =+V11-'Historical Financials'!#REF! -> #REF! | W12: =+W11-'Historical Financials'!#REF! -> #REF! | X12: =+X11-'Historical Financials'!S11 -> -4606.2 | Y12: =+Y11-'Historical Financials'!T11 -> -4812.365 | Z12: =+Z11-'Historical Financials'!U11 -> -4981.464 | AA12: =+AA11-'Historical Financials'!V11 -> -5165.487 | AB12: =+AB11-'Historical Financials'!W11 -> -5361.5 | AC12: =+AC11-'Historical Financials'!X11 -> -5529.944 | AD12: =+AD11-'Historical Financials'!Y11 -> -5638.106 | AE12: =+AE11-'Historical Financials'!Z11 -> -5772.371
B14: =B9&"(%)" -> XXX(%) | C14: =SUM(C9/C$11) -> #DIV/0! | D14: =SUM(D9/D$11) -> #DIV/0! | E14: =SUM(E9/E$11) -> #DIV/0! | F14: =SUM(F9/F$11) -> #DIV/0! | H14: =SUM(H9/H$11) -> #DIV/0! | I14: =SUM(I9/I$11) -> #DIV/0! | J14: =SUM(J9/J$11) -> #DIV/0! | K14: =SUM(K9/K$11) -> #DIV/0! | L14: =SUM(L9/L$11) -> #DIV/0! | M14: =SUM(M9/M$11) -> #DIV/0! | N14: =SUM(N9/N$11) -> #DIV/0! | O14: =SUM(O9/O$11) -> #DIV/0! | ... T14: =SUM(T9/T$11) -> #DIV/0! | V14: =I14 -> #DIV/0! | W14: =J14 -> #DIV/0! | X14: =K14 -> #DIV/0! | Y14: =L14 -> #DIV/0! | Z14: =M14 -> #DIV/0! | AA14: =N14 -> #DIV/0! | AB14: =O14 -> #DIV/0! | AC14: =P14 -> #DIV/0! | ... AE14: =R14 -> #DIV/0!
B15: =B10&"(%)" -> XXX(%) | C15: =SUM(C10/C$11) -> #DIV/0! | D15: =SUM(D10/D$11) -> #DIV/0! | E15: =SUM(E10/E$11) -> #DIV/0! | F15: =SUM(F10/F$11) -> #DIV/0! | H15: =SUM(H10/H$11) -> #DIV/0! | I15: =SUM(I10/I$11) -> #DIV/0! | J15: =SUM(J10/J$11) -> #DIV/0! | K15: =SUM(K10/K$11) -> #DIV/0! | L15: =SUM(L10/L$11) -> #DIV/0! | M15: =SUM(M10/M$11) -> #DIV/0! | N15: =SUM(N10/N$11) -> #DIV/0! | O15: =SUM(O10/O$11) -> #DIV/0! | ... T15: =SUM(T10/T$11) -> #DIV/0! | V15: =I15 -> #DIV/0! | W15: =J15 -> #DIV/0! | X15: =K15 -> #DIV/0! | Y15: =L15 -> #DIV/0! | Z15: =M15 -> #DIV/0! | AA15: =N15 -> #DIV/0! | AB15: =O15 -> #DIV/0! | AC15: =P15 -> #DIV/0! | ... AE15: =R15 -> #DIV/0!
A17: X | B17: Revenue by product category
A19: X | B19: Revenue by XXX
B20: XXX | K20: =SUM(D20-SUM(H20:J20)) -> 0 | O20: =SUM(E20-SUM(L20:N20)) -> 0 | S20: =SUM(F20-SUM(P20:R20)) -> 0 | V20: =SUM(H20:K20) -> 0 | W20: =SUM(I20:L20) -> 0 | X20: =SUM(J20:M20) -> 0 | Y20: =SUM(K20:N20) -> 0 | Z20: =SUM(L20:O20) -> 0 | AA20: =SUM(M20:P20) -> 0 | AB20: =SUM(N20:Q20) -> 0 | AC20: =SUM(O20:R20) -> 0 | ... AE20: =SUM(Q20:T20) -> 0
B21: XXX | K21: =SUM(D21-SUM(H21:J21)) -> 0 | O21: =SUM(E21-SUM(L21:N21)) -> 0 | S21: =SUM(F21-SUM(P21:R21)) -> 0 | V21: =SUM(H21:K21) -> 0 | W21: =SUM(I21:L21) -> 0 | X21: =SUM(J21:M21) -> 0 | Y21: =SUM(K21:N21) -> 0 | Z21: =SUM(L21:O21) -> 0 | AA21: =SUM(M21:P21) -> 0 | AB21: =SUM(N21:Q21) -> 0 | AC21: =SUM(O21:R21) -> 0 | ... AE21: =SUM(Q21:T21) -> 0
B22: XXX | K22: =SUM(D22-SUM(H22:J22)) -> 0 | O22: =SUM(E22-SUM(L22:N22)) -> 0 | S22: =SUM(F22-SUM(P22:R22)) -> 0 | V22: =SUM(H22:K22) -> 0 | W22: =SUM(I22:L22) -> 0 | X22: =SUM(J22:M22) -> 0 | Y22: =SUM(K22:N22) -> 0 | Z22: =SUM(L22:O22) -> 0 | AA22: =SUM(M22:P22) -> 0 | AB22: =SUM(N22:Q22) -> 0 | AC22: =SUM(O22:R22) -> 0 | ... AE22: =SUM(Q22:T22) -> 0
B23: XXX | K23: =SUM(D23-SUM(H23:J23)) -> 0 | O23: =SUM(E23-SUM(L23:N23)) -> 0 | S23: =SUM(F23-SUM(P23:R23)) -> 0 | V23: =SUM(H23:K23) -> 0 | W23: =SUM(I23:L23) -> 0 | X23: =SUM(J23:M23) -> 0 | Y23: =SUM(K23:N23) -> 0 | Z23: =SUM(L23:O23) -> 0 | AA23: =SUM(M23:P23) -> 0 | AB23: =SUM(N23:Q23) -> 0 | AC23: =SUM(O23:R23) -> 0 | ... AE23: =SUM(Q23:T23) -> 0
B24: XXX | K24: =SUM(D24-SUM(H24:J24)) -> 0 | O24: =SUM(E24-SUM(L24:N24)) -> 0 | S24: =SUM(F24-SUM(P24:R24)) -> 0 | V24: =SUM(H24:K24) -> 0 | W24: =SUM(I24:L24) -> 0 | X24: =SUM(J24:M24) -> 0 | Y24: =SUM(K24:N24) -> 0 | Z24: =SUM(L24:O24) -> 0 | AA24: =SUM(M24:P24) -> 0 | AB24: =SUM(N24:Q24) -> 0 | AC24: =SUM(O24:R24) -> 0 | ... AE24: =SUM(Q24:T24) -> 0
B25: XXX | K25: =SUM(D25-SUM(H25:J25)) -> 0 | O25: =SUM(E25-SUM(L25:N25)) -> 0 | S25: =SUM(F25-SUM(P25:R25)) -> 0 | V25: =SUM(H25:K25) -> 0 | W25: =SUM(I25:L25) -> 0 | X25: =SUM(J25:M25) -> 0 | Y25: =SUM(K25:N25) -> 0 | Z25: =SUM(L25:O25) -> 0 | AA25: =SUM(M25:P25) -> 0 | AB25: =SUM(N25:Q25) -> 0 | AC25: =SUM(O25:R25) -> 0 | ... AE25: =SUM(Q25:T25) -> 0
B26: Total Revenue | C26: =SUM(C20:C25) -> 0 | D26: =SUM(D20:D25) -> 0 | E26: =SUM(E20:E25) -> 0 | F26: =SUM(F20:F25) -> 0 | H26: =SUM(H20:H25) -> 0 | I26: =SUM(I20:I25) -> 0 | J26: =SUM(J20:J25) -> 0 | K26: =SUM(K20:K25) -> 0 | L26: =SUM(L20:L25) -> 0 | M26: =SUM(M20:M25) -> 0 | N26: =SUM(N20:N25) -> 0 | O26: =SUM(O20:O25) -> 0 | ... T26: =SUM(T20:T25) -> 0 | V26: =SUM(V20:V25) -> 0 | W26: =SUM(W20:W25) -> 0 | X26: =SUM(X20:X25) -> 0 | Y26: =SUM(Y20:Y25) -> 0 | Z26: =SUM(Z20:Z25) -> 0 | AA26: =SUM(AA20:AA25) -> 0 | AB26: =SUM(AB20:AB25) -> 0 | AC26: =SUM(AC20:AC25) -> 0 | ... AE26: =SUM(AE20:AE25) -> 0
B27: Balance Check | C27: =+C26-C11 -> 0 | D27: =+D26-D11 -> 0 | E27: =+E26-E11 -> 0 | F27: =+F26-F11 -> 0 | H27: =+H26-H11 -> 0 | I27: =+I26-I11 -> 0 | J27: =+J26-J11 -> 0 | K27: =+K26-K11 -> 0 | L27: =+L26-L11 -> 0 | M27: =+M26-M11 -> 0 | N27: =+N26-N11 -> 0 | O27: =+O26-O11 -> 0 | ... T27: =+T26-T11 -> 0 | V27: =+V26-V11 -> 0 | W27: =+W26-W11 -> 0 | X27: =+X26-X11 -> 0 | Y27: =+Y26-Y11 -> 0 | Z27: =+Z26-Z11 -> 0 | AA27: =+AA26-AA11 -> 0 | AB27: =+AB26-AB11 -> 0 | AC27: =+AC26-AC11 -> 0 | ... AE27: =+AE26-AE11 -> 0
B29: =B20&"(%)" -> XXX(%) | C29: =C20/C$26 -> #DIV/0! | D29: =D20/D$26 -> #DIV/0! | E29: =E20/E$26 -> #DIV/0! | F29: =F20/F$26 -> #DIV/0! | H29: =H20/H$26 -> #DIV/0! | I29: =I20/I$26 -> #DIV/0! | J29: =J20/J$26 -> #DIV/0! | K29: =K20/K$26 -> #DIV/0! | L29: =L20/L$26 -> #DIV/0! | M29: =M20/M$26 -> #DIV/0! | N29: =N20/N$26 -> #DIV/0! | O29: =O20/O$26 -> #DIV/0! | ... T29: =T20/T$26 -> #DIV/0! | V29: =V20/V$26 -> #DIV/0! | W29: =W20/W$26 -> #DIV/0! | X29: =X20/X$26 -> #DIV/0! | Y29: =Y20/Y$26 -> #DIV/0! | Z29: =Z20/Z$26 -> #DIV/0! | AA29: =AA20/AA$26 -> #DIV/0! | AB29: =AB20/AB$26 -> #DIV/0! | AC29: =AC20/AC$26 -> #DIV/0! | ... AE29: =AE20/AE$26 -> #DIV/0!
B30: =B21&"(%)" -> XXX(%) | C30: =C21/C$26 -> #DIV/0! | D30: =D21/D$26 -> #DIV/0! | E30: =E21/E$26 -> #DIV/0! | F30: =F21/F$26 -> #DIV/0! | H30: =H21/H$26 -> #DIV/0! | I30: =I21/I$26 -> #DIV/0! | J30: =J21/J$26 -> #DIV/0! | K30: =K21/K$26 -> #DIV/0! | L30: =L21/L$26 -> #DIV/0! | M30: =M21/M$26 -> #DIV/0! | N30: =N21/N$26 -> #DIV/0! | O30: =O21/O$26 -> #DIV/0! | ... T30: =T21/T$26 -> #DIV/0! | V30: =V21/V$26 -> #DIV/0! | W30: =W21/W$26 -> #DIV/0! | X30: =X21/X$26 -> #DIV/0! | Y30: =Y21/Y$26 -> #DIV/0! | Z30: =Z21/Z$26 -> #DIV/0! | AA30: =AA21/AA$26 -> #DIV/0! | AB30: =AB21/AB$26 -> #DIV/0! | AC30: =AC21/AC$26 -> #DIV/0! | ... AE30: =AE21/AE$26 -> #DIV/0!
B31: =B22&"(%)" -> XXX(%) | C31: =C22/C$26 -> #DIV/0! | D31: =D22/D$26 -> #DIV/0! | E31: =E22/E$26 -> #DIV/0! | F31: =F22/F$26 -> #DIV/0! | H31: =H22/H$26 -> #DIV/0! | I31: =I22/I$26 -> #DIV/0! | J31: =J22/J$26 -> #DIV/0! | K31: =K22/K$26 -> #DIV/0! | L31: =L22/L$26 -> #DIV/0! | M31: =M22/M$26 -> #DIV/0! | N31: =N22/N$26 -> #DIV/0! | O31: =O22/O$26 -> #DIV/0! | ... T31: =T22/T$26 -> #DIV/0! | V31: =V22/V$26 -> #DIV/0! | W31: =W22/W$26 -> #DIV/0! | X31: =X22/X$26 -> #DIV/0! | Y31: =Y22/Y$26 -> #DIV/0! | Z31: =Z22/Z$26 -> #DIV/0! | AA31: =AA22/AA$26 -> #DIV/0! | AB31: =AB22/AB$26 -> #DIV/0! | AC31: =AC22/AC$26 -> #DIV/0! | ... AE31: =AE22/AE$26 -> #DIV/0!
B32: =B23&"(%)" -> XXX(%) | C32: =C23/C$26 -> #DIV/0! | D32: =D23/D$26 -> #DIV/0! | E32: =E23/E$26 -> #DIV/0! | F32: =F23/F$26 -> #DIV/0! | H32: =H23/H$26 -> #DIV/0! | I32: =I23/I$26 -> #DIV/0! | J32: =J23/J$26 -> #DIV/0! | K32: =K23/K$26 -> #DIV/0! | L32: =L23/L$26 -> #DIV/0! | M32: =M23/M$26 -> #DIV/0! | N32: =N23/N$26 -> #DIV/0! | O32: =O23/O$26 -> #DIV/0! | ... T32: =T23/T$26 -> #DIV/0! | V32: =V23/V$26 -> #DIV/0! | W32: =W23/W$26 -> #DIV/0! | X32: =X23/X$26 -> #DIV/0! | Y32: =Y23/Y$26 -> #DIV/0! | Z32: =Z23/Z$26 -> #DIV/0! | AA32: =AA23/AA$26 -> #DIV/0! | AB32: =AB23/AB$26 -> #DIV/0! | AC32: =AC23/AC$26 -> #DIV/0! | ... AE32: =AE23/AE$26 -> #DIV/0!
B33: =B24&"(%)" -> XXX(%) | C33: =C24/C$26 -> #DIV/0! | D33: =D24/D$26 -> #DIV/0! | E33: =E24/E$26 -> #DIV/0! | F33: =F24/F$26 -> #DIV/0! | H33: =H24/H$26 -> #DIV/0! | I33: =I24/I$26 -> #DIV/0! | J33: =J24/J$26 -> #DIV/0! | K33: =K24/K$26 -> #DIV/0! | L33: =L24/L$26 -> #DIV/0! | M33: =M24/M$26 -> #DIV/0! | N33: =N24/N$26 -> #DIV/0! | O33: =O24/O$26 -> #DIV/0! | ... T33: =T24/T$26 -> #DIV/0! | V33: =V24/V$26 -> #DIV/0! | W33: =W24/W$26 -> #DIV/0! | X33: =X24/X$26 -> #DIV/0! | Y33: =Y24/Y$26 -> #DIV/0! | Z33: =Z24/Z$26 -> #DIV/0! | AA33: =AA24/AA$26 -> #DIV/0! | AB33: =AB24/AB$26 -> #DIV/0! | AC33: =AC24/AC$26 -> #DIV/0! | ... AE33: =AE24/AE$26 -> #DIV/0!
B34: =B25&"(%)" -> XXX(%) | C34: =C25/C$26 -> #DIV/0! | D34: =D25/D$26 -> #DIV/0! | E34: =E25/E$26 -> #DIV/0! | F34: =F25/F$26 -> #DIV/0! | H34: =H25/H$26 -> #DIV/0! | I34: =I25/I$26 -> #DIV/0! | J34: =J25/J$26 -> #DIV/0! | K34: =K25/K$26 -> #DIV/0! | L34: =L25/L$26 -> #DIV/0! | M34: =M25/M$26 -> #DIV/0! | N34: =N25/N$26 -> #DIV/0! | O34: =O25/O$26 -> #DIV/0! | ... T34: =T25/T$26 -> #DIV/0! | V34: =V25/V$26 -> #DIV/0! | W34: =W25/W$26 -> #DIV/0! | X34: =X25/X$26 -> #DIV/0! | Y34: =Y25/Y$26 -> #DIV/0! | Z34: =Z25/Z$26 -> #DIV/0! | AA34: =AA25/AA$26 -> #DIV/0! | AB34: =AB25/AB$26 -> #DIV/0! | AC34: =AC25/AC$26 -> #DIV/0! | ... AE34: =AE25/AE$26 -> #DIV/0!

Sheet FCF
B2: ='Historical Financials'!B2 -> Snap Inc (NASDAQ: SNAP) | D2: FYE | H2: Quarterly | R2: Quarterly | Z2: LTM | AA2: LTM | AG2: Variance
B3: FCF Analysis | C3: ='Historical Financials'!C7 -> 2022 | D3: ='Historical Financials'!D7 -> 2023 | E3: ='Historical Financials'!E7 -> 2024 | F3: ='Historical Financials'!#REF! -> #REF! | H3: ='Historical Financials'!G7 -> 1Q23 | I3: ='Historical Financials'!H7 -> 2Q23 | J3: ='Historical Financials'!I7 -> 3Q23 | K3: ='Historical Financials'!J7 -> 4Q23 | L3: ='Historical Financials'!K7 -> 1Q24 | M3: ='Historical Financials'!L7 -> 2Q24 | N3: ='Historical Financials'!M7 -> 3Q24 | O3: ='Historical Financials'!N7 -> 4Q24 | ... R3: ='Historical Financials'!Q7 -> 3Q25 | S3: ='Historical Financials'!#REF! -> #REF! | T3: ='Historical Financials'!#REF! -> #REF! | V3: =K3 -> 4Q23 | W3: =L3 -> 1Q24 | X3: =M3 -> 2Q24 | Y3: =N3 -> 3Q24 | Z3: =O3 -> 4Q24 | AA3: =P3 -> 1Q25 | AB3: =Q3 -> 2Q25 | AC3: =R3 -> 3Q25 | ... AE3: =T3 -> #REF!
B4: ($ In Millions) | C4: ='Historical Financials'!C8 -> 44926 | D4: ='Historical Financials'!D8 -> 45291 | E4: ='Historical Financials'!E8 -> 45657 | F4: ='Historical Financials'!#REF! -> #REF! | H4: ='Historical Financials'!G8 -> 45016 | I4: ='Historical Financials'!H8 -> 45107 | J4: ='Historical Financials'!I8 -> 45199 | K4: ='Historical Financials'!J8 -> 45291 | L4: ='Historical Financials'!K8 -> 45382 | M4: ='Historical Financials'!L8 -> 45473 | N4: ='Historical Financials'!M8 -> 45565 | O4: ='Historical Financials'!N8 -> 45657 | ... R4: ='Historical Financials'!Q8 -> 45930 | S4: ='Historical Financials'!#REF! -> #REF! | T4: ='Historical Financials'!#REF! -> #REF! | V4: =K4 -> 45291 | W4: =L4 -> 45382 | X4: =M4 -> 45473 | Y4: =N4 -> 45565 | Z4: =O4 -> 45657 | AA4: =P4 -> 45747 | AB4: =Q4 -> 45838 | AC4: =R4 -> 45930 | ... AE4: =T4 -> #REF!
B6: XXX | V6: =SUM(H6:K6) -> 0 | W6: =SUM(I6:L6) -> 0 | X6: =SUM(J6:M6) -> 0 | Y6: =SUM(K6:N6) -> 0 | Z6: =SUM(L6:O6) -> 0 | AA6: =SUM(M6:P6) -> 0 | AB6: =SUM(N6:Q6) -> 0 | AC6: =SUM(O6:R6) -> 0 | ... AE6: =SUM(Q6:T6) -> 0 | AG6: =SUM(AE6/AA6)-1 -> #DIV/0!
B7: XXX | V7: =SUM(H7:K7) -> 0 | W7: =SUM(I7:L7) -> 0 | X7: =SUM(J7:M7) -> 0 | Y7: =SUM(K7:N7) -> 0 | Z7: =SUM(L7:O7) -> 0 | AA7: =SUM(M7:P7) -> 0 | AB7: =SUM(N7:Q7) -> 0 | AC7: =SUM(O7:R7) -> 0 | ... AE7: =SUM(Q7:T7) -> 0 | AG7: =SUM(AE7/AA7)-1 -> #DIV/0!
B8: XXX | V8: =SUM(H8:K8) -> 0 | W8: =SUM(I8:L8) -> 0 | X8: =SUM(J8:M8) -> 0 | Y8: =SUM(K8:N8) -> 0 | Z8: =SUM(L8:O8) -> 0 | AA8: =SUM(M8:P8) -> 0 | AB8: =SUM(N8:Q8) -> 0 | AC8: =SUM(O8:R8) -> 0 | ... AE8: =SUM(Q8:T8) -> 0 | AG8: =SUM(AE8/AA8)-1 -> #DIV/0!
B9: XXX | V9: =SUM(H9:K9) -> 0 | W9: =SUM(I9:L9) -> 0 | X9: =SUM(J9:M9) -> 0 | Y9: =SUM(K9:N9) -> 0 | Z9: =SUM(L9:O9) -> 0 | AA9: =SUM(M9:P9) -> 0 | AB9: =SUM(N9:Q9) -> 0 | AC9: =SUM(O9:R9) -> 0 | ... AE9: =SUM(Q9:T9) -> 0 | AG9: =SUM(AE9/AA9)-1 -> #DIV/0!
B10: XXX | V10: =SUM(H10:K10) -> 0 | W10: =SUM(I10:L10) -> 0 | X10: =SUM(J10:M10) -> 0 | Y10: =SUM(K10:N10) -> 0 | Z10: =SUM(L10:O10) -> 0 | AA10: =SUM(M10:P10) -> 0 | AB10: =SUM(N10:Q10) -> 0 | AC10: =SUM(O10:R10) -> 0 | ... AE10: =SUM(Q10:T10) -> 0 | AG10: =SUM(AE10/AA10)-1 -> #DIV/0!
B11: XXX | V11: =SUM(H11:K11) -> 0 | W11: =SUM(I11:L11) -> 0 | X11: =SUM(J11:M11) -> 0 | Y11: =SUM(K11:N11) -> 0 | Z11: =SUM(L11:O11) -> 0 | AA11: =SUM(M11:P11) -> 0 | AB11: =SUM(N11:Q11) -> 0 | AC11: =SUM(O11:R11) -> 0 | ... AE11: =SUM(Q11:T11) -> 0 | AG11: =SUM(AE11/AA11)-1 -> #DIV/0!
B12: Total Revenue | C12: =SUM(C6:C11) -> 0 | D12: =SUM(D6:D11) -> 0 | E12: =SUM(E6:E11) -> 0 | F12: =SUM(F6:F11) -> 0 | H12: =SUM(H6:H11) -> 0 | I12: =SUM(I6:I11) -> 0 | J12: =SUM(J6:J11) -> 0 | K12: =SUM(K6:K11) -> 0 | L12: =SUM(L6:L11) -> 0 | M12: =SUM(M6:M11) -> 0 | N12: =SUM(N6:N11) -> 0 | O12: =SUM(O6:O11) -> 0 | ... T12: =SUM(T6:T11) -> 0 | V12: =SUM(V6:V11) -> 0 | W12: =SUM(W6:W11) -> 0 | X12: =SUM(X6:X11) -> 0 | Y12: =SUM(Y6:Y11) -> 0 | Z12: =SUM(Z6:Z11) -> 0 | AA12: =SUM(AA6:AA11) -> 0 | AB12: =SUM(AB6:AB11) -> 0 | AC12: =SUM(AC6:AC11) -> 0 | ... AE12: =SUM(AE6:AE11) -> 0 | AG12: =SUM(AE12/AA12)-1 -> #DIV/0!
B13: Y/Y Growth (%) | C13: =SUM(C12/#REF!)-1 -> #REF! | D13: =SUM(D12/C12)-1 -> #DIV/0! | E13: =SUM(E12/D12)-1 -> #DIV/0! | F13: =SUM(F12/E12)-1 -> #DIV/0! | L13: =SUM(L12/H12)-1 -> #DIV/0! | M13: =SUM(M12/I12)-1 -> #DIV/0! | N13: =SUM(N12/J12)-1 -> #DIV/0! | O13: =SUM(O12/K12)-1 -> #DIV/0! | P13: =SUM(P12/L12)-1 -> #DIV/0! | Q13: =SUM(Q12/M12)-1 -> #DIV/0! | R13: =SUM(R12/N12)-1 -> #DIV/0! | S13: =SUM(S12/O12)-1 -> #DIV/0! | T13: =SUM(T12/P12)-1 -> #DIV/0! | Z13: =SUM(Z12/V12)-1 -> #DIV/0! | AA13: =SUM(AA12/W12)-1 -> #DIV/0! | AB13: =SUM(AB12/X12)-1 -> #DIV/0! | AC13: =SUM(AC12/Y12)-1 -> #DIV/0! | AD13: =SUM(AD12/Z12)-1 -> #DIV/0! | AE13: =SUM(AE12/AA12)-1 -> #DIV/0! | AG13: =SUM(AE13-AA13)*10000 -> #DIV/0!
B14: Q/Q Growth (%) | C14: N/A | D14: N/A | E14: N/A | F14: N/A | I14: =SUM(I12/H12)-1 -> #DIV/0! | J14: =SUM(J12/I12)-1 -> #DIV/0! | K14: =SUM(K12/J12)-1 -> #DIV/0! | L14: =SUM(L12/K12)-1 -> #DIV/0! | M14: =SUM(M12/L12)-1 -> #DIV/0! | N14: =SUM(N12/M12)-1 -> #DIV/0! | O14: =SUM(O12/N12)-1 -> #DIV/0! | P14: =SUM(P12/O12)-1 -> #DIV/0! | ... T14: =SUM(T12/S12)-1 -> #DIV/0! | V14: N/A | W14: N/A | X14: N/A | Y14: N/A | Z14: N/A | AA14: N/A | AB14: N/A | AC14: N/A | AD14: N/A | AE14: N/A
B16: (-) Cost of Sales | V16: =SUM(H16:K16) -> 0 | W16: =SUM(I16:L16) -> 0 | X16: =SUM(J16:M16) -> 0 | Y16: =SUM(K16:N16) -> 0 | Z16: =SUM(L16:O16) -> 0 | AA16: =SUM(M16:P16) -> 0 | AB16: =SUM(N16:Q16) -> 0 | AC16: =SUM(O16:R16) -> 0 | ... AE16: =SUM(Q16:T16) -> 0 | AG16: =SUM(AE16/AA16)-1 -> #DIV/0!
B17: Gross Profit | C17: =SUM(C12+SUM(C16:C16)) -> 0 | D17: =SUM(D12+SUM(D16:D16)) -> 0 | E17: =SUM(E12+SUM(E16:E16)) -> 0 | F17: =SUM(F12+SUM(F16:F16)) -> 0 | H17: =SUM(H12+SUM(H16:H16)) -> 0 | I17: =SUM(I12+SUM(I16:I16)) -> 0 | J17: =SUM(J12+SUM(J16:J16)) -> 0 | K17: =SUM(K12+SUM(K16:K16)) -> 0 | L17: =SUM(L12+SUM(L16:L16)) -> 0 | M17: =SUM(M12+SUM(M16:M16)) -> 0 | N17: =SUM(N12+SUM(N16:N16)) -> 0 | O17: =SUM(O12+SUM(O16:O16)) -> 0 | ... T17: =SUM(T12+SUM(T16:T16)) -> 0 | V17: =SUM(V12+SUM(V16:V16)) -> 0 | W17: =SUM(W12+SUM(W16:W16)) -> 0 | X17: =SUM(X12+SUM(X16:X16)) -> 0 | Y17: =SUM(Y12+SUM(Y16:Y16)) -> 0 | Z17: =SUM(Z12+SUM(Z16:Z16)) -> 0 | AA17: =SUM(AA12+SUM(AA16:AA16)) -> 0 | AB17: =SUM(AB12+SUM(AB16:AB16)) -> 0 | AC17: =SUM(AC12+SUM(AC16:AC16)) -> 0 | ... AE17: =SUM(AE12+SUM(AE16:AE16)) -> 0 | AG17: =SUM(AE17/AA17)-1 -> #DIV/0!
B18: Gross Margin (%) | C18: =C17/C12 -> #DIV/0! | D18: =D17/D12 -> #DIV/0! | E18: =E17/E12 -> #DIV/0! | F18: =F17/F12 -> #DIV/0! | H18: =H17/H12 -> #DIV/0! | I18: =I17/I12 -> #DIV/0! | J18: =J17/J12 -> #DIV/0! | K18: =K17/K12 -> #DIV/0! | L18: =L17/L12 -> #DIV/0! | M18: =M17/M12 -> #DIV/0! | N18: =N17/N12 -> #DIV/0! | O18: =O17/O12 -> #DIV/0! | ... T18: =T17/T12 -> #DIV/0! | V18: =V17/V12 -> #DIV/0! | W18: =W17/W12 -> #DIV/0! | X18: =X17/X12 -> #DIV/0! | Y18: =Y17/Y12 -> #DIV/0! | Z18: =Z17/Z12 -> #DIV/0! | AA18: =AA17/AA12 -> #DIV/0! | AB18: =AB17/AB12 -> #DIV/0! | AC18: =AC17/AC12 -> #DIV/0! | ... AE18: =AE17/AE12 -> #DIV/0! | AG18: =SUM(AE18-AA18)*10000 -> #DIV/0!
B20: (-) XXX | V20: =SUM(H20:K20) -> 0 | W20: =SUM(I20:L20) -> 0 | X20: =SUM(J20:M20) -> 0 | Y20: =SUM(K20:N20) -> 0 | Z20: =SUM(L20:O20) -> 0 | AA20: =SUM(M20:P20) -> 0 | AB20: =SUM(N20:Q20) -> 0 | AC20: =SUM(O20:R20) -> 0 | ... AE20: =SUM(Q20:T20) -> 0 | AG20: =SUM(AE20/AA20)-1 -> #DIV/0!
B21: (-) XXX | V21: =SUM(H21:K21) -> 0 | W21: =SUM(I21:L21) -> 0 | X21: =SUM(J21:M21) -> 0 | Y21: =SUM(K21:N21) -> 0 | Z21: =SUM(L21:O21) -> 0 | AA21: =SUM(M21:P21) -> 0 | AB21: =SUM(N21:Q21) -> 0 | AC21: =SUM(O21:R21) -> 0 | ... AE21: =SUM(Q21:T21) -> 0 | AG21: =SUM(AE21/AA21)-1 -> #DIV/0!
B22: (-) XXX | V22: =SUM(H22:K22) -> 0 | W22: =SUM(I22:L22) -> 0 | X22: =SUM(J22:M22) -> 0 | Y22: =SUM(K22:N22) -> 0 | Z22: =SUM(L22:O22) -> 0 | AA22: =SUM(M22:P22) -> 0 | AB22: =SUM(N22:Q22) -> 0 | AC22: =SUM(O22:R22) -> 0 | ... AE22: =SUM(Q22:T22) -> 0 | AG22: =SUM(AE22/AA22)-1 -> #DIV/0!
B23: (-) XXX | V23: =SUM(H23:K23) -> 0 | W23: =SUM(I23:L23) -> 0 | X23: =SUM(J23:M23) -> 0 | Y23: =SUM(K23:N23) -> 0 | Z23: =SUM(L23:O23) -> 0 | AA23: =SUM(M23:P23) -> 0 | AB23: =SUM(N23:Q23) -> 0 | AC23: =SUM(O23:R23) -> 0 | ... AE23: =SUM(Q23:T23) -> 0 | AG23: =SUM(AE23/AA23)-1 -> #DIV/0!
B24: (-) XXX | V24: =SUM(H24:K24) -> 0 | W24: =SUM(I24:L24) -> 0 | X24: =SUM(J24:M24) -> 0 | Y24: =SUM(K24:N24) -> 0 | Z24: =SUM(L24:O24) -> 0 | AA24: =SUM(M24:P24) -> 0 | AB24: =SUM(N24:Q24) -> 0 | AC24: =SUM(O24:R24) -> 0 | ... AE24: =SUM(Q24:T24) -> 0 | AG24: =SUM(AE24/AA24)-1 -> #DIV/0!
B25: Earning before Interest & Taxes (EBIT) | C25: =SUM(C17+SUM(C20:C24)) -> 0 | D25: =SUM(D17+SUM(D20:D24)) -> 0 | E25: =SUM(E17+SUM(E20:E24)) -> 0 | F25: =SUM(F17+SUM(F20:F24)) -> 0 | H25: =SUM(H17+SUM(H20:H24)) -> 0 | I25: =SUM(I17+SUM(I20:I24)) -> 0 | J25: =SUM(J17+SUM(J20:J24)) -> 0 | K25: =SUM(K17+SUM(K20:K24)) -> 0 | L25: =SUM(L17+SUM(L20:L24)) -> 0 | M25: =SUM(M17+SUM(M20:M24)) -> 0 | N25: =SUM(N17+SUM(N20:N24)) -> 0 | O25: =SUM(O17+SUM(O20:O24)) -> 0 | ... T25: =SUM(T17+SUM(T20:T24)) -> 0 | V25: =SUM(V17+SUM(V20:V24)) -> 0 | W25: =SUM(W17+SUM(W20:W24)) -> 0 | X25: =SUM(X17+SUM(X20:X24)) -> 0 | Y25: =SUM(Y17+SUM(Y20:Y24)) -> 0 | Z25: =SUM(Z17+SUM(Z20:Z24)) -> 0 | AA25: =SUM(AA17+SUM(AA20:AA24)) -> 0 | AB25: =SUM(AB17+SUM(AB20:AB24)) -> 0 | AC25: =SUM(AC17+SUM(AC20:AC24)) -> 0 | ... AE25: =SUM(AE17+SUM(AE20:AE24)) -> 0 | AG25: =SUM(AE25/AA25)-1 -> #DIV/0!
B26: Operating Margin (%) | C26: =C25/C12 -> #DIV/0! | D26: =D25/D12 -> #DIV/0! | E26: =E25/E12 -> #DIV/0! | F26: =F25/F12 -> #DIV/0! | H26: =H25/H12 -> #DIV/0! | I26: =I25/I12 -> #DIV/0! | J26: =J25/J12 -> #DIV/0! | K26: =K25/K12 -> #DIV/0! | L26: =L25/L12 -> #DIV/0! | M26: =M25/M12 -> #DIV/0! | N26: =N25/N12 -> #DIV/0! | O26: =O25/O12 -> #DIV/0! | ... T26: =T25/T12 -> #DIV/0! | V26: =V25/V12 -> #DIV/0! | W26: =W25/W12 -> #DIV/0! | X26: =X25/X12 -> #DIV/0! | Y26: =Y25/Y12 -> #DIV/0! | Z26: =Z25/Z12 -> #DIV/0! | AA26: =AA25/AA12 -> #DIV/0! | AB26: =AB25/AB12 -> #DIV/0! | AC26: =AC25/AC12 -> #DIV/0! | ... AE26: =AE25/AE12 -> #DIV/0! | AG26: =SUM(AE26-AA26)*10000 -> #DIV/0!
B28: (+) Depreciation and Amortization (D&A) | V28: =SUM(H28:K28) -> 0 | W28: =SUM(I28:L28) -> 0 | X28: =SUM(J28:M28) -> 0 | Y28: =SUM(K28:N28) -> 0 | Z28: =SUM(L28:O28) -> 0 | AA28: =SUM(M28:P28) -> 0 | AB28: =SUM(N28:Q28) -> 0 | AC28: =SUM(O28:R28) -> 0 | ... AE28: =SUM(Q28:T28) -> 0 | AG28: =SUM(AE28/AA28)-1 -> #DIV/0!
B29: EBITDA | C29: =SUM(C25+SUM(C28:C28)) -> 0 | D29: =SUM(D25+SUM(D28:D28)) -> 0 | E29: =SUM(E25+SUM(E28:E28)) -> 0 | F29: =SUM(F25+SUM(F28:F28)) -> 0 | H29: =SUM(H25+SUM(H28:H28)) -> 0 | I29: =SUM(I25+SUM(I28:I28)) -> 0 | J29: =SUM(J25+SUM(J28:J28)) -> 0 | K29: =SUM(K25+SUM(K28:K28)) -> 0 | L29: =SUM(L25+SUM(L28:L28)) -> 0 | M29: =SUM(M25+SUM(M28:M28)) -> 0 | N29: =SUM(N25+SUM(N28:N28)) -> 0 | O29: =SUM(O25+SUM(O28:O28)) -> 0 | ... T29: =SUM(T25+SUM(T28:T28)) -> 0 | V29: =SUM(V25+SUM(V28:V28)) -> 0 | W29: =SUM(W25+SUM(W28:W28)) -> 0 | X29: =SUM(X25+SUM(X28:X28)) -> 0 | Y29: =SUM(Y25+SUM(Y28:Y28)) -> 0 | Z29: =SUM(Z25+SUM(Z28:Z28)) -> 0 | AA29: =SUM(AA25+SUM(AA28:AA28)) -> 0 | AB29: =SUM(AB25+SUM(AB28:AB28)) -> 0 | AC29: =SUM(AC25+SUM(AC28:AC28)) -> 0 | ... AE29: =SUM(AE25+SUM(AE28:AE28)) -> 0 | AG29: =SUM(AE29/AA29)-1 -> #DIV/0!
B30: EBITDA Margin (%) | C30: =C29/C12 -> #DIV/0! | D30: =D29/D12 -> #DIV/0! | E30: =E29/E12 -> #DIV/0! | F30: =F29/F12 -> #DIV/0! | H30: =H29/H12 -> #DIV/0! | I30: =I29/I12 -> #DIV/0! | J30: =J29/J12 -> #DIV/0! | K30: =K29/K12 -> #DIV/0! | L30: =L29/L12 -> #DIV/0! | M30: =M29/M12 -> #DIV/0! | N30: =N29/N12 -> #DIV/0! | O30: =O29/O12 -> #DIV/0! | ... T30: =T29/T12 -> #DIV/0! | V30: =V29/V12 -> #DIV/0! | W30: =W29/W12 -> #DIV/0! | X30: =X29/X12 -> #DIV/0! | Y30: =Y29/Y12 -> #DIV/0! | Z30: =Z29/Z12 -> #DIV/0! | AA30: =AA29/AA12 -> #DIV/0! | AB30: =AB29/AB12 -> #DIV/0! | AC30: =AC29/AC12 -> #DIV/0! | ... AE30: =AE29/AE12 -> #DIV/0! | AG30: =SUM(AE30-AA30)*10000 -> #DIV/0!
B32: (+) Stock-Based Compensation (SBC) | V32: =SUM(H32:K32) -> 0 | W32: =SUM(I32:L32) -> 0 | X32: =SUM(J32:M32) -> 0 | Y32: =SUM(K32:N32) -> 0 | Z32: =SUM(L32:O32) -> 0 | AA32: =SUM(M32:P32) -> 0 | AB32: =SUM(N32:Q32) -> 0 | AC32: =SUM(O32:R32) -> 0 | ... AE32: =SUM(Q32:T32) -> 0 | AG32: =SUM(AE32/AA32)-1 -> #DIV/0!
B33: (+) XXX | V33: =SUM(H33:K33) -> 0 | W33: =SUM(I33:L33) -> 0 | X33: =SUM(J33:M33) -> 0 | Y33: =SUM(K33:N33) -> 0 | Z33: =SUM(L33:O33) -> 0 | AA33: =SUM(M33:P33) -> 0 | AB33: =SUM(N33:Q33) -> 0 | AC33: =SUM(O33:R33) -> 0 | ... AE33: =SUM(Q33:T33) -> 0 | AG33: =SUM(AE33/AA33)-1 -> #DIV/0!
B34: Adj. EBITDA | C34: =+SUM(C29+SUM(C32:C32)) -> 0 | D34: =+SUM(D29+SUM(D32:D32)) -> 0 | E34: =+SUM(E29+SUM(E32:E32)) -> 0 | F34: =+SUM(F29+SUM(F32:F32)) -> 0 | H34: =+SUM(H29+SUM(H32:H32)) -> 0 | I34: =+SUM(I29+SUM(I32:I32)) -> 0 | J34: =+SUM(J29+SUM(J32:J32)) -> 0 | K34: =+SUM(K29+SUM(K32:K32)) -> 0 | L34: =+SUM(L29+SUM(L32:L32)) -> 0 | M34: =+SUM(M29+SUM(M32:M32)) -> 0 | N34: =+SUM(N29+SUM(N32:N32)) -> 0 | O34: =+SUM(O29+SUM(O32:O32)) -> 0 | ... T34: =+SUM(T29+SUM(T32:T32)) -> 0 | V34: =+SUM(V29+SUM(V32:V32)) -> 0 | W34: =+SUM(W29+SUM(W32:W32)) -> 0 | X34: =+SUM(X29+SUM(X32:X32)) -> 0 | Y34: =+SUM(Y29+SUM(Y32:Y32)) -> 0 | Z34: =+SUM(Z29+SUM(Z32:Z32)) -> 0 | AA34: =+SUM(AA29+SUM(AA32:AA32)) -> 0 | AB34: =+SUM(AB29+SUM(AB32:AB32)) -> 0 | AC34: =+SUM(AC29+SUM(AC32:AC32)) -> 0 | ... AE34: =+SUM(AE29+SUM(AE32:AE32)) -> 0 | AG34: =SUM(AE34/AA34)-1 -> #DIV/0!
B35: Adj. EBITDA Margin (%) | C35: =C34/C12 -> #DIV/0! | D35: =D34/D12 -> #DIV/0! | E35: =E34/E12 -> #DIV/0! | F35: =F34/F12 -> #DIV/0! | H35: =H34/H12 -> #DIV/0! | I35: =I34/I12 -> #DIV/0! | J35: =J34/J12 -> #DIV/0! | K35: =K34/K12 -> #DIV/0! | L35: =L34/L12 -> #DIV/0! | M35: =M34/M12 -> #DIV/0! | N35: =N34/N12 -> #DIV/0! | O35: =O34/O12 -> #DIV/0! | ... T35: =T34/T12 -> #DIV/0! | V35: =V34/V12 -> #DIV/0! | W35: =W34/W12 -> #DIV/0! | X35: =X34/X12 -> #DIV/0! | Y35: =Y34/Y12 -> #DIV/0! | Z35: =Z34/Z12 -> #DIV/0! | AA35: =AA34/AA12 -> #DIV/0! | AB35: =AB34/AB12 -> #DIV/0! | AC35: =AC34/AC12 -> #DIV/0! | ... AE35: =AE34/AE12 -> #DIV/0! | AG35: =SUM(AE35-AA35)*10000 -> #DIV/0!
B37: (-) Capital Expenditures | V37: =SUM(H37:K37) -> 0 | W37: =SUM(I37:L37) -> 0 | X37: =SUM(J37:M37) -> 0 | Y37: =SUM(K37:N37) -> 0 | Z37: =SUM(L37:O37) -> 0 | AA37: =SUM(M37:P37) -> 0 | AB37: =SUM(N37:Q37) -> 0 | AC37: =SUM(O37:R37) -> 0 | ... AE37: =SUM(Q37:T37) -> 0 | AG37: =SUM(AE37/AA37)-1 -> #DIV/0!
B38: (-) Cash Taxes | V38: =SUM(H38:K38) -> 0 | W38: =SUM(I38:L38) -> 0 | X38: =SUM(J38:M38) -> 0 | Y38: =SUM(K38:N38) -> 0 | Z38: =SUM(L38:O38) -> 0 | AA38: =SUM(M38:P38) -> 0 | AB38: =SUM(N38:Q38) -> 0 | AC38: =SUM(O38:R38) -> 0 | ... AE38: =SUM(Q38:T38) -> 0 | AG38: =SUM(AE38/AA38)-1 -> #DIV/0!
B39: (-) Cash Interest | V39: =SUM(H39:K39) -> 0 | W39: =SUM(I39:L39) -> 0 | X39: =SUM(J39:M39) -> 0 | Y39: =SUM(K39:N39) -> 0 | Z39: =SUM(L39:O39) -> 0 | AA39: =SUM(M39:P39) -> 0 | AB39: =SUM(N39:Q39) -> 0 | AC39: =SUM(O39:R39) -> 0 | ... AE39: =SUM(Q39:T39) -> 0 | AG39: =SUM(AE39/AA39)-1 -> #DIV/0!
B40: (-) Mandatory Outflows | V40: =SUM(H40:K40) -> 0 | W40: =SUM(I40:L40) -> 0 | X40: =SUM(J40:M40) -> 0 | Y40: =SUM(K40:N40) -> 0 | Z40: =SUM(L40:O40) -> 0 | AA40: =SUM(M40:P40) -> 0 | AB40: =SUM(N40:Q40) -> 0 | AC40: =SUM(O40:R40) -> 0 | ... AE40: =SUM(Q40:T40) -> 0 | AG40: =SUM(AE40/AA40)-1 -> #DIV/0!
B41: (+/-) Changes in NWC | V41: =SUM(H41:K41) -> 0 | W41: =SUM(I41:L41) -> 0 | X41: =SUM(J41:M41) -> 0 | Y41: =SUM(K41:N41) -> 0 | Z41: =SUM(L41:O41) -> 0 | AA41: =SUM(M41:P41) -> 0 | AB41: =SUM(N41:Q41) -> 0 | AC41: =SUM(O41:R41) -> 0 | ... AE41: =SUM(Q41:T41) -> 0 | AG41: =SUM(AE41/AA41)-1 -> #DIV/0!
B42: Discretionary Cash-Flows | C42: =SUM(C34+SUM(C37:C41)) -> 0 | D42: =SUM(D34+SUM(D37:D41)) -> 0 | E42: =SUM(E34+SUM(E37:E41)) -> 0 | F42: =SUM(F34+SUM(F37:F41)) -> 0 | H42: =SUM(H34+SUM(H37:H41)) -> 0 | I42: =SUM(I34+SUM(I37:I41)) -> 0 | J42: =SUM(J34+SUM(J37:J41)) -> 0 | K42: =SUM(K34+SUM(K37:K41)) -> 0 | L42: =SUM(L34+SUM(L37:L41)) -> 0 | M42: =SUM(M34+SUM(M37:M41)) -> 0 | N42: =SUM(N34+SUM(N37:N41)) -> 0 | O42: =SUM(O34+SUM(O37:O41)) -> 0 | ... T42: =SUM(T34+SUM(T37:T41)) -> 0 | V42: =SUM(V34+SUM(V37:V41)) -> 0 | W42: =SUM(W34+SUM(W37:W41)) -> 0 | X42: =SUM(X34+SUM(X37:X41)) -> 0 | Y42: =SUM(Y34+SUM(Y37:Y41)) -> 0 | Z42: =SUM(Z34+SUM(Z37:Z41)) -> 0 | AA42: =SUM(AA34+SUM(AA37:AA41)) -> 0 | AB42: =SUM(AB34+SUM(AB37:AB41)) -> 0 | AC42: =SUM(AC34+SUM(AC37:AC41)) -> 0 | ... AE42: =SUM(AE34+SUM(AE37:AE41)) -> 0 | AG42: =SUM(AE42/AA42)-1 -> #DIV/0!
B44: (+/-) XXX | V44: =SUM(H44:K44) -> 0 | W44: =SUM(I44:L44) -> 0 | X44: =SUM(J44:M44) -> 0 | Y44: =SUM(K44:N44) -> 0 | Z44: =SUM(L44:O44) -> 0 | AA44: =SUM(M44:P44) -> 0 | AB44: =SUM(N44:Q44) -> 0 | AC44: =SUM(O44:R44) -> 0 | ... AE44: =SUM(Q44:T44) -> 0
B45: (+/-) XXX | V45: =SUM(H45:K45) -> 0 | W45: =SUM(I45:L45) -> 0 | X45: =SUM(J45:M45) -> 0 | Y45: =SUM(K45:N45) -> 0 | Z45: =SUM(L45:O45) -> 0 | AA45: =SUM(M45:P45) -> 0 | AB45: =SUM(N45:Q45) -> 0 | AC45: =SUM(O45:R45) -> 0 | ... AE45: =SUM(Q45:T45) -> 0
B46: (+/-) XXX | V46: =SUM(H46:K46) -> 0 | W46: =SUM(I46:L46) -> 0 | X46: =SUM(J46:M46) -> 0 | Y46: =SUM(K46:N46) -> 0 | Z46: =SUM(L46:O46) -> 0 | AA46: =SUM(M46:P46) -> 0 | AB46: =SUM(N46:Q46) -> 0 | AC46: =SUM(O46:R46) -> 0 | ... AE46: =SUM(Q46:T46) -> 0
B47: (+/-) XXX | V47: =SUM(H47:K47) -> 0 | W47: =SUM(I47:L47) -> 0 | X47: =SUM(J47:M47) -> 0 | Y47: =SUM(K47:N47) -> 0 | Z47: =SUM(L47:O47) -> 0 | AA47: =SUM(M47:P47) -> 0 | AB47: =SUM(N47:Q47) -> 0 | AC47: =SUM(O47:R47) -> 0 | ... AE47: =SUM(Q47:T47) -> 0
B48: (+/-) XXX | V48: =SUM(H48:K48) -> 0 | W48: =SUM(I48:L48) -> 0 | X48: =SUM(J48:M48) -> 0 | Y48: =SUM(K48:N48) -> 0 | Z48: =SUM(L48:O48) -> 0 | AA48: =SUM(M48:P48) -> 0 | AB48: =SUM(N48:Q48) -> 0 | AC48: =SUM(O48:R48) -> 0 | ... AE48: =SUM(Q48:T48) -> 0
...
