Workbook

Sheet Historical Financials
B2: Apple Inc. (NASDAQ: AAPL)
B3: Historical Financials
B4: $ mm except per share
A6: X | B6: Income Statement | C6: FYE | F6: FYE | G6: FYE | N6: Quarterly | T6: Quarterly | W6: Quarterly | X6: Quarterly | AK6: LTM | AR6: Variance
B7: Fiscal Period | C7: 2016 | D7: 2017 | E7: 2018 | F7: 2019 | G7: 2020 | H7: 2021 | I7: 2022 | J7: 2023 | K7: 2024 | L7: 2025 | N7: 1Q22 | O7: 2Q22 | P7: 3Q22 | Q7: 4Q22 | R7: 1Q23 | S7: 2Q23 | T7: 3Q23 | U7: 4Q23 | V7: 1Q24 | W7: 2Q24 | X7: 3Q24 | Y7: 4Q24 | Z7: 1Q25 | AA7: 2Q25 | AB7: 3Q25 | AC7: 4Q25 | AE7: =R7 -> 1Q23 | AF7: =S7 -> 2Q23 | AG7: =T7 -> 3Q23 | AH7: =U7 -> 4Q23 | AI7: =V7 -> 1Q24 | AJ7: =W7 -> 2Q24 | AK7: =X7 -> 3Q24 | AL7: =Y7 -> 4Q24 | ... AP7: =AC7 -> 4Q25
B8: Fiscal Period End Date | C8: 42643 | D8: 43008 | E8: 43372 | F8: 43737 | G8: 44104 | H8: 44469 | I8: 44834 | J8: 45192 | K8: 45559 | L8: 45927 | N8: 44560 | O8: 44650 | P8: 44742 | Q8: =I8 -> 44834 | R8: 44917 | S8: 45008 | T8: 45100 | U8: =J8 -> 45192 | V8: 45283 | W8: 45375 | X8: 45467 | Y8: =K8 -> 45559 | Z8: 45650 | AA8: 45741 | AB8: 45833 | AC8: =L8 -> 45927 | AE8: =R8 -> 44917 | AF8: =S8 -> 45008 | AG8: =T8 -> 45100 | AH8: =U8 -> 45192 | AI8: =V8 -> 45283 | AJ8: =W8 -> 45375 | AK8: =X8 -> 45467 | AL8: =Y8 -> 45559 | ... AP8: =AC8 -> 45927
B10: Consolidated Revenue | C10: 215639 | D10: 229234 | E10: 265595 | F10: 260174 | G10: 274515 | H10: 365817 | I10: 394328 | J10: 383285 | K10: 391035 | L10: 416161 | N10: 123945 | O10: 97278 | P10: 82959 | Q10: =SUM(I10-SUM(N10:P10)) -> 90146 | R10: 117154 | S10: 94836 | T10: 81797 | U10: =SUM(J10-SUM(R10:T10)) -> 89498 | V10: 119575 | W10: 90753 | X10: 85777 | Y10: =SUM(K10-SUM(V10:X10)) -> 94930 | Z10: 124300 | AA10: 95359 | AB10: 94036 | AC10: =SUM(L10-SUM(Z10:AB10)) -> 102466 | AE10: =SUM(O10:R10) -> 387537 | AF10: =SUM(P10:S10) -> 385095 | AG10: =SUM(Q10:T10) -> 383933 | AH10: =SUM(R10:U10) -> 383285 | AI10: =SUM(S10:V10) -> 385706 | AJ10: =SUM(T10:W10) -> 381623 | AK10: =SUM(U10:X10) -> 385603 | AL10: =SUM(V10:Y10) -> 391035 | ... AP10: =SUM(Z10:AC10) -> 416161 | AR10: =SUM(AP10/AL10)-1 -> 0.064255118
B11: Total Revenue | C11: =+SUM(C10:C10) -> 215639 | D11: =+SUM(D10:D10) -> 229234 | E11: =+SUM(E10:E10) -> 265595 | F11: =+SUM(F10:F10) -> 260174 | G11: =+SUM(G10:G10) -> 274515 | H11: =+SUM(H10:H10) -> 365817 | I11: =+SUM(I10:I10) -> 394328 | J11: =+SUM(J10:J10) -> 383285 | ... L11: =+SUM(L10:L10) -> 416161 | N11: =+SUM(N10:N10) -> 123945 | O11: =+SUM(O10:O10) -> 97278 | P11: =+SUM(P10:P10) -> 82959 | Q11: =+SUM(Q10:Q10) -> 90146 | R11: =+SUM(R10:R10) -> 117154 | S11: =+SUM(S10:S10) -> 94836 | T11: =+SUM(T10:T10) -> 81797 | U11: =+SUM(U10:U10) -> 89498 | ... AC11: =+SUM(AC10:AC10) -> 102466 | AE11: =+SUM(AE10:AE10) -> 387537 | AF11: =+SUM(AF10:AF10) -> 385095 | AG11: =+SUM(AG10:AG10) -> 383933 | AH11: =+SUM(AH10:AH10) -> 383285 | AI11: =+SUM(AI10:AI10) -> 385706 | AJ11: =+SUM(AJ10:AJ10) -> 381623 | AK11: =+SUM(AK10:AK10) -> 385603 | AL11: =+SUM(AL10:AL10) -> 391035 | ... AP11: =+SUM(AP10:AP10) -> 416161 | AR11: =SUM(AP11/AL11)-1 -> 0.064255118
B13: Cost of Sales | C13: -131376 | D13: -141048 | E13: -163756 | F13: -161782 | G13: -169559 | H13: -212981 | I13: -223546 | J13: -214137 | K13: -210352 | L13: -220960 | N13: -69702 | O13: -54719 | P13: -47074 | Q13: =SUM(I13-SUM(N13:P13)) -> -52051 | R13: -66822 | S13: -52860 | T13: -45384 | U13: =SUM(J13-SUM(R13:T13)) -> -49071 | V13: -64720 | W13: -48482 | X13: -46099 | Y13: =SUM(K13-SUM(V13:X13)) -> -51051 | Z13: -66025 | AA13: -50492 | AB13: -50318 | AC13: =SUM(L13-SUM(Z13:AB13)) -> -54125 | AE13: =SUM(O13:R13) -> -220666 | AF13: =SUM(P13:S13) -> -218807 | AG13: =SUM(Q13:T13) -> -217117 | AH13: =SUM(R13:U13) -> -214137 | AI13: =SUM(S13:V13) -> -212035 | AJ13: =SUM(T13:W13) -> -207657 | AK13: =SUM(U13:X13) -> -208372 | AL13: =SUM(V13:Y13) -> -210352 | ... AP13: =SUM(Z13:AC13) -> -220960 | AR13: =SUM(AP13/AL13)-1 -> 0.050429756
B14: Gross Profit | C14: =+SUM(C11+SUM(C13:C13)) -> 84263 | D14: =+SUM(D11+SUM(D13:D13)) -> 88186 | E14: =+SUM(E11+SUM(E13:E13)) -> 101839 | F14: =+SUM(F11+SUM(F13:F13)) -> 98392 | G14: =+SUM(G11+SUM(G13:G13)) -> 104956 | H14: =+SUM(H11+SUM(H13:H13)) -> 152836 | I14: =+SUM(I11+SUM(I13:I13)) -> 170782 | J14: =+SUM(J11+SUM(J13:J13)) -> 169148 | ... L14: =+SUM(L11+SUM(L13:L13)) -> 195201 | N14: =+SUM(N11+SUM(N13:N13)) -> 54243 | O14: =+SUM(O11+SUM(O13:O13)) -> 42559 | P14: =+SUM(P11+SUM(P13:P13)) -> 35885 | Q14: =+SUM(Q11+SUM(Q13:Q13)) -> 38095 | R14: =+SUM(R11+SUM(R13:R13)) -> 50332 | S14: =+SUM(S11+SUM(S13:S13)) -> 41976 | T14: =+SUM(T11+SUM(T13:T13)) -> 36413 | U14: =+SUM(U11+SUM(U13:U13)) -> 40427 | ... AC14: =+SUM(AC11+SUM(AC13:AC13)) -> 48341 | AE14: =+SUM(AE11+SUM(AE13:AE13)) -> 166871 | AF14: =+SUM(AF11+SUM(AF13:AF13)) -> 166288 | AG14: =+SUM(AG11+SUM(AG13:AG13)) -> 166816 | AH14: =+SUM(AH11+SUM(AH13:AH13)) -> 169148 | AI14: =+SUM(AI11+SUM(AI13:AI13)) -> 173671 | AJ14: =+SUM(AJ11+SUM(AJ13:AJ13)) -> 173966 | AK14: =+SUM(AK11+SUM(AK13:AK13)) -> 177231 | AL14: =+SUM(AL11+SUM(AL13:AL13)) -> 180683 | ... AP14: =+SUM(AP11+SUM(AP13:AP13)) -> 195201 | AR14: =SUM(AP14/AL14)-1 -> 0.080350669
B15: Gross Margin (%) | C15: =C14/C11 -> 0.39075956 | D15: =D14/D11 -> 0.3846986 | E15: =E14/E11 -> 0.38343719 | F15: =F14/F11 -> 0.37817768 | G15: =G14/G11 -> 0.38233248 | H15: =H14/H11 -> 0.4177936 | I15: =I14/I11 -> 0.43309631 | J15: =J14/J11 -> 0.4413113 | ... L15: =L14/L11 -> 0.46905164 | N15: =N14/N11 -> 0.43763766 | O15: =O14/O11 -> 0.43749872 | P15: =P14/P11 -> 0.43256307 | Q15: =Q14/Q11 -> 0.42259224 | R15: =R14/R11 -> 0.42962255 | S15: =S14/S11 -> 0.44261673 | T15: =T14/T11 -> 0.44516303 | U15: =U14/U11 -> 0.45170842 | ... AC15: =AC14/AC11 -> 0.471776 | AE15: =AE14/AE11 -> 0.43059372 | AF15: =AF14/AF11 -> 0.43181033 | AG15: =AG14/AG11 -> 0.43449248 | AH15: =AH14/AH11 -> 0.4413113 | AI15: =AI14/AI11 -> 0.45026782 | AJ15: =AJ14/AJ11 -> 0.45585827 | AK15: =AK14/AK11 -> 0.45962039 | AL15: =AL14/AL11 -> 0.4620635 | ... AP15: =AP14/AP11 -> 0.46905164 | AR15: =SUM(AP15-AL15)*1000 -> 6.9881429
B17: Research & Development | C17: -10045 | D17: -11581 | E17: -14236 | F17: -16217 | G17: -18752 | H17: -21914 | I17: -26251 | J17: -29915 | K17: -31370 | L17: -34550 | N17: -6306 | O17: -6387 | P17: -6797 | Q17: =SUM(I17-SUM(N17:P17)) -> -6761 | R17: -7709 | S17: -7457 | T17: -7442 | U17: =SUM(J17-SUM(R17:T17)) -> -7307 | V17: -7696 | W17: -7903 | X17: -8006 | Y17: =SUM(K17-SUM(V17:X17)) -> -7765 | Z17: -8268 | AA17: -8550 | AB17: -8866 | AC17: =SUM(L17-SUM(Z17:AB17)) -> -8866 | AE17: =SUM(O17:R17) -> -27654 | AF17: =SUM(P17:S17) -> -28724 | AG17: =SUM(Q17:T17) -> -29369 | AH17: =SUM(R17:U17) -> -29915 | AI17: =SUM(S17:V17) -> -29902 | AJ17: =SUM(T17:W17) -> -30348 | AK17: =SUM(U17:X17) -> -30912 | AL17: =SUM(V17:Y17) -> -31370 | ... AP17: =SUM(Z17:AC17) -> -34550 | AR17: =SUM(AP17/AL17)-1 -> 0.10137074
B18: Selling, General & Administrative | C18: -14194 | D18: -15261 | E18: -16705 | F18: -18245 | G18: -19916 | H18: -21973 | I18: -25094 | J18: -24932 | K18: -26097 | L18: -27601 | N18: -6449 | O18: -6193 | P18: -6012 | Q18: =SUM(I18-SUM(N18:P18)) -> -6440 | R18: -6607 | S18: -6201 | T18: -5973 | U18: =SUM(J18-SUM(R18:T18)) -> -6151 | V18: -6786 | W18: -6468 | X18: -6320 | Y18: =SUM(K18-SUM(V18:X18)) -> -6523 | Z18: -7175 | AA18: -6728 | AB18: -6650 | AC18: =SUM(L18-SUM(Z18:AB18)) -> -7048 | AE18: =SUM(O18:R18) -> -25252 | AF18: =SUM(P18:S18) -> -25260 | AG18: =SUM(Q18:T18) -> -25221 | AH18: =SUM(R18:U18) -> -24932 | AI18: =SUM(S18:V18) -> -25111 | AJ18: =SUM(T18:W18) -> -25378 | AK18: =SUM(U18:X18) -> -25725 | AL18: =SUM(V18:Y18) -> -26097 | ... AP18: =SUM(Z18:AC18) -> -27601 | AR18: =SUM(AP18/AL18)-1 -> 0.057631145
B19: Profit From Operations | C19: =SUM(C14+SUM(C17:C18)) -> 60024 | D19: =SUM(D14+SUM(D17:D18)) -> 61344 | E19: =SUM(E14+SUM(E17:E18)) -> 70898 | F19: =SUM(F14+SUM(F17:F18)) -> 63930 | G19: =SUM(G14+SUM(G17:G18)) -> 66288 | H19: =SUM(H14+SUM(H17:H18)) -> 108949 | I19: =SUM(I14+SUM(I17:I18)) -> 119437 | J19: =SUM(J14+SUM(J17:J18)) -> 114301 | ... L19: =SUM(L14+SUM(L17:L18)) -> 133050 | N19: =SUM(N14+SUM(N17:N18)) -> 41488 | O19: =SUM(O14+SUM(O17:O18)) -> 29979 | P19: =SUM(P14+SUM(P17:P18)) -> 23076 | Q19: =SUM(Q14+SUM(Q17:Q18)) -> 24894 | R19: =SUM(R14+SUM(R17:R18)) -> 36016 | S19: =SUM(S14+SUM(S17:S18)) -> 28318 | T19: =SUM(T14+SUM(T17:T18)) -> 22998 | U19: =SUM(U14+SUM(U17:U18)) -> 26969 | ... AC19: =SUM(AC14+SUM(AC17:AC18)) -> 32427 | AE19: =SUM(AE14+SUM(AE17:AE18)) -> 113965 | AF19: =SUM(AF14+SUM(AF17:AF18)) -> 112304 | AG19: =SUM(AG14+SUM(AG17:AG18)) -> 112226 | AH19: =SUM(AH14+SUM(AH17:AH18)) -> 114301 | AI19: =SUM(AI14+SUM(AI17:AI18)) -> 118658 | AJ19: =SUM(AJ14+SUM(AJ17:AJ18)) -> 118240 | AK19: =SUM(AK14+SUM(AK17:AK18)) -> 120594 | AL19: =SUM(AL14+SUM(AL17:AL18)) -> 123216 | ... AP19: =SUM(AP14+SUM(AP17:AP18)) -> 133050 | AR19: =SUM(AP19/AL19)-1 -> 0.079811063
B20: Operating Margin (%) | C20: =C19/C11 -> 0.2783541 | D20: =D19/D11 -> 0.26760428 | E20: =E19/E11 -> 0.26694027 | F20: =F19/F11 -> 0.24572017 | G20: =G19/G11 -> 0.24147314 | H20: =H19/H11 -> 0.29782378 | I20: =I19/I11 -> 0.30288744 | J20: =J19/J11 -> 0.29821412 | ... L20: =L19/L11 -> 0.319708 | N20: =N19/N11 -> 0.33472911 | O20: =O19/O11 -> 0.30817862 | P20: =P19/P11 -> 0.2781615 | Q20: =Q19/Q11 -> 0.27615202 | R20: =R19/R11 -> 0.30742442 | S20: =S19/S11 -> 0.29859969 | T20: =T19/T11 -> 0.28115946 | U20: =U19/U11 -> 0.30133634 | ... AC20: =AC19/AC11 -> 0.31646595 | AE20: =AE19/AE11 -> 0.29407515 | AF20: =AF19/AF11 -> 0.29162674 | AG20: =AG19/AG11 -> 0.29230621 | AH20: =AH19/AH11 -> 0.29821412 | AI20: =AI19/AI11 -> 0.30763846 | AJ20: =AJ19/AJ11 -> 0.30983457 | AK20: =AK19/AK11 -> 0.31274134 | AL20: =AL19/AL11 -> 0.31510223 | ... AP20: =AP19/AP11 -> 0.319708 | AR20: =SUM(AP20-AL20)*1000 -> 4.6057689
B22: Other income/(expense), net | C22: 1348 | D22: 2745 | E22: 2005 | F22: 1807 | G22: 803 | H22: 258 | I22: -334 | J22: -565 | K22: 269 | L22: -321 | N22: -247 | O22: 160 | P22: -10 | Q22: =SUM(I22-SUM(N22:P22)) -> -237 | R22: -393 | S22: 64 | T22: -265 | U22: =SUM(J22-SUM(R22:T22)) -> 29 | V22: -50 | W22: 158 | X22: 142 | Y22: =SUM(K22-SUM(V22:X22)) -> 19 | Z22: -248 | AA22: -279 | AB22: -171 | AC22: =SUM(L22-SUM(Z22:AB22)) -> 377 | AE22: =SUM(O22:R22) -> -480 | AF22: =SUM(P22:S22) -> -576 | AG22: =SUM(Q22:T22) -> -831 | AH22: =SUM(R22:U22) -> -565 | AI22: =SUM(S22:V22) -> -222 | AJ22: =SUM(T22:W22) -> -128 | AK22: =SUM(U22:X22) -> 279 | AL22: =SUM(V22:Y22) -> 269 | ... AP22: =SUM(Z22:AC22) -> -321 | AR22: =SUM(AP22/AL22)-1 -> -2.1933086
B23: Net loss before provision for income taxes | C23: =SUM(C22:C22)+C19 -> 61372 | D23: =SUM(D22:D22)+D19 -> 64089 | E23: =SUM(E22:E22)+E19 -> 72903 | F23: =SUM(F22:F22)+F19 -> 65737 | G23: =SUM(G22:G22)+G19 -> 67091 | H23: =SUM(H22:H22)+H19 -> 109207 | I23: =SUM(I22:I22)+I19 -> 119103 | J23: =SUM(J22:J22)+J19 -> 113736 | ... L23: =SUM(L22:L22)+L19 -> 132729 | N23: =SUM(N22:N22)+N19 -> 41241 | O23: =SUM(O22:O22)+O19 -> 30139 | P23: =SUM(P22:P22)+P19 -> 23066 | Q23: =SUM(Q22:Q22)+Q19 -> 24657 | R23: =SUM(R22:R22)+R19 -> 35623 | S23: =SUM(S22:S22)+S19 -> 28382 | T23: =SUM(T22:T22)+T19 -> 22733 | U23: =SUM(U22:U22)+U19 -> 26998 | ... AC23: =SUM(AC22:AC22)+AC19 -> 32804 | AE23: =SUM(AE22:AE22)+AE19 -> 113485 | AF23: =SUM(AF22:AF22)+AF19 -> 111728 | AG23: =SUM(AG22:AG22)+AG19 -> 111395 | AH23: =SUM(AH22:AH22)+AH19 -> 113736 | AI23: =SUM(AI22:AI22)+AI19 -> 118436 | AJ23: =SUM(AJ22:AJ22)+AJ19 -> 118112 | AK23: =SUM(AK22:AK22)+AK19 -> 120873 | AL23: =SUM(AL22:AL22)+AL19 -> 123485 | ... AP23: =SUM(AP22:AP22)+AP19 -> 132729 | AR23: =SUM(AP23/AL23)-1 -> 0.074859295
B25: Provision for taxes | C25: -15685 | D25: -15738 | E25: -13372 | F25: -10481 | G25: -9680 | H25: -14527 | I25: -19300 | J25: -16741 | K25: -29749 | L25: -20719 | N25: -6611 | O25: -5129 | P25: -3624 | Q25: =SUM(I25-SUM(N25:P25)) -> -3936 | R25: -5625 | S25: -4222 | T25: -2852 | U25: =SUM(J25-SUM(R25:T25)) -> -4042 | V25: -6407 | W25: -4422 | X25: -4046 | Y25: =SUM(K25-SUM(V25:X25)) -> -14874 | Z25: -6254 | AA25: -4530 | AB25: -4597 | AC25: =SUM(L25-SUM(Z25:AB25)) -> -5338 | AE25: =SUM(O25:R25) -> -18314 | AF25: =SUM(P25:S25) -> -17407 | AG25: =SUM(Q25:T25) -> -16635 | AH25: =SUM(R25:U25) -> -16741 | AI25: =SUM(S25:V25) -> -17523 | AJ25: =SUM(T25:W25) -> -17723 | AK25: =SUM(U25:X25) -> -18917 | AL25: =SUM(V25:Y25) -> -29749 | ... AP25: =SUM(Z25:AC25) -> -20719 | AR25: =SUM(AP25/AL25)-1 -> -0.30353961
B26: Net loss | C26: =SUM(C23+C25) -> 45687 | D26: =SUM(D23+D25) -> 48351 | E26: =SUM(E23+E25) -> 59531 | F26: =SUM(F23+F25) -> 55256 | G26: =SUM(G23+G25) -> 57411 | H26: =SUM(H23+H25) -> 94680 | I26: =SUM(I23+I25) -> 99803 | J26: =SUM(J23+J25) -> 96995 | ... L26: =SUM(L23+L25) -> 112010 | N26: =SUM(N23+N25) -> 34630 | O26: =SUM(O23+O25) -> 25010 | P26: =SUM(P23+P25) -> 19442 | Q26: =SUM(Q23+Q25) -> 20721 | R26: =SUM(R23+R25) -> 29998 | S26: =SUM(S23+S25) -> 24160 | T26: =SUM(T23+T25) -> 19881 | U26: =SUM(U23+U25) -> 22956 | ... AC26: =SUM(AC23+AC25) -> 27466 | AE26: =SUM(AE23+AE25) -> 95171 | AF26: =SUM(AF23+AF25) -> 94321 | AG26: =SUM(AG23+AG25) -> 94760 | AH26: =SUM(AH23+AH25) -> 96995 | AI26: =SUM(AI23+AI25) -> 100913 | AJ26: =SUM(AJ23+AJ25) -> 100389 | AK26: =SUM(AK23+AK25) -> 101956 | AL26: =SUM(AL23+AL25) -> 93736 | ... AP26: =SUM(AP23+AP25) -> 112010 | AR26: =SUM(AP26/AL26)-1 -> 0.19495178
B27: Net Margin (%) | C27: =C26/C11 -> 0.21186798 | D27: =D26/D11 -> 0.21092421 | E27: =E26/E11 -> 0.22414202 | F27: =F26/F11 -> 0.21238095 | G27: =G26/G11 -> 0.20913611 | H27: =H26/H11 -> 0.25881793 | I27: =I26/I11 -> 0.25309641 | J27: =J26/J11 -> 0.25306234 | ... L27: =L26/L11 -> 0.26915064 | N27: =N26/N11 -> 0.27939812 | O27: =O26/O11 -> 0.25709821 | P27: =P26/P11 -> 0.23435673 | Q27: =Q26/Q11 -> 0.22986045 | R27: =R26/R11 -> 0.25605613 | S27: =S26/S11 -> 0.25475558 | T27: =T26/T11 -> 0.24305292 | U27: =U26/U11 -> 0.25649735 | ... AC27: =AC26/AC11 -> 0.26804989 | AE27: =AE26/AE11 -> 0.24557913 | AF27: =AF26/AF11 -> 0.24492917 | AG27: =AG26/AG11 -> 0.2468139 | AH27: =AH26/AH11 -> 0.25306234 | AI27: =AI26/AI11 -> 0.26163192 | AJ27: =AJ26/AJ11 -> 0.26305804 | AK27: =AK26/AK11 -> 0.26440666 | AL27: =AL26/AL11 -> 0.23971256 | ... AP27: =AP26/AP11 -> 0.26915064 | AR27: =SUM(AP27-AL27)*1000 -> 29.438084
B29: Basic shares | C29: 21883.281 | D29: 20868.968 | E29: 19821.51 | F29: 18471.336 | G29: 17352.119 | H29: 16701.272 | I29: 16215.963 | J29: 15744.231 | K29: 15343.783 | L29: 14948.5 | N29: 16391.724 | O29: 16278.802 | P29: 16162.945 | Q29: =I29 -> 16215.963 | R29: 15892.723 | S29: 15787.154 | T29: 15697.614 | U29: =J29 -> 15744.231 | V29: 15509.763 | W29: 15405.856 | X29: 15287.521 | Y29: =K29 -> 15343.783 | Z29: 15081.724 | AA29: 14994.082 | AB29: 14902.886 | AC29: =L29 -> 14948.5 | AE29: =R29 -> 15892.723 | AF29: =S29 -> 15787.154 | AG29: =T29 -> 15697.614 | AH29: =U29 -> 15744.231 | AI29: =V29 -> 15509.763 | AJ29: =W29 -> 15405.856 | AK29: =X29 -> 15287.521 | AL29: =Y29 -> 15343.783 | ... AP29: =AC29 -> 14948.5 | AR29: =SUM(AP29/AL29)-1 -> -0.025761769
B30: Basic EPS | C30: =C26/C29 -> 2.0877582 | D30: =D26/D29 -> 2.3168851 | E30: =E26/E29 -> 3.0033534 | F30: =F26/F29 -> 2.9914458 | G30: =G26/G29 -> 3.3085873 | H30: =H26/H29 -> 5.6690293 | I30: =I26/I29 -> 6.1546144 | J30: =J26/J29 -> 6.1606693 | ... L30: =L26/L29 -> 7.4930595 | N30: =N26/N29 -> 2.1126515 | O30: =O26/O29 -> 1.5363538 | P30: =P26/P29 -> 1.2028748 | Q30: =Q26/Q29 -> 1.277815 | R30: =R26/R29 -> 1.8875305 | S30: =S26/S29 -> 1.5303582 | T30: =T26/T29 -> 1.2664982 | U30: =U26/U29 -> 1.4580579 | ... AC30: =AC26/AC29 -> 1.837375 | AE30: =AE26/AE29 -> 5.9883382 | AF30: =AF26/AF29 -> 5.9745411 | AG30: =AG26/AG29 -> 6.0365862 | AH30: =AH26/AH29 -> 6.1606693 | AI30: =AI26/AI29 -> 6.5064179 | AJ30: =AJ26/AJ29 -> 6.5162884 | AK30: =AK26/AK29 -> 6.6692304 | AL30: =AL26/AL29 -> 6.1090541 | ... AP30: =AP26/AP29 -> 7.4930595 | AR30: =SUM(AP30/AL30)-1 -> 0.22654987
B32: Fully Diluted Shares | C32: 22001.127 | D32: 21006.767 | E32: 20000.436 | F32: 18595.651 | G32: 17528.214 | H32: 16864.919 | I32: 16325.819 | J32: 15812.547 | K32: 15408.095 | L32: 15004.697 | N32: 16519.291 | O32: 16403.316 | P32: 16262.203 | Q32: =I32 -> 16325.819 | R32: 15955.718 | S32: 15847.05 | T32: 15775.021 | U32: =J32 -> 15812.547 | V32: 15576.641 | W32: 15464.709 | X32: 15348.175 | Y32: =K32 -> 15408.095 | Z32: 15150.865 | AA32: 15056.133 | AB32: 14948.179 | AC32: =L32 -> 15004.697 | AE32: =R32 -> 15955.718 | AF32: =S32 -> 15847.05 | AG32: =T32 -> 15775.021 | AH32: =U32 -> 15812.547 | AI32: =V32 -> 15576.641 | AJ32: =W32 -> 15464.709 | AK32: =X32 -> 15348.175 | AL32: =Y32 -> 15408.095 | ... AP32: =AC32 -> 15004.697 | AR32: =SUM(AP32/AL32)-1 -> -0.026180913
B33: Diluted EPS | C33: =C26/C32 -> 2.0765754 | D33: =D26/D32 -> 2.3016869 | E33: =E26/E32 -> 2.9764851 | F33: =F26/F32 -> 2.9714475 | G33: =G26/G32 -> 3.275348 | H33: =H26/H32 -> 5.6140204 | I33: =I26/I32 -> 6.1132002 | J33: =J26/J32 -> 6.1340529 | ... L33: =L26/L32 -> 7.4649958 | N33: =N26/N32 -> 2.0963369 | O33: =O26/O32 -> 1.5246917 | P33: =P26/P32 -> 1.195533 | Q33: =Q26/Q32 -> 1.2692166 | R33: =R26/R32 -> 1.8800784 | S33: =S26/S32 -> 1.524574 | T33: =T26/T32 -> 1.2602836 | U33: =U26/U32 -> 1.4517585 | ... AC33: =AC26/AC32 -> 1.8304935 | AE33: =AE26/AE32 -> 5.9646955 | AF33: =AF26/AF32 -> 5.9519595 | AG33: =AG26/AG32 -> 6.0069651 | AH33: =AH26/AH32 -> 6.1340529 | AI33: =AI26/AI32 -> 6.4784827 | AJ33: =AJ26/AJ32 -> 6.4914898 | AK33: =AK26/AK32 -> 6.6428745 | AL33: =AL26/AL32 -> 6.0835554 | ... AP33: =AP26/AP32 -> 7.4649958 | AR33: =SUM(AP33/AL33)-1 -> 0.2270778
A35: X | B35: Balance Sheet | C35: FYE | N35: Quarterly | AK35: LTM | AR35: Variance
B36: =B7 -> Fiscal Period | C36: =C7 -> 2016 | D36: =D7 -> 2017 | E36: =E7 -> 2018 | F36: =F7 -> 2019 | G36: =G7 -> 2020 | H36: =H7 -> 2021 | I36: =I7 -> 2022 | ... L36: =L7 -> 2025 | N36: =N7 -> 1Q22 | O36: =O7 -> 2Q22 | P36: =P7 -> 3Q22 | Q36: =Q7 -> 4Q22 | R36: =R7 -> 1Q23 | S36: =S7 -> 2Q23 | T36: =T7 -> 3Q23 | U36: =U7 -> 4Q23 | ... AC36: =AC7 -> 4Q25 | AE36: =AE7 -> 1Q23 | AF36: =AF7 -> 2Q23 | AG36: =AG7 -> 3Q23 | AH36: =AH7 -> 4Q23 | AI36: =AI7 -> 1Q24 | AJ36: =AJ7 -> 2Q24 | AK36: =AK7 -> 3Q24 | AL36: =AL7 -> 4Q24 | ... AP36: =AP7 -> 4Q25
B37: =B8 -> Fiscal Period End Date | C37: =C8 -> 42643 | D37: =D8 -> 43008 | E37: =E8 -> 43372 | F37: =F8 -> 43737 | G37: =G8 -> 44104 | H37: =H8 -> 44469 | I37: =I8 -> 44834 | ... L37: =L8 -> 45927 | N37: =N8 -> 44560 | O37: =O8 -> 44650 | P37: =P8 -> 44742 | Q37: =Q8 -> 44834 | R37: =R8 -> 44917 | S37: =S8 -> 45008 | T37: =T8 -> 45100 | U37: =U8 -> 45192 | ... AC37: =AC8 -> 45927 | AE37: =AE8 -> 44917 | AF37: =AF8 -> 45008 | AG37: =AG8 -> 45100 | AH37: =AH8 -> 45192 | AI37: =AI8 -> 45283 | AJ37: =AJ8 -> 45375 | AK37: =AK8 -> 45467 | AL37: =AL8 -> 45559 | ... AP37: =AP8 -> 45927
B39: Cash/Equivalents | C39: 20484 | D39: 20289 | E39: 25913 | F39: 48844 | G39: 38016 | H39: 34940 | I39: 23646 | J39: 29965 | K39: 29943 | L39: 35934 | N39: 37119 | O39: 28098 | P39: 27502 | Q39: =I39 -> 23646 | R39: 20535 | S39: 24687 | T39: 28408 | U39: =J39 -> 29965 | V39: 40760 | W39: 32695 | X39: 25565 | Y39: =K39 -> 29943 | Z39: 30299 | AA39: 28162 | AB39: 36269 | AC39: =L39 -> 35934 | AE39: =R39 -> 20535 | AF39: =S39 -> 24687 | AG39: =T39 -> 28408 | AH39: =U39 -> 29965 | AI39: =V39 -> 40760 | AJ39: =W39 -> 32695 | AK39: =X39 -> 25565 | AL39: =Y39 -> 29943 | ... AP39: =AC39 -> 35934 | AR39: =SUM(AP39/AL39)-1 -> 0.20008015
B40: Marketable Securities, Current | C40: 46671 | D40: 53892 | E40: 40388 | F40: 51713 | G40: 52927 | H40: 27699 | I40: 24658 | J40: 31590 | K40: 35228 | L40: 18763 | N40: 26794 | O40: 23413 | P40: 20729 | Q40: =I40 -> 24658 | R40: 30820 | S40: 31185 | T40: 34074 | U40: =J40 -> 31590 | V40: 32340 | W40: 34455 | X40: 36236 | Y40: =K40 -> 35228 | Z40: 23476 | AA40: 20336 | AB40: 19103 | AC40: =L40 -> 18763 | AE40: =R40 -> 30820 | AF40: =S40 -> 31185 | AG40: =T40 -> 34074 | AH40: =U40 -> 31590 | AI40: =V40 -> 32340 | AJ40: =W40 -> 34455 | AK40: =X40 -> 36236 | AL40: =Y40 -> 35228 | ... AP40: =AC40 -> 18763 | AR40: =SUM(AP40/AL40)-1 -> -0.4673839
B41: Accounts Receivable | C41: 15754 | D41: 17874 | E41: 23186 | F41: 22926 | G41: 16120 | H41: 26278 | I41: 28184 | J41: 29508 | K41: 66243 | L41: 39777 | N41: 30213 | O41: 20815 | P41: 21803 | Q41: =I41 -> 28184 | R41: 23752 | S41: 17936 | T41: 19549 | U41: =J41 -> 29508 | V41: 23194 | W41: 21837 | X41: 22795 | Y41: =K41 -> 66243 | Z41: 29639 | AA41: 49798 | AB41: 46835 | AC41: =L41 -> 39777 | AE41: =R41 -> 23752 | AF41: =S41 -> 17936 | AG41: =T41 -> 19549 | AH41: =U41 -> 29508 | AI41: =V41 -> 23194 | AJ41: =W41 -> 21837 | AK41: =X41 -> 22795 | AL41: =Y41 -> 66243 | ... AP41: =AC41 -> 39777 | AR41: =SUM(AP41/AL41)-1 -> -0.39952901
B42: Inventory | C42: 2132 | D42: 4855 | E42: 3956 | F42: 4106 | G42: 4061 | H42: 6580 | I42: 4946 | J42: 6331 | K42: 7286 | L42: 5718 | N42: 5876 | O42: 5460 | P42: 5433 | Q42: =I42 -> 4946 | R42: 6820 | S42: 7482 | T42: 7351 | U42: =J42 -> 6331 | V42: 6511 | W42: 6232 | X42: 6165 | Y42: =K42 -> 7286 | Z42: 6911 | AA42: 6269 | AB42: 5925 | AC42: =L42 -> 5718 | AE42: =R42 -> 6820 | AF42: =S42 -> 7482 | AG42: =T42 -> 7351 | AH42: =U42 -> 6331 | AI42: =V42 -> 6511 | AJ42: =W42 -> 6232 | AK42: =X42 -> 6165 | AL42: =Y42 -> 7286 | ... AP42: =AC42 -> 5718 | AR42: =SUM(AP42/AL42)-1 -> -0.21520725
B43: Other Current Assets | C43: 21828 | D43: =13936+17799 -> 31735 | E43: 37896 | F43: 35230 | G43: 32589 | H43: 39339 | I43: 53971 | J43: 46172 | K43: 14287 | L43: =33180+14585 -> 47765 | N43: 53152 | O43: 40394 | P43: 36825 | Q43: =I43 -> 53971 | R43: 46850 | S43: 31623 | T43: 33277 | U43: =J43 -> 46172 | V43: 40887 | W43: 33197 | X43: 34674 | Y43: =K43 -> 14287 | Z43: 42915 | AA43: 14109 | AB43: 14359 | AC43: =L43 -> 47765 | AE43: =R43 -> 46850 | AF43: =S43 -> 31623 | AG43: =T43 -> 33277 | AH43: =U43 -> 46172 | AI43: =V43 -> 40887 | AJ43: =W43 -> 33197 | AK43: =X43 -> 34674 | AL43: =Y43 -> 14287 | ... AP43: =AC43 -> 47765 | AR43: =SUM(AP43/AL43)-1 -> 2.3432491
B44: Total Current Assets | C44: =SUM(C39:C43) -> 106869 | D44: =SUM(D39:D43) -> 128645 | E44: =SUM(E39:E43) -> 131339 | F44: =SUM(F39:F43) -> 162819 | G44: =SUM(G39:G43) -> 143713 | H44: =SUM(H39:H43) -> 134836 | I44: =SUM(I39:I43) -> 135405 | J44: =SUM(J39:J43) -> 143566 | ... L44: =SUM(L39:L43) -> 147957 | N44: =SUM(N39:N43) -> 153154 | O44: =SUM(O39:O43) -> 118180 | P44: =SUM(P39:P43) -> 112292 | Q44: =SUM(Q39:Q43) -> 135405 | R44: =SUM(R39:R43) -> 128777 | S44: =SUM(S39:S43) -> 112913 | T44: =SUM(T39:T43) -> 122659 | U44: =SUM(U39:U43) -> 143566 | ... AC44: =SUM(AC39:AC43) -> 147957 | AE44: =SUM(AE39:AE43) -> 128777 | AF44: =SUM(AF39:AF43) -> 112913 | AG44: =SUM(AG39:AG43) -> 122659 | AH44: =SUM(AH39:AH43) -> 143566 | AI44: =SUM(AI39:AI43) -> 143692 | AJ44: =SUM(AJ39:AJ43) -> 128416 | AK44: =SUM(AK39:AK43) -> 125435 | AL44: =SUM(AL39:AL43) -> 152987 | ... AP44: =SUM(AP39:AP43) -> 147957 | AR44: =SUM(AP44/AL44)-1 -> -0.032878611
B46: Property, plant & equipment | C46: 27010 | D46: 33783 | E46: 41304 | F46: 37378 | G46: 36766 | H46: 39440 | I46: 42117 | J46: 43715 | K46: 45680 | L46: 49834 | N46: 39245 | O46: 39304 | P46: 40335 | Q46: =I46 -> 42117 | R46: 42951 | S46: 43398 | T46: 43550 | U46: =J46 -> 43715 | V46: 43666 | W46: 43546 | X46: 44502 | Y46: =K46 -> 45680 | Z46: 46069 | AA46: 46876 | AB46: 48508 | AC46: =L46 -> 49834 | AE46: =R46 -> 42951 | AF46: =S46 -> 43398 | AG46: =T46 -> 43550 | AH46: =U46 -> 43715 | AI46: =V46 -> 43666 | AJ46: =W46 -> 43546 | AK46: =X46 -> 44502 | AL46: =Y46 -> 45680 | ... AP46: =AC46 -> 49834 | AR46: =SUM(AP46/AL46)-1 -> 0.090936953
B47: Marketable Securities, Net of Current Portion | C47: 170430 | D47: 194714 | E47: 170799 | F47: 105341 | G47: 100887 | H47: 127877 | I47: 120805 | J47: 100544 | K47: 91479 | L47: 77723 | N47: 138683 | O47: 141219 | P47: 131077 | Q47: =I47 -> 120805 | R47: 114095 | S47: 110461 | T47: 104061 | U47: =J47 -> 100544 | V47: 99475 | W47: 95187 | X47: 91240 | Y47: =K47 -> 91479 | Z47: 87593 | AA47: 84424 | AB47: 77614 | AC47: =L47 -> 77723 | AE47: =R47 -> 114095 | AF47: =S47 -> 110461 | AG47: =T47 -> 104061 | AH47: =U47 -> 100544 | AI47: =V47 -> 99475 | AJ47: =W47 -> 95187 | AK47: =X47 -> 91240 | AL47: =Y47 -> 91479 | ... AP47: =AC47 -> 77723 | AR47: =SUM(AP47/AL47)-1 -> -0.15037331
B48: Other Assets | C48: =5414+3206+8757 -> 17377 | D48: 18177 | E48: 22283 | F48: 32978 | G48: 42522 | H48: 48849 | I48: 54428 | J48: 64758 | K48: 74834 | L48: 83727 | N48: 42071 | O48: 43921 | P48: 44567 | Q48: =I48 -> 54428 | R48: 52886 | S48: 57350 | T48: 56730 | U48: =J48 -> 64758 | V48: 58643 | W48: 62224 | X48: 62397 | Y48: =K48 -> 74834 | Z48: 77183 | AA48: 81259 | AB48: 82882 | AC48: =L48 -> 83727 | AE48: =R48 -> 52886 | AF48: =S48 -> 57350 | AG48: =T48 -> 56730 | AH48: =U48 -> 64758 | AI48: =V48 -> 58643 | AJ48: =W48 -> 62224 | AK48: =X48 -> 62397 | AL48: =Y48 -> 74834 | ... AP48: =AC48 -> 83727 | AR48: =SUM(AP48/AL48)-1 -> 0.11883636
B49: Total Assets | C49: =SUM(C46:C48)+C44 -> 321686 | D49: =SUM(D46:D48)+D44 -> 375319 | E49: =SUM(E46:E48)+E44 -> 365725 | F49: =SUM(F46:F48)+F44 -> 338516 | G49: =SUM(G46:G48)+G44 -> 323888 | H49: =SUM(H46:H48)+H44 -> 351002 | I49: =SUM(I46:I48)+I44 -> 352755 | J49: =SUM(J46:J48)+J44 -> 352583 | ... L49: =SUM(L46:L48)+L44 -> 359241 | N49: =SUM(N46:N48)+N44 -> 373153 | O49: =SUM(O46:O48)+O44 -> 342624 | P49: =SUM(P46:P48)+P44 -> 328271 | Q49: =SUM(Q46:Q48)+Q44 -> 352755 | R49: =SUM(R46:R48)+R44 -> 338709 | S49: =SUM(S46:S48)+S44 -> 324122 | T49: =SUM(T46:T48)+T44 -> 327000 | U49: =SUM(U46:U48)+U44 -> 352583 | ... AC49: =SUM(AC46:AC48)+AC44 -> 359241 | AE49: =SUM(AE46:AE48)+AE44 -> 338709 | AF49: =SUM(AF46:AF48)+AF44 -> 324122 | AG49: =SUM(AG46:AG48)+AG44 -> 327000 | AH49: =SUM(AH46:AH48)+AH44 -> 352583 | AI49: =SUM(AI46:AI48)+AI44 -> 345476 | AJ49: =SUM(AJ46:AJ48)+AJ44 -> 329373 | AK49: =SUM(AK46:AK48)+AK44 -> 323574 | AL49: =SUM(AL46:AL48)+AL44 -> 364980 | ... AP49: =SUM(AP46:AP48)+AP44 -> 359241 | AR49: =SUM(AP49/AL49)-1 -> -0.015724149
B51: Accounts Payable | C51: 37294 | D51: 44242 | E51: 55888 | F51: 46236 | G51: 42296 | H51: 54763 | I51: 64115 | J51: 62611 | K51: 68960 | L51: 69860 | N51: 74362 | O51: 52682 | P51: 48343 | Q51: =I51 -> 64115 | R51: 57918 | S51: 42945 | T51: 46699 | U51: =J51 -> 62611 | V51: 58146 | W51: 45753 | X51: 47574 | Y51: =K51 -> 68960 | Z51: 61910 | AA51: 54126 | AB51: 50374 | AC51: =L51 -> 69860 | AE51: =R51 -> 57918 | AF51: =S51 -> 42945 | AG51: =T51 -> 46699 | AH51: =U51 -> 62611 | AI51: =V51 -> 58146 | AJ51: =W51 -> 45753 | AK51: =X51 -> 47574 | AL51: =Y51 -> 68960 | ... AP51: =AC51 -> 69860 | AR51: =SUM(AP51/AL51)-1 -> 0.013051044
B52: Deferred Revenue | C52: 8080 | D52: 7548 | E52: 7543 | F52: 5522 | G52: 6643 | H52: 7612 | I52: 7912 | J52: 8061 | K52: 8249 | L52: 9055 | N52: 7876 | O52: 7920 | P52: 7728 | Q52: =I52 -> 7912 | R52: 7992 | S52: 8131 | T52: 8158 | U52: =J52 -> 8061 | V52: 8264 | W52: 8012 | X52: 8053 | Y52: =K52 -> 8249 | Z52: 8461 | AA52: 8976 | AB52: 8979 | AC52: =L52 -> 9055 | AE52: =R52 -> 7992 | AF52: =S52 -> 8131 | AG52: =T52 -> 8158 | AH52: =U52 -> 8061 | AI52: =V52 -> 8264 | AJ52: =W52 -> 8012 | AK52: =X52 -> 8053 | AL52: =Y52 -> 8249 | ... AP52: =AC52 -> 9055 | AR52: =SUM(AP52/AL52)-1 -> 0.097708813
B53: Other Current Liabilities | C53: 22027 | D53: 30551 | E53: 32687 | F53: 37720 | G53: 42684 | H53: 47493 | I53: 60845 | J53: 58829 | K53: 78304 | L53: 66387 | N53: 49167 | O53: 50248 | P53: 48811 | Q53: =I53 -> 60845 | R53: 59893 | S53: 56425 | T53: 58897 | U53: =J53 -> 58829 | V53: 54611 | W53: 57298 | X53: 60889 | Y53: =K53 -> 78304 | Z53: 61151 | AA53: 61849 | AB53: 62499 | AC53: =L53 -> 66387 | AE53: =R53 -> 59893 | AF53: =S53 -> 56425 | AG53: =T53 -> 58897 | AH53: =U53 -> 58829 | AI53: =V53 -> 54611 | AJ53: =W53 -> 57298 | AK53: =X53 -> 60889 | AL53: =Y53 -> 78304 | ... AP53: =AC53 -> 66387 | AR53: =SUM(AP53/AL53)-1 -> -0.1521889
...

Sheet Revenue Drivers
B2: Apple Inc. (NASDAQ: AAPL) | C2: FYE | N2: Quarterly | V2: Quarterly | W2: Quarterly | AE2: LTM | AI2: LTM | AR2: Variance
B3: Segment Anaysis | C3: ='Historical Financials'!C7 -> 2016 | D3: ='Historical Financials'!D7 -> 2017 | E3: ='Historical Financials'!E7 -> 2018 | F3: ='Historical Financials'!F7 -> 2019 | G3: ='Historical Financials'!G7 -> 2020 | H3: ='Historical Financials'!H7 -> 2021 | I3: ='Historical Financials'!I7 -> 2022 | J3: ='Historical Financials'!J7 -> 2023 | ... L3: ='Historical Financials'!L7 -> 2025 | N3: ='Historical Financials'!N7 -> 1Q22 | O3: ='Historical Financials'!O7 -> 2Q22 | P3: ='Historical Financials'!P7 -> 3Q22 | Q3: ='Historical Financials'!Q7 -> 4Q22 | R3: ='Historical Financials'!R7 -> 1Q23 | S3: ='Historical Financials'!S7 -> 2Q23 | T3: ='Historical Financials'!T7 -> 3Q23 | U3: ='Historical Financials'!U7 -> 4Q23 | ... AC3: ='Historical Financials'!AC7 -> 4Q25 | AE3: =R3 -> 1Q23 | AF3: =S3 -> 2Q23 | AG3: =T3 -> 3Q23 | AH3: =U3 -> 4Q23 | AI3: =V3 -> 1Q24 | AJ3: =W3 -> 2Q24 | AK3: =X3 -> 3Q24 | AL3: =Y3 -> 4Q24 | ... AP3: =AC3 -> 4Q25
B4: $ mm except per share | C4: ='Historical Financials'!C8 -> 42643 | D4: ='Historical Financials'!D8 -> 43008 | E4: ='Historical Financials'!E8 -> 43372 | F4: ='Historical Financials'!F8 -> 43737 | G4: ='Historical Financials'!G8 -> 44104 | H4: ='Historical Financials'!H8 -> 44469 | I4: ='Historical Financials'!I8 -> 44834 | J4: ='Historical Financials'!J8 -> 45192 | ... L4: ='Historical Financials'!L8 -> 45927 | N4: ='Historical Financials'!N8 -> 44560 | O4: ='Historical Financials'!O8 -> 44650 | P4: ='Historical Financials'!P8 -> 44742 | Q4: ='Historical Financials'!Q8 -> 44834 | R4: ='Historical Financials'!R8 -> 44917 | S4: ='Historical Financials'!S8 -> 45008 | T4: ='Historical Financials'!T8 -> 45100 | U4: ='Historical Financials'!U8 -> 45192 | ... AC4: ='Historical Financials'!AC8 -> 45927 | AE4: =R4 -> 44917 | AF4: =S4 -> 45008 | AG4: =T4 -> 45100 | AH4: =U4 -> 45192 | AI4: =V4 -> 45283 | AJ4: =W4 -> 45375 | AK4: =X4 -> 45467 | AL4: =Y4 -> 45559 | ... AP4: =AC4 -> 45927
A6: X | B6: Revenue by reportable segment
A8: X | B8: Revenue by End Product
B9: iPhone Revenue | C9: 136700 | D9: 141319 | E9: 164888 | F9: 142381 | G9: 137781 | H9: 191973 | I9: 205489 | J9: 200583 | K9: 201183 | L9: 209586 | N9: 71628 | O9: 50570 | P9: 40665 | Q9: =SUM(I9-SUM(N9:P9)) -> 42626 | R9: 65775 | S9: 51334 | T9: 39669 | U9: =SUM(J9-SUM(R9:T9)) -> 43805 | V9: 69702 | W9: 45963 | X9: 39296 | Y9: =SUM(K9-SUM(V9:X9)) -> 46222 | Z9: 69138 | AA9: 46841 | AB9: 44582 | AC9: =SUM(L9-SUM(Z9:AB9)) -> 49025 | AE9: =SUM(O9:R9) -> 199636 | AF9: =SUM(P9:S9) -> 200400 | AG9: =SUM(Q9:T9) -> 199404 | AH9: =SUM(R9:U9) -> 200583 | AI9: =SUM(S9:V9) -> 204510 | AJ9: =SUM(T9:W9) -> 199139 | AK9: =SUM(U9:X9) -> 198766 | AL9: =SUM(V9:Y9) -> 201183 | ... AP9: =SUM(Z9:AC9) -> 209586 | AR9: =SUM(AO9/AK9)-1 -> 0.04033386
B10: Mac Revenue | C10: 22831 | D10: 25850 | E10: 25198 | F10: 25740 | G10: 28622 | H10: 35190 | I10: 40177 | J10: 29357 | K10: 29984 | L10: 33708 | N10: 10852 | O10: 10435 | P10: 7382 | Q10: =SUM(I10-SUM(N10:P10)) -> 11508 | R10: 7735 | S10: 7168 | T10: 6840 | U10: =SUM(J10-SUM(R10:T10)) -> 7614 | V10: 7780 | W10: 7451 | X10: 7009 | Y10: =SUM(K10-SUM(V10:X10)) -> 7744 | Z10: 8987 | AA10: 7949 | AB10: 8046 | AC10: =SUM(L10-SUM(Z10:AB10)) -> 8726 | AE10: =SUM(O10:R10) -> 37060 | AF10: =SUM(P10:S10) -> 33793 | AG10: =SUM(Q10:T10) -> 33251 | AH10: =SUM(R10:U10) -> 29357 | AI10: =SUM(S10:V10) -> 29402 | AJ10: =SUM(T10:W10) -> 29685 | AK10: =SUM(U10:X10) -> 29854 | AL10: =SUM(V10:Y10) -> 29984 | ... AP10: =SUM(Z10:AC10) -> 33708 | AR10: =SUM(AO10/AK10)-1 -> 0.096201514
B11: iPad Revenue | C11: 20628 | D11: 19222 | E11: 18380 | F11: 21280 | G11: 23724 | H11: 31862 | I11: 29292 | J11: 28300 | K11: 26694 | L11: 28023 | N11: 7248 | O11: 7646 | P11: 7224 | Q11: =SUM(I11-SUM(N11:P11)) -> 7174 | R11: 9396 | S11: 6670 | T11: 5791 | U11: =SUM(J11-SUM(R11:T11)) -> 6443 | V11: 7023 | W11: 5559 | X11: 7162 | Y11: =SUM(K11-SUM(V11:X11)) -> 6950 | Z11: 8088 | AA11: 6402 | AB11: 6581 | AC11: =SUM(L11-SUM(Z11:AB11)) -> 6952 | AE11: =SUM(O11:R11) -> 31440 | AF11: =SUM(P11:S11) -> 30464 | AG11: =SUM(Q11:T11) -> 29031 | AH11: =SUM(R11:U11) -> 28300 | AI11: =SUM(S11:V11) -> 25927 | AJ11: =SUM(T11:W11) -> 24816 | AK11: =SUM(U11:X11) -> 26187 | AL11: =SUM(V11:Y11) -> 26694 | ... AP11: =SUM(Z11:AC11) -> 28023 | AR11: =SUM(AO11/AK11)-1 -> 0.07003475
B12: Services Revenue | C12: 24348 | D12: 29980 | E12: 39748 | F12: 46291 | G12: 53768 | H12: 68425 | I12: 78129 | J12: 85200 | K12: 96169 | L12: 109158 | N12: 19516 | O12: 19821 | P12: 19604 | Q12: =SUM(I12-SUM(N12:P12)) -> 19188 | R12: 20766 | S12: 20907 | T12: 21213 | U12: =SUM(J12-SUM(R12:T12)) -> 22314 | V12: 23117 | W12: 23867 | X12: 24213 | Y12: =SUM(K12-SUM(V12:X12)) -> 24972 | Z12: 26340 | AA12: 26645 | AB12: 27423 | AC12: =SUM(L12-SUM(Z12:AB12)) -> 28750 | AE12: =SUM(O12:R12) -> 79379 | AF12: =SUM(P12:S12) -> 80465 | AG12: =SUM(Q12:T12) -> 82074 | AH12: =SUM(R12:U12) -> 85200 | AI12: =SUM(S12:V12) -> 87551 | AJ12: =SUM(T12:W12) -> 90511 | AK12: =SUM(U12:X12) -> 93511 | AL12: =SUM(V12:Y12) -> 96169 | ... AP12: =SUM(Z12:AC12) -> 109158 | AR12: =SUM(AO12/AK12)-1 -> 0.12692624
B13: Wearables, Home, and Accessories Revenue | C13: 11132 | D13: 12863 | E13: 17381 | F13: 24482 | G13: 30620 | H13: 38367 | I13: 41241 | J13: 39845 | K13: 37005 | L13: 35686 | N13: 14701 | O13: 8806 | P13: 8084 | Q13: =SUM(I13-SUM(N13:P13)) -> 9650 | R13: 13482 | S13: 8757 | T13: 8284 | U13: =SUM(J13-SUM(R13:T13)) -> 9322 | V13: 11953 | W13: 7913 | X13: 8097 | Y13: =SUM(K13-SUM(V13:X13)) -> 9042 | Z13: 11747 | AA13: 7522 | AB13: 7404 | AC13: =SUM(L13-SUM(Z13:AB13)) -> 9013 | AE13: =SUM(O13:R13) -> 40022 | AF13: =SUM(P13:S13) -> 39973 | AG13: =SUM(Q13:T13) -> 40173 | AH13: =SUM(R13:U13) -> 39845 | AI13: =SUM(S13:V13) -> 38316 | AJ13: =SUM(T13:W13) -> 37472 | AK13: =SUM(U13:X13) -> 37285 | AL13: =SUM(V13:Y13) -> 37005 | ... AP13: =SUM(Z13:AC13) -> 35686 | AR13: =SUM(AO13/AK13)-1 -> -0.042108086
B14: Total Net Revenue | C14: =SUM(C9:C13) -> 215639 | D14: =SUM(D9:D13) -> 229234 | E14: =SUM(E9:E13) -> 265595 | F14: =SUM(F9:F13) -> 260174 | G14: =SUM(G9:G13) -> 274515 | H14: =SUM(H9:H13) -> 365817 | I14: =SUM(I9:I13) -> 394328 | J14: =SUM(J9:J13) -> 383285 | ... L14: =SUM(L9:L13) -> 416161 | N14: =SUM(N9:N13) -> 123945 | O14: =SUM(O9:O13) -> 97278 | P14: =SUM(P9:P13) -> 82959 | Q14: =SUM(Q9:Q13) -> 90146 | R14: =SUM(R9:R13) -> 117154 | S14: =SUM(S9:S13) -> 94836 | T14: =SUM(T9:T13) -> 81797 | U14: =SUM(U9:U13) -> 89498 | ... AC14: =SUM(AC9:AC13) -> 102466 | AE14: =SUM(AE9:AE13) -> 387537 | AF14: =SUM(AF9:AF13) -> 385095 | AG14: =SUM(AG9:AG13) -> 383933 | AH14: =SUM(AH9:AH13) -> 383285 | AI14: =SUM(AI9:AI13) -> 385706 | AJ14: =SUM(AJ9:AJ13) -> 381623 | AK14: =SUM(AK9:AK13) -> 385603 | AL14: =SUM(AL9:AL13) -> 391035 | ... AP14: =SUM(AP9:AP13) -> 416161 | AR14: =SUM(AO14/AK14)-1 -> 0.059703892
B15: Variance Check | C15: =C14-'Historical Financials'!C11 -> 0 | D15: =D14-'Historical Financials'!D11 -> 0 | E15: =E14-'Historical Financials'!E11 -> 0 | F15: =F14-'Historical Financials'!F11 -> 0 | G15: =G14-'Historical Financials'!G11 -> 0 | H15: =H14-'Historical Financials'!H11 -> 0 | I15: =I14-'Historical Financials'!I11 -> 0 | J15: =J14-'Historical Financials'!J11 -> 0 | ... L15: =L14-'Historical Financials'!L11 -> 0 | N15: =N14-'Historical Financials'!N11 -> 0 | O15: =O14-'Historical Financials'!O11 -> 0 | P15: =P14-'Historical Financials'!P11 -> 0 | Q15: =Q14-'Historical Financials'!Q11 -> 0 | R15: =R14-'Historical Financials'!R11 -> 0 | S15: =S14-'Historical Financials'!S11 -> 0 | T15: =T14-'Historical Financials'!T11 -> 0 | U15: =U14-'Historical Financials'!U11 -> 0 | ... AC15: =AC14-'Historical Financials'!AC11 -> 0 | AE15: =AE14-'Historical Financials'!AE11 -> 0 | AF15: =AF14-'Historical Financials'!AF11 -> 0 | AG15: =AG14-'Historical Financials'!AG11 -> 0 | AH15: =AH14-'Historical Financials'!AH11 -> 0 | AI15: =AI14-'Historical Financials'!AI11 -> 0 | AJ15: =AJ14-'Historical Financials'!AJ11 -> 0 | AK15: =AK14-'Historical Financials'!AK11 -> 0 | AL15: =AL14-'Historical Financials'!AL11 -> 0 | ... AO15: =AO14-'Historical Financials'!AO11 -> 0 | AP15: =AP14-'Historical Financials'!AQ11 -> 416161
B17: Segments as a % of Total Revenue
B18: =B9&"(%)" -> iPhone Revenue(%) | C18: =SUM(C9/C$14) -> 0.63392985 | D18: =SUM(D9/D$14) -> 0.61648359 | E18: =SUM(E9/E$14) -> 0.62082494 | F18: =SUM(F9/F$14) -> 0.54725299 | G18: =SUM(G9/G$14) -> 0.501907 | H18: =SUM(H9/H$14) -> 0.52477878 | I18: =SUM(I9/I$14) -> 0.52111187 | J18: =SUM(J9/J$14) -> 0.52332598 | ... L18: =SUM(L9/L$14) -> 0.50361759 | N18: =SUM(N9/N$14) -> 0.57790149 | O18: =SUM(O9/O$14) -> 0.51985033 | P18: =SUM(P9/P$14) -> 0.4901819 | Q18: =SUM(Q9/Q$14) -> 0.47285515 | R18: =SUM(R9/R$14) -> 0.5614405 | S18: =SUM(S9/S$14) -> 0.54129234 | T18: =SUM(T9/T$14) -> 0.48496889 | U18: =SUM(U9/U$14) -> 0.48945228 | ... AC18: =SUM(AC9/AC$14) -> 0.47845139 | AE18: =SUM(AE9/AE$14) -> 0.51514049 | AF18: =SUM(AF9/AF$14) -> 0.52039107 | AG18: =SUM(AG9/AG$14) -> 0.51937187 | AH18: =SUM(AH9/AH$14) -> 0.52332598 | AI18: =SUM(AI9/AI$14) -> 0.5302225 | AJ18: =SUM(AJ9/AJ$14) -> 0.52182127 | AK18: =SUM(AK9/AK$14) -> 0.51546798 | AL18: =SUM(AL9/AL$14) -> 0.51448847 | ... AP18: =SUM(AP9/AP$14) -> 0.50361759
B19: =B10&"(%)" -> Mac Revenue(%) | C19: =SUM(C10/C$14) -> 0.10587602 | D19: =SUM(D10/D$14) -> 0.11276687 | E19: =SUM(E10/E$14) -> 0.094873774 | F19: =SUM(F10/F$14) -> 0.09893379 | G19: =SUM(G10/G$14) -> 0.10426388 | H19: =SUM(H10/H$14) -> 0.096195639 | I19: =SUM(I10/I$14) -> 0.10188726 | J19: =SUM(J10/J$14) -> 0.076593136 | ... L19: =SUM(L10/L$14) -> 0.080997499 | N19: =SUM(N10/N$14) -> 0.087554964 | O19: =SUM(O10/O$14) -> 0.10726989 | P19: =SUM(P10/P$14) -> 0.088983715 | Q19: =SUM(Q10/Q$14) -> 0.12765957 | R19: =SUM(R10/R$14) -> 0.066024207 | S19: =SUM(S10/S$14) -> 0.075583112 | T19: =SUM(T10/T$14) -> 0.083621649 | U19: =SUM(U10/U$14) -> 0.085074527 | ... AC19: =SUM(AC10/AC$14) -> 0.085159955 | AE19: =SUM(AE10/AE$14) -> 0.095629579 | AF19: =SUM(AF10/AF$14) -> 0.087752373 | AG19: =SUM(AG10/AG$14) -> 0.086606257 | AH19: =SUM(AH10/AH$14) -> 0.076593136 | AI19: =SUM(AI10/AI$14) -> 0.076229045 | AJ19: =SUM(AJ10/AJ$14) -> 0.077786192 | AK19: =SUM(AK10/AK$14) -> 0.077421597 | AL19: =SUM(AL10/AL$14) -> 0.076678558 | ... AP19: =SUM(AP10/AP$14) -> 0.080997499
B20: =B11&"(%)" -> iPad Revenue(%) | C20: =SUM(C11/C$14) -> 0.095659876 | D20: =SUM(D11/D$14) -> 0.083853181 | E20: =SUM(E11/E$14) -> 0.06920311 | F20: =SUM(F11/F$14) -> 0.081791417 | G20: =SUM(G11/G$14) -> 0.086421507 | H20: =SUM(H11/H$14) -> 0.087098194 | I20: =SUM(I11/I$14) -> 0.074283338 | J20: =SUM(J11/J$14) -> 0.073835397 | ... L20: =SUM(L11/L$14) -> 0.06733692 | N20: =SUM(N11/N$14) -> 0.058477551 | O20: =SUM(O11/O$14) -> 0.078599478 | P20: =SUM(P11/P$14) -> 0.08707916 | Q20: =SUM(Q11/Q$14) -> 0.079582011 | R20: =SUM(R11/R$14) -> 0.080202127 | S20: =SUM(S11/S$14) -> 0.070331941 | T20: =SUM(T11/T$14) -> 0.070797218 | U20: =SUM(U11/U$14) -> 0.071990436 | ... AC20: =SUM(AC11/AC$14) -> 0.067846896 | AE20: =SUM(AE11/AE$14) -> 0.081127737 | AF20: =SUM(AF11/AF$14) -> 0.079107753 | AG20: =SUM(AG11/AG$14) -> 0.075614756 | AH20: =SUM(AH11/AH$14) -> 0.073835397 | AI20: =SUM(AI11/AI$14) -> 0.067219592 | AJ20: =SUM(AJ11/AJ$14) -> 0.065027527 | AK20: =SUM(AK11/AK$14) -> 0.067911816 | AL20: =SUM(AL11/AL$14) -> 0.068264989 | ... AP20: =SUM(AP11/AP$14) -> 0.06733692
B21: =B12&"(%)" -> Services Revenue(%) | C21: =SUM(C12/C$14) -> 0.11291093 | D21: =SUM(D12/D$14) -> 0.13078339 | E21: =SUM(E12/E$14) -> 0.14965643 | F21: =SUM(F12/F$14) -> 0.17792324 | G21: =SUM(G12/G$14) -> 0.19586544 | H21: =SUM(H12/H$14) -> 0.18704708 | I21: =SUM(I12/I$14) -> 0.19813201 | J21: =SUM(J12/J$14) -> 0.2222889 | ... L21: =SUM(L12/L$14) -> 0.26229752 | N21: =SUM(N12/N$14) -> 0.15745694 | O21: =SUM(O12/O$14) -> 0.20375624 | P21: =SUM(P12/P$14) -> 0.2363095 | Q21: =SUM(Q12/Q$14) -> 0.2128547 | R21: =SUM(R12/R$14) -> 0.17725387 | S21: =SUM(S12/S$14) -> 0.22045426 | T21: =SUM(T12/T$14) -> 0.25933714 | U21: =SUM(U12/U$14) -> 0.24932401 | ... AC21: =SUM(AC12/AC$14) -> 0.28058088 | AE21: =SUM(AE12/AE$14) -> 0.20482947 | AF21: =SUM(AF12/AF$14) -> 0.20894844 | AG21: =SUM(AG12/AG$14) -> 0.21377167 | AH21: =SUM(AH12/AH$14) -> 0.2222889 | AI21: =SUM(AI12/AI$14) -> 0.22698895 | AJ21: =SUM(AJ12/AJ$14) -> 0.23717386 | AK21: =SUM(AK12/AK$14) -> 0.24250589 | AL21: =SUM(AL12/AL$14) -> 0.24593451 | ... AP21: =SUM(AP12/AP$14) -> 0.26229752
B22: =B13&"(%)" -> Wearables, Home, and Accessories Revenue(%) | C22: =SUM(C13/C$14) -> 0.051623315 | D22: =SUM(D13/D$14) -> 0.056112968 | E22: =SUM(E13/E$14) -> 0.065441744 | F22: =SUM(F13/F$14) -> 0.094098565 | G22: =SUM(G13/G$14) -> 0.11154217 | H22: =SUM(H13/H$14) -> 0.10488031 | I22: =SUM(I13/I$14) -> 0.10458552 | J22: =SUM(J13/J$14) -> 0.10395659 | ... L22: =SUM(L13/L$14) -> 0.085750467 | N22: =SUM(N13/N$14) -> 0.11860906 | O22: =SUM(O13/O$14) -> 0.090524065 | P22: =SUM(P13/P$14) -> 0.097445726 | Q22: =SUM(Q13/Q$14) -> 0.10704857 | R22: =SUM(R13/R$14) -> 0.1150793 | S22: =SUM(S13/S$14) -> 0.092338353 | T22: =SUM(T13/T$14) -> 0.10127511 | U22: =SUM(U13/U$14) -> 0.10415875 | ... AC22: =SUM(AC13/AC$14) -> 0.087960885 | AE22: =SUM(AE13/AE$14) -> 0.10327272 | AF22: =SUM(AF13/AF$14) -> 0.10380036 | AG22: =SUM(AG13/AG$14) -> 0.10463544 | AH22: =SUM(AH13/AH$14) -> 0.10395659 | AI22: =SUM(AI13/AI$14) -> 0.099339912 | AJ22: =SUM(AJ13/AJ$14) -> 0.098191147 | AK22: =SUM(AK13/AK$14) -> 0.096692712 | AL22: =SUM(AL13/AL$14) -> 0.094633473 | ... AP22: =SUM(AP13/AP$14) -> 0.085750467
B23: Y/Y Growth Rates (%)
B24: =B9&"(%)" -> iPhone Revenue(%) | C24: N/A | D24: =SUM(D9/C9)-1 -> 0.03378932 | E24: =SUM(E9/D9)-1 -> 0.16677871 | F24: =SUM(F9/E9)-1 -> -0.13649871 | G24: =SUM(G9/F9)-1 -> -0.032307682 | H24: =SUM(H9/G9)-1 -> 0.39331983 | I24: =SUM(I9/H9)-1 -> 0.070405734 | J24: =SUM(J9/I9)-1 -> -0.023874757 | K24: =SUM(K9/J9)-1 -> 0.0029912804 | L24: =SUM(L9/K9)-1 -> 0.041767943 | N24: N/A | O24: N/A | P24: N/A | Q24: N/A | R24: =SUM(R9/N9)-1 -> -0.081713855 | S24: =SUM(S9/R9)-1 -> -0.2195515 | T24: =SUM(T9/S9)-1 -> -0.22723731 | U24: =SUM(U9/T9)-1 -> 0.10426277 | V24: =SUM(V9/U9)-1 -> 0.59118822 | W24: =SUM(W9/V9)-1 -> -0.34057846 | X24: =SUM(X9/W9)-1 -> -0.14505145 | Y24: =SUM(Y9/X9)-1 -> 0.17625204 | Z24: =SUM(Z9/Y9)-1 -> 0.49578123 | ... AC24: =SUM(AC9/AB9)-1 -> 0.099659055 | AE24: N/A | AF24: N/A | AG24: N/A | AH24: N/A | AI24: =SUM(AI9/AE9)-1 -> 0.024414434 | AJ24: =SUM(AJ9/AF9)-1 -> -0.0062924152 | AK24: =SUM(AK9/AG9)-1 -> -0.0031995346 | AL24: =SUM(AL9/AH9)-1 -> 0.0029912804 | AM24: =SUM(AM9/AI9)-1 -> -0.019025965 | AN24: =SUM(AN9/AJ9)-1 -> 0.011840975 | AO24: =SUM(AO9/AK9)-1 -> 0.04033386 | AP24: =SUM(AP9/AL9)-1 -> 0.041767943
B25: =B10&"(%)" -> Mac Revenue(%) | C25: N/A | D25: =SUM(D10/C10)-1 -> 0.13223249 | E25: =SUM(E10/D10)-1 -> -0.025222437 | F25: =SUM(F10/E10)-1 -> 0.021509644 | G25: =SUM(G10/F10)-1 -> 0.11196581 | H25: =SUM(H10/G10)-1 -> 0.22947383 | I25: =SUM(I10/H10)-1 -> 0.1417164 | J25: =SUM(J10/I10)-1 -> -0.26930831 | K25: =SUM(K10/J10)-1 -> 0.021357768 | L25: =SUM(L10/K10)-1 -> 0.12419957 | N25: N/A | O25: N/A | P25: N/A | Q25: N/A | R25: =SUM(R10/N10)-1 -> -0.28722816 | S25: =SUM(S10/R10)-1 -> -0.073303167 | T25: =SUM(T10/S10)-1 -> -0.045758929 | U25: =SUM(U10/T10)-1 -> 0.11315789 | V25: =SUM(V10/U10)-1 -> 0.021801944 | W25: =SUM(W10/V10)-1 -> -0.042287918 | X25: =SUM(X10/W10)-1 -> -0.059320897 | Y25: =SUM(Y10/X10)-1 -> 0.10486517 | Z25: =SUM(Z10/Y10)-1 -> 0.16051136 | ... AC25: =SUM(AC10/AB10)-1 -> 0.084514044 | AE25: N/A | AF25: N/A | AG25: N/A | AH25: N/A | AI25: =SUM(AI10/AE10)-1 -> -0.20663788 | AJ25: =SUM(AJ10/AF10)-1 -> -0.12156364 | AK25: =SUM(AK10/AG10)-1 -> -0.10216234 | AL25: =SUM(AL10/AH10)-1 -> 0.021357768 | AM25: =SUM(AM10/AI10)-1 -> 0.060846201 | AN25: =SUM(AN10/AJ10)-1 -> 0.067508843 | AO25: =SUM(AO10/AK10)-1 -> 0.096201514 | AP25: =SUM(AP10/AL10)-1 -> 0.12419957
B26: =B11&"(%)" -> iPad Revenue(%) | C26: N/A | D26: =SUM(D11/C11)-1 -> -0.068159783 | E26: =SUM(E11/D11)-1 -> -0.043803975 | F26: =SUM(F11/E11)-1 -> 0.1577802 | G26: =SUM(G11/F11)-1 -> 0.11484962 | H26: =SUM(H11/G11)-1 -> 0.34302816 | I26: =SUM(I11/H11)-1 -> -0.080660348 | J26: =SUM(J11/I11)-1 -> -0.033865902 | K26: =SUM(K11/J11)-1 -> -0.056749117 | L26: =SUM(L11/K11)-1 -> 0.049786469 | N26: N/A | O26: N/A | P26: N/A | Q26: N/A | R26: =SUM(R11/N11)-1 -> 0.29635762 | S26: =SUM(S11/R11)-1 -> -0.29012346 | T26: =SUM(T11/S11)-1 -> -0.13178411 | U26: =SUM(U11/T11)-1 -> 0.1125885 | V26: =SUM(V11/U11)-1 -> 0.090020177 | W26: =SUM(W11/V11)-1 -> -0.20845792 | X26: =SUM(X11/W11)-1 -> 0.28836122 | Y26: =SUM(Y11/X11)-1 -> -0.02960067 | Z26: =SUM(Z11/Y11)-1 -> 0.16374101 | ... AC26: =SUM(AC11/AB11)-1 -> 0.056374411 | AE26: N/A | AF26: N/A | AG26: N/A | AH26: N/A | AI26: =SUM(AI11/AE11)-1 -> -0.17534987 | AJ26: =SUM(AJ11/AF11)-1 -> -0.18539916 | AK26: =SUM(AK11/AG11)-1 -> -0.097964245 | AL26: =SUM(AL11/AH11)-1 -> -0.056749117 | AM26: =SUM(AM11/AI11)-1 -> 0.07065993 | AN26: =SUM(AN11/AJ11)-1 -> 0.15256286 | AO26: =SUM(AO11/AK11)-1 -> 0.07003475 | AP26: =SUM(AP11/AL11)-1 -> 0.049786469
B27: =B12&"(%)" -> Services Revenue(%) | C27: N/A | D27: =SUM(D12/C12)-1 -> 0.23131263 | E27: =SUM(E12/D12)-1 -> 0.32581721 | F27: =SUM(F12/E12)-1 -> 0.16461206 | G27: =SUM(G12/F12)-1 -> 0.16152168 | H27: =SUM(H12/G12)-1 -> 0.27259708 | I27: =SUM(I12/H12)-1 -> 0.14181951 | J27: =SUM(J12/I12)-1 -> 0.090504166 | K27: =SUM(K12/J12)-1 -> 0.12874413 | L27: =SUM(L12/K12)-1 -> 0.13506431 | N27: N/A | O27: N/A | P27: N/A | Q27: N/A | R27: =SUM(R12/N12)-1 -> 0.06405001 | S27: =SUM(S12/R12)-1 -> 0.0067899451 | T27: =SUM(T12/S12)-1 -> 0.014636246 | U27: =SUM(U12/T12)-1 -> 0.051902135 | V27: =SUM(V12/U12)-1 -> 0.035986376 | W27: =SUM(W12/V12)-1 -> 0.032443656 | X27: =SUM(X12/W12)-1 -> 0.014497004 | Y27: =SUM(Y12/X12)-1 -> 0.031346797 | Z27: =SUM(Z12/Y12)-1 -> 0.054781355 | ... AC27: =SUM(AC12/AB12)-1 -> 0.048390038 | AE27: N/A | AF27: N/A | AG27: N/A | AH27: N/A | AI27: =SUM(AI12/AE12)-1 -> 0.10294914 | AJ27: =SUM(AJ12/AF12)-1 -> 0.12484931 | AK27: =SUM(AK12/AG12)-1 -> 0.13934986 | AL27: =SUM(AL12/AH12)-1 -> 0.12874413 | AM27: =SUM(AM12/AI12)-1 -> 0.13524688 | AN27: =SUM(AN12/AJ12)-1 -> 0.12881307 | AO27: =SUM(AO12/AK12)-1 -> 0.12692624 | AP27: =SUM(AP12/AL12)-1 -> 0.13506431
B28: =B13&"(%)" -> Wearables, Home, and Accessories Revenue(%) | C28: N/A | D28: =SUM(D13/C13)-1 -> 0.15549766 | E28: =SUM(E13/D13)-1 -> 0.35123999 | F28: =SUM(F13/E13)-1 -> 0.40854957 | G28: =SUM(G13/F13)-1 -> 0.25071481 | H28: =SUM(H13/G13)-1 -> 0.25300457 | I28: =SUM(I13/H13)-1 -> 0.074908124 | J28: =SUM(J13/I13)-1 -> -0.03384981 | K28: =SUM(K13/J13)-1 -> -0.071276195 | L28: =SUM(L13/K13)-1 -> -0.035643832 | N28: N/A | O28: N/A | P28: N/A | Q28: N/A | R28: =SUM(R13/N13)-1 -> -0.082919529 | S28: =SUM(S13/R13)-1 -> -0.35046729 | T28: =SUM(T13/S13)-1 -> -0.054013932 | U28: =SUM(U13/T13)-1 -> 0.12530179 | V28: =SUM(V13/U13)-1 -> 0.28223557 | W28: =SUM(W13/V13)-1 -> -0.33799046 | X28: =SUM(X13/W13)-1 -> 0.023252875 | Y28: =SUM(Y13/X13)-1 -> 0.11670989 | Z28: =SUM(Z13/Y13)-1 -> 0.29915948 | ... AC28: =SUM(AC13/AB13)-1 -> 0.21731496 | AE28: N/A | AF28: N/A | AG28: N/A | AH28: N/A | AI28: =SUM(AI13/AE13)-1 -> -0.042626555 | AJ28: =SUM(AJ13/AF13)-1 -> -0.062567233 | AK28: =SUM(AK13/AG13)-1 -> -0.07188908 | AL28: =SUM(AL13/AH13)-1 -> -0.071276195 | AM28: =SUM(AM13/AI13)-1 -> -0.039591815 | AN28: =SUM(AN13/AJ13)-1 -> -0.028394535 | AO28: =SUM(AO13/AK13)-1 -> -0.042108086 | AP28: =SUM(AP13/AL13)-1 -> -0.035643832
B29: Q/Q Growth Rates (%)
B30: =B9&"(%)" -> iPhone Revenue(%) | C30: N/A | D30: N/A | E30: N/A | F30: N/A | G30: N/A | H30: N/A | I30: N/A | J30: N/A | K30: N/A | L30: N/A | N30: N/A | O30: =SUM(O9/N9)-1 -> -0.29399118 | P30: =SUM(P9/O9)-1 -> -0.19586711 | Q30: =SUM(Q9/P9)-1 -> 0.048223288 | R30: =SUM(R9/Q9)-1 -> 0.5430723 | S30: =SUM(S9/R9)-1 -> -0.2195515 | T30: =SUM(T9/S9)-1 -> -0.22723731 | U30: =SUM(U9/T9)-1 -> 0.10426277 | V30: =SUM(V9/U9)-1 -> 0.59118822 | ... AC30: =SUM(AC9/AB9)-1 -> 0.099659055 | AE30: N/A | AF30: N/A | AG30: N/A | AH30: N/A | AI30: N/A | AJ30: N/A | AK30: N/A | AL30: N/A | AM30: N/A | AN30: N/A | AO30: N/A | AP30: N/A
B31: =B10&"(%)" -> Mac Revenue(%) | C31: N/A | D31: N/A | E31: N/A | F31: N/A | G31: N/A | H31: N/A | I31: N/A | J31: N/A | K31: N/A | L31: N/A | N31: N/A | O31: =SUM(O10/N10)-1 -> -0.038426097 | P31: =SUM(P10/O10)-1 -> -0.29257307 | Q31: =SUM(Q10/P10)-1 -> 0.55892712 | R31: =SUM(R10/Q10)-1 -> -0.32785888 | S31: =SUM(S10/R10)-1 -> -0.073303167 | T31: =SUM(T10/S10)-1 -> -0.045758929 | U31: =SUM(U10/T10)-1 -> 0.11315789 | V31: =SUM(V10/U10)-1 -> 0.021801944 | ... AC31: =SUM(AC10/AB10)-1 -> 0.084514044 | AE31: N/A | AF31: N/A | AG31: N/A | AH31: N/A | AI31: N/A | AJ31: N/A | AK31: N/A | AL31: N/A | AM31: N/A | AN31: N/A | AO31: N/A | AP31: N/A
B32: =B11&"(%)" -> iPad Revenue(%) | C32: N/A | D32: N/A | E32: N/A | F32: N/A | G32: N/A | H32: N/A | I32: N/A | J32: N/A | K32: N/A | L32: N/A | N32: N/A | O32: =SUM(O11/N11)-1 -> 0.0549117 | P32: =SUM(P11/O11)-1 -> -0.055192257 | Q32: =SUM(Q11/P11)-1 -> -0.0069213732 | R32: =SUM(R11/Q11)-1 -> 0.30972958 | S32: =SUM(S11/R11)-1 -> -0.29012346 | T32: =SUM(T11/S11)-1 -> -0.13178411 | U32: =SUM(U11/T11)-1 -> 0.1125885 | V32: =SUM(V11/U11)-1 -> 0.090020177 | ... AC32: =SUM(AC11/AB11)-1 -> 0.056374411 | AE32: N/A | AF32: N/A | AG32: N/A | AH32: N/A | AI32: N/A | AJ32: N/A | AK32: N/A | AL32: N/A | AM32: N/A | AN32: N/A | AO32: N/A | AP32: N/A
B33: =B12&"(%)" -> Services Revenue(%) | C33: N/A | D33: N/A | E33: N/A | F33: N/A | G33: N/A | H33: N/A | I33: N/A | J33: N/A | K33: N/A | L33: N/A | N33: N/A | O33: =SUM(O12/N12)-1 -> 0.015628203 | P33: =SUM(P12/O12)-1 -> -0.010947984 | Q33: =SUM(Q12/P12)-1 -> -0.021220159 | R33: =SUM(R12/Q12)-1 -> 0.082238899 | S33: =SUM(S12/R12)-1 -> 0.0067899451 | T33: =SUM(T12/S12)-1 -> 0.014636246 | U33: =SUM(U12/T12)-1 -> 0.051902135 | V33: =SUM(V12/U12)-1 -> 0.035986376 | ... AC33: =SUM(AC12/AB12)-1 -> 0.048390038 | AE33: N/A | AF33: N/A | AG33: N/A | AH33: N/A | AI33: N/A | AJ33: N/A | AK33: N/A | AL33: N/A | AM33: N/A | AN33: N/A | AO33: N/A | AP33: N/A
B34: =B13&"(%)" -> Wearables, Home, and Accessories Revenue(%) | C34: N/A | D34: N/A | E34: N/A | F34: N/A | G34: N/A | H34: N/A | I34: N/A | J34: N/A | K34: N/A | L34: N/A | N34: N/A | O34: =SUM(O13/N13)-1 -> -0.40099313 | P34: =SUM(P13/O13)-1 -> -0.081989553 | Q34: =SUM(Q13/P13)-1 -> 0.19371598 | R34: =SUM(R13/Q13)-1 -> 0.39709845 | S34: =SUM(S13/R13)-1 -> -0.35046729 | T34: =SUM(T13/S13)-1 -> -0.054013932 | U34: =SUM(U13/T13)-1 -> 0.12530179 | V34: =SUM(V13/U13)-1 -> 0.28223557 | ... AC34: =SUM(AC13/AB13)-1 -> 0.21731496 | AE34: N/A | AF34: N/A | AG34: N/A | AH34: N/A | AI34: N/A | AJ34: N/A | AK34: N/A | AL34: N/A | AM34: N/A | AN34: N/A | AO34: N/A | AP34: N/A
A36: X | B36: Per Unit Data (k)
A38: X | B38: Total Units Sold per End Market
B39: iPhone | C39: 211884 | D39: 216756 | E39: 217722 | F39: 186000 | G39: 186860 | H39: 235000 | I39: 245000 | J39: 218000 | K39: 224000 | L39: 231000 | N39: 82000 | O39: 60000 | P39: 50000 | Q39: =SUM(I39-SUM(N39:P39)) -> 53000 | R39: 70000 | S39: 55000 | T39: 42000 | U39: =SUM(J39-SUM(R39:T39)) -> 51000 | V39: 77000 | W39: 52000 | X39: 43000 | Y39: =SUM(K39-SUM(V39:X39)) -> 52000 | Z39: 75000 | AA39: 53000 | AB39: 49000 | AC39: =SUM(L39-SUM(Z39:AB39)) -> 54000 | AE39: =SUM(O39:R39) -> 233000 | AF39: =SUM(P39:S39) -> 228000 | AG39: =SUM(Q39:T39) -> 220000 | AH39: =SUM(R39:U39) -> 218000 | AI39: =SUM(S39:V39) -> 225000 | AJ39: =SUM(T39:W39) -> 222000 | AK39: =SUM(U39:X39) -> 223000 | AL39: =SUM(V39:Y39) -> 224000 | ... AP39: =SUM(Z39:AC39) -> 231000 | AR39: =SUM(AO39/AK39)-1 -> 0.02690583
B40: iPad | C40: 45590 | D40: 43753 | E40: 43535 | F40: 45307.857 | G40: 52626 | H40: 68511 | I40: 59348.24 | J40: 52508.536 | K40: 50349.696 | L40: 50850 | N40: 15648 | O40: 15806 | P40: 14810 | Q40: =SUM(I40-SUM(N40:P40)) -> 13084.24 | R40: 14709.12 | S40: 13435.1 | T40: 12588.5 | U40: =SUM(J40-SUM(R40:T40)) -> 11775.816 | V40: 11767.296 | W40: 12991.742 | X40: 13343.81 | Y40: =SUM(K40-SUM(V40:X40)) -> 12246.849 | Z40: 12237.988 | AA40: 13251.577 | AB40: 13610.686 | AC40: =SUM(L40-SUM(Z40:AB40)) -> 11749.749 | AE40: =SUM(O40:R40) -> 58409.36 | AF40: =SUM(P40:S40) -> 56038.46 | AG40: =SUM(Q40:T40) -> 53816.96 | AH40: =SUM(R40:U40) -> 52508.536 | AI40: =SUM(S40:V40) -> 49566.712 | AJ40: =SUM(T40:W40) -> 49123.354 | AK40: =SUM(U40:X40) -> 49878.664 | AL40: =SUM(V40:Y40) -> 50349.696 | ... AP40: =SUM(Z40:AC40) -> 50850 | AR40: =SUM(AO40/AK40)-1 -> 0.029440153
B41: Mac | C41: 18484 | D41: 19251 | E41: 18209 | F41: 18433.59 | G41: 20907.113 | H41: 27537.026 | I41: 28368.573 | J41: 24996.716 | K41: 24935.376 | L41: 26947 | N41: 7608.573 | O41: 7160 | P41: 5500 | Q41: =SUM(I41-SUM(N41:P41)) -> 8100 | R41: 6847.7157 | S41: 6444 | T41: 5225 | U41: =SUM(J41-SUM(R41:T41)) -> 6480 | V41: 6368.3756 | W41: 6444 | X41: 5643 | Y41: =SUM(K41-SUM(V41:X41)) -> 6480 | Z41: 7005.2132 | AA41: 6766.2 | AB41: 6545.88 | AC41: =SUM(L41-SUM(Z41:AB41)) -> 6629.7068 | AE41: =SUM(O41:R41) -> 27607.716 | AF41: =SUM(P41:S41) -> 26891.716 | AG41: =SUM(Q41:T41) -> 26616.716 | AH41: =SUM(R41:U41) -> 24996.716 | AI41: =SUM(S41:V41) -> 24517.376 | AJ41: =SUM(T41:W41) -> 24517.376 | AK41: =SUM(U41:X41) -> 24935.376 | AL41: =SUM(V41:Y41) -> 24935.376 | ... AP41: =SUM(Z41:AC41) -> 26947 | AR41: =SUM(AO41/AK41)-1 -> 0.074669722
B42: Apple Watch | C42: 10500 | D42: 14000 | E42: 20700 | F42: 30350 | G42: 41627.5 | H42: 49942.75 | I42: 54498.707 | J42: 47633.541 | K42: 43243.04 | L42: 43916 | N42: 25582.9 | O42: 7688.52 | P42: 10411.538 | Q42: =SUM(I42-SUM(N42:P42)) -> 10815.75 | R42: 21745.465 | S42: 7304.094 | T42: 8849.8069 | U42: =SUM(J42-SUM(R42:T42)) -> 9734.175 | V42: 18483.645 | W42: 6573.6846 | X42: 7964.8262 | Y42: =SUM(K42-SUM(V42:X42)) -> 10220.884 | Z42: 18668.482 | AA42: 6902.3688 | AB42: 8124.1227 | AC42: =SUM(L42-SUM(Z42:AB42)) -> 10221.027 | AE42: =SUM(O42:R42) -> 50661.272 | AF42: =SUM(P42:S42) -> 50276.846 | AG42: =SUM(Q42:T42) -> 48715.116 | AH42: =SUM(R42:U42) -> 47633.541 | AI42: =SUM(S42:V42) -> 44371.721 | AJ42: =SUM(T42:W42) -> 43641.312 | AK42: =SUM(U42:X42) -> 42756.331 | AL42: =SUM(V42:Y42) -> 43243.04 | ... AP42: =SUM(Z42:AC42) -> 43916 | AR42: =SUM(AO42/AK42)-1 -> 0.027119398
B43: Total Units Sold | C43: =SUM(C39:C42) -> 286458 | D43: =SUM(D39:D42) -> 293760 | E43: =SUM(E39:E42) -> 300166 | F43: =SUM(F39:F42) -> 280091.45 | G43: =SUM(G39:G42) -> 302020.61 | H43: =SUM(H39:H42) -> 380990.78 | I43: =SUM(I39:I42) -> 387215.52 | J43: =SUM(J39:J42) -> 343138.79 | ... L43: =SUM(L39:L42) -> 352713 | N43: =SUM(N39:N42) -> 130839.47 | O43: =SUM(O39:O42) -> 90654.52 | P43: =SUM(P39:P42) -> 80721.538 | Q43: =SUM(Q39:Q42) -> 84999.99 | R43: =SUM(R39:R42) -> 113302.3 | S43: =SUM(S39:S42) -> 82183.194 | T43: =SUM(T39:T42) -> 68663.307 | U43: =SUM(U39:U42) -> 78989.991 | ... AC43: =SUM(AC39:AC42) -> 82600.483 | AE43: =SUM(AE39:AE41) -> 319017.08 | AF43: =SUM(AF39:AF41) -> 310930.18 | AG43: =SUM(AG39:AG41) -> 300433.68 | AH43: =SUM(AH39:AH41) -> 295505.25 | AI43: =SUM(AI39:AI41) -> 299084.09 | AJ43: =SUM(AJ39:AJ41) -> 295640.73 | AK43: =SUM(AK39:AK42) -> 340570.37 | AL43: =SUM(AL39:AL42) -> 342528.11 | AM43: =SUM(AM39:AM42) -> 341820.48 | AN43: =SUM(AN39:AN42) -> 343731.2 | AO43: =SUM(AO39:AO42) -> 351060.25 | AP43: =SUM(AP39:AP42) -> 352713 | AR43: =SUM(AO43/AK43)-1 -> 0.030800915
B45: Segments as a % of Total Revenue
B46: =B39&"(%)" -> iPhone(%) | C46: =SUM(C39/C$43) -> 0.73966864 | D46: =SUM(D39/D$43) -> 0.73786765 | E46: =SUM(E39/E$43) -> 0.72533865 | F46: =SUM(F39/F$43) -> 0.66406883 | G46: =SUM(G39/G$43) -> 0.61869949 | H46: =SUM(H39/H$43) -> 0.61681283 | I46: =SUM(I39/I$43) -> 0.63272257 | J46: =SUM(J39/J$43) -> 0.63531144 | ... L46: =SUM(L39/L$43) -> 0.65492341 | N46: =SUM(N39/N$43) -> 0.62672218 | O46: =SUM(O39/O$43) -> 0.66185337 | P46: =SUM(P39/P$43) -> 0.61941338 | Q46: =SUM(Q39/Q$43) -> 0.62352949 | R46: =SUM(R39/R$43) -> 0.61781623 | S46: =SUM(S39/S$43) -> 0.66923658 | T46: =SUM(T39/T$43) -> 0.61168041 | U46: =SUM(U39/U$43) -> 0.64565142 | ... AC46: =SUM(AC39/AC$43) -> 0.6537492 | AE46: =SUM(AE39/AE$43) -> 0.73036843 | AF46: =SUM(AF39/AF$43) -> 0.7332836 | AG46: =SUM(AG39/AG$43) -> 0.73227477 | AH46: =SUM(AH39/AH$43) -> 0.73771955 | AI46: =SUM(AI39/AI$43) -> 0.75229679 | AJ46: =SUM(AJ39/AJ$43) -> 0.75091142 | AK46: =SUM(AK39/AK$43) -> 0.65478391 | AL46: =SUM(AL39/AL$43) -> 0.65396092 | ... AP46: =SUM(AP39/AP$43) -> 0.65492341
B47: =B40&"(%)" -> iPad(%) | C47: =SUM(C40/C$43) -> 0.15915073 | D47: =SUM(D40/D$43) -> 0.14894131 | E47: =SUM(E40/E$43) -> 0.14503641 | F47: =SUM(F40/F$43) -> 0.16176094 | G47: =SUM(G40/G$43) -> 0.17424638 | H47: =SUM(H40/H$43) -> 0.17982325 | I47: =SUM(I40/I$43) -> 0.15326927 | J47: =SUM(J40/J$43) -> 0.15302419 | ... L47: =SUM(L40/L$43) -> 0.1441682 | N47: =SUM(N40/N$43) -> 0.11959694 | O47: =SUM(O40/O$43) -> 0.17435424 | P47: =SUM(P40/P$43) -> 0.18347024 | Q47: =SUM(Q40/Q$43) -> 0.15393225 | R47: =SUM(R40/R$43) -> 0.1298219 | S47: =SUM(S40/S$43) -> 0.16347746 | T47: =SUM(T40/T$43) -> 0.18333664 | U47: =SUM(U40/U$43) -> 0.14907985 | ... AC47: =SUM(AC40/AC$43) -> 0.14224795 | AE47: =SUM(AE40/AE$43) -> 0.18309164 | AF47: =SUM(AF40/AF$43) -> 0.18022844 | AG47: =SUM(AG40/AG$43) -> 0.17913092 | AH47: =SUM(AH40/AH$43) -> 0.1776907 | AI47: =SUM(AI40/AI$43) -> 0.16572835 | AJ47: =SUM(AJ40/AJ$43) -> 0.16615895 | AK47: =SUM(AK40/AK$43) -> 0.14645626 | AL47: =SUM(AL40/AL$43) -> 0.14699435 | ... AP47: =SUM(AP40/AP$43) -> 0.1441682
...

Sheet Balance Sheet Drivers
B2: Apple Inc. (NASDAQ: AAPL) | C2: FYE | F2: FYE | N2: Quarterly | T2: Quarterly | W2: Quarterly | X2: Quarterly | AK2: LTM | AQ2: Variance
B3: Balance Sheet Drivers | C3: ='Historical Financials'!C7 -> 2016 | D3: ='Historical Financials'!D7 -> 2017 | E3: ='Historical Financials'!E7 -> 2018 | F3: ='Historical Financials'!F7 -> 2019 | G3: ='Historical Financials'!G7 -> 2020 | H3: ='Historical Financials'!H7 -> 2021 | I3: ='Historical Financials'!I7 -> 2022 | J3: ='Historical Financials'!J7 -> 2023 | ... L3: ='Historical Financials'!L7 -> 2025 | N3: ='Historical Financials'!N7 -> 1Q22 | O3: ='Historical Financials'!O7 -> 2Q22 | P3: ='Historical Financials'!P7 -> 3Q22 | Q3: ='Historical Financials'!Q7 -> 4Q22 | R3: ='Historical Financials'!R7 -> 1Q23 | S3: ='Historical Financials'!S7 -> 2Q23 | T3: ='Historical Financials'!T7 -> 3Q23 | U3: ='Historical Financials'!U7 -> 4Q23 | ... AC3: ='Historical Financials'!AC7 -> 4Q25 | AE3: =R3 -> 1Q23 | AF3: =S3 -> 2Q23 | AG3: =T3 -> 3Q23 | AH3: =U3 -> 4Q23 | AI3: =V3 -> 1Q24 | AJ3: =W3 -> 2Q24 | AK3: =X3 -> 3Q24 | AL3: =Y3 -> 4Q24 | ... AP3: =AC3 -> 4Q25
B4: ($ in Millions) | C4: ='Historical Financials'!C8 -> 42643 | D4: ='Historical Financials'!D8 -> 43008 | E4: ='Historical Financials'!E8 -> 43372 | F4: ='Historical Financials'!F8 -> 43737 | G4: ='Historical Financials'!G8 -> 44104 | H4: ='Historical Financials'!H8 -> 44469 | I4: ='Historical Financials'!I8 -> 44834 | J4: ='Historical Financials'!J8 -> 45192 | ... L4: ='Historical Financials'!L8 -> 45927 | N4: ='Historical Financials'!N8 -> 44560 | O4: ='Historical Financials'!O8 -> 44650 | P4: ='Historical Financials'!P8 -> 44742 | Q4: ='Historical Financials'!Q8 -> 44834 | R4: ='Historical Financials'!R8 -> 44917 | S4: ='Historical Financials'!S8 -> 45008 | T4: ='Historical Financials'!T8 -> 45100 | U4: ='Historical Financials'!U8 -> 45192 | ... AC4: ='Historical Financials'!AC8 -> 45927 | AE4: =R4 -> 44917 | AF4: =S4 -> 45008 | AG4: =T4 -> 45100 | AH4: =U4 -> 45192 | AI4: =V4 -> 45283 | AJ4: =W4 -> 45375 | AK4: =X4 -> 45467 | AL4: =Y4 -> 45559 | ... AP4: =AC4 -> 45927
A6: X | B6: Working Capital
