Workbook

Sheet Historical Financials
B2: Apple Inc. (NASDAQ: AAPL)
B3: Historical Financials
B4: $ mm except per share
A10: X | B10: Income Statement | C10: FYE | M10: Quarterly | S10: Quarterly | V10: Quarterly | W10: Quarterly | AI10: LTM | AO10: Variance
B11: Fiscal Period | C11: 2016 | D11: 2017 | E11: 2018 | F11: 2019 | G11: 2020 | H11: 2021 | I11: 2022 | J11: 2023 | K11: 2024 | M11: 1Q22 | N11: 2Q22 | O11: 3Q22 | P11: 4Q22 | Q11: 1Q23 | R11: 2Q23 | S11: 3Q23 | T11: 4Q23 | U11: 1Q24 | V11: 2Q24 | W11: 3Q24 | X11: 4Q24 | Y11: 1Q25 | Z11: 2Q25 | AA11: 3Q25 | AC11: =Q11 -> 1Q23 | AD11: =R11 -> 2Q23 | AE11: =S11 -> 3Q23 | AF11: =T11 -> 4Q23 | AG11: =U11 -> 1Q24 | AH11: =V11 -> 2Q24 | AI11: =W11 -> 3Q24 | AJ11: =X11 -> 4Q24 | ... AM11: =AA11 -> 3Q25
B12: Fiscal Period End Date | C12: 42643 | D12: 43008 | E12: 43372 | F12: 43737 | G12: 44104 | H12: 44469 | I12: 44834 | J12: 45192 | K12: 45559 | M12: 44560 | N12: 44650 | O12: 44742 | P12: =I12 -> 44834 | Q12: 44917 | R12: 45008 | S12: 45100 | T12: =J12 -> 45192 | U12: 45283 | V12: 45375 | W12: 45467 | X12: =K12 -> 45559 | Y12: 45650 | Z12: 45741 | AA12: 45833 | AC12: =Q12 -> 44917 | AD12: =R12 -> 45008 | AE12: =S12 -> 45100 | AF12: =T12 -> 45192 | AG12: =U12 -> 45283 | AH12: =V12 -> 45375 | AI12: =W12 -> 45467 | AJ12: =X12 -> 45559 | ... AM12: =AA12 -> 45833
B14: Consolidated Revenue | C14: 215639 | D14: 229234 | E14: 265595 | F14: 260174 | G14: 274515 | H14: 365817 | I14: 394328 | J14: 383285 | K14: 391035 | M14: 123945 | N14: 97278 | O14: 82959 | P14: =SUM(I14-SUM(M14:O14)) -> 90146 | Q14: 117154 | R14: 94836 | S14: 81797 | T14: =SUM(J14-SUM(Q14:S14)) -> 89498 | U14: 119575 | V14: 90753 | W14: 85777 | X14: =SUM(K14-SUM(U14:W14)) -> 94930 | Y14: 124300 | Z14: 95359 | AA14: 94036 | AC14: =SUM(N14:Q14) -> 387537 | AD14: =SUM(O14:R14) -> 385095 | AE14: =SUM(P14:S14) -> 383933 | AF14: =SUM(Q14:T14) -> 383285 | AG14: =SUM(R14:U14) -> 385706 | AH14: =SUM(S14:V14) -> 381623 | AI14: =SUM(T14:W14) -> 385603 | AJ14: =SUM(U14:X14) -> 391035 | ... AM14: =SUM(X14:AA14) -> 408625 | AO14: =SUM(AM14/AI14)-1 -> 0.059703892
B15: Total Revenue | C15: =+SUM(C14:C14) -> 215639 | D15: =+SUM(D14:D14) -> 229234 | E15: =+SUM(E14:E14) -> 265595 | F15: =+SUM(F14:F14) -> 260174 | G15: =+SUM(G14:G14) -> 274515 | H15: =+SUM(H14:H14) -> 365817 | I15: =+SUM(I14:I14) -> 394328 | J15: =+SUM(J14:J14) -> 383285 | K15: =+SUM(K14:K14) -> 391035 | M15: =+SUM(M14:M14) -> 123945 | N15: =+SUM(N14:N14) -> 97278 | O15: =+SUM(O14:O14) -> 82959 | P15: =+SUM(P14:P14) -> 90146 | Q15: =+SUM(Q14:Q14) -> 117154 | R15: =+SUM(R14:R14) -> 94836 | S15: =+SUM(S14:S14) -> 81797 | T15: =+SUM(T14:T14) -> 89498 | ... AA15: =+SUM(AA14:AA14) -> 94036 | AC15: =+SUM(AC14:AC14) -> 387537 | AD15: =+SUM(AD14:AD14) -> 385095 | AE15: =+SUM(AE14:AE14) -> 383933 | AF15: =+SUM(AF14:AF14) -> 383285 | AG15: =+SUM(AG14:AG14) -> 385706 | AH15: =+SUM(AH14:AH14) -> 381623 | AI15: =+SUM(AI14:AI14) -> 385603 | AJ15: =+SUM(AJ14:AJ14) -> 391035 | ... AM15: =+SUM(AM14:AM14) -> 408625 | AO15: =SUM(AM15/AI15)-1 -> 0.059703892
B17: Cost of Sales | C17: -131376 | D17: -141048 | E17: -163756 | F17: -161782 | G17: -169559 | H17: -212981 | I17: -223546 | J17: -214137 | K17: -210352 | M17: -69702 | N17: -54719 | O17: -47074 | P17: =SUM(I17-SUM(M17:O17)) -> -52051 | Q17: -66822 | R17: -52860 | S17: -45384 | T17: =SUM(J17-SUM(Q17:S17)) -> -49071 | U17: -64720 | V17: -48482 | W17: -46099 | X17: =SUM(K17-SUM(U17:W17)) -> -51051 | Y17: -66025 | Z17: -50492 | AA17: -50318 | AC17: =SUM(N17:Q17) -> -220666 | AD17: =SUM(O17:R17) -> -218807 | AE17: =SUM(P17:S17) -> -217117 | AF17: =SUM(Q17:T17) -> -214137 | AG17: =SUM(R17:U17) -> -212035 | AH17: =SUM(S17:V17) -> -207657 | AI17: =SUM(T17:W17) -> -208372 | AJ17: =SUM(U17:X17) -> -210352 | ... AM17: =SUM(X17:AA17) -> -217886 | AO17: =SUM(AM17/AI17)-1 -> 0.045658726
B18: Gross Profit | C18: =+SUM(C15+SUM(C17:C17)) -> 84263 | D18: =+SUM(D15+SUM(D17:D17)) -> 88186 | E18: =+SUM(E15+SUM(E17:E17)) -> 101839 | F18: =+SUM(F15+SUM(F17:F17)) -> 98392 | G18: =+SUM(G15+SUM(G17:G17)) -> 104956 | H18: =+SUM(H15+SUM(H17:H17)) -> 152836 | I18: =+SUM(I15+SUM(I17:I17)) -> 170782 | J18: =+SUM(J15+SUM(J17:J17)) -> 169148 | K18: =+SUM(K15+SUM(K17:K17)) -> 180683 | M18: =+SUM(M15+SUM(M17:M17)) -> 54243 | N18: =+SUM(N15+SUM(N17:N17)) -> 42559 | O18: =+SUM(O15+SUM(O17:O17)) -> 35885 | P18: =+SUM(P15+SUM(P17:P17)) -> 38095 | Q18: =+SUM(Q15+SUM(Q17:Q17)) -> 50332 | R18: =+SUM(R15+SUM(R17:R17)) -> 41976 | S18: =+SUM(S15+SUM(S17:S17)) -> 36413 | T18: =+SUM(T15+SUM(T17:T17)) -> 40427 | ... AA18: =+SUM(AA15+SUM(AA17:AA17)) -> 43718 | AC18: =+SUM(AC15+SUM(AC17:AC17)) -> 166871 | AD18: =+SUM(AD15+SUM(AD17:AD17)) -> 166288 | AE18: =+SUM(AE15+SUM(AE17:AE17)) -> 166816 | AF18: =+SUM(AF15+SUM(AF17:AF17)) -> 169148 | AG18: =+SUM(AG15+SUM(AG17:AG17)) -> 173671 | AH18: =+SUM(AH15+SUM(AH17:AH17)) -> 173966 | AI18: =+SUM(AI15+SUM(AI17:AI17)) -> 177231 | AJ18: =+SUM(AJ15+SUM(AJ17:AJ17)) -> 180683 | ... AM18: =+SUM(AM15+SUM(AM17:AM17)) -> 190739 | AO18: =SUM(AM18/AI18)-1 -> 0.076216915
B19: Gross Margin (%) | C19: =C18/C15 -> 0.39075956 | D19: =D18/D15 -> 0.3846986 | E19: =E18/E15 -> 0.38343719 | F19: =F18/F15 -> 0.37817768 | G19: =G18/G15 -> 0.38233248 | H19: =H18/H15 -> 0.4177936 | I19: =I18/I15 -> 0.43309631 | J19: =J18/J15 -> 0.4413113 | K19: =K18/K15 -> 0.4620635 | M19: =M18/M15 -> 0.43763766 | N19: =N18/N15 -> 0.43749872 | O19: =O18/O15 -> 0.43256307 | P19: =P18/P15 -> 0.42259224 | Q19: =Q18/Q15 -> 0.42962255 | R19: =R18/R15 -> 0.44261673 | S19: =S18/S15 -> 0.44516303 | T19: =T18/T15 -> 0.45170842 | ... AA19: =AA18/AA15 -> 0.46490706 | AC19: =AC18/AC15 -> 0.43059372 | AD19: =AD18/AD15 -> 0.43181033 | AE19: =AE18/AE15 -> 0.43449248 | AF19: =AF18/AF15 -> 0.4413113 | AG19: =AG18/AG15 -> 0.45026782 | AH19: =AH18/AH15 -> 0.45585827 | AI19: =AI18/AI15 -> 0.45962039 | AJ19: =AJ18/AJ15 -> 0.4620635 | ... AM19: =AM18/AM15 -> 0.4667825 | AO19: =SUM(AM19-AI19)*1000 -> 7.1621155
B21: Research & Development | C21: -10045 | D21: -11581 | E21: -14236 | F21: -16217 | G21: -18752 | H21: -21914 | I21: -26251 | J21: -29915 | K21: -31370 | M21: -6306 | N21: -6387 | O21: -6797 | P21: =SUM(I21-SUM(M21:O21)) -> -6761 | Q21: -7709 | R21: -7457 | S21: -7442 | T21: =SUM(J21-SUM(Q21:S21)) -> -7307 | U21: -7696 | V21: -7903 | W21: -8006 | X21: =SUM(K21-SUM(U21:W21)) -> -7765 | Y21: -8268 | Z21: -8550 | AA21: -8866 | AC21: =SUM(N21:Q21) -> -27654 | AD21: =SUM(O21:R21) -> -28724 | AE21: =SUM(P21:S21) -> -29369 | AF21: =SUM(Q21:T21) -> -29915 | AG21: =SUM(R21:U21) -> -29902 | AH21: =SUM(S21:V21) -> -30348 | AI21: =SUM(T21:W21) -> -30912 | AJ21: =SUM(U21:X21) -> -31370 | ... AM21: =SUM(X21:AA21) -> -33449 | AO21: =SUM(AM21/AI21)-1 -> 0.082071687
B22: Selling, General & Administrative | C22: -14194 | D22: -15261 | E22: -16705 | F22: -18245 | G22: -19916 | H22: -21973 | I22: -25094 | J22: -24932 | K22: -26097 | M22: -6449 | N22: -6193 | O22: -6012 | P22: =SUM(I22-SUM(M22:O22)) -> -6440 | Q22: -6607 | R22: -6201 | S22: -5973 | T22: =SUM(J22-SUM(Q22:S22)) -> -6151 | U22: -6786 | V22: -6468 | W22: -6320 | X22: =SUM(K22-SUM(U22:W22)) -> -6523 | Y22: -7175 | Z22: -6728 | AA22: -6650 | AC22: =SUM(N22:Q22) -> -25252 | AD22: =SUM(O22:R22) -> -25260 | AE22: =SUM(P22:S22) -> -25221 | AF22: =SUM(Q22:T22) -> -24932 | AG22: =SUM(R22:U22) -> -25111 | AH22: =SUM(S22:V22) -> -25378 | AI22: =SUM(T22:W22) -> -25725 | AJ22: =SUM(U22:X22) -> -26097 | ... AM22: =SUM(X22:AA22) -> -27076 | AO22: =SUM(AM22/AI22)-1 -> 0.052517007
B23: Profit From Operations | C23: =SUM(C18+SUM(C21:C22)) -> 60024 | D23: =SUM(D18+SUM(D21:D22)) -> 61344 | E23: =SUM(E18+SUM(E21:E22)) -> 70898 | F23: =SUM(F18+SUM(F21:F22)) -> 63930 | G23: =SUM(G18+SUM(G21:G22)) -> 66288 | H23: =SUM(H18+SUM(H21:H22)) -> 108949 | I23: =SUM(I18+SUM(I21:I22)) -> 119437 | J23: =SUM(J18+SUM(J21:J22)) -> 114301 | K23: =SUM(K18+SUM(K21:K22)) -> 123216 | M23: =SUM(M18+SUM(M21:M22)) -> 41488 | N23: =SUM(N18+SUM(N21:N22)) -> 29979 | O23: =SUM(O18+SUM(O21:O22)) -> 23076 | P23: =SUM(P18+SUM(P21:P22)) -> 24894 | Q23: =SUM(Q18+SUM(Q21:Q22)) -> 36016 | R23: =SUM(R18+SUM(R21:R22)) -> 28318 | S23: =SUM(S18+SUM(S21:S22)) -> 22998 | T23: =SUM(T18+SUM(T21:T22)) -> 26969 | ... AA23: =SUM(AA18+SUM(AA21:AA22)) -> 28202 | AC23: =SUM(AC18+SUM(AC21:AC22)) -> 113965 | AD23: =SUM(AD18+SUM(AD21:AD22)) -> 112304 | AE23: =SUM(AE18+SUM(AE21:AE22)) -> 112226 | AF23: =SUM(AF18+SUM(AF21:AF22)) -> 114301 | AG23: =SUM(AG18+SUM(AG21:AG22)) -> 118658 | AH23: =SUM(AH18+SUM(AH21:AH22)) -> 118240 | AI23: =SUM(AI18+SUM(AI21:AI22)) -> 120594 | AJ23: =SUM(AJ18+SUM(AJ21:AJ22)) -> 123216 | ... AM23: =SUM(AM18+SUM(AM21:AM22)) -> 130214 | AO23: =SUM(AM23/AI23)-1 -> 0.079771796
B24: Operating Margin (%) | C24: =C23/C15 -> 0.2783541 | D24: =D23/D15 -> 0.26760428 | E24: =E23/E15 -> 0.26694027 | F24: =F23/F15 -> 0.24572017 | G24: =G23/G15 -> 0.24147314 | H24: =H23/H15 -> 0.29782378 | I24: =I23/I15 -> 0.30288744 | J24: =J23/J15 -> 0.29821412 | K24: =K23/K15 -> 0.31510223 | M24: =M23/M15 -> 0.33472911 | N24: =N23/N15 -> 0.30817862 | O24: =O23/O15 -> 0.2781615 | P24: =P23/P15 -> 0.27615202 | Q24: =Q23/Q15 -> 0.30742442 | R24: =R23/R15 -> 0.29859969 | S24: =S23/S15 -> 0.28115946 | T24: =T23/T15 -> 0.30133634 | ... AA24: =AA23/AA15 -> 0.29990642 | AC24: =AC23/AC15 -> 0.29407515 | AD24: =AD23/AD15 -> 0.29162674 | AE24: =AE23/AE15 -> 0.29230621 | AF24: =AF23/AF15 -> 0.29821412 | AG24: =AG23/AG15 -> 0.30763846 | AH24: =AH23/AH15 -> 0.30983457 | AI24: =AI23/AI15 -> 0.31274134 | AJ24: =AJ23/AJ15 -> 0.31510223 | ... AM24: =AM23/AM15 -> 0.31866381 | AO24: =SUM(AM24-AI24)*1000 -> 5.9224688
B26: Other income/(expense), net | C26: 1348 | D26: 2745 | E26: 2005 | F26: 1807 | G26: 803 | H26: 258 | I26: -334 | J26: -565 | K26: 269 | M26: -247 | N26: 160 | O26: -10 | P26: =SUM(I26-SUM(M26:O26)) -> -237 | Q26: -393 | R26: 64 | S26: -265 | T26: =SUM(J26-SUM(Q26:S26)) -> 29 | U26: -50 | V26: 158 | W26: 142 | X26: =SUM(K26-SUM(U26:W26)) -> 19 | Y26: -248 | Z26: -279 | AA26: -171 | AC26: =SUM(N26:Q26) -> -480 | AD26: =SUM(O26:R26) -> -576 | AE26: =SUM(P26:S26) -> -831 | AF26: =SUM(Q26:T26) -> -565 | AG26: =SUM(R26:U26) -> -222 | AH26: =SUM(S26:V26) -> -128 | AI26: =SUM(T26:W26) -> 279 | AJ26: =SUM(U26:X26) -> 269 | ... AM26: =SUM(X26:AA26) -> -679 | AO26: =SUM(AM26/AI26)-1 -> -3.4336918
B27: Net loss before provision for income taxes | C27: =SUM(C26:C26)+C23 -> 61372 | D27: =SUM(D26:D26)+D23 -> 64089 | E27: =SUM(E26:E26)+E23 -> 72903 | F27: =SUM(F26:F26)+F23 -> 65737 | G27: =SUM(G26:G26)+G23 -> 67091 | H27: =SUM(H26:H26)+H23 -> 109207 | I27: =SUM(I26:I26)+I23 -> 119103 | J27: =SUM(J26:J26)+J23 -> 113736 | K27: =SUM(K26:K26)+K23 -> 123485 | M27: =SUM(M26:M26)+M23 -> 41241 | N27: =SUM(N26:N26)+N23 -> 30139 | O27: =SUM(O26:O26)+O23 -> 23066 | P27: =SUM(P26:P26)+P23 -> 24657 | Q27: =SUM(Q26:Q26)+Q23 -> 35623 | R27: =SUM(R26:R26)+R23 -> 28382 | S27: =SUM(S26:S26)+S23 -> 22733 | T27: =SUM(T26:T26)+T23 -> 26998 | ... AA27: =SUM(AA26:AA26)+AA23 -> 28031 | AC27: =SUM(AC26:AC26)+AC23 -> 113485 | AD27: =SUM(AD26:AD26)+AD23 -> 111728 | AE27: =SUM(AE26:AE26)+AE23 -> 111395 | AF27: =SUM(AF26:AF26)+AF23 -> 113736 | AG27: =SUM(AG26:AG26)+AG23 -> 118436 | AH27: =SUM(AH26:AH26)+AH23 -> 118112 | AI27: =SUM(AI26:AI26)+AI23 -> 120873 | AJ27: =SUM(AJ26:AJ26)+AJ23 -> 123485 | ... AM27: =SUM(AM26:AM26)+AM23 -> 129535 | AO27: =SUM(AM27/AI27)-1 -> 0.071661992
B29: Provision for taxes | C29: -15685 | D29: -15738 | E29: -13372 | F29: -10481 | G29: -9680 | H29: -14527 | I29: -19300 | J29: -16741 | K29: -29749 | M29: -6611 | N29: -5129 | O29: -3624 | P29: =SUM(I29-SUM(M29:O29)) -> -3936 | Q29: -5625 | R29: -4222 | S29: -2852 | T29: =SUM(J29-SUM(Q29:S29)) -> -4042 | U29: -6407 | V29: -4422 | W29: -4046 | X29: =SUM(K29-SUM(U29:W29)) -> -14874 | Y29: -6254 | Z29: -4530 | AA29: -4597 | AC29: =SUM(N29:Q29) -> -18314 | AD29: =SUM(O29:R29) -> -17407 | AE29: =SUM(P29:S29) -> -16635 | AF29: =SUM(Q29:T29) -> -16741 | AG29: =SUM(R29:U29) -> -17523 | AH29: =SUM(S29:V29) -> -17723 | AI29: =SUM(T29:W29) -> -18917 | AJ29: =SUM(U29:X29) -> -29749 | ... AM29: =SUM(X29:AA29) -> -30255 | AO29: =SUM(AM29/AI29)-1 -> 0.59935508
B30: Net loss | C30: =SUM(C27+C29) -> 45687 | D30: =SUM(D27+D29) -> 48351 | E30: =SUM(E27+E29) -> 59531 | F30: =SUM(F27+F29) -> 55256 | G30: =SUM(G27+G29) -> 57411 | H30: =SUM(H27+H29) -> 94680 | I30: =SUM(I27+I29) -> 99803 | J30: =SUM(J27+J29) -> 96995 | K30: =SUM(K27+K29) -> 93736 | M30: =SUM(M27+M29) -> 34630 | N30: =SUM(N27+N29) -> 25010 | O30: =SUM(O27+O29) -> 19442 | P30: =SUM(P27+P29) -> 20721 | Q30: =SUM(Q27+Q29) -> 29998 | R30: =SUM(R27+R29) -> 24160 | S30: =SUM(S27+S29) -> 19881 | T30: =SUM(T27+T29) -> 22956 | ... AA30: =SUM(AA27+AA29) -> 23434 | AC30: =SUM(AC27+AC29) -> 95171 | AD30: =SUM(AD27+AD29) -> 94321 | AE30: =SUM(AE27+AE29) -> 94760 | AF30: =SUM(AF27+AF29) -> 96995 | AG30: =SUM(AG27+AG29) -> 100913 | AH30: =SUM(AH27+AH29) -> 100389 | AI30: =SUM(AI27+AI29) -> 101956 | AJ30: =SUM(AJ27+AJ29) -> 93736 | ... AM30: =SUM(AM27+AM29) -> 99280 | AO30: =SUM(AM30/AI30)-1 -> -0.026246616
B31: Net Margin (%) | C31: =C30/C15 -> 0.21186798 | D31: =D30/D15 -> 0.21092421 | E31: =E30/E15 -> 0.22414202 | F31: =F30/F15 -> 0.21238095 | G31: =G30/G15 -> 0.20913611 | H31: =H30/H15 -> 0.25881793 | I31: =I30/I15 -> 0.25309641 | J31: =J30/J15 -> 0.25306234 | K31: =K30/K15 -> 0.23971256 | M31: =M30/M15 -> 0.27939812 | N31: =N30/N15 -> 0.25709821 | O31: =O30/O15 -> 0.23435673 | P31: =P30/P15 -> 0.22986045 | Q31: =Q30/Q15 -> 0.25605613 | R31: =R30/R15 -> 0.25475558 | S31: =S30/S15 -> 0.24305292 | T31: =T30/T15 -> 0.25649735 | ... AA31: =AA30/AA15 -> 0.24920243 | AC31: =AC30/AC15 -> 0.24557913 | AD31: =AD30/AD15 -> 0.24492917 | AE31: =AE30/AE15 -> 0.2468139 | AF31: =AF30/AF15 -> 0.25306234 | AG31: =AG30/AG15 -> 0.26163192 | AH31: =AH30/AH15 -> 0.26305804 | AI31: =AI30/AI15 -> 0.26440666 | AJ31: =AJ30/AJ15 -> 0.23971256 | ... AM31: =AM30/AM15 -> 0.24296115 | AO31: =SUM(AM31-AI31)*1000 -> -21.445506
B33: Basic shares | C33: 21883.281 | D33: 20868.968 | E33: 19821.51 | F33: 18471.336 | G33: 17352.119 | H33: 16701.272 | I33: 16215.963 | J33: 15744.231 | K33: 15343.783 | M33: 16391.724 | N33: 16278.802 | O33: 16162.945 | P33: =I33 -> 16215.963 | Q33: 15892.723 | R33: 15787.154 | S33: 15697.614 | T33: =J33 -> 15744.231 | U33: 15509.763 | V33: 15405.856 | W33: 15287.521 | X33: =K33 -> 15343.783 | Y33: 15081.724 | Z33: 14994.082 | AA33: 14902.886 | AC33: =Q33 -> 15892.723 | AD33: =R33 -> 15787.154 | AE33: =S33 -> 15697.614 | AF33: =T33 -> 15744.231 | AG33: =U33 -> 15509.763 | AH33: =V33 -> 15405.856 | AI33: =W33 -> 15287.521 | AJ33: =X33 -> 15343.783 | ... AM33: =AA33 -> 14902.886
B34: Basic EPS | C34: =C30/C33 -> 2.0877582 | D34: =D30/D33 -> 2.3168851 | E34: =E30/E33 -> 3.0033534 | F34: =F30/F33 -> 2.9914458 | G34: =G30/G33 -> 3.3085873 | H34: =H30/H33 -> 5.6690293 | I34: =I30/I33 -> 6.1546144 | J34: =J30/J33 -> 6.1606693 | K34: =K30/K33 -> 6.1090541 | M34: =M30/M33 -> 2.1126515 | N34: =N30/N33 -> 1.5363538 | O34: =O30/O33 -> 1.2028748 | P34: =P30/P33 -> 1.277815 | Q34: =Q30/Q33 -> 1.8875305 | R34: =R30/R33 -> 1.5303582 | S34: =S30/S33 -> 1.2664982 | T34: =T30/T33 -> 1.4580579 | ... AA34: =AA30/AA33 -> 1.5724471 | AC34: =AC30/AC33 -> 5.9883382 | AD34: =AD30/AD33 -> 5.9745411 | AE34: =AE30/AE33 -> 6.0365862 | AF34: =AF30/AF33 -> 6.1606693 | AG34: =AG30/AG33 -> 6.5064179 | AH34: =AH30/AH33 -> 6.5162884 | AI34: =AI30/AI33 -> 6.6692304 | AJ34: =AJ30/AJ33 -> 6.1090541 | ... AM34: =AM30/AM33 -> 6.6617969 | AO34: =SUM(AM34/AI34)-1 -> -0.0011145959
B36: Fully Diluted Shares | C36: 22001.127 | D36: 21006.767 | E36: 20000.436 | F36: 18595.651 | G36: 17528.214 | H36: 16864.919 | I36: 16325.819 | J36: 15812.547 | K36: 15408.095 | M36: 16519.291 | N36: 16403.316 | O36: 16262.203 | P36: =I36 -> 16325.819 | Q36: 15955.718 | R36: 15847.05 | S36: 15775.021 | T36: =J36 -> 15812.547 | U36: 15576.641 | V36: 15464.709 | W36: 15348.175 | X36: =K36 -> 15408.095 | Y36: 15150.865 | Z36: 15056.133 | AA36: 14948.179 | AC36: =Q36 -> 15955.718 | AD36: =R36 -> 15847.05 | AE36: =S36 -> 15775.021 | AF36: =T36 -> 15812.547 | AG36: =U36 -> 15576.641 | AH36: =V36 -> 15464.709 | AI36: =W36 -> 15348.175 | AJ36: =X36 -> 15408.095 | ... AM36: =AA36 -> 14948.179
B37: Diluted EPS | C37: =C30/C36 -> 2.0765754 | D37: =D30/D36 -> 2.3016869 | E37: =E30/E36 -> 2.9764851 | F37: =F30/F36 -> 2.9714475 | G37: =G30/G36 -> 3.275348 | H37: =H30/H36 -> 5.6140204 | I37: =I30/I36 -> 6.1132002 | J37: =J30/J36 -> 6.1340529 | K37: =K30/K36 -> 6.0835554 | M37: =M30/M36 -> 2.0963369 | N37: =N30/N36 -> 1.5246917 | O37: =O30/O36 -> 1.195533 | P37: =P30/P36 -> 1.2692166 | Q37: =Q30/Q36 -> 1.8800784 | R37: =R30/R36 -> 1.524574 | S37: =S30/S36 -> 1.2602836 | T37: =T30/T36 -> 1.4517585 | ... AA37: =AA30/AA36 -> 1.5676826 | AC37: =AC30/AC36 -> 5.9646955 | AD37: =AD30/AD36 -> 5.9519595 | AE37: =AE30/AE36 -> 6.0069651 | AF37: =AF30/AF36 -> 6.1340529 | AG37: =AG30/AG36 -> 6.4784827 | AH37: =AH30/AH36 -> 6.4914898 | AI37: =AI30/AI36 -> 6.6428745 | AJ37: =AJ30/AJ36 -> 6.0835554 | ... AM37: =AM30/AM36 -> 6.6416117 | AO37: =SUM(AM37/AI37)-1 -> -0.00019010064
A39: X | B39: Balance Sheet | C39: FYE | M39: Quarterly | AI39: LTM | AO39: Variance
B40: =B11 -> Fiscal Period | C40: =C11 -> 2016 | D40: =D11 -> 2017 | E40: =E11 -> 2018 | F40: =F11 -> 2019 | G40: =G11 -> 2020 | H40: =H11 -> 2021 | I40: =I11 -> 2022 | ... K40: =K11 -> 2024 | M40: =M11 -> 1Q22 | N40: =N11 -> 2Q22 | O40: =O11 -> 3Q22 | P40: =P11 -> 4Q22 | Q40: =Q11 -> 1Q23 | R40: =R11 -> 2Q23 | S40: =S11 -> 3Q23 | T40: =T11 -> 4Q23 | ... AA40: =AA11 -> 3Q25 | AC40: =AC11 -> 1Q23 | AD40: =AD11 -> 2Q23 | AE40: =AE11 -> 3Q23 | AF40: =AF11 -> 4Q23 | AG40: =AG11 -> 1Q24 | AH40: =AH11 -> 2Q24 | AI40: =AI11 -> 3Q24 | AJ40: =AJ11 -> 4Q24 | ... AM40: =AM11 -> 3Q25
B41: =B12 -> Fiscal Period End Date | C41: =C12 -> 42643 | D41: =D12 -> 43008 | E41: =E12 -> 43372 | F41: =F12 -> 43737 | G41: =G12 -> 44104 | H41: =H12 -> 44469 | I41: =I12 -> 44834 | ... K41: =K12 -> 45559 | M41: =M12 -> 44560 | N41: =N12 -> 44650 | O41: =O12 -> 44742 | P41: =P12 -> 44834 | Q41: =Q12 -> 44917 | R41: =R12 -> 45008 | S41: =S12 -> 45100 | T41: =T12 -> 45192 | ... AA41: =AA12 -> 45833 | AC41: =AC12 -> 44917 | AD41: =AD12 -> 45008 | AE41: =AE12 -> 45100 | AF41: =AF12 -> 45192 | AG41: =AG12 -> 45283 | AH41: =AH12 -> 45375 | AI41: =AI12 -> 45467 | AJ41: =AJ12 -> 45559 | ... AM41: =AM12 -> 45833
B43: Cash/Equivalents | C43: 20484 | D43: 20289 | E43: 25913 | F43: 48844 | G43: 38016 | H43: 34940 | I43: 23646 | J43: 29965 | K43: 29943 | M43: 37119 | N43: 28098 | O43: 27502 | P43: =I43 -> 23646 | Q43: 20535 | R43: 24687 | S43: 28408 | T43: =J43 -> 29965 | U43: 40760 | V43: 32695 | W43: 25565 | X43: =K43 -> 29943 | Y43: 30299 | Z43: 28162 | AA43: 36269 | AC43: =Q43 -> 20535 | AD43: =R43 -> 24687 | AE43: =S43 -> 28408 | AF43: =T43 -> 29965 | AG43: =U43 -> 40760 | AH43: =V43 -> 32695 | AI43: =W43 -> 25565 | AJ43: =X43 -> 29943 | ... AM43: =AA43 -> 36269 | AO43: =SUM(AM43/AI43)-1 -> 0.41869744
B44: Marketable Securities, Current | C44: 46671 | D44: 53892 | E44: 40388 | F44: 51713 | G44: 52927 | H44: 27699 | I44: 24658 | J44: 31590 | K44: 35228 | M44: 26794 | N44: 23413 | O44: 20729 | P44: =I44 -> 24658 | Q44: 30820 | R44: 31185 | S44: 34074 | T44: =J44 -> 31590 | U44: 32340 | V44: 34455 | W44: 36236 | X44: =K44 -> 35228 | Y44: 23476 | Z44: 20336 | AA44: 19103 | AC44: =Q44 -> 30820 | AD44: =R44 -> 31185 | AE44: =S44 -> 34074 | AF44: =T44 -> 31590 | AG44: =U44 -> 32340 | AH44: =V44 -> 34455 | AI44: =W44 -> 36236 | AJ44: =X44 -> 35228 | ... AM44: =AA44 -> 19103 | AO44: =SUM(AM44/AI44)-1 -> -0.47281709
B45: Accounts Receivable | C45: 15754 | D45: 17874 | E45: 23186 | F45: 22926 | G45: 16120 | H45: 26278 | I45: 28184 | J45: 29508 | K45: 66243 | M45: 30213 | N45: 20815 | O45: 21803 | P45: =I45 -> 28184 | Q45: 23752 | R45: 17936 | S45: 19549 | T45: =J45 -> 29508 | U45: 23194 | V45: 21837 | W45: 22795 | X45: =K45 -> 66243 | Y45: 29639 | Z45: 49798 | AA45: 46835 | AC45: =Q45 -> 23752 | AD45: =R45 -> 17936 | AE45: =S45 -> 19549 | AF45: =T45 -> 29508 | AG45: =U45 -> 23194 | AH45: =V45 -> 21837 | AI45: =W45 -> 22795 | AJ45: =X45 -> 66243 | ... AM45: =AA45 -> 46835 | AO45: =SUM(AM45/AI45)-1 -> 1.0546172
B46: Inventory | C46: 2132 | D46: 4855 | E46: 3956 | F46: 4106 | G46: 4061 | H46: 6580 | I46: 4946 | J46: 6331 | K46: 7286 | M46: 5876 | N46: 5460 | O46: 5433 | P46: =I46 -> 4946 | Q46: 6820 | R46: 7482 | S46: 7351 | T46: =J46 -> 6331 | U46: 6511 | V46: 6232 | W46: 6165 | X46: =K46 -> 7286 | Y46: 6911 | Z46: 6269 | AA46: 5925 | AC46: =Q46 -> 6820 | AD46: =R46 -> 7482 | AE46: =S46 -> 7351 | AF46: =T46 -> 6331 | AG46: =U46 -> 6511 | AH46: =V46 -> 6232 | AI46: =W46 -> 6165 | AJ46: =X46 -> 7286 | ... AM46: =AA46 -> 5925 | AO46: =SUM(AM46/AI46)-1 -> -0.03892944
B47: Other Current Assets | C47: 21828 | D47: =13936+17799 -> 31735 | E47: 37896 | F47: 35230 | G47: 32589 | H47: 39339 | I47: 53971 | J47: 46172 | K47: 14287 | M47: 53152 | N47: 40394 | O47: 36825 | P47: =I47 -> 53971 | Q47: 46850 | R47: 31623 | S47: 33277 | T47: =J47 -> 46172 | U47: 40887 | V47: 33197 | W47: 34674 | X47: =K47 -> 14287 | Y47: 42915 | Z47: 14109 | AA47: 14359 | AC47: =Q47 -> 46850 | AD47: =R47 -> 31623 | AE47: =S47 -> 33277 | AF47: =T47 -> 46172 | AG47: =U47 -> 40887 | AH47: =V47 -> 33197 | AI47: =W47 -> 34674 | AJ47: =X47 -> 14287 | ... AM47: =AA47 -> 14359 | AO47: =SUM(AM47/AI47)-1 -> -0.58588568
B48: Total Current Assets | C48: =SUM(C43:C47) -> 106869 | D48: =SUM(D43:D47) -> 128645 | E48: =SUM(E43:E47) -> 131339 | F48: =SUM(F43:F47) -> 162819 | G48: =SUM(G43:G47) -> 143713 | H48: =SUM(H43:H47) -> 134836 | I48: =SUM(I43:I47) -> 135405 | J48: =SUM(J43:J47) -> 143566 | K48: =SUM(K43:K47) -> 152987 | M48: =SUM(M43:M47) -> 153154 | N48: =SUM(N43:N47) -> 118180 | O48: =SUM(O43:O47) -> 112292 | P48: =SUM(P43:P47) -> 135405 | Q48: =SUM(Q43:Q47) -> 128777 | R48: =SUM(R43:R47) -> 112913 | S48: =SUM(S43:S47) -> 122659 | T48: =SUM(T43:T47) -> 143566 | ... AA48: =SUM(AA43:AA47) -> 122491 | AC48: =SUM(AC43:AC47) -> 128777 | AD48: =SUM(AD43:AD47) -> 112913 | AE48: =SUM(AE43:AE47) -> 122659 | AF48: =SUM(AF43:AF47) -> 143566 | AG48: =SUM(AG43:AG47) -> 143692 | AH48: =SUM(AH43:AH47) -> 128416 | AI48: =SUM(AI43:AI47) -> 125435 | AJ48: =SUM(AJ43:AJ47) -> 152987 | ... AM48: =SUM(AM43:AM47) -> 122491 | AO48: =SUM(AM48/AI48)-1 -> -0.023470323
B50: PP&E | C50: 27010 | D50: 33783 | E50: 41304 | F50: 37378 | G50: 36766 | H50: 39440 | I50: 42117 | J50: 43715 | K50: 45680 | M50: 39245 | N50: 39304 | O50: 40335 | P50: =I50 -> 42117 | Q50: 42951 | R50: 43398 | S50: 43550 | T50: =J50 -> 43715 | U50: 43666 | V50: 43546 | W50: 44502 | X50: =K50 -> 45680 | Y50: 46069 | Z50: 46876 | AA50: 48508 | AC50: =Q50 -> 42951 | AD50: =R50 -> 43398 | AE50: =S50 -> 43550 | AF50: =T50 -> 43715 | AG50: =U50 -> 43666 | AH50: =V50 -> 43546 | AI50: =W50 -> 44502 | AJ50: =X50 -> 45680 | ... AM50: =AA50 -> 48508 | AO50: =SUM(AM50/AI50)-1 -> 0.090018426
B51: Marketable Securities, Net of Current Portion | C51: 170430 | D51: 194714 | E51: 170799 | F51: 105341 | G51: 100887 | H51: 127877 | I51: 120805 | J51: 100544 | K51: 91479 | M51: 138683 | N51: 141219 | O51: 131077 | P51: =I51 -> 120805 | Q51: 114095 | R51: 110461 | S51: 104061 | T51: =J51 -> 100544 | U51: 99475 | V51: 95187 | W51: 91240 | X51: =K51 -> 91479 | Y51: 87593 | Z51: 84424 | AA51: 77614 | AC51: =Q51 -> 114095 | AD51: =R51 -> 110461 | AE51: =S51 -> 104061 | AF51: =T51 -> 100544 | AG51: =U51 -> 99475 | AH51: =V51 -> 95187 | AI51: =W51 -> 91240 | AJ51: =X51 -> 91479 | ... AM51: =AA51 -> 77614 | AO51: =SUM(AM51/AI51)-1 -> -0.14934239
B52: Other Assets | C52: =5414+3206+8757 -> 17377 | D52: 18177 | E52: 22283 | F52: 32978 | G52: 42522 | H52: 48849 | I52: 54428 | J52: 64758 | K52: 74834 | M52: 42071 | N52: 43921 | O52: 44567 | P52: =I52 -> 54428 | Q52: 52886 | R52: 57350 | S52: 56730 | T52: =J52 -> 64758 | U52: 58643 | V52: 62224 | W52: 62397 | X52: =K52 -> 74834 | Y52: 77183 | Z52: 81259 | AA52: 82882 | AC52: =Q52 -> 52886 | AD52: =R52 -> 57350 | AE52: =S52 -> 56730 | AF52: =T52 -> 64758 | AG52: =U52 -> 58643 | AH52: =V52 -> 62224 | AI52: =W52 -> 62397 | AJ52: =X52 -> 74834 | ... AM52: =AA52 -> 82882 | AO52: =SUM(AM52/AI52)-1 -> 0.32830104
B53: Total Assets | C53: =SUM(C50:C52)+C48 -> 321686 | D53: =SUM(D50:D52)+D48 -> 375319 | E53: =SUM(E50:E52)+E48 -> 365725 | F53: =SUM(F50:F52)+F48 -> 338516 | G53: =SUM(G50:G52)+G48 -> 323888 | H53: =SUM(H50:H52)+H48 -> 351002 | I53: =SUM(I50:I52)+I48 -> 352755 | J53: =SUM(J50:J52)+J48 -> 352583 | K53: =SUM(K50:K52)+K48 -> 364980 | M53: =SUM(M50:M52)+M48 -> 373153 | N53: =SUM(N50:N52)+N48 -> 342624 | O53: =SUM(O50:O52)+O48 -> 328271 | P53: =SUM(P50:P52)+P48 -> 352755 | Q53: =SUM(Q50:Q52)+Q48 -> 338709 | R53: =SUM(R50:R52)+R48 -> 324122 | S53: =SUM(S50:S52)+S48 -> 327000 | T53: =SUM(T50:T52)+T48 -> 352583 | ... AA53: =SUM(AA50:AA52)+AA48 -> 331495 | AC53: =SUM(AC50:AC52)+AC48 -> 338709 | AD53: =SUM(AD50:AD52)+AD48 -> 324122 | AE53: =SUM(AE50:AE52)+AE48 -> 327000 | AF53: =SUM(AF50:AF52)+AF48 -> 352583 | AG53: =SUM(AG50:AG52)+AG48 -> 345476 | AH53: =SUM(AH50:AH52)+AH48 -> 329373 | AI53: =SUM(AI50:AI52)+AI48 -> 323574 | AJ53: =SUM(AJ50:AJ52)+AJ48 -> 364980 | ... AM53: =SUM(AM50:AM52)+AM48 -> 331495 | AO53: =SUM(AM53/AI53)-1 -> 0.024479717
B55: Accounts Payable | C55: 37294 | D55: 44242 | E55: 55888 | F55: 46236 | G55: 42296 | H55: 54763 | I55: 64115 | J55: 62611 | K55: 68960 | M55: 74362 | N55: 52682 | O55: 48343 | P55: =I55 -> 64115 | Q55: 57918 | R55: 42945 | S55: 46699 | T55: =J55 -> 62611 | U55: 58146 | V55: 45753 | W55: 47574 | X55: =K55 -> 68960 | Y55: 61910 | Z55: 54126 | AA55: 50374 | AC55: =Q55 -> 57918 | AD55: =R55 -> 42945 | AE55: =S55 -> 46699 | AF55: =T55 -> 62611 | AG55: =U55 -> 58146 | AH55: =V55 -> 45753 | AI55: =W55 -> 47574 | AJ55: =X55 -> 68960 | ... AM55: =AA55 -> 50374 | AO55: =SUM(AM55/AI55)-1 -> 0.058855677
B56: Deferred Revenue - Current | C56: 8080 | D56: 7548 | E56: 7543 | F56: 5522 | G56: 6643 | H56: 7612 | I56: 7912 | J56: 8061 | K56: 8249 | M56: 7876 | N56: 7920 | O56: 7728 | P56: =I56 -> 7912 | Q56: 7992 | R56: 8131 | S56: 8158 | T56: =J56 -> 8061 | U56: 8264 | V56: 8012 | W56: 8053 | X56: =K56 -> 8249 | Y56: 8461 | Z56: 8976 | AA56: 8979 | AC56: =Q56 -> 7992 | AD56: =R56 -> 8131 | AE56: =S56 -> 8158 | AF56: =T56 -> 8061 | AG56: =U56 -> 8264 | AH56: =V56 -> 8012 | AI56: =W56 -> 8053 | AJ56: =X56 -> 8249 | ... AM56: =AA56 -> 8979 | AO56: =SUM(AM56/AI56)-1 -> 0.1149882
B57: Other Current Liabilities (accrued exp) | C57: 22027 | D57: 30551 | E57: 32687 | F57: 37720 | G57: 42684 | H57: 47493 | I57: 60845 | J57: 58829 | K57: 78304 | M57: 49167 | N57: 50248 | O57: 48811 | P57: =I57 -> 60845 | Q57: 59893 | R57: 56425 | S57: 58897 | T57: =J57 -> 58829 | U57: 54611 | V57: 57298 | W57: 60889 | X57: =K57 -> 78304 | Y57: 61151 | Z57: 61849 | AA57: 62499 | AC57: =Q57 -> 59893 | AD57: =R57 -> 56425 | AE57: =S57 -> 58897 | AF57: =T57 -> 58829 | AG57: =U57 -> 54611 | AH57: =V57 -> 57298 | AI57: =W57 -> 60889 | AJ57: =X57 -> 78304 | ... AM57: =AA57 -> 62499 | AO57: =SUM(AM57/AI57)-1 -> 0.026441558
...

Sheet Revenue Drivers
B2: Apple Inc. (NASDAQ: AAPL) | C2: FYE | M2: Quarterly | U2: Quarterly | V2: Quarterly | AC2: LTM | AG2: LTM | AO2: Variance
B3: Segment Anaysis | C3: ='Historical Financials'!C11 -> 2016 | D3: ='Historical Financials'!D11 -> 2017 | E3: ='Historical Financials'!E11 -> 2018 | F3: ='Historical Financials'!F11 -> 2019 | G3: ='Historical Financials'!G11 -> 2020 | H3: ='Historical Financials'!H11 -> 2021 | I3: ='Historical Financials'!I11 -> 2022 | J3: ='Historical Financials'!J11 -> 2023 | K3: ='Historical Financials'!K11 -> 2024 | M3: 1Q22 | N3: 2Q22 | O3: 3Q22 | P3: 4Q22 | Q3: 1Q23 | R3: 2Q23 | S3: 3Q23 | T3: 4Q23 | U3: 1Q24 | V3: 2Q24 | W3: 3Q24 | X3: 4Q24 | Y3: 1Q25 | Z3: 2Q25 | AA3: 3Q25 | AC3: 1Q23 | AD3: 2Q23 | AE3: 3Q23 | AF3: 4Q23 | AG3: 1Q24 | AH3: 2Q24 | AI3: 3Q24 | AJ3: 4Q24 | AK3: 1Q25 | AL3: 2Q25 | AM3: 3Q25
B4: $ mm except per share | C4: ='Historical Financials'!C12 -> 42643 | D4: ='Historical Financials'!D12 -> 43008 | E4: ='Historical Financials'!E12 -> 43372 | F4: ='Historical Financials'!F12 -> 43737 | G4: ='Historical Financials'!G12 -> 44104 | H4: ='Historical Financials'!H12 -> 44469 | I4: ='Historical Financials'!I12 -> 44834 | J4: ='Historical Financials'!J12 -> 45192 | K4: ='Historical Financials'!K12 -> 45559 | M4: 44560 | N4: 44650 | O4: 44742 | P4: 44834 | Q4: 44917 | R4: 45008 | S4: 45100 | T4: 45192 | U4: 45283 | V4: 45375 | W4: 45467 | X4: 45559 | Y4: 45650 | Z4: 45741 | AA4: 45833 | AC4: 44917 | AD4: 45008 | AE4: 45100 | AF4: 45192 | AG4: 45283 | AH4: 45375 | AI4: 45467 | AJ4: 45559 | AK4: 45650 | AL4: 45741 | AM4: 45833
A6: X | B6: Revenue by End Product
B7: iPhone Revenue | C7: 136700 | D7: 141319 | E7: 164888 | F7: 142381 | G7: 137781 | H7: 191973 | I7: 205489 | J7: 200583 | K7: 201183 | M7: 71628 | N7: 50570 | O7: 40665 | P7: 42626 | Q7: 65775 | R7: 51334 | S7: 39669 | T7: 43805 | U7: 69702 | V7: 45963 | W7: 39296 | X7: 46222 | Y7: 69138 | Z7: 46841 | AA7: 44582 | AC7: =SUM(N7:Q7) -> 199636 | AD7: =SUM(O7:R7) -> 200400 | AE7: =SUM(P7:S7) -> 199404 | AF7: =SUM(Q7:T7) -> 200583 | AG7: =SUM(R7:U7) -> 204510 | AH7: =SUM(S7:V7) -> 199139 | AI7: =SUM(T7:W7) -> 198766 | AJ7: =SUM(U7:X7) -> 201183 | ... AM7: =SUM(X7:AA7) -> 206783 | AO7: =SUM(AM7/AI7)-1 -> 0.04033386
B8: Mac Revenue | C8: 22831 | D8: 25850 | E8: 25198 | F8: 25740 | G8: 28622 | H8: 35190 | I8: 40177 | J8: 29357 | K8: 29984 | M8: 10852 | N8: 10435 | O8: 7382 | P8: 11508 | Q8: 7735 | R8: 7168 | S8: 6840 | T8: 7614 | U8: 7780 | V8: 7451 | W8: 7009 | X8: 7744 | Y8: 8987 | Z8: 7949 | AA8: 8046 | AC8: =SUM(N8:Q8) -> 37060 | AD8: =SUM(O8:R8) -> 33793 | AE8: =SUM(P8:S8) -> 33251 | AF8: =SUM(Q8:T8) -> 29357 | AG8: =SUM(R8:U8) -> 29402 | AH8: =SUM(S8:V8) -> 29685 | AI8: =SUM(T8:W8) -> 29854 | AJ8: =SUM(U8:X8) -> 29984 | ... AM8: =SUM(X8:AA8) -> 32726 | AO8: =SUM(AM8/AI8)-1 -> 0.096201514
B9: iPad Revenue | C9: 20628 | D9: 19222 | E9: 18380 | F9: 21280 | G9: 23724 | H9: 31862 | I9: 29292 | J9: 28300 | K9: 26694 | M9: 7248 | N9: 7646 | O9: 7224 | P9: 7174 | Q9: 9396 | R9: 6670 | S9: 5791 | T9: 6443 | U9: 7023 | V9: 5559 | W9: 7162 | X9: 6950 | Y9: 8088 | Z9: 6402 | AA9: 6581 | AC9: =SUM(N9:Q9) -> 31440 | AD9: =SUM(O9:R9) -> 30464 | AE9: =SUM(P9:S9) -> 29031 | AF9: =SUM(Q9:T9) -> 28300 | AG9: =SUM(R9:U9) -> 25927 | AH9: =SUM(S9:V9) -> 24816 | AI9: =SUM(T9:W9) -> 26187 | AJ9: =SUM(U9:X9) -> 26694 | ... AM9: =SUM(X9:AA9) -> 28021 | AO9: =SUM(AM9/AI9)-1 -> 0.07003475
B10: Services Revenue | C10: 24348 | D10: 29980 | E10: 39748 | F10: 46291 | G10: 53768 | H10: 68425 | I10: 78129 | J10: 85200 | K10: 96169 | M10: 19516 | N10: 19821 | O10: 19604 | P10: 19188 | Q10: 20766 | R10: 20907 | S10: 21213 | T10: 22314 | U10: 23117 | V10: 23867 | W10: 24213 | X10: 24972 | Y10: 26340 | Z10: 26645 | AA10: 27423 | AI10: =SUM(T10:W10) -> 93511 | AJ10: =SUM(U10:X10) -> 96169 | AK10: =SUM(V10:Y10) -> 99392 | AL10: =SUM(W10:Z10) -> 102170 | AM10: =SUM(X10:AA10) -> 105380
B11: Wearables, Home, and Accessories Revenue | C11: 11132 | D11: 12863 | E11: 17381 | F11: 24482 | G11: 30620 | H11: 38367 | I11: 41241 | J11: 39845 | K11: 37005 | M11: 14701 | N11: 8806 | O11: 8084 | P11: 9650 | Q11: 13482 | R11: 8757 | S11: 8284 | T11: 9322 | U11: 11953 | V11: 7913 | W11: 8097 | X11: 9042 | Y11: 11747 | Z11: 7522 | AA11: 7404 | AI11: =SUM(T11:W11) -> 37285 | AJ11: =SUM(U11:X11) -> 37005 | AK11: =SUM(V11:Y11) -> 36799 | AL11: =SUM(W11:Z11) -> 36408 | AM11: =SUM(X11:AA11) -> 35715
B12: Total Net Revenue | C12: =SUM(C7:C11) -> 215639 | D12: =SUM(D7:D11) -> 229234 | E12: =SUM(E7:E11) -> 265595 | F12: =SUM(F7:F11) -> 260174 | G12: =SUM(G7:G11) -> 274515 | H12: =SUM(H7:H11) -> 365817 | I12: =SUM(I7:I11) -> 394328 | J12: =SUM(J7:J11) -> 383285 | K12: =SUM(K7:K11) -> 391035 | M12: =SUM(M7:M11) -> 123945 | N12: =SUM(N7:N11) -> 97278 | O12: =SUM(O7:O11) -> 82959 | P12: =SUM(P7:P11) -> 90146 | Q12: =SUM(Q7:Q11) -> 117154 | R12: =SUM(R7:R11) -> 94836 | S12: =SUM(S7:S11) -> 81797 | T12: =SUM(T7:T11) -> 89498 | ... AA12: =SUM(AA7:AA11) -> 94036 | AC12: =SUM(AC7:AC9) -> 268136 | AD12: =SUM(AD7:AD9) -> 264657 | AE12: =SUM(AE7:AE9) -> 261686 | AF12: =SUM(AF7:AF9) -> 258240 | AG12: =SUM(AG7:AG9) -> 259839 | AH12: =SUM(AH7:AH9) -> 253640 | AI12: =SUM(AI7:AI11) -> 385603 | AJ12: =SUM(AJ7:AJ11) -> 391035 | AK12: =SUM(AK7:AK11) -> 395760 | AL12: =SUM(AL7:AL11) -> 400366 | AM12: =SUM(AM7:AM11) -> 408625 | AO12: =SUM(AM12/AI12)-1 -> 0.059703892
B13: Balance Check | C13: =C12-'Historical Financials'!C15 -> 0 | D13: =D12-'Historical Financials'!D15 -> 0 | E13: =E12-'Historical Financials'!E15 -> 0 | F13: =F12-'Historical Financials'!F15 -> 0 | G13: =G12-'Historical Financials'!G15 -> 0 | H13: =H12-'Historical Financials'!H15 -> 0 | I13: =I12-'Historical Financials'!I15 -> 0 | J13: =J12-'Historical Financials'!J15 -> 0 | K13: =K12-'Historical Financials'!K15 -> 0 | M13: =M12-'Historical Financials'!M15 -> 0 | N13: =N12-'Historical Financials'!N15 -> 0 | O13: =O12-'Historical Financials'!O15 -> 0 | P13: =P12-'Historical Financials'!P15 -> 0 | Q13: =Q12-'Historical Financials'!Q15 -> 0 | R13: =R12-'Historical Financials'!R15 -> 0 | S13: =S12-'Historical Financials'!S15 -> 0 | T13: =T12-'Historical Financials'!T15 -> 0 | ... AA13: =AA12-'Historical Financials'!AA15 -> 0 | AC13: =AC12-'Historical Financials'!AC15 -> -119401 | AD13: =AD12-'Historical Financials'!AD15 -> -120438 | AE13: =AE12-'Historical Financials'!AE15 -> -122247 | AF13: =AF12-'Historical Financials'!AF15 -> -125045 | AG13: =AG12-'Historical Financials'!AG15 -> -125867 | AH13: =AH12-'Historical Financials'!AH15 -> -127983 | AI13: =AI12-'Historical Financials'!AI15 -> 0 | AJ13: =AJ12-'Historical Financials'!AJ15 -> 0 | ... AM13: =AM12-'Historical Financials'!AM15 -> 0
A15: X | B15: Revenue by Product Offerings: Wearables, Home, and Accessories
B16: Accessories | G16: 16019.941 | H16: 20596.468 | I16: 21262.875 | J16: 19827.709 | K16: 18865.888 | M16: 5656.6733 | N16: 6070.4168 | O16: 4391.8204 | P16: 5143.9643 | Q16: 4250.8013 | R16: 5709.2465 | S16: 4595.9109 | T16: 5271.75 | U16: 4111.1639 | V16: 5174.0625 | W16: 4782.089 | X16: 4798.5722 | Y16: 3839.2947 | Z16: 4674.9385 | AA16: 4052.9944 | AC16: =SUM(N16:Q16) -> 19857.003 | AD16: =SUM(O16:R16) -> 19495.832 | AE16: =SUM(P16:S16) -> 19699.923 | AF16: =SUM(Q16:T16) -> 19827.709 | AG16: =SUM(R16:U16) -> 19688.071 | AH16: =SUM(S16:V16) -> 19152.887 | AI16: =SUM(T16:W16) -> 19339.065 | AJ16: =SUM(U16:X16) -> 18865.888 | ... AM16: =SUM(X16:AA16) -> 17365.8 | AO16: =SUM(AM16/AI16)-1 -> -0.10203521
B17: Apple Watch | G17: 14229.125 | H17: 17479.962 | I17: 19750.272 | J17: 19838.618 | K17: 17999.002 | M17: 8954.015 | N17: 2690.982 | O17: 3644.0381 | P17: 4461.2373 | Q17: 9160.4076 | R17: 3012.7635 | S17: 3650.3329 | T17: 4015.1136 | U17: 7786.3465 | V17: 2711.4871 | W17: 3285.2996 | X17: 4215.8692 | Y17: 7864.2099 | Z17: 2847.0615 | AA17: 3351.0056 | AC17: =SUM(N17:Q17) -> 19956.665 | AD17: =SUM(O17:R17) -> 20278.447 | AE17: =SUM(P17:S17) -> 20284.741 | AF17: =SUM(Q17:T17) -> 19838.618 | AG17: =SUM(R17:U17) -> 18464.556 | AH17: =SUM(S17:V17) -> 18163.28 | AI17: =SUM(T17:W17) -> 17798.247 | AJ17: =SUM(U17:X17) -> 17999.002 | ... AM17: =SUM(X17:AA17) -> 18278.146 | AO17: =SUM(AM17/AI17)-1 -> 0.026963301
B18: Total Intel Products Revenue | G18: =SUM(G16:G17) -> 30249.066 | H18: =SUM(H16:H17) -> 38076.431 | I18: =SUM(I16:I17) -> 41013.147 | J18: =SUM(J16:J17) -> 39666.326 | K18: =SUM(K16:K17) -> 36864.89 | M18: =SUM(M16:M17) -> 14610.688 | N18: =SUM(N16:N17) -> 8761.3988 | O18: =SUM(O16:O17) -> 8035.8585 | P18: =SUM(P16:P17) -> 9605.2016 | Q18: =SUM(Q16:Q17) -> 13411.209 | R18: =SUM(R16:R17) -> 8722.01 | S18: =SUM(S16:S17) -> 8246.2439 | T18: =SUM(T16:T17) -> 9286.8636 | ... AA18: =SUM(AA16:AA17) -> 7404 | AC18: =SUM(AC16:AC17) -> 39813.668 | AD18: =SUM(AD16:AD17) -> 39774.279 | AE18: =SUM(AE16:AE17) -> 39984.664 | AF18: =SUM(AF16:AF17) -> 39666.326 | AG18: =SUM(AG16:AG17) -> 38152.628 | AH18: =SUM(AH16:AH17) -> 37316.167 | AI18: =SUM(AI16:AI17) -> 37137.312 | AJ18: =SUM(AJ16:AJ17) -> 36864.89 | ... AM18: =SUM(AM16:AM17) -> 35643.946 | AO18: =SUM(AM18/AI18)-1 -> -0.040212015
B19: Balance Check | G19: =G11-G18 -> 370.93376 | H19: =H11-H18 -> 290.56925 | I19: =I11-I18 -> 227.85276 | J19: =J11-J18 -> 178.67374 | K19: =K11-K18 -> 140.10996 | M19: =M11-M18 -> 90.311719 | N19: =N11-N18 -> 44.601177 | O19: =O11-O18 -> 48.141511 | P19: =P11-P18 -> 44.798357 | Q19: =Q11-Q18 -> 70.79113 | R19: =R11-R18 -> 34.990036 | S19: =S11-S18 -> 37.756146 | T19: =T11-T18 -> 35.136432 | ... AA19: =AA11-AA18 -> 0 | AC19: =AC7-AC18 -> 159822.33 | AD19: =AD7-AD18 -> 160625.72 | AE19: =AE7-AE18 -> 159419.34 | AF19: =AF7-AF18 -> 160916.67 | AG19: =AG7-AG18 -> 166357.37 | AH19: =AH7-AH18 -> 161822.83 | AI19: =AI7-AI18 -> 161628.69 | AJ19: =AJ7-AJ18 -> 164318.11 | ... AM19: =AM7-AM18 -> 171139.05

Sheet FCF
B2: Apple Inc. (NASDAQ: AAPL) | C2: FYE | I2: Quarterly | Q2: Quarterly | S2: Quarterly | Y2: LTM | AC2: LTM | AF2: LTM | AL2: Variance
B3: FCF Analysis | C3: 2020 | D3: 2021 | E3: 2022 | F3: 2023 | G3: 2024 | I3: 1Q22 | J3: 2Q22 | K3: 3Q22 | L3: 4Q22 | M3: 1Q23 | N3: 2Q23 | O3: 3Q23 | P3: 4Q23 | Q3: 1Q24 | R3: 2Q24 | S3: 3Q24 | T3: 4Q24 | U3: 1Q25 | V3: 2Q25 | W3: 3Q25 | Y3: 4Q22 | Z3: 1Q23 | AA3: 2Q23 | AB3: 3Q23 | AC3: 4Q23 | AD3: 1Q24 | AE3: 2Q24 | AF3: 3Q24 | AG3: 4Q24 | AH3: 1Q25 | AI3: 2Q25 | AJ3: 3Q25
B4: $ mm except per share | C4: 44104 | D4: 44469 | E4: 44834 | F4: 45192 | G4: 45559 | I4: 44560 | J4: 44650 | K4: 44742 | L4: 44834 | M4: 44917 | N4: 45008 | O4: 45100 | P4: 45192 | Q4: 45283 | R4: 45375 | S4: 45467 | T4: 45559 | U4: 45650 | V4: 45741 | W4: 45833 | Y4: 44834 | Z4: 44917 | AA4: 45008 | AB4: 45100 | AC4: 45192 | AD4: 45283 | AE4: 45375 | AF4: 45467 | AG4: 45559 | AH4: 45650 | AI4: 45741 | AJ4: 45833
B6: ='Revenue Drivers'!B7 -> iPhone Revenue | C6: ='Revenue Drivers'!G7 -> 137781 | D6: ='Revenue Drivers'!H7 -> 191973 | E6: ='Revenue Drivers'!I7 -> 205489 | F6: ='Revenue Drivers'!J7 -> 200583 | G6: ='Revenue Drivers'!K7 -> 201183 | I6: ='Revenue Drivers'!M7 -> 71628 | J6: ='Revenue Drivers'!N7 -> 50570 | K6: ='Revenue Drivers'!O7 -> 40665 | L6: ='Revenue Drivers'!P7 -> 42626 | M6: ='Revenue Drivers'!Q7 -> 65775 | N6: ='Revenue Drivers'!R7 -> 51334 | O6: ='Revenue Drivers'!S7 -> 39669 | P6: ='Revenue Drivers'!T7 -> 43805 | ... W6: ='Revenue Drivers'!AA7 -> 44582 | Y6: =SUM(I6:L6) -> 205489 | Z6: =SUM(J6:M6) -> 199636 | AA6: =SUM(K6:N6) -> 200400 | AB6: =SUM(L6:O6) -> 199404 | AC6: =SUM(M6:P6) -> 200583 | AD6: =SUM(N6:Q6) -> 204510 | AE6: =SUM(O6:R6) -> 199139 | AF6: =SUM(P6:S6) -> 198766 | ... AJ6: =SUM(T6:W6) -> 206783 | AL6: =SUM(AJ6/AF6)-1 -> 0.04033386
B7: ='Revenue Drivers'!B8 -> Mac Revenue | C7: ='Revenue Drivers'!G8 -> 28622 | D7: ='Revenue Drivers'!H8 -> 35190 | E7: ='Revenue Drivers'!I8 -> 40177 | F7: ='Revenue Drivers'!J8 -> 29357 | G7: ='Revenue Drivers'!K8 -> 29984 | I7: ='Revenue Drivers'!M8 -> 10852 | J7: ='Revenue Drivers'!N8 -> 10435 | K7: ='Revenue Drivers'!O8 -> 7382 | L7: ='Revenue Drivers'!P8 -> 11508 | M7: ='Revenue Drivers'!Q8 -> 7735 | N7: ='Revenue Drivers'!R8 -> 7168 | O7: ='Revenue Drivers'!S8 -> 6840 | P7: ='Revenue Drivers'!T8 -> 7614 | ... W7: ='Revenue Drivers'!AA8 -> 8046 | Y7: =SUM(I7:L7) -> 40177 | Z7: =SUM(J7:M7) -> 37060 | AA7: =SUM(K7:N7) -> 33793 | AB7: =SUM(L7:O7) -> 33251 | AC7: =SUM(M7:P7) -> 29357 | AD7: =SUM(N7:Q7) -> 29402 | AE7: =SUM(O7:R7) -> 29685 | AF7: =SUM(P7:S7) -> 29854 | ... AJ7: =SUM(T7:W7) -> 32726 | AL7: =SUM(AJ7/AF7)-1 -> 0.096201514
B8: ='Revenue Drivers'!B9 -> iPad Revenue | C8: ='Revenue Drivers'!G9 -> 23724 | D8: ='Revenue Drivers'!H9 -> 31862 | E8: ='Revenue Drivers'!I9 -> 29292 | F8: ='Revenue Drivers'!J9 -> 28300 | G8: ='Revenue Drivers'!K9 -> 26694 | I8: ='Revenue Drivers'!M9 -> 7248 | J8: ='Revenue Drivers'!N9 -> 7646 | K8: ='Revenue Drivers'!O9 -> 7224 | L8: ='Revenue Drivers'!P9 -> 7174 | M8: ='Revenue Drivers'!Q9 -> 9396 | N8: ='Revenue Drivers'!R9 -> 6670 | O8: ='Revenue Drivers'!S9 -> 5791 | P8: ='Revenue Drivers'!T9 -> 6443 | ... W8: ='Revenue Drivers'!AA9 -> 6581 | Y8: =SUM(I8:L8) -> 29292 | Z8: =SUM(J8:M8) -> 31440 | AA8: =SUM(K8:N8) -> 30464 | AB8: =SUM(L8:O8) -> 29031 | AC8: =SUM(M8:P8) -> 28300 | AD8: =SUM(N8:Q8) -> 25927 | AE8: =SUM(O8:R8) -> 24816 | AF8: =SUM(P8:S8) -> 26187 | ... AJ8: =SUM(T8:W8) -> 28021 | AL8: =SUM(AJ8/AF8)-1 -> 0.07003475
B9: ='Revenue Drivers'!B10 -> Services Revenue | C9: ='Revenue Drivers'!G10 -> 53768 | D9: ='Revenue Drivers'!H10 -> 68425 | E9: ='Revenue Drivers'!I10 -> 78129 | F9: ='Revenue Drivers'!J10 -> 85200 | G9: ='Revenue Drivers'!K10 -> 96169 | I9: ='Revenue Drivers'!M10 -> 19516 | J9: ='Revenue Drivers'!N10 -> 19821 | K9: ='Revenue Drivers'!O10 -> 19604 | L9: ='Revenue Drivers'!P10 -> 19188 | M9: ='Revenue Drivers'!Q10 -> 20766 | N9: ='Revenue Drivers'!R10 -> 20907 | O9: ='Revenue Drivers'!S10 -> 21213 | P9: ='Revenue Drivers'!T10 -> 22314 | ... W9: ='Revenue Drivers'!AA10 -> 27423 | Y9: =SUM(I9:L9) -> 78129 | Z9: =SUM(J9:M9) -> 79379 | AA9: =SUM(K9:N9) -> 80465 | AB9: =SUM(L9:O9) -> 82074 | AC9: =SUM(M9:P9) -> 85200 | AD9: =SUM(N9:Q9) -> 87551 | AE9: =SUM(O9:R9) -> 90511 | AF9: =SUM(P9:S9) -> 93511 | ... AJ9: =SUM(T9:W9) -> 105380 | AL9: =SUM(AJ9/AF9)-1 -> 0.12692624
B10: ='Revenue Drivers'!B11 -> Wearables, Home, and Accessories Revenue | C10: ='Revenue Drivers'!G11 -> 30620 | D10: ='Revenue Drivers'!H11 -> 38367 | E10: ='Revenue Drivers'!I11 -> 41241 | F10: ='Revenue Drivers'!J11 -> 39845 | G10: ='Revenue Drivers'!K11 -> 37005 | I10: ='Revenue Drivers'!M11 -> 14701 | J10: ='Revenue Drivers'!N11 -> 8806 | K10: ='Revenue Drivers'!O11 -> 8084 | L10: ='Revenue Drivers'!P11 -> 9650 | M10: ='Revenue Drivers'!Q11 -> 13482 | N10: ='Revenue Drivers'!R11 -> 8757 | O10: ='Revenue Drivers'!S11 -> 8284 | P10: ='Revenue Drivers'!T11 -> 9322 | ... W10: ='Revenue Drivers'!AA11 -> 7404 | Y10: =SUM(I10:L10) -> 41241 | Z10: =SUM(J10:M10) -> 40022 | AA10: =SUM(K10:N10) -> 39973 | AB10: =SUM(L10:O10) -> 40173 | AC10: =SUM(M10:P10) -> 39845 | AD10: =SUM(N10:Q10) -> 38316 | AE10: =SUM(O10:R10) -> 37472 | AF10: =SUM(P10:S10) -> 37285 | ... AJ10: =SUM(T10:W10) -> 35715 | AL10: =SUM(AJ10/AF10)-1 -> -0.042108086
B11: Total Revenue | C11: =SUM(C6:C10) -> 274515 | D11: =SUM(D6:D10) -> 365817 | E11: =SUM(E6:E10) -> 394328 | F11: =SUM(F6:F10) -> 383285 | G11: =SUM(G6:G10) -> 391035 | I11: =SUM(I6:I10) -> 123945 | J11: =SUM(J6:J10) -> 97278 | K11: =SUM(K6:K10) -> 82959 | L11: =SUM(L6:L10) -> 90146 | M11: =SUM(M6:M10) -> 117154 | N11: =SUM(N6:N10) -> 94836 | O11: =SUM(O6:O10) -> 81797 | P11: =SUM(P6:P10) -> 89498 | ... W11: =SUM(W6:W10) -> 94036 | Y11: =SUM(Y6:Y10) -> 394328 | Z11: =SUM(Z6:Z10) -> 387537 | AA11: =SUM(AA6:AA10) -> 385095 | AB11: =SUM(AB6:AB10) -> 383933 | AC11: =SUM(AC6:AC10) -> 383285 | AD11: =SUM(AD6:AD10) -> 385706 | AE11: =SUM(AE6:AE10) -> 381623 | AF11: =SUM(AF6:AF10) -> 385603 | ... AJ11: =SUM(AJ6:AJ10) -> 408625 | AL11: =SUM(AJ11/AF11)-1 -> 0.059703892
B12: Y/Y Growth (%) | D12: =SUM(D11/C11)-1 -> 0.33259385 | E12: =SUM(E11/D11)-1 -> 0.077937876 | F12: =SUM(F11/E11)-1 -> -0.028004605 | G12: =SUM(G11/F11)-1 -> 0.020219941 | M12: =SUM(M11/I11)-1 -> -0.054790431 | N12: =SUM(N11/J11)-1 -> -0.025103312 | O12: =SUM(O11/K11)-1 -> -0.014006919 | P12: =SUM(P11/L11)-1 -> -0.0071883389 | Q12: =SUM(Q11/M11)-1 -> 0.020665107 | R12: =SUM(R11/N11)-1 -> -0.043053271 | S12: =SUM(S11/O11)-1 -> 0.048657041 | T12: =SUM(T11/P11)-1 -> 0.060694094 | ... W12: =SUM(W11/S11)-1 -> 0.096284552 | AC12: =SUM(AC11/Y11)-1 -> -0.028004605 | AD12: =SUM(AD11/Z11)-1 -> -0.0047247102 | AE12: =SUM(AE11/AA11)-1 -> -0.0090159571 | AF12: =SUM(AF11/AB11)-1 -> 0.0043497173 | AG12: =SUM(AG11/AC11)-1 -> 0.020219941 | AH12: =SUM(AH11/AD11)-1 -> 0.026066486 | AI12: =SUM(AI11/AE11)-1 -> 0.049113916 | AJ12: =SUM(AJ11/AF11)-1 -> 0.059703892 | AL12: =SUM(AJ12-AF12)*10000 -> 553.54175
B13: Q/Q Growth (%) | C13: N/A | D13: N/A | E13: N/A | F13: N/A | G13: N/A | J13: =SUM(J11/I11)-1 -> -0.21515188 | K13: =SUM(K11/J11)-1 -> -0.14719669 | L13: =SUM(L11/K11)-1 -> 0.086633156 | M13: =SUM(M11/L11)-1 -> 0.29960287 | N13: =SUM(N11/M11)-1 -> -0.19050139 | O13: =SUM(O11/N11)-1 -> -0.13748998 | P13: =SUM(P11/O11)-1 -> 0.094147707 | Q13: =SUM(Q11/P11)-1 -> 0.33606338 | ... W13: =SUM(W11/V11)-1 -> -0.013873887 | Y13: N/A | Z13: N/A | AA13: N/A | AB13: N/A | AC13: N/A | AD13: N/A | AE13: N/A | AF13: N/A | AG13: N/A | AH13: N/A | AI13: N/A | AJ13: N/A
B15: (-) Cost of Sales | C15: ='Historical Financials'!G17 -> -169559 | D15: ='Historical Financials'!H17 -> -212981 | E15: ='Historical Financials'!I17 -> -223546 | F15: ='Historical Financials'!J17 -> -214137 | G15: ='Historical Financials'!K17 -> -210352 | I15: ='Historical Financials'!M17 -> -69702 | J15: ='Historical Financials'!N17 -> -54719 | K15: ='Historical Financials'!O17 -> -47074 | L15: ='Historical Financials'!P17 -> -52051 | M15: ='Historical Financials'!Q17 -> -66822 | N15: ='Historical Financials'!R17 -> -52860 | O15: ='Historical Financials'!S17 -> -45384 | P15: ='Historical Financials'!T17 -> -49071 | ... W15: ='Historical Financials'!AA17 -> -50318 | Y15: =SUM(I15:L15) -> -223546 | Z15: =SUM(J15:M15) -> -220666 | AA15: =SUM(K15:N15) -> -218807 | AB15: =SUM(L15:O15) -> -217117 | AC15: =SUM(M15:P15) -> -214137 | AD15: =SUM(N15:Q15) -> -212035 | AE15: =SUM(O15:R15) -> -207657 | AF15: =SUM(P15:S15) -> -208372 | ... AJ15: =SUM(T15:W15) -> -217886 | AL15: =SUM(AJ15/AF15)-1 -> 0.045658726
B16: Gross Profit | C16: =+C11+C15 -> 104956 | D16: =+D11+D15 -> 152836 | E16: =+E11+E15 -> 170782 | F16: =+F11+F15 -> 169148 | G16: =+G11+G15 -> 180683 | I16: =+I11+I15 -> 54243 | J16: =+J11+J15 -> 42559 | K16: =+K11+K15 -> 35885 | L16: =+L11+L15 -> 38095 | M16: =+M11+M15 -> 50332 | N16: =+N11+N15 -> 41976 | O16: =+O11+O15 -> 36413 | P16: =+P11+P15 -> 40427 | ... W16: =+W11+W15 -> 43718 | Y16: =+Y11+Y15 -> 170782 | Z16: =+Z11+Z15 -> 166871 | AA16: =+AA11+AA15 -> 166288 | AB16: =+AB11+AB15 -> 166816 | AC16: =+AC11+AC15 -> 169148 | AD16: =+AD11+AD15 -> 173671 | AE16: =+AE11+AE15 -> 173966 | AF16: =+AF11+AF15 -> 177231 | ... AJ16: =+AJ11+AJ15 -> 190739 | AL16: =SUM(AJ16/AF16)-1 -> 0.076216915
B17: Gross Margin (%) | C17: =C16/C11 -> 0.38233248 | D17: =D16/D11 -> 0.4177936 | E17: =E16/E11 -> 0.43309631 | F17: =F16/F11 -> 0.4413113 | G17: =G16/G11 -> 0.4620635 | I17: =I16/I11 -> 0.43763766 | J17: =J16/J11 -> 0.43749872 | K17: =K16/K11 -> 0.43256307 | L17: =L16/L11 -> 0.42259224 | M17: =M16/M11 -> 0.42962255 | N17: =N16/N11 -> 0.44261673 | O17: =O16/O11 -> 0.44516303 | P17: =P16/P11 -> 0.45170842 | ... W17: =W16/W11 -> 0.46490706 | Y17: =Y16/Y11 -> 0.43309631 | Z17: =Z16/Z11 -> 0.43059372 | AA17: =AA16/AA11 -> 0.43181033 | AB17: =AB16/AB11 -> 0.43449248 | AC17: =AC16/AC11 -> 0.4413113 | AD17: =AD16/AD11 -> 0.45026782 | AE17: =AE16/AE11 -> 0.45585827 | AF17: =AF16/AF11 -> 0.45962039 | ... AJ17: =AJ16/AJ11 -> 0.4667825 | AL17: =SUM(AJ17-AF17)*10000 -> 71.621155
B19: (-) Research and Development (R&D) | C19: ='Historical Financials'!G21 -> -18752 | D19: ='Historical Financials'!H21 -> -21914 | E19: ='Historical Financials'!I21 -> -26251 | F19: ='Historical Financials'!J21 -> -29915 | G19: ='Historical Financials'!K21 -> -31370 | I19: ='Historical Financials'!M21 -> -6306 | J19: ='Historical Financials'!N21 -> -6387 | K19: ='Historical Financials'!O21 -> -6797 | L19: ='Historical Financials'!P21 -> -6761 | M19: ='Historical Financials'!Q21 -> -7709 | N19: ='Historical Financials'!R21 -> -7457 | O19: ='Historical Financials'!S21 -> -7442 | P19: ='Historical Financials'!T21 -> -7307 | ... W19: ='Historical Financials'!AA21 -> -8866 | Y19: =SUM(I19:L19) -> -26251 | Z19: =SUM(J19:M19) -> -27654 | AA19: =SUM(K19:N19) -> -28724 | AB19: =SUM(L19:O19) -> -29369 | AC19: =SUM(M19:P19) -> -29915 | AD19: =SUM(N19:Q19) -> -29902 | AE19: =SUM(O19:R19) -> -30348 | AF19: =SUM(P19:S19) -> -30912 | ... AJ19: =SUM(T19:W19) -> -33449 | AL19: =SUM(AJ19/AF19)-1 -> 0.082071687
B20: (-) Selling, General & Administrative (SG&A) | C20: ='Historical Financials'!G22 -> -19916 | D20: ='Historical Financials'!H22 -> -21973 | E20: ='Historical Financials'!I22 -> -25094 | F20: ='Historical Financials'!J22 -> -24932 | G20: ='Historical Financials'!K22 -> -26097 | I20: ='Historical Financials'!M22 -> -6449 | J20: ='Historical Financials'!N22 -> -6193 | K20: ='Historical Financials'!O22 -> -6012 | L20: ='Historical Financials'!P22 -> -6440 | M20: ='Historical Financials'!Q22 -> -6607 | N20: ='Historical Financials'!R22 -> -6201 | O20: ='Historical Financials'!S22 -> -5973 | P20: ='Historical Financials'!T22 -> -6151 | ... W20: ='Historical Financials'!AA22 -> -6650 | Y20: =SUM(I20:L20) -> -25094 | Z20: =SUM(J20:M20) -> -25252 | AA20: =SUM(K20:N20) -> -25260 | AB20: =SUM(L20:O20) -> -25221 | AC20: =SUM(M20:P20) -> -24932 | AD20: =SUM(N20:Q20) -> -25111 | AE20: =SUM(O20:R20) -> -25378 | AF20: =SUM(P20:S20) -> -25725 | ... AJ20: =SUM(T20:W20) -> -27076 | AL20: =SUM(AJ20/AF20)-1 -> 0.052517007
B21: Earning before Interest & Taxes (EBIT) | C21: =SUM(C16+SUM(C19:C20)) -> 66288 | D21: =SUM(D16+SUM(D19:D20)) -> 108949 | E21: =SUM(E16+SUM(E19:E20)) -> 119437 | F21: =SUM(F16+SUM(F19:F20)) -> 114301 | G21: =SUM(G16+SUM(G19:G20)) -> 123216 | I21: =SUM(I16+SUM(I19:I20)) -> 41488 | J21: =SUM(J16+SUM(J19:J20)) -> 29979 | K21: =SUM(K16+SUM(K19:K20)) -> 23076 | L21: =SUM(L16+SUM(L19:L20)) -> 24894 | M21: =SUM(M16+SUM(M19:M20)) -> 36016 | N21: =SUM(N16+SUM(N19:N20)) -> 28318 | O21: =SUM(O16+SUM(O19:O20)) -> 22998 | P21: =SUM(P16+SUM(P19:P20)) -> 26969 | ... W21: =SUM(W16+SUM(W19:W20)) -> 28202 | Y21: =SUM(Y16+SUM(Y19:Y20)) -> 119437 | Z21: =SUM(Z16+SUM(Z19:Z20)) -> 113965 | AA21: =SUM(AA16+SUM(AA19:AA20)) -> 112304 | AB21: =SUM(AB16+SUM(AB19:AB20)) -> 112226 | AC21: =SUM(AC16+SUM(AC19:AC20)) -> 114301 | AD21: =SUM(AD16+SUM(AD19:AD20)) -> 118658 | AE21: =SUM(AE16+SUM(AE19:AE20)) -> 118240 | AF21: =SUM(AF16+SUM(AF19:AF20)) -> 120594 | ... AJ21: =SUM(AJ16+SUM(AJ19:AJ20)) -> 130214 | AL21: =SUM(AJ21/AF21)-1 -> 0.079771796
B22: Operating Margin (%) | C22: =C21/C11 -> 0.24147314 | D22: =D21/D11 -> 0.29782378 | E22: =E21/E11 -> 0.30288744 | F22: =F21/F11 -> 0.29821412 | G22: =G21/G11 -> 0.31510223 | I22: =I21/I11 -> 0.33472911 | J22: =J21/J11 -> 0.30817862 | K22: =K21/K11 -> 0.2781615 | L22: =L21/L11 -> 0.27615202 | M22: =M21/M11 -> 0.30742442 | N22: =N21/N11 -> 0.29859969 | O22: =O21/O11 -> 0.28115946 | P22: =P21/P11 -> 0.30133634 | ... W22: =W21/W11 -> 0.29990642 | Y22: =Y21/Y11 -> 0.30288744 | Z22: =Z21/Z11 -> 0.29407515 | AA22: =AA21/AA11 -> 0.29162674 | AB22: =AB21/AB11 -> 0.29230621 | AC22: =AC21/AC11 -> 0.29821412 | AD22: =AD21/AD11 -> 0.30763846 | AE22: =AE21/AE11 -> 0.30983457 | AF22: =AF21/AF11 -> 0.31274134 | ... AJ22: =AJ21/AJ11 -> 0.31866381 | AL22: =SUM(AJ22-AF22)*10000 -> 59.224688
B24: (+) Depreciation and Amortization | C24: ='Historical Financials'!G83 -> 11056 | D24: ='Historical Financials'!H83 -> 11284 | E24: ='Historical Financials'!I83 -> 11104 | F24: ='Historical Financials'!J83 -> 11519 | G24: ='Historical Financials'!K83 -> 11445 | I24: ='Historical Financials'!M83 -> 2697 | J24: ='Historical Financials'!N83 -> 2737 | K24: ='Historical Financials'!O83 -> 2805 | L24: ='Historical Financials'!P83 -> 2865 | M24: ='Historical Financials'!Q83 -> 2916 | N24: ='Historical Financials'!R83 -> 2898 | O24: ='Historical Financials'!S83 -> 3052 | P24: ='Historical Financials'!T83 -> 2653 | ... W24: ='Historical Financials'!AA83 -> 2830 | Y24: =SUM(I24:L24) -> 11104 | Z24: =SUM(J24:M24) -> 11323 | AA24: =SUM(K24:N24) -> 11484 | AB24: =SUM(L24:O24) -> 11731 | AC24: =SUM(M24:P24) -> 11519 | AD24: =SUM(N24:Q24) -> 11451 | AE24: =SUM(O24:R24) -> 11389 | AF24: =SUM(P24:S24) -> 11187 | ... AJ24: =SUM(T24:W24) -> 11482 | AL24: =SUM(AJ24/AF24)-1 -> 0.026369894
B25: EBITDA | C25: =SUM(C21+C24) -> 77344 | D25: =SUM(D21+D24) -> 120233 | E25: =SUM(E21+E24) -> 130541 | F25: =SUM(F21+F24) -> 125820 | G25: =SUM(G21+G24) -> 134661 | I25: =SUM(I21+I24) -> 44185 | J25: =SUM(J21+J24) -> 32716 | K25: =SUM(K21+K24) -> 25881 | L25: =SUM(L21+L24) -> 27759 | M25: =SUM(M21+M24) -> 38932 | N25: =SUM(N21+N24) -> 31216 | O25: =SUM(O21+O24) -> 26050 | P25: =SUM(P21+P24) -> 29622 | ... W25: =SUM(W21+W24) -> 31032 | Y25: =SUM(Y21+Y24) -> 130541 | Z25: =SUM(Z21+Z24) -> 125288 | AA25: =SUM(AA21+AA24) -> 123788 | AB25: =SUM(AB21+AB24) -> 123957 | AC25: =SUM(AC21+AC24) -> 125820 | AD25: =SUM(AD21+AD24) -> 130109 | AE25: =SUM(AE21+AE24) -> 129629 | AF25: =SUM(AF21+AF24) -> 131781 | ... AJ25: =SUM(AJ21+AJ24) -> 141696 | AL25: =SUM(AJ25/AF25)-1 -> 0.075238464
B26: EBITDA Margin (%) | C26: =C25/C11 -> 0.28174781 | D26: =D25/D11 -> 0.3286698 | E26: =E25/E11 -> 0.33104674 | F26: =F25/F11 -> 0.32826748 | G26: =G25/G11 -> 0.34437071 | I26: =I25/I11 -> 0.35648877 | J26: =J25/J11 -> 0.33631448 | K26: =K25/K11 -> 0.31197338 | L26: =L25/L11 -> 0.3079338 | M26: =M25/M11 -> 0.33231473 | N26: =N25/N11 -> 0.3291577 | O26: =O25/O11 -> 0.31847134 | P26: =P25/P11 -> 0.33097946 | ... W26: =W25/W11 -> 0.33000128 | Y26: =Y25/Y11 -> 0.33104674 | Z26: =Z25/Z11 -> 0.323293 | AA26: =AA25/AA11 -> 0.32144795 | AB26: =AB25/AB11 -> 0.32286102 | AC26: =AC25/AC11 -> 0.32826748 | AD26: =AD25/AD11 -> 0.33732688 | AE26: =AE25/AE11 -> 0.33967816 | AF26: =AF25/AF11 -> 0.34175305 | ... AJ26: =AJ25/AJ11 -> 0.34676292 | AL26: =SUM(AJ26-AF26)*10000 -> 50.098779
B28: (+) Share-based Compensation | C28: ='Historical Financials'!G84 -> 6829 | D28: ='Historical Financials'!H84 -> 7906 | E28: ='Historical Financials'!I84 -> 9038 | F28: ='Historical Financials'!J84 -> 10833 | G28: ='Historical Financials'!K84 -> 11688 | I28: ='Historical Financials'!M84 -> 2265 | J28: ='Historical Financials'!N84 -> 2252 | K28: ='Historical Financials'!O84 -> 2243 | L28: ='Historical Financials'!P84 -> 2278 | M28: ='Historical Financials'!Q84 -> 2905 | N28: ='Historical Financials'!R84 -> 2686 | O28: ='Historical Financials'!S84 -> 2617 | P28: ='Historical Financials'!T84 -> 2625 | ... W28: ='Historical Financials'!AA84 -> 3168 | Y28: =SUM(I28:L28) -> 9038 | Z28: =SUM(J28:M28) -> 9678 | AA28: =SUM(K28:N28) -> 10112 | AB28: =SUM(L28:O28) -> 10486 | AC28: =SUM(M28:P28) -> 10833 | AD28: =SUM(N28:Q28) -> 10925 | AE28: =SUM(O28:R28) -> 11206 | AF28: =SUM(P28:S28) -> 11455 | ... AJ28: =SUM(T28:W28) -> 12538 | AL28: =SUM(AJ28/AF28)-1 -> 0.094543867
B29: Adj. EBITDA | C29: =+SUM(C25+SUM(C28:C28)) -> 84173 | D29: =+SUM(D25+SUM(D28:D28)) -> 128139 | E29: =+SUM(E25+SUM(E28:E28)) -> 139579 | F29: =+SUM(F25+SUM(F28:F28)) -> 136653 | G29: =+SUM(G25+SUM(G28:G28)) -> 146349 | I29: =+SUM(I25+SUM(I28:I28)) -> 46450 | J29: =+SUM(J25+SUM(J28:J28)) -> 34968 | K29: =+SUM(K25+SUM(K28:K28)) -> 28124 | L29: =+SUM(L25+SUM(L28:L28)) -> 30037 | M29: =+SUM(M25+SUM(M28:M28)) -> 41837 | N29: =+SUM(N25+SUM(N28:N28)) -> 33902 | O29: =+SUM(O25+SUM(O28:O28)) -> 28667 | P29: =+SUM(P25+SUM(P28:P28)) -> 32247 | ... W29: =+SUM(W25+SUM(W28:W28)) -> 34200 | Y29: =+SUM(Y25+SUM(Y28:Y28)) -> 139579 | Z29: =+SUM(Z25+SUM(Z28:Z28)) -> 134966 | AA29: =+SUM(AA25+SUM(AA28:AA28)) -> 133900 | AB29: =+SUM(AB25+SUM(AB28:AB28)) -> 134443 | AC29: =+SUM(AC25+SUM(AC28:AC28)) -> 136653 | AD29: =+SUM(AD25+SUM(AD28:AD28)) -> 141034 | AE29: =+SUM(AE25+SUM(AE28:AE28)) -> 140835 | AF29: =+SUM(AF25+SUM(AF28:AF28)) -> 143236 | ... AJ29: =+SUM(AJ25+SUM(AJ28:AJ28)) -> 154234 | AL29: =SUM(AJ29/AF29)-1 -> 0.076782373
B30: Adj. EBITDA Margin (%) | C30: =C29/C11 -> 0.30662441 | D30: =D29/D11 -> 0.3502817 | E30: =E29/E11 -> 0.35396675 | F30: =F29/F11 -> 0.35653104 | G30: =G29/G11 -> 0.37426062 | I30: =I29/I11 -> 0.374763 | J30: =J29/J11 -> 0.35946463 | K30: =K29/K11 -> 0.33901084 | L30: =L29/L11 -> 0.33320391 | M30: =M29/M11 -> 0.35711115 | N30: =N29/N11 -> 0.35748028 | O30: =O29/O11 -> 0.35046518 | P30: =P29/P11 -> 0.36030973 | ... W30: =W29/W11 -> 0.3636905 | Y30: =Y29/Y11 -> 0.35396675 | Z30: =Z29/Z11 -> 0.3482661 | AA30: =AA29/AA11 -> 0.34770641 | AB30: =AB29/AB11 -> 0.35017308 | AC30: =AC29/AC11 -> 0.35653104 | AD30: =AD29/AD11 -> 0.36565156 | AE30: =AE29/AE11 -> 0.36904222 | AF30: =AF29/AF11 -> 0.37145977 | ... AJ30: =AJ29/AJ11 -> 0.37744631 | AL30: =SUM(AJ30-AF30)*10000 -> 59.865482
B32: (-) Capital Expenditures | C32: ='Historical Financials'!G98 -> -7309 | D32: ='Historical Financials'!H98 -> -11085 | E32: ='Historical Financials'!I98 -> -10708 | F32: ='Historical Financials'!J98 -> -10959 | G32: ='Historical Financials'!K98 -> -9447 | I32: ='Historical Financials'!M98 -> -2803 | J32: ='Historical Financials'!N98 -> -2514 | K32: ='Historical Financials'!O98 -> -2102 | L32: ='Historical Financials'!P98 -> -3289 | M32: ='Historical Financials'!Q98 -> -3787 | N32: ='Historical Financials'!R98 -> -2916 | O32: ='Historical Financials'!S98 -> -2093 | P32: ='Historical Financials'!T98 -> -2163 | ... W32: ='Historical Financials'!AA98 -> -3462 | Y32: =SUM(I32:L32) -> -10708 | Z32: =SUM(J32:M32) -> -11692 | AA32: =SUM(K32:N32) -> -12094 | AB32: =SUM(L32:O32) -> -12085 | AC32: =SUM(M32:P32) -> -10959 | AD32: =SUM(N32:Q32) -> -9564 | AE32: =SUM(O32:R32) -> -8644 | AF32: =SUM(P32:S32) -> -8702 | ... AJ32: =SUM(T32:W32) -> -12381 | AL32: =SUM(AJ32/AF32)-1 -> 0.42277637
B33: (-) Cash Taxes | C33: =-'Historical Financials'!G128 -> -9501 | D33: =-'Historical Financials'!H128 -> -25385 | E33: =-'Historical Financials'!I128 -> -19573 | F33: =-'Historical Financials'!J128 -> -18679 | G33: =-'Historical Financials'!K128 -> -26102 | I33: =-'Historical Financials'!M128 -> -5235 | J33: =-'Historical Financials'!N128 -> -4066 | K33: =-'Historical Financials'!O128 -> -2950 | L33: =-'Historical Financials'!P128 -> -7322 | M33: =-'Historical Financials'!Q128 -> -828 | N33: =-'Historical Financials'!R128 -> -4066 | O33: =-'Historical Financials'!S128 -> -2126 | P33: =-'Historical Financials'!T128 -> -11659 | ... W33: =-'Historical Financials'!AA128 -> -5649 | Y33: =SUM(I33:L33) -> -19573 | Z33: =SUM(J33:M33) -> -15166 | AA33: =SUM(K33:N33) -> -15166 | AB33: =SUM(L33:O33) -> -14342 | AC33: =SUM(M33:P33) -> -18679 | AD33: =SUM(N33:Q33) -> -25106 | AE33: =SUM(O33:R33) -> -28316 | AF33: =SUM(P33:S33) -> -30889 | ... AJ33: =SUM(T33:W33) -> -44204 | AL33: =SUM(AJ33/AF33)-1 -> 0.4310596
B34: (-) Cash Interest | C34: =-'Historical Financials'!G129 -> -3002 | D34: =-'Historical Financials'!H129 -> -2687 | E34: =-'Historical Financials'!I129 -> -2865 | F34: =-'Historical Financials'!J129 -> -3803 | G34: =-'Historical Financials'!K129 -> 0 | I34: =-'Historical Financials'!M129 -> -531 | J34: =-'Historical Financials'!N129 -> -875 | K34: =-'Historical Financials'!O129 -> -504 | L34: =-'Historical Financials'!P129 -> -955 | M34: =-'Historical Financials'!Q129 -> -703 | N34: =-'Historical Financials'!R129 -> -1170 | O34: =-'Historical Financials'!S129 -> -717 | P34: =-'Historical Financials'!T129 -> -1213 | ... W34: =-'Historical Financials'!AA129 -> 0 | Y34: =SUM(I34:L34) -> -2865 | Z34: =SUM(J34:M34) -> -3037 | AA34: =SUM(K34:N34) -> -3332 | AB34: =SUM(L34:O34) -> -3545 | AC34: =SUM(M34:P34) -> -3803 | AD34: =SUM(N34:Q34) -> -3100 | AE34: =SUM(O34:R34) -> -1930 | AF34: =SUM(P34:S34) -> -1213 | ... AJ34: =SUM(T34:W34) -> 0 | AL34: =SUM(AJ34/AF34)-1 -> -1
