Workbook

Sheet Historical Financials
B2: GE Vernova Inc (NYSE: GEV)
B3: Historical Financials
B4: ($ In Millions, except EPS)
A6: X | B6: Income Statement | D6: FYE | G6: Quarterly | M6: Quarterly | U6: LTM | AA6: Variance
B7: Fiscal Period | C7: 2022 | D7: 2023 | E7: 2024 | G7: 1Q23 | H7: 2Q23 | I7: 3Q23 | J7: 4Q23 | K7: 1Q24 | L7: 2Q24 | M7: 3Q24 | N7: 4Q24 | O7: 1Q25 | P7: 2Q25 | Q7: 3Q25 | S7: =K7 -> 1Q24 | T7: =L7 -> 2Q24 | U7: =M7 -> 3Q24 | V7: =N7 -> 4Q24 | W7: =O7 -> 1Q25 | X7: =P7 -> 2Q25 | Y7: =Q7 -> 3Q25
B8: Fiscal Period End Date | C8: XXX | D8: XXX | E8: XXX | G8: XXX | H8: XXX | I8: XXX | J8: =D8 -> XXX | K8: XXX | L8: XXX | M8: XXX | N8: =E8 -> XXX | O8: XXX | P8: XXX | Q8: XXX | S8: =K8 -> XXX | T8: =L8 -> XXX | U8: =M8 -> XXX | V8: =N8 -> XXX | W8: =O8 -> XXX | X8: =P8 -> XXX | Y8: =Q8 -> XXX
B10: Consolidated Revenue | C10: 29654 | D10: 33239 | E10: 34935 | G10: 6822 | H10: 8119 | I10: 8252 | J10: =SUM(D10-SUM(G10:I10)) -> 10046 | K10: 7259 | L10: 8204 | M10: 8913 | N10: =SUM(E10-SUM(K10:M10)) -> 10559 | O10: 8032 | P10: 9111 | Q10: 9969 | S10: =SUM(G10:J10) -> 33239 | T10: =SUM(H10:K10) -> 33676 | U10: =SUM(I10:L10) -> 33761 | V10: =SUM(J10:M10) -> 34422 | W10: =SUM(K10:N10) -> 34935 | X10: =SUM(L10:O10) -> 35708 | Y10: =SUM(M10:P10) -> 36615 | AA10: =SUM(Y10/U10)-1 -> 0.084535411
B11: Total Revenue | C11: =+SUM(C10:C10) -> 29654 | D11: =+SUM(D10:D10) -> 33239 | E11: =+SUM(E10:E10) -> 34935 | G11: =+SUM(G10:G10) -> 6822 | H11: =+SUM(H10:H10) -> 8119 | I11: =+SUM(I10:I10) -> 8252 | J11: =+SUM(J10:J10) -> 10046 | K11: =+SUM(K10:K10) -> 7259 | L11: =+SUM(L10:L10) -> 8204 | M11: =+SUM(M10:M10) -> 8913 | N11: =+SUM(N10:N10) -> 10559 | ... Q11: =+SUM(Q10:Q10) -> 9969 | S11: =+SUM(S10:S10) -> 33239 | T11: =+SUM(T10:T10) -> 33676 | U11: =+SUM(U10:U10) -> 33761 | V11: =+SUM(V10:V10) -> 34422 | W11: =+SUM(W10:W10) -> 34935 | X11: =+SUM(X10:X10) -> 35708 | Y11: =+SUM(Y10:Y10) -> 36615 | AA11: =SUM(Y11/U11)-1 -> 0.084535411
B13: Cost of Equipment | C13: -16972 | D13: -18705 | E13: -17989 | G13: -3575 | H13: -4621 | I13: -5005 | J13: =SUM(D13-SUM(G13:I13)) -> -5504 | K13: -3693 | L13: -3853 | M13: -5076 | N13: =SUM(E13-SUM(K13:M13)) -> -5367 | O13: -3915 | P13: -4265 | Q13: -5165 | S13: =SUM(G13:J13) -> -18705 | T13: =SUM(H13:K13) -> -18823 | U13: =SUM(I13:L13) -> -18055 | V13: =SUM(J13:M13) -> -18126 | W13: =SUM(K13:N13) -> -17989 | X13: =SUM(L13:O13) -> -18211 | Y13: =SUM(M13:P13) -> -18623 | AA13: =SUM(Y13/U13)-1 -> 0.03145943
B14: Cost of Services | C14: -9224 | D14: -9716 | E14: -10861 | G14: -2328 | H14: -2351 | I14: -2196 | J14: =SUM(D14-SUM(G14:I14)) -> -2841 | K14: -2416 | L14: -2649 | M14: -2728 | N14: =SUM(E14-SUM(K14:M14)) -> -3068 | O14: -2647 | P14: -3000 | Q14: -2906 | S14: =SUM(G14:J14) -> -9716 | T14: =SUM(H14:K14) -> -9804 | U14: =SUM(I14:L14) -> -10102 | V14: =SUM(J14:M14) -> -10634 | W14: =SUM(K14:N14) -> -10861 | X14: =SUM(L14:O14) -> -11092 | Y14: =SUM(M14:P14) -> -11443 | AA14: =SUM(Y14/U14)-1 -> 0.13274599
B15: Gross Profit | C15: =+SUM(C11+SUM(C13:C14)) -> 3458 | D15: =+SUM(D11+SUM(D13:D14)) -> 4818 | E15: =+SUM(E11+SUM(E13:E14)) -> 6085 | G15: =+SUM(G11+SUM(G13:G14)) -> 919 | H15: =+SUM(H11+SUM(H13:H14)) -> 1147 | I15: =+SUM(I11+SUM(I13:I14)) -> 1051 | J15: =+SUM(J11+SUM(J13:J14)) -> 1701 | K15: =+SUM(K11+SUM(K13:K14)) -> 1150 | L15: =+SUM(L11+SUM(L13:L14)) -> 1702 | M15: =+SUM(M11+SUM(M13:M14)) -> 1109 | N15: =+SUM(N11+SUM(N13:N14)) -> 2124 | ... Q15: =+SUM(Q11+SUM(Q13:Q14)) -> 1898 | S15: =+SUM(S11+SUM(S13:S14)) -> 4818 | T15: =+SUM(T11+SUM(T13:T14)) -> 5049 | U15: =+SUM(U11+SUM(U13:U14)) -> 5604 | V15: =+SUM(V11+SUM(V13:V14)) -> 5662 | W15: =+SUM(W11+SUM(W13:W14)) -> 6085 | X15: =+SUM(X11+SUM(X13:X14)) -> 6405 | Y15: =+SUM(Y11+SUM(Y13:Y14)) -> 6549 | AA15: =SUM(Y15/U15)-1 -> 0.16862955
B16: Gross Margin (%) | C16: =C15/C11 -> 0.11661159 | D16: =D15/D11 -> 0.14495021 | E16: =E15/E11 -> 0.17418062 | G16: =G15/G11 -> 0.13471123 | H16: =H15/H11 -> 0.14127356 | I16: =I15/I11 -> 0.12736306 | J16: =J15/J11 -> 0.16932112 | K16: =K15/K11 -> 0.15842403 | L16: =L15/L11 -> 0.20745978 | M16: =M15/M11 -> 0.124425 | N16: =N15/N11 -> 0.20115541 | ... Q16: =Q15/Q11 -> 0.19039021 | S16: =S15/S11 -> 0.14495021 | T16: =T15/T11 -> 0.14992873 | U16: =U15/U11 -> 0.16599034 | V16: =V15/V11 -> 0.16448783 | W16: =W15/W11 -> 0.17418062 | X16: =X15/X11 -> 0.17937157 | Y16: =Y15/Y11 -> 0.17886112 | AA16: =SUM(Y16-U16)*1000 -> 12.870779
B18: Selling, General, and Administrative | C18: -5360 | D18: -4845 | E18: -4632 | G18: -1186 | H18: -1272 | I18: -1135 | J18: =SUM(D18-SUM(G18:I18)) -> -1252 | K18: -1202 | L18: -938 | M18: -1226 | N18: =SUM(E18-SUM(K18:M18)) -> -1266 | O18: -1188 | P18: -1185 | Q18: -1221 | S18: =SUM(G18:J18) -> -4845 | T18: =SUM(H18:K18) -> -4861 | U18: =SUM(I18:L18) -> -4527 | V18: =SUM(J18:M18) -> -4618 | W18: =SUM(K18:N18) -> -4632 | X18: =SUM(L18:O18) -> -4618 | Y18: =SUM(M18:P18) -> -4865 | AA18: =SUM(Y18/U18)-1 -> 0.074663132
B19: Research and Development | C19: -979 | D19: -896 | E19: -982 | G19: -202 | H19: -216 | I19: -223 | J19: =SUM(D19-SUM(G19:I19)) -> -255 | K19: -237 | L19: -237 | M19: -242 | N19: =SUM(E19-SUM(K19:M19)) -> -266 | O19: -239 | P19: -283 | Q19: -310 | S19: =SUM(G19:J19) -> -896 | T19: =SUM(H19:K19) -> -931 | U19: =SUM(I19:L19) -> -952 | V19: =SUM(J19:M19) -> -971 | W19: =SUM(K19:N19) -> -982 | X19: =SUM(L19:O19) -> -984 | Y19: =SUM(M19:P19) -> -1030 | AA19: =SUM(Y19/U19)-1 -> 0.081932773
B20: Operating Profit | C20: =+SUM(C15+SUM(C18:C19)) -> -2881 | D20: =+SUM(D15+SUM(D18:D19)) -> -923 | E20: =+SUM(E15+SUM(E18:E19)) -> 471 | G20: =+SUM(G15+SUM(G18:G19)) -> -469 | H20: =+SUM(H15+SUM(H18:H19)) -> -341 | I20: =+SUM(I15+SUM(I18:I19)) -> -307 | J20: =+SUM(J15+SUM(J18:J19)) -> 194 | K20: =+SUM(K15+SUM(K18:K19)) -> -289 | L20: =+SUM(L15+SUM(L18:L19)) -> 527 | M20: =+SUM(M15+SUM(M18:M19)) -> -359 | N20: =+SUM(N15+SUM(N18:N19)) -> 592 | ... Q20: =+SUM(Q15+SUM(Q18:Q19)) -> 367 | S20: =+SUM(S15+SUM(S18:S19)) -> -923 | T20: =+SUM(T15+SUM(T18:T19)) -> -743 | U20: =+SUM(U15+SUM(U18:U19)) -> 125 | V20: =+SUM(V15+SUM(V18:V19)) -> 73 | W20: =+SUM(W15+SUM(W18:W19)) -> 471 | X20: =+SUM(X15+SUM(X18:X19)) -> 803 | Y20: =+SUM(Y15+SUM(Y18:Y19)) -> 654 | AA20: =SUM(Y20/U20)-1 -> 4.232
B21: Operating Margin (%) | C21: =C20/C11 -> -0.097153841 | D21: =D20/D11 -> -0.027768585 | E21: =E20/E11 -> 0.013482181 | G21: =G20/G11 -> -0.068748168 | H21: =H20/H11 -> -0.042000246 | I21: =I20/I11 -> -0.037203102 | J21: =J20/J11 -> 0.019311169 | K21: =K20/K11 -> -0.039812646 | L21: =L20/L11 -> 0.064236958 | M21: =M20/M11 -> -0.040278245 | N21: =N20/N11 -> 0.056065915 | ... Q21: =Q20/Q11 -> 0.036814124 | S21: =S20/S11 -> -0.027768585 | T21: =T20/T11 -> -0.02206319 | U21: =U20/U11 -> 0.003702497 | V21: =V20/V11 -> 0.0021207367 | W21: =W20/W11 -> 0.013482181 | X21: =X20/X11 -> 0.022487958 | Y21: =Y20/Y11 -> 0.017861532 | AA21: =SUM(Y21-U21)*1000 -> 14.159035
B23: Interest Income (Expense) | C23: -151 | D23: -98 | E23: 120 | G23: -21 | H23: -21 | I23: -21 | J23: =SUM(D23-SUM(G23:I23)) -> -35 | K23: -14 | L23: 60 | M23: 36 | N23: =SUM(E23-SUM(K23:M23)) -> 38 | O23: 56 | P23: 42 | Q23: 44 | S23: =SUM(G23:J23) -> -98 | T23: =SUM(H23:K23) -> -91 | U23: =SUM(I23:L23) -> -10 | V23: =SUM(J23:M23) -> 47 | W23: =SUM(K23:N23) -> 120 | X23: =SUM(L23:O23) -> 190 | Y23: =SUM(M23:P23) -> 172 | AA23: =SUM(Y23/U23)-1 -> -18.2
B24: Non-Operating Income | C24: 188 | D24: 567 | E24: 536 | G24: 139 | H24: 143 | I24: 134 | J24: =SUM(D24-SUM(G24:I24)) -> 151 | K24: 134 | L24: 134 | M24: 130 | N24: =SUM(E24-SUM(K24:M24)) -> 138 | O24: 115 | P24: 110 | Q24: 115 | S24: =SUM(G24:J24) -> 567 | T24: =SUM(H24:K24) -> 562 | U24: =SUM(I24:L24) -> 553 | V24: =SUM(J24:M24) -> 549 | W24: =SUM(K24:N24) -> 536 | X24: =SUM(L24:O24) -> 517 | Y24: =SUM(M24:P24) -> 493 | AA24: =SUM(Y24/U24)-1 -> -0.1084991
B25: Other Income | C25: 370 | D25: 324 | E25: 1372 | G25: -64 | H25: 192 | I25: 178 | J25: =SUM(D25-SUM(G25:I25)) -> 18 | K25: 73 | L25: 881 | M25: 71 | N25: =SUM(E25-SUM(K25:M25)) -> 347 | O25: 118 | P25: 115 | Q25: 221 | S25: =SUM(G25:J25) -> 324 | T25: =SUM(H25:K25) -> 461 | U25: =SUM(I25:L25) -> 1150 | V25: =SUM(J25:M25) -> 1043 | W25: =SUM(K25:N25) -> 1372 | X25: =SUM(L25:O25) -> 1417 | Y25: =SUM(M25:P25) -> 651 | AA25: =SUM(Y25/U25)-1 -> -0.43391304
B26: Earnings before Taxes | C26: =SUM(C23:C25)+C20 -> -2474 | D26: =SUM(D23:D25)+D20 -> -130 | E26: =SUM(E23:E25)+E20 -> 2499 | G26: =SUM(G23:G25)+G20 -> -415 | H26: =SUM(H23:H25)+H20 -> -27 | I26: =SUM(I23:I25)+I20 -> -16 | J26: =SUM(J23:J25)+J20 -> 328 | K26: =SUM(K23:K25)+K20 -> -96 | L26: =SUM(L23:L25)+L20 -> 1602 | M26: =SUM(M23:M25)+M20 -> -122 | N26: =SUM(N23:N25)+N20 -> 1115 | ... Q26: =SUM(Q23:Q25)+Q20 -> 747 | S26: =SUM(S23:S25)+S20 -> -130 | T26: =SUM(T23:T25)+T20 -> 189 | U26: =SUM(U23:U25)+U20 -> 1818 | V26: =SUM(V23:V25)+V20 -> 1712 | W26: =SUM(W23:W25)+W20 -> 2499 | X26: =SUM(X23:X25)+X20 -> 2927 | Y26: =SUM(Y23:Y25)+Y20 -> 1970 | AA26: =SUM(Y26/U26)-1 -> 0.083608361
B27: EBT Margin (%) | C27: =C26/C11 -> -0.08342888 | D27: =D26/D11 -> -0.0039110683 | E27: =E26/E11 -> 0.071532847 | G27: =G26/G11 -> -0.0608326 | H27: =H26/H11 -> -0.0033255327 | I27: =I26/I11 -> -0.0019389239 | J27: =J26/J11 -> 0.032649811 | K27: =K26/K11 -> -0.013224962 | L27: =L26/L11 -> 0.1952706 | M27: =M26/M11 -> -0.013687872 | N27: =N26/N11 -> 0.10559712 | ... Q27: =Q26/Q11 -> 0.07493229 | S27: =S26/S11 -> -0.0039110683 | T27: =T26/T11 -> 0.0056123055 | U27: =U26/U11 -> 0.053849116 | V27: =V26/V11 -> 0.049735634 | W27: =W26/W11 -> 0.071532847 | X27: =X26/X11 -> 0.081970427 | Y27: =Y26/Y11 -> 0.053803086 | AA27: =SUM(Y27-U27)*1000 -> -0.046029677
B29: Income tax expense | C29: -248 | D29: -344 | E29: -939 | G29: 69 | H29: -122 | I29: -169 | J29: =SUM(D29-SUM(G29:I29)) -> -122 | K29: -10 | L29: -322 | M29: 23 | N29: =SUM(E29-SUM(K29:M29)) -> -630 | O29: -68 | P29: -153 | Q29: -293 | S29: =SUM(G29:J29) -> -344 | T29: =SUM(H29:K29) -> -423 | U29: =SUM(I29:L29) -> -623 | V29: =SUM(J29:M29) -> -431 | W29: =SUM(K29:N29) -> -939 | X29: =SUM(L29:O29) -> -997 | Y29: =SUM(M29:P29) -> -828 | AA29: =SUM(Y29/U29)-1 -> 0.32905297
B30: Net loss | C30: =SUM(C26+SUM(C29:C29)) -> -2722 | D30: =SUM(D26+SUM(D29:D29)) -> -474 | E30: =SUM(E26+SUM(E29:E29)) -> 1560 | G30: =SUM(G26+SUM(G29:G29)) -> -346 | H30: =SUM(H26+SUM(H29:H29)) -> -149 | I30: =SUM(I26+SUM(I29:I29)) -> -185 | J30: =SUM(J26+SUM(J29:J29)) -> 206 | K30: =SUM(K26+SUM(K29:K29)) -> -106 | L30: =SUM(L26+SUM(L29:L29)) -> 1280 | M30: =SUM(M26+SUM(M29:M29)) -> -99 | N30: =SUM(N26+SUM(N29:N29)) -> 485 | ... Q30: =SUM(Q26+SUM(Q29:Q29)) -> 454 | S30: =SUM(S26+SUM(S29:S29)) -> -474 | T30: =SUM(T26+SUM(T29:T29)) -> -234 | U30: =SUM(U26+SUM(U29:U29)) -> 1195 | V30: =SUM(V26+SUM(V29:V29)) -> 1281 | W30: =SUM(W26+SUM(W29:W29)) -> 1560 | X30: =SUM(X26+SUM(X29:X29)) -> 1930 | Y30: =SUM(Y26+SUM(Y29:Y29)) -> 1142 | AA30: =SUM(Y30/U30)-1 -> -0.044351464
B31: Net Margin (%) | C31: =C30/C11 -> -0.091792001 | D31: =D30/D11 -> -0.014260357 | E31: =E30/E11 -> 0.044654358 | G31: =G30/G11 -> -0.050718264 | H31: =H30/H11 -> -0.018352014 | I31: =I30/I11 -> -0.022418808 | J31: =J30/J11 -> 0.020505674 | K31: =K30/K11 -> -0.014602562 | L31: =L30/L11 -> 0.15602145 | M31: =M30/M11 -> -0.011107371 | N31: =N30/N11 -> 0.04593238 | ... Q31: =Q30/Q11 -> 0.045541178 | S31: =S30/S11 -> -0.014260357 | T31: =T30/T11 -> -0.0069485687 | U31: =U30/U11 -> 0.035395871 | V31: =V30/V11 -> 0.037214572 | W31: =W30/W11 -> 0.044654358 | X31: =X30/X11 -> 0.054049513 | Y31: =Y30/Y11 -> 0.031189403 | AA31: =SUM(Y31-U31)*1000 -> -4.2064677
B33: Basic shares | J33: =D33 -> 0 | N33: =E33 -> 0 | S33: =J33 -> 0 | T33: =K33 -> 0 | U33: =L33 -> 0 | V33: =M33 -> 0 | W33: =N33 -> 0 | X33: =O33 -> 0 | Y33: =P33 -> 0 | AA33: =SUM(Y33/U33)-1 -> #DIV/0!
B34: Basic EPS | C34: =C30/C33 -> #DIV/0! | D34: =D30/D33 -> #DIV/0! | E34: =E30/E33 -> #DIV/0! | G34: =G30/G33 -> #DIV/0! | H34: =H30/H33 -> #DIV/0! | I34: =I30/I33 -> #DIV/0! | J34: =J30/J33 -> #DIV/0! | K34: =K30/K33 -> #DIV/0! | L34: =L30/L33 -> #DIV/0! | M34: =M30/M33 -> #DIV/0! | N34: =N30/N33 -> #DIV/0! | ... Q34: =Q30/Q33 -> #DIV/0! | S34: =S30/S33 -> #DIV/0! | T34: =T30/T33 -> #DIV/0! | U34: =U30/U33 -> #DIV/0! | V34: =V30/V33 -> #DIV/0! | W34: =W30/W33 -> #DIV/0! | X34: =X30/X33 -> #DIV/0! | Y34: =Y30/Y33 -> #DIV/0! | AA34: =SUM(Y34/U34)-1 -> #DIV/0!
B36: Fully Diluted Shares | J36: =D36 -> 0 | N36: =E36 -> 0 | S36: =J36 -> 0 | T36: =K36 -> 0 | U36: =L36 -> 0 | V36: =M36 -> 0 | W36: =N36 -> 0 | X36: =O36 -> 0 | Y36: =P36 -> 0 | AA36: =SUM(Y36/U36)-1 -> #DIV/0!
B37: Diluted EPS | C37: =C30/C36 -> #DIV/0! | D37: =D30/D36 -> #DIV/0! | E37: =E30/E36 -> #DIV/0! | G37: =G30/G36 -> #DIV/0! | H37: =H30/H36 -> #DIV/0! | I37: =I30/I36 -> #DIV/0! | J37: =J30/J36 -> #DIV/0! | K37: =K30/K36 -> #DIV/0! | L37: =L30/L36 -> #DIV/0! | M37: =M30/M36 -> #DIV/0! | N37: =N30/N36 -> #DIV/0! | ... Q37: =Q30/Q36 -> #DIV/0! | S37: =S30/S36 -> #DIV/0! | T37: =T30/T36 -> #DIV/0! | U37: =U30/U36 -> #DIV/0! | V37: =V30/V36 -> #DIV/0! | W37: =W30/W36 -> #DIV/0! | X37: =X30/X36 -> #DIV/0! | Y37: =Y30/Y36 -> #DIV/0! | AA37: =SUM(Y37/U37)-1 -> #DIV/0!
A39: X | B39: Balance Sheet | C39: FYE | M39: Quarterly | U39: LTM | AA39: Variance
B40: =B7 -> Fiscal Period | C40: =C7 -> 2022 | D40: =D7 -> 2023 | E40: =E7 -> 2024 | G40: =G7 -> 1Q23 | H40: =H7 -> 2Q23 | I40: =I7 -> 3Q23 | J40: =J7 -> 4Q23 | K40: =K7 -> 1Q24 | L40: =L7 -> 2Q24 | M40: =M7 -> 3Q24 | N40: =N7 -> 4Q24 | ... Q40: =Q7 -> 3Q25 | S40: =S7 -> 1Q24 | T40: =T7 -> 2Q24 | U40: =U7 -> 3Q24 | V40: =V7 -> 4Q24 | W40: =W7 -> 1Q25 | X40: =X7 -> 2Q25 | Y40: =Y7 -> 3Q25
B41: =B8 -> Fiscal Period End Date | C41: =C8 -> XXX | D41: =D8 -> XXX | E41: =E8 -> XXX | G41: =G8 -> XXX | H41: =H8 -> XXX | I41: =I8 -> XXX | J41: =J8 -> XXX | K41: =K8 -> XXX | L41: =L8 -> XXX | M41: =M8 -> XXX | N41: =N8 -> XXX | ... Q41: =Q8 -> XXX | S41: =S8 -> XXX | T41: =T8 -> XXX | U41: =U8 -> XXX | V41: =V8 -> XXX | W41: =W8 -> XXX | X41: =X8 -> XXX | Y41: =Y8 -> XXX
B43: Current Assets
B44: Cash & CEs | D44: 1551 | E44: 8205 | J44: =D44 -> 1551 | K44: 3255 | L44: 5779 | M44: 7395 | N44: =E44 -> 8205 | O44: 8107 | P44: 7892 | Q44: 7945 | S44: =J44 -> 1551 | T44: =K44 -> 3255 | U44: =L44 -> 5779 | V44: =M44 -> 7395 | W44: =N44 -> 8205 | X44: =O44 -> 8107 | Y44: =P44 -> 7892 | AA44: =SUM(Y44/U44)-1 -> 0.36563419
B45: A/R | D45: 7489 | E45: 8177 | J45: =D45 -> 7489 | K45: 7096 | L45: 6431 | M45: 7226 | N45: =E45 -> 8177 | O45: 7136 | P45: 6948 | Q45: 7374 | S45: =J45 -> 7489 | T45: =K45 -> 7096 | U45: =L45 -> 6431 | V45: =M45 -> 7226 | W45: =N45 -> 8177 | X45: =O45 -> 7136 | Y45: =P45 -> 6948 | AA45: =SUM(Y45/U45)-1 -> 0.080391852
B46: Inventories | D46: 8253 | E46: 8587 | J46: =D46 -> 8253 | K46: 8859 | L46: 9346 | M46: 9377 | N46: =E46 -> 8587 | O46: 9156 | P46: 9825 | Q46: 10032 | S46: =J46 -> 8253 | T46: =K46 -> 8859 | U46: =L46 -> 9346 | V46: =M46 -> 9377 | W46: =N46 -> 8587 | X46: =O46 -> 9156 | Y46: =P46 -> 9825 | AA46: =SUM(Y46/U46)-1 -> 0.051251872
B47: Current Contract Assets | D47: 8339 | E47: 8621 | J47: =D47 -> 8339 | K47: 8579 | L47: 8702 | M47: 8592 | N47: =E47 -> 8621 | O47: 9040 | P47: 9489 | Q47: 9485 | S47: =J47 -> 8339 | T47: =K47 -> 8579 | U47: =L47 -> 8702 | V47: =M47 -> 8592 | W47: =N47 -> 8621 | X47: =O47 -> 9040 | Y47: =P47 -> 9489 | AA47: =SUM(Y47/U47)-1 -> 0.09043898
B48: Other Current Assets | D48: 352 | E48: 564 | J48: =D48 -> 352 | K48: 462 | L48: 463 | M48: 550 | N48: =E48 -> 564 | O48: 497 | P48: 555 | Q48: 934 | S48: =J48 -> 352 | T48: =K48 -> 462 | U48: =L48 -> 463 | V48: =M48 -> 550 | W48: =N48 -> 564 | X48: =O48 -> 497 | Y48: =P48 -> 555 | AA48: =SUM(Y48/U48)-1 -> 0.1987041
B49: Total Current Assets | C49: =SUM(C44:C48) -> 0 | D49: =SUM(D44:D48) -> 25984 | E49: =SUM(E44:E48) -> 34154 | G49: =SUM(G44:G48) -> 0 | H49: =SUM(H44:H48) -> 0 | I49: =SUM(I44:I48) -> 0 | J49: =SUM(J44:J48) -> 25984 | K49: =SUM(K44:K48) -> 28251 | L49: =SUM(L44:L48) -> 30721 | M49: =SUM(M44:M48) -> 33140 | N49: =SUM(N44:N48) -> 34154 | ... Q49: =SUM(Q44:Q48) -> 35770 | S49: =SUM(S44:S48) -> 25984 | T49: =SUM(T44:T48) -> 28251 | U49: =SUM(U44:U48) -> 30721 | V49: =SUM(V44:V48) -> 33140 | W49: =SUM(W44:W48) -> 34154 | X49: =SUM(X44:X48) -> 33936 | Y49: =SUM(Y44:Y48) -> 34709 | AA49: =SUM(Y49/U49)-1 -> 0.12981348
B51: Non-Current Assets
B52: Assets Held For Sale | D52: 1444 | E52: 0 | J52: =D52 -> 1444 | K52: 993 | L52: 0 | M52: 0 | N52: =E52 -> 0 | O52: 0 | P52: 0 | Q52: 508 | S52: =J52 -> 1444 | T52: =K52 -> 993 | U52: =L52 -> 0 | V52: =M52 -> 0 | W52: =N52 -> 0 | X52: =O52 -> 0 | Y52: =P52 -> 0 | AA52: =SUM(Y52/U52)-1 -> #DIV/0!
...

Sheet Revenue Drivers
B2: ='Historical Financials'!B2 -> GE Vernova Inc (NYSE: GEV) | C2: FYE | M2: Quarterly | U2: LTM
B3: Segment Anaysis | C3: ='Historical Financials'!C7 -> 2022 | D3: ='Historical Financials'!D7 -> 2023 | E3: ='Historical Financials'!E7 -> 2024 | G3: ='Historical Financials'!G7 -> 1Q23 | H3: ='Historical Financials'!H7 -> 2Q23 | I3: ='Historical Financials'!I7 -> 3Q23 | J3: ='Historical Financials'!J7 -> 4Q23 | K3: ='Historical Financials'!K7 -> 1Q24 | L3: ='Historical Financials'!L7 -> 2Q24 | M3: ='Historical Financials'!M7 -> 3Q24 | N3: ='Historical Financials'!N7 -> 4Q24 | ... Q3: ='Historical Financials'!Q7 -> 3Q25 | S3: =J3 -> 4Q23 | T3: =K3 -> 1Q24 | U3: =L3 -> 2Q24 | V3: =M3 -> 3Q24 | W3: =N3 -> 4Q24 | X3: =O3 -> 1Q25 | Y3: =P3 -> 2Q25
B4: ($ In Millions) | C4: ='Historical Financials'!C8 -> XXX | D4: ='Historical Financials'!D8 -> XXX | E4: ='Historical Financials'!E8 -> XXX | G4: ='Historical Financials'!G8 -> XXX | H4: ='Historical Financials'!H8 -> XXX | I4: ='Historical Financials'!I8 -> XXX | J4: ='Historical Financials'!J8 -> XXX | K4: ='Historical Financials'!K8 -> XXX | L4: ='Historical Financials'!L8 -> XXX | M4: ='Historical Financials'!M8 -> XXX | N4: ='Historical Financials'!N8 -> XXX | ... Q4: ='Historical Financials'!Q8 -> XXX | S4: =J4 -> XXX | T4: =K4 -> XXX | U4: =L4 -> XXX | V4: =M4 -> XXX | W4: =N4 -> XXX | X4: =O4 -> XXX | Y4: =P4 -> XXX
A6: X | B6: Revenue by reportable segment
A8: X | B8: Revenue Segment Anaysis
B9: Equipment | C9: 15819 | D9: 18258 | E9: 18952 | G9: 3489 | H9: 4388 | I9: 4869 | J9: =SUM(D9-SUM(G9:I9)) -> 5512 | K9: 3617 | L9: 4194 | M9: 5290 | N9: =SUM(E9-SUM(K9:M9)) -> 5851 | O9: 4197 | P9: 4894 | Q9: 5880 | S9: =SUM(G9:J9) -> 18258 | T9: =SUM(H9:K9) -> 18386 | U9: =SUM(I9:L9) -> 18192 | V9: =SUM(J9:M9) -> 18613 | W9: =SUM(K9:N9) -> 18952 | X9: =SUM(L9:O9) -> 19532 | Y9: =SUM(M9:P9) -> 20232
B10: Sales | C10: 13835 | D10: 14981 | E10: 15983 | G10: 3333 | H10: 3731 | I10: 3383 | J10: =SUM(D10-SUM(G10:I10)) -> 4534 | K10: 3642 | L10: 4010 | M10: 3623 | N10: =SUM(E10-SUM(K10:M10)) -> 4708 | O10: 3835 | P10: 4217 | Q10: 4089 | S10: =SUM(G10:J10) -> 14981 | T10: =SUM(H10:K10) -> 15290 | U10: =SUM(I10:L10) -> 15569 | V10: =SUM(J10:M10) -> 15809 | W10: =SUM(K10:N10) -> 15983 | X10: =SUM(L10:O10) -> 16176 | Y10: =SUM(M10:P10) -> 16383
B11: Total Net Revenue | C11: =SUM(C9:C10) -> 29654 | D11: =SUM(D9:D10) -> 33239 | E11: =SUM(E9:E10) -> 34935 | G11: =SUM(G9:G10) -> 6822 | H11: =SUM(H9:H10) -> 8119 | I11: =SUM(I9:I10) -> 8252 | J11: =SUM(J9:J10) -> 10046 | K11: =SUM(K9:K10) -> 7259 | L11: =SUM(L9:L10) -> 8204 | M11: =SUM(M9:M10) -> 8913 | N11: =SUM(N9:N10) -> 10559 | ... Q11: =SUM(Q9:Q10) -> 9969 | S11: =SUM(S9:S10) -> 33239 | T11: =SUM(T9:T10) -> 33676 | U11: =SUM(U9:U10) -> 33761 | V11: =SUM(V9:V10) -> 34422 | W11: =SUM(W9:W10) -> 34935 | X11: =SUM(X9:X10) -> 35708 | Y11: =SUM(Y9:Y10) -> 36615
B12: Balance Check | C12: =+C11-'Historical Financials'!C11 -> 0 | D12: =+D11-'Historical Financials'!D11 -> 0 | E12: =+E11-'Historical Financials'!E11 -> 0 | G12: =+G11-'Historical Financials'!G11 -> 0 | H12: =+H11-'Historical Financials'!H11 -> 0 | I12: =+I11-'Historical Financials'!I11 -> 0 | J12: =+J11-'Historical Financials'!J11 -> 0 | K12: =+K11-'Historical Financials'!K11 -> 0 | L12: =+L11-'Historical Financials'!L11 -> 0 | M12: =+M11-'Historical Financials'!M11 -> 0 | N12: =+N11-'Historical Financials'!N11 -> 0 | ... Q12: =+Q11-'Historical Financials'!Q11 -> 0 | S12: =+S11-'Historical Financials'!S11 -> 0 | T12: =+T11-'Historical Financials'!T11 -> 0 | U12: =+U11-'Historical Financials'!U11 -> 0 | V12: =+V11-'Historical Financials'!V11 -> 0 | W12: =+W11-'Historical Financials'!W11 -> 0 | X12: =+X11-'Historical Financials'!X11 -> 0 | Y12: =+Y11-'Historical Financials'!Y11 -> 0
B14: =B9&"(%)" -> Equipment(%) | C14: =SUM(C9/C$11) -> 0.53345249 | D14: =SUM(D9/D$11) -> 0.5492945 | E14: =SUM(E9/E$11) -> 0.5424932 | G14: =SUM(G9/G$11) -> 0.5114336 | H14: =SUM(H9/H$11) -> 0.54046065 | I14: =SUM(I9/I$11) -> 0.59003878 | J14: =SUM(J9/J$11) -> 0.54867609 | K14: =SUM(K9/K$11) -> 0.498278 | L14: =SUM(L9/L$11) -> 0.51121404 | M14: =SUM(M9/M$11) -> 0.59351509 | N14: =SUM(N9/N$11) -> 0.55412444 | ... Q14: =SUM(Q9/Q$11) -> 0.58982847 | S14: =K14 -> 0.498278 | T14: =L14 -> 0.51121404 | U14: =M14 -> 0.59351509 | V14: =N14 -> 0.55412444 | W14: =O14 -> 0.52253486 | X14: =P14 -> 0.53715289 | Y14: =#REF! -> #REF!
B15: =B10&"(%)" -> Sales(%) | C15: =SUM(C10/C$11) -> 0.46654751 | D15: =SUM(D10/D$11) -> 0.4507055 | E15: =SUM(E10/E$11) -> 0.4575068 | G15: =SUM(G10/G$11) -> 0.4885664 | H15: =SUM(H10/H$11) -> 0.45953935 | I15: =SUM(I10/I$11) -> 0.40996122 | J15: =SUM(J10/J$11) -> 0.45132391 | K15: =SUM(K10/K$11) -> 0.501722 | L15: =SUM(L10/L$11) -> 0.48878596 | M15: =SUM(M10/M$11) -> 0.40648491 | N15: =SUM(N10/N$11) -> 0.44587556 | ... Q15: =SUM(Q10/Q$11) -> 0.41017153 | S15: =K15 -> 0.501722 | T15: =L15 -> 0.48878596 | U15: =M15 -> 0.40648491 | V15: =N15 -> 0.44587556 | W15: =O15 -> 0.47746514 | X15: =P15 -> 0.46284711 | Y15: =#REF! -> #REF!
A17: X | B17: Revenue: End Channels
B18: Power | C18: =C33 -> 16124 | D18: =D33 -> 17436 | E18: =E33 -> 18128 | G18: =G33 -> 3821 | H18: =H33 -> 4131 | I18: =I33 -> 3893 | J18: =J33 -> 5591 | K18: =K33 -> 4035 | L18: =L33 -> 4455 | M18: =M33 -> 4207 | N18: =N33 -> 5431 | ... Q18: =Q33 -> 4839 | S18: =SUM(G18:J18) -> 17436 | T18: =SUM(H18:K18) -> 17650 | U18: =SUM(I18:L18) -> 17974 | V18: =SUM(J18:M18) -> 18288 | W18: =SUM(K18:N18) -> 18128 | X18: =SUM(L18:O18) -> 18516 | Y18: =SUM(M18:P18) -> 18819
B19: Wind | C19: =C45 -> 8905 | D19: =D45 -> 9826 | E19: =E45 -> 9700 | G19: =G45 -> 1751 | H19: =H45 -> 2601 | I19: =I45 -> 2887 | J19: =J45 -> 2587 | K19: =K45 -> 1639 | L19: =L45 -> 2062 | M19: =M45 -> 2891 | N19: =N45 -> 3108 | ... Q19: =Q45 -> 2648 | S19: =SUM(G19:J19) -> 9826 | T19: =SUM(H19:K19) -> 9714 | U19: =SUM(I19:L19) -> 9175 | V19: =SUM(J19:M19) -> 9179 | W19: =SUM(K19:N19) -> 9700 | X19: =SUM(L19:O19) -> 9911 | Y19: =SUM(M19:P19) -> 10094
B20: Electrification | C20: =C56 -> 5076 | D20: =D56 -> 6338 | E20: =E56 -> 7550 | G20: =G56 -> 1331 | H20: =H56 -> 1505 | I20: =I56 -> 1577 | J20: =J56 -> 1925 | K20: =K56 -> 1651 | L20: =L56 -> 1791 | M20: =M56 -> 1928 | N20: =N56 -> 2180 | ... Q20: =Q56 -> 2602 | S20: =SUM(G20:J20) -> 6338 | T20: =SUM(H20:K20) -> 6658 | U20: =SUM(I20:L20) -> 6944 | V20: =SUM(J20:M20) -> 7295 | W20: =SUM(K20:N20) -> 7550 | X20: =SUM(L20:O20) -> 7779 | Y20: =SUM(M20:P20) -> 8189
B21: Total Net Revenue | C21: =SUM(C18:C20) -> 30105 | D21: =SUM(D18:D20) -> 33600 | E21: =SUM(E18:E20) -> 35378 | G21: =SUM(G18:G20) -> 6903 | H21: =SUM(H18:H20) -> 8237 | I21: =SUM(I18:I20) -> 8357 | J21: =SUM(J18:J20) -> 10103 | K21: =SUM(K18:K20) -> 7325 | L21: =SUM(L18:L20) -> 8308 | M21: =SUM(M18:M20) -> 9026 | N21: =SUM(N18:N20) -> 10719 | ... Q21: =SUM(Q18:Q20) -> 10089 | S21: =SUM(S18:S20) -> 33600 | T21: =SUM(T18:T20) -> 34022 | U21: =SUM(U18:U20) -> 34093 | V21: =SUM(V18:V20) -> 34762 | W21: =SUM(W18:W20) -> 35378 | X21: =SUM(X18:X20) -> 36206 | Y21: =SUM(Y18:Y20) -> 37102
B22: Balance Check | C22: =C21-C11 -> 451 | D22: =D21-D11 -> 361 | E22: =E21-E11 -> 443 | G22: =G21-G11 -> 81 | H22: =H21-H11 -> 118 | I22: =I21-I11 -> 105 | J22: =J21-J11 -> 57 | K22: =K21-K11 -> 66 | L22: =L21-L11 -> 104 | M22: =M21-M11 -> 113 | N22: =N21-N11 -> 160 | ... Q22: =Q21-Q11 -> 120 | S22: =S21-S11 -> 361 | T22: =T21-T11 -> 346 | U22: =U21-U11 -> 332 | V22: =V21-V11 -> 340 | W22: =W21-W11 -> 443 | X22: =X21-X11 -> 498 | Y22: =Y21-Y11 -> 487
B24: =B18&"(%)" -> Power (%) | C24: =SUM(C18/C$11) -> 0.54373778 | D24: =SUM(D18/D$11) -> 0.52456452 | E24: =SUM(E18/E$11) -> 0.51890654 | G24: =SUM(G18/G$11) -> 0.56009968 | H24: =SUM(H18/H$11) -> 0.5088065 | I24: =SUM(I18/I$11) -> 0.47176442 | J24: =SUM(J18/J$11) -> 0.55653992 | K24: =SUM(K18/K$11) -> 0.55586169 | L24: =SUM(L18/L$11) -> 0.54302779 | M24: =SUM(M18/M$11) -> 0.47200718 | N24: =SUM(N18/N$11) -> 0.51434795 | ... Q24: =SUM(Q18/Q$11) -> 0.48540475 | S24: =K24 -> 0.55586169 | T24: =L24 -> 0.54302779 | U24: =M24 -> 0.47200718 | V24: =N24 -> 0.51434795 | W24: =O24 -> 0.55067231 | X24: =P24 -> 0.52222588 | Y24: =#REF! -> #REF!
B25: =B19&"(%)" -> Wind (%) | C25: =SUM(C19/C$11) -> 0.30029676 | D25: =SUM(D19/D$11) -> 0.29561659 | E25: =SUM(E19/E$11) -> 0.27765851 | G25: =SUM(G19/G$11) -> 0.2566696 | H25: =SUM(H19/H$11) -> 0.32035965 | I25: =SUM(I19/I$11) -> 0.34985458 | J25: =SUM(J19/J$11) -> 0.25751543 | K25: =SUM(K19/K$11) -> 0.22578868 | L25: =SUM(L19/L$11) -> 0.25134081 | M25: =SUM(M19/M$11) -> 0.32435768 | N25: =SUM(N19/N$11) -> 0.29434606 | ... Q25: =SUM(Q19/Q$11) -> 0.26562343 | S25: =K25 -> 0.22578868 | T25: =L25 -> 0.25134081 | U25: =M25 -> 0.32435768 | V25: =N25 -> 0.29434606 | W25: =O25 -> 0.23032869 | X25: =P25 -> 0.24640544 | Y25: =#REF! -> #REF!
B26: =B20&"(%)" -> Electrification (%) | C26: =SUM(C20/C$11) -> 0.17117421 | D26: =SUM(D20/D$11) -> 0.19067962 | E26: =SUM(E20/E$11) -> 0.21611564 | G26: =SUM(G20/G$11) -> 0.19510408 | H26: =SUM(H20/H$11) -> 0.18536766 | I26: =SUM(I20/I$11) -> 0.19110519 | J26: =SUM(J20/J$11) -> 0.19161855 | K26: =SUM(K20/K$11) -> 0.2274418 | L26: =SUM(L20/L$11) -> 0.21830814 | M26: =SUM(M20/M$11) -> 0.21631325 | N26: =SUM(N20/N$11) -> 0.20645894 | ... Q26: =SUM(Q20/Q$11) -> 0.26100913 | S26: =K26 -> 0.2274418 | T26: =L26 -> 0.21830814 | U26: =M26 -> 0.21631325 | V26: =N26 -> 0.20645894 | W26: =O26 -> 0.23406375 | X26: =P26 -> 0.24157612 | Y26: =#REF! -> #REF!
A28: X | B28: Revenue: Power
B29: Gas Power | C29: 12079 | D29: 13220 | E29: 14465 | G29: 2882 | H29: 3051 | I29: 2944 | J29: =SUM(D29-SUM(G29:I29)) -> 4343 | K29: 3041 | L29: 3459 | M29: 3466 | N29: =SUM(E29-SUM(K29:M29)) -> 4499 | O29: 3579 | P29: 3884 | Q29: 3923 | S29: =SUM(G29:J29) -> 13220 | T29: =SUM(H29:K29) -> 13379 | U29: =SUM(I29:L29) -> 13787 | V29: =SUM(J29:M29) -> 14309 | W29: =SUM(K29:N29) -> 14465 | X29: =SUM(L29:O29) -> 15003 | Y29: =SUM(M29:P29) -> 15428
B30: Nuclear Power | C30: 699 | D30: 827 | E30: 819 | G30: 221 | H30: 212 | I30: 158 | J30: =SUM(D30-SUM(G30:I30)) -> 236 | K30: 229 | L30: 222 | M30: 167 | N30: =SUM(E30-SUM(K30:M30)) -> 201 | O30: 200 | P30: 189 | Q30: 251 | S30: =SUM(G30:J30) -> 827 | T30: =SUM(H30:K30) -> 835 | U30: =SUM(I30:L30) -> 845 | V30: =SUM(J30:M30) -> 854 | W30: =SUM(K30:N30) -> 819 | X30: =SUM(L30:O30) -> 790 | Y30: =SUM(M30:P30) -> 757
B31: Hydro Power | C31: 703 | D31: 887 | E31: 781 | G31: 178 | H31: 220 | I31: 220 | J31: =SUM(D31-SUM(G31:I31)) -> 269 | K31: 181 | L31: 182 | M31: 181 | N31: =SUM(E31-SUM(K31:M31)) -> 237 | O31: 157 | P31: 201 | Q31: 223 | S31: =SUM(G31:J31) -> 887 | T31: =SUM(H31:K31) -> 890 | U31: =SUM(I31:L31) -> 852 | V31: =SUM(J31:M31) -> 813 | W31: =SUM(K31:N31) -> 781 | X31: =SUM(L31:O31) -> 757 | Y31: =SUM(M31:P31) -> 776
B32: Steam Power | C32: 2643 | D32: 2502 | E32: 2063 | G32: 540 | H32: 648 | I32: 571 | J32: =SUM(D32-SUM(G32:I32)) -> 743 | K32: 584 | L32: 592 | M32: 393 | N32: =SUM(E32-SUM(K32:M32)) -> 494 | O32: 487 | P32: 484 | Q32: 442 | S32: =SUM(G32:J32) -> 2502 | T32: =SUM(H32:K32) -> 2546 | U32: =SUM(I32:L32) -> 2490 | V32: =SUM(J32:M32) -> 2312 | W32: =SUM(K32:N32) -> 2063 | X32: =SUM(L32:O32) -> 1966 | Y32: =SUM(M32:P32) -> 1858
B33: Total Net Revenue | C33: =SUM(C29:C32) -> 16124 | D33: =SUM(D29:D32) -> 17436 | E33: =SUM(E29:E32) -> 18128 | G33: =SUM(G29:G32) -> 3821 | H33: =SUM(H29:H32) -> 4131 | I33: =SUM(I29:I32) -> 3893 | J33: =SUM(J29:J32) -> 5591 | K33: =SUM(K29:K32) -> 4035 | L33: =SUM(L29:L32) -> 4455 | M33: =SUM(M29:M32) -> 4207 | N33: =SUM(N29:N32) -> 5431 | ... Q33: =SUM(Q29:Q32) -> 4839 | S33: =SUM(S29:S32) -> 17436 | T33: =SUM(T29:T32) -> 17650 | U33: =SUM(U29:U32) -> 17974 | V33: =SUM(V29:V32) -> 18288 | W33: =SUM(W29:W32) -> 18128 | X33: =SUM(X29:X32) -> 18516 | Y33: =SUM(Y29:Y32) -> 18819
B34: Balance Check | C34: =C33-C18 -> 0 | D34: =D33-D18 -> 0 | E34: =E33-E18 -> 0 | G34: =G33-G18 -> 0 | H34: =H33-H18 -> 0 | I34: =I33-I18 -> 0 | J34: =J33-J18 -> 0 | K34: =K33-K18 -> 0 | L34: =L33-L18 -> 0 | M34: =M33-M18 -> 0 | N34: =N33-N18 -> 0 | ... Q34: =Q33-Q18 -> 0 | S34: =S33-S18 -> 0 | T34: =T33-T18 -> 0 | U34: =U33-U18 -> 0 | V34: =V33-V18 -> 0 | W34: =W33-W18 -> 0 | X34: =X33-X18 -> 0 | Y34: =Y33-Y18 -> 0
B36: =B29&"(%)" -> Gas Power (%) | C36: =SUM(C29/C$11) -> 0.40733122 | D36: =SUM(D29/D$11) -> 0.39772556 | E36: =SUM(E29/E$11) -> 0.41405467 | G36: =SUM(G29/G$11) -> 0.42245676 | H36: =SUM(H29/H$11) -> 0.3757852 | I36: =SUM(I29/I$11) -> 0.356762 | J36: =SUM(J29/J$11) -> 0.43231137 | K36: =SUM(K29/K$11) -> 0.41892823 | L36: =SUM(L29/L$11) -> 0.4216236 | M36: =SUM(M29/M$11) -> 0.38887019 | N36: =SUM(N29/N$11) -> 0.42608202 | ... Q36: =SUM(Q29/Q$11) -> 0.39351991 | S36: =K36 -> 0.41892823 | T36: =L36 -> 0.4216236 | U36: =M36 -> 0.38887019 | V36: =N36 -> 0.42608202 | W36: =O36 -> 0.44559263 | X36: =P36 -> 0.42629788 | Y36: =#REF! -> #REF!
B37: =B30&"(%)" -> Nuclear Power (%) | C37: =SUM(C30/C$11) -> 0.023571862 | D37: =SUM(D30/D$11) -> 0.024880412 | E37: =SUM(E30/E$11) -> 0.023443538 | G37: =SUM(G30/G$11) -> 0.032395192 | H37: =SUM(H30/H$11) -> 0.02611159 | I37: =SUM(I30/I$11) -> 0.019146873 | J37: =SUM(J30/J$11) -> 0.023491937 | K37: =SUM(K30/K$11) -> 0.031547045 | L37: =SUM(L30/L$11) -> 0.027059971 | M37: =SUM(M30/M$11) -> 0.018736677 | N37: =SUM(N30/N$11) -> 0.019035894 | ... Q37: =SUM(Q30/Q$11) -> 0.025178052 | S37: =K37 -> 0.031547045 | T37: =L37 -> 0.027059971 | U37: =M37 -> 0.018736677 | V37: =N37 -> 0.019035894 | W37: =O37 -> 0.024900398 | X37: =P37 -> 0.020744155 | Y37: =#REF! -> #REF!
B38: =B31&"(%)" -> Hydro Power (%) | C38: =SUM(C31/C$11) -> 0.023706751 | D38: =SUM(D31/D$11) -> 0.02668552 | E38: =SUM(E31/E$11) -> 0.022355804 | G38: =SUM(G31/G$11) -> 0.026092055 | H38: =SUM(H31/H$11) -> 0.027096933 | I38: =SUM(I31/I$11) -> 0.026660204 | J38: =SUM(J31/J$11) -> 0.026776827 | K38: =SUM(K31/K$11) -> 0.024934564 | L38: =SUM(L31/L$11) -> 0.0221843 | M38: =SUM(M31/M$11) -> 0.020307416 | N38: =SUM(N31/N$11) -> 0.022445307 | ... Q38: =SUM(Q31/Q$11) -> 0.022369345 | S38: =K38 -> 0.024934564 | T38: =L38 -> 0.0221843 | U38: =M38 -> 0.020307416 | V38: =N38 -> 0.022445307 | W38: =O38 -> 0.019546813 | X38: =P38 -> 0.022061245 | Y38: =#REF! -> #REF!
B39: =B32&"(%)" -> Steam Power (%) | C39: =SUM(C32/C$11) -> 0.089127942 | D39: =SUM(D32/D$11) -> 0.075273023 | E39: =SUM(E32/E$11) -> 0.059052526 | G39: =SUM(G32/G$11) -> 0.079155673 | H39: =SUM(H32/H$11) -> 0.079812785 | I39: =SUM(I32/I$11) -> 0.069195347 | J39: =SUM(J32/J$11) -> 0.073959785 | K39: =SUM(K32/K$11) -> 0.080451853 | L39: =SUM(L32/L$11) -> 0.072159922 | M39: =SUM(M32/M$11) -> 0.044092898 | N39: =SUM(N32/N$11) -> 0.046784733 | ... Q39: =SUM(Q32/Q$11) -> 0.044337446 | S39: =K39 -> 0.080451853 | T39: =L39 -> 0.072159922 | U39: =M39 -> 0.044092898 | V39: =N39 -> 0.046784733 | W39: =O39 -> 0.06063247 | X39: =P39 -> 0.053122599 | Y39: =#REF! -> #REF!
A41: X | B41: Revenue: Wind
B42: Onshore Wind | C42: 7941 | D42: 7761 | E42: 7781 | G42: 1422 | H42: 2174 | I42: 2281 | J42: =SUM(D42-SUM(G42:I42)) -> 1884 | K42: 1059 | L42: 1560 | M42: 2355 | N42: =SUM(E42-SUM(K42:M42)) -> 2807 | O42: 1583 | P42: 1962 | Q42: 2402 | S42: =SUM(G42:J42) -> 7761 | T42: =SUM(H42:K42) -> 7398 | U42: =SUM(I42:L42) -> 6784 | V42: =SUM(J42:M42) -> 6858 | W42: =SUM(K42:N42) -> 7781 | X42: =SUM(L42:O42) -> 8305 | Y42: =SUM(M42:P42) -> 8707
B43: Offshore Wind | C43: 531 | D43: 1455 | E43: 1377 | G43: 249 | H43: 285 | I43: 455 | J43: =SUM(D43-SUM(G43:I43)) -> 466 | K43: 441 | L43: 353 | M43: 388 | N43: =SUM(E43-SUM(K43:M43)) -> 195 | O43: 204 | P43: 225 | Q43: 195 | S43: =SUM(G43:J43) -> 1455 | T43: =SUM(H43:K43) -> 1647 | U43: =SUM(I43:L43) -> 1715 | V43: =SUM(J43:M43) -> 1648 | W43: =SUM(K43:N43) -> 1377 | X43: =SUM(L43:O43) -> 1140 | Y43: =SUM(M43:P43) -> 1012
B44: LM Wind | C44: 433 | D44: 610 | E44: 542 | G44: 80 | H44: 142 | I44: 151 | J44: 237 | K44: 139 | L44: 149 | M44: 148 | N44: =SUM(E44-SUM(K44:M44)) -> 106 | O44: 63 | P44: 58 | Q44: 51 | S44: =SUM(G44:J44) -> 610 | T44: =SUM(H44:K44) -> 669 | U44: =SUM(I44:L44) -> 676 | V44: =SUM(J44:M44) -> 673 | W44: =SUM(K44:N44) -> 542 | X44: =SUM(L44:O44) -> 466 | Y44: =SUM(M44:P44) -> 375
B45: Total Net Revenue | C45: =SUM(C42:C44) -> 8905 | D45: =SUM(D42:D44) -> 9826 | E45: =SUM(E42:E44) -> 9700 | G45: =SUM(G42:G44) -> 1751 | H45: =SUM(H42:H44) -> 2601 | I45: =SUM(I42:I44) -> 2887 | J45: =SUM(J42:J44) -> 2587 | K45: =SUM(K42:K44) -> 1639 | L45: =SUM(L42:L44) -> 2062 | M45: =SUM(M42:M44) -> 2891 | N45: =SUM(N42:N44) -> 3108 | ... Q45: =SUM(Q42:Q44) -> 2648 | S45: =SUM(S42:S44) -> 9826 | T45: =SUM(T42:T44) -> 9714 | U45: =SUM(U42:U44) -> 9175 | V45: =SUM(V42:V44) -> 9179 | W45: =SUM(W42:W44) -> 9700 | X45: =SUM(X42:X44) -> 9911 | Y45: =SUM(Y42:Y44) -> 10094
B46: Balance Check | C46: =C45-C19 -> 0 | D46: =D45-D19 -> 0 | E46: =E45-E19 -> 0 | G46: =G45-G19 -> 0 | H46: =H45-H19 -> 0 | I46: =I45-I19 -> 0 | J46: =J45-J19 -> 0 | K46: =K45-K19 -> 0 | L46: =L45-L19 -> 0 | M46: =M45-M19 -> 0 | N46: =N45-N19 -> 0 | ... Q46: =Q45-Q19 -> 0 | S46: =S45-S19 -> 0 | T46: =T45-T19 -> 0 | U46: =U45-U19 -> 0 | V46: =V45-V19 -> 0 | W46: =W45-W19 -> 0 | X46: =X45-X19 -> 0 | Y46: =Y45-Y19 -> 0
B48: =B42&"(%)" -> Onshore Wind(%) | C48: =SUM(C42/C$11) -> 0.26778849 | D48: =SUM(D42/D$11) -> 0.23349078 | E48: =SUM(E42/E$11) -> 0.22272792 | G48: =SUM(G42/G$11) -> 0.20844327 | H48: =SUM(H42/H$11) -> 0.26776697 | I48: =SUM(I42/I$11) -> 0.27641784 | J48: =SUM(J42/J$11) -> 0.18753733 | K48: =SUM(K42/K$11) -> 0.14588786 | L48: =SUM(L42/L$11) -> 0.19015115 | M48: =SUM(M42/M$11) -> 0.2642208 | N48: =SUM(N42/N$11) -> 0.26583957 | ... Q48: =SUM(Q42/Q$11) -> 0.24094694 | S48: =K48 -> 0.14588786 | T48: =L48 -> 0.19015115 | U48: =M48 -> 0.2642208 | V48: =N48 -> 0.26583957 | W48: =O48 -> 0.19708665 | X48: =P48 -> 0.21534409 | Y48: =#REF! -> #REF!
B49: =B43&"(%)" -> Offshore Wind(%) | C49: =SUM(C43/C$11) -> 0.017906522 | D49: =SUM(D43/D$11) -> 0.04377388 | E49: =SUM(E43/E$11) -> 0.039416058 | G49: =SUM(G43/G$11) -> 0.03649956 | H49: =SUM(H43/H$11) -> 0.035102845 | I49: =SUM(I43/I$11) -> 0.055138148 | J49: =SUM(J43/J$11) -> 0.046386622 | K49: =SUM(K43/K$11) -> 0.06075217 | L49: =SUM(L43/L$11) -> 0.043027791 | M49: =SUM(M43/M$11) -> 0.04353192 | N49: =SUM(N43/N$11) -> 0.018467658 | ... Q49: =SUM(Q43/Q$11) -> 0.019560638 | S49: =K49 -> 0.06075217 | T49: =L49 -> 0.043027791 | U49: =M49 -> 0.04353192 | V49: =N49 -> 0.018467658 | W49: =O49 -> 0.025398406 | X49: =P49 -> 0.024695423 | Y49: =#REF! -> #REF!
B50: =B44&"(%)" -> LM Wind(%) | C50: =SUM(C44/C$11) -> 0.01460174 | D50: =SUM(D44/D$11) -> 0.018351936 | E50: =SUM(E44/E$11) -> 0.015514527 | G50: =SUM(G44/G$11) -> 0.011726766 | H50: =SUM(H44/H$11) -> 0.017489839 | I50: =SUM(I44/I$11) -> 0.018298594 | J50: =SUM(J44/J$11) -> 0.023591479 | K50: =SUM(K44/K$11) -> 0.019148643 | L50: =SUM(L44/L$11) -> 0.018161872 | M50: =SUM(M44/M$11) -> 0.016604959 | N50: =SUM(N44/N$11) -> 0.010038829 | ... Q50: =SUM(Q44/Q$11) -> 0.0051158592 | S50: =K50 -> 0.019148643 | T50: =L50 -> 0.018161872 | U50: =M50 -> 0.016604959 | V50: =N50 -> 0.010038829 | W50: =O50 -> 0.0078436255 | X50: =P50 -> 0.0063659313 | Y50: =#REF! -> #REF!
...

Sheet FCF
B2: ='Historical Financials'!B2 -> GE Vernova Inc (NYSE: GEV) | D2: FYE | H2: Quarterly | R2: Quarterly | Z2: LTM | AA2: LTM | AG2: Variance
B3: FCF Analysis | C3: ='Historical Financials'!C7 -> 2022 | D3: ='Historical Financials'!D7 -> 2023 | E3: ='Historical Financials'!E7 -> 2024 | F3: ='Historical Financials'!#REF! -> #REF! | H3: ='Historical Financials'!G7 -> 1Q23 | I3: ='Historical Financials'!H7 -> 2Q23 | J3: ='Historical Financials'!I7 -> 3Q23 | K3: ='Historical Financials'!J7 -> 4Q23 | L3: ='Historical Financials'!K7 -> 1Q24 | M3: ='Historical Financials'!L7 -> 2Q24 | N3: ='Historical Financials'!M7 -> 3Q24 | O3: ='Historical Financials'!N7 -> 4Q24 | ... Q3: ='Historical Financials'!P7 -> 2Q25 | R3: ='Historical Financials'!#REF! -> #REF! | S3: ='Historical Financials'!#REF! -> #REF! | T3: ='Historical Financials'!#REF! -> #REF! | V3: =K3 -> 4Q23 | W3: =L3 -> 1Q24 | X3: =M3 -> 2Q24 | Y3: =N3 -> 3Q24 | Z3: =O3 -> 4Q24 | AA3: =P3 -> 1Q25 | AB3: =Q3 -> 2Q25 | AC3: =R3 -> #REF! | ... AE3: =T3 -> #REF!
B4: ($ In Millions) | C4: ='Historical Financials'!C8 -> XXX | D4: ='Historical Financials'!D8 -> XXX | E4: ='Historical Financials'!E8 -> XXX | F4: ='Historical Financials'!#REF! -> #REF! | H4: ='Historical Financials'!G8 -> XXX | I4: ='Historical Financials'!H8 -> XXX | J4: ='Historical Financials'!I8 -> XXX | K4: ='Historical Financials'!J8 -> XXX | L4: ='Historical Financials'!K8 -> XXX | M4: ='Historical Financials'!L8 -> XXX | N4: ='Historical Financials'!M8 -> XXX | O4: ='Historical Financials'!N8 -> XXX | ... Q4: ='Historical Financials'!P8 -> XXX | R4: ='Historical Financials'!#REF! -> #REF! | S4: ='Historical Financials'!#REF! -> #REF! | T4: ='Historical Financials'!#REF! -> #REF! | V4: =K4 -> XXX | W4: =L4 -> XXX | X4: =M4 -> XXX | Y4: =N4 -> XXX | Z4: =O4 -> XXX | AA4: =P4 -> XXX | AB4: =Q4 -> XXX | AC4: =R4 -> #REF! | ... AE4: =T4 -> #REF!
B6: XXX | V6: =SUM(H6:K6) -> 0 | W6: =SUM(I6:L6) -> 0 | X6: =SUM(J6:M6) -> 0 | Y6: =SUM(K6:N6) -> 0 | Z6: =SUM(L6:O6) -> 0 | AA6: =SUM(M6:P6) -> 0 | AB6: =SUM(N6:Q6) -> 0 | AC6: =SUM(O6:R6) -> 0 | ... AE6: =SUM(Q6:T6) -> 0 | AG6: =SUM(AE6/AA6)-1 -> #DIV/0!
B7: XXX | V7: =SUM(H7:K7) -> 0 | W7: =SUM(I7:L7) -> 0 | X7: =SUM(J7:M7) -> 0 | Y7: =SUM(K7:N7) -> 0 | Z7: =SUM(L7:O7) -> 0 | AA7: =SUM(M7:P7) -> 0 | AB7: =SUM(N7:Q7) -> 0 | AC7: =SUM(O7:R7) -> 0 | ... AE7: =SUM(Q7:T7) -> 0 | AG7: =SUM(AE7/AA7)-1 -> #DIV/0!
B8: XXX | V8: =SUM(H8:K8) -> 0 | W8: =SUM(I8:L8) -> 0 | X8: =SUM(J8:M8) -> 0 | Y8: =SUM(K8:N8) -> 0 | Z8: =SUM(L8:O8) -> 0 | AA8: =SUM(M8:P8) -> 0 | AB8: =SUM(N8:Q8) -> 0 | AC8: =SUM(O8:R8) -> 0 | ... AE8: =SUM(Q8:T8) -> 0 | AG8: =SUM(AE8/AA8)-1 -> #DIV/0!
B9: XXX | V9: =SUM(H9:K9) -> 0 | W9: =SUM(I9:L9) -> 0 | X9: =SUM(J9:M9) -> 0 | Y9: =SUM(K9:N9) -> 0 | Z9: =SUM(L9:O9) -> 0 | AA9: =SUM(M9:P9) -> 0 | AB9: =SUM(N9:Q9) -> 0 | AC9: =SUM(O9:R9) -> 0 | ... AE9: =SUM(Q9:T9) -> 0 | AG9: =SUM(AE9/AA9)-1 -> #DIV/0!
B10: XXX | V10: =SUM(H10:K10) -> 0 | W10: =SUM(I10:L10) -> 0 | X10: =SUM(J10:M10) -> 0 | Y10: =SUM(K10:N10) -> 0 | Z10: =SUM(L10:O10) -> 0 | AA10: =SUM(M10:P10) -> 0 | AB10: =SUM(N10:Q10) -> 0 | AC10: =SUM(O10:R10) -> 0 | ... AE10: =SUM(Q10:T10) -> 0 | AG10: =SUM(AE10/AA10)-1 -> #DIV/0!
B11: XXX | V11: =SUM(H11:K11) -> 0 | W11: =SUM(I11:L11) -> 0 | X11: =SUM(J11:M11) -> 0 | Y11: =SUM(K11:N11) -> 0 | Z11: =SUM(L11:O11) -> 0 | AA11: =SUM(M11:P11) -> 0 | AB11: =SUM(N11:Q11) -> 0 | AC11: =SUM(O11:R11) -> 0 | ... AE11: =SUM(Q11:T11) -> 0 | AG11: =SUM(AE11/AA11)-1 -> #DIV/0!
B12: Total Revenue | C12: =SUM(C6:C11) -> 0 | D12: =SUM(D6:D11) -> 0 | E12: =SUM(E6:E11) -> 0 | F12: =SUM(F6:F11) -> 0 | H12: =SUM(H6:H11) -> 0 | I12: =SUM(I6:I11) -> 0 | J12: =SUM(J6:J11) -> 0 | K12: =SUM(K6:K11) -> 0 | L12: =SUM(L6:L11) -> 0 | M12: =SUM(M6:M11) -> 0 | N12: =SUM(N6:N11) -> 0 | O12: =SUM(O6:O11) -> 0 | ... T12: =SUM(T6:T11) -> 0 | V12: =SUM(V6:V11) -> 0 | W12: =SUM(W6:W11) -> 0 | X12: =SUM(X6:X11) -> 0 | Y12: =SUM(Y6:Y11) -> 0 | Z12: =SUM(Z6:Z11) -> 0 | AA12: =SUM(AA6:AA11) -> 0 | AB12: =SUM(AB6:AB11) -> 0 | AC12: =SUM(AC6:AC11) -> 0 | ... AE12: =SUM(AE6:AE11) -> 0 | AG12: =SUM(AE12/AA12)-1 -> #DIV/0!
B13: Y/Y Growth (%) | C13: =SUM(C12/#REF!)-1 -> #REF! | D13: =SUM(D12/C12)-1 -> #DIV/0! | E13: =SUM(E12/D12)-1 -> #DIV/0! | F13: =SUM(F12/E12)-1 -> #DIV/0! | L13: =SUM(L12/H12)-1 -> #DIV/0! | M13: =SUM(M12/I12)-1 -> #DIV/0! | N13: =SUM(N12/J12)-1 -> #DIV/0! | O13: =SUM(O12/K12)-1 -> #DIV/0! | P13: =SUM(P12/L12)-1 -> #DIV/0! | Q13: =SUM(Q12/M12)-1 -> #DIV/0! | R13: =SUM(R12/N12)-1 -> #DIV/0! | S13: =SUM(S12/O12)-1 -> #DIV/0! | T13: =SUM(T12/P12)-1 -> #DIV/0! | Z13: =SUM(Z12/V12)-1 -> #DIV/0! | AA13: =SUM(AA12/W12)-1 -> #DIV/0! | AB13: =SUM(AB12/X12)-1 -> #DIV/0! | AC13: =SUM(AC12/Y12)-1 -> #DIV/0! | AD13: =SUM(AD12/Z12)-1 -> #DIV/0! | AE13: =SUM(AE12/AA12)-1 -> #DIV/0! | AG13: =SUM(AE13-AA13)*10000 -> #DIV/0!
B14: Q/Q Growth (%) | C14: N/A | D14: N/A | E14: N/A | F14: N/A | I14: =SUM(I12/H12)-1 -> #DIV/0! | J14: =SUM(J12/I12)-1 -> #DIV/0! | K14: =SUM(K12/J12)-1 -> #DIV/0! | L14: =SUM(L12/K12)-1 -> #DIV/0! | M14: =SUM(M12/L12)-1 -> #DIV/0! | N14: =SUM(N12/M12)-1 -> #DIV/0! | O14: =SUM(O12/N12)-1 -> #DIV/0! | P14: =SUM(P12/O12)-1 -> #DIV/0! | ... T14: =SUM(T12/S12)-1 -> #DIV/0! | V14: N/A | W14: N/A | X14: N/A | Y14: N/A | Z14: N/A | AA14: N/A | AB14: N/A | AC14: N/A | AD14: N/A | AE14: N/A
B16: (-) Cost of Sales | V16: =SUM(H16:K16) -> 0 | W16: =SUM(I16:L16) -> 0 | X16: =SUM(J16:M16) -> 0 | Y16: =SUM(K16:N16) -> 0 | Z16: =SUM(L16:O16) -> 0 | AA16: =SUM(M16:P16) -> 0 | AB16: =SUM(N16:Q16) -> 0 | AC16: =SUM(O16:R16) -> 0 | ... AE16: =SUM(Q16:T16) -> 0 | AG16: =SUM(AE16/AA16)-1 -> #DIV/0!
B17: Gross Profit | C17: =SUM(C12+SUM(C16:C16)) -> 0 | D17: =SUM(D12+SUM(D16:D16)) -> 0 | E17: =SUM(E12+SUM(E16:E16)) -> 0 | F17: =SUM(F12+SUM(F16:F16)) -> 0 | H17: =SUM(H12+SUM(H16:H16)) -> 0 | I17: =SUM(I12+SUM(I16:I16)) -> 0 | J17: =SUM(J12+SUM(J16:J16)) -> 0 | K17: =SUM(K12+SUM(K16:K16)) -> 0 | L17: =SUM(L12+SUM(L16:L16)) -> 0 | M17: =SUM(M12+SUM(M16:M16)) -> 0 | N17: =SUM(N12+SUM(N16:N16)) -> 0 | O17: =SUM(O12+SUM(O16:O16)) -> 0 | ... T17: =SUM(T12+SUM(T16:T16)) -> 0 | V17: =SUM(V12+SUM(V16:V16)) -> 0 | W17: =SUM(W12+SUM(W16:W16)) -> 0 | X17: =SUM(X12+SUM(X16:X16)) -> 0 | Y17: =SUM(Y12+SUM(Y16:Y16)) -> 0 | Z17: =SUM(Z12+SUM(Z16:Z16)) -> 0 | AA17: =SUM(AA12+SUM(AA16:AA16)) -> 0 | AB17: =SUM(AB12+SUM(AB16:AB16)) -> 0 | AC17: =SUM(AC12+SUM(AC16:AC16)) -> 0 | ... AE17: =SUM(AE12+SUM(AE16:AE16)) -> 0 | AG17: =SUM(AE17/AA17)-1 -> #DIV/0!
B18: Gross Margin (%) | C18: =C17/C12 -> #DIV/0! | D18: =D17/D12 -> #DIV/0! | E18: =E17/E12 -> #DIV/0! | F18: =F17/F12 -> #DIV/0! | H18: =H17/H12 -> #DIV/0! | I18: =I17/I12 -> #DIV/0! | J18: =J17/J12 -> #DIV/0! | K18: =K17/K12 -> #DIV/0! | L18: =L17/L12 -> #DIV/0! | M18: =M17/M12 -> #DIV/0! | N18: =N17/N12 -> #DIV/0! | O18: =O17/O12 -> #DIV/0! | ... T18: =T17/T12 -> #DIV/0! | V18: =V17/V12 -> #DIV/0! | W18: =W17/W12 -> #DIV/0! | X18: =X17/X12 -> #DIV/0! | Y18: =Y17/Y12 -> #DIV/0! | Z18: =Z17/Z12 -> #DIV/0! | AA18: =AA17/AA12 -> #DIV/0! | AB18: =AB17/AB12 -> #DIV/0! | AC18: =AC17/AC12 -> #DIV/0! | ... AE18: =AE17/AE12 -> #DIV/0! | AG18: =SUM(AE18-AA18)*10000 -> #DIV/0!
B20: (-) XXX | V20: =SUM(H20:K20) -> 0 | W20: =SUM(I20:L20) -> 0 | X20: =SUM(J20:M20) -> 0 | Y20: =SUM(K20:N20) -> 0 | Z20: =SUM(L20:O20) -> 0 | AA20: =SUM(M20:P20) -> 0 | AB20: =SUM(N20:Q20) -> 0 | AC20: =SUM(O20:R20) -> 0 | ... AE20: =SUM(Q20:T20) -> 0 | AG20: =SUM(AE20/AA20)-1 -> #DIV/0!
B21: (-) XXX | V21: =SUM(H21:K21) -> 0 | W21: =SUM(I21:L21) -> 0 | X21: =SUM(J21:M21) -> 0 | Y21: =SUM(K21:N21) -> 0 | Z21: =SUM(L21:O21) -> 0 | AA21: =SUM(M21:P21) -> 0 | AB21: =SUM(N21:Q21) -> 0 | AC21: =SUM(O21:R21) -> 0 | ... AE21: =SUM(Q21:T21) -> 0 | AG21: =SUM(AE21/AA21)-1 -> #DIV/0!
B22: (-) XXX | V22: =SUM(H22:K22) -> 0 | W22: =SUM(I22:L22) -> 0 | X22: =SUM(J22:M22) -> 0 | Y22: =SUM(K22:N22) -> 0 | Z22: =SUM(L22:O22) -> 0 | AA22: =SUM(M22:P22) -> 0 | AB22: =SUM(N22:Q22) -> 0 | AC22: =SUM(O22:R22) -> 0 | ... AE22: =SUM(Q22:T22) -> 0 | AG22: =SUM(AE22/AA22)-1 -> #DIV/0!
B23: (-) XXX | V23: =SUM(H23:K23) -> 0 | W23: =SUM(I23:L23) -> 0 | X23: =SUM(J23:M23) -> 0 | Y23: =SUM(K23:N23) -> 0 | Z23: =SUM(L23:O23) -> 0 | AA23: =SUM(M23:P23) -> 0 | AB23: =SUM(N23:Q23) -> 0 | AC23: =SUM(O23:R23) -> 0 | ... AE23: =SUM(Q23:T23) -> 0 | AG23: =SUM(AE23/AA23)-1 -> #DIV/0!
B24: (-) XXX | V24: =SUM(H24:K24) -> 0 | W24: =SUM(I24:L24) -> 0 | X24: =SUM(J24:M24) -> 0 | Y24: =SUM(K24:N24) -> 0 | Z24: =SUM(L24:O24) -> 0 | AA24: =SUM(M24:P24) -> 0 | AB24: =SUM(N24:Q24) -> 0 | AC24: =SUM(O24:R24) -> 0 | ... AE24: =SUM(Q24:T24) -> 0 | AG24: =SUM(AE24/AA24)-1 -> #DIV/0!
B25: Earning before Interest & Taxes (EBIT) | C25: =SUM(C17+SUM(C20:C24)) -> 0 | D25: =SUM(D17+SUM(D20:D24)) -> 0 | E25: =SUM(E17+SUM(E20:E24)) -> 0 | F25: =SUM(F17+SUM(F20:F24)) -> 0 | H25: =SUM(H17+SUM(H20:H24)) -> 0 | I25: =SUM(I17+SUM(I20:I24)) -> 0 | J25: =SUM(J17+SUM(J20:J24)) -> 0 | K25: =SUM(K17+SUM(K20:K24)) -> 0 | L25: =SUM(L17+SUM(L20:L24)) -> 0 | M25: =SUM(M17+SUM(M20:M24)) -> 0 | N25: =SUM(N17+SUM(N20:N24)) -> 0 | O25: =SUM(O17+SUM(O20:O24)) -> 0 | ... T25: =SUM(T17+SUM(T20:T24)) -> 0 | V25: =SUM(V17+SUM(V20:V24)) -> 0 | W25: =SUM(W17+SUM(W20:W24)) -> 0 | X25: =SUM(X17+SUM(X20:X24)) -> 0 | Y25: =SUM(Y17+SUM(Y20:Y24)) -> 0 | Z25: =SUM(Z17+SUM(Z20:Z24)) -> 0 | AA25: =SUM(AA17+SUM(AA20:AA24)) -> 0 | AB25: =SUM(AB17+SUM(AB20:AB24)) -> 0 | AC25: =SUM(AC17+SUM(AC20:AC24)) -> 0 | ... AE25: =SUM(AE17+SUM(AE20:AE24)) -> 0 | AG25: =SUM(AE25/AA25)-1 -> #DIV/0!
B26: Operating Margin (%) | C26: =C25/C12 -> #DIV/0! | D26: =D25/D12 -> #DIV/0! | E26: =E25/E12 -> #DIV/0! | F26: =F25/F12 -> #DIV/0! | H26: =H25/H12 -> #DIV/0! | I26: =I25/I12 -> #DIV/0! | J26: =J25/J12 -> #DIV/0! | K26: =K25/K12 -> #DIV/0! | L26: =L25/L12 -> #DIV/0! | M26: =M25/M12 -> #DIV/0! | N26: =N25/N12 -> #DIV/0! | O26: =O25/O12 -> #DIV/0! | ... T26: =T25/T12 -> #DIV/0! | V26: =V25/V12 -> #DIV/0! | W26: =W25/W12 -> #DIV/0! | X26: =X25/X12 -> #DIV/0! | Y26: =Y25/Y12 -> #DIV/0! | Z26: =Z25/Z12 -> #DIV/0! | AA26: =AA25/AA12 -> #DIV/0! | AB26: =AB25/AB12 -> #DIV/0! | AC26: =AC25/AC12 -> #DIV/0! | ... AE26: =AE25/AE12 -> #DIV/0! | AG26: =SUM(AE26-AA26)*10000 -> #DIV/0!
B28: (+) Depreciation and Amortization (D&A) | V28: =SUM(H28:K28) -> 0 | W28: =SUM(I28:L28) -> 0 | X28: =SUM(J28:M28) -> 0 | Y28: =SUM(K28:N28) -> 0 | Z28: =SUM(L28:O28) -> 0 | AA28: =SUM(M28:P28) -> 0 | AB28: =SUM(N28:Q28) -> 0 | AC28: =SUM(O28:R28) -> 0 | ... AE28: =SUM(Q28:T28) -> 0 | AG28: =SUM(AE28/AA28)-1 -> #DIV/0!
B29: EBITDA | C29: =SUM(C25+SUM(C28:C28)) -> 0 | D29: =SUM(D25+SUM(D28:D28)) -> 0 | E29: =SUM(E25+SUM(E28:E28)) -> 0 | F29: =SUM(F25+SUM(F28:F28)) -> 0 | H29: =SUM(H25+SUM(H28:H28)) -> 0 | I29: =SUM(I25+SUM(I28:I28)) -> 0 | J29: =SUM(J25+SUM(J28:J28)) -> 0 | K29: =SUM(K25+SUM(K28:K28)) -> 0 | L29: =SUM(L25+SUM(L28:L28)) -> 0 | M29: =SUM(M25+SUM(M28:M28)) -> 0 | N29: =SUM(N25+SUM(N28:N28)) -> 0 | O29: =SUM(O25+SUM(O28:O28)) -> 0 | ... T29: =SUM(T25+SUM(T28:T28)) -> 0 | V29: =SUM(V25+SUM(V28:V28)) -> 0 | W29: =SUM(W25+SUM(W28:W28)) -> 0 | X29: =SUM(X25+SUM(X28:X28)) -> 0 | Y29: =SUM(Y25+SUM(Y28:Y28)) -> 0 | Z29: =SUM(Z25+SUM(Z28:Z28)) -> 0 | AA29: =SUM(AA25+SUM(AA28:AA28)) -> 0 | AB29: =SUM(AB25+SUM(AB28:AB28)) -> 0 | AC29: =SUM(AC25+SUM(AC28:AC28)) -> 0 | ... AE29: =SUM(AE25+SUM(AE28:AE28)) -> 0 | AG29: =SUM(AE29/AA29)-1 -> #DIV/0!
B30: EBITDA Margin (%) | C30: =C29/C12 -> #DIV/0! | D30: =D29/D12 -> #DIV/0! | E30: =E29/E12 -> #DIV/0! | F30: =F29/F12 -> #DIV/0! | H30: =H29/H12 -> #DIV/0! | I30: =I29/I12 -> #DIV/0! | J30: =J29/J12 -> #DIV/0! | K30: =K29/K12 -> #DIV/0! | L30: =L29/L12 -> #DIV/0! | M30: =M29/M12 -> #DIV/0! | N30: =N29/N12 -> #DIV/0! | O30: =O29/O12 -> #DIV/0! | ... T30: =T29/T12 -> #DIV/0! | V30: =V29/V12 -> #DIV/0! | W30: =W29/W12 -> #DIV/0! | X30: =X29/X12 -> #DIV/0! | Y30: =Y29/Y12 -> #DIV/0! | Z30: =Z29/Z12 -> #DIV/0! | AA30: =AA29/AA12 -> #DIV/0! | AB30: =AB29/AB12 -> #DIV/0! | AC30: =AC29/AC12 -> #DIV/0! | ... AE30: =AE29/AE12 -> #DIV/0! | AG30: =SUM(AE30-AA30)*10000 -> #DIV/0!
B32: (+) Stock-Based Compensation (SBC) | V32: =SUM(H32:K32) -> 0 | W32: =SUM(I32:L32) -> 0 | X32: =SUM(J32:M32) -> 0 | Y32: =SUM(K32:N32) -> 0 | Z32: =SUM(L32:O32) -> 0 | AA32: =SUM(M32:P32) -> 0 | AB32: =SUM(N32:Q32) -> 0 | AC32: =SUM(O32:R32) -> 0 | ... AE32: =SUM(Q32:T32) -> 0 | AG32: =SUM(AE32/AA32)-1 -> #DIV/0!
B33: (+) XXX | V33: =SUM(H33:K33) -> 0 | W33: =SUM(I33:L33) -> 0 | X33: =SUM(J33:M33) -> 0 | Y33: =SUM(K33:N33) -> 0 | Z33: =SUM(L33:O33) -> 0 | AA33: =SUM(M33:P33) -> 0 | AB33: =SUM(N33:Q33) -> 0 | AC33: =SUM(O33:R33) -> 0 | ... AE33: =SUM(Q33:T33) -> 0 | AG33: =SUM(AE33/AA33)-1 -> #DIV/0!
B34: Adj. EBITDA | C34: =+SUM(C29+SUM(C32:C32)) -> 0 | D34: =+SUM(D29+SUM(D32:D32)) -> 0 | E34: =+SUM(E29+SUM(E32:E32)) -> 0 | F34: =+SUM(F29+SUM(F32:F32)) -> 0 | H34: =+SUM(H29+SUM(H32:H32)) -> 0 | I34: =+SUM(I29+SUM(I32:I32)) -> 0 | J34: =+SUM(J29+SUM(J32:J32)) -> 0 | K34: =+SUM(K29+SUM(K32:K32)) -> 0 | L34: =+SUM(L29+SUM(L32:L32)) -> 0 | M34: =+SUM(M29+SUM(M32:M32)) -> 0 | N34: =+SUM(N29+SUM(N32:N32)) -> 0 | O34: =+SUM(O29+SUM(O32:O32)) -> 0 | ... T34: =+SUM(T29+SUM(T32:T32)) -> 0 | V34: =+SUM(V29+SUM(V32:V32)) -> 0 | W34: =+SUM(W29+SUM(W32:W32)) -> 0 | X34: =+SUM(X29+SUM(X32:X32)) -> 0 | Y34: =+SUM(Y29+SUM(Y32:Y32)) -> 0 | Z34: =+SUM(Z29+SUM(Z32:Z32)) -> 0 | AA34: =+SUM(AA29+SUM(AA32:AA32)) -> 0 | AB34: =+SUM(AB29+SUM(AB32:AB32)) -> 0 | AC34: =+SUM(AC29+SUM(AC32:AC32)) -> 0 | ... AE34: =+SUM(AE29+SUM(AE32:AE32)) -> 0 | AG34: =SUM(AE34/AA34)-1 -> #DIV/0!
B35: Adj. EBITDA Margin (%) | C35: =C34/C12 -> #DIV/0! | D35: =D34/D12 -> #DIV/0! | E35: =E34/E12 -> #DIV/0! | F35: =F34/F12 -> #DIV/0! | H35: =H34/H12 -> #DIV/0! | I35: =I34/I12 -> #DIV/0! | J35: =J34/J12 -> #DIV/0! | K35: =K34/K12 -> #DIV/0! | L35: =L34/L12 -> #DIV/0! | M35: =M34/M12 -> #DIV/0! | N35: =N34/N12 -> #DIV/0! | O35: =O34/O12 -> #DIV/0! | ... T35: =T34/T12 -> #DIV/0! | V35: =V34/V12 -> #DIV/0! | W35: =W34/W12 -> #DIV/0! | X35: =X34/X12 -> #DIV/0! | Y35: =Y34/Y12 -> #DIV/0! | Z35: =Z34/Z12 -> #DIV/0! | AA35: =AA34/AA12 -> #DIV/0! | AB35: =AB34/AB12 -> #DIV/0! | AC35: =AC34/AC12 -> #DIV/0! | ... AE35: =AE34/AE12 -> #DIV/0! | AG35: =SUM(AE35-AA35)*10000 -> #DIV/0!
B37: (-) Capital Expenditures | V37: =SUM(H37:K37) -> 0 | W37: =SUM(I37:L37) -> 0 | X37: =SUM(J37:M37) -> 0 | Y37: =SUM(K37:N37) -> 0 | Z37: =SUM(L37:O37) -> 0 | AA37: =SUM(M37:P37) -> 0 | AB37: =SUM(N37:Q37) -> 0 | AC37: =SUM(O37:R37) -> 0 | ... AE37: =SUM(Q37:T37) -> 0 | AG37: =SUM(AE37/AA37)-1 -> #DIV/0!
B38: (-) Cash Taxes | V38: =SUM(H38:K38) -> 0 | W38: =SUM(I38:L38) -> 0 | X38: =SUM(J38:M38) -> 0 | Y38: =SUM(K38:N38) -> 0 | Z38: =SUM(L38:O38) -> 0 | AA38: =SUM(M38:P38) -> 0 | AB38: =SUM(N38:Q38) -> 0 | AC38: =SUM(O38:R38) -> 0 | ... AE38: =SUM(Q38:T38) -> 0 | AG38: =SUM(AE38/AA38)-1 -> #DIV/0!
B39: (-) Cash Interest | V39: =SUM(H39:K39) -> 0 | W39: =SUM(I39:L39) -> 0 | X39: =SUM(J39:M39) -> 0 | Y39: =SUM(K39:N39) -> 0 | Z39: =SUM(L39:O39) -> 0 | AA39: =SUM(M39:P39) -> 0 | AB39: =SUM(N39:Q39) -> 0 | AC39: =SUM(O39:R39) -> 0 | ... AE39: =SUM(Q39:T39) -> 0 | AG39: =SUM(AE39/AA39)-1 -> #DIV/0!
B40: (-) Mandatory Outflows | V40: =SUM(H40:K40) -> 0 | W40: =SUM(I40:L40) -> 0 | X40: =SUM(J40:M40) -> 0 | Y40: =SUM(K40:N40) -> 0 | Z40: =SUM(L40:O40) -> 0 | AA40: =SUM(M40:P40) -> 0 | AB40: =SUM(N40:Q40) -> 0 | AC40: =SUM(O40:R40) -> 0 | ... AE40: =SUM(Q40:T40) -> 0 | AG40: =SUM(AE40/AA40)-1 -> #DIV/0!
B41: (+/-) Changes in NWC | V41: =SUM(H41:K41) -> 0 | W41: =SUM(I41:L41) -> 0 | X41: =SUM(J41:M41) -> 0 | Y41: =SUM(K41:N41) -> 0 | Z41: =SUM(L41:O41) -> 0 | AA41: =SUM(M41:P41) -> 0 | AB41: =SUM(N41:Q41) -> 0 | AC41: =SUM(O41:R41) -> 0 | ... AE41: =SUM(Q41:T41) -> 0 | AG41: =SUM(AE41/AA41)-1 -> #DIV/0!
B42: Discretionary Cash-Flows | C42: =SUM(C34+SUM(C37:C41)) -> 0 | D42: =SUM(D34+SUM(D37:D41)) -> 0 | E42: =SUM(E34+SUM(E37:E41)) -> 0 | F42: =SUM(F34+SUM(F37:F41)) -> 0 | H42: =SUM(H34+SUM(H37:H41)) -> 0 | I42: =SUM(I34+SUM(I37:I41)) -> 0 | J42: =SUM(J34+SUM(J37:J41)) -> 0 | K42: =SUM(K34+SUM(K37:K41)) -> 0 | L42: =SUM(L34+SUM(L37:L41)) -> 0 | M42: =SUM(M34+SUM(M37:M41)) -> 0 | N42: =SUM(N34+SUM(N37:N41)) -> 0 | O42: =SUM(O34+SUM(O37:O41)) -> 0 | ... T42: =SUM(T34+SUM(T37:T41)) -> 0 | V42: =SUM(V34+SUM(V37:V41)) -> 0 | W42: =SUM(W34+SUM(W37:W41)) -> 0 | X42: =SUM(X34+SUM(X37:X41)) -> 0 | Y42: =SUM(Y34+SUM(Y37:Y41)) -> 0 | Z42: =SUM(Z34+SUM(Z37:Z41)) -> 0 | AA42: =SUM(AA34+SUM(AA37:AA41)) -> 0 | AB42: =SUM(AB34+SUM(AB37:AB41)) -> 0 | AC42: =SUM(AC34+SUM(AC37:AC41)) -> 0 | ... AE42: =SUM(AE34+SUM(AE37:AE41)) -> 0 | AG42: =SUM(AE42/AA42)-1 -> #DIV/0!
B44: (+/-) XXX | V44: =SUM(H44:K44) -> 0 | W44: =SUM(I44:L44) -> 0 | X44: =SUM(J44:M44) -> 0 | Y44: =SUM(K44:N44) -> 0 | Z44: =SUM(L44:O44) -> 0 | AA44: =SUM(M44:P44) -> 0 | AB44: =SUM(N44:Q44) -> 0 | AC44: =SUM(O44:R44) -> 0 | ... AE44: =SUM(Q44:T44) -> 0
B45: (+/-) XXX | V45: =SUM(H45:K45) -> 0 | W45: =SUM(I45:L45) -> 0 | X45: =SUM(J45:M45) -> 0 | Y45: =SUM(K45:N45) -> 0 | Z45: =SUM(L45:O45) -> 0 | AA45: =SUM(M45:P45) -> 0 | AB45: =SUM(N45:Q45) -> 0 | AC45: =SUM(O45:R45) -> 0 | ... AE45: =SUM(Q45:T45) -> 0
B46: (+/-) XXX | V46: =SUM(H46:K46) -> 0 | W46: =SUM(I46:L46) -> 0 | X46: =SUM(J46:M46) -> 0 | Y46: =SUM(K46:N46) -> 0 | Z46: =SUM(L46:O46) -> 0 | AA46: =SUM(M46:P46) -> 0 | AB46: =SUM(N46:Q46) -> 0 | AC46: =SUM(O46:R46) -> 0 | ... AE46: =SUM(Q46:T46) -> 0
B47: (+/-) XXX | V47: =SUM(H47:K47) -> 0 | W47: =SUM(I47:L47) -> 0 | X47: =SUM(J47:M47) -> 0 | Y47: =SUM(K47:N47) -> 0 | Z47: =SUM(L47:O47) -> 0 | AA47: =SUM(M47:P47) -> 0 | AB47: =SUM(N47:Q47) -> 0 | AC47: =SUM(O47:R47) -> 0 | ... AE47: =SUM(Q47:T47) -> 0
B48: (+/-) XXX | V48: =SUM(H48:K48) -> 0 | W48: =SUM(I48:L48) -> 0 | X48: =SUM(J48:M48) -> 0 | Y48: =SUM(K48:N48) -> 0 | Z48: =SUM(L48:O48) -> 0 | AA48: =SUM(M48:P48) -> 0 | AB48: =SUM(N48:Q48) -> 0 | AC48: =SUM(O48:R48) -> 0 | ... AE48: =SUM(Q48:T48) -> 0
...
