Workbook

Sheet Historical Financials
B2: Alphabet Inc. (NASDAQ: GOOG)
B3: Historical Financials
B4: $ mm except per share
A6: X | B6: Income Statement | G6: FYE | O6: Quarterly | Y6: Quarterly | AE6: LTM | AS6: LTM | AT6: LTM | AZ6: Variance
B7: Fiscal Period | C7: 2018 | D7: 2019 | E7: 2020 | F7: 2021 | G7: 2022 | H7: 2023 | I7: 2024 | K7: 1Q21 | L7: 2Q21 | M7: 3Q21 | N7: 4Q21 | O7: 1Q22 | P7: 2Q22 | Q7: 3Q22 | R7: 4Q22 | S7: 1Q23 | T7: 2Q23 | U7: 3Q23 | V7: 4Q23 | W7: 1Q24 | X7: 2Q24 | Y7: 3Q24 | Z7: 4Q24 | AA7: 1Q25 | AB7: 2Q25 | AC7: 3Q25 | AE7: =#REF! -> #REF! | AF7: =K7 -> 1Q21 | AG7: =L7 -> 2Q21 | AH7: =M7 -> 3Q21 | AI7: =N7 -> 4Q21 | AJ7: =O7 -> 1Q22 | AK7: =P7 -> 2Q22 | AL7: =Q7 -> 3Q22 | AM7: =R7 -> 4Q22 | ... AX7: =AC7 -> 3Q25
B8: Fiscal Period End Date | C8: 43465 | D8: 43830 | E8: 44196 | F8: 44561 | G8: 44926 | H8: 45291 | I8: 45657 | K8: 44286 | L8: 44377 | M8: 44469 | N8: =F8 -> 44561 | O8: 44651 | P8: 44742 | Q8: 44834 | R8: =G8 -> 44926 | S8: 45016 | T8: 45107 | U8: 45199 | V8: =H8 -> 45291 | W8: 45382 | X8: 45473 | Y8: 45565 | Z8: =I8 -> 45657 | AA8: 45747 | AB8: 45838 | AC8: 45930 | AE8: =#REF! -> #REF! | AF8: =K8 -> 44286 | AG8: =L8 -> 44377 | AH8: =M8 -> 44469 | AI8: =N8 -> 44561 | AJ8: =O8 -> 44651 | AK8: =P8 -> 44742 | AL8: =Q8 -> 44834 | AM8: =R8 -> 44926 | ... AX8: =AC8 -> 45930
B10: Consolidated Revenue | C10: 136819 | D10: 161857 | E10: 182527 | F10: 257637 | G10: 282836 | H10: 307394 | I10: 350018 | K10: 55314 | L10: 61880 | M10: 65118 | N10: =SUM(F10-SUM(K10:M10)) -> 75325 | O10: 68011 | P10: 69685 | Q10: 69092 | R10: =SUM(G10-SUM(O10:Q10)) -> 76048 | S10: 69787 | T10: 74604 | U10: 76693 | V10: =SUM(H10-SUM(S10:U10)) -> 86310 | W10: 80539 | X10: 84742 | Y10: 88268 | Z10: =SUM(I10-SUM(W10:Y10)) -> 96469 | AA10: 90234 | AB10: 96428 | AC10: 102346 | AE10: =SUM(#REF!) -> #REF! | AF10: =SUM(K10:K10) -> 55314 | AG10: =SUM(K10:L10) -> 117194 | AH10: =SUM(K10:M10) -> 182312 | AI10: =SUM(K10:N10) -> 257637 | AJ10: =SUM(L10:O10) -> 270334 | AK10: =SUM(M10:P10) -> 278139 | AL10: =SUM(N10:Q10) -> 282113 | AM10: =SUM(O10:R10) -> 282836 | AN10: =SUM(P10:S10) -> 284612 | AO10: =SUM(Q10:T10) -> 289531 | AP10: =SUM(R10:U10) -> 297132 | ... AX10: =SUM(Z10:AC10) -> 385477 | AZ10: =SUM(AX10/AT10)-1 -> 0.13422625
B11: Total Revenue | C11: =+SUM(C10:C10) -> 136819 | D11: =+SUM(D10:D10) -> 161857 | E11: =+SUM(E10:E10) -> 182527 | F11: =+SUM(F10:F10) -> 257637 | G11: =+SUM(G10:G10) -> 282836 | H11: =+SUM(H10:H10) -> 307394 | I11: =+SUM(I10:I10) -> 350018 | K11: =+SUM(K10:K10) -> 55314 | L11: =+SUM(L10:L10) -> 61880 | M11: =+SUM(M10:M10) -> 65118 | N11: =+SUM(N10:N10) -> 75325 | O11: =+SUM(O10:O10) -> 68011 | P11: =+SUM(P10:P10) -> 69685 | Q11: =+SUM(Q10:Q10) -> 69092 | R11: =+SUM(R10:R10) -> 76048 | ... AC11: =+SUM(AC10:AC10) -> 102346 | AE11: =+SUM(AE10:AE10) -> #REF! | AF11: =+SUM(AF10:AF10) -> 55314 | AG11: =+SUM(AG10:AG10) -> 117194 | AH11: =+SUM(AH10:AH10) -> 182312 | AI11: =+SUM(AI10:AI10) -> 257637 | AJ11: =+SUM(AJ10:AJ10) -> 270334 | AK11: =+SUM(AK10:AK10) -> 278139 | AL11: =+SUM(AL10:AL10) -> 282113 | ... AX11: =+SUM(AX10:AX10) -> 385477 | AZ11: =SUM(AX11/AT11)-1 -> 0.13422625
B13: Cost of Sales | C13: -59549 | D13: -71896 | E13: -84732 | F13: -110939 | G13: -126203 | H13: -133332 | I13: -146306 | K13: -24103 | L13: -26227 | M13: -27621 | N13: =SUM(F13-SUM(K13:M13)) -> -32988 | O13: -29599 | P13: -30104 | Q13: -31158 | R13: =SUM(G13-SUM(O13:Q13)) -> -35342 | S13: -30612 | T13: -31916 | U13: -33229 | V13: =SUM(H13-SUM(S13:U13)) -> -37575 | W13: -33712 | X13: -35507 | Y13: -36474 | Z13: =SUM(I13-SUM(W13:Y13)) -> -40613 | AA13: -36361 | AB13: -39039 | AC13: -41369 | AE13: =SUM(#REF!) -> #REF! | AF13: =SUM(K13:K13) -> -24103 | AG13: =SUM(K13:L13) -> -50330 | AH13: =SUM(K13:M13) -> -77951 | AI13: =SUM(K13:N13) -> -110939 | AJ13: =SUM(L13:O13) -> -116435 | AK13: =SUM(M13:P13) -> -120312 | AL13: =SUM(N13:Q13) -> -123849 | AM13: =SUM(O13:R13) -> -126203 | AN13: =SUM(P13:S13) -> -127216 | AO13: =SUM(Q13:T13) -> -129028 | AP13: =SUM(R13:U13) -> -131099 | ... AX13: =SUM(Z13:AC13) -> -157382 | AZ13: =SUM(AX13/AT13)-1 -> 0.098514672
B14: Gross Profit | C14: =+SUM(C11+SUM(C13:C13)) -> 77270 | D14: =+SUM(D11+SUM(D13:D13)) -> 89961 | E14: =+SUM(E11+SUM(E13:E13)) -> 97795 | F14: =+SUM(F11+SUM(F13:F13)) -> 146698 | G14: =+SUM(G11+SUM(G13:G13)) -> 156633 | H14: =+SUM(H11+SUM(H13:H13)) -> 174062 | I14: =+SUM(I11+SUM(I13:I13)) -> 203712 | K14: =+SUM(K11+SUM(K13:K13)) -> 31211 | L14: =+SUM(L11+SUM(L13:L13)) -> 35653 | M14: =+SUM(M11+SUM(M13:M13)) -> 37497 | N14: =+SUM(N11+SUM(N13:N13)) -> 42337 | O14: =+SUM(O11+SUM(O13:O13)) -> 38412 | P14: =+SUM(P11+SUM(P13:P13)) -> 39581 | Q14: =+SUM(Q11+SUM(Q13:Q13)) -> 37934 | R14: =+SUM(R11+SUM(R13:R13)) -> 40706 | ... AC14: =+SUM(AC11+SUM(AC13:AC13)) -> 60977 | AE14: =+SUM(AE11+SUM(AE13:AE13)) -> #REF! | AF14: =+SUM(AF11+SUM(AF13:AF13)) -> 31211 | AG14: =+SUM(AG11+SUM(AG13:AG13)) -> 66864 | AH14: =+SUM(AH11+SUM(AH13:AH13)) -> 104361 | AI14: =+SUM(AI11+SUM(AI13:AI13)) -> 146698 | AJ14: =+SUM(AJ11+SUM(AJ13:AJ13)) -> 153899 | AK14: =+SUM(AK11+SUM(AK13:AK13)) -> 157827 | AL14: =+SUM(AL11+SUM(AL13:AL13)) -> 158264 | ... AX14: =+SUM(AX11+SUM(AX13:AX13)) -> 228095 | AZ14: =SUM(AX14/AT14)-1 -> 0.16025149
B15: Gross Margin (%) | C15: =C14/C11 -> 0.56476074 | D15: =D14/D11 -> 0.55580543 | E15: =E14/E11 -> 0.53578375 | F15: =F14/F11 -> 0.56939803 | G15: =G14/G11 -> 0.55379443 | H15: =H14/H11 -> 0.56625048 | I15: =I14/I11 -> 0.58200435 | K15: =K14/K11 -> 0.56425136 | L15: =L14/L11 -> 0.57616354 | M15: =M14/M11 -> 0.57583157 | N15: =N14/N11 -> 0.56205775 | O15: =O14/O11 -> 0.56479099 | P15: =P14/P11 -> 0.56799885 | Q15: =Q14/Q11 -> 0.54903607 | R15: =R14/R11 -> 0.5352672 | ... AC15: =AC14/AC11 -> 0.5957927 | AE15: =AE14/AE11 -> #REF! | AF15: =AF14/AF11 -> 0.56425136 | AG15: =AG14/AG11 -> 0.57054115 | AH15: =AH14/AH11 -> 0.57243078 | AI15: =AI14/AI11 -> 0.56939803 | AJ15: =AJ14/AJ11 -> 0.56929206 | AK15: =AK14/AK11 -> 0.5674393 | AL15: =AL14/AL11 -> 0.56099506 | ... AX15: =AX14/AX11 -> 0.59172143 | AZ15: =SUM(AX15-AT15)*1000 -> 13.272716
B17: Research & Development (R&D) | C17: -21419 | D17: -26018 | E17: -27573 | F17: -31562 | G17: -39500 | H17: -45427 | I17: -49326 | K17: -7485 | L17: -7675 | M17: -7694 | N17: =SUM(F17-SUM(K17:M17)) -> -8708 | O17: -9119 | P17: -9841 | Q17: -10273 | R17: =SUM(G17-SUM(O17:Q17)) -> -10267 | S17: -11468 | T17: -10588 | U17: -11258 | V17: =SUM(H17-SUM(S17:U17)) -> -12113 | W17: -11903 | X17: -11860 | Y17: -12447 | Z17: =SUM(I17-SUM(W17:Y17)) -> -13116 | AA17: -13556 | AB17: -13808 | AC17: -15151 | AE17: =SUM(#REF!) -> #REF! | AF17: =SUM(K17:K17) -> -7485 | AG17: =SUM(K17:L17) -> -15160 | AH17: =SUM(K17:M17) -> -22854 | AI17: =SUM(K17:N17) -> -31562 | AJ17: =SUM(L17:O17) -> -33196 | AK17: =SUM(M17:P17) -> -35362 | AL17: =SUM(N17:Q17) -> -37941 | AM17: =SUM(O17:R17) -> -39500 | AN17: =SUM(P17:S17) -> -41849 | AO17: =SUM(Q17:T17) -> -42596 | AP17: =SUM(R17:U17) -> -43581 | ... AX17: =SUM(Z17:AC17) -> -55631 | AZ17: =SUM(AX17/AT17)-1 -> 0.15123233
B18: Sales and Marketing (S&M) | C18: -16333 | D18: -18464 | E18: -17946 | F18: -22912 | G18: -26567 | H18: -27917 | I18: -27808 | K18: -4516 | L18: -5276 | M18: -5516 | N18: =SUM(F18-SUM(K18:M18)) -> -7604 | O18: -5825 | P18: -6630 | Q18: -6929 | R18: =SUM(G18-SUM(O18:Q18)) -> -7183 | S18: -6533 | T18: -6781 | U18: -6884 | V18: =SUM(H18-SUM(S18:U18)) -> -7719 | W18: -6426 | X18: -6792 | Y18: -7227 | Z18: =SUM(I18-SUM(W18:Y18)) -> -7363 | AA18: -6172 | AB18: -7101 | AC18: -7205 | AE18: =SUM(#REF!) -> #REF! | AF18: =SUM(K18:K18) -> -4516 | AG18: =SUM(K18:L18) -> -9792 | AH18: =SUM(K18:M18) -> -15308 | AI18: =SUM(K18:N18) -> -22912 | AJ18: =SUM(L18:O18) -> -24221 | AK18: =SUM(M18:P18) -> -25575 | AL18: =SUM(N18:Q18) -> -26988 | AM18: =SUM(O18:R18) -> -26567 | AN18: =SUM(P18:S18) -> -27275 | AO18: =SUM(Q18:T18) -> -27426 | AP18: =SUM(R18:U18) -> -27381 | ... AX18: =SUM(Z18:AC18) -> -27841 | AZ18: =SUM(AX18/AT18)-1 -> -0.011468541
B19: General and Administrative (G&A) | C19: -6923 | D19: -9551 | E19: -11052 | F19: -13510 | G19: -15724 | H19: -16425 | I19: -14188 | K19: -2773 | L19: -3341 | M19: -3256 | N19: =SUM(F19-SUM(K19:M19)) -> -4140 | O19: -3374 | P19: -3657 | Q19: -3597 | R19: =SUM(G19-SUM(O19:Q19)) -> -5096 | S19: -3759 | T19: -3481 | U19: -3979 | V19: =SUM(H19-SUM(S19:U19)) -> -5206 | W19: -3026 | X19: -3158 | Y19: -3599 | Z19: =SUM(I19-SUM(W19:Y19)) -> -4405 | AA19: -3539 | AB19: -5209 | AC19: -7393 | AE19: =SUM(#REF!) -> #REF! | AF19: =SUM(K19:K19) -> -2773 | AG19: =SUM(K19:L19) -> -6114 | AH19: =SUM(K19:M19) -> -9370 | AI19: =SUM(K19:N19) -> -13510 | AJ19: =SUM(L19:O19) -> -14111 | AK19: =SUM(M19:P19) -> -14427 | AL19: =SUM(N19:Q19) -> -14768 | AM19: =SUM(O19:R19) -> -15724 | AN19: =SUM(P19:S19) -> -16109 | AO19: =SUM(Q19:T19) -> -15933 | AP19: =SUM(R19:U19) -> -16315 | ... AX19: =SUM(Z19:AC19) -> -20546 | AZ19: =SUM(AX19/AT19)-1 -> 0.37073854
B20: European Commission Fines | C20: -5071 | D20: -1697 | E20: 0 | F20: 0 | G20: 0 | H20: 0 | I20: 0 | K20: 0 | N20: =SUM(F20-SUM(K20:M20)) -> 0 | R20: =SUM(G20-SUM(O20:Q20)) -> 0 | V20: =SUM(H20-SUM(S20:U20)) -> 0 | W20: 0 | Z20: =SUM(I20-SUM(W20:Y20)) -> 0 | AZ20: =SUM(AX20/AT20)-1 -> #DIV/0!
B21: Operating Profit | C21: =+SUM(C14+SUM(C17:C20)) -> 27524 | D21: =+SUM(D14+SUM(D17:D20)) -> 34231 | E21: =+SUM(E14+SUM(E17:E20)) -> 41224 | F21: =+SUM(F14+SUM(F17:F20)) -> 78714 | G21: =+SUM(G14+SUM(G17:G20)) -> 74842 | H21: =+SUM(H14+SUM(H17:H20)) -> 84293 | I21: =+SUM(I14+SUM(I17:I20)) -> 112390 | K21: =+SUM(K14+SUM(K17:K20)) -> 16437 | L21: =+SUM(L14+SUM(L17:L20)) -> 19361 | M21: =+SUM(M14+SUM(M17:M20)) -> 21031 | N21: =+SUM(N14+SUM(N17:N20)) -> 21885 | O21: =+SUM(O14+SUM(O17:O20)) -> 20094 | P21: =+SUM(P14+SUM(P17:P20)) -> 19453 | Q21: =+SUM(Q14+SUM(Q17:Q20)) -> 17135 | R21: =+SUM(R14+SUM(R17:R20)) -> 18160 | ... AC21: =+SUM(AC14+SUM(AC17:AC20)) -> 31228 | AE21: =+SUM(AE14+SUM(AE17:AE19)) -> #REF! | AF21: =+SUM(AF14+SUM(AF17:AF19)) -> 16437 | AG21: =+SUM(AG14+SUM(AG17:AG19)) -> 35798 | AH21: =+SUM(AH14+SUM(AH17:AH19)) -> 56829 | AI21: =+SUM(AI14+SUM(AI17:AI19)) -> 78714 | AJ21: =+SUM(AJ14+SUM(AJ17:AJ19)) -> 82371 | AK21: =+SUM(AK14+SUM(AK17:AK19)) -> 82463 | AL21: =+SUM(AL14+SUM(AL17:AL19)) -> 78567 | ... AX21: =+SUM(AX14+SUM(AX17:AX19)) -> 124077 | AZ21: =SUM(AX21/AT21)-1 -> 0.1803929
B22: Operating Margin (%) | C22: =C21/C11 -> 0.20117089 | D22: =D21/D11 -> 0.21148915 | E22: =E21/E11 -> 0.22585152 | F22: =F21/F11 -> 0.30552289 | G22: =G21/G11 -> 0.26461271 | H22: =H21/H11 -> 0.2742181 | I22: =I21/I11 -> 0.32109777 | K22: =K21/K11 -> 0.29715804 | L22: =L21/L11 -> 0.31287977 | M22: =M21/M11 -> 0.32296754 | N22: =N21/N11 -> 0.29054099 | O22: =O21/O11 -> 0.29545221 | P22: =P21/P11 -> 0.2791562 | Q22: =Q21/Q11 -> 0.24800266 | R22: =R21/R11 -> 0.23879655 | ... AC22: =AC21/AC11 -> 0.30512184 | AE22: =AE21/AE11 -> #REF! | AF22: =AF21/AF11 -> 0.29715804 | AG22: =AG21/AG11 -> 0.30545932 | AH22: =AH21/AH11 -> 0.31171289 | AI22: =AI21/AI11 -> 0.30552289 | AJ22: =AJ21/AJ11 -> 0.30470085 | AK22: =AK21/AK11 -> 0.29648126 | AL22: =AL21/AL11 -> 0.27849479 | ... AX22: =AX21/AX11 -> 0.32187913 | AZ22: =SUM(AX22-AT22)*1000 -> 12.589097
B24: Interest Income | C24: 1878 | D24: 2427 | E24: 1865 | F24: 1499 | G24: 2174 | H24: 3865 | I24: 4482 | K24: 345 | L24: 389 | M24: 387 | N24: =SUM(F24-SUM(K24:M24)) -> 378 | O24: 414 | P24: 486 | Q24: 615 | R24: =SUM(G24-SUM(O24:Q24)) -> 659 | S24: 797 | T24: 892 | U24: 1066 | V24: =SUM(H24-SUM(S24:U24)) -> 1110 | W24: 1061 | X24: 1090 | Y24: 1243 | Z24: =SUM(I24-SUM(W24:Y24)) -> 1088 | AA24: 1001 | AB24: 1050 | AC24: 1076 | AE24: =SUM(#REF!) -> #REF! | AF24: =SUM(K24:K24) -> 345 | AG24: =SUM(K24:L24) -> 734 | AH24: =SUM(K24:M24) -> 1121 | AI24: =SUM(K24:N24) -> 1499 | AJ24: =SUM(L24:O24) -> 1568 | AK24: =SUM(M24:P24) -> 1665 | AL24: =SUM(N24:Q24) -> 1893 | AM24: =SUM(O24:R24) -> 2174 | AN24: =SUM(P24:S24) -> 2557 | AO24: =SUM(Q24:T24) -> 2963 | AP24: =SUM(R24:U24) -> 3414 | ... AX24: =SUM(Z24:AC24) -> 4215 | AZ24: =SUM(AX24/AT24)-1 -> -0.064165187
B25: Interest Expense | C25: -114 | D25: -100 | E25: -135 | F25: -346 | G25: -357 | H25: -308 | I25: -268 | K25: -76 | L25: -76 | M25: -77 | N25: =SUM(F25-SUM(K25:M25)) -> -117 | O25: -83 | P25: -83 | Q25: -101 | R25: =SUM(G25-SUM(O25:Q25)) -> -90 | S25: -80 | T25: -43 | U25: -116 | V25: =SUM(H25-SUM(S25:U25)) -> -69 | W25: -94 | X25: -67 | Y25: -54 | Z25: =SUM(I25-SUM(W25:Y25)) -> -53 | AA25: -34 | AB25: -261 | AC25: -143 | AE25: =SUM(#REF!) -> #REF! | AF25: =SUM(K25:K25) -> -76 | AG25: =SUM(K25:L25) -> -152 | AH25: =SUM(K25:M25) -> -229 | AI25: =SUM(K25:N25) -> -346 | AJ25: =SUM(L25:O25) -> -353 | AK25: =SUM(M25:P25) -> -360 | AL25: =SUM(N25:Q25) -> -384 | AM25: =SUM(O25:R25) -> -357 | AN25: =SUM(P25:S25) -> -354 | AO25: =SUM(Q25:T25) -> -314 | AP25: =SUM(R25:U25) -> -329 | ... AX25: =SUM(Z25:AC25) -> -491 | AZ25: =SUM(AX25/AT25)-1 -> 0.72887324
B26: Other Income/Gains (Expenses/Losses) | C26: =-80+1190+5460-1203-120+378 -> 5625 | D26: =103+149+2649-326+390+102 -> 3067 | E26: =-344+725+5592-609+401-637 -> 5128 | F26: =-240-110+12380-1908+334+411 -> 10867 | G26: =-654-2064-3455+798-337+381 -> -5331 | H26: =-1238-1215+392+257-628+299 -> -2133 | I26: =-409-1043+3714+218-188+919 -> 3211 | K26: =113-86+4837-665+5+373 -> 4577 | L26: =-51+111+2772-523+92-90 -> 2311 | M26: =-139+37+2121-492+188+8 -> 1723 | N26: =SUM(F26-SUM(K26:M26)) -> 2256 | O26: =-73-367-1070+233-89-125 -> -1491 | P26: =-260-790-251+318-118+259 -> -842 | Q26: =-136-731-647+54-99+143 -> -1416 | R26: =SUM(G26-SUM(O26:Q26)) -> -1582 | S26: =-210-293+377+118-51+132 -> 73 | T26: =-268-304-205+5-106+94 -> -784 | U26: =-311-503-366+179-215+120 -> -1096 | V26: =SUM(H26-SUM(S26:U26)) -> -326 | W26: =-238-462+2243+104-26+255 -> 1876 | X26: =-173-310-714+128+32+140 -> -897 | Y26: =23+160+1821+29-107+70 -> 1996 | Z26: =SUM(I26-SUM(W26:Y26)) -> 236 | AA26: =-106+202+9758-40-22+424 -> 10216 | AB26: =-69+165+1286-83+419+155 -> 1873 | AC26: =-143+122+10734-174-30+1317 -> 11826 | AE26: =SUM(#REF!) -> #REF! | AF26: =SUM(K26:K26) -> 4577 | AG26: =SUM(K26:L26) -> 6888 | AH26: =SUM(K26:M26) -> 8611 | AI26: =SUM(K26:N26) -> 10867 | AJ26: =SUM(L26:O26) -> 4799 | AK26: =SUM(M26:P26) -> 1646 | AL26: =SUM(N26:Q26) -> -1493 | AM26: =SUM(O26:R26) -> -5331 | AN26: =SUM(P26:S26) -> -3767 | AO26: =SUM(Q26:T26) -> -3709 | AP26: =SUM(R26:U26) -> -3389 | ... AX26: =SUM(Z26:AC26) -> 24151 | AZ26: =SUM(AX26/AT26)-1 -> 8.1170253
B27: Earning Before Taxes | C27: =SUM(C21+SUM(C24:C26)) -> 34913 | D27: =SUM(D21+SUM(D24:D26)) -> 39625 | E27: =SUM(E21+SUM(E24:E26)) -> 48082 | F27: =SUM(F21+SUM(F24:F26)) -> 90734 | G27: =SUM(G21+SUM(G24:G26)) -> 71328 | H27: =SUM(H21+SUM(H24:H26)) -> 85717 | I27: =SUM(I21+SUM(I24:I26)) -> 119815 | K27: =SUM(K21+SUM(K24:K26)) -> 21283 | L27: =SUM(L21+SUM(L24:L26)) -> 21985 | M27: =SUM(M21+SUM(M24:M26)) -> 23064 | N27: =SUM(N21+SUM(N24:N26)) -> 24402 | O27: =SUM(O21+SUM(O24:O26)) -> 18934 | P27: =SUM(P21+SUM(P24:P26)) -> 19014 | Q27: =SUM(Q21+SUM(Q24:Q26)) -> 16233 | R27: =SUM(R21+SUM(R24:R26)) -> 17147 | ... AC27: =SUM(AC21+SUM(AC24:AC26)) -> 43987 | AE27: =SUM(AE21+SUM(AE24:AE26)) -> #REF! | AF27: =SUM(AF21+SUM(AF24:AF26)) -> 21283 | AG27: =SUM(AG21+SUM(AG24:AG26)) -> 43268 | AH27: =SUM(AH21+SUM(AH24:AH26)) -> 66332 | AI27: =SUM(AI21+SUM(AI24:AI26)) -> 90734 | AJ27: =SUM(AJ21+SUM(AJ24:AJ26)) -> 88385 | AK27: =SUM(AK21+SUM(AK24:AK26)) -> 85414 | AL27: =SUM(AL21+SUM(AL24:AL26)) -> 78583 | ... AX27: =SUM(AX21+SUM(AX24:AX26)) -> 151952 | AZ27: =SUM(AX27/AT27)-1 -> 0.35690813
B28: EBT Margin (%) | C28: =C27/C11 -> 0.25517655 | D28: =D27/D11 -> 0.24481487 | E28: =E27/E11 -> 0.26342404 | F28: =F27/F11 -> 0.35217768 | G28: =G27/G11 -> 0.25218855 | H28: =H27/H11 -> 0.2788506 | I28: =I27/I11 -> 0.34231097 | K28: =K27/K11 -> 0.38476697 | L28: =L27/L11 -> 0.35528442 | M28: =M27/M11 -> 0.35418778 | N28: =N27/N11 -> 0.32395619 | O28: =O27/O11 -> 0.27839614 | P28: =P27/P11 -> 0.27285643 | Q28: =Q27/Q11 -> 0.23494761 | R28: =R27/R11 -> 0.22547602 | ... AC28: =AC27/AC11 -> 0.42978719 | AE28: =AE27/AE11 -> #REF! | AF28: =AF27/AF11 -> 0.38476697 | AG28: =AG27/AG11 -> 0.36919979 | AH28: =AH27/AH11 -> 0.36383782 | AI28: =AI27/AI11 -> 0.35217768 | AJ28: =AJ27/AJ11 -> 0.32694741 | AK28: =AK27/AK11 -> 0.30709106 | AL28: =AL27/AL11 -> 0.2785515 | ... AX28: =AX27/AX11 -> 0.39419213 | AZ28: =SUM(AX28-AT28)*1000 -> 64.690779
B30: Provision for taxes | C30: -4177 | D30: -5282 | E30: -7813 | F30: -14701 | G30: -11356 | H30: -11922 | I30: -19697 | K30: -3353 | L30: -3460 | M30: -4128 | N30: =SUM(F30-SUM(K30:M30)) -> -3760 | O30: -2498 | P30: -3012 | Q30: -2323 | R30: =SUM(G30-SUM(O30:Q30)) -> -3523 | S30: -3154 | T30: -3535 | U30: -1508 | V30: =SUM(H30-SUM(S30:U30)) -> -3725 | W30: -4653 | X30: -3932 | Y30: -5405 | Z30: =SUM(I30-SUM(W30:Y30)) -> -5707 | AA30: -7249 | AB30: -5737 | AC30: -9008 | AE30: =SUM(#REF!) -> #REF! | AF30: =SUM(K30:K30) -> -3353 | AG30: =SUM(K30:L30) -> -6813 | AH30: =SUM(K30:M30) -> -10941 | AI30: =SUM(K30:N30) -> -14701 | AJ30: =SUM(L30:O30) -> -13846 | AK30: =SUM(M30:P30) -> -13398 | AL30: =SUM(N30:Q30) -> -11593 | AM30: =SUM(O30:R30) -> -11356 | AN30: =SUM(P30:S30) -> -12012 | AO30: =SUM(Q30:T30) -> -12535 | AP30: =SUM(R30:U30) -> -11720 | ... AX30: =SUM(Z30:AC30) -> -27701 | AZ30: =SUM(AX30/AT30)-1 -> 0.56370308
B31: Net loss | C31: =SUM(C27+SUM(C30:C30)) -> 30736 | D31: =SUM(D27+SUM(D30:D30)) -> 34343 | E31: =SUM(E27+SUM(E30:E30)) -> 40269 | F31: =SUM(F27+SUM(F30:F30)) -> 76033 | G31: =SUM(G27+SUM(G30:G30)) -> 59972 | H31: =SUM(H27+SUM(H30:H30)) -> 73795 | I31: =SUM(I27+SUM(I30:I30)) -> 100118 | K31: =SUM(K27+SUM(K30:K30)) -> 17930 | L31: =SUM(L27+SUM(L30:L30)) -> 18525 | M31: =SUM(M27+SUM(M30:M30)) -> 18936 | N31: =SUM(N27+SUM(N30:N30)) -> 20642 | O31: =SUM(O27+SUM(O30:O30)) -> 16436 | P31: =SUM(P27+SUM(P30:P30)) -> 16002 | Q31: =SUM(Q27+SUM(Q30:Q30)) -> 13910 | R31: =SUM(R27+SUM(R30:R30)) -> 13624 | ... AC31: =SUM(AC27+SUM(AC30:AC30)) -> 34979 | AE31: =SUM(AE27+SUM(AE30:AE30)) -> #REF! | AF31: =SUM(AF27+SUM(AF30:AF30)) -> 17930 | AG31: =SUM(AG27+SUM(AG30:AG30)) -> 36455 | AH31: =SUM(AH27+SUM(AH30:AH30)) -> 55391 | AI31: =SUM(AI27+SUM(AI30:AI30)) -> 76033 | AJ31: =SUM(AJ27+SUM(AJ30:AJ30)) -> 74539 | AK31: =SUM(AK27+SUM(AK30:AK30)) -> 72016 | AL31: =SUM(AL27+SUM(AL30:AL30)) -> 66990 | ... AX31: =SUM(AX27+SUM(AX30:AX30)) -> 124251 | AZ31: =SUM(AX31/AT31)-1 -> 0.31804729
B32: Net Margin (%) | C32: =C31/C11 -> 0.22464716 | D32: =D31/D11 -> 0.21218112 | E32: =E31/E11 -> 0.22061942 | F32: =F31/F11 -> 0.29511677 | G32: =G31/G11 -> 0.21203807 | H32: =H31/H11 -> 0.24006649 | I32: =I31/I11 -> 0.28603672 | K32: =K31/K11 -> 0.3241494 | L32: =L31/L11 -> 0.29936975 | M32: =M31/M11 -> 0.29079517 | N32: =N31/N11 -> 0.27403916 | O32: =O31/O11 -> 0.24166679 | P32: =P31/P11 -> 0.22963335 | Q32: =Q31/Q11 -> 0.20132577 | R32: =R31/R11 -> 0.17915001 | ... AC32: =AC31/AC11 -> 0.34177203 | AE32: =AE31/AE11 -> #REF! | AF32: =AF31/AF11 -> 0.3241494 | AG32: =AG31/AG11 -> 0.31106541 | AH32: =AH31/AH11 -> 0.30382531 | AI32: =AI31/AI11 -> 0.29511677 | AJ32: =AJ31/AJ11 -> 0.27572928 | AK32: =AK31/AK11 -> 0.2589209 | AL32: =AL31/AL11 -> 0.23745804 | ... AX32: =AX31/AX11 -> 0.32233052 | AZ32: =SUM(AX32-AT32)*1000 -> 44.953721
B34: Basic EPS | C34: =EPS!C18 -> 1.3075276 | D34: =EPS!D18 -> 1.3475749 | E34: =EPS!E18 -> 1.4113478 | F34: =EPS!F18 -> 5.6940762 | G34: =EPS!G18 -> 4.5909822 | H34: =EPS!H18 -> 5.8428345 | I34: =EPS!I18 -> 8.1271207 | K34: =EPS!K18 -> 1.3316598 | L34: =EPS!L18 -> 1.3846161 | M34: =EPS!M18 -> 1.4221384 | N34: =EPS!N18 -> 1.5458698 | O34: =EPS!O18 -> 1.244829 | P34: =EPS!P18 -> 1.2184573 | Q34: =EPS!Q18 -> 1.0685205 | R34: =EPS!R18 -> 1.0429457 | ... AC34: =EPS!AC18 -> 2.8941751 | AE34: =EPS!#REF! -> #REF! | AF34: =EPS!#REF! -> #REF! | AG34: =EPS!#REF! -> #REF! | AH34: =EPS!#REF! -> #REF! | AI34: =EPS!AE18 -> 5.6940762 | AJ34: =EPS!AF18 -> 5.6454313 | AK34: =EPS!AG18 -> 5.483591 | AL34: =EPS!AH18 -> 5.1459518 | AM34: =EPS!AI18 -> 4.5909822 | AN34: =EPS!AJ18 -> 4.5839136 | AO34: =EPS!AK18 -> 4.8115725 | AP34: =EPS!AL18 -> 5.3041889 | ... AX34: =EPS!AT18 -> 10.280573 | AZ34: =SUM(AX34/AT34)-1 -> 0.34029465
B35: Fully Diluted EPS | C35: =EPS!C24 -> 2.1851659 | D35: =EPS!D24 -> 2.4581154 | E35: =EPS!E24 -> 2.9306747 | F35: =EPS!F24 -> 5.6098431 | G35: =EPS!G24 -> 4.0336484 | H35: =EPS!H24 -> 5.139897 | I35: =EPS!I24 -> 6.8015243 | K35: =EPS!K24 -> 1.3143777 | L35: =EPS!L24 -> 1.3629457 | M35: =EPS!M24 -> 1.399526 | N35: =EPS!N24 -> 1.5228037 | O35: =EPS!O24 -> 1.2311013 | P35: =EPS!P24 -> 1.2086932 | Q35: =EPS!Q24 -> 1.0620798 | R35: =EPS!R24 -> 1.0363805 | ... AC35: =EPS!AC24 -> 2.8664929 | AE35: =EPS!#REF! -> #REF! | AF35: =EPS!#REF! -> #REF! | AG35: =EPS!#REF! -> #REF! | AH35: =EPS!#REF! -> #REF! | AI35: =EPS!AE24 -> 5.6114444 | AJ35: =EPS!AF24 -> 5.5841942 | AK35: =EPS!AG24 -> 5.4389778 | AL35: =EPS!AH24 -> 5.1118581 | AM35: =EPS!AI24 -> 4.5574541 | AN35: =EPS!AJ24 -> 4.565008 | AO35: =EPS!AK24 -> 4.7831228 | AP35: =EPS!AL24 -> 5.2555449 | ... AX35: =EPS!AT24 -> 10.186772 | AZ35: =SUM(AX35/AT35)-1 -> 0.34231121
A37: X | B37: Balance Sheet | AS37: LTM | AZ37: Variance
B38: =B7 -> Fiscal Period | C38: =C7 -> 2018 | D38: =D7 -> 2019 | E38: =E7 -> 2020 | F38: =F7 -> 2021 | G38: =G7 -> 2022 | H38: =H7 -> 2023 | I38: =I7 -> 2024 | K38: =K7 -> 1Q21 | L38: =L7 -> 2Q21 | M38: =M7 -> 3Q21 | N38: =N7 -> 4Q21 | O38: =O7 -> 1Q22 | P38: =P7 -> 2Q22 | Q38: =Q7 -> 3Q22 | R38: =R7 -> 4Q22 | ... AC38: =AC7 -> 3Q25 | AE38: =AE7 -> #REF! | AF38: =AF7 -> 1Q21 | AG38: =AG7 -> 2Q21 | AH38: =AH7 -> 3Q21 | AI38: =AI7 -> 4Q21 | AJ38: =AJ7 -> 1Q22 | AK38: =AK7 -> 2Q22 | AL38: =AL7 -> 3Q22 | ... AX38: =AX7 -> 3Q25
B39: =B8 -> Fiscal Period End Date | C39: =C8 -> 43465 | D39: =D8 -> 43830 | E39: =E8 -> 44196 | F39: =F8 -> 44561 | G39: =G8 -> 44926 | H39: =H8 -> 45291 | I39: =I8 -> 45657 | K39: =K8 -> 44286 | L39: =L8 -> 44377 | M39: =M8 -> 44469 | N39: =N8 -> 44561 | O39: =O8 -> 44651 | P39: =P8 -> 44742 | Q39: =Q8 -> 44834 | R39: =R8 -> 44926 | ... AC39: =AC8 -> 45930 | AE39: =AE8 -> #REF! | AF39: =AF8 -> 44286 | AG39: =AG8 -> 44377 | AH39: =AH8 -> 44469 | AI39: =AI8 -> 44561 | AJ39: =AJ8 -> 44651 | AK39: =AK8 -> 44742 | AL39: =AL8 -> 44834 | ... AX39: =AX8 -> 45930
B41: Current Assets
B42: Cash and Cash Equivalents | C42: 16701 | D42: 18498 | E42: 26465 | F42: 20945 | G42: 21879 | H42: 24048 | I42: 23466 | K42: 26622 | L42: 23630 | M42: 23719 | N42: =F42 -> 20945 | O42: 20886 | P42: 17936 | Q42: 21984 | R42: =G42 -> 21879 | S42: 25924 | T42: 25929 | U42: 30702 | V42: =H42 -> 24048 | W42: 24493 | X42: 27225 | Y42: 19959 | Z42: =I42 -> 23466 | AA42: 23264 | AB42: 21036 | AC42: 23090 | AE42: =#REF! -> #REF! | AF42: =K42 -> 26622 | AG42: =L42 -> 23630 | AH42: =M42 -> 23719 | AI42: =N42 -> 20945 | AJ42: =O42 -> 20886 | AK42: =P42 -> 17936 | AL42: =Q42 -> 21984 | AM42: =R42 -> 21879 | ... AX42: =AC42 -> 23090 | AZ42: =SUM(AX42/AT42)-1 -> 0.15687159
B43: Marketable securities | C43: 92439 | D43: 101177 | E43: 110229 | F43: 118704 | G43: 91883 | H43: 86868 | I43: 72191 | K43: 108482 | L43: 112233 | M43: 118284 | N43: =F43 -> 118704 | O43: 113084 | P43: 107061 | Q43: 94275 | R43: =G43 -> 91883 | S43: 89178 | T43: 92403 | U43: 89233 | V43: =H43 -> 86868 | W43: 83597 | X43: 73500 | Y43: 73271 | Z43: =I43 -> 72191 | AA43: 72064 | AB43: 74112 | AC43: 75406 | AE43: =#REF! -> #REF! | AF43: =K43 -> 108482 | AG43: =L43 -> 112233 | AH43: =M43 -> 118284 | AI43: =N43 -> 118704 | AJ43: =O43 -> 113084 | AK43: =P43 -> 107061 | AL43: =Q43 -> 94275 | AM43: =R43 -> 91883 | ... AX43: =AC43 -> 75406 | AZ43: =SUM(AX43/AT43)-1 -> 0.029138404
B44: Accounts Receivables | C44: 20838 | D44: 25326 | E44: 30930 | F44: 39304 | G44: 40258 | H44: 47964 | I44: 52340 | K44: 28006 | L44: 31967 | M44: 34047 | N44: =F44 -> 39304 | O44: 34703 | P44: 35707 | Q44: 34697 | R44: =G44 -> 40258 | S44: 36036 | T44: 38804 | U44: 41020 | V44: =H44 -> 47964 | W44: 44552 | X44: 47087 | Y44: 49104 | Z44: =I44 -> 52340 | AA44: 51000 | AB44: 55048 | AC44: 57148 | AE44: =#REF! -> #REF! | AF44: =K44 -> 28006 | AG44: =L44 -> 31967 | AH44: =M44 -> 34047 | AI44: =N44 -> 39304 | AJ44: =O44 -> 34703 | AK44: =P44 -> 35707 | AL44: =Q44 -> 34697 | AM44: =R44 -> 40258 | ... AX44: =AC44 -> 57148 | AZ44: =SUM(AX44/AT44)-1 -> 0.16381558
B45: Other Current Assets | C45: =4236+1107+355 -> 5698 | D45: =2166+999+4412 -> 7577 | E45: =454+728+5490 -> 6672 | F45: =1170+8020 -> 9190 | G45: =8105+2670 -> 10775 | H45: 12650 | I45: 15714 | K45: =493+888+7646 -> 9027 | L45: =6076+884+907 -> 7867 | M45: =1278+753+6029 -> 8060 | N45: =F45 -> 9190 | O45: =6892+919+1369 -> 9180 | P45: =8321+1980+1366 -> 11667 | Q45: =10518+3156+1479 -> 15153 | R45: =G45 -> 10775 | S45: =8532+2315 -> 10847 | T45: =9421+2231 -> 11652 | U45: =12398+2957 -> 15355 | V45: =H45 -> 12650 | W45: 12829 | X45: 14183 | Y45: 15207 | Z45: =I45 -> 15714 | AA45: 15724 | AB45: 16020 | AC45: 18303 | AE45: =#REF! -> #REF! | AF45: =K45 -> 9027 | AG45: =L45 -> 7867 | AH45: =M45 -> 8060 | AI45: =N45 -> 9190 | AJ45: =O45 -> 9180 | AK45: =P45 -> 11667 | AL45: =Q45 -> 15153 | AM45: =R45 -> 10775 | ... AX45: =AC45 -> 18303 | AZ45: =SUM(AX45/AT45)-1 -> 0.20359045
B46: Total Current Assets | C46: =SUM(C42:C45) -> 135676 | D46: =SUM(D42:D45) -> 152578 | E46: =SUM(E42:E45) -> 174296 | F46: =SUM(F42:F45) -> 188143 | G46: =SUM(G42:G45) -> 164795 | H46: =SUM(H42:H45) -> 171530 | I46: =SUM(I42:I45) -> 163711 | K46: =SUM(K42:K45) -> 172137 | L46: =SUM(L42:L45) -> 175697 | M46: =SUM(M42:M45) -> 184110 | N46: =SUM(N42:N45) -> 188143 | O46: =SUM(O42:O45) -> 177853 | P46: =SUM(P42:P45) -> 172371 | Q46: =SUM(Q42:Q45) -> 166109 | R46: =SUM(R42:R45) -> 164795 | ... AC46: =SUM(AC42:AC45) -> 173947 | AE46: =SUM(AE42:AE45) -> #REF! | AF46: =SUM(AF42:AF45) -> 172137 | AG46: =SUM(AG42:AG45) -> 175697 | AH46: =SUM(AH42:AH45) -> 184110 | AI46: =SUM(AI42:AI45) -> 188143 | AJ46: =SUM(AJ42:AJ45) -> 177853 | AK46: =SUM(AK42:AK45) -> 172371 | AL46: =SUM(AL42:AL45) -> 166109 | ... AX46: =SUM(AX42:AX45) -> 173947 | AZ46: =SUM(AX46/AT46)-1 -> 0.10413797
B48: Non-Current Assets
B49: Non-marketable securities | C49: 13859 | D49: 13078 | E49: 20703 | F49: 29549 | G49: 30492 | H49: 31008 | I49: 37982 | K49: 25294 | L49: 25532 | M49: 26101 | N49: =F49 -> 29549 | O49: 30544 | P49: 30665 | Q49: 30419 | R49: =G49 -> 30492 | S49: 31213 | T49: 31224 | U49: 30907 | V49: =H49 -> 31008 | W49: 33994 | X49: 34172 | Y49: 36177 | Z49: =I49 -> 37982 | AA49: 51029 | AB49: 52574 | AC49: 63800 | AE49: =#REF! -> #REF! | AF49: =K49 -> 25294 | AG49: =L49 -> 25532 | AH49: =M49 -> 26101 | AI49: =N49 -> 29549 | AJ49: =O49 -> 30544 | AK49: =P49 -> 30665 | AL49: =Q49 -> 30419 | AM49: =R49 -> 30492 | ... AX49: =AC49 -> 63800 | AZ49: =SUM(AX49/AT49)-1 -> 0.76355143
B50: Deferred income taxes | C50: 737 | D50: 721 | E50: 1084 | F50: 1284 | G50: 5261 | H50: 12169 | I50: 17180 | K50: 1129 | L50: 1153 | M50: 1195 | N50: =F50 -> 1284 | O50: 1388 | P50: 1490 | Q50: 2991 | R50: =G50 -> 5261 | S50: 6885 | T50: 9357 | U50: 10983 | V50: =H50 -> 12169 | W50: 11687 | X50: 14958 | Y50: 15915 | Z50: =I50 -> 17180 | AA50: 18386 | AB50: 19289 | AC50: 10331 | AE50: =#REF! -> #REF! | AF50: =K50 -> 1129 | AG50: =L50 -> 1153 | AH50: =M50 -> 1195 | AI50: =N50 -> 1284 | AJ50: =O50 -> 1388 | AK50: =P50 -> 1490 | AL50: =Q50 -> 2991 | AM50: =R50 -> 5261 | ... AX50: =AC50 -> 10331 | AZ50: =SUM(AX50/AT50)-1 -> -0.35086396
B51: Property and equipment, net | C51: 59719 | D51: 73646 | E51: 84749 | F51: 97599 | G51: 112668 | H51: 134345 | I51: 171036 | K51: 87606 | L51: 91697 | M51: 94631 | N51: =F51 -> 97599 | O51: 104218 | P51: 106223 | Q51: 108363 | R51: =G51 -> 112668 | S51: 117560 | T51: 121208 | U51: 125705 | V51: =H51 -> 134345 | W51: 143182 | X51: 151155 | Y51: 161270 | Z51: =I51 -> 171036 | AA51: 185062 | AB51: 203231 | AC51: 223787 | AE51: =#REF! -> #REF! | AF51: =K51 -> 87606 | AG51: =L51 -> 91697 | AH51: =M51 -> 94631 | AI51: =N51 -> 97599 | AJ51: =O51 -> 104218 | AK51: =P51 -> 106223 | AL51: =Q51 -> 108363 | AM51: =R51 -> 112668 | ... AX51: =AC51 -> 223787 | AZ51: =SUM(AX51/AT51)-1 -> 0.38765424
...

Sheet EPS
B2: Alphabet Inc. (NASDAQ: GOOG)
B3: EPS Build-Up
B4: ($ in Bns, Including Shares)
B6: Stock Split Converter | C6: 1
B7: Stock Split Amount | C7: 20
B8: Stock Split End Period | C8: 2Q22
B10: Net Income Per Share | G10: FYE | O10: Quarterly | Y10: Quarterly | AO10: LTM | AP10: LTM
B11: Fiscal Period | C11: 2018 | D11: 2019 | E11: 2020 | F11: 2021 | G11: 2022 | H11: 2023 | I11: 2024 | K11: 1Q21 | L11: 2Q21 | M11: 3Q21 | N11: 4Q21 | O11: 1Q22 | P11: 2Q22 | Q11: 3Q22 | R11: 4Q22 | S11: 1Q23 | T11: 2Q23 | U11: 3Q23 | V11: 4Q23 | W11: 1Q24 | X11: 2Q24 | Y11: 3Q24 | Z11: 4Q24 | AA11: 1Q25 | AB11: 2Q25 | AC11: 3Q25 | AE11: =N11 -> 4Q21 | AF11: =O11 -> 1Q22 | AG11: =P11 -> 2Q22 | AH11: =Q11 -> 3Q22 | AI11: =R11 -> 4Q22 | AJ11: =S11 -> 1Q23 | AK11: =T11 -> 2Q23 | AL11: =U11 -> 3Q23 | ... AT11: =AC11 -> 3Q25
B12: Fiscal Period End Date | C12: 43465 | D12: 43830 | E12: 44196 | F12: 44561 | G12: 44926 | H12: 45291 | I12: 45657 | K12: 44289 | L12: 44380 | M12: 44471 | N12: 44561 | O12: 44653 | P12: 44744 | Q12: 44835 | R12: 44926 | S12: 45017 | T12: 45108 | U12: 45199 | V12: 45291 | W12: 45381 | X12: 45472 | Y12: 45563 | Z12: 45657 | AA12: 45745 | AB12: 45836 | AC12: 45927 | AE12: =N12 -> 44561 | AF12: =O12 -> 44653 | AG12: =P12 -> 44744 | AH12: =Q12 -> 44835 | AI12: =R12 -> 44926 | AJ12: =S12 -> 45017 | AK12: =T12 -> 45108 | AL12: =U12 -> 45199 | ... AT12: =AC12 -> 45927
A14: X | B14: Consolidated Basic EPS
B16: Consolidated Allocation of undistributed earnings | C16: =C29+C35+C41 -> 30736 | D16: =D29+D35+D41 -> 34343 | E16: =E29+E35+E41 -> 40269 | F16: =F29+F35+F41 -> 76033 | G16: =G29+G35+G41 -> 59972 | H16: =H29+H35+H41 -> 73795 | I16: =I29+I35+I41 -> 100118 | K16: =K29+K35+K41 -> 17930 | L16: =L29+L35+L41 -> 18525 | M16: =M29+M35+M41 -> 18936 | N16: =N29+N35+N41 -> 20642 | O16: =O29+O35+O41 -> 16436 | P16: =P29+P35+P41 -> 16002 | Q16: =Q29+Q35+Q41 -> 13910 | R16: =R29+R35+R41 -> 13624 | ... AC16: =AC29+AC35+AC41 -> 34979 | AE16: =AE29+AE35+AE41 -> 76033 | AF16: =AF29+AF35+AF41 -> 74539 | AG16: =AG29+AG35+AG41 -> 72016 | AH16: =AH29+AH35+AH41 -> 66990 | AI16: =AI29+AI35+AI41 -> 59972 | AJ16: =AJ29+AJ35+AJ41 -> 58587 | AK16: =AK29+AK35+AK41 -> 60953 | AL16: =AL29+AL35+AL41 -> 66732 | ... AT16: =AT29+AT35+AT41 -> 124251
B17: Consolidated Basic Shares | C17: =IF($C$6=1,C30+C35+C41,C31+C37+C43) -> 23506.96 | D17: =IF($C$6=1,D30+D35+D41,D31+D37+D43) -> 25485.04 | E17: =IF($C$6=1,E30+E35+E41,E31+E37+E43) -> 28532.3 | F17: =IF($C$6=1,F30+F36+F42,F31+F37+F43) -> 13353 | G17: =IF($C$6=1,G30+G36+G42,G31+G37+G43) -> 13063 | H17: =IF($C$6=1,H30+H36+H42,H31+H37+H43) -> 12630 | I17: =IF($C$6=1,I30+I36+I42,I31+I37+I43) -> 12319 | K17: =IF($C$6=1,K30+K36+K42,K31+K37+K43) -> 13464.4 | L17: =IF($C$6=1,L30+L36+L42,L31+L37+L43) -> 13379.16 | M17: =IF($C$6=1,M30+M36+M42,M31+M37+M43) -> 13315.16 | N17: =IF($C$6=1,N30+N36+N42,N31+N37+N43) -> 13353 | O17: =IF($C$6=1,O30+O36+O42,O31+O37+O43) -> 13203.42 | P17: =IF($C$6=1,P30+P36+P42,P31+P37+P43) -> 13133 | Q17: =IF($C$6=1,Q30+Q36+Q42,Q31+Q37+Q43) -> 13018 | R17: =IF($C$6=1,R30+R36+R42,R31+R37+R43) -> 13063 | ... AC17: =IF($C$6=1,AC30+AC36+AC42,AC31+AC37+AC43) -> 12086 | AE17: =IF($C$6=1,AE30+AE36+AE42,AE31+AE37+AE43) -> 13353 | AF17: =IF($C$6=1,AF30+AF36+AF42,AF31+AF37+AF43) -> 13203.42 | AG17: =IF($C$6=1,AG30+AG36+AG42,AG31+AG37+AG43) -> 13133 | AH17: =IF($C$6=1,AH30+AH36+AH42,AH31+AH37+AH43) -> 13018 | AI17: =IF($C$6=1,AI30+AI36+AI42,AI31+AI37+AI43) -> 13063 | AJ17: =IF($C$6=1,AJ30+AJ36+AJ42,AJ31+AJ37+AJ43) -> 12781 | AK17: =IF($C$6=1,AK30+AK36+AK42,AK31+AK37+AK43) -> 12668 | AL17: =IF($C$6=1,AL30+AL36+AL42,AL31+AL37+AL43) -> 12581 | ... AT17: =IF($C$6=1,AT30+AT36+AT42,AT31+AT37+AT43) -> 12086
B18: Consolidated Basic EPS | C18: =C16/C17 -> 1.3075276 | D18: =D16/D17 -> 1.3475749 | E18: =E16/E17 -> 1.4113478 | F18: =F16/F17 -> 5.6940762 | G18: =G16/G17 -> 4.5909822 | H18: =H16/H17 -> 5.8428345 | I18: =I16/I17 -> 8.1271207 | K18: =K16/K17 -> 1.3316598 | L18: =L16/L17 -> 1.3846161 | M18: =M16/M17 -> 1.4221384 | N18: =N16/N17 -> 1.5458698 | O18: =O16/O17 -> 1.244829 | P18: =P16/P17 -> 1.2184573 | Q18: =Q16/Q17 -> 1.0685205 | R18: =R16/R17 -> 1.0429457 | ... AC18: =AC16/AC17 -> 2.8941751 | AE18: =AE16/AE17 -> 5.6940762 | AF18: =AF16/AF17 -> 5.6454313 | AG18: =AG16/AG17 -> 5.483591 | AH18: =AH16/AH17 -> 5.1459518 | AI18: =AI16/AI17 -> 4.5909822 | AJ18: =AJ16/AJ17 -> 4.5839136 | AK18: =AK16/AK17 -> 4.8115725 | AL18: =AL16/AL17 -> 5.3041889 | ... AT18: =AT16/AT17 -> 10.280573
A20: X | B20: Consolidated Fully Diluted EPS
B22: Consolidated Allocation of undistributed earnings | C22: =+C49+C58+C64 -> 32784 | D22: =+D49+D58+D64 -> 36630 | E22: =+E49+E58+E64 -> 42976 | F22: =+F49+F58+F64 -> 81130 | G22: =+G49+G58+G64 -> 64014 | H22: =+H49+H58+H64 -> 78882 | I22: =+I49+I58+I64 -> 107090 | K22: =+K49+K58+K64 -> 19135 | L22: =+L49+L58+L64 -> 19771 | M22: =+M49+M58+M64 -> 20207 | N22: =+N49+N58+N64 -> 22017 | O22: =+O49+O58+O64 -> 17533 | P22: =+P49+P58+P64 -> 17074 | Q22: =+Q49+Q58+Q64 -> 14850 | R22: =+R49+R58+R64 -> 14557 | ... AC22: =+AC49+AC58+AC64 -> 37402 | AE22: =+AE49+AE58+AE64 -> 81130 | AF22: =+AF49+AF58+AF64 -> 79528 | AG22: =+AG49+AG58+AG64 -> 76831 | AH22: =+AH49+AH58+AH64 -> 71474 | AI22: =+AI49+AI58+AI64 -> 64014 | AJ22: =+AJ49+AJ58+AJ64 -> 62568 | AK22: =+AK49+AK58+AK64 -> 65127 | AL22: =+AL49+AL58+AL64 -> 71323 | ... AT22: =+AT49+AT58+AT64 -> 132917
B23: Consolidated Fully Diluted Shares | C23: =+C50+C59+C65 -> 15002.98 | D23: =+D50+D59+D65 -> 14901.66 | E23: =+E50+E59+E65 -> 14664.2 | F23: =+F50+F59+F65 -> 14462.08 | G23: =+G50+G59+G65 -> 15870 | H23: =+H50+H59+H65 -> 15347 | I23: =+I50+I59+I65 -> 15745 | K23: =+K50+K59+K65 -> 14558.22 | L23: =+L50+L59+L65 -> 14506.08 | M23: =+M50+M59+M65 -> 14438.46 | N23: =+N50+N59+N65 -> 14458.2 | O23: =+O50+O59+O65 -> 14241.72 | P23: =+P50+P59+P65 -> 14126 | Q23: =+Q50+Q59+Q65 -> 13982 | R23: =+R50+R59+R65 -> 14046 | ... AC23: =+AC50+AC59+AC65 -> 13048 | AE23: =+AE50+AE59+AE65 -> 14457.953 | AF23: =+AF50+AF59+AF65 -> 14241.625 | AG23: =+AG50+AG59+AG65 -> 14126 | AH23: =+AH50+AH59+AH65 -> 13982 | AI23: =+AI50+AI59+AI65 -> 14046 | AJ23: =+AJ50+AJ59+AJ65 -> 13706 | AK23: =+AK50+AK59+AK65 -> 13616 | AL23: =+AL50+AL59+AL65 -> 13571 | ... AT23: =+AT50+AT59+AT65 -> 13048
B24: Consolidated Basic EPS | C24: =C22/C23 -> 2.1851659 | D24: =D22/D23 -> 2.4581154 | E24: =E22/E23 -> 2.9306747 | F24: =F22/F23 -> 5.6098431 | G24: =G22/G23 -> 4.0336484 | H24: =H22/H23 -> 5.139897 | I24: =I22/I23 -> 6.8015243 | K24: =K22/K23 -> 1.3143777 | L24: =L22/L23 -> 1.3629457 | M24: =M22/M23 -> 1.399526 | N24: =N22/N23 -> 1.5228037 | O24: =O22/O23 -> 1.2311013 | P24: =P22/P23 -> 1.2086932 | Q24: =Q22/Q23 -> 1.0620798 | R24: =R22/R23 -> 1.0363805 | ... AC24: =AC22/AC23 -> 2.8664929 | AE24: =AE22/AE23 -> 5.6114444 | AF24: =AF22/AF23 -> 5.5841942 | AG24: =AG22/AG23 -> 5.4389778 | AH24: =AH22/AH23 -> 5.1118581 | AI24: =AI22/AI23 -> 4.5574541 | AJ24: =AJ22/AJ23 -> 4.565008 | AK24: =AK22/AK23 -> 4.7831228 | AL24: =AL22/AL23 -> 5.2555449 | ... AT24: =AT22/AT23 -> 10.186772
A26: X | B26: Basic EPS Per Share Class
B28: Class A
B29: Allocation of undistributed earnings | C29: 13200 | D29: 14846 | E29: 17733 | F29: 34200 | G29: 27518 | H29: 34601 | I29: 47594 | K29: 8011 | L29: 8321 | M29: 8548 | N29: =SUM(F29-SUM(K29:M29)) -> 9320 | O29: 7481 | P29: 7329 | Q29: 6393 | R29: =SUM(G29-SUM(O29:Q29)) -> 6315 | S29: 7006 | T29: 8600 | U29: 9271 | V29: =SUM(H29-SUM(S29:U29)) -> 9724 | W29: 11213 | X29: 11219 | Y29: 12521 | Z29: =SUM(I29-SUM(W29:Y29)) -> 12641 | AA29: 16534 | AB29: 13536 | AC29: 16839 | AE29: =SUM(K29:N29) -> 34200 | AF29: =SUM(L29:O29) -> 33670 | AG29: =SUM(M29:P29) -> 32678 | AH29: =SUM(N29:Q29) -> 30523 | AI29: =SUM(O29:R29) -> 27518 | AJ29: =SUM(P29:S29) -> 27043 | AK29: =SUM(Q29:T29) -> 28314 | AL29: =SUM(R29:U29) -> 31192 | ... AT29: =SUM(Z29:AC29) -> 59550
B30: Stock Split Adjusted Basic Shares | C30: =IF($C$6=1,C31*20,C31) -> 5970.96 | D30: =IF($C$6=1,D31*20,D31) -> 5988.04 | E30: =IF($C$6=1,E31*20,E31) -> 5996.3 | F30: =IF($C$6=1,F31*20,F31) -> 6006.2 | G30: =G31 -> 5994 | H30: =H31 -> 5922 | I30: =I31 -> 5855 | K30: =IF($C$6=1,K31*20,K31) -> 6016 | L30: =IF($C$6=1,L31*20,L31) -> 6009.7 | M30: =IF($C$6=1,M31*20,M31) -> 6010.38 | N30: =IF($C$6=1,N31*20,N31) -> 6006.2 | O30: =IF($C$6=1,O31*20,O31) -> 6009.56 | P30: =P31 -> 6015 | Q30: =Q31 -> 5983 | R30: =R31 -> 5994 | S30: =S31 -> 5949 | T30: =T31 -> 5931 | U30: =U31 -> 5924 | V30: =V31 -> 5922 | W30: =W31 -> 5883 | ... AC30: =AC31 -> 5818 | AE30: =N30 -> 6006.2 | AF30: =O30 -> 6009.56 | AG30: =P30 -> 6015 | AH30: =Q30 -> 5983 | AI30: =R30 -> 5994 | AJ30: =S30 -> 5949 | AK30: =T30 -> 5931 | AL30: =U30 -> 5924 | ... AT30: =AC30 -> 5818
B31: Unadjusted Basic Shares | C31: 298.548 | D31: 299.402 | E31: 299.815 | F31: 300.31 | G31: 5994 | H31: 5922 | I31: 5855 | K31: 300.8 | L31: 300.485 | M31: 300.519 | N31: =F31 -> 300.31 | O31: 300.478 | P31: 6015 | Q31: 5983 | R31: =G31 -> 5994 | S31: 5949 | T31: 5931 | U31: 5924 | V31: =H31 -> 5922 | W31: 5883 | X31: 5862 | Y31: 5850 | Z31: =I31 -> 5855 | AA31: 5831 | AB31: 5819 | AC31: 5818 | AE31: =N31 -> 300.31 | AF31: =O31 -> 300.478 | AG31: =P31 -> 6015 | AH31: =Q31 -> 5983 | AI31: =R31 -> 5994 | AJ31: =S31 -> 5949 | AK31: =T31 -> 5931 | AL31: =U31 -> 5924 | ... AT31: =AC31 -> 5818
B32: Class A Basic EPS | C32: =IF($C$6=1, C29/C30,C29/C31) -> 2.2106998 | D32: =IF($C$6=1, D29/D30,D29/D31) -> 2.4792754 | E32: =IF($C$6=1, E29/E30,E29/E31) -> 2.9573237 | F32: =IF($C$6=1, F29/F30,F29/F31) -> 5.6941161 | G32: =IF($C$6=1, G29/G30,G29/G31) -> 4.5909243 | H32: =IF($C$6=1, H29/H30,H29/H31) -> 5.8427896 | I32: =IF($C$6=1, I29/I30,I29/I31) -> 8.1287788 | K32: =IF($C$6=1, K29/K30,K29/K31) -> 1.3316157 | L32: =IF($C$6=1, L29/L30,L29/L31) -> 1.3845949 | M32: =IF($C$6=1, M29/M30,M29/M31) -> 1.4222062 | N32: =IF($C$6=1, N29/N30,N29/N31) -> 1.5517299 | O32: =IF($C$6=1, O29/O30,O29/O31) -> 1.2448499 | P32: =IF($C$6=1, P29/P30,P29/P31) -> 1.2184539 | Q32: =IF($C$6=1, Q29/Q30,Q29/Q31) -> 1.0685275 | R32: =IF($C$6=1, R29/R30,R29/R31) -> 1.0535536 | ... AC32: =IF($C$6=1, AC29/AC30,AC29/AC31) -> 2.8942936 | AE32: =IF($C$6=1, AE29/AE30,AE29/AE31) -> 5.6941161 | AF32: =IF($C$6=1, AF29/AF30,AF29/AF31) -> 5.6027396 | AG32: =IF($C$6=1, AG29/AG30,AG29/AG31) -> 5.4327515 | AH32: =IF($C$6=1, AH29/AH30,AH29/AH31) -> 5.1016213 | AI32: =IF($C$6=1, AI29/AI30,AI29/AI31) -> 4.5909243 | AJ32: =IF($C$6=1, AJ29/AJ30,AJ29/AJ31) -> 4.545806 | AK32: =IF($C$6=1, AK29/AK30,AK29/AK31) -> 4.7738998 | AL32: =IF($C$6=1, AL29/AL30,AL29/AL31) -> 5.2653612 | ... AT32: =IF($C$6=1, AT29/AT30,AT29/AT31) -> 10.235476
B34: Class B
B35: Allocation of undistributed earnings | C35: 2072 | D35: 2307 | E35: 2732 | F35: 5174 | G35: 4072 | H35: 5124 | I35: 7039 | K35: 1221 | L35: 1265 | M35: 1291 | N35: =SUM(F35-SUM(K35:M35)) -> 1397 | O35: 1109 | P35: 1081 | Q35: 946 | R35: =SUM(G35-SUM(O35:Q35)) -> 936 | S35: 1040 | T35: 1275 | U35: 1369 | V35: =SUM(H35-SUM(S35:U35)) -> 1440 | W35: 1656 | X35: 1657 | Y35: 1851 | Z35: =SUM(I35-SUM(W35:Y35)) -> 1875 | AA35: 2435 | AB35: 1981 | AC35: 2445 | AE35: =SUM(K35:N35) -> 5174 | AF35: =SUM(L35:O35) -> 5062 | AG35: =SUM(M35:P35) -> 4878 | AH35: =SUM(N35:Q35) -> 4533 | AI35: =SUM(O35:R35) -> 4072 | AJ35: =SUM(P35:S35) -> 4003 | AK35: =SUM(Q35:T35) -> 4197 | AL35: =SUM(R35:U35) -> 4620 | ... AT35: =SUM(Z35:AC35) -> 8736
B36: Stock Split Adjusted Basic Shares | C36: =IF($C$6=1,C37*20,C37) -> 937.28 | D36: =IF($C$6=1,D37*20,D37) -> 930.54 | E36: =IF($C$6=1,E37*20,E37) -> 923.64 | F36: =IF($C$6=1,F37*20,F37) -> 908.6 | G36: =G37 -> 887 | H36: =H37 -> 877 | I36: =I37 -> 866 | K36: =IF($C$6=1,K37*20,K37) -> 916.8 | L36: =IF($C$6=1,L37*20,L37) -> 913.84 | M36: =IF($C$6=1,M37*20,M37) -> 908.08 | N36: =IF($C$6=1,N37*20,N37) -> 908.6 | O36: =IF($C$6=1,O37*20,O37) -> 890.7 | P36: =P37 -> 887 | Q36: =Q37 -> 885 | R36: =R37 -> 887 | S36: =S37 -> 883 | T36: =T37 -> 879 | U36: =U37 -> 875 | V36: =V37 -> 877 | W36: =W37 -> 869 | ... AC36: =AC37 -> 845 | AE36: =N36 -> 908.6 | AF36: =O36 -> 890.7 | AG36: =P36 -> 887 | AH36: =Q36 -> 885 | AI36: =R36 -> 887 | AJ36: =S36 -> 883 | AK36: =T36 -> 879 | AL36: =U36 -> 875 | ... AT36: =AC36 -> 845
B37: Unadjusted Basic Shares | C37: 46.864 | D37: 46.527 | E37: 46.182 | F37: 45.43 | G37: 887 | H37: 877 | I37: 866 | K37: 45.84 | L37: 45.692 | M37: 45.404 | N37: =F37 -> 45.43 | O37: 44.535 | P37: 887 | Q37: 885 | R37: =G37 -> 887 | S37: 883 | T37: 879 | U37: 875 | V37: =H37 -> 877 | W37: 869 | X37: 866 | Y37: 865 | Z37: =I37 -> 866 | AA37: 859 | AB37: 852 | AC37: 845 | AE37: =N37 -> 45.43 | AF37: =O37 -> 44.535 | AG37: =P37 -> 887 | AH37: =Q37 -> 885 | AI37: =R37 -> 887 | AJ37: =S37 -> 883 | AK37: =T37 -> 879 | AL37: =U37 -> 875 | ... AT37: =AC37 -> 845
B38: Class B Basic EPS | C38: =IF($C$6=1, C35/C36,C35/C37) -> 2.2106521 | D38: =IF($C$6=1, D35/D36,D35/D37) -> 2.4792056 | E38: =IF($C$6=1, E35/E36,E35/E37) -> 2.9578624 | F38: =IF($C$6=1, F35/F36,F35/F37) -> 5.694475 | G38: =IF($C$6=1, G35/G36,G35/G37) -> 4.5907554 | H38: =IF($C$6=1, H35/H36,H35/H37) -> 5.8426454 | I38: =IF($C$6=1, I35/I36,I35/I37) -> 8.1281755 | K38: =IF($C$6=1, K35/K36,K35/K37) -> 1.3318063 | L38: =IF($C$6=1, L35/L36,L35/L37) -> 1.3842686 | M38: =IF($C$6=1, M35/M36,M35/M37) -> 1.4216809 | N38: =IF($C$6=1, N35/N36,N35/N37) -> 1.5375303 | O38: =IF($C$6=1, O35/O36,O35/O37) -> 1.2450881 | P38: =IF($C$6=1, P35/P36,P35/P37) -> 1.2187148 | Q38: =IF($C$6=1, Q35/Q36,Q35/Q37) -> 1.0689266 | R38: =IF($C$6=1, R35/R36,R35/R37) -> 1.0552424 | ... AC38: =IF($C$6=1, AC35/AC36,AC35/AC37) -> 2.8934911 | AE38: =IF($C$6=1, AE35/AE36,AE35/AE37) -> 5.694475 | AF38: =IF($C$6=1, AF35/AF36,AF35/AF37) -> 5.6831705 | AG38: =IF($C$6=1, AG35/AG36,AG35/AG37) -> 5.4994363 | AH38: =IF($C$6=1, AH35/AH36,AH35/AH37) -> 5.1220339 | AI38: =IF($C$6=1, AI35/AI36,AI35/AI37) -> 4.5907554 | AJ38: =IF($C$6=1, AJ35/AJ36,AJ35/AJ37) -> 4.5334088 | AK38: =IF($C$6=1, AK35/AK36,AK35/AK37) -> 4.774744 | AL38: =IF($C$6=1, AL35/AL36,AL35/AL37) -> 5.28 | ... AT38: =IF($C$6=1, AT35/AT36,AT35/AT37) -> 10.338462
B40: Class C
B41: Allocation of undistributed earnings | C41: 15464 | D41: 17190 | E41: 19804 | F41: 36659 | G41: 28382 | H41: 34070 | I41: 45485 | K41: 8698 | L41: 8939 | M41: 9097 | N41: =SUM(F41-SUM(K41:M41)) -> 9925 | O41: 7846 | P41: 7592 | Q41: 6571 | R41: =SUM(G41-SUM(O41:Q41)) -> 6373 | S41: 7005 | T41: 8493 | U41: 9049 | V41: =SUM(H41-SUM(S41:U41)) -> 9523 | W41: 10793 | X41: 10743 | Y41: 11929 | Z41: =SUM(I41-SUM(W41:Y41)) -> 12020 | AA41: 15571 | AB41: 12679 | AC41: 15695 | AE41: =SUM(K41:N41) -> 36659 | AF41: =SUM(L41:O41) -> 35807 | AG41: =SUM(M41:P41) -> 34460 | AH41: =SUM(N41:Q41) -> 31934 | AI41: =SUM(O41:R41) -> 28382 | AJ41: =SUM(P41:S41) -> 27541 | AK41: =SUM(Q41:T41) -> 28442 | AL41: =SUM(R41:U41) -> 30920 | ... AT41: =SUM(Z41:AC41) -> 55965
B42: Stock Split Adjusted Basic Shares | C42: =IF($C$6=1,C43*20,C43) -> 6994.56 | D42: =IF($C$6=1,D43*20,D43) -> 6933.34 | E42: =IF($C$6=1,E43*20,E43) -> 6696.38 | F42: =IF($C$6=1,F43*20,F43) -> 6438.2 | G42: =G43 -> 6182 | H42: =H43 -> 5831 | I42: =I43 -> 5598 | K42: =IF($C$6=1,K43*20,K43) -> 6531.6 | L42: =IF($C$6=1,L43*20,L43) -> 6455.62 | M42: =IF($C$6=1,M43*20,M43) -> 6396.7 | N42: =IF($C$6=1,N43*20,N43) -> 6438.2 | O42: =IF($C$6=1,O43*20,O43) -> 6303.16 | P42: =P43 -> 6231 | Q42: =Q43 -> 6150 | R42: =R43 -> 6182 | S42: =S43 -> 5949 | T42: =T43 -> 5858 | U42: =U43 -> 5782 | V42: =V43 -> 5831 | W42: =W43 -> 5663 | ... AC42: =AC43 -> 5423 | AE42: =N42 -> 6438.2 | AF42: =O42 -> 6303.16 | AG42: =P42 -> 6231 | AH42: =Q42 -> 6150 | AI42: =R42 -> 6182 | AJ42: =S42 -> 5949 | AK42: =T42 -> 5858 | AL42: =U42 -> 5782 | ... AT42: =AC42 -> 5423
B43: Unadjusted Basic Shares | C43: 349.728 | D43: 346.667 | E43: 334.819 | F43: 321.91 | G43: 6182 | H43: 5831 | I43: 5598 | K43: 326.58 | L43: 322.781 | M43: 319.835 | N43: =F43 -> 321.91 | O43: 315.158 | P43: 6231 | Q43: 6150 | R43: =G43 -> 6182 | S43: 5949 | T43: 5858 | U43: 5782 | V43: =H43 -> 5831 | W43: 5663 | X43: 5615 | Y43: 5575 | Z43: =I43 -> 5598 | AA43: 5493 | AB43: 5451 | AC43: 5423 | AE43: =N43 -> 321.91 | AF43: =O43 -> 315.158 | AG43: =P43 -> 6231 | AH43: =Q43 -> 6150 | AI43: =R43 -> 6182 | AJ43: =S43 -> 5949 | AK43: =T43 -> 5858 | AL43: =U43 -> 5782 | ... AT43: =AC43 -> 5423
B44: Class C Basic EPS | C44: =IF($C$6=1, C41/C42,C41/C43) -> 2.210861 | D44: =IF($C$6=1, D41/D42,D41/D43) -> 2.4793245 | E44: =IF($C$6=1, E41/E42,E41/E43) -> 2.9574188 | F44: =IF($C$6=1, F41/F42,F41/F43) -> 5.6939828 | G44: =IF($C$6=1, G41/G42,G41/G43) -> 4.5910709 | H44: =IF($C$6=1, H41/H42,H41/H43) -> 5.8429086 | I44: =IF($C$6=1, I41/I42,I41/I43) -> 8.1252233 | K44: =IF($C$6=1, K41/K42,K41/K43) -> 1.3316798 | L44: =IF($C$6=1, L41/L42,L41/L43) -> 1.384685 | M44: =IF($C$6=1, M41/M42,M41/M43) -> 1.4221395 | N44: =IF($C$6=1, N41/N42,N41/N43) -> 1.5415799 | O44: =IF($C$6=1, O41/O42,O41/O43) -> 1.2447725 | P44: =IF($C$6=1, P41/P42,P41/P43) -> 1.218424 | Q44: =IF($C$6=1, Q41/Q42,Q41/Q43) -> 1.0684553 | R44: =IF($C$6=1, R41/R42,R41/R43) -> 1.0308962 | ... AC44: =IF($C$6=1, AC41/AC42,AC41/AC43) -> 2.8941545 | AE44: =IF($C$6=1, AE41/AE42,AE41/AE43) -> 5.6939828 | AF44: =IF($C$6=1, AF41/AF42,AF41/AF43) -> 5.6808014 | AG44: =IF($C$6=1, AG41/AG42,AG41/AG43) -> 5.5304125 | AH44: =IF($C$6=1, AH41/AH42,AH41/AH43) -> 5.1925203 | AI44: =IF($C$6=1, AI41/AI42,AI41/AI43) -> 4.5910709 | AJ44: =IF($C$6=1, AJ41/AJ42,AJ41/AJ43) -> 4.6295176 | AK44: =IF($C$6=1, AK41/AK42,AK41/AK43) -> 4.8552407 | AL44: =IF($C$6=1, AL41/AL42,AL41/AL43) -> 5.3476306 | ... AT44: =IF($C$6=1, AT41/AT42,AT41/AT43) -> 10.319934
A46: X | B46: Fully Diluted EPS Per Share Class
B48: Class A
B49: Allocation of undistributed earnings | C49: 15126 | D49: 17027 | E49: 20285 | F49: 38793 | G49: 31360 | H49: 39438 | I49: 54113 | K49: 9113 | L49: 9437 | M49: 9683 | N49: =SUM(F49-SUM(K49:M49)) -> 10560 | O49: 8495 | P49: 8342 | Q49: 7294 | R49: =SUM(G49-SUM(O49:Q49)) -> 7229 | S49: 8019 | T49: 9800 | U49: 10544 | V49: =SUM(H49-SUM(S49:U49)) -> 11075 | W49: 12754 | X49: 12736 | Y49: 14237 | Z49: =SUM(I49-SUM(W49:Y49)) -> 14386 | AA49: 18813 | AB49: 15429 | AC49: 19113 | AE49: =SUM(K49:N49) -> 38793 | AF49: =SUM(L49:O49) -> 38175 | AG49: =SUM(M49:P49) -> 37080 | AH49: =SUM(N49:Q49) -> 34691 | AI49: =SUM(O49:R49) -> 31360 | AJ49: =SUM(P49:S49) -> 30884 | AK49: =SUM(Q49:T49) -> 32342 | AL49: =SUM(R49:U49) -> 35592 | ... AT49: =SUM(Z49:AC49) -> 67741
B50: Fully Diluted Shares | C50: =SUM(C51:C53) -> 6922.02 | D50: =SUM(D51:D53) -> 6926.84 | E50: =SUM(E51:E53) -> 6921.68 | F50: =SUM(F51:F53) -> 6915.1 | G50: =SUM(G51:G53) -> 6881 | H50: =SUM(H51:H53) -> 6799 | I50: =SUM(I51:I53) -> 6721 | K50: =SUM(K51:K53) -> 6933.16 | L50: =SUM(L51:L53) -> 6923.84 | M50: =SUM(M51:M53) -> 6918.74 | N50: =SUM(N51:N53) -> 6915.06 | O50: =SUM(O51:O53) -> 6900.36 | P50: =SUM(P51:P53) -> 6902 | Q50: =SUM(Q51:Q53) -> 6868 | R50: =SUM(R51:R53) -> 6881 | ... AC50: =SUM(AC51:AC53) -> 6663 | AE50: =SUM(AE51:AE53) -> 6914.813 | AF50: =SUM(AF51:AF53) -> 6900.265 | AG50: =SUM(AG51:AG53) -> 6902 | AH50: =SUM(AH51:AH53) -> 6868 | AI50: =SUM(AI51:AI53) -> 6881 | AJ50: =SUM(AJ51:AJ53) -> 6832 | AK50: =SUM(AK51:AK53) -> 6810 | AL50: =SUM(AL51:AL53) -> 6799 | ... AT50: =SUM(AT51:AT53) -> 6663
B51: Number of shares used in basic computation | C51: =IF($C$6=1,C30,C31) -> 5970.96 | D51: =IF($C$6=1,D30,D31) -> 5988.04 | E51: =IF($C$6=1,E30,E31) -> 5996.3 | F51: =IF($C$6=1,F30,F31) -> 6006.2 | G51: =IF($C$6=1,G30,G31) -> 5994 | H51: =IF($C$6=1,H30,H31) -> 5922 | I51: =IF($C$6=1,I30,I31) -> 5855 | K51: =IF($C$6=1,K30,K31) -> 6016 | L51: =IF($C$6=1,L30,L31) -> 6009.7 | M51: =IF($C$6=1,M30,M31) -> 6010.38 | N51: =IF($C$6=1,N30,N31) -> 6006.2 | O51: =IF($C$6=1,O30,O31) -> 6009.56 | P51: =IF($C$6=1,P30,P31) -> 6015 | Q51: =IF($C$6=1,Q30,Q31) -> 5983 | R51: =IF($C$6=1,R30,R31) -> 5994 | ... AC51: =IF($C$6=1,AC30,AC31) -> 5818 | AE51: =IF($C$6=1,AE30,AE31) -> 6006.2 | AF51: =IF($C$6=1,AF30,AF31) -> 6009.56 | AG51: =IF($C$6=1,AG30,AG31) -> 6015 | AH51: =IF($C$6=1,AH30,AH31) -> 5983 | AI51: =IF($C$6=1,AI30,AI31) -> 5994 | AJ51: =IF($C$6=1,AJ30,AJ31) -> 5949 | AK51: =IF($C$6=1,AK30,AK31) -> 5931 | AL51: =IF($C$6=1,AL30,AL31) -> 5924 | ... AT51: =IF($C$6=1,AT30,AT31) -> 5818
B52: Conversion of Class B to Class A common shares outstanding | C52: =IF($C$6=1,C36,C37) -> 937.28 | D52: =IF($C$6=1,D36,D37) -> 930.54 | E52: =IF($C$6=1,E36,E37) -> 923.64 | F52: =IF($C$6=1,F36,F37) -> 908.6 | G52: =IF($C$6=1,G36,G37) -> 887 | H52: =IF($C$6=1,H36,H37) -> 877 | I52: =IF($C$6=1,I36,I37) -> 866 | K52: =IF($C$6=1,K36,K37) -> 916.8 | L52: =IF($C$6=1,L36,L37) -> 913.84 | M52: =IF($C$6=1,M36,M37) -> 908.08 | N52: =IF($C$6=1,N36,N37) -> 908.6 | O52: =IF($C$6=1,O36,O37) -> 890.7 | P52: =IF($C$6=1,P36,P37) -> 887 | Q52: =IF($C$6=1,Q36,Q37) -> 885 | R52: =IF($C$6=1,R36,R37) -> 887 | ... AC52: =IF($C$6=1,AC36,AC37) -> 845 | AE52: =IF($C$6=1,AE36,AE37) -> 908.6 | AF52: =IF($C$6=1,AF36,AF37) -> 890.7 | AG52: =IF($C$6=1,AG36,AG37) -> 887 | AH52: =IF($C$6=1,AH36,AH37) -> 885 | AI52: =IF($C$6=1,AI36,AI37) -> 887 | AJ52: =IF($C$6=1,AJ36,AJ37) -> 883 | AK52: =IF($C$6=1,AK36,AK37) -> 879 | AL52: =IF($C$6=1,AL36,AL37) -> 875 | ... AT52: =IF($C$6=1,AT36,AT37) -> 845
B53: Adjusted RSUs and other contingently issuable shares | C53: =IF($C$6=1,C54*20,C54) -> 13.78 | D53: =IF($C$6=1,D54*20,D54) -> 8.26 | E53: =IF($C$6=1,E54*20,E54) -> 1.74 | F53: =IF($C$6=1,F54*20,F54) -> 0.3 | G53: =IF($C$6=1,G54*20,G54) -> 0 | H53: =IF($C$6=1,H54*20,H54) -> 0 | I53: =IF($C$6=1,I54*20,I54) -> 0 | K53: =IF($C$6=1,K54*20,K54) -> 0.36 | L53: =IF($C$6=1,L54*20,L54) -> 0.3 | M53: =IF($C$6=1,M54*20,M54) -> 0.28 | N53: =IF($C$6=1,N54*20,N54) -> 0.26 | O53: =IF($C$6=1,O54*20,O54) -> 0.1 | P53: =IF($C$6=1,P54*20,P54) -> 0 | Q53: =Q54 -> 0 | R53: =R54 -> 0 | S53: =S54 -> 0 | T53: =T54 -> 0 | U53: =U54 -> 0 | V53: =V54 -> 0 | W53: =W54 -> 0 | X53: =X54 -> 0 | ... AC53: =AC54 -> 0 | AE53: =AE54 -> 0.013 | AF53: =AF54 -> 0.005 | AG53: =AG54 -> 0 | AH53: =AH54 -> 0 | AI53: =AI54 -> 0 | AJ53: =AJ54 -> 0 | AK53: =AK54 -> 0 | AL53: =AL54 -> 0 | ... AT53: =AT54 -> 0
...

Sheet Revenue Drivers
B2: ='Historical Financials'!B2 -> Alphabet Inc. (NASDAQ: GOOG) | C2: FYE | G2: FYE | K2: Quarterly | S2: Quarterly | T2: Quarterly | AA2: LTM | AE2: LTM | AG2: LTM | AM2: Variance
B3: Segment Anaysis | C3: ='Historical Financials'!C7 -> 2018 | D3: ='Historical Financials'!D7 -> 2019 | E3: ='Historical Financials'!E7 -> 2020 | F3: ='Historical Financials'!F7 -> 2021 | G3: ='Historical Financials'!G7 -> 2022 | H3: ='Historical Financials'!H7 -> 2023 | I3: ='Historical Financials'!I7 -> 2024 | K3: ='Historical Financials'!O7 -> 1Q22 | L3: ='Historical Financials'!P7 -> 2Q22 | M3: ='Historical Financials'!Q7 -> 3Q22 | N3: ='Historical Financials'!R7 -> 4Q22 | O3: ='Historical Financials'!S7 -> 1Q23 | P3: ='Historical Financials'!T7 -> 2Q23 | Q3: ='Historical Financials'!U7 -> 3Q23 | R3: ='Historical Financials'!V7 -> 4Q23 | ... Y3: ='Historical Financials'!AC7 -> 3Q25 | AA3: =O3 -> 1Q23 | AB3: =P3 -> 2Q23 | AC3: =Q3 -> 3Q23 | AD3: =R3 -> 4Q23 | AE3: =S3 -> 1Q24 | AF3: =T3 -> 2Q24 | AG3: =U3 -> 3Q24 | AH3: =V3 -> 4Q24 | ... AK3: =Y3 -> 3Q25
B4: $ mm except per share | C4: ='Historical Financials'!C8 -> 43465 | D4: ='Historical Financials'!D8 -> 43830 | E4: ='Historical Financials'!E8 -> 44196 | F4: ='Historical Financials'!F8 -> 44561 | G4: ='Historical Financials'!G8 -> 44926 | H4: ='Historical Financials'!H8 -> 45291 | I4: ='Historical Financials'!I8 -> 45657 | K4: ='Historical Financials'!O8 -> 44651 | L4: ='Historical Financials'!P8 -> 44742 | M4: ='Historical Financials'!Q8 -> 44834 | N4: ='Historical Financials'!R8 -> 44926 | O4: ='Historical Financials'!S8 -> 45016 | P4: ='Historical Financials'!T8 -> 45107 | Q4: ='Historical Financials'!U8 -> 45199 | R4: ='Historical Financials'!V8 -> 45291 | ... Y4: ='Historical Financials'!AC8 -> 45930 | AA4: =O4 -> 45016 | AB4: =P4 -> 45107 | AC4: =Q4 -> 45199 | AD4: =R4 -> 45291 | AE4: =S4 -> 45382 | AF4: =T4 -> 45473 | AG4: =U4 -> 45565 | AH4: =V4 -> 45657 | ... AK4: =Y4 -> 45930
A6: X | B6: Offerings Drivers
B8: Disaggregated Revenues
B9: Google Services | C9: =+C19 -> 130524 | D9: =+D19 -> 151825 | E9: =+E19 -> 168635 | F9: =+F19 -> 237529 | G9: =+G19 -> 253528 | H9: =+H19 -> 272543 | I9: =+I19 -> 304930 | K9: =+K19 -> 61472 | L9: =+L19 -> 62841 | M9: =+M19 -> 61377 | N9: =+N19 -> 67838 | O9: =+O19 -> 61961 | P9: =+P19 -> 66285 | Q9: =+Q19 -> 67986 | R9: =+R19 -> 76311 | ... Y9: =+Y19 -> 87052 | AA9: =SUM(L9:O9) -> 254017 | AB9: =SUM(M9:P9) -> 257461 | AC9: =SUM(N9:Q9) -> 264070 | AD9: =SUM(O9:R9) -> 272543 | AE9: =SUM(P9:S9) -> 280980 | AF9: =SUM(Q9:T9) -> 288623 | AG9: =SUM(R9:U9) -> 297147 | AH9: =SUM(S9:V9) -> 304930 | ... AK9: =SUM(V9:Y9) -> 330953 | AM9: =SUM(AK9/AG9)-1 -> 0.11376861
B10: Google Cloud | C10: 5838 | D10: 8918 | E10: 13059 | F10: 19206 | G10: 26280 | H10: 33088 | I10: 43229 | K10: 5821 | L10: 6276 | M10: 6868 | N10: =SUM(G10-SUM(K10:M10)) -> 7315 | O10: 7454 | P10: 8031 | Q10: 8411 | R10: =SUM(H10-SUM(O10:Q10)) -> 9192 | S10: 9574 | T10: 10347 | U10: 11353 | V10: =SUM(I10-SUM(S10:U10)) -> 11955 | W10: 12260 | X10: 13624 | Y10: 15157 | AG10: =SUM(R10:U10) -> 40466 | AH10: =SUM(S10:V10) -> 43229 | AI10: =SUM(T10:W10) -> 45915 | AJ10: =SUM(U10:X10) -> 49192 | AK10: =SUM(V10:Y10) -> 52996 | AM10: =SUM(AK10/AG10)-1 -> 0.30964266
B11: Other Bets | C11: 595 | D11: 659 | E11: 657 | F11: 753 | G11: 1068 | H11: 1527 | I11: 1648 | K11: 440 | L11: 193 | M11: 209 | N11: =SUM(G11-SUM(K11:M11)) -> 226 | O11: 288 | P11: 285 | Q11: 297 | R11: =SUM(H11-SUM(O11:Q11)) -> 657 | S11: 495 | T11: 365 | U11: 388 | V11: =SUM(I11-SUM(S11:U11)) -> 400 | W11: 450 | X11: 373 | Y11: 344 | AG11: =SUM(R11:U11) -> 1905 | AH11: =SUM(S11:V11) -> 1648 | AI11: =SUM(T11:W11) -> 1603 | AJ11: =SUM(U11:X11) -> 1611 | AK11: =SUM(V11:Y11) -> 1567 | AM11: =SUM(AK11/AG11)-1 -> -0.17742782
B12: Hedging gains (losses) | C12: -138 | D12: 455 | E12: 176 | F12: 149 | G12: 1960 | H12: 236 | I12: 211 | K12: 278 | L12: 375 | M12: 638 | N12: =SUM(G12-SUM(K12:M12)) -> 669 | O12: 84 | P12: 3 | Q12: -1 | R12: =SUM(H12-SUM(O12:Q12)) -> 150 | S12: 72 | T12: 102 | U12: 17 | V12: =SUM(I12-SUM(S12:U12)) -> 20 | W12: 260 | X12: -112 | Y12: -207 | AG12: =SUM(R12:U12) -> 341 | AH12: =SUM(S12:V12) -> 211 | AI12: =SUM(T12:W12) -> 399 | AJ12: =SUM(U12:X12) -> 185 | AK12: =SUM(V12:Y12) -> -39 | AM12: =SUM(AK12/AG12)-1 -> -1.1143695
B13: Total Net Revenue | C13: =SUM(C9:C12) -> 136819 | D13: =SUM(D9:D12) -> 161857 | E13: =SUM(E9:E12) -> 182527 | F13: =SUM(F9:F12) -> 257637 | G13: =SUM(G9:G12) -> 282836 | H13: =SUM(H9:H12) -> 307394 | I13: =SUM(I9:I12) -> 350018 | K13: =SUM(K9:K12) -> 68011 | L13: =SUM(L9:L12) -> 69685 | M13: =SUM(M9:M12) -> 69092 | N13: =SUM(N9:N12) -> 76048 | O13: =SUM(O9:O12) -> 69787 | P13: =SUM(P9:P12) -> 74604 | Q13: =SUM(Q9:Q12) -> 76693 | R13: =SUM(R9:R12) -> 86310 | ... Y13: =SUM(Y9:Y12) -> 102346 | AA13: =SUM(AA9:AA12) -> 254017 | AB13: =SUM(AB9:AB12) -> 257461 | AC13: =SUM(AC9:AC12) -> 264070 | AD13: =SUM(AD9:AD12) -> 272543 | AE13: =SUM(AE9:AE12) -> 280980 | AF13: =SUM(AF9:AF12) -> 288623 | AG13: =SUM(AG9:AG12) -> 339859 | AH13: =SUM(AH9:AH12) -> 350018 | ... AK13: =SUM(AK9:AK12) -> 385477 | AM13: =SUM(AK13/AG13)-1 -> 0.13422625
B14: Variance Check | C14: =+C13-'Historical Financials'!C11 -> 0 | D14: =+D13-'Historical Financials'!D11 -> 0 | E14: =+E13-'Historical Financials'!E11 -> 0 | F14: =+F13-'Historical Financials'!F11 -> 0 | G14: =+G13-'Historical Financials'!G11 -> 0 | H14: =+H13-'Historical Financials'!H11 -> 0 | I14: =+I13-'Historical Financials'!I11 -> 0 | K14: =K13-'Historical Financials'!O11 -> 0 | L14: =L13-'Historical Financials'!P11 -> 0 | M14: =M13-'Historical Financials'!Q11 -> 0 | N14: =N13-'Historical Financials'!R11 -> 0 | O14: =O13-'Historical Financials'!S11 -> 0 | P14: =P13-'Historical Financials'!T11 -> 0 | Q14: =Q13-'Historical Financials'!U11 -> 0 | R14: =R13-'Historical Financials'!V11 -> 0 | ... Y14: =Y13-'Historical Financials'!AC11 -> 0 | AA14: =+AA13-'Historical Financials'!AN11 -> -30595 | AB14: =+AB13-'Historical Financials'!AO11 -> -32070 | AC14: =+AC13-'Historical Financials'!AP11 -> -33062 | AD14: =+AD13-'Historical Financials'!AQ11 -> -34851 | AE14: =+AE13-'Historical Financials'!AR11 -> -37166 | AF14: =+AF13-'Historical Financials'!AS11 -> -39661 | AG14: =+AG13-'Historical Financials'!AT11 -> 0 | AH14: =+AH13-'Historical Financials'!AU11 -> 0 | ... AJ14: =+AJ13-'Historical Financials'!AW11 -> 0 | AK14: =AK13-'Historical Financials'!AX11 -> 0
B16: Google Services
B17: Google Advertising | C17: =+C25 -> 116461 | D17: =+D25 -> 134811 | E17: =+E25 -> 146924 | F17: =+F25 -> 209497 | G17: =+G25 -> 224473 | H17: =+H25 -> 237855 | I17: =+I25 -> 264590 | K17: =+K25 -> 54661 | L17: =+L25 -> 56288 | M17: =+M25 -> 54482 | N17: =+N25 -> 59042 | O17: =+O25 -> 54548 | P17: =+P25 -> 58143 | Q17: =+Q25 -> 59647 | R17: =+R25 -> 65517 | ... Y17: =+Y25 -> 74182 | AA17: =SUM(L17:O17) -> 224360 | AB17: =SUM(M17:P17) -> 226215 | AC17: =SUM(N17:Q17) -> 231380 | AD17: =SUM(O17:R17) -> 237855 | AE17: =SUM(P17:S17) -> 244966 | AF17: =SUM(Q17:T17) -> 251439 | AG17: =SUM(R17:U17) -> 257646 | AH17: =SUM(S17:V17) -> 264590 | ... AK17: =SUM(V17:Y17) -> 284868 | AM17: =SUM(AK17/AG17)-1 -> 0.1056566
B18: Google subscriptions, platforms, and devices | C18: =+C29 -> 14063 | D18: =+D29 -> 17014 | E18: =+E29 -> 21711 | F18: =+F29 -> 28032 | G18: =+G29 -> 29055 | H18: =+H29 -> 34688 | I18: =+I29 -> 40340 | K18: =+K29 -> 6811 | L18: =+L29 -> 6553 | M18: =+M29 -> 6895 | N18: =+N29 -> 8796 | O18: =+O29 -> 7413 | P18: =+P29 -> 8142 | Q18: =+Q29 -> 8339 | R18: =+R29 -> 10794 | ... Y18: =+Y29 -> 12870 | AG18: =SUM(R18:U18) -> 39501 | AH18: =SUM(S18:V18) -> 40340 | AI18: =SUM(T18:W18) -> 41980 | AJ18: =SUM(U18:X18) -> 43871 | AK18: =SUM(V18:Y18) -> 46085 | AM18: =SUM(AK18/AG18)-1 -> 0.16667932
B19: Total Google Services Revenue | C19: =SUM(C17:C18) -> 130524 | D19: =SUM(D17:D18) -> 151825 | E19: =SUM(E17:E18) -> 168635 | F19: =SUM(F17:F18) -> 237529 | G19: =SUM(G17:G18) -> 253528 | H19: =SUM(H17:H18) -> 272543 | I19: =SUM(I17:I18) -> 304930 | K19: =SUM(K17:K18) -> 61472 | L19: =SUM(L17:L18) -> 62841 | M19: =SUM(M17:M18) -> 61377 | N19: =SUM(N17:N18) -> 67838 | O19: =SUM(O17:O18) -> 61961 | P19: =SUM(P17:P18) -> 66285 | Q19: =SUM(Q17:Q18) -> 67986 | R19: =SUM(R17:R18) -> 76311 | ... Y19: =SUM(Y17:Y18) -> 87052 | AA19: =SUM(AA17:AA18) -> 224360 | AB19: =SUM(AB17:AB18) -> 226215 | AC19: =SUM(AC17:AC18) -> 231380 | AD19: =SUM(AD17:AD18) -> 237855 | AE19: =SUM(AE17:AE18) -> 244966 | AF19: =SUM(AF17:AF18) -> 251439 | AG19: =SUM(AG17:AG18) -> 297147 | AH19: =SUM(AH17:AH18) -> 304930 | ... AK19: =SUM(AK17:AK18) -> 330953 | AM19: =SUM(AK19/AG19)-1 -> 0.11376861
B21: Google Advertising
B22: Google Search & other | C22: 85296 | D22: 98115 | E22: 104062 | F22: 148951 | G22: 162450 | H22: 175033 | I22: 198084 | K22: 39618 | L22: 40689 | M22: 39539 | N22: =SUM(G22-SUM(K22:M22)) -> 42604 | O22: 40359 | P22: 42628 | Q22: 44026 | R22: =SUM(H22-SUM(O22:Q22)) -> 48020 | S22: 46156 | T22: 48509 | U22: 49385 | V22: =SUM(I22-SUM(S22:U22)) -> 54034 | W22: 50702 | X22: 54190 | Y22: 56567 | AA22: =SUM(L22:O22) -> 163191 | AB22: =SUM(M22:P22) -> 165130 | AC22: =SUM(N22:Q22) -> 169617 | AD22: =SUM(O22:R22) -> 175033 | AE22: =SUM(P22:S22) -> 180830 | AF22: =SUM(Q22:T22) -> 186711 | AG22: =SUM(R22:U22) -> 192070 | AH22: =SUM(S22:V22) -> 198084 | ... AK22: =SUM(V22:Y22) -> 215493 | AM22: =SUM(AK22/AG22)-1 -> 0.12195033
