Workbook

Sheet Historical Financials
B2: Affirm Holdings Inc (NASDAQ: AFRM)
B3: Historical Financials
B4: ($ In Millions, except EPS)
A6: X | B6: Income Statement | D6: FYE | H6: Quarterly | N6: Quarterly | AA6: LTM | AG6: Variance
B7: Fiscal Period | C7: 2022 | D7: 2023 | E7: 2024 | F7: 2025 | H7: 1Q23 | I7: 2Q23 | J7: 3Q23 | K7: 4Q23 | L7: 1Q24 | M7: 2Q24 | N7: 3Q24 | O7: 4Q24 | P7: 1Q25 | Q7: 2Q25 | R7: 3Q25 | S7: 4Q25 | T7: 1Q26 | V7: =K7 -> 4Q23 | W7: =L7 -> 1Q24 | X7: =M7 -> 2Q24 | Y7: =N7 -> 3Q24 | Z7: =O7 -> 4Q24 | AA7: =P7 -> 1Q25 | AB7: =Q7 -> 2Q25 | AC7: =R7 -> 3Q25 | ... AE7: =T7 -> 1Q26
B8: Fiscal Period End Date | C8: 44713 | D8: 45078 | E8: 45444 | F8: 45809 | H8: 44805 | I8: 44896 | J8: 44986 | K8: =D8 -> 45078 | L8: 45170 | M8: 45261 | N8: 45352 | O8: =E8 -> 45444 | P8: 45536 | Q8: 45627 | R8: 45717 | S8: =F8 -> 45809 | T8: 45901 | V8: =K8 -> 45078 | W8: =L8 -> 45170 | X8: =M8 -> 45261 | Y8: =N8 -> 45352 | Z8: =O8 -> 45444 | AA8: =P8 -> 45536 | AB8: =Q8 -> 45627 | AC8: =R8 -> 45717 | ... AE8: =T8 -> 45901
B10: Consolidated Revenue | C10: 1349.292 | D10: 1587.985 | E10: 2322.999 | F10: 3224.41 | H10: 361.624 | I10: 399.558 | J10: 380.978 | K10: =SUM(D10-SUM(H10:J10)) -> 445.825 | L10: 496.547 | M10: 591.11 | N10: 576.157 | O10: =SUM(E10-SUM(L10:N10)) -> 659.185 | P10: 698.479 | Q10: 866.381 | R10: 783.134 | S10: =SUM(F10-SUM(P10:R10)) -> 876.416 | T10: 933.337 | V10: =SUM(H10:K10) -> 1587.985 | W10: =SUM(I10:L10) -> 1722.908 | X10: =SUM(J10:M10) -> 1914.46 | Y10: =SUM(K10:N10) -> 2109.639 | Z10: =SUM(L10:O10) -> 2322.999 | AA10: =SUM(M10:P10) -> 2524.931 | AB10: =SUM(N10:Q10) -> 2800.202 | AC10: =SUM(O10:R10) -> 3007.179 | ... AE10: =SUM(Q10:T10) -> 3459.268 | AG10: =SUM(AE10/AA10)-1 -> 0.37004457
B11: Total Revenue | C11: =+SUM(C10:C10) -> 1349.292 | D11: =+SUM(D10:D10) -> 1587.985 | E11: =+SUM(E10:E10) -> 2322.999 | F11: =+SUM(F10:F10) -> 3224.41 | H11: =+SUM(H10:H10) -> 361.624 | I11: =+SUM(I10:I10) -> 399.558 | J11: =+SUM(J10:J10) -> 380.978 | K11: =+SUM(K10:K10) -> 445.825 | L11: =+SUM(L10:L10) -> 496.547 | M11: =+SUM(M10:M10) -> 591.11 | N11: =+SUM(N10:N10) -> 576.157 | O11: =+SUM(O10:O10) -> 659.185 | ... T11: =+SUM(T10:T10) -> 933.337 | V11: =+SUM(V10:V10) -> 1587.985 | W11: =+SUM(W10:W10) -> 1722.908 | X11: =+SUM(X10:X10) -> 1914.46 | Y11: =+SUM(Y10:Y10) -> 2109.639 | Z11: =+SUM(Z10:Z10) -> 2322.999 | AA11: =+SUM(AA10:AA10) -> 2524.931 | AB11: =+SUM(AB10:AB10) -> 2800.202 | AC11: =+SUM(AC10:AC10) -> 3007.179 | ... AE11: =+SUM(AE10:AE10) -> 3459.268 | AG11: =SUM(AE11/AA11)-1 -> 0.37004457
B13: Loss on loan purchase commitment | C13: -204.081 | D13: -140.265 | E13: -180.395 | F13: -242.264 | H13: -35.61 | I13: -38.422 | J13: -31.224 | K13: =SUM(D13-SUM(H13:J13)) -> -35.009 | L13: -34.866 | M13: -53.63 | N13: -44.143 | O13: =SUM(E13-SUM(L13:N13)) -> -47.756 | P13: -54.237 | Q13: -70.278 | R13: -57.29 | S13: =SUM(F13-SUM(P13:R13)) -> -60.459 | T13: -71.552 | V13: =SUM(H13:K13) -> -140.265 | W13: =SUM(I13:L13) -> -139.521 | X13: =SUM(J13:M13) -> -154.729 | Y13: =SUM(K13:N13) -> -167.648 | Z13: =SUM(L13:O13) -> -180.395 | AA13: =SUM(M13:P13) -> -199.766 | AB13: =SUM(N13:Q13) -> -216.414 | AC13: =SUM(O13:R13) -> -229.561 | ... AE13: =SUM(Q13:T13) -> -259.579 | AG13: =SUM(AE13/AA13)-1 -> 0.29941532
B14: Provision for credit losses | C14: -255.272 | D14: -331.86 | E14: -460.628 | F14: -616.683 | H14: -64.25 | I14: -106.689 | J14: -66.438 | K14: =SUM(D14-SUM(H14:J14)) -> -94.483 | L14: -99.696 | M14: -120.88 | N14: -122.443 | O14: =SUM(E14-SUM(L14:N14)) -> -117.609 | P14: -159.824 | Q14: -152.98 | R14: -147.252 | S14: =SUM(F14-SUM(P14:R14)) -> -156.627 | T14: -162.752 | V14: =SUM(H14:K14) -> -331.86 | W14: =SUM(I14:L14) -> -367.306 | X14: =SUM(J14:M14) -> -381.497 | Y14: =SUM(K14:N14) -> -437.502 | Z14: =SUM(L14:O14) -> -460.628 | AA14: =SUM(M14:P14) -> -520.756 | AB14: =SUM(N14:Q14) -> -552.856 | AC14: =SUM(O14:R14) -> -577.665 | ... AE14: =SUM(Q14:T14) -> -619.611 | AG14: =SUM(AE14/AA14)-1 -> 0.18982979
B15: Funding costs | C15: -69.694 | D15: -183.013 | E15: -344.253 | F15: -425.45 | H15: -25.066 | I15: -43.751 | J15: -51.188 | K15: =SUM(D15-SUM(H15:J15)) -> -63.008 | L15: -73.931 | M15: -84.617 | N15: -90.449 | O15: =SUM(E15-SUM(L15:N15)) -> -95.256 | P15: -104.145 | Q15: -107.762 | R15: -107.631 | S15: =SUM(F15-SUM(P15:R15)) -> -105.912 | T15: -110.027 | V15: =SUM(H15:K15) -> -183.013 | W15: =SUM(I15:L15) -> -231.878 | X15: =SUM(J15:M15) -> -272.744 | Y15: =SUM(K15:N15) -> -312.005 | Z15: =SUM(L15:O15) -> -344.253 | AA15: =SUM(M15:P15) -> -374.467 | AB15: =SUM(N15:Q15) -> -397.612 | AC15: =SUM(O15:R15) -> -414.794 | ... AE15: =SUM(Q15:T15) -> -431.332 | AG15: =SUM(AE15/AA15)-1 -> 0.15185584
B16: Processing and servicing | C16: -157.814 | D16: -257.343 | E16: -343.249 | F16: -457.849 | H16: -54.359 | I16: -66.508 | J16: -65.229 | K16: =SUM(D16-SUM(H16:J16)) -> -71.247 | L16: -75.671 | M16: -90.203 | N16: -88.209 | O16: =SUM(E16-SUM(L16:N16)) -> -89.166 | P16: -95.146 | Q16: -115.96 | R16: -118.398 | S16: =SUM(F16-SUM(P16:R16)) -> -128.345 | T16: -133.807 | V16: =SUM(H16:K16) -> -257.343 | W16: =SUM(I16:L16) -> -278.655 | X16: =SUM(J16:M16) -> -302.35 | Y16: =SUM(K16:N16) -> -325.33 | Z16: =SUM(L16:O16) -> -343.249 | AA16: =SUM(M16:P16) -> -362.724 | AB16: =SUM(N16:Q16) -> -388.481 | AC16: =SUM(O16:R16) -> -418.67 | ... AE16: =SUM(Q16:T16) -> -496.51 | AG16: =SUM(AE16/AA16)-1 -> 0.36883691
B17: Revenue Less Transaction Expenses | C17: =+SUM(C11+SUM(C13:C16)) -> 662.431 | D17: =+SUM(D11+SUM(D13:D16)) -> 675.504 | E17: =+SUM(E11+SUM(E13:E16)) -> 994.474 | F17: =+SUM(F11+SUM(F13:F16)) -> 1482.164 | H17: =+SUM(H11+SUM(H13:H16)) -> 182.339 | I17: =+SUM(I11+SUM(I13:I16)) -> 144.188 | J17: =+SUM(J11+SUM(J13:J16)) -> 166.899 | K17: =+SUM(K11+SUM(K13:K16)) -> 182.078 | L17: =+SUM(L11+SUM(L13:L16)) -> 212.383 | M17: =+SUM(M11+SUM(M13:M16)) -> 241.78 | N17: =+SUM(N11+SUM(N13:N16)) -> 230.913 | O17: =+SUM(O11+SUM(O13:O16)) -> 309.398 | ... T17: =+SUM(T11+SUM(T13:T16)) -> 455.199 | V17: =+SUM(V11+SUM(V13:V16)) -> 675.504 | W17: =+SUM(W11+SUM(W13:W16)) -> 705.548 | X17: =+SUM(X11+SUM(X13:X16)) -> 803.14 | Y17: =+SUM(Y11+SUM(Y13:Y16)) -> 867.154 | Z17: =+SUM(Z11+SUM(Z13:Z16)) -> 994.474 | AA17: =+SUM(AA11+SUM(AA13:AA16)) -> 1067.218 | AB17: =+SUM(AB11+SUM(AB13:AB16)) -> 1244.839 | AC17: =+SUM(AC11+SUM(AC13:AC16)) -> 1366.489 | ... AE17: =+SUM(AE11+SUM(AE13:AE16)) -> 1652.236 | AG17: =SUM(AE17/AA17)-1 -> 0.54817104
B18: Gross Margin (%) | C18: =C17/C11 -> 0.4909471 | D18: =D17/D11 -> 0.42538437 | E18: =E17/E11 -> 0.42809919 | F18: =F17/F11 -> 0.45966983 | H18: =H17/H11 -> 0.50422262 | I18: =I17/I11 -> 0.36086876 | J18: =J17/J11 -> 0.43808041 | K18: =K17/K11 -> 0.40840689 | L18: =L17/L11 -> 0.42771983 | M18: =M17/M11 -> 0.40902708 | N18: =N17/N11 -> 0.40078138 | O18: =O17/O11 -> 0.46936444 | ... T18: =T17/T11 -> 0.4877113 | V18: =V17/V11 -> 0.42538437 | W18: =W17/W11 -> 0.40950997 | X18: =X17/X11 -> 0.41951255 | Y18: =Y17/Y11 -> 0.41104379 | Z18: =Z17/Z11 -> 0.42809919 | AA18: =AA17/AA11 -> 0.42267214 | AB18: =AB17/AB11 -> 0.44455329 | AC18: =AC17/AC11 -> 0.45440893 | ... AE18: =AE17/AE11 -> 0.4776259 | AG18: =SUM(AE18-AA18)*1000 -> 54.953758
B20: Technology and data analytics | C20: -418.643 | D20: -615.818 | E20: -501.857 | F20: -589.723 | H20: -144.961 | I20: -156.747 | J20: -161.792 | K20: =SUM(D20-SUM(H20:J20)) -> -152.318 | L20: -132.965 | M20: -119.833 | N20: -124.828 | O20: =SUM(E20-SUM(L20:N20)) -> -124.231 | P20: -134.29 | Q20: -148.213 | R20: -152.62 | S20: =SUM(F20-SUM(P20:R20)) -> -154.6 | T20: -168.106 | V20: =SUM(H20:K20) -> -615.818 | W20: =SUM(I20:L20) -> -603.822 | X20: =SUM(J20:M20) -> -566.908 | Y20: =SUM(K20:N20) -> -529.944 | Z20: =SUM(L20:O20) -> -501.857 | AA20: =SUM(M20:P20) -> -503.182 | AB20: =SUM(N20:Q20) -> -531.562 | AC20: =SUM(O20:R20) -> -559.354 | ... AE20: =SUM(Q20:T20) -> -623.539 | AG20: =SUM(AE20/AA20)-1 -> 0.23919178
B21: Sales and marketing | C21: -532.343 | D21: -638.28 | E21: -576.405 | F21: -434.847 | H21: -163.873 | I21: -188.334 | J21: -140.942 | K21: =SUM(D21-SUM(H21:J21)) -> -145.131 | L21: -146.866 | M21: -161.265 | N21: -132.95 | O21: =SUM(E21-SUM(L21:N21)) -> -135.324 | P21: -145.233 | Q21: -136.038 | R21: -74.022 | S21: =SUM(F21-SUM(P21:R21)) -> -79.554 | T21: -78.491 | V21: =SUM(H21:K21) -> -638.28 | W21: =SUM(I21:L21) -> -621.273 | X21: =SUM(J21:M21) -> -594.204 | Y21: =SUM(K21:N21) -> -586.212 | Z21: =SUM(L21:O21) -> -576.405 | AA21: =SUM(M21:P21) -> -574.772 | AB21: =SUM(N21:Q21) -> -549.545 | AC21: =SUM(O21:R21) -> -490.617 | ... AE21: =SUM(Q21:T21) -> -368.105 | AG21: =SUM(AE21/AA21)-1 -> -0.35956344
B22: General and administrative | C22: -577.493 | D22: -586.398 | E22: -525.291 | F22: -545.053 | H22: -160.972 | I22: -158.639 | J22: -139.266 | K22: =SUM(D22-SUM(H22:J22)) -> -127.521 | L22: -140.334 | M22: -132.777 | N22: -128.721 | O22: =SUM(E22-SUM(L22:N22)) -> -123.459 | P22: -138.482 | Q22: -139.412 | R22: -134.303 | S22: =SUM(F22-SUM(P22:R22)) -> -132.856 | T22: -144.941 | V22: =SUM(H22:K22) -> -586.398 | W22: =SUM(I22:L22) -> -565.76 | X22: =SUM(J22:M22) -> -539.898 | Y22: =SUM(K22:N22) -> -529.353 | Z22: =SUM(L22:O22) -> -525.291 | AA22: =SUM(M22:P22) -> -523.439 | AB22: =SUM(N22:Q22) -> -530.074 | AC22: =SUM(O22:R22) -> -535.656 | ... AE22: =SUM(Q22:T22) -> -551.512 | AG22: =SUM(AE22/AA22)-1 -> 0.053631846
B23: Restructuring charges, net | C23: 0 | D23: -35.87 | E23: -6.768 | F23: 0.183 | H23: 0 | I23: 0 | J23: -34.934 | K23: =SUM(D23-SUM(H23:J23)) -> -0.936 | L23: -1.665 | M23: -0.056 | N23: -5.203 | O23: =SUM(E23-SUM(L23:N23)) -> 0.156 | P23: 0.255 | Q23: -0.06 | R23: -0.012 | S23: =SUM(F23-SUM(P23:R23)) -> 0 | T23: 0 | V23: =SUM(H23:K23) -> -35.87 | W23: =SUM(I23:L23) -> -37.535 | X23: =SUM(J23:M23) -> -37.591 | Y23: =SUM(K23:N23) -> -7.86 | Z23: =SUM(L23:O23) -> -6.768 | AA23: =SUM(M23:P23) -> -4.848 | AB23: =SUM(N23:Q23) -> -4.852 | AC23: =SUM(O23:R23) -> 0.339 | ... AE23: =SUM(Q23:T23) -> -0.072 | AG23: =SUM(AE23/AA23)-1 -> -0.98514851
B24: Operating Profit | C24: =+SUM(C17+SUM(C20:C23)) -> -866.048 | D24: =+SUM(D17+SUM(D20:D23)) -> -1200.862 | E24: =+SUM(E17+SUM(E20:E23)) -> -615.847 | F24: =+SUM(F17+SUM(F20:F23)) -> -87.276 | H24: =+SUM(H17+SUM(H20:H23)) -> -287.467 | I24: =+SUM(I17+SUM(I20:I23)) -> -359.532 | J24: =+SUM(J17+SUM(J20:J23)) -> -310.035 | K24: =+SUM(K17+SUM(K20:K23)) -> -243.828 | L24: =+SUM(L17+SUM(L20:L23)) -> -209.447 | M24: =+SUM(M17+SUM(M20:M23)) -> -172.151 | N24: =+SUM(N17+SUM(N20:N23)) -> -160.789 | O24: =+SUM(O17+SUM(O20:O23)) -> -73.46 | ... T24: =+SUM(T17+SUM(T20:T23)) -> 63.661 | V24: =+SUM(V17+SUM(V20:V23)) -> -1200.862 | W24: =+SUM(W17+SUM(W20:W23)) -> -1122.842 | X24: =+SUM(X17+SUM(X20:X23)) -> -935.461 | Y24: =+SUM(Y17+SUM(Y20:Y23)) -> -786.215 | Z24: =+SUM(Z17+SUM(Z20:Z23)) -> -615.847 | AA24: =+SUM(AA17+SUM(AA20:AA23)) -> -539.023 | AB24: =+SUM(AB17+SUM(AB20:AB23)) -> -371.194 | AC24: =+SUM(AC17+SUM(AC20:AC23)) -> -218.799 | ... AE24: =+SUM(AE17+SUM(AE20:AE23)) -> 109.008 | AG24: =SUM(AE24/AA24)-1 -> -1.2022326
B25: Operating Margin (%) | C25: =C24/C11 -> -0.64185365 | D25: =D24/D11 -> -0.75621747 | E25: =E24/E11 -> -0.26510859 | F25: =F24/F11 -> -0.027067277 | H25: =H24/H11 -> -0.79493341 | I25: =I24/I11 -> -0.89982431 | J25: =J24/J11 -> -0.81378715 | K25: =K24/K11 -> -0.54691415 | L25: =L24/L11 -> -0.421807 | M25: =M24/M11 -> -0.29123344 | N25: =N24/N11 -> -0.2790715 | O25: =O24/O11 -> -0.11144064 | ... T25: =T24/T11 -> 0.068207946 | V25: =V24/V11 -> -0.75621747 | W25: =W24/W11 -> -0.65171327 | X25: =X24/X11 -> -0.48862917 | Y25: =Y24/Y11 -> -0.37267751 | Z25: =Z24/Z11 -> -0.26510859 | AA25: =AA24/AA11 -> -0.21348029 | AB25: =AB24/AB11 -> -0.13255972 | AC25: =AC24/AC11 -> -0.072758888 | ... AE25: =AE24/AE11 -> 0.031511869 | AG25: =SUM(AE25-AA25)*1000 -> 244.99216
B27: Other income (expense), net | C27: 141.217 | D27: 211.617 | E27: 100.32 | F27: 148.739 | H27: 36.018 | I27: 35.527 | J27: 103.522 | K27: =SUM(D27-SUM(H27:J27)) -> 36.55 | L27: 38.707 | M27: 4.549 | N27: 27.743 | O27: =SUM(E27-SUM(L27:N27)) -> 29.321 | P27: 34.303 | Q27: 87.181 | R27: 13.738 | S27: =SUM(F27-SUM(P27:R27)) -> 13.517 | T27: 19.358 | V27: =SUM(H27:K27) -> 211.617 | W27: =SUM(I27:L27) -> 214.306 | X27: =SUM(J27:M27) -> 183.328 | Y27: =SUM(K27:N27) -> 107.549 | Z27: =SUM(L27:O27) -> 100.32 | AA27: =SUM(M27:P27) -> 95.916 | AB27: =SUM(N27:Q27) -> 178.548 | AC27: =SUM(O27:R27) -> 164.543 | ... AE27: =SUM(Q27:T27) -> 133.794 | AG27: =SUM(AE27/AA27)-1 -> 0.39490804
B28: Earnings before Taxes | C28: =SUM(C27:C27)+C24 -> -724.831 | D28: =SUM(D27:D27)+D24 -> -989.245 | E28: =SUM(E27:E27)+E24 -> -515.527 | F28: =SUM(F27:F27)+F24 -> 61.463 | H28: =SUM(H27:H27)+H24 -> -251.449 | I28: =SUM(I27:I27)+I24 -> -324.005 | J28: =SUM(J27:J27)+J24 -> -206.513 | K28: =SUM(K27:K27)+K24 -> -207.278 | L28: =SUM(L27:L27)+L24 -> -170.74 | M28: =SUM(M27:M27)+M24 -> -167.602 | N28: =SUM(N27:N27)+N24 -> -133.046 | O28: =SUM(O27:O27)+O24 -> -44.139 | ... T28: =SUM(T27:T27)+T24 -> 83.019 | V28: =SUM(V27:V27)+V24 -> -989.245 | W28: =SUM(W27:W27)+W24 -> -908.536 | X28: =SUM(X27:X27)+X24 -> -752.133 | Y28: =SUM(Y27:Y27)+Y24 -> -678.666 | Z28: =SUM(Z27:Z27)+Z24 -> -515.527 | AA28: =SUM(AA27:AA27)+AA24 -> -443.107 | AB28: =SUM(AB27:AB27)+AB24 -> -192.646 | AC28: =SUM(AC27:AC27)+AC24 -> -54.256 | ... AE28: =SUM(AE27:AE27)+AE24 -> 242.802 | AG28: =SUM(AE28/AA28)-1 -> -1.5479534
B29: EBT Margin (%) | C29: =C28/C11 -> -0.53719358 | D29: =D28/D11 -> -0.62295614 | E29: =E28/E11 -> -0.22192304 | F29: =F28/F11 -> 0.019061782 | H29: =H28/H11 -> -0.69533272 | I29: =I28/I11 -> -0.81090855 | J29: =J28/J11 -> -0.54206017 | K29: =K28/K11 -> -0.46493131 | L29: =L28/L11 -> -0.34385466 | M29: =M28/M11 -> -0.28353775 | N29: =N28/N11 -> -0.2309197 | O29: =O28/O11 -> -0.066959958 | ... T29: =T28/T11 -> 0.088948579 | V29: =V28/V11 -> -0.62295614 | W29: =W28/W11 -> -0.52732705 | X29: =X28/X11 -> -0.39286953 | Y29: =Y28/Y11 -> -0.32169769 | Z29: =Z28/Z11 -> -0.22192304 | AA29: =AA28/AA11 -> -0.17549272 | AB29: =AB28/AB11 -> -0.06879718 | AC29: =AC28/AC11 -> -0.018042158 | ... AE29: =AE28/AE11 -> 0.070188838 | AG29: =SUM(AE29-AA29)*1000 -> 245.68155
B31: Income tax benefit (expense) | C31: -18.308 | D31: 3.9 | E31: -2.23 | F31: -9.279 | H31: 0.18 | I31: 1.568 | J31: 0.836 | K31: =SUM(D31-SUM(H31:J31)) -> 1.316 | L31: -1.043 | M31: 0.7 | N31: -0.89 | O31: =SUM(E31-SUM(L31:N31)) -> -0.997 | P31: -1.902 | Q31: -2.499 | R31: -2.541 | S31: =SUM(F31-SUM(P31:R31)) -> -2.337 | T31: -2.326 | V31: =SUM(H31:K31) -> 3.9 | W31: =SUM(I31:L31) -> 2.677 | X31: =SUM(J31:M31) -> 1.809 | Y31: =SUM(K31:N31) -> 0.083 | Z31: =SUM(L31:O31) -> -2.23 | AA31: =SUM(M31:P31) -> -3.089 | AB31: =SUM(N31:Q31) -> -6.288 | AC31: =SUM(O31:R31) -> -7.939 | ... AE31: =SUM(Q31:T31) -> -9.703 | AG31: =SUM(AE31/AA31)-1 -> 2.141146
B32: Net loss | C32: =SUM(C28+SUM(C31:C31)) -> -743.139 | D32: =SUM(D28+SUM(D31:D31)) -> -985.345 | E32: =SUM(E28+SUM(E31:E31)) -> -517.757 | F32: =SUM(F28+SUM(F31:F31)) -> 52.184 | H32: =SUM(H28+SUM(H31:H31)) -> -251.269 | I32: =SUM(I28+SUM(I31:I31)) -> -322.437 | J32: =SUM(J28+SUM(J31:J31)) -> -205.677 | K32: =SUM(K28+SUM(K31:K31)) -> -205.962 | L32: =SUM(L28+SUM(L31:L31)) -> -171.783 | M32: =SUM(M28+SUM(M31:M31)) -> -166.902 | N32: =SUM(N28+SUM(N31:N31)) -> -133.936 | O32: =SUM(O28+SUM(O31:O31)) -> -45.136 | ... T32: =SUM(T28+SUM(T31:T31)) -> 80.693 | V32: =SUM(V28+SUM(V31:V31)) -> -985.345 | W32: =SUM(W28+SUM(W31:W31)) -> -905.859 | X32: =SUM(X28+SUM(X31:X31)) -> -750.324 | Y32: =SUM(Y28+SUM(Y31:Y31)) -> -678.583 | Z32: =SUM(Z28+SUM(Z31:Z31)) -> -517.757 | AA32: =SUM(AA28+SUM(AA31:AA31)) -> -446.196 | AB32: =SUM(AB28+SUM(AB31:AB31)) -> -198.934 | AC32: =SUM(AC28+SUM(AC31:AC31)) -> -62.195 | ... AE32: =SUM(AE28+SUM(AE31:AE31)) -> 233.099 | AG32: =SUM(AE32/AA32)-1 -> -1.5224139
B33: Net Margin (%) | C33: =C32/C11 -> -0.55076218 | D33: =D32/D11 -> -0.62050019 | E33: =E32/E11 -> -0.22288301 | F33: =F32/F11 -> 0.016184046 | H33: =H32/H11 -> -0.69483497 | I33: =I32/I11 -> -0.80698422 | J33: =J32/J11 -> -0.53986582 | K33: =K32/K11 -> -0.46197948 | L33: =L32/L11 -> -0.34595517 | M33: =M32/M11 -> -0.28235354 | N33: =N32/N11 -> -0.23246442 | O33: =O32/O11 -> -0.068472432 | ... T33: =T32/T11 -> 0.086456446 | V33: =V32/V11 -> -0.62050019 | W33: =W32/W11 -> -0.52577329 | X33: =X32/X11 -> -0.39192462 | Y33: =Y32/Y11 -> -0.32165835 | Z33: =Z32/Z11 -> -0.22288301 | AA33: =AA32/AA11 -> -0.17671612 | AB33: =AB32/AB11 -> -0.071042732 | AC33: =AC32/AC11 -> -0.020682174 | ... AE33: =AE32/AE11 -> 0.067383909 | AG33: =SUM(AE33-AA33)*1000 -> 244.10003
B35: Basic shares | C35: 281.73994 | D35: 295.36527 | E35: 309.85713 | F35: 322.85187 | H35: 290.92927 | I35: 293.68333 | J35: 297.20472 | K35: =D35 -> 295.36527 | L35: 303.83967 | M35: 307.5716 | N35: 312.62673 | O35: =E35 -> 309.85713 | P35: 318.23456 | Q35: 322.28233 | R35: 324.05397 | S35: =F35 -> 322.85187 | T35: 330.23802 | V35: =K35 -> 295.36527 | W35: =L35 -> 303.83967 | X35: =M35 -> 307.5716 | Y35: =N35 -> 312.62673 | Z35: =O35 -> 309.85713 | AA35: =P35 -> 318.23456 | AB35: =Q35 -> 322.28233 | AC35: =R35 -> 324.05397 | ... AE35: =T35 -> 330.23802 | AG35: =SUM(AE35/AA35)-1 -> 0.03771894
B36: Basic EPS | C36: =C32/C35 -> -2.6376771 | D36: =D32/D35 -> -3.3360219 | E36: =E32/E35 -> -1.670954 | F36: =F32/F35 -> 0.1616345 | H36: =H32/H35 -> -0.86367728 | I36: =I32/I35 -> -1.0979071 | J36: =J32/J35 -> -0.69203815 | K36: =K32/K35 -> -0.69731286 | L36: =L32/L35 -> -0.56537384 | M36: =M32/M35 -> -0.54264438 | N36: =N32/N35 -> -0.42842146 | O36: =O32/O35 -> -0.14566713 | ... T36: =T32/T35 -> 0.244348 | V36: =V32/V35 -> -3.3360219 | W36: =W32/W35 -> -2.9813717 | X36: =X32/X35 -> -2.43951 | Y36: =Y32/Y35 -> -2.1705854 | Z36: =Z32/Z35 -> -1.670954 | AA36: =AA32/AA35 -> -1.4020979 | AB36: =AB32/AB35 -> -0.61726623 | AC36: =AC32/AC35 -> -0.19192791 | ... AE36: =AE32/AE35 -> 0.70585148 | AG36: =SUM(AE36/AA36)-1 -> -1.5034253
B38: Fully Diluted Shares | C38: 281.73994 | D38: 295.36527 | E38: 309.85713 | F38: 341.02357 | H38: 313 | I38: 324 | J38: 321 | K38: =D38 -> 295.36527 | L38: 334 | M38: 341 | N38: 341 | O38: =E38 -> 309.85713 | P38: 357 | Q38: 356 | R38: 352 | S38: =F38 -> 341.02357 | T38: 361 | V38: =K38 -> 295.36527 | W38: =L38 -> 334 | X38: =M38 -> 341 | Y38: =N38 -> 341 | Z38: =O38 -> 309.85713 | AA38: =P38 -> 357 | AB38: =Q38 -> 356 | AC38: =R38 -> 352 | ... AE38: =T38 -> 361 | AG38: =SUM(AE38/AA38)-1 -> 0.011204482
B39: Diluted EPS | C39: =C32/C38 -> -2.6376771 | D39: =D32/D38 -> -3.3360219 | E39: =E32/E38 -> -1.670954 | F39: =F32/F38 -> 0.15302168 | H39: =H32/H38 -> -0.80277636 | I39: =I32/I38 -> -0.99517593 | J39: =J32/J38 -> -0.64073832 | K39: =K32/K38 -> -0.69731286 | L39: =L32/L38 -> -0.51432036 | M39: =M32/M38 -> -0.48944868 | N39: =N32/N38 -> -0.39277419 | O39: =O32/O38 -> -0.14566713 | ... T39: =T32/T38 -> 0.22352632 | V39: =V32/V38 -> -3.3360219 | W39: =W32/W38 -> -2.7121527 | X39: =X32/X38 -> -2.2003636 | Y39: =Y32/Y38 -> -1.9899795 | Z39: =Z32/Z38 -> -1.670954 | AA39: =AA32/AA38 -> -1.2498487 | AB39: =AB32/AB38 -> -0.55880337 | AC39: =AC32/AC38 -> -0.17669034 | ... AE39: =AE32/AE38 -> 0.6457036 | AG39: =SUM(AE39/AA39)-1 -> -1.5166254
A41: X | B41: Balance Sheet | C41: FYE | N41: Quarterly | AA41: LTM | AG41: Variance
B42: =B7 -> Fiscal Period | C42: =C7 -> 2022 | D42: =D7 -> 2023 | E42: =E7 -> 2024 | F42: =F7 -> 2025 | H42: =H7 -> 1Q23 | I42: =I7 -> 2Q23 | J42: =J7 -> 3Q23 | K42: =K7 -> 4Q23 | L42: =L7 -> 1Q24 | M42: =M7 -> 2Q24 | N42: =N7 -> 3Q24 | O42: =O7 -> 4Q24 | ... T42: =T7 -> 1Q26 | V42: =V7 -> 4Q23 | W42: =W7 -> 1Q24 | X42: =X7 -> 2Q24 | Y42: =Y7 -> 3Q24 | Z42: =Z7 -> 4Q24 | AA42: =AA7 -> 1Q25 | AB42: =AB7 -> 2Q25 | AC42: =AC7 -> 3Q25 | ... AE42: =AE7 -> 1Q26
B43: =B8 -> Fiscal Period End Date | C43: =C8 -> 44713 | D43: =D8 -> 45078 | E43: =E8 -> 45444 | F43: =F8 -> 45809 | H43: =H8 -> 44805 | I43: =I8 -> 44896 | J43: =J8 -> 44986 | K43: =K8 -> 45078 | L43: =L8 -> 45170 | M43: =M8 -> 45261 | N43: =N8 -> 45352 | O43: =O8 -> 45444 | ... T43: =T8 -> 45901 | V43: =V8 -> 45078 | W43: =W8 -> 45170 | X43: =X8 -> 45261 | Y43: =Y8 -> 45352 | Z43: =Z8 -> 45444 | AA43: =AA8 -> 45536 | AB43: =AB8 -> 45627 | AC43: =AC8 -> 45717 | ... AE43: =AE8 -> 45901
B46: Total Assets
B47: Cash and cash equivalents | C47: 1255.171 | D47: 892.027 | E47: 1013.106 | F47: 1354.455 | H47: 1530.132 | I47: 1440.333 | J47: 972.477 | K47: =D47 -> 892.027 | L47: 1079.261 | M47: 1036.719 | N47: 1272.76 | O47: =E47 -> 1013.106 | P47: 1046.16 | Q47: 1200.381 | R47: 1351.148 | S47: =F47 -> 1354.455 | T47: 1428.848 | V47: =K47 -> 892.027 | W47: =L47 -> 1079.261 | X47: =M47 -> 1036.719 | Y47: =N47 -> 1272.76 | Z47: =O47 -> 1013.106 | AA47: =P47 -> 1046.16 | AB47: =Q47 -> 1200.381 | AC47: =R47 -> 1351.148 | ... AE47: =T47 -> 1428.848 | AG47: =SUM(AE47/AA47)-1 -> 0.36580255
B48: Restricted cash | C48: 295.636 | D48: 367.917 | E48: 282.293 | F48: 401.968 | H48: 383.406 | I48: 424.46 | J48: 409.015 | K48: =D48 -> 367.917 | L48: 409.231 | M48: 411.259 | N48: 346.931 | O48: =E48 -> 282.293 | P48: 338.462 | Q48: 536.776 | R48: 384.811 | S48: =F48 -> 401.968 | T48: 668.762 | V48: =K48 -> 367.917 | W48: =L48 -> 409.231 | X48: =M48 -> 411.259 | Y48: =N48 -> 346.931 | Z48: =O48 -> 282.293 | AA48: =P48 -> 338.462 | AB48: =Q48 -> 536.776 | AC48: =R48 -> 384.811 | ... AE48: =T48 -> 668.762 | AG48: =SUM(AE48/AA48)-1 -> 0.97588503
B49: Securities available for sale at fair value | C49: 1595.373 | D49: 1174.653 | E49: 1131.628 | F49: 871.425 | H49: 1237.291 | I49: 914.923 | J49: 1059.031 | K49: =D49 -> 1174.653 | L49: 1021.63 | M49: 914.069 | N49: 781.402 | O49: =E49 -> 1131.628 | P49: 1073.685 | Q49: 666.684 | R49: 780.17 | S49: =F49 -> 871.425 | T49: 812.442 | V49: =K49 -> 1174.653 | W49: =L49 -> 1021.63 | X49: =M49 -> 914.069 | Y49: =N49 -> 781.402 | Z49: =O49 -> 1131.628 | AA49: =P49 -> 1073.685 | AB49: =Q49 -> 666.684 | AC49: =R49 -> 780.17 | ... AE49: =T49 -> 812.442 | AG49: =SUM(AE49/AA49)-1 -> -0.24331438
B50: Loans held for sale | C50: 2.67 | D50: 0.076 | E50: 0.036 | F50: 0 | H50: 7.112 | I50: 0.344 | J50: 0.122 | K50: =D50 -> 0.076 | L50: 0.145 | M50: 0.029 | N50: 0.127 | O50: =E50 -> 0.036 | P50: 0 | Q50: 0 | R50: 0.001 | S50: =F50 -> 0 | T50: 0.012 | V50: =K50 -> 0.076 | W50: =L50 -> 0.145 | X50: =M50 -> 0.029 | Y50: =N50 -> 0.127 | Z50: =O50 -> 0.036 | AA50: =P50 -> 0 | AB50: =Q50 -> 0 | AC50: =R50 -> 0.001 | ... AE50: =T50 -> 0.012 | AG50: =SUM(AE50/AA50)-1 -> #DIV/0!
B51: Loans held for investment, net | C51: 2348.169 | D51: 4198.431 | E51: 5360.959 | F51: 6628.605 | H51: 2528.612 | I51: 3473.404 | J51: 3599.206 | K51: =D51 -> 4198.431 | L51: 4317.354 | M51: 4976.608 | N51: 5172.319 | O51: =E51 -> 5360.959 | P51: 5960.228 | Q51: 6432.336 | R51: 6255.459 | S51: =F51 -> 6628.605 | T51: 6809.376 | V51: =K51 -> 4198.431 | W51: =L51 -> 4317.354 | X51: =M51 -> 4976.608 | Y51: =N51 -> 5172.319 | Z51: =O51 -> 5360.959 | AA51: =P51 -> 5960.228 | AB51: =Q51 -> 6432.336 | AC51: =R51 -> 6255.459 | ... AE51: =T51 -> 6809.376
B52: Accounts receivable, net | C52: 142.052 | D52: 199.085 | E52: 353.028 | F52: 426.177 | H52: 147.757 | I52: 201.622 | J52: 135.816 | K52: =D52 -> 199.085 | L52: 236.234 | M52: 307.286 | N52: 293.388 | O52: =E52 -> 353.028 | P52: 308.394 | Q52: 203.626 | R52: 220.279 | S52: =F52 -> 426.177 | T52: 283.726 | V52: =K52 -> 199.085 | W52: =L52 -> 236.234 | X52: =M52 -> 307.286 | Y52: =N52 -> 293.388 | Z52: =O52 -> 353.028 | AA52: =P52 -> 308.394 | AB52: =Q52 -> 203.626 | AC52: =R52 -> 220.279 | ... AE52: =T52 -> 283.726
...

Sheet Revenue Drivers
B2: ='Historical Financials'!B2 -> Affirm Holdings Inc (NASDAQ: AFRM) | C2: FYE | N2: Quarterly | AA2: LTM
B3: Segment Anaysis | C3: ='Historical Financials'!C7 -> 2022 | D3: ='Historical Financials'!D7 -> 2023 | E3: ='Historical Financials'!E7 -> 2024 | F3: ='Historical Financials'!F7 -> 2025 | H3: ='Historical Financials'!H7 -> 1Q23 | I3: ='Historical Financials'!I7 -> 2Q23 | J3: ='Historical Financials'!J7 -> 3Q23 | K3: ='Historical Financials'!K7 -> 4Q23 | L3: ='Historical Financials'!L7 -> 1Q24 | M3: ='Historical Financials'!M7 -> 2Q24 | N3: ='Historical Financials'!N7 -> 3Q24 | O3: ='Historical Financials'!O7 -> 4Q24 | ... T3: ='Historical Financials'!T7 -> 1Q26 | V3: =K3 -> 4Q23 | W3: =L3 -> 1Q24 | X3: =M3 -> 2Q24 | Y3: =N3 -> 3Q24 | Z3: =O3 -> 4Q24 | AA3: =P3 -> 1Q25 | AB3: =Q3 -> 2Q25 | AC3: =R3 -> 3Q25 | ... AE3: =T3 -> 1Q26
B4: ($ In Millions) | C4: ='Historical Financials'!C8 -> 44713 | D4: ='Historical Financials'!D8 -> 45078 | E4: ='Historical Financials'!E8 -> 45444 | F4: ='Historical Financials'!F8 -> 45809 | H4: ='Historical Financials'!H8 -> 44805 | I4: ='Historical Financials'!I8 -> 44896 | J4: ='Historical Financials'!J8 -> 44986 | K4: ='Historical Financials'!K8 -> 45078 | L4: ='Historical Financials'!L8 -> 45170 | M4: ='Historical Financials'!M8 -> 45261 | N4: ='Historical Financials'!N8 -> 45352 | O4: ='Historical Financials'!O8 -> 45444 | ... T4: ='Historical Financials'!T8 -> 45901 | V4: =K4 -> 45078 | W4: =L4 -> 45170 | X4: =M4 -> 45261 | Y4: =N4 -> 45352 | Z4: =O4 -> 45444 | AA4: =P4 -> 45536 | AB4: =Q4 -> 45627 | AC4: =R4 -> 45717 | ... AE4: =T4 -> 45901
A6: X | B6: Revenue by reportable segment
A8: X | B8: Revenue Segment Anaysis
B9: Network revenue | C9: 559.207 | D9: 626.938 | E9: 826.008 | F9: 1113.966 | H9: 139.857 | I9: 163.136 | J9: 148.482 | K9: =SUM(D9-SUM(H9:J9)) -> 175.463 | L9: 179.426 | M9: 227.626 | N9: 194.968 | O9: =SUM(E9-SUM(L9:N9)) -> 223.988 | P9: 231.819 | Q9: 303.037 | R9: 272.545 | S9: =SUM(F9-SUM(P9:R9)) -> 306.565 | T9: 320.477 | V9: =SUM(H9:K9) -> 626.938 | W9: =SUM(I9:L9) -> 666.507 | X9: =SUM(J9:M9) -> 730.997 | Y9: =SUM(K9:N9) -> 777.483 | Z9: =SUM(L9:O9) -> 826.008 | AA9: =SUM(M9:P9) -> 878.401 | AB9: =SUM(N9:Q9) -> 953.812 | AC9: =SUM(O9:R9) -> 1031.389 | ... AE9: =SUM(Q9:T9) -> 1202.624
B10: Interest Income | C10: 527.88 | D10: 685.217 | E10: 1204.355 | F10: 1608.221 | H10: 136.802 | I10: 155.321 | J10: 178.27 | K10: =SUM(D10-SUM(H10:J10)) -> 214.824 | L10: 262.679 | M10: 288.346 | N10: 315.712 | O10: =SUM(E10-SUM(L10:N10)) -> 337.618 | P10: 377.064 | Q10: 409.367 | R10: 402.701 | S10: =SUM(F10-SUM(P10:R10)) -> 419.089 | T10: 454.122 | V10: =SUM(H10:K10) -> 685.217 | W10: =SUM(I10:L10) -> 811.094 | X10: =SUM(J10:M10) -> 944.119 | Y10: =SUM(K10:N10) -> 1081.561 | Z10: =SUM(L10:O10) -> 1204.355 | AA10: =SUM(M10:P10) -> 1318.74 | AB10: =SUM(N10:Q10) -> 1439.761 | AC10: =SUM(O10:R10) -> 1526.75 | ... AE10: =SUM(Q10:T10) -> 1685.279
B11: Gain (loss) on sales of loans | C11: 196.435 | D11: 188.341 | E11: 197.153 | F11: 381.622 | H11: 63.595 | I11: 59.607 | J11: 32.813 | K11: =SUM(D11-SUM(H11:J11)) -> 32.326 | L11: 34.285 | M11: 52.702 | N11: 40.183 | O11: =SUM(E11-SUM(L11:N11)) -> 69.983 | P11: 63.613 | Q11: 125.287 | R11: 75.838 | S11: =SUM(F11-SUM(P11:R11)) -> 116.884 | T11: 119.049 | V11: =SUM(H11:K11) -> 188.341 | W11: =SUM(I11:L11) -> 159.031 | X11: =SUM(J11:M11) -> 152.126 | Y11: =SUM(K11:N11) -> 159.496 | Z11: =SUM(L11:O11) -> 197.153 | AA11: =SUM(M11:P11) -> 226.481 | AB11: =SUM(N11:Q11) -> 299.066 | AC11: =SUM(O11:R11) -> 334.721 | ... AE11: =SUM(Q11:T11) -> 437.058
B12: Servicing income | C12: 65.77 | D12: 87.489 | E12: 95.483 | F12: 120.601 | H12: 21.37 | I12: 21.494 | J12: 21.413 | K12: =SUM(D12-SUM(H12:J12)) -> 23.212 | L12: 20.157 | M12: 22.436 | N12: 25.294 | O12: =SUM(E12-SUM(L12:N12)) -> 27.596 | P12: 25.983 | Q12: 28.69 | R12: 32.05 | S12: =SUM(F12-SUM(P12:R12)) -> 33.878 | T12: 39.689 | V12: =SUM(H12:K12) -> 87.489 | W12: =SUM(I12:L12) -> 86.276 | X12: =SUM(J12:M12) -> 87.218 | Y12: =SUM(K12:N12) -> 91.099 | Z12: =SUM(L12:O12) -> 95.483 | AA12: =SUM(M12:P12) -> 101.309 | AB12: =SUM(N12:Q12) -> 107.563 | AC12: =SUM(O12:R12) -> 114.319 | ... AE12: =SUM(Q12:T12) -> 134.307
B13: Total Net Revenue | C13: =SUM(C9:C12) -> 1349.292 | D13: =SUM(D9:D12) -> 1587.985 | E13: =SUM(E9:E12) -> 2322.999 | F13: =SUM(F9:F12) -> 3224.41 | H13: =SUM(H9:H12) -> 361.624 | I13: =SUM(I9:I12) -> 399.558 | J13: =SUM(J9:J12) -> 380.978 | K13: =SUM(K9:K12) -> 445.825 | L13: =SUM(L9:L12) -> 496.547 | M13: =SUM(M9:M12) -> 591.11 | N13: =SUM(N9:N12) -> 576.157 | O13: =SUM(O9:O12) -> 659.185 | ... T13: =SUM(T9:T12) -> 933.337 | V13: =SUM(V9:V12) -> 1587.985 | W13: =SUM(W9:W12) -> 1722.908 | X13: =SUM(X9:X12) -> 1914.46 | Y13: =SUM(Y9:Y12) -> 2109.639 | Z13: =SUM(Z9:Z12) -> 2322.999 | AA13: =SUM(AA9:AA12) -> 2524.931 | AB13: =SUM(AB9:AB12) -> 2800.202 | AC13: =SUM(AC9:AC12) -> 3007.179 | ... AE13: =SUM(AE9:AE12) -> 3459.268
B14: Balance Check | C14: =+C13-'Historical Financials'!C11 -> 0 | D14: =+D13-'Historical Financials'!D11 -> 0 | E14: =+E13-'Historical Financials'!E11 -> 0 | F14: =+F13-'Historical Financials'!F11 -> 0 | H14: =+H13-'Historical Financials'!H11 -> 0 | I14: =+I13-'Historical Financials'!I11 -> 0 | J14: =+J13-'Historical Financials'!J11 -> 0 | K14: =+K13-'Historical Financials'!K11 -> 0 | L14: =+L13-'Historical Financials'!L11 -> 0 | M14: =+M13-'Historical Financials'!M11 -> 0 | N14: =+N13-'Historical Financials'!N11 -> 0 | O14: =+O13-'Historical Financials'!O11 -> 0 | ... T14: =+T13-'Historical Financials'!T11 -> 0 | V14: =+V13-'Historical Financials'!V11 -> 0 | W14: =+W13-'Historical Financials'!W11 -> 0 | X14: =+X13-'Historical Financials'!X11 -> 0 | Y14: =+Y13-'Historical Financials'!Y11 -> 0 | Z14: =+Z13-'Historical Financials'!Z11 -> 0 | AA14: =+AA13-'Historical Financials'!AA11 -> 0 | AB14: =+AB13-'Historical Financials'!AB11 -> 0 | AC14: =+AC13-'Historical Financials'!AC11 -> 0 | ... AE14: =+AE13-'Historical Financials'!AE11 -> 0
B16: =B9&"(%)" -> Network revenue (%) | C16: =SUM(C9/C$13) -> 0.41444476 | D16: =SUM(D9/D$13) -> 0.39480096 | E16: =SUM(E9/E$13) -> 0.35557828 | F16: =SUM(F9/F$13) -> 0.34547902 | H16: =SUM(H9/H$13) -> 0.38674701 | I16: =SUM(I9/I$13) -> 0.40829116 | J16: =SUM(J9/J$13) -> 0.38973904 | K16: =SUM(K9/K$13) -> 0.39356923 | L16: =SUM(L9/L$13) -> 0.36134747 | M16: =SUM(M9/M$13) -> 0.3850823 | N16: =SUM(N9/N$13) -> 0.33839388 | O16: =SUM(O9/O$13) -> 0.33979535 | ... T16: =SUM(T9/T$13) -> 0.34336687 | V16: =I16 -> 0.40829116 | W16: =J16 -> 0.38973904 | X16: =K16 -> 0.39356923 | Y16: =L16 -> 0.36134747 | Z16: =M16 -> 0.3850823 | AA16: =N16 -> 0.33839388 | AB16: =O16 -> 0.33979535 | AC16: =P16 -> 0.33189115 | ... AE16: =R16 -> 0.34801835
B17: =B10&"(%)" -> Interest Income (%) | C17: =SUM(C10/C$13) -> 0.3912274 | D17: =SUM(D10/D$13) -> 0.43150093 | E17: =SUM(E10/E$13) -> 0.51844835 | F17: =SUM(F10/F$13) -> 0.49876443 | H17: =SUM(H10/H$13) -> 0.37829901 | I17: =SUM(I10/I$13) -> 0.38873205 | J17: =SUM(J10/J$13) -> 0.46792728 | K17: =SUM(K10/K$13) -> 0.48185723 | L17: =SUM(L10/L$13) -> 0.52901135 | M17: =SUM(M10/M$13) -> 0.4878043 | N17: =SUM(N10/N$13) -> 0.54796175 | O17: =SUM(O10/O$13) -> 0.51217488 | ... T17: =SUM(T10/T$13) -> 0.48655737 | V17: =I17 -> 0.38873205 | W17: =J17 -> 0.46792728 | X17: =K17 -> 0.48185723 | Y17: =L17 -> 0.52901135 | Z17: =M17 -> 0.4878043 | AA17: =N17 -> 0.54796175 | AB17: =O17 -> 0.51217488 | AC17: =P17 -> 0.53983584 | ... AE17: =R17 -> 0.51421723
B18: =B11&"(%)" -> Gain (loss) on sales of loans (%) | C18: =SUM(C11/C$13) -> 0.14558376 | D18: =SUM(D11/D$13) -> 0.11860377 | E18: =SUM(E11/E$13) -> 0.084870032 | F18: =SUM(F11/F$13) -> 0.11835406 | H18: =SUM(H11/H$13) -> 0.17585946 | I18: =SUM(I11/I$13) -> 0.14918235 | J18: =SUM(J11/J$13) -> 0.086128333 | K18: =SUM(K11/K$13) -> 0.072508271 | L18: =SUM(L11/L$13) -> 0.069046837 | M18: =SUM(M11/M$13) -> 0.089157686 | N18: =SUM(N11/N$13) -> 0.069743143 | O18: =SUM(O11/O$13) -> 0.10616595 | ... T18: =SUM(T11/T$13) -> 0.127552 | V18: =I18 -> 0.14918235 | W18: =J18 -> 0.086128333 | X18: =K18 -> 0.072508271 | Y18: =L18 -> 0.069046837 | Z18: =M18 -> 0.089157686 | AA18: =N18 -> 0.069743143 | AB18: =O18 -> 0.10616595 | AC18: =P18 -> 0.091073604 | ... AE18: =R18 -> 0.096839111
B19: =B12&"(%)" -> Servicing income (%) | C19: =SUM(C12/C$13) -> 0.048744082 | D19: =SUM(D12/D$13) -> 0.055094349 | E19: =SUM(E12/E$13) -> 0.041103332 | F19: =SUM(F12/F$13) -> 0.037402502 | H19: =SUM(H12/H$13) -> 0.059094529 | I19: =SUM(I12/I$13) -> 0.053794443 | J19: =SUM(J12/J$13) -> 0.056205345 | K19: =SUM(K12/K$13) -> 0.052065272 | L19: =SUM(L12/L$13) -> 0.040594345 | M19: =SUM(M12/M$13) -> 0.03795571 | N19: =SUM(N12/N$13) -> 0.043901228 | O19: =SUM(O12/O$13) -> 0.041863817 | ... T19: =SUM(T12/T$13) -> 0.042523762 | V19: =I19 -> 0.053794443 | W19: =J19 -> 0.056205345 | X19: =K19 -> 0.052065272 | Y19: =L19 -> 0.040594345 | Z19: =M19 -> 0.03795571 | AA19: =N19 -> 0.043901228 | AB19: =O19 -> 0.041863817 | AC19: =P19 -> 0.0371994 | ... AE19: =R19 -> 0.040925308
A21: X | B21: KPIs
A23: X | B23: Gross Merchandise Volume (GMV)
B24: GMW | C24: 15483 | D24: 20186 | E24: 26600 | F24: 36700 | H24: 4389 | I24: 5658 | J24: 4639 | K24: =SUM(D24-SUM(H24:J24)) -> 5500 | L24: 5600 | M24: 7500 | N24: 6300 | O24: =SUM(E24-SUM(L24:N24)) -> 7200 | P24: 7600 | Q24: 10100 | R24: 8600 | S24: =SUM(F24-SUM(P24:R24)) -> 10400 | T24: 10758 | V24: =SUM(H24:K24) -> 20186 | W24: =SUM(I24:L24) -> 21397 | X24: =SUM(J24:M24) -> 23239 | Y24: =SUM(K24:N24) -> 24900 | Z24: =SUM(L24:O24) -> 26600 | AA24: =SUM(M24:P24) -> 28600 | AB24: =SUM(N24:Q24) -> 31200 | AC24: =SUM(O24:R24) -> 33500 | ... AE24: =SUM(Q24:T24) -> 39858
B25: Total GMW | C25: =SUM(C24:C24) -> 15483 | D25: =SUM(D24:D24) -> 20186 | E25: =SUM(E24:E24) -> 26600 | F25: =SUM(F24:F24) -> 36700 | H25: =SUM(H24:H24) -> 4389 | I25: =SUM(I24:I24) -> 5658 | J25: =SUM(J24:J24) -> 4639 | K25: =SUM(K24:K24) -> 5500 | L25: =SUM(L24:L24) -> 5600 | M25: =SUM(M24:M24) -> 7500 | N25: =SUM(N24:N24) -> 6300 | O25: =SUM(O24:O24) -> 7200 | ... T25: =SUM(T24:T24) -> 10758 | V25: =SUM(V24:V24) -> 20186 | W25: =SUM(W24:W24) -> 21397 | X25: =SUM(X24:X24) -> 23239 | Y25: =SUM(Y24:Y24) -> 24900 | Z25: =SUM(Z24:Z24) -> 26600 | AA25: =SUM(AA24:AA24) -> 28600 | AB25: =SUM(AB24:AB24) -> 31200 | AC25: =SUM(AC24:AC24) -> 33500 | ... AE25: =SUM(AE24:AE24) -> 39858
B26: Y/Y Growth (%) | D26: =SUM(D25/C25)-1 -> 0.3037525 | E26: =SUM(E25/D25)-1 -> 0.31774497 | F26: =SUM(F25/E25)-1 -> 0.37969925 | L26: =SUM(L25/H25)-1 -> 0.27591707 | M26: =SUM(M25/I25)-1 -> 0.32555673 | N26: =SUM(N25/J25)-1 -> 0.3580513 | O26: =SUM(O25/K25)-1 -> 0.30909091 | P26: =SUM(P25/L25)-1 -> 0.35714286 | Q26: =SUM(Q25/M25)-1 -> 0.34666667 | R26: =SUM(R25/N25)-1 -> 0.36507937 | S26: =SUM(S25/O25)-1 -> 0.44444444 | T26: =SUM(T25/P25)-1 -> 0.41552632 | V26: =K26 -> 0 | W26: =L26 -> 0.27591707 | X26: =M26 -> 0.32555673 | Y26: =N26 -> 0.3580513 | Z26: =O26 -> 0.30909091 | AA26: =P26 -> 0.35714286 | AB26: =Q26 -> 0.34666667 | AC26: =R26 -> 0.36507937 | ... AE26: =T26 -> 0.41552632
B27: Q/Q Growth (%) | C27: N/A | D27: N/A | E27: N/A | F27: N/A | I27: =SUM(I25/H25)-1 -> 0.28913192 | J27: =SUM(J25/I25)-1 -> -0.18009897 | K27: =SUM(K25/J25)-1 -> 0.18560034 | L27: =SUM(L25/K25)-1 -> 0.018181818 | M27: =SUM(M25/L25)-1 -> 0.33928571 | N27: =SUM(N25/M25)-1 -> -0.16 | O27: =SUM(O25/N25)-1 -> 0.14285714 | P27: =SUM(P25/O25)-1 -> 0.055555556 | ... T27: =SUM(T25/S25)-1 -> 0.034423077 | V27: N/A | W27: N/A | X27: N/A | Y27: N/A | Z27: N/A | AA27: N/A | AB27: N/A | AC27: N/A | AD27: N/A | AE27: N/A
A29: X | B29: Merchants
B30: <=$1,000 TTM GMV | C30: 152000 | D30: 158000 | E30: 180000 | F30: 222000 | H30: 157000 | I30: 153000 | J30: 153000 | K30: =D30 -> 158000 | L30: 163000 | M30: 170000 | N30: 176000 | O30: =E30 -> 180000 | P30: 194000 | Q30: 201000 | R30: 210000 | S30: =F30 -> 222000 | T30: 251000 | V30: =K30 -> 158000 | W30: =L30 -> 163000 | X30: =M30 -> 170000 | Y30: =N30 -> 176000 | Z30: =O30 -> 180000 | AA30: =P30 -> 194000 | AB30: =Q30 -> 201000 | AC30: =R30 -> 210000 | ... AE30: =T30 -> 251000
B31: >$1,000 TTM GMV | C31: 83000 | D31: 96000 | E31: 123000 | F31: 155000 | H31: 88000 | I31: 90000 | J31: 92000 | K31: =D31 -> 96000 | L31: 103000 | M31: 109000 | N31: 117000 | O31: =E31 -> 123000 | P31: 129000 | Q31: 136000 | R31: 148000 | S31: =F31 -> 155000 | T31: 168000 | V31: =K31 -> 96000 | W31: =L31 -> 103000 | X31: =M31 -> 109000 | Y31: =N31 -> 117000 | Z31: =O31 -> 123000 | AA31: =P31 -> 129000 | AB31: =Q31 -> 136000 | AC31: =R31 -> 148000 | ... AE31: =T31 -> 168000
B32: Total Active Merchants | C32: =SUM(C30:C31) -> 235000 | D32: =SUM(D30:D31) -> 254000 | E32: =SUM(E30:E31) -> 303000 | F32: =SUM(F30:F31) -> 377000 | H32: =SUM(H30:H31) -> 245000 | I32: =SUM(I30:I31) -> 243000 | J32: =SUM(J30:J31) -> 245000 | K32: =SUM(K30:K31) -> 254000 | L32: =SUM(L30:L31) -> 266000 | M32: =SUM(M30:M31) -> 279000 | N32: =SUM(N30:N31) -> 293000 | O32: =SUM(O30:O31) -> 303000 | ... T32: =SUM(T30:T31) -> 419000 | V32: =SUM(V30:V31) -> 254000 | W32: =SUM(W30:W31) -> 266000 | X32: =SUM(X30:X31) -> 279000 | Y32: =SUM(Y30:Y31) -> 293000 | Z32: =SUM(Z30:Z31) -> 303000 | AA32: =SUM(AA30:AA31) -> 323000 | AB32: =SUM(AB30:AB31) -> 337000 | AC32: =SUM(AC30:AC31) -> 358000 | ... AE32: =SUM(AE30:AE31) -> 419000
B33: Y/Y Growth (%) | D33: =SUM(D32/C32)-1 -> 0.080851064 | E33: =SUM(E32/D32)-1 -> 0.19291339 | F33: =SUM(F32/E32)-1 -> 0.24422442 | L33: =SUM(L32/H32)-1 -> 0.085714286 | M33: =SUM(M32/I32)-1 -> 0.14814815 | N33: =SUM(N32/J32)-1 -> 0.19591837 | O33: =SUM(O32/K32)-1 -> 0.19291339 | P33: =SUM(P32/L32)-1 -> 0.21428571 | Q33: =SUM(Q32/M32)-1 -> 0.2078853 | R33: =SUM(R32/N32)-1 -> 0.221843 | S33: =SUM(S32/O32)-1 -> 0.24422442 | T33: =SUM(T32/P32)-1 -> 0.29721362 | V33: =K33 -> 0 | W33: =L33 -> 0.085714286 | X33: =M33 -> 0.14814815 | Y33: =N33 -> 0.19591837 | Z33: =O33 -> 0.19291339 | AA33: =P33 -> 0.21428571 | AB33: =Q33 -> 0.2078853 | AC33: =R33 -> 0.221843 | ... AE33: =T33 -> 0.29721362
B34: Q/Q Growth (%) | C34: N/A | D34: N/A | E34: N/A | F34: N/A | I34: =SUM(I32/H32)-1 -> -0.0081632653 | J34: =SUM(J32/I32)-1 -> 0.0082304527 | K34: =SUM(K32/J32)-1 -> 0.036734694 | L34: =SUM(L32/K32)-1 -> 0.047244094 | M34: =SUM(M32/L32)-1 -> 0.04887218 | N34: =SUM(N32/M32)-1 -> 0.050179211 | O34: =SUM(O32/N32)-1 -> 0.034129693 | P34: =SUM(P32/O32)-1 -> 0.066006601 | ... T34: =SUM(T32/S32)-1 -> 0.11140584 | V34: N/A | W34: N/A | X34: N/A | Y34: N/A | Z34: N/A | AA34: N/A | AB34: N/A | AC34: N/A | AD34: N/A | AE34: N/A
A36: X | B36: Total Loans Sold
B37: Loans sold | C37: =C42*C25 -> 7100.61 | D37: =D42*D25 -> 7500 | E37: =E42*E25 -> 10200 | F37: =F42*F25 -> 15800 | H37: =H42*H25 -> 2018.94 | I37: =I42*I25 -> 2093.46 | J37: =J42*J25 -> 1716.43 | K37: =K42*K25 -> 1671.17 | L37: =L42*L25 -> 2576 | M37: =M42*M25 -> 3100 | N37: =N42*N25 -> 2100 | O37: =O42*O25 -> 2424 | ... T37: =T42*T25 -> 4930 | V37: =SUM(H37:K37) -> 7500 | W37: =SUM(I37:L37) -> 8057.06 | X37: =SUM(J37:M37) -> 9063.6 | Y37: =SUM(K37:N37) -> 9447.17 | Z37: =SUM(L37:O37) -> 10200 | AA37: =SUM(M37:P37) -> 10424 | AB37: =SUM(N37:Q37) -> 11924 | AC37: =SUM(O37:R37) -> 13424 | ... AE37: =SUM(Q37:T37) -> 17930
B38: Total Active Merchants | C38: =C37 -> 7100.61 | D38: =D37 -> 7500 | E38: =E37 -> 10200 | F38: =F37 -> 15800 | H38: =H37 -> 2018.94 | I38: =I37 -> 2093.46 | J38: =J37 -> 1716.43 | K38: =K37 -> 1671.17 | L38: =L37 -> 2576 | M38: =M37 -> 3100 | N38: =N37 -> 2100 | O38: =O37 -> 2424 | ... T38: =T37 -> 4930 | V38: =V37 -> 7500 | W38: =W37 -> 8057.06 | X38: =X37 -> 9063.6 | Y38: =Y37 -> 9447.17 | Z38: =Z37 -> 10200 | AA38: =AA37 -> 10424 | AB38: =AB37 -> 11924 | AC38: =AC37 -> 13424 | ... AE38: =AE37 -> 17930
B39: Y/Y Growth (%) | D39: =SUM(D38/C38)-1 -> 0.05624728 | E39: =SUM(E38/D38)-1 -> 0.36 | F39: =SUM(F38/E38)-1 -> 0.54901961 | L39: =SUM(L38/H38)-1 -> 0.27591707 | M39: =SUM(M38/I38)-1 -> 0.48080212 | N39: =SUM(N38/J38)-1 -> 0.22346964 | O39: =SUM(O38/K38)-1 -> 0.4504808 | P39: =SUM(P38/L38)-1 -> 0.086956522 | Q39: =SUM(Q38/M38)-1 -> 0.48387097 | R39: =SUM(R38/N38)-1 -> 0.71428571 | S39: =SUM(S38/O38)-1 -> 0.98019802 | T39: =SUM(T38/P38)-1 -> 0.76071429 | V39: =K39 -> 0 | W39: =L39 -> 0.27591707 | X39: =M39 -> 0.48080212 | Y39: =N39 -> 0.22346964 | Z39: =O39 -> 0.4504808 | AA39: =P39 -> 0.086956522 | AB39: =Q39 -> 0.48387097 | AC39: =R39 -> 0.71428571 | ... AE39: =T39 -> 0.76071429
B40: Q/Q Growth (%) | C40: N/A | D40: N/A | E40: N/A | F40: N/A | I40: =SUM(I38/H38)-1 -> 0.036910458 | J40: =SUM(J38/I38)-1 -> -0.18009897 | K40: =SUM(K38/J38)-1 -> -0.026368684 | L40: =SUM(L38/K38)-1 -> 0.54143504 | M40: =SUM(M38/L38)-1 -> 0.20341615 | N40: =SUM(N38/M38)-1 -> -0.32258065 | O40: =SUM(O38/N38)-1 -> 0.15428571 | P40: =SUM(P38/O38)-1 -> 0.15511551 | ... T40: =SUM(T38/S38)-1 -> 0.027083333 | V40: N/A | W40: N/A | X40: N/A | Y40: N/A | Z40: N/A | AA40: N/A | AB40: N/A | AC40: N/A | AD40: N/A | AE40: N/A
B42: (%) of GMV sold | C42: 0.45860686 | D42: 0.37154463 | E42: 0.38345865 | F42: 0.43051771 | H42: 0.46 | I42: 0.37 | J42: 0.37 | K42: 0.30384909 | L42: 0.46 | M42: 0.41333333 | N42: 0.33333333 | O42: 0.33666667 | P42: 0.36842105 | Q42: 0.45544554 | R42: 0.41860465 | S42: 0.46153846 | T42: 0.45826362 | V42: =K42 -> 0.30384909 | W42: =L42 -> 0.46 | X42: =M42 -> 0.41333333 | Y42: =N42 -> 0.33333333 | Z42: =O42 -> 0.33666667 | AA42: =P42 -> 0.36842105 | AB42: =Q42 -> 0.45544554 | AC42: =R42 -> 0.41860465 | ... AE42: =T42 -> 0.45826362
A44: X | B44: GMV per active customer
B45: GMV per active customer | V45: =K45 -> 0 | W45: =L45 -> 0 | X45: =M45 -> 0 | Y45: =N45 -> 0 | Z45: =O45 -> 0 | AA45: =P45 -> 0 | AB45: =Q45 -> 0 | AC45: =R45 -> 0 | ... AE45: =T45 -> 0
B46: GMV per active customer | C46: =SUM(C45:C45) -> 0 | D46: =SUM(D45:D45) -> 0 | E46: =SUM(E45:E45) -> 0 | F46: =SUM(F45:F45) -> 0 | H46: =SUM(H45:H45) -> 0 | I46: =SUM(I45:I45) -> 0 | J46: =SUM(J45:J45) -> 0 | K46: =SUM(K45:K45) -> 0 | L46: =SUM(L45:L45) -> 0 | M46: =SUM(M45:M45) -> 0 | N46: =SUM(N45:N45) -> 0 | O46: =SUM(O45:O45) -> 0 | ... T46: =SUM(T45:T45) -> 0 | V46: =SUM(V45:V45) -> 0 | W46: =SUM(W45:W45) -> 0 | X46: =SUM(X45:X45) -> 0 | Y46: =SUM(Y45:Y45) -> 0 | Z46: =SUM(Z45:Z45) -> 0 | AA46: =SUM(AA45:AA45) -> 0 | AB46: =SUM(AB45:AB45) -> 0 | AC46: =SUM(AC45:AC45) -> 0 | ... AE46: =SUM(AE45:AE45) -> 0
B47: Y/Y Growth (%) | D47: =SUM(D46/C46)-1 -> #DIV/0! | E47: =SUM(E46/D46)-1 -> #DIV/0! | F47: =SUM(F46/E46)-1 -> #DIV/0! | L47: =SUM(L46/H46)-1 -> #DIV/0! | M47: =SUM(M46/I46)-1 -> #DIV/0! | N47: =SUM(N46/J46)-1 -> #DIV/0! | O47: =SUM(O46/K46)-1 -> #DIV/0! | P47: =SUM(P46/L46)-1 -> #DIV/0! | Q47: =SUM(Q46/M46)-1 -> #DIV/0! | R47: =SUM(R46/N46)-1 -> #DIV/0! | S47: =SUM(S46/O46)-1 -> #DIV/0! | T47: =SUM(T46/P46)-1 -> #DIV/0! | V47: =K47 -> 0 | W47: =L47 -> #DIV/0! | X47: =M47 -> #DIV/0! | Y47: =N47 -> #DIV/0! | Z47: =O47 -> #DIV/0! | AA47: =P47 -> #DIV/0! | AB47: =Q47 -> #DIV/0! | AC47: =R47 -> #DIV/0! | ... AE47: =T47 -> #DIV/0!
B48: Q/Q Growth (%) | C48: N/A | D48: N/A | E48: N/A | F48: N/A | I48: =SUM(I46/H46)-1 -> #DIV/0! | J48: =SUM(J46/I46)-1 -> #DIV/0! | K48: =SUM(K46/J46)-1 -> #DIV/0! | L48: =SUM(L46/K46)-1 -> #DIV/0! | M48: =SUM(M46/L46)-1 -> #DIV/0! | N48: =SUM(N46/M46)-1 -> #DIV/0! | O48: =SUM(O46/N46)-1 -> #DIV/0! | P48: =SUM(P46/O46)-1 -> #DIV/0! | ... T48: =SUM(T46/S46)-1 -> #DIV/0! | V48: N/A | W48: N/A | X48: N/A | Y48: N/A | Z48: N/A | AA48: N/A | AB48: N/A | AC48: N/A | AD48: N/A | AE48: N/A
A50: X | B50: GMV % Mix by loan type
B51: Core 0% APR | C51: 3899 | D51: 2684.65 | E51: 3052 | F51: 4723 | H51: 818 | I51: 565.8 | J51: 695.85 | K51: =SUM(D51-SUM(H51:J51)) -> 605 | L51: 616 | M51: 825 | N51: 819 | O51: =SUM(E51-SUM(L51:N51)) -> 792 | P51: 836 | Q51: 1313 | R51: 1118 | S51: =SUM(F51-SUM(P51:R51)) -> 1456 | T51: 1398.54 | V51: =SUM(H51:K51) -> 2684.65 | W51: =SUM(I51:L51) -> 2482.65 | X51: =SUM(J51:M51) -> 2741.85 | Y51: =SUM(K51:N51) -> 2865 | Z51: =SUM(L51:O51) -> 3052 | AA51: =SUM(M51:P51) -> 3272 | AB51: =SUM(N51:Q51) -> 3760 | AC51: =SUM(O51:R51) -> 4059 | ... AE51: =SUM(Q51:T51) -> 5285.54
...

Sheet FCF
B2: ='Historical Financials'!B2 -> Affirm Holdings Inc (NASDAQ: AFRM) | D2: FYE | H2: Quarterly | R2: Quarterly | Z2: LTM | AA2: LTM | AG2: Variance
B3: FCF Analysis | C3: ='Historical Financials'!C7 -> 2022 | D3: ='Historical Financials'!D7 -> 2023 | E3: ='Historical Financials'!E7 -> 2024 | F3: ='Historical Financials'!F7 -> 2025 | H3: ='Historical Financials'!H7 -> 1Q23 | I3: ='Historical Financials'!I7 -> 2Q23 | J3: ='Historical Financials'!J7 -> 3Q23 | K3: ='Historical Financials'!K7 -> 4Q23 | L3: ='Historical Financials'!L7 -> 1Q24 | M3: ='Historical Financials'!M7 -> 2Q24 | N3: ='Historical Financials'!N7 -> 3Q24 | O3: ='Historical Financials'!O7 -> 4Q24 | ... T3: ='Historical Financials'!T7 -> 1Q26 | V3: =K3 -> 4Q23 | W3: =L3 -> 1Q24 | X3: =M3 -> 2Q24 | Y3: =N3 -> 3Q24 | Z3: =O3 -> 4Q24 | AA3: =P3 -> 1Q25 | AB3: =Q3 -> 2Q25 | AC3: =R3 -> 3Q25 | ... AE3: =T3 -> 1Q26
B4: ($ In Millions) | C4: ='Historical Financials'!C8 -> 44713 | D4: ='Historical Financials'!D8 -> 45078 | E4: ='Historical Financials'!E8 -> 45444 | F4: ='Historical Financials'!F8 -> 45809 | H4: ='Historical Financials'!H8 -> 44805 | I4: ='Historical Financials'!I8 -> 44896 | J4: ='Historical Financials'!J8 -> 44986 | K4: ='Historical Financials'!K8 -> 45078 | L4: ='Historical Financials'!L8 -> 45170 | M4: ='Historical Financials'!M8 -> 45261 | N4: ='Historical Financials'!N8 -> 45352 | O4: ='Historical Financials'!O8 -> 45444 | ... T4: ='Historical Financials'!T8 -> 45901 | V4: =K4 -> 45078 | W4: =L4 -> 45170 | X4: =M4 -> 45261 | Y4: =N4 -> 45352 | Z4: =O4 -> 45444 | AA4: =P4 -> 45536 | AB4: =Q4 -> 45627 | AC4: =R4 -> 45717 | ... AE4: =T4 -> 45901
B6: ='Revenue Drivers'!B9 -> Network revenue | C6: ='Revenue Drivers'!C9 -> 559.207 | D6: ='Revenue Drivers'!D9 -> 626.938 | E6: ='Revenue Drivers'!E9 -> 826.008 | F6: ='Revenue Drivers'!F9 -> 1113.966 | H6: ='Revenue Drivers'!H9 -> 139.857 | I6: ='Revenue Drivers'!I9 -> 163.136 | J6: ='Revenue Drivers'!J9 -> 148.482 | K6: ='Revenue Drivers'!K9 -> 175.463 | L6: ='Revenue Drivers'!L9 -> 179.426 | M6: ='Revenue Drivers'!M9 -> 227.626 | N6: ='Revenue Drivers'!N9 -> 194.968 | O6: ='Revenue Drivers'!O9 -> 223.988 | ... T6: ='Revenue Drivers'!T9 -> 320.477 | V6: =SUM(H6:K6) -> 626.938 | W6: =SUM(I6:L6) -> 666.507 | X6: =SUM(J6:M6) -> 730.997 | Y6: =SUM(K6:N6) -> 777.483 | Z6: =SUM(L6:O6) -> 826.008 | AA6: =SUM(M6:P6) -> 878.401 | AB6: =SUM(N6:Q6) -> 953.812 | AC6: =SUM(O6:R6) -> 1031.389 | ... AE6: =SUM(Q6:T6) -> 1202.624 | AG6: =SUM(AE6/AA6)-1 -> 0.36910591
B7: ='Revenue Drivers'!B10 -> Interest Income | C7: ='Revenue Drivers'!C10 -> 527.88 | D7: ='Revenue Drivers'!D10 -> 685.217 | E7: ='Revenue Drivers'!E10 -> 1204.355 | F7: ='Revenue Drivers'!F10 -> 1608.221 | H7: ='Revenue Drivers'!H10 -> 136.802 | I7: ='Revenue Drivers'!I10 -> 155.321 | J7: ='Revenue Drivers'!J10 -> 178.27 | K7: ='Revenue Drivers'!K10 -> 214.824 | L7: ='Revenue Drivers'!L10 -> 262.679 | M7: ='Revenue Drivers'!M10 -> 288.346 | N7: ='Revenue Drivers'!N10 -> 315.712 | O7: ='Revenue Drivers'!O10 -> 337.618 | ... T7: ='Revenue Drivers'!T10 -> 454.122 | V7: =SUM(H7:K7) -> 685.217 | W7: =SUM(I7:L7) -> 811.094 | X7: =SUM(J7:M7) -> 944.119 | Y7: =SUM(K7:N7) -> 1081.561 | Z7: =SUM(L7:O7) -> 1204.355 | AA7: =SUM(M7:P7) -> 1318.74 | AB7: =SUM(N7:Q7) -> 1439.761 | AC7: =SUM(O7:R7) -> 1526.75 | ... AE7: =SUM(Q7:T7) -> 1685.279 | AG7: =SUM(AE7/AA7)-1 -> 0.27794637
B8: ='Revenue Drivers'!B11 -> Gain (loss) on sales of loans | C8: ='Revenue Drivers'!C11 -> 196.435 | D8: ='Revenue Drivers'!D11 -> 188.341 | E8: ='Revenue Drivers'!E11 -> 197.153 | F8: ='Revenue Drivers'!F11 -> 381.622 | H8: ='Revenue Drivers'!H11 -> 63.595 | I8: ='Revenue Drivers'!I11 -> 59.607 | J8: ='Revenue Drivers'!J11 -> 32.813 | K8: ='Revenue Drivers'!K11 -> 32.326 | L8: ='Revenue Drivers'!L11 -> 34.285 | M8: ='Revenue Drivers'!M11 -> 52.702 | N8: ='Revenue Drivers'!N11 -> 40.183 | O8: ='Revenue Drivers'!O11 -> 69.983 | ... T8: ='Revenue Drivers'!T11 -> 119.049 | V8: =SUM(H8:K8) -> 188.341 | W8: =SUM(I8:L8) -> 159.031 | X8: =SUM(J8:M8) -> 152.126 | Y8: =SUM(K8:N8) -> 159.496 | Z8: =SUM(L8:O8) -> 197.153 | AA8: =SUM(M8:P8) -> 226.481 | AB8: =SUM(N8:Q8) -> 299.066 | AC8: =SUM(O8:R8) -> 334.721 | ... AE8: =SUM(Q8:T8) -> 437.058 | AG8: =SUM(AE8/AA8)-1 -> 0.92977777
B9: ='Revenue Drivers'!B12 -> Servicing income | C9: ='Revenue Drivers'!C12 -> 65.77 | D9: ='Revenue Drivers'!D12 -> 87.489 | E9: ='Revenue Drivers'!E12 -> 95.483 | F9: ='Revenue Drivers'!F12 -> 120.601 | H9: ='Revenue Drivers'!H12 -> 21.37 | I9: ='Revenue Drivers'!I12 -> 21.494 | J9: ='Revenue Drivers'!J12 -> 21.413 | K9: ='Revenue Drivers'!K12 -> 23.212 | L9: ='Revenue Drivers'!L12 -> 20.157 | M9: ='Revenue Drivers'!M12 -> 22.436 | N9: ='Revenue Drivers'!N12 -> 25.294 | O9: ='Revenue Drivers'!O12 -> 27.596 | ... T9: ='Revenue Drivers'!T12 -> 39.689 | V9: =SUM(H9:K9) -> 87.489 | W9: =SUM(I9:L9) -> 86.276 | X9: =SUM(J9:M9) -> 87.218 | Y9: =SUM(K9:N9) -> 91.099 | Z9: =SUM(L9:O9) -> 95.483 | AA9: =SUM(M9:P9) -> 101.309 | AB9: =SUM(N9:Q9) -> 107.563 | AC9: =SUM(O9:R9) -> 114.319 | ... AE9: =SUM(Q9:T9) -> 134.307 | AG9: =SUM(AE9/AA9)-1 -> 0.32571637
B10: Total Revenue | C10: =SUM(C6:C9) -> 1349.292 | D10: =SUM(D6:D9) -> 1587.985 | E10: =SUM(E6:E9) -> 2322.999 | F10: =SUM(F6:F9) -> 3224.41 | H10: =SUM(H6:H9) -> 361.624 | I10: =SUM(I6:I9) -> 399.558 | J10: =SUM(J6:J9) -> 380.978 | K10: =SUM(K6:K9) -> 445.825 | L10: =SUM(L6:L9) -> 496.547 | M10: =SUM(M6:M9) -> 591.11 | N10: =SUM(N6:N9) -> 576.157 | O10: =SUM(O6:O9) -> 659.185 | ... T10: =SUM(T6:T9) -> 933.337 | V10: =SUM(V6:V9) -> 1587.985 | W10: =SUM(W6:W9) -> 1722.908 | X10: =SUM(X6:X9) -> 1914.46 | Y10: =SUM(Y6:Y9) -> 2109.639 | Z10: =SUM(Z6:Z9) -> 2322.999 | AA10: =SUM(AA6:AA9) -> 2524.931 | AB10: =SUM(AB6:AB9) -> 2800.202 | AC10: =SUM(AC6:AC9) -> 3007.179 | ... AE10: =SUM(AE6:AE9) -> 3459.268 | AG10: =SUM(AE10/AA10)-1 -> 0.37004457
B11: Y/Y Growth (%) | D11: =SUM(D10/C10)-1 -> 0.17690241 | E11: =SUM(E10/D10)-1 -> 0.46285954 | F11: =SUM(F10/E10)-1 -> 0.38803762 | L11: =SUM(L10/H10)-1 -> 0.373103 | M11: =SUM(M10/I10)-1 -> 0.47940975 | N11: =SUM(N10/J10)-1 -> 0.51231042 | O11: =SUM(O10/K10)-1 -> 0.47857343 | P11: =SUM(P10/L10)-1 -> 0.40667248 | Q11: =SUM(Q10/M10)-1 -> 0.4656849 | R11: =SUM(R10/N10)-1 -> 0.35923715 | S11: =SUM(S10/O10)-1 -> 0.32954482 | T11: =SUM(T10/P10)-1 -> 0.33624203 | Z11: =SUM(Z10/V10)-1 -> 0.46285954 | AA11: =SUM(AA10/W10)-1 -> 0.46550541 | AB11: =SUM(AB10/X10)-1 -> 0.46265892 | AC11: =SUM(AC10/Y10)-1 -> 0.4254472 | AD11: =SUM(AD10/Z10)-1 -> 0.38803762 | AE11: =SUM(AE10/AA10)-1 -> 0.37004457 | AG11: =SUM(AE11-AA11)*10000 -> -954.60845
B12: Q/Q Growth (%) | C12: N/A | D12: N/A | E12: N/A | F12: N/A | I12: =SUM(I10/H10)-1 -> 0.10489901 | J12: =SUM(J10/I10)-1 -> -0.046501384 | K12: =SUM(K10/J10)-1 -> 0.17021193 | L12: =SUM(L10/K10)-1 -> 0.1137711 | M12: =SUM(M10/L10)-1 -> 0.19044119 | N12: =SUM(N10/M10)-1 -> -0.025296476 | O12: =SUM(O10/N10)-1 -> 0.14410655 | P12: =SUM(P10/O10)-1 -> 0.059609973 | ... T12: =SUM(T10/S10)-1 -> 0.064947468 | V12: N/A | W12: N/A | X12: N/A | Y12: N/A | Z12: N/A | AA12: N/A | AB12: N/A | AC12: N/A | AD12: N/A | AE12: N/A
B14: (-) Loss on loan purchase commitment | C14: ='Historical Financials'!C13 -> -204.081 | D14: ='Historical Financials'!D13 -> -140.265 | E14: ='Historical Financials'!E13 -> -180.395 | F14: ='Historical Financials'!F13 -> -242.264 | H14: ='Historical Financials'!H13 -> -35.61 | I14: ='Historical Financials'!I13 -> -38.422 | J14: ='Historical Financials'!J13 -> -31.224 | K14: ='Historical Financials'!K13 -> -35.009 | L14: ='Historical Financials'!L13 -> -34.866 | M14: ='Historical Financials'!M13 -> -53.63 | N14: ='Historical Financials'!N13 -> -44.143 | O14: ='Historical Financials'!O13 -> -47.756 | ... T14: ='Historical Financials'!T13 -> -71.552 | V14: =SUM(H14:K14) -> -140.265 | W14: =SUM(I14:L14) -> -139.521 | X14: =SUM(J14:M14) -> -154.729 | Y14: =SUM(K14:N14) -> -167.648 | Z14: =SUM(L14:O14) -> -180.395 | AA14: =SUM(M14:P14) -> -199.766 | AB14: =SUM(N14:Q14) -> -216.414 | AC14: =SUM(O14:R14) -> -229.561 | ... AE14: =SUM(Q14:T14) -> -259.579 | AG14: =SUM(AE14/AA14)-1 -> 0.29941532
B15: (-) Provision for credit losses | C15: ='Historical Financials'!C14 -> -255.272 | D15: ='Historical Financials'!D14 -> -331.86 | E15: ='Historical Financials'!E14 -> -460.628 | F15: ='Historical Financials'!F14 -> -616.683 | H15: ='Historical Financials'!H14 -> -64.25 | I15: ='Historical Financials'!I14 -> -106.689 | J15: ='Historical Financials'!J14 -> -66.438 | K15: ='Historical Financials'!K14 -> -94.483 | L15: ='Historical Financials'!L14 -> -99.696 | M15: ='Historical Financials'!M14 -> -120.88 | N15: ='Historical Financials'!N14 -> -122.443 | O15: ='Historical Financials'!O14 -> -117.609 | ... T15: ='Historical Financials'!T14 -> -162.752 | V15: =SUM(H15:K15) -> -331.86 | W15: =SUM(I15:L15) -> -367.306 | X15: =SUM(J15:M15) -> -381.497 | Y15: =SUM(K15:N15) -> -437.502 | Z15: =SUM(L15:O15) -> -460.628 | AA15: =SUM(M15:P15) -> -520.756 | AB15: =SUM(N15:Q15) -> -552.856 | AC15: =SUM(O15:R15) -> -577.665 | ... AE15: =SUM(Q15:T15) -> -619.611 | AG15: =SUM(AE15/AA15)-1 -> 0.18982979
B16: (-) Funding costs | C16: ='Historical Financials'!C15 -> -69.694 | D16: ='Historical Financials'!D15 -> -183.013 | E16: ='Historical Financials'!E15 -> -344.253 | F16: ='Historical Financials'!F15 -> -425.45 | H16: ='Historical Financials'!H15 -> -25.066 | I16: ='Historical Financials'!I15 -> -43.751 | J16: ='Historical Financials'!J15 -> -51.188 | K16: ='Historical Financials'!K15 -> -63.008 | L16: ='Historical Financials'!L15 -> -73.931 | M16: ='Historical Financials'!M15 -> -84.617 | N16: ='Historical Financials'!N15 -> -90.449 | O16: ='Historical Financials'!O15 -> -95.256 | ... T16: ='Historical Financials'!T15 -> -110.027 | V16: =SUM(H16:K16) -> -183.013 | W16: =SUM(I16:L16) -> -231.878 | X16: =SUM(J16:M16) -> -272.744 | Y16: =SUM(K16:N16) -> -312.005 | Z16: =SUM(L16:O16) -> -344.253 | AA16: =SUM(M16:P16) -> -374.467 | AB16: =SUM(N16:Q16) -> -397.612 | AC16: =SUM(O16:R16) -> -414.794 | ... AE16: =SUM(Q16:T16) -> -431.332 | AG16: =SUM(AE16/AA16)-1 -> 0.15185584
B17: (-) Processing and servicing | C17: ='Historical Financials'!C16 -> -157.814 | D17: ='Historical Financials'!D16 -> -257.343 | E17: ='Historical Financials'!E16 -> -343.249 | F17: ='Historical Financials'!F16 -> -457.849 | H17: ='Historical Financials'!H16 -> -54.359 | I17: ='Historical Financials'!I16 -> -66.508 | J17: ='Historical Financials'!J16 -> -65.229 | K17: ='Historical Financials'!K16 -> -71.247 | L17: ='Historical Financials'!L16 -> -75.671 | M17: ='Historical Financials'!M16 -> -90.203 | N17: ='Historical Financials'!N16 -> -88.209 | O17: ='Historical Financials'!O16 -> -89.166 | ... T17: ='Historical Financials'!T16 -> -133.807 | V17: =SUM(H17:K17) -> -257.343 | W17: =SUM(I17:L17) -> -278.655 | X17: =SUM(J17:M17) -> -302.35 | Y17: =SUM(K17:N17) -> -325.33 | Z17: =SUM(L17:O17) -> -343.249 | AA17: =SUM(M17:P17) -> -362.724 | AB17: =SUM(N17:Q17) -> -388.481 | AC17: =SUM(O17:R17) -> -418.67 | ... AE17: =SUM(Q17:T17) -> -496.51 | AG17: =SUM(AE17/AA17)-1 -> 0.36883691
B18: Gross Profit | C18: =SUM(C10+SUM(C14:C17)) -> 662.431 | D18: =SUM(D10+SUM(D14:D17)) -> 675.504 | E18: =SUM(E10+SUM(E14:E17)) -> 994.474 | F18: =SUM(F10+SUM(F14:F17)) -> 1482.164 | H18: =SUM(H10+SUM(H14:H17)) -> 182.339 | I18: =SUM(I10+SUM(I14:I17)) -> 144.188 | J18: =SUM(J10+SUM(J14:J17)) -> 166.899 | K18: =SUM(K10+SUM(K14:K17)) -> 182.078 | L18: =SUM(L10+SUM(L14:L17)) -> 212.383 | M18: =SUM(M10+SUM(M14:M17)) -> 241.78 | N18: =SUM(N10+SUM(N14:N17)) -> 230.913 | O18: =SUM(O10+SUM(O14:O17)) -> 309.398 | ... T18: =SUM(T10+SUM(T14:T17)) -> 455.199 | V18: =SUM(V10+SUM(V14:V17)) -> 675.504 | W18: =SUM(W10+SUM(W14:W17)) -> 705.548 | X18: =SUM(X10+SUM(X14:X17)) -> 803.14 | Y18: =SUM(Y10+SUM(Y14:Y17)) -> 867.154 | Z18: =SUM(Z10+SUM(Z14:Z17)) -> 994.474 | AA18: =SUM(AA10+SUM(AA14:AA17)) -> 1067.218 | AB18: =SUM(AB10+SUM(AB14:AB17)) -> 1244.839 | AC18: =SUM(AC10+SUM(AC14:AC17)) -> 1366.489 | ... AE18: =SUM(AE10+SUM(AE14:AE17)) -> 1652.236 | AG18: =SUM(AE18/AA18)-1 -> 0.54817104
B19: Gross Margin (%) | C19: =C18/C10 -> 0.4909471 | D19: =D18/D10 -> 0.42538437 | E19: =E18/E10 -> 0.42809919 | F19: =F18/F10 -> 0.45966983 | H19: =H18/H10 -> 0.50422262 | I19: =I18/I10 -> 0.36086876 | J19: =J18/J10 -> 0.43808041 | K19: =K18/K10 -> 0.40840689 | L19: =L18/L10 -> 0.42771983 | M19: =M18/M10 -> 0.40902708 | N19: =N18/N10 -> 0.40078138 | O19: =O18/O10 -> 0.46936444 | ... T19: =T18/T10 -> 0.4877113 | V19: =V18/V10 -> 0.42538437 | W19: =W18/W10 -> 0.40950997 | X19: =X18/X10 -> 0.41951255 | Y19: =Y18/Y10 -> 0.41104379 | Z19: =Z18/Z10 -> 0.42809919 | AA19: =AA18/AA10 -> 0.42267214 | AB19: =AB18/AB10 -> 0.44455329 | AC19: =AC18/AC10 -> 0.45440893 | ... AE19: =AE18/AE10 -> 0.4776259 | AG19: =SUM(AE19-AA19)*10000 -> 549.53758
B21: (-) Technology and data analytics | C21: ='Historical Financials'!C20 -> -418.643 | D21: ='Historical Financials'!D20 -> -615.818 | E21: ='Historical Financials'!E20 -> -501.857 | F21: ='Historical Financials'!F20 -> -589.723 | H21: ='Historical Financials'!H20 -> -144.961 | I21: ='Historical Financials'!I20 -> -156.747 | J21: ='Historical Financials'!J20 -> -161.792 | K21: ='Historical Financials'!K20 -> -152.318 | L21: ='Historical Financials'!L20 -> -132.965 | M21: ='Historical Financials'!M20 -> -119.833 | N21: ='Historical Financials'!N20 -> -124.828 | O21: ='Historical Financials'!O20 -> -124.231 | ... T21: ='Historical Financials'!T20 -> -168.106 | V21: =SUM(H21:K21) -> -615.818 | W21: =SUM(I21:L21) -> -603.822 | X21: =SUM(J21:M21) -> -566.908 | Y21: =SUM(K21:N21) -> -529.944 | Z21: =SUM(L21:O21) -> -501.857 | AA21: =SUM(M21:P21) -> -503.182 | AB21: =SUM(N21:Q21) -> -531.562 | AC21: =SUM(O21:R21) -> -559.354 | ... AE21: =SUM(Q21:T21) -> -623.539 | AG21: =SUM(AE21/AA21)-1 -> 0.23919178
B22: (-) Sales and marketing | C22: ='Historical Financials'!C21 -> -532.343 | D22: ='Historical Financials'!D21 -> -638.28 | E22: ='Historical Financials'!E21 -> -576.405 | F22: ='Historical Financials'!F21 -> -434.847 | H22: ='Historical Financials'!H21 -> -163.873 | I22: ='Historical Financials'!I21 -> -188.334 | J22: ='Historical Financials'!J21 -> -140.942 | K22: ='Historical Financials'!K21 -> -145.131 | L22: ='Historical Financials'!L21 -> -146.866 | M22: ='Historical Financials'!M21 -> -161.265 | N22: ='Historical Financials'!N21 -> -132.95 | O22: ='Historical Financials'!O21 -> -135.324 | ... T22: ='Historical Financials'!T21 -> -78.491 | V22: =SUM(H22:K22) -> -638.28 | W22: =SUM(I22:L22) -> -621.273 | X22: =SUM(J22:M22) -> -594.204 | Y22: =SUM(K22:N22) -> -586.212 | Z22: =SUM(L22:O22) -> -576.405 | AA22: =SUM(M22:P22) -> -574.772 | AB22: =SUM(N22:Q22) -> -549.545 | AC22: =SUM(O22:R22) -> -490.617 | ... AE22: =SUM(Q22:T22) -> -368.105 | AG22: =SUM(AE22/AA22)-1 -> -0.35956344
B23: (-) General and administrative | C23: ='Historical Financials'!C22 -> -577.493 | D23: ='Historical Financials'!D22 -> -586.398 | E23: ='Historical Financials'!E22 -> -525.291 | F23: ='Historical Financials'!F22 -> -545.053 | H23: ='Historical Financials'!H22 -> -160.972 | I23: ='Historical Financials'!I22 -> -158.639 | J23: ='Historical Financials'!J22 -> -139.266 | K23: ='Historical Financials'!K22 -> -127.521 | L23: ='Historical Financials'!L22 -> -140.334 | M23: ='Historical Financials'!M22 -> -132.777 | N23: ='Historical Financials'!N22 -> -128.721 | O23: ='Historical Financials'!O22 -> -123.459 | ... T23: ='Historical Financials'!T22 -> -144.941 | V23: =SUM(H23:K23) -> -586.398 | W23: =SUM(I23:L23) -> -565.76 | X23: =SUM(J23:M23) -> -539.898 | Y23: =SUM(K23:N23) -> -529.353 | Z23: =SUM(L23:O23) -> -525.291 | AA23: =SUM(M23:P23) -> -523.439 | AB23: =SUM(N23:Q23) -> -530.074 | AC23: =SUM(O23:R23) -> -535.656 | ... AE23: =SUM(Q23:T23) -> -551.512 | AG23: =SUM(AE23/AA23)-1 -> 0.053631846
