Workbook
Name IQ_CH: 110000
Name IQ_CQ: 5000
Name IQ_CY: 10000
Name IQ_DAILY: 500000
Name IQ_FH: 100000
Name IQ_FQ: 500
Name IQ_FY: 1000
Name IQ_LTM: 2000
Name IQ_MONTH: 15000
Name IQ_NTM: 6000
Name IQ_WEEK: 50000
Name IQ_YTD: 3000

Sheet Historical Financials
B2: ServiceNow, Inc. (NYSE: NOW)
B3: Historical Financials
B4: ($ In Millions, except EPS)
A6: X | B6: Income Statement | D6: FYE | H6: Quarterly | N6: Quarterly | P6: Quarterly | AA6: LTM | AG6: Variance
B7: Fiscal Period | C7: 2022 | D7: 2023 | E7: 2024 | F7: 2025 | H7: 1Q23 | I7: 2Q23 | J7: 3Q23 | K7: 4Q23 | L7: 1Q24 | M7: 2Q24 | N7: 3Q24 | O7: 4Q24 | P7: 1Q25 | Q7: 2Q25 | R7: 3Q25 | S7: 4Q25 | T7: 1Q26 | V7: =K7 -> 4Q23 | W7: =L7 -> 1Q24 | X7: =M7 -> 2Q24 | Y7: =N7 -> 3Q24 | Z7: =O7 -> 4Q24 | AA7: =P7 -> 1Q25 | AB7: =Q7 -> 2Q25 | AC7: =R7 -> 3Q25 | ... AE7: =T7 -> 1Q26
B8: Fiscal Period End Date | C8: 44926 | D8: 45291 | E8: 45657 | F8: 46022 | H8: 45016 | I8: 45107 | J8: 45199 | K8: =D8 -> 45291 | L8: 45382 | M8: 45473 | N8: 45565 | O8: =E8 -> 45657 | P8: 45747 | Q8: 45838 | R8: 45930 | S8: =F8 -> 46022 | T8: 46112 | V8: =K8 -> 45291 | W8: =L8 -> 45382 | X8: =M8 -> 45473 | Y8: =N8 -> 45565 | Z8: =O8 -> 45657 | AA8: =P8 -> 45747 | AB8: =Q8 -> 45838 | AC8: =R8 -> 45930 | ... AE8: =T8 -> 46112
B10: Consolidated Revenue | C10: 7245 | D10: 8971 | E10: 10984 | F10: 13278 | H10: 2096 | I10: 2150 | J10: 2288 | K10: =SUM(D10-SUM(H10:J10)) -> 2437 | L10: 2603 | M10: 2627 | N10: 2797 | O10: =SUM(E10-SUM(L10:N10)) -> 2957 | P10: 3088 | Q10: 3215 | R10: 3407 | S10: =SUM(F10-SUM(P10:R10)) -> 3568 | T10: 3770 | V10: =SUM(H10:K10) -> 8971 | W10: =SUM(I10:L10) -> 9478 | X10: =SUM(J10:M10) -> 9955 | Y10: =SUM(K10:N10) -> 10464 | Z10: =SUM(L10:O10) -> 10984 | AA10: =SUM(M10:P10) -> 11469 | AB10: =SUM(N10:Q10) -> 12057 | AC10: =SUM(O10:R10) -> 12667 | ... AE10: =SUM(Q10:T10) -> 13960 | AG10: =SUM(AE10/AA10)-1 -> 0.21719418
B11: Total Revenue | C11: =+SUM(C10:C10) -> 7245 | D11: =+SUM(D10:D10) -> 8971 | E11: =+SUM(E10:E10) -> 10984 | F11: =+SUM(F10:F10) -> 13278 | H11: =+SUM(H10:H10) -> 2096 | I11: =+SUM(I10:I10) -> 2150 | J11: =+SUM(J10:J10) -> 2288 | K11: =+SUM(K10:K10) -> 2437 | L11: =+SUM(L10:L10) -> 2603 | M11: =+SUM(M10:M10) -> 2627 | N11: =+SUM(N10:N10) -> 2797 | O11: =+SUM(O10:O10) -> 2957 | ... T11: =+SUM(T10:T10) -> 3770 | V11: =+SUM(V10:V10) -> 8971 | W11: =+SUM(W10:W10) -> 9478 | X11: =+SUM(X10:X10) -> 9955 | Y11: =+SUM(Y10:Y10) -> 10464 | Z11: =+SUM(Z10:Z10) -> 10984 | AA11: =+SUM(AA10:AA10) -> 11469 | AB11: =+SUM(AB10:AB10) -> 12057 | AC11: =+SUM(AC10:AC10) -> 12667 | ... AE11: =+SUM(AE10:AE10) -> 13960 | AG11: =SUM(AE11/AA11)-1 -> 0.21719418
B13: Subscription | C13: -1187 | D13: -1606 | E13: -1942 | F13: -2569 | H13: -354 | I13: -389 | J13: -420 | K13: =SUM(D13-SUM(H13:J13)) -> -443 | L13: -441 | M13: -469 | N13: -496 | O13: =SUM(E13-SUM(L13:N13)) -> -536 | P13: -561 | Q13: -625 | R13: -666 | S13: =SUM(F13-SUM(P13:R13)) -> -717 | T13: -820 | V13: =SUM(H13:K13) -> -1606 | W13: =SUM(I13:L13) -> -1693 | X13: =SUM(J13:M13) -> -1773 | Y13: =SUM(K13:N13) -> -1849 | Z13: =SUM(L13:O13) -> -1942 | AA13: =SUM(M13:P13) -> -2062 | AB13: =SUM(N13:Q13) -> -2218 | AC13: =SUM(O13:R13) -> -2388 | ... AE13: =SUM(Q13:T13) -> -2828 | AG13: =SUM(AE13/AA13)-1 -> 0.371484
B14: Professional Services Other | C14: -386 | D14: -315 | E14: -345 | F14: -414 | H14: -84 | I14: -82 | J14: -76 | K14: =SUM(D14-SUM(H14:J14)) -> -73 | L14: -79 | M14: -83 | N14: -88 | O14: =SUM(E14-SUM(L14:N14)) -> -95 | P14: -90 | Q14: -99 | R14: -108 | S14: =SUM(F14-SUM(P14:R14)) -> -117 | T14: -120 | V14: =SUM(H14:K14) -> -315 | W14: =SUM(I14:L14) -> -310 | X14: =SUM(J14:M14) -> -311 | Y14: =SUM(K14:N14) -> -323 | Z14: =SUM(L14:O14) -> -345 | AA14: =SUM(M14:P14) -> -356 | AB14: =SUM(N14:Q14) -> -372 | AC14: =SUM(O14:R14) -> -392 | ... AE14: =SUM(Q14:T14) -> -444 | AG14: =SUM(AE14/AA14)-1 -> 0.24719101
B15: Gross Profit | C15: =+SUM(C11+SUM(C13:C14)) -> 5672 | D15: =+SUM(D11+SUM(D13:D14)) -> 7050 | E15: =+SUM(E11+SUM(E13:E14)) -> 8697 | F15: =+SUM(F11+SUM(F13:F14)) -> 10295 | H15: =+SUM(H11+SUM(H13:H14)) -> 1658 | I15: =+SUM(I11+SUM(I13:I14)) -> 1679 | J15: =+SUM(J11+SUM(J13:J14)) -> 1792 | K15: =+SUM(K11+SUM(K13:K14)) -> 1921 | L15: =+SUM(L11+SUM(L13:L14)) -> 2083 | M15: =+SUM(M11+SUM(M13:M14)) -> 2075 | N15: =+SUM(N11+SUM(N13:N14)) -> 2213 | O15: =+SUM(O11+SUM(O13:O14)) -> 2326 | ... T15: =+SUM(T11+SUM(T13:T14)) -> 2830 | V15: =+SUM(V11+SUM(V13:V14)) -> 7050 | W15: =+SUM(W11+SUM(W13:W14)) -> 7475 | X15: =+SUM(X11+SUM(X13:X14)) -> 7871 | Y15: =+SUM(Y11+SUM(Y13:Y14)) -> 8292 | Z15: =+SUM(Z11+SUM(Z13:Z14)) -> 8697 | AA15: =+SUM(AA11+SUM(AA13:AA14)) -> 9051 | AB15: =+SUM(AB11+SUM(AB13:AB14)) -> 9467 | AC15: =+SUM(AC11+SUM(AC13:AC14)) -> 9887 | ... AE15: =+SUM(AE11+SUM(AE13:AE14)) -> 10688 | AG15: =SUM(AE15/AA15)-1 -> 0.18086399
B16: Gross Margin (%) | C16: =C15/C11 -> 0.78288475 | D16: =D15/D11 -> 0.78586557 | E16: =E15/E11 -> 0.79178806 | F16: =F15/F11 -> 0.77534267 | H16: =H15/H11 -> 0.79103053 | I16: =I15/I11 -> 0.78093023 | J16: =J15/J11 -> 0.78321678 | K16: =K15/K11 -> 0.78826426 | L16: =L15/L11 -> 0.8002305 | M16: =M15/M11 -> 0.78987438 | N16: =N15/N11 -> 0.79120486 | O16: =O15/O11 -> 0.78660805 | ... T16: =T15/T11 -> 0.75066313 | V16: =V15/V11 -> 0.78586557 | W16: =W15/W11 -> 0.7886685 | X16: =X15/X11 -> 0.79065796 | Y16: =Y15/Y11 -> 0.79243119 | Z16: =Z15/Z11 -> 0.79178806 | AA16: =AA15/AA11 -> 0.78917081 | AB16: =AB15/AB11 -> 0.78518703 | AC16: =AC15/AC11 -> 0.78053209 | ... AE16: =AE15/AE11 -> 0.76561605 | AG16: =SUM(AE16-AA16)*1000 -> -23.554762
B18: Sales and Marketing | C18: -2814 | D18: -3301 | E18: -3854 | F18: -4388 | H18: -823 | I18: -832 | J18: -799 | K18: =SUM(D18-SUM(H18:J18)) -> -847 | L18: -923 | M18: -960 | N18: -944 | O18: =SUM(E18-SUM(L18:N18)) -> -1027 | P18: -1054 | Q18: -1128 | R18: -1056 | S18: =SUM(F18-SUM(P18:R18)) -> -1150 | T18: -1216 | V18: =SUM(H18:K18) -> -3301 | W18: =SUM(I18:L18) -> -3401 | X18: =SUM(J18:M18) -> -3529 | Y18: =SUM(K18:N18) -> -3674 | Z18: =SUM(L18:O18) -> -3854 | AA18: =SUM(M18:P18) -> -3985 | AB18: =SUM(N18:Q18) -> -4153 | AC18: =SUM(O18:R18) -> -4265 | ... AE18: =SUM(Q18:T18) -> -4550 | AG18: =SUM(AE18/AA18)-1 -> 0.14178168
B19: General and Administrative | C19: -735 | D19: -863 | E19: -936 | F19: -1123 | H19: -199 | I19: -209 | J19: -213 | K19: =SUM(D19-SUM(H19:J19)) -> -242 | L19: -222 | M19: -232 | N19: -225 | O19: =SUM(E19-SUM(L19:N19)) -> -257 | P19: -229 | Q19: -271 | R19: -255 | S19: =SUM(F19-SUM(P19:R19)) -> -368 | T19: -288 | V19: =SUM(H19:K19) -> -863 | W19: =SUM(I19:L19) -> -886 | X19: =SUM(J19:M19) -> -909 | Y19: =SUM(K19:N19) -> -921 | Z19: =SUM(L19:O19) -> -936 | AA19: =SUM(M19:P19) -> -943 | AB19: =SUM(N19:Q19) -> -982 | AC19: =SUM(O19:R19) -> -1012 | ... AE19: =SUM(Q19:T19) -> -1182 | AG19: =SUM(AE19/AA19)-1 -> 0.25344645
B20: Research and Development | C20: -1768 | D20: -2124 | E20: -2543 | F20: -2960 | H20: -492 | I20: -521 | J20: -549 | K20: =SUM(D20-SUM(H20:J20)) -> -562 | L20: -606 | M20: -643 | N20: -626 | O20: =SUM(E20-SUM(L20:N20)) -> -668 | P20: -703 | Q20: -734 | R20: -750 | S20: =SUM(F20-SUM(P20:R20)) -> -773 | T20: -823 | V20: =SUM(H20:K20) -> -2124 | W20: =SUM(I20:L20) -> -2238 | X20: =SUM(J20:M20) -> -2360 | Y20: =SUM(K20:N20) -> -2437 | Z20: =SUM(L20:O20) -> -2543 | AA20: =SUM(M20:P20) -> -2640 | AB20: =SUM(N20:Q20) -> -2731 | AC20: =SUM(O20:R20) -> -2855 | ... AE20: =SUM(Q20:T20) -> -3080 | AG20: =SUM(AE20/AA20)-1 -> 0.16666667
B21: Operating Profit | C21: =+SUM(C15+SUM(C18:C20)) -> 355 | D21: =+SUM(D15+SUM(D18:D20)) -> 762 | E21: =+SUM(E15+SUM(E18:E20)) -> 1364 | F21: =+SUM(F15+SUM(F18:F20)) -> 1824 | H21: =+SUM(H15+SUM(H18:H20)) -> 144 | I21: =+SUM(I15+SUM(I18:I20)) -> 117 | J21: =+SUM(J15+SUM(J18:J20)) -> 231 | K21: =+SUM(K15+SUM(K18:K20)) -> 270 | L21: =+SUM(L15+SUM(L18:L20)) -> 332 | M21: =+SUM(M15+SUM(M18:M20)) -> 240 | N21: =+SUM(N15+SUM(N18:N20)) -> 418 | O21: =+SUM(O15+SUM(O18:O20)) -> 374 | ... T21: =+SUM(T15+SUM(T18:T20)) -> 503 | V21: =+SUM(V15+SUM(V18:V20)) -> 762 | W21: =+SUM(W15+SUM(W18:W20)) -> 950 | X21: =+SUM(X15+SUM(X18:X20)) -> 1073 | Y21: =+SUM(Y15+SUM(Y18:Y20)) -> 1260 | Z21: =+SUM(Z15+SUM(Z18:Z20)) -> 1364 | AA21: =+SUM(AA15+SUM(AA18:AA20)) -> 1483 | AB21: =+SUM(AB15+SUM(AB18:AB20)) -> 1601 | AC21: =+SUM(AC15+SUM(AC18:AC20)) -> 1755 | ... AE21: =+SUM(AE15+SUM(AE18:AE20)) -> 1876 | AG21: =SUM(AE21/AA21)-1 -> 0.26500337
B22: Operating Margin (%) | C22: =C21/C11 -> 0.04899931 | D22: =D21/D11 -> 0.084940363 | E22: =E21/E11 -> 0.12418063 | F22: =F21/F11 -> 0.13737009 | H22: =H21/H11 -> 0.06870229 | I22: =I21/I11 -> 0.054418605 | J22: =J21/J11 -> 0.10096154 | K22: =K21/K11 -> 0.11079196 | L22: =L21/L11 -> 0.12754514 | M22: =M21/M11 -> 0.091358965 | N22: =N21/N11 -> 0.14944583 | O22: =O21/O11 -> 0.12647954 | ... T22: =T21/T11 -> 0.13342175 | V22: =V21/V11 -> 0.084940363 | W22: =W21/W11 -> 0.10023212 | X22: =X21/X11 -> 0.10778503 | Y22: =Y21/Y11 -> 0.12041284 | Z22: =Z21/Z11 -> 0.12418063 | AA22: =AA21/AA11 -> 0.12930508 | AB22: =AB21/AB11 -> 0.13278593 | AC22: =AC21/AC11 -> 0.13854899 | ... AE22: =AE21/AE11 -> 0.13438395 | AG22: =SUM(AE22-AA22)*1000 -> 5.0788709
B24: Interest Income | C24: 82 | D24: 302 | E24: 419 | F24: 451 | H24: 60 | I24: 74 | J24: 82 | K24: =SUM(D24-SUM(H24:J24)) -> 86 | L24: 101 | M24: 104 | N24: 108 | O24: =SUM(E24-SUM(L24:N24)) -> 106 | P24: 115 | Q24: 116 | R24: 115 | S24: =SUM(F24-SUM(P24:R24)) -> 105 | T24: 88 | V24: =SUM(H24:K24) -> 302 | W24: =SUM(I24:L24) -> 343 | X24: =SUM(J24:M24) -> 373 | Y24: =SUM(K24:N24) -> 399 | Z24: =SUM(L24:O24) -> 419 | AA24: =SUM(M24:P24) -> 433 | AB24: =SUM(N24:Q24) -> 445 | AC24: =SUM(O24:R24) -> 452 | ... AE24: =SUM(Q24:T24) -> 424 | AG24: =SUM(AE24/AA24)-1 -> -0.020785219
B25: Other Income/expense-net | C25: -38 | D25: -56 | E25: -45 | F25: -14 | H25: -16 | I25: -17 | J25: -14 | K25: =SUM(D25-SUM(H25:J25)) -> -9 | L25: -8 | M25: -10 | N25: -10 | O25: =SUM(E25-SUM(L25:N25)) -> -17 | P25: -11 | Q25: -3 | R25: 7 | S25: =SUM(F25-SUM(P25:R25)) -> -7 | T25: 82 | V25: =SUM(H25:K25) -> -56 | W25: =SUM(I25:L25) -> -48 | X25: =SUM(J25:M25) -> -41 | Y25: =SUM(K25:N25) -> -37 | Z25: =SUM(L25:O25) -> -45 | AA25: =SUM(M25:P25) -> -48 | AB25: =SUM(N25:Q25) -> -41 | AC25: =SUM(O25:R25) -> -24 | ... AE25: =SUM(Q25:T25) -> 79 | AG25: =SUM(AE25/AA25)-1 -> -2.6458333
B26: Earnings before Taxes | C26: =SUM(C24:C25)+C21 -> 399 | D26: =SUM(D24:D25)+D21 -> 1008 | E26: =SUM(E24:E25)+E21 -> 1738 | F26: =SUM(F24:F25)+F21 -> 2261 | H26: =SUM(H24:H25)+H21 -> 188 | I26: =SUM(I24:I25)+I21 -> 174 | J26: =SUM(J24:J25)+J21 -> 299 | K26: =SUM(K24:K25)+K21 -> 347 | L26: =SUM(L24:L25)+L21 -> 425 | M26: =SUM(M24:M25)+M21 -> 334 | N26: =SUM(N24:N25)+N21 -> 516 | O26: =SUM(O24:O25)+O21 -> 463 | ... T26: =SUM(T24:T25)+T21 -> 673 | V26: =SUM(V24:V25)+V21 -> 1008 | W26: =SUM(W24:W25)+W21 -> 1245 | X26: =SUM(X24:X25)+X21 -> 1405 | Y26: =SUM(Y24:Y25)+Y21 -> 1622 | Z26: =SUM(Z24:Z25)+Z21 -> 1738 | AA26: =SUM(AA24:AA25)+AA21 -> 1868 | AB26: =SUM(AB24:AB25)+AB21 -> 2005 | AC26: =SUM(AC24:AC25)+AC21 -> 2183 | ... AE26: =SUM(AE24:AE25)+AE21 -> 2379 | AG26: =SUM(AE26/AA26)-1 -> 0.2735546
B27: EBT Margin (%) | C27: =C26/C11 -> 0.055072464 | D27: =D26/D11 -> 0.11236206 | E27: =E26/E11 -> 0.15823015 | F27: =F26/F11 -> 0.17028167 | H27: =H26/H11 -> 0.089694656 | I27: =I26/I11 -> 0.080930233 | J27: =J26/J11 -> 0.13068182 | K27: =K26/K11 -> 0.14238818 | L27: =L26/L11 -> 0.16327315 | M27: =M26/M11 -> 0.12714123 | N27: =N26/N11 -> 0.18448338 | O27: =O26/O11 -> 0.15657761 | ... T27: =T26/T11 -> 0.17851459 | V27: =V26/V11 -> 0.11236206 | W27: =W26/W11 -> 0.13135683 | X27: =X26/X11 -> 0.14113511 | Y27: =Y26/Y11 -> 0.15500765 | Z27: =Z26/Z11 -> 0.15823015 | AA27: =AA26/AA11 -> 0.16287383 | AB27: =AB26/AB11 -> 0.16629344 | AC27: =AC26/AC11 -> 0.17233757 | ... AE27: =AE26/AE11 -> 0.17041547 | AG27: =SUM(AE27-AA27)*1000 -> 7.541639
B29: Provision for Income Tax | C29: -74 | D29: 723 | E29: -313 | F29: -513 | H29: -38 | I29: 870 | J29: -57 | K29: =SUM(D29-SUM(H29:J29)) -> -52 | L29: -78 | M29: -72 | N29: -84 | O29: =SUM(E29-SUM(L29:N29)) -> -79 | P29: -95 | Q29: -86 | R29: -192 | S29: =SUM(F29-SUM(P29:R29)) -> -140 | T29: -204 | V29: =SUM(H29:K29) -> 723 | W29: =SUM(I29:L29) -> 683 | X29: =SUM(J29:M29) -> -259 | Y29: =SUM(K29:N29) -> -286 | Z29: =SUM(L29:O29) -> -313 | AA29: =SUM(M29:P29) -> -330 | AB29: =SUM(N29:Q29) -> -344 | AC29: =SUM(O29:R29) -> -452 | ... AE29: =SUM(Q29:T29) -> -622 | AG29: =SUM(AE29/AA29)-1 -> 0.88484848
B30: Net Income | C30: =SUM(C26+SUM(C29:C29)) -> 325 | D30: =SUM(D26+SUM(D29:D29)) -> 1731 | E30: =SUM(E26+SUM(E29:E29)) -> 1425 | F30: =SUM(F26+SUM(F29:F29)) -> 1748 | H30: =SUM(H26+SUM(H29:H29)) -> 150 | I30: =SUM(I26+SUM(I29:I29)) -> 1044 | J30: =SUM(J26+SUM(J29:J29)) -> 242 | K30: =SUM(K26+SUM(K29:K29)) -> 295 | L30: =SUM(L26+SUM(L29:L29)) -> 347 | M30: =SUM(M26+SUM(M29:M29)) -> 262 | N30: =SUM(N26+SUM(N29:N29)) -> 432 | O30: =SUM(O26+SUM(O29:O29)) -> 384 | ... T30: =SUM(T26+SUM(T29:T29)) -> 469 | V30: =SUM(V26+SUM(V29:V29)) -> 1731 | W30: =SUM(W26+SUM(W29:W29)) -> 1928 | X30: =SUM(X26+SUM(X29:X29)) -> 1146 | Y30: =SUM(Y26+SUM(Y29:Y29)) -> 1336 | Z30: =SUM(Z26+SUM(Z29:Z29)) -> 1425 | AA30: =SUM(AA26+SUM(AA29:AA29)) -> 1538 | AB30: =SUM(AB26+SUM(AB29:AB29)) -> 1661 | AC30: =SUM(AC26+SUM(AC29:AC29)) -> 1731 | ... AE30: =SUM(AE26+SUM(AE29:AE29)) -> 1757 | AG30: =SUM(AE30/AA30)-1 -> 0.14239272
B31: Net Margin (%) | C31: =C30/C11 -> 0.044858523 | D31: =D30/D11 -> 0.19295508 | E31: =E30/E11 -> 0.12973416 | F31: =F30/F11 -> 0.13164633 | H31: =H30/H11 -> 0.071564885 | I31: =I30/I11 -> 0.4855814 | J31: =J30/J11 -> 0.10576923 | K31: =K30/K11 -> 0.12105047 | L31: =L30/L11 -> 0.13330772 | M31: =M30/M11 -> 0.099733536 | N31: =N30/N11 -> 0.1544512 | O31: =O30/O11 -> 0.12986135 | ... T31: =T30/T11 -> 0.12440318 | V31: =V30/V11 -> 0.19295508 | W31: =W30/W11 -> 0.20341844 | X31: =X30/X11 -> 0.11511803 | Y31: =Y30/Y11 -> 0.12767584 | Z31: =Z30/Z11 -> 0.12973416 | AA31: =AA30/AA11 -> 0.13410062 | AB31: =AB30/AB11 -> 0.1377623 | AC31: =AC30/AC11 -> 0.1366543 | ... AE31: =AE30/AE11 -> 0.1258596 | AG31: =SUM(AE31-AA31)*1000 -> -8.2410202
B33: Basic shares | C33: 201.43 | D33: 1020.685 | E33: 1029.169 | F33: 1036.74 | H33: 203.385 | I33: 204.021 | J33: 204.464 | K33: =D33 -> 1020.685 | L33: 205.108 | M33: 205.644 | N33: 206.158 | O33: =E33 -> 1029.169 | P33: 206.82 | Q33: 207.164 | R33: 207.63 | S33: =F33 -> 1036.74 | T33: 1035.138 | V33: =K33 -> 1020.685 | W33: =L33 -> 205.108 | X33: =M33 -> 205.644 | Y33: =N33 -> 206.158 | Z33: =O33 -> 1029.169 | AA33: =P33 -> 206.82 | AB33: =Q33 -> 207.164 | AC33: =R33 -> 207.63 | ... AE33: =T33 -> 1035.138 | AG33: =SUM(AE33/AA33)-1 -> 4.0050189
B34: Basic EPS | C34: =C30/C33 -> 1.6134637 | D34: =D30/D33 -> 1.6959199 | E34: =E30/E33 -> 1.3846122 | F34: =F30/F33 -> 1.6860544 | H34: =H30/H33 -> 0.73751752 | I34: =I30/I33 -> 5.1171203 | J34: =J30/J33 -> 1.1835824 | K34: =K30/K33 -> 0.28902159 | L34: =L30/L33 -> 1.6917916 | M34: =M30/M33 -> 1.2740464 | N34: =N30/N33 -> 2.0954802 | O34: =O30/O33 -> 0.37311656 | ... T34: =T30/T33 -> 0.45307969 | V34: =V30/V33 -> 1.6959199 | W34: =W30/W33 -> 9.3999259 | X34: =X30/X33 -> 5.5727374 | Y34: =Y30/Y33 -> 6.4804664 | Z34: =Z30/Z33 -> 1.3846122 | AA34: =AA30/AA33 -> 7.4364181 | AB34: =AB30/AB33 -> 8.0178023 | AC34: =AC30/AC33 -> 8.3369455 | ... AE34: =AE30/AE33 -> 1.6973582 | AG34: =SUM(AE34/AA34)-1 -> -0.77175057
B36: Fully Diluted Shares | C36: 203.535 | D36: 1027.953 | E36: 1042.113 | F36: 1046.691 | H36: 204.263 | I36: 205.351 | J36: 206.277 | K36: =D36 -> 1027.953 | L36: 207.684 | M36: 207.799 | N36: 208.552 | O36: =E36 -> 1042.113 | P36: 209.371 | Q36: 209.322 | R36: 209.505 | S36: =F36 -> 1046.691 | T36: 1039.884 | V36: =K36 -> 1027.953 | W36: =L36 -> 207.684 | X36: =M36 -> 207.799 | Y36: =N36 -> 208.552 | Z36: =O36 -> 1042.113 | AA36: =P36 -> 209.371 | AB36: =Q36 -> 209.322 | AC36: =R36 -> 209.505 | ... AE36: =T36 -> 1039.884 | AG36: =SUM(AE36/AA36)-1 -> 3.966705
B37: Diluted EPS | C37: =C30/C36 -> 1.596777 | D37: =D30/D36 -> 1.6839291 | E37: =E30/E36 -> 1.3674141 | F37: =F30/F36 -> 1.6700249 | H37: =H30/H36 -> 0.73434739 | I37: =I30/I36 -> 5.0839782 | J37: =J30/J36 -> 1.1731798 | K37: =K30/K36 -> 0.2869781 | L37: =L30/L36 -> 1.6708076 | M37: =M30/M36 -> 1.2608338 | N37: =N30/N36 -> 2.0714258 | O37: =O30/O36 -> 0.36848211 | ... T37: =T30/T36 -> 0.45101184 | V37: =V30/V36 -> 1.6839291 | W37: =W30/W36 -> 9.2833343 | X37: =X30/X36 -> 5.5149447 | Y37: =Y30/Y36 -> 6.4060762 | Z37: =Z30/Z36 -> 1.3674141 | AA37: =AA30/AA36 -> 7.345812 | AB37: =AB30/AB36 -> 7.935143 | AC37: =AC30/AC36 -> 8.2623326 | ... AE37: =AE30/AE36 -> 1.6896115 | AG37: =SUM(AE37/AA37)-1 -> -0.76998982
A39: X | B39: Balance Sheet | C39: FYE | N39: Quarterly | P39: Quarterly | AA39: LTM | AG39: Variance
B40: =B7 -> Fiscal Period | C40: =C7 -> 2022 | D40: =D7 -> 2023 | E40: =E7 -> 2024 | F40: =F7 -> 2025 | H40: =H7 -> 1Q23 | I40: =I7 -> 2Q23 | J40: =J7 -> 3Q23 | K40: =K7 -> 4Q23 | L40: =L7 -> 1Q24 | M40: =M7 -> 2Q24 | N40: =N7 -> 3Q24 | O40: =O7 -> 4Q24 | ... T40: =T7 -> 1Q26 | V40: =V7 -> 4Q23 | W40: =W7 -> 1Q24 | X40: =X7 -> 2Q24 | Y40: =Y7 -> 3Q24 | Z40: =Z7 -> 4Q24 | AA40: =AA7 -> 1Q25 | AB40: =AB7 -> 2Q25 | AC40: =AC7 -> 3Q25 | ... AE40: =AE7 -> 1Q26
B41: =B8 -> Fiscal Period End Date | C41: =C8 -> 44926 | D41: =D8 -> 45291 | E41: =E8 -> 45657 | F41: =F8 -> 46022 | H41: =H8 -> 45016 | I41: =I8 -> 45107 | J41: =J8 -> 45199 | K41: =K8 -> 45291 | L41: =L8 -> 45382 | M41: =M8 -> 45473 | N41: =N8 -> 45565 | O41: =O8 -> 45657 | ... T41: =T8 -> 46112 | V41: =V8 -> 45291 | W41: =W8 -> 45382 | X41: =X8 -> 45473 | Y41: =Y8 -> 45565 | Z41: =Z8 -> 45657 | AA41: =AA8 -> 45747 | AB41: =AB8 -> 45838 | AC41: =AC8 -> 45930 | ... AE41: =AE8 -> 46112
B43: Current Assets
B44: Cash and Cash Equivalents | C44: 1470 | D44: 1897 | E44: 2304 | F44: 3726 | H44: 1852 | I44: 1663 | J44: 1112 | K44: =D44 -> 1897 | L44: 2056 | M44: 2159 | N44: 1885 | O44: =E44 -> 2304 | P44: 3369 | Q44: 3124 | R44: 2725 | S44: =F44 -> 3726 | T44: 2702 | V44: =K44 -> 1897 | W44: =L44 -> 2056 | X44: =M44 -> 2159 | Y44: =N44 -> 1885 | Z44: =O44 -> 2304 | AA44: =P44 -> 3369 | AB44: =Q44 -> 3124 | AC44: =R44 -> 2725 | ... AE44: =T44 -> 2702 | AG44: =SUM(AE44/AA44)-1 -> -0.1979816
B45: Marketable Securities | C45: 0 | D45: 0 | E45: 3458 | F45: 2558 | H45: 0 | I45: 0 | J45: 0 | K45: =D45 -> 0 | L45: 0 | M45: 0 | N45: 0 | O45: =E45 -> 3458 | P45: 0 | Q45: 0 | R45: 2686 | S45: =F45 -> 2558 | T45: 2480 | V45: =K45 -> 0 | W45: =L45 -> 0 | X45: =M45 -> 0 | Y45: =N45 -> 0 | Z45: =O45 -> 3458 | AA45: =P45 -> 0 | AB45: =Q45 -> 0 | AC45: =R45 -> 2686 | ... AE45: =T45 -> 2480 | AG45: =SUM(AE45/AA45)-1 -> #DIV/0!
B46: Short-term Investments | C46: 2810 | D46: 2980 | E46: 0 | F46: 0 | H46: 3062 | I46: 3084 | J46: 2955 | K46: =D46 -> 2980 | L46: 3054 | M46: 3254 | N46: 3410 | O46: =E46 -> 0 | P46: 3228 | Q46: 3008 | R46: 0 | S46: =F46 -> 0 | T46: 0 | V46: =K46 -> 2980 | W46: =L46 -> 3054 | X46: =M46 -> 3254 | Y46: =N46 -> 3410 | Z46: =O46 -> 0 | AA46: =P46 -> 3228 | AB46: =Q46 -> 3008 | AC46: =R46 -> 0 | ... AE46: =T46 -> 0 | AG46: =SUM(AE46/AA46)-1 -> -1
B47: Accounts Receivable, Net | C47: 1725 | D47: 2036 | E47: 2240 | F47: 2627 | H47: 1109 | I47: 1093 | J47: 1168 | K47: =D47 -> 2036 | L47: 1306 | M47: 1518 | N47: 1308 | O47: =E47 -> 2240 | P47: 1359 | Q47: 1696 | R47: 1548 | S47: =F47 -> 2627 | T47: 1713 | V47: =K47 -> 2036 | W47: =L47 -> 1306 | X47: =M47 -> 1518 | Y47: =N47 -> 1308 | Z47: =O47 -> 2240 | AA47: =P47 -> 1359 | AB47: =Q47 -> 1696 | AC47: =R47 -> 1548 | ... AE47: =T47 -> 1713 | AG47: =SUM(AE47/AA47)-1 -> 0.26048565
B48: Prepaid Expenses and Other Current Assets | C48: 280 | D48: 403 | E48: 668 | F48: 970 | H48: 319 | I48: 362 | J48: 394 | K48: =D48 -> 403 | L48: 482 | M48: 608 | N48: 591 | O48: =E48 -> 668 | P48: 781 | Q48: 896 | R48: 846 | S48: =F48 -> 970 | T48: 949 | V48: =K48 -> 403 | W48: =L48 -> 482 | X48: =M48 -> 608 | Y48: =N48 -> 591 | Z48: =O48 -> 668 | AA48: =P48 -> 781 | AB48: =Q48 -> 896 | AC48: =R48 -> 846 | ... AE48: =T48 -> 949 | AG48: =SUM(AE48/AA48)-1 -> 0.21510883
B49: Current Portion of Deferred Commissions | C49: 369 | D49: 461 | E49: 517 | F49: 590 | H49: 392 | I49: 401 | J49: 417 | K49: =D49 -> 461 | L49: 474 | M49: 482 | N49: 502 | O49: =E49 -> 517 | P49: 533 | Q49: 551 | R49: 559 | S49: =F49 -> 590 | T49: 591 | V49: =K49 -> 461 | W49: =L49 -> 474 | X49: =M49 -> 482 | Y49: =N49 -> 502 | Z49: =O49 -> 517 | AA49: =P49 -> 533 | AB49: =Q49 -> 551 | AC49: =R49 -> 559 | ... AE49: =T49 -> 591 | AG49: =SUM(AE49/AA49)-1 -> 0.10881801
B50: Total Current Assets | C50: =SUM(C44:C49) -> 6654 | D50: =SUM(D44:D49) -> 7777 | E50: =SUM(E44:E49) -> 9187 | F50: =SUM(F44:F49) -> 10471 | H50: =SUM(H44:H49) -> 6734 | I50: =SUM(I44:I49) -> 6603 | J50: =SUM(J44:J49) -> 6046 | K50: =SUM(K44:K49) -> 7777 | L50: =SUM(L44:L49) -> 7372 | M50: =SUM(M44:M49) -> 8021 | N50: =SUM(N44:N49) -> 7696 | O50: =SUM(O44:O49) -> 9187 | ... T50: =SUM(T44:T49) -> 8435 | V50: =SUM(V44:V49) -> 7777 | W50: =SUM(W44:W49) -> 7372 | X50: =SUM(X44:X49) -> 8021 | Y50: =SUM(Y44:Y49) -> 7696 | Z50: =SUM(Z44:Z49) -> 9187 | AA50: =SUM(AA44:AA49) -> 9270 | AB50: =SUM(AB44:AB49) -> 9275 | AC50: =SUM(AC44:AC49) -> 8364 | ... AE50: =SUM(AE44:AE49) -> 8435 | AG50: =SUM(AE50/AA50)-1 -> -0.090075512
B52: Non-Current Assets
...

Sheet Revenue Drivers
B2: ='Historical Financials'!B2 -> ServiceNow, Inc. (NYSE: NOW) | C2: FYE | D2: FYE | N2: Quarterly | P2: Quarterly | AA2: LTM
B3: Segment Anaysis | C3: ='Historical Financials'!C7 -> 2022 | D3: ='Historical Financials'!D7 -> 2023 | E3: ='Historical Financials'!E7 -> 2024 | F3: ='Historical Financials'!F7 -> 2025 | H3: ='Historical Financials'!H7 -> 1Q23 | I3: ='Historical Financials'!I7 -> 2Q23 | J3: ='Historical Financials'!J7 -> 3Q23 | K3: ='Historical Financials'!K7 -> 4Q23 | L3: ='Historical Financials'!L7 -> 1Q24 | M3: ='Historical Financials'!M7 -> 2Q24 | N3: ='Historical Financials'!N7 -> 3Q24 | O3: ='Historical Financials'!O7 -> 4Q24 | ... T3: ='Historical Financials'!T7 -> 1Q26 | V3: =K3 -> 4Q23 | W3: =L3 -> 1Q24 | X3: =M3 -> 2Q24 | Y3: =N3 -> 3Q24 | Z3: =O3 -> 4Q24 | AA3: =P3 -> 1Q25 | AB3: =Q3 -> 2Q25 | AC3: =R3 -> 3Q25 | ... AE3: =T3 -> 1Q26
B4: ($ In Millions) | C4: ='Historical Financials'!C8 -> 44926 | D4: ='Historical Financials'!D8 -> 45291 | E4: ='Historical Financials'!E8 -> 45657 | F4: ='Historical Financials'!F8 -> 46022 | H4: ='Historical Financials'!H8 -> 45016 | I4: ='Historical Financials'!I8 -> 45107 | J4: ='Historical Financials'!J8 -> 45199 | K4: ='Historical Financials'!K8 -> 45291 | L4: ='Historical Financials'!L8 -> 45382 | M4: ='Historical Financials'!M8 -> 45473 | N4: ='Historical Financials'!N8 -> 45565 | O4: ='Historical Financials'!O8 -> 45657 | ... T4: ='Historical Financials'!T8 -> 46112 | V4: =K4 -> 45291 | W4: =L4 -> 45382 | X4: =M4 -> 45473 | Y4: =N4 -> 45565 | Z4: =O4 -> 45657 | AA4: =P4 -> 45747 | AB4: =Q4 -> 45838 | AC4: =R4 -> 45930 | ... AE4: =T4 -> 46112
A6: X | B6: Revenue by reportable segment
A8: X | B8: Revenue Segment Anaysis
B9: Subscription | C9: 6891 | D9: 8680 | E9: 10646 | F9: 12883 | H9: 2024 | I9: 2075 | J9: 2216 | K9: =SUM(D9-SUM(H9:J9)) -> 2365 | L9: 2523 | M9: 2542 | N9: 2715 | O9: =SUM(E9-SUM(L9:N9)) -> 2866 | P9: 3005 | Q9: 3113 | R9: 3299 | S9: =SUM(F9-SUM(P9:R9)) -> 3466 | T9: 3671 | V9: =SUM(H9:K9) -> 8680 | W9: =SUM(I9:L9) -> 9179 | X9: =SUM(J9:M9) -> 9646 | Y9: =SUM(K9:N9) -> 10145 | Z9: =SUM(L9:O9) -> 10646 | AA9: =SUM(M9:P9) -> 11128 | AB9: =SUM(N9:Q9) -> 11699 | AC9: =SUM(O9:R9) -> 12283 | ... AE9: =SUM(Q9:T9) -> 13549
B10: Professional Services Other | C10: 354 | D10: 291 | E10: 338 | F10: 395 | H10: 72 | I10: 75 | J10: 72 | K10: =SUM(D10-SUM(H10:J10)) -> 72 | L10: 80 | M10: 85 | N10: 82 | O10: =SUM(E10-SUM(L10:N10)) -> 91 | P10: 83 | Q10: 102 | R10: 108 | S10: =SUM(F10-SUM(P10:R10)) -> 102 | T10: 99 | V10: =SUM(H10:K10) -> 291 | W10: =SUM(I10:L10) -> 299 | X10: =SUM(J10:M10) -> 309 | Y10: =SUM(K10:N10) -> 319 | Z10: =SUM(L10:O10) -> 338 | AA10: =SUM(M10:P10) -> 341 | AB10: =SUM(N10:Q10) -> 358 | AC10: =SUM(O10:R10) -> 384 | ... AE10: =SUM(Q10:T10) -> 411
B11: Total Net Revenue | C11: =SUM(C9:C10) -> 7245 | D11: =SUM(D9:D10) -> 8971 | E11: =SUM(E9:E10) -> 10984 | F11: =SUM(F9:F10) -> 13278 | H11: =SUM(H9:H10) -> 2096 | I11: =SUM(I9:I10) -> 2150 | J11: =SUM(J9:J10) -> 2288 | K11: =SUM(K9:K10) -> 2437 | L11: =SUM(L9:L10) -> 2603 | M11: =SUM(M9:M10) -> 2627 | N11: =SUM(N9:N10) -> 2797 | O11: =SUM(O9:O10) -> 2957 | ... T11: =SUM(T9:T10) -> 3770 | V11: =SUM(V9:V10) -> 8971 | W11: =SUM(W9:W10) -> 9478 | X11: =SUM(X9:X10) -> 9955 | Y11: =SUM(Y9:Y10) -> 10464 | Z11: =SUM(Z9:Z10) -> 10984 | AA11: =SUM(AA9:AA10) -> 11469 | AB11: =SUM(AB9:AB10) -> 12057 | AC11: =SUM(AC9:AC10) -> 12667 | ... AE11: =SUM(AE9:AE10) -> 13960
B12: Variance Check | C12: =+C11-'Historical Financials'!C11 -> 0 | D12: =+D11-'Historical Financials'!D11 -> 0 | E12: =+E11-'Historical Financials'!E11 -> 0 | F12: =+F11-'Historical Financials'!F11 -> 0 | H12: =+H11-'Historical Financials'!H11 -> 0 | I12: =+I11-'Historical Financials'!I11 -> 0 | J12: =+J11-'Historical Financials'!J11 -> 0 | K12: =+K11-'Historical Financials'!K11 -> 0 | L12: =+L11-'Historical Financials'!L11 -> 0 | M12: =+M11-'Historical Financials'!M11 -> 0 | N12: =+N11-'Historical Financials'!N11 -> 0 | O12: =+O11-'Historical Financials'!O11 -> 0 | ... T12: =+T11-'Historical Financials'!T11 -> 0 | V12: =+V11-'Historical Financials'!V11 -> 0 | W12: =+W11-'Historical Financials'!W11 -> 0 | X12: =+X11-'Historical Financials'!X11 -> 0 | Y12: =+Y11-'Historical Financials'!Y11 -> 0 | Z12: =+Z11-'Historical Financials'!Z11 -> 0 | AA12: =+AA11-'Historical Financials'!AA11 -> 0 | AB12: =+AB11-'Historical Financials'!AB11 -> 0 | AC12: =+AC11-'Historical Financials'!AC11 -> 0 | ... AE12: =+AE11-'Historical Financials'!AE11 -> 0
B14: =B9&"(%)" -> Subscription (%) | C14: =SUM(C9/C$11) -> 0.95113872 | D14: =SUM(D9/D$11) -> 0.96756214 | E14: =SUM(E9/E$11) -> 0.96922797 | F14: =SUM(F9/F$11) -> 0.97025154 | H14: =SUM(H9/H$11) -> 0.96564885 | I14: =SUM(I9/I$11) -> 0.96511628 | J14: =SUM(J9/J$11) -> 0.96853147 | K14: =SUM(K9/K$11) -> 0.97045548 | L14: =SUM(L9/L$11) -> 0.96926623 | M14: =SUM(M9/M$11) -> 0.9676437 | N14: =SUM(N9/N$11) -> 0.97068287 | O14: =SUM(O9/O$11) -> 0.96922557 | ... T14: =SUM(T9/T$11) -> 0.97374005 | V14: =I14 -> 0.96511628 | W14: =J14 -> 0.96853147 | X14: =K14 -> 0.97045548 | Y14: =L14 -> 0.96926623 | Z14: =M14 -> 0.9676437 | AA14: =N14 -> 0.97068287 | AB14: =O14 -> 0.96922557 | AC14: =P14 -> 0.97312176 | ... AE14: =R14 -> 0.96830056
B15: =B10&"(%)" -> Professional Services Other (%) | C15: =SUM(C10/C$11) -> 0.048861284 | D15: =SUM(D10/D$11) -> 0.032437855 | E15: =SUM(E10/E$11) -> 0.030772032 | F15: =SUM(F10/F$11) -> 0.029748456 | H15: =SUM(H10/H$11) -> 0.034351145 | I15: =SUM(I10/I$11) -> 0.034883721 | J15: =SUM(J10/J$11) -> 0.031468531 | K15: =SUM(K10/K$11) -> 0.029544522 | L15: =SUM(L10/L$11) -> 0.030733769 | M15: =SUM(M10/M$11) -> 0.0323563 | N15: =SUM(N10/N$11) -> 0.029317125 | O15: =SUM(O10/O$11) -> 0.030774434 | ... T15: =SUM(T10/T$11) -> 0.026259947 | V15: =I15 -> 0.034883721 | W15: =J15 -> 0.031468531 | X15: =K15 -> 0.029544522 | Y15: =L15 -> 0.030733769 | Z15: =M15 -> 0.0323563 | AA15: =N15 -> 0.029317125 | AB15: =O15 -> 0.030774434 | AC15: =P15 -> 0.026878238 | ... AE15: =R15 -> 0.031699442

Sheet FCF
B2: ='Historical Financials'!B2 -> ServiceNow, Inc. (NYSE: NOW) | C2: FYE | D2: FYE | H2: Quarterly | P2: Quarterly | Z2: LTM | AA2: LTM | AG2: Variance
B3: FCF Analysis | C3: ='Historical Financials'!C7 -> 2022 | D3: ='Historical Financials'!D7 -> 2023 | E3: ='Historical Financials'!E7 -> 2024 | F3: ='Historical Financials'!F7 -> 2025 | H3: ='Historical Financials'!H7 -> 1Q23 | I3: ='Historical Financials'!I7 -> 2Q23 | J3: ='Historical Financials'!J7 -> 3Q23 | K3: ='Historical Financials'!K7 -> 4Q23 | L3: ='Historical Financials'!L7 -> 1Q24 | M3: ='Historical Financials'!M7 -> 2Q24 | N3: ='Historical Financials'!N7 -> 3Q24 | O3: ='Historical Financials'!O7 -> 4Q24 | ... T3: ='Historical Financials'!T7 -> 1Q26 | V3: =K3 -> 4Q23 | W3: =L3 -> 1Q24 | X3: =M3 -> 2Q24 | Y3: =N3 -> 3Q24 | Z3: =O3 -> 4Q24 | AA3: =P3 -> 1Q25 | AB3: =Q3 -> 2Q25 | AC3: =R3 -> 3Q25 | ... AE3: =T3 -> 1Q26
B4: ($ In Millions) | C4: ='Historical Financials'!C8 -> 44926 | D4: ='Historical Financials'!D8 -> 45291 | E4: ='Historical Financials'!E8 -> 45657 | F4: ='Historical Financials'!F8 -> 46022 | H4: ='Historical Financials'!H8 -> 45016 | I4: ='Historical Financials'!I8 -> 45107 | J4: ='Historical Financials'!J8 -> 45199 | K4: ='Historical Financials'!K8 -> 45291 | L4: ='Historical Financials'!L8 -> 45382 | M4: ='Historical Financials'!M8 -> 45473 | N4: ='Historical Financials'!N8 -> 45565 | O4: ='Historical Financials'!O8 -> 45657 | ... T4: ='Historical Financials'!T8 -> 46112 | V4: =K4 -> 45291 | W4: =L4 -> 45382 | X4: =M4 -> 45473 | Y4: =N4 -> 45565 | Z4: =O4 -> 45657 | AA4: =P4 -> 45747 | AB4: =Q4 -> 45838 | AC4: =R4 -> 45930 | ... AE4: =T4 -> 46112
B6: ='Revenue Drivers'!B9 -> Subscription | C6: ='Revenue Drivers'!C9 -> 6891 | D6: ='Revenue Drivers'!D9 -> 8680 | E6: ='Revenue Drivers'!E9 -> 10646 | F6: ='Revenue Drivers'!F9 -> 12883 | H6: ='Revenue Drivers'!H9 -> 2024 | I6: ='Revenue Drivers'!I9 -> 2075 | J6: ='Revenue Drivers'!J9 -> 2216 | K6: ='Revenue Drivers'!K9 -> 2365 | L6: ='Revenue Drivers'!L9 -> 2523 | M6: ='Revenue Drivers'!M9 -> 2542 | N6: ='Revenue Drivers'!N9 -> 2715 | O6: ='Revenue Drivers'!O9 -> 2866 | ... T6: ='Revenue Drivers'!T9 -> 3671 | V6: =SUM(H6:K6) -> 8680 | W6: =SUM(I6:L6) -> 9179 | X6: =SUM(J6:M6) -> 9646 | Y6: =SUM(K6:N6) -> 10145 | Z6: =SUM(L6:O6) -> 10646 | AA6: =SUM(M6:P6) -> 11128 | AB6: =SUM(N6:Q6) -> 11699 | AC6: =SUM(O6:R6) -> 12283 | ... AE6: =SUM(Q6:T6) -> 13549 | AG6: =SUM(AE6/AA6)-1 -> 0.21755931
B7: ='Revenue Drivers'!B10 -> Professional Services Other | C7: ='Revenue Drivers'!C10 -> 354 | D7: ='Revenue Drivers'!D10 -> 291 | E7: ='Revenue Drivers'!E10 -> 338 | F7: ='Revenue Drivers'!F10 -> 395 | H7: ='Revenue Drivers'!H10 -> 72 | I7: ='Revenue Drivers'!I10 -> 75 | J7: ='Revenue Drivers'!J10 -> 72 | K7: ='Revenue Drivers'!K10 -> 72 | L7: ='Revenue Drivers'!L10 -> 80 | M7: ='Revenue Drivers'!M10 -> 85 | N7: ='Revenue Drivers'!N10 -> 82 | O7: ='Revenue Drivers'!O10 -> 91 | ... T7: ='Revenue Drivers'!T10 -> 99 | V7: =SUM(H7:K7) -> 291 | W7: =SUM(I7:L7) -> 299 | X7: =SUM(J7:M7) -> 309 | Y7: =SUM(K7:N7) -> 319 | Z7: =SUM(L7:O7) -> 338 | AA7: =SUM(M7:P7) -> 341 | AB7: =SUM(N7:Q7) -> 358 | AC7: =SUM(O7:R7) -> 384 | ... AE7: =SUM(Q7:T7) -> 411 | AG7: =SUM(AE7/AA7)-1 -> 0.20527859
B8: Total Revenue | C8: =SUM(C6:C7) -> 7245 | D8: =SUM(D6:D7) -> 8971 | E8: =SUM(E6:E7) -> 10984 | F8: =SUM(F6:F7) -> 13278 | H8: =SUM(H6:H7) -> 2096 | I8: =SUM(I6:I7) -> 2150 | J8: =SUM(J6:J7) -> 2288 | K8: =SUM(K6:K7) -> 2437 | L8: =SUM(L6:L7) -> 2603 | M8: =SUM(M6:M7) -> 2627 | N8: =SUM(N6:N7) -> 2797 | O8: =SUM(O6:O7) -> 2957 | ... T8: =SUM(T6:T7) -> 3770 | V8: =SUM(V6:V7) -> 8971 | W8: =SUM(W6:W7) -> 9478 | X8: =SUM(X6:X7) -> 9955 | Y8: =SUM(Y6:Y7) -> 10464 | Z8: =SUM(Z6:Z7) -> 10984 | AA8: =SUM(AA6:AA7) -> 11469 | AB8: =SUM(AB6:AB7) -> 12057 | AC8: =SUM(AC6:AC7) -> 12667 | ... AE8: =SUM(AE6:AE7) -> 13960 | AG8: =SUM(AE8/AA8)-1 -> 0.21719418
B9: Y/Y Growth (%) | D9: =SUM(D8/C8)-1 -> 0.23823326 | E9: =SUM(E8/D8)-1 -> 0.2243897 | F9: =SUM(F8/E8)-1 -> 0.20884924 | L9: =SUM(L8/H8)-1 -> 0.24188931 | M9: =SUM(M8/I8)-1 -> 0.22186047 | N9: =SUM(N8/J8)-1 -> 0.22246503 | O9: =SUM(O8/K8)-1 -> 0.2133771 | P9: =SUM(P8/L8)-1 -> 0.18632347 | Q9: =SUM(Q8/M8)-1 -> 0.22382946 | R9: =SUM(R8/N8)-1 -> 0.21809081 | S9: =SUM(S8/O8)-1 -> 0.20662834 | T9: =SUM(T8/P8)-1 -> 0.22085492 | Z9: =SUM(Z8/V8)-1 -> 0.2243897 | AA9: =SUM(AA8/W8)-1 -> 0.21006541 | AB9: =SUM(AB8/X8)-1 -> 0.21115018 | AC9: =SUM(AC8/Y8)-1 -> 0.21053135 | AD9: =SUM(AD8/Z8)-1 -> 0.20884924 | AE9: =SUM(AE8/AA8)-1 -> 0.21719418 | AG9: =SUM(AE9-AA9)*10000 -> 71.28761
B10: Q/Q Growth (%) | I10: =SUM(I8/H8)-1 -> 0.025763359 | J10: =SUM(J8/I8)-1 -> 0.064186047 | K10: =SUM(K8/J8)-1 -> 0.065122378 | L10: =SUM(L8/K8)-1 -> 0.068116537 | M10: =SUM(M8/L8)-1 -> 0.0092201306 | N10: =SUM(N8/M8)-1 -> 0.0647126 | O10: =SUM(O8/N8)-1 -> 0.057204147 | P10: =SUM(P8/O8)-1 -> 0.044301657 | ... T10: =SUM(T8/S8)-1 -> 0.05661435
B12: (-) Subscription | C12: ='Historical Financials'!C13 -> -1187 | D12: ='Historical Financials'!D13 -> -1606 | E12: ='Historical Financials'!E13 -> -1942 | F12: ='Historical Financials'!F13 -> -2569 | H12: ='Historical Financials'!H13 -> -354 | I12: ='Historical Financials'!I13 -> -389 | J12: ='Historical Financials'!J13 -> -420 | K12: ='Historical Financials'!K13 -> -443 | L12: ='Historical Financials'!L13 -> -441 | M12: ='Historical Financials'!M13 -> -469 | N12: ='Historical Financials'!N13 -> -496 | O12: ='Historical Financials'!O13 -> -536 | ... T12: ='Historical Financials'!T13 -> -820 | V12: =SUM(H12:K12) -> -1606 | W12: =SUM(I12:L12) -> -1693 | X12: =SUM(J12:M12) -> -1773 | Y12: =SUM(K12:N12) -> -1849 | Z12: =SUM(L12:O12) -> -1942 | AA12: =SUM(M12:P12) -> -2062 | AB12: =SUM(N12:Q12) -> -2218 | AC12: =SUM(O12:R12) -> -2388 | ... AE12: =SUM(Q12:T12) -> -2828 | AG12: =SUM(AE12/AA12)-1 -> 0.371484
B13: (-) Professional Services Other | C13: ='Historical Financials'!C14 -> -386 | D13: ='Historical Financials'!D14 -> -315 | E13: ='Historical Financials'!E14 -> -345 | F13: ='Historical Financials'!F14 -> -414 | H13: ='Historical Financials'!H14 -> -84 | I13: ='Historical Financials'!I14 -> -82 | J13: ='Historical Financials'!J14 -> -76 | K13: ='Historical Financials'!K14 -> -73 | L13: ='Historical Financials'!L14 -> -79 | M13: ='Historical Financials'!M14 -> -83 | N13: ='Historical Financials'!N14 -> -88 | O13: ='Historical Financials'!O14 -> -95 | ... T13: ='Historical Financials'!T14 -> -120 | V13: =SUM(H13:K13) -> -315 | W13: =SUM(I13:L13) -> -310 | X13: =SUM(J13:M13) -> -311 | Y13: =SUM(K13:N13) -> -323 | Z13: =SUM(L13:O13) -> -345 | AA13: =SUM(M13:P13) -> -356 | AB13: =SUM(N13:Q13) -> -372 | AC13: =SUM(O13:R13) -> -392 | ... AE13: =SUM(Q13:T13) -> -444 | AG13: =SUM(AE13/AA13)-1 -> 0.24719101
B14: Gross Profit | C14: =SUM(C8+SUM(C12:C13)) -> 5672 | D14: =SUM(D8+SUM(D12:D13)) -> 7050 | E14: =SUM(E8+SUM(E12:E13)) -> 8697 | F14: =SUM(F8+SUM(F12:F13)) -> 10295 | H14: =SUM(H8+SUM(H12:H13)) -> 1658 | I14: =SUM(I8+SUM(I12:I13)) -> 1679 | J14: =SUM(J8+SUM(J12:J13)) -> 1792 | K14: =SUM(K8+SUM(K12:K13)) -> 1921 | L14: =SUM(L8+SUM(L12:L13)) -> 2083 | M14: =SUM(M8+SUM(M12:M13)) -> 2075 | N14: =SUM(N8+SUM(N12:N13)) -> 2213 | O14: =SUM(O8+SUM(O12:O13)) -> 2326 | ... T14: =SUM(T8+SUM(T12:T13)) -> 2830 | V14: =SUM(V8+SUM(V12:V13)) -> 7050 | W14: =SUM(W8+SUM(W12:W13)) -> 7475 | X14: =SUM(X8+SUM(X12:X13)) -> 7871 | Y14: =SUM(Y8+SUM(Y12:Y13)) -> 8292 | Z14: =SUM(Z8+SUM(Z12:Z13)) -> 8697 | AA14: =SUM(AA8+SUM(AA12:AA13)) -> 9051 | AB14: =SUM(AB8+SUM(AB12:AB13)) -> 9467 | AC14: =SUM(AC8+SUM(AC12:AC13)) -> 9887 | ... AE14: =SUM(AE8+SUM(AE12:AE13)) -> 10688 | AG14: =SUM(AE14/AA14)-1 -> 0.18086399
B15: Gross Margin (%) | C15: =C14/C8 -> 0.78288475 | D15: =D14/D8 -> 0.78586557 | E15: =E14/E8 -> 0.79178806 | F15: =F14/F8 -> 0.77534267 | H15: =H14/H8 -> 0.79103053 | I15: =I14/I8 -> 0.78093023 | J15: =J14/J8 -> 0.78321678 | K15: =K14/K8 -> 0.78826426 | L15: =L14/L8 -> 0.8002305 | M15: =M14/M8 -> 0.78987438 | N15: =N14/N8 -> 0.79120486 | O15: =O14/O8 -> 0.78660805 | ... T15: =T14/T8 -> 0.75066313 | V15: =V14/V8 -> 0.78586557 | W15: =W14/W8 -> 0.7886685 | X15: =X14/X8 -> 0.79065796 | Y15: =Y14/Y8 -> 0.79243119 | Z15: =Z14/Z8 -> 0.79178806 | AA15: =AA14/AA8 -> 0.78917081 | AB15: =AB14/AB8 -> 0.78518703 | AC15: =AC14/AC8 -> 0.78053209 | ... AE15: =AE14/AE8 -> 0.76561605 | AG15: =SUM(AE15-AA15)*10000 -> -235.54762
B17: (-) Sales and Marketing | C17: ='Historical Financials'!C18 -> -2814 | D17: ='Historical Financials'!D18 -> -3301 | E17: ='Historical Financials'!E18 -> -3854 | F17: ='Historical Financials'!F18 -> -4388 | H17: ='Historical Financials'!H18 -> -823 | I17: ='Historical Financials'!I18 -> -832 | J17: ='Historical Financials'!J18 -> -799 | K17: ='Historical Financials'!K18 -> -847 | L17: ='Historical Financials'!L18 -> -923 | M17: ='Historical Financials'!M18 -> -960 | N17: ='Historical Financials'!N18 -> -944 | O17: ='Historical Financials'!O18 -> -1027 | ... T17: ='Historical Financials'!T18 -> -1216 | V17: =SUM(H17:K17) -> -3301 | W17: =SUM(I17:L17) -> -3401 | X17: =SUM(J17:M17) -> -3529 | Y17: =SUM(K17:N17) -> -3674 | Z17: =SUM(L17:O17) -> -3854 | AA17: =SUM(M17:P17) -> -3985 | AB17: =SUM(N17:Q17) -> -4153 | AC17: =SUM(O17:R17) -> -4265 | ... AE17: =SUM(Q17:T17) -> -4550 | AG17: =SUM(AE17/AA17)-1 -> 0.14178168
B18: (-) General and Administrative | C18: ='Historical Financials'!C19 -> -735 | D18: ='Historical Financials'!D19 -> -863 | E18: ='Historical Financials'!E19 -> -936 | F18: ='Historical Financials'!F19 -> -1123 | H18: ='Historical Financials'!H19 -> -199 | I18: ='Historical Financials'!I19 -> -209 | J18: ='Historical Financials'!J19 -> -213 | K18: ='Historical Financials'!K19 -> -242 | L18: ='Historical Financials'!L19 -> -222 | M18: ='Historical Financials'!M19 -> -232 | N18: ='Historical Financials'!N19 -> -225 | O18: ='Historical Financials'!O19 -> -257 | ... T18: ='Historical Financials'!T19 -> -288 | V18: =SUM(H18:K18) -> -863 | W18: =SUM(I18:L18) -> -886 | X18: =SUM(J18:M18) -> -909 | Y18: =SUM(K18:N18) -> -921 | Z18: =SUM(L18:O18) -> -936 | AA18: =SUM(M18:P18) -> -943 | AB18: =SUM(N18:Q18) -> -982 | AC18: =SUM(O18:R18) -> -1012 | ... AE18: =SUM(Q18:T18) -> -1182 | AG18: =SUM(AE18/AA18)-1 -> 0.25344645
B19: (-) Research and Development | C19: ='Historical Financials'!C20 -> -1768 | D19: ='Historical Financials'!D20 -> -2124 | E19: ='Historical Financials'!E20 -> -2543 | F19: ='Historical Financials'!F20 -> -2960 | H19: ='Historical Financials'!H20 -> -492 | I19: ='Historical Financials'!I20 -> -521 | J19: ='Historical Financials'!J20 -> -549 | K19: ='Historical Financials'!K20 -> -562 | L19: ='Historical Financials'!L20 -> -606 | M19: ='Historical Financials'!M20 -> -643 | N19: ='Historical Financials'!N20 -> -626 | O19: ='Historical Financials'!O20 -> -668 | ... T19: ='Historical Financials'!T20 -> -823 | V19: =SUM(H19:K19) -> -2124 | W19: =SUM(I19:L19) -> -2238 | X19: =SUM(J19:M19) -> -2360 | Y19: =SUM(K19:N19) -> -2437 | Z19: =SUM(L19:O19) -> -2543 | AA19: =SUM(M19:P19) -> -2640 | AB19: =SUM(N19:Q19) -> -2731 | AC19: =SUM(O19:R19) -> -2855 | ... AE19: =SUM(Q19:T19) -> -3080 | AG19: =SUM(AE19/AA19)-1 -> 0.16666667
B20: Earning before Interest & Taxes (EBIT) | C20: =SUM(C14+SUM(C17:C19)) -> 355 | D20: =SUM(D14+SUM(D17:D19)) -> 762 | E20: =SUM(E14+SUM(E17:E19)) -> 1364 | F20: =SUM(F14+SUM(F17:F19)) -> 1824 | H20: =SUM(H14+SUM(H17:H19)) -> 144 | I20: =SUM(I14+SUM(I17:I19)) -> 117 | J20: =SUM(J14+SUM(J17:J19)) -> 231 | K20: =SUM(K14+SUM(K17:K19)) -> 270 | L20: =SUM(L14+SUM(L17:L19)) -> 332 | M20: =SUM(M14+SUM(M17:M19)) -> 240 | N20: =SUM(N14+SUM(N17:N19)) -> 418 | O20: =SUM(O14+SUM(O17:O19)) -> 374 | ... T20: =SUM(T14+SUM(T17:T19)) -> 503 | V20: =SUM(V14+SUM(V17:V19)) -> 762 | W20: =SUM(W14+SUM(W17:W19)) -> 950 | X20: =SUM(X14+SUM(X17:X19)) -> 1073 | Y20: =SUM(Y14+SUM(Y17:Y19)) -> 1260 | Z20: =SUM(Z14+SUM(Z17:Z19)) -> 1364 | AA20: =SUM(AA14+SUM(AA17:AA19)) -> 1483 | AB20: =SUM(AB14+SUM(AB17:AB19)) -> 1601 | AC20: =SUM(AC14+SUM(AC17:AC19)) -> 1755 | ... AE20: =SUM(AE14+SUM(AE17:AE19)) -> 1876 | AG20: =SUM(AE20/AA20)-1 -> 0.26500337
B21: Operating Margin (%) | C21: =C20/C8 -> 0.04899931 | D21: =D20/D8 -> 0.084940363 | E21: =E20/E8 -> 0.12418063 | F21: =F20/F8 -> 0.13737009 | H21: =H20/H8 -> 0.06870229 | I21: =I20/I8 -> 0.054418605 | J21: =J20/J8 -> 0.10096154 | K21: =K20/K8 -> 0.11079196 | L21: =L20/L8 -> 0.12754514 | M21: =M20/M8 -> 0.091358965 | N21: =N20/N8 -> 0.14944583 | O21: =O20/O8 -> 0.12647954 | ... T21: =T20/T8 -> 0.13342175 | V21: =V20/V8 -> 0.084940363 | W21: =W20/W8 -> 0.10023212 | X21: =X20/X8 -> 0.10778503 | Y21: =Y20/Y8 -> 0.12041284 | Z21: =Z20/Z8 -> 0.12418063 | AA21: =AA20/AA8 -> 0.12930508 | AB21: =AB20/AB8 -> 0.13278593 | AC21: =AC20/AC8 -> 0.13854899 | ... AE21: =AE20/AE8 -> 0.13438395 | AG21: =SUM(AE21-AA21)*10000 -> 50.788709
B23: (+) Depreciation and Amortization (D&A) | C23: ='Historical Financials'!C98 -> 433 | D23: ='Historical Financials'!D98 -> 562 | E23: ='Historical Financials'!E98 -> 564 | F23: ='Historical Financials'!F98 -> 738 | H23: ='Historical Financials'!H98 -> 126 | I23: ='Historical Financials'!I98 -> 136 | J23: ='Historical Financials'!J98 -> 146 | K23: ='Historical Financials'!K98 -> 154 | L23: ='Historical Financials'!L98 -> 130 | M23: ='Historical Financials'!M98 -> 136 | N23: ='Historical Financials'!N98 -> 144 | O23: ='Historical Financials'!O98 -> 154 | ... T23: ='Historical Financials'!T98 -> 258 | V23: =SUM(H23:K23) -> 562 | W23: =SUM(I23:L23) -> 566 | X23: =SUM(J23:M23) -> 566 | Y23: =SUM(K23:N23) -> 564 | Z23: =SUM(L23:O23) -> 564 | AA23: =SUM(M23:P23) -> 594 | AB23: =SUM(N23:Q23) -> 630 | AC23: =SUM(O23:R23) -> 680 | ... AE23: =SUM(Q23:T23) -> 836 | AG23: =SUM(AE23/AA23)-1 -> 0.40740741
B24: EBITDA | C24: =SUM(C20+SUM(C23:C23)) -> 788 | D24: =SUM(D20+SUM(D23:D23)) -> 1324 | E24: =SUM(E20+SUM(E23:E23)) -> 1928 | F24: =SUM(F20+SUM(F23:F23)) -> 2562 | H24: =SUM(H20+SUM(H23:H23)) -> 270 | I24: =SUM(I20+SUM(I23:I23)) -> 253 | J24: =SUM(J20+SUM(J23:J23)) -> 377 | K24: =SUM(K20+SUM(K23:K23)) -> 424 | L24: =SUM(L20+SUM(L23:L23)) -> 462 | M24: =SUM(M20+SUM(M23:M23)) -> 376 | N24: =SUM(N20+SUM(N23:N23)) -> 562 | O24: =SUM(O20+SUM(O23:O23)) -> 528 | ... T24: =SUM(T20+SUM(T23:T23)) -> 761 | V24: =SUM(V20+SUM(V23:V23)) -> 1324 | W24: =SUM(W20+SUM(W23:W23)) -> 1516 | X24: =SUM(X20+SUM(X23:X23)) -> 1639 | Y24: =SUM(Y20+SUM(Y23:Y23)) -> 1824 | Z24: =SUM(Z20+SUM(Z23:Z23)) -> 1928 | AA24: =SUM(AA20+SUM(AA23:AA23)) -> 2077 | AB24: =SUM(AB20+SUM(AB23:AB23)) -> 2231 | AC24: =SUM(AC20+SUM(AC23:AC23)) -> 2435 | ... AE24: =SUM(AE20+SUM(AE23:AE23)) -> 2712 | AG24: =SUM(AE24/AA24)-1 -> 0.30572942
B25: EBITDA Margin (%) | C25: =C24/C8 -> 0.10876467 | D25: =D24/D8 -> 0.14758667 | E25: =E24/E8 -> 0.17552804 | F25: =F24/F8 -> 0.19295075 | H25: =H24/H8 -> 0.12881679 | I25: =I24/I8 -> 0.11767442 | J25: =J24/J8 -> 0.16477273 | K25: =K24/K8 -> 0.17398441 | L25: =L24/L8 -> 0.17748751 | M25: =M24/M8 -> 0.14312904 | N25: =N24/N8 -> 0.20092957 | O25: =O24/O8 -> 0.17855935 | ... T25: =T24/T8 -> 0.20185676 | V25: =V24/V8 -> 0.14758667 | W25: =W24/W8 -> 0.15994936 | X25: =X24/X8 -> 0.16464088 | Y25: =Y24/Y8 -> 0.17431193 | Z25: =Z24/Z8 -> 0.17552804 | AA25: =AA24/AA8 -> 0.18109687 | AB25: =AB24/AB8 -> 0.18503774 | AC25: =AC24/AC8 -> 0.19223178 | ... AE25: =AE24/AE8 -> 0.19426934 | AG25: =SUM(AE25-AA25)*10000 -> 131.72471
B27: (+) Stock-Based Compensation (SBC) | C27: ='Historical Financials'!C100 -> 1401 | D27: ='Historical Financials'!D100 -> 1604 | E27: ='Historical Financials'!E100 -> 1746 | F27: ='Historical Financials'!F100 -> 1955 | H27: ='Historical Financials'!H100 -> 381 | I27: ='Historical Financials'!I100 -> 397 | J27: ='Historical Financials'!J100 -> 413 | K27: ='Historical Financials'!K100 -> 413 | L27: ='Historical Financials'!L100 -> 422 | M27: ='Historical Financials'!M100 -> 444 | N27: ='Historical Financials'!N100 -> 426 | O27: ='Historical Financials'!O100 -> 454 | ... T27: ='Historical Financials'!T100 -> 547 | V27: =SUM(H27:K27) -> 1604 | W27: =SUM(I27:L27) -> 1645 | X27: =SUM(J27:M27) -> 1692 | Y27: =SUM(K27:N27) -> 1705 | Z27: =SUM(L27:O27) -> 1746 | AA27: =SUM(M27:P27) -> 1794 | AB27: =SUM(N27:Q27) -> 1849 | AC27: =SUM(O27:R27) -> 1915 | ... AE27: =SUM(Q27:T27) -> 2032 | AG27: =SUM(AE27/AA27)-1 -> 0.13266444
B28: (+) Amortization of Deferred Commissions | C28: ='Historical Financials'!C99 -> 358 | D28: ='Historical Financials'!D99 -> 459 | E28: ='Historical Financials'!E99 -> 550 | F28: ='Historical Financials'!F99 -> 621 | H28: ='Historical Financials'!H99 -> 106 | I28: ='Historical Financials'!I99 -> 112 | J28: ='Historical Financials'!J99 -> 115 | K28: ='Historical Financials'!K99 -> 126 | L28: ='Historical Financials'!L99 -> 131 | M28: ='Historical Financials'!M99 -> 132 | N28: ='Historical Financials'!N99 -> 140 | O28: ='Historical Financials'!O99 -> 147 | ... T28: ='Historical Financials'!T99 -> 168 | V28: =SUM(H28:K28) -> 459 | W28: =SUM(I28:L28) -> 484 | X28: =SUM(J28:M28) -> 504 | Y28: =SUM(K28:N28) -> 529 | Z28: =SUM(L28:O28) -> 550 | AA28: =SUM(M28:P28) -> 564 | AB28: =SUM(N28:Q28) -> 580 | AC28: =SUM(O28:R28) -> 601 | ... AE28: =SUM(Q28:T28) -> 644 | AG28: =SUM(AE28/AA28)-1 -> 0.14184397
B29: Adj. EBITDA | C29: =+SUM(C24+SUM(C27:C27)) -> 2189 | D29: =+SUM(D24+SUM(D27:D27)) -> 2928 | E29: =+SUM(E24+SUM(E27:E27)) -> 3674 | F29: =+SUM(F24+SUM(F27:F27)) -> 4517 | H29: =+SUM(H24+SUM(H27:H27)) -> 651 | I29: =+SUM(I24+SUM(I27:I27)) -> 650 | J29: =+SUM(J24+SUM(J27:J27)) -> 790 | K29: =+SUM(K24+SUM(K27:K27)) -> 837 | L29: =+SUM(L24+SUM(L27:L27)) -> 884 | M29: =+SUM(M24+SUM(M27:M27)) -> 820 | N29: =+SUM(N24+SUM(N27:N27)) -> 988 | O29: =+SUM(O24+SUM(O27:O27)) -> 982 | ... T29: =+SUM(T24+SUM(T27:T27)) -> 1308 | V29: =+SUM(V24+SUM(V27:V27)) -> 2928 | W29: =+SUM(W24+SUM(W27:W27)) -> 3161 | X29: =+SUM(X24+SUM(X27:X27)) -> 3331 | Y29: =+SUM(Y24+SUM(Y27:Y27)) -> 3529 | Z29: =+SUM(Z24+SUM(Z27:Z27)) -> 3674 | AA29: =+SUM(AA24+SUM(AA27:AA27)) -> 3871 | AB29: =+SUM(AB24+SUM(AB27:AB27)) -> 4080 | AC29: =+SUM(AC24+SUM(AC27:AC27)) -> 4350 | ... AE29: =+SUM(AE24+SUM(AE27:AE27)) -> 4744 | AG29: =SUM(AE29/AA29)-1 -> 0.22552312
B30: Adj. EBITDA Margin (%) | C30: =C29/C8 -> 0.30213941 | D30: =D29/D8 -> 0.32638502 | E30: =E29/E8 -> 0.33448653 | F30: =F29/F8 -> 0.34018678 | H30: =H29/H8 -> 0.3105916 | I30: =I29/I8 -> 0.30232558 | J30: =J29/J8 -> 0.34527972 | K30: =K29/K8 -> 0.34345507 | L30: =L29/L8 -> 0.33960814 | M30: =M29/M8 -> 0.31214313 | N30: =N29/N8 -> 0.35323561 | O30: =O29/O8 -> 0.33209334 | ... T30: =T29/T8 -> 0.3469496 | V30: =V29/V8 -> 0.32638502 | W30: =W29/W8 -> 0.33350918 | X30: =X29/X8 -> 0.33460573 | Y30: =Y29/Y8 -> 0.33725153 | Z30: =Z29/Z8 -> 0.33448653 | AA30: =AA29/AA8 -> 0.33751853 | AB30: =AB29/AB8 -> 0.33839263 | AC30: =AC29/AC8 -> 0.34341202 | ... AE30: =AE29/AE8 -> 0.33982808 | AG30: =SUM(AE30-AA30)*10000 -> 23.09552
B32: (-) Capital Expenditures | C32: ='Historical Financials'!C114 -> -550 | D32: ='Historical Financials'!D114 -> -694 | E32: ='Historical Financials'!E114 -> -852 | F32: ='Historical Financials'!F114 -> -868 | H32: ='Historical Financials'!H114 -> -165 | I32: ='Historical Financials'!I114 -> -132 | J32: ='Historical Financials'!J114 -> -136 | K32: ='Historical Financials'!K114 -> -261 | L32: ='Historical Financials'!L114 -> -135 | M32: ='Historical Financials'!M114 -> -262 | N32: ='Historical Financials'!N114 -> -202 | O32: ='Historical Financials'!O114 -> -253 | ... T32: ='Historical Financials'!T114 -> -141 | V32: =SUM(H32:K32) -> -694 | W32: =SUM(I32:L32) -> -664 | X32: =SUM(J32:M32) -> -794 | Y32: =SUM(K32:N32) -> -860 | Z32: =SUM(L32:O32) -> -852 | AA32: =SUM(M32:P32) -> -922 | AB32: =SUM(N32:Q32) -> -850 | AC32: =SUM(O32:R32) -> -883 | ... AE32: =SUM(Q32:T32) -> -804 | AG32: =SUM(AE32/AA32)-1 -> -0.12798265
B33: (-) Cash Taxes | C33: =-'Historical Financials'!C148 -> -45 | D33: =-'Historical Financials'!D148 -> -127 | E33: =-'Historical Financials'!E148 -> -230 | F33: =-'Historical Financials'!F148 -> -283 | H33: =-'Historical Financials'!H148 -> -22 | I33: =-'Historical Financials'!I148 -> -41 | J33: =-'Historical Financials'!J148 -> -40 | K33: =-'Historical Financials'!K148 -> -24 | L33: =-'Historical Financials'!L148 -> -21 | M33: =-'Historical Financials'!M148 -> -91 | N33: =-'Historical Financials'!N148 -> -71 | O33: =-'Historical Financials'!O148 -> -47 | ... T33: =-'Historical Financials'!T148 -> -38 | V33: =SUM(H33:K33) -> -127 | W33: =SUM(I33:L33) -> -126 | X33: =SUM(J33:M33) -> -176 | Y33: =SUM(K33:N33) -> -207 | Z33: =SUM(L33:O33) -> -230 | AA33: =SUM(M33:P33) -> -245 | AB33: =SUM(N33:Q33) -> -247 | AC33: =SUM(O33:R33) -> -228 | ... AE33: =SUM(Q33:T33) -> -285 | AG33: =SUM(AE33/AA33)-1 -> 0.16326531
B34: (-) Cash Interest | C34: =-'Historical Financials'!C147 -> -24 | D34: =-'Historical Financials'!D147 -> -23 | E34: =-'Historical Financials'!E147 -> -23 | F34: =-'Historical Financials'!F147 -> -22 | H34: =-'Historical Financials'!H147 -> -11 | I34: =-'Historical Financials'!I147 -> -1 | J34: =-'Historical Financials'!J147 -> -11 | K34: =-'Historical Financials'!K147 -> 0 | L34: =-'Historical Financials'!L147 -> -11 | M34: =-'Historical Financials'!M147 -> -1 | N34: =-'Historical Financials'!N147 -> -11 | O34: =-'Historical Financials'!O147 -> 0 | ... T34: =-'Historical Financials'!T147 -> -11 | V34: =SUM(H34:K34) -> -23 | W34: =SUM(I34:L34) -> -23 | X34: =SUM(J34:M34) -> -23 | Y34: =SUM(K34:N34) -> -23 | Z34: =SUM(L34:O34) -> -23 | AA34: =SUM(M34:P34) -> -23 | AB34: =SUM(N34:Q34) -> -22 | AC34: =SUM(O34:R34) -> -22 | ... AE34: =SUM(Q34:T34) -> -22 | AG34: =SUM(AE34/AA34)-1 -> -0.043478261
B35: (-) Mandatory Outflows | C35: 0 | D35: 0 | E35: 0 | F35: 0 | H35: 0 | I35: 0 | J35: 0 | K35: 0 | L35: 0 | M35: 0 | N35: 0 | O35: 0 | P35: 0 | Q35: 0 | R35: 0 | S35: 0 | T35: 0 | V35: =SUM(H35:K35) -> 0 | W35: =SUM(I35:L35) -> 0 | X35: =SUM(J35:M35) -> 0 | Y35: =SUM(K35:N35) -> 0 | Z35: =SUM(L35:O35) -> 0 | AA35: =SUM(M35:P35) -> 0 | AB35: =SUM(N35:Q35) -> 0 | AC35: =SUM(O35:R35) -> 0 | ... AE35: =SUM(Q35:T35) -> 0 | AG35: =SUM(AE35/AA35)-1 -> #DIV/0!
B36: (+/-) Changes in NWC | C36: =SUM('Historical Financials'!C105:C110) -> 174 | D36: =SUM('Historical Financials'!D105:D110) -> -101 | E36: =SUM('Historical Financials'!E105:E110) -> -65 | F36: =SUM('Historical Financials'!F105:F110) -> 29 | H36: =SUM('Historical Financials'!H105:H110) -> 131 | I36: =SUM('Historical Financials'!I105:I110) -> -195 | J36: =SUM('Historical Financials'!J105:J110) -> -624 | K36: =SUM('Historical Financials'!K105:K110) -> 587 | L36: =SUM('Historical Financials'!L105:L110) -> 301 | M36: =SUM('Historical Financials'!M105:M110) -> -371 | N36: =SUM('Historical Financials'!N105:N110) -> -460 | O36: =SUM('Historical Financials'!O105:O110) -> 465 | ... T36: =SUM('Historical Financials'!T105:T110) -> 208 | V36: =SUM(H36:K36) -> -101 | W36: =SUM(I36:L36) -> 69 | X36: =SUM(J36:M36) -> -107 | Y36: =SUM(K36:N36) -> 57 | Z36: =SUM(L36:O36) -> -65 | AA36: =SUM(M36:P36) -> 40 | AB36: =SUM(N36:Q36) -> -151 | AC36: =SUM(O36:R36) -> -332 | ... AE36: =SUM(Q36:T36) -> -169 | AG36: =SUM(AE36/AA36)-1 -> -5.225
B37: Discretionary Cash-Flows | C37: =SUM(C29+SUM(C32:C36)) -> 1744 | D37: =SUM(D29+SUM(D32:D36)) -> 1983 | E37: =SUM(E29+SUM(E32:E36)) -> 2504 | F37: =SUM(F29+SUM(F32:F36)) -> 3373 | H37: =SUM(H29+SUM(H32:H36)) -> 584 | I37: =SUM(I29+SUM(I32:I36)) -> 281 | J37: =SUM(J29+SUM(J32:J36)) -> -21 | K37: =SUM(K29+SUM(K32:K36)) -> 1139 | L37: =SUM(L29+SUM(L32:L36)) -> 1018 | M37: =SUM(M29+SUM(M32:M36)) -> 95 | N37: =SUM(N29+SUM(N32:N36)) -> 244 | O37: =SUM(O29+SUM(O32:O36)) -> 1147 | ... T37: =SUM(T29+SUM(T32:T36)) -> 1326 | V37: =SUM(V29+SUM(V32:V36)) -> 1983 | W37: =SUM(W29+SUM(W32:W36)) -> 2417 | X37: =SUM(X29+SUM(X32:X36)) -> 2231 | Y37: =SUM(Y29+SUM(Y32:Y36)) -> 2496 | Z37: =SUM(Z29+SUM(Z32:Z36)) -> 2504 | AA37: =SUM(AA29+SUM(AA32:AA36)) -> 2721 | AB37: =SUM(AB29+SUM(AB32:AB36)) -> 2810 | AC37: =SUM(AC29+SUM(AC32:AC36)) -> 2885 | ... AE37: =SUM(AE29+SUM(AE32:AE36)) -> 3464 | AG37: =SUM(AE37/AA37)-1 -> 0.27306137
B39: (+/-) Sales & Maturity / (Purchase) of Marketable Securities | C39: =SUM('Historical Financials'!C121:C122) -> 0 | D39: =SUM('Historical Financials'!D121:D122) -> -1112 | E39: =SUM('Historical Financials'!E121:E122) -> -1279 | F39: =SUM('Historical Financials'!F121:F122) -> 1324 | H39: =SUM('Historical Financials'!H121:H122) -> 0 | I39: =SUM('Historical Financials'!I121:I122) -> 0 | J39: =SUM('Historical Financials'!J121:J122) -> 0 | K39: =SUM('Historical Financials'!K121:K122) -> -1112 | L39: =SUM('Historical Financials'!L121:L122) -> 0 | M39: =SUM('Historical Financials'!M121:M122) -> 0 | N39: =SUM('Historical Financials'!N121:N122) -> -928 | O39: =SUM('Historical Financials'!O121:O122) -> -351 | ... T39: =SUM('Historical Financials'!T121:T122) -> 1108 | V39: =SUM(H39:K39) -> -1112 | W39: =SUM(I39:L39) -> -1112 | X39: =SUM(J39:M39) -> -1112 | Y39: =SUM(K39:N39) -> -2040 | Z39: =SUM(L39:O39) -> -1279 | AA39: =SUM(M39:P39) -> -1238 | AB39: =SUM(N39:Q39) -> -1279 | AC39: =SUM(O39:R39) -> 340 | ... AE39: =SUM(Q39:T39) -> 2391
B40: (+/-) Divestitures / (Acquisitions) | C40: ='Historical Financials'!C115+'Historical Financials'!C131 -> -91 | D40: ='Historical Financials'!D115+'Historical Financials'!D131 -> -279 | E40: ='Historical Financials'!E115+'Historical Financials'!E131 -> -297 | F40: ='Historical Financials'!F115+'Historical Financials'!F131 -> -1084 | H40: ='Historical Financials'!H115+'Historical Financials'!H131 -> 0 | I40: ='Historical Financials'!I115+'Historical Financials'!I131 -> 0 | J40: ='Historical Financials'!J115+'Historical Financials'!J131 -> -279 | K40: ='Historical Financials'!K115+'Historical Financials'!K131 -> 0 | L40: ='Historical Financials'!L115+'Historical Financials'!L131 -> -194 | M40: ='Historical Financials'!M115+'Historical Financials'!M131 -> -31 | N40: ='Historical Financials'!N115+'Historical Financials'!N131 -> -41 | O40: ='Historical Financials'!O115+'Historical Financials'!O131 -> -31 | ... T40: ='Historical Financials'!T115+'Historical Financials'!T131 -> -1325 | V40: =SUM(H40:K40) -> -279 | W40: =SUM(I40:L40) -> -473 | X40: =SUM(J40:M40) -> -504 | Y40: =SUM(K40:N40) -> -266 | Z40: =SUM(L40:O40) -> -297 | AA40: =SUM(M40:P40) -> -121 | AB40: =SUM(N40:Q40) -> -148 | AC40: =SUM(O40:R40) -> -246 | ... AE40: =SUM(Q40:T40) -> -2391
B41: (+/-) Sales and Maturities / (Purchase) of Investments | C41: =SUM('Historical Financials'!C117:C120) -> -1960 | D41: =SUM('Historical Financials'!D117:D120) -> -75 | E41: =SUM('Historical Financials'!E117:E120) -> -181 | F41: =SUM('Historical Financials'!F117:F120) -> -1056 | H41: =SUM('Historical Financials'!H117:H120) -> -372 | I41: =SUM('Historical Financials'!I117:I120) -> -542 | J41: =SUM('Historical Financials'!J117:J120) -> -79 | K41: =SUM('Historical Financials'!K117:K120) -> 918 | L41: =SUM('Historical Financials'!L117:L120) -> -574 | M41: =SUM('Historical Financials'!M117:M120) -> -61 | N41: =SUM('Historical Financials'!N117:N120) -> 486 | O41: =SUM('Historical Financials'!O117:O120) -> -32 | ... T41: =SUM('Historical Financials'!T117:T120) -> -121 | V41: =SUM(H41:K41) -> -75 | W41: =SUM(I41:L41) -> -277 | X41: =SUM(J41:M41) -> 204 | Y41: =SUM(K41:N41) -> 769 | Z41: =SUM(L41:O41) -> -181 | AA41: =SUM(M41:P41) -> 389 | AB41: =SUM(N41:Q41) -> 275 | AC41: =SUM(O41:R41) -> -1052 | ... AE41: =SUM(Q41:T41) -> -1173
B42: (+/-) Proceeds / (Repayment) of Debt | C42: ='Historical Financials'!C127 -> -94 | D42: ='Historical Financials'!D127 -> 0 | E42: ='Historical Financials'!E127 -> 0 | F42: ='Historical Financials'!F127 -> 0 | H42: ='Historical Financials'!H127 -> 0 | I42: ='Historical Financials'!I127 -> 0 | J42: ='Historical Financials'!J127 -> 0 | K42: ='Historical Financials'!K127 -> 0 | L42: ='Historical Financials'!L127 -> 0 | M42: ='Historical Financials'!M127 -> 0 | N42: ='Historical Financials'!N127 -> 0 | O42: ='Historical Financials'!O127 -> 0 | ... T42: ='Historical Financials'!T127 -> 0 | V42: =SUM(H42:K42) -> 0 | W42: =SUM(I42:L42) -> 0 | X42: =SUM(J42:M42) -> 0 | Y42: =SUM(K42:N42) -> 0 | Z42: =SUM(L42:O42) -> 0 | AA42: =SUM(M42:P42) -> 0 | AB42: =SUM(N42:Q42) -> 0 | AC42: =SUM(O42:R42) -> 0 | ... AE42: =SUM(Q42:T42) -> 0
B43: (+/-) Issuance / (Repurchase) of Common Stock | C43: ='Historical Financials'!C129 -> 0 | D43: ='Historical Financials'!D129 -> -538 | E43: ='Historical Financials'!E129 -> -696 | F43: ='Historical Financials'!F129 -> -1840 | H43: ='Historical Financials'!H129 -> 0 | I43: ='Historical Financials'!I129 -> 0 | J43: ='Historical Financials'!J129 -> -282 | K43: ='Historical Financials'!K129 -> -256 | L43: ='Historical Financials'!L129 -> -175 | M43: ='Historical Financials'!M129 -> 0 | N43: ='Historical Financials'!N129 -> -225 | O43: ='Historical Financials'!O129 -> -296 | ... T43: ='Historical Financials'!T129 -> -2225 | V43: =SUM(H43:K43) -> -538 | W43: =SUM(I43:L43) -> -713 | X43: =SUM(J43:M43) -> -713 | Y43: =SUM(K43:N43) -> -656 | Z43: =SUM(L43:O43) -> -696 | AA43: =SUM(M43:P43) -> -819 | AB43: =SUM(N43:Q43) -> -1180 | AC43: =SUM(O43:R43) -> -1539 | ... AE43: =SUM(Q43:T43) -> -3767
B44: (+/-) Proceeds from Exercise of Stock Options | C44: ='Historical Financials'!C128 -> 177 | D44: ='Historical Financials'!D128 -> 194 | E44: ='Historical Financials'!E128 -> 237 | F44: ='Historical Financials'!F128 -> 270 | H44: ='Historical Financials'!H128 -> 117 | I44: ='Historical Financials'!I128 -> 0 | J44: ='Historical Financials'!J128 -> 76 | K44: ='Historical Financials'!K128 -> 1 | L44: ='Historical Financials'!L128 -> 131 | M44: ='Historical Financials'!M128 -> 0 | N44: ='Historical Financials'!N128 -> 106 | O44: ='Historical Financials'!O128 -> 0 | ... T44: ='Historical Financials'!T128 -> 153 | V44: =SUM(H44:K44) -> 194 | W44: =SUM(I44:L44) -> 208 | X44: =SUM(J44:M44) -> 208 | Y44: =SUM(K44:N44) -> 238 | Z44: =SUM(L44:O44) -> 237 | AA44: =SUM(M44:P44) -> 259 | AB44: =SUM(N44:Q44) -> 259 | AC44: =SUM(O44:R44) -> 270 | ... AE44: =SUM(Q44:T44) -> 270
B45: (+/-) Taxes Paid Related to Net Share Settlement of Equity Awards | C45: ='Historical Financials'!C130 -> -427 | D45: ='Historical Financials'!D130 -> -459 | E45: ='Historical Financials'!E130 -> -700 | F45: ='Historical Financials'!F130 -> -770 | H45: ='Historical Financials'!H130 -> -112 | I45: ='Historical Financials'!I130 -> -94 | J45: ='Historical Financials'!J130 -> -127 | K45: ='Historical Financials'!K130 -> -126 | L45: ='Historical Financials'!L130 -> -215 | M45: ='Historical Financials'!M130 -> -137 | N45: ='Historical Financials'!N130 -> -173 | O45: ='Historical Financials'!O130 -> -175 | ... T45: ='Historical Financials'!T130 -> -164 | V45: =SUM(H45:K45) -> -459 | W45: =SUM(I45:L45) -> -562 | X45: =SUM(J45:M45) -> -605 | Y45: =SUM(K45:N45) -> -651 | Z45: =SUM(L45:O45) -> -700 | AA45: =SUM(M45:P45) -> -738 | AB45: =SUM(N45:Q45) -> -786 | AC45: =SUM(O45:R45) -> -803 | ... AE45: =SUM(Q45:T45) -> -681
B46: (+/-) Other | D46: =SUM(D51)-SUM(C51)-SUM(D37:D43) -> 448 | E46: =SUM(E51)-SUM(D51)-SUM(E37:E43) -> 356 | F46: =SUM(F51)-SUM(E51)-SUM(F37:F43) -> 705 | H46: =SUM(H51)-SUM(C51)-SUM(H37:H43) -> 170 | I46: =SUM(I51)-SUM(H51)-SUM(I37:I43) -> 72 | J46: =SUM(J51)-SUM(I51)-SUM(J37:J43) -> 110 | K46: =SUM(K51)-SUM(J51)-SUM(K37:K43) -> 96 | L46: =SUM(L51)-SUM(K51)-SUM(L37:L43) -> 84 | M46: =SUM(M51)-SUM(L51)-SUM(M37:M43) -> 100 | N46: =SUM(N51)-SUM(M51)-SUM(N37:N43) -> 190 | O46: =SUM(O51)-SUM(N51)-SUM(O37:O43) -> -18 | P46: =SUM(P51)-SUM(O51)-SUM(P37:P43) -> 109 | ... T46: =SUM(T51)-SUM(S51)-SUM(T37:T43) -> 213 | V46: =SUM(H46:K46) -> 448 | W46: =SUM(I46:L46) -> 362 | X46: =SUM(J46:M46) -> 390 | Y46: =SUM(K46:N46) -> 470 | Z46: =SUM(L46:O46) -> 356 | AA46: =SUM(M46:P46) -> 381 | AB46: =SUM(N46:Q46) -> 487 | AC46: =SUM(O46:R46) -> 452 | ... AE46: =SUM(Q46:T46) -> 809
