Workbook

Sheet Historical Financials
B2: Microstrategy, Inc. (NASDAQ: MSTR)
B3: Historical Financials
B4: $ in thousands except per share
A6: X | B6: Income Statement | D6: FYE | H6: Quarterly | R6: Quarterly | AD6: LTM | AE6: LTM | AK6: Variance
B7: Fiscal Period | C7: 2021 | D7: 2022 | E7: 2023 | F7: 2024 | H7: 1Q22 | I7: 2Q22 | J7: 3Q22 | K7: 4Q22 | L7: 1Q23 | M7: 2Q23 | N7: 3Q23 | O7: 4Q23 | P7: 1Q24 | Q7: 2Q24 | R7: 3Q24 | S7: 4Q24 | T7: 1Q25 | U7: 2Q25 | V7: 3Q25 | X7: =K7 -> 4Q22 | Y7: =L7 -> 1Q23 | Z7: =M7 -> 2Q23 | AA7: =N7 -> 3Q23 | AB7: =O7 -> 4Q23 | AC7: =P7 -> 1Q24 | AD7: =Q7 -> 2Q24 | AE7: =R7 -> 3Q24 | ... AI7: =V7 -> 3Q25
B8: Fiscal Period End Date | C8: 44561 | D8: 44926 | E8: 45291 | F8: 45657 | H8: 44651 | I8: 44742 | J8: 44834 | K8: =D8 -> 44926 | L8: 45016 | M8: 45107 | N8: 45199 | O8: =E8 -> 45291 | P8: 45382 | Q8: 45473 | R8: 45565 | S8: =F8 -> 45657 | T8: 45747 | U8: 45838 | V8: 45930 | X8: =K8 -> 44926 | Y8: =L8 -> 45016 | Z8: =M8 -> 45107 | AA8: =N8 -> 45199 | AB8: =O8 -> 45291 | AC8: =P8 -> 45382 | AD8: =Q8 -> 45473 | AE8: =R8 -> 45565 | ... AI8: =V8 -> 45930
B10: Consolidated Revenue | C10: 510762 | D10: 499264 | E10: 496261 | F10: 463456 | H10: 119277 | I10: 122073 | J10: 125360 | K10: =SUM(D10-SUM(H10:J10)) -> 132554 | L10: 121915 | M10: 120400 | N10: 129462 | O10: =SUM(E10-SUM(L10:N10)) -> 124484 | P10: 115246 | Q10: 111442 | R10: 116071 | S10: =SUM(F10-SUM(P10:R10)) -> 120697 | T10: 111066 | U10: 114488 | V10: 128691 | X10: =SUM(H10:K10) -> 499264 | Y10: =SUM(I10:L10) -> 501902 | Z10: =SUM(J10:M10) -> 500229 | AA10: =SUM(K10:N10) -> 504331 | AB10: =SUM(L10:O10) -> 496261 | AC10: =SUM(M10:P10) -> 489592 | AD10: =SUM(N10:Q10) -> 480634 | AE10: =SUM(O10:R10) -> 467243 | ... AI10: =SUM(S10:V10) -> 474942 | AK10: =SUM(AH10/AD10)-1 -> -0.038099677
B11: Total Revenue | C11: =+SUM(C10:C10) -> 510762 | D11: =+SUM(D10:D10) -> 499264 | E11: =+SUM(E10:E10) -> 496261 | F11: =+SUM(F10:F10) -> 463456 | H11: =+SUM(H10:H10) -> 119277 | I11: =+SUM(I10:I10) -> 122073 | J11: =+SUM(J10:J10) -> 125360 | K11: =+SUM(K10:K10) -> 132554 | L11: =+SUM(L10:L10) -> 121915 | M11: =+SUM(M10:M10) -> 120400 | N11: =+SUM(N10:N10) -> 129462 | O11: =+SUM(O10:O10) -> 124484 | ... V11: =+SUM(V10:V10) -> 128691 | X11: =+SUM(X10:X10) -> 499264 | Y11: =+SUM(Y10:Y10) -> 501902 | Z11: =+SUM(Z10:Z10) -> 500229 | AA11: =+SUM(AA10:AA10) -> 504331 | AB11: =+SUM(AB10:AB10) -> 496261 | AC11: =+SUM(AC10:AC10) -> 489592 | AD11: =+SUM(AD10:AD10) -> 480634 | AE11: =+SUM(AE10:AE10) -> 467243 | ... AI11: =+SUM(AI10:AI10) -> 474942 | AK11: =SUM(AH11/AD11)-1 -> -0.038099677
B13: Cost of Revenue | C13: -91909 | D13: -102989 | E13: -109944 | F13: -129468 | H13: -25677 | I13: -25204 | J13: -25385 | K13: =SUM(D13-SUM(H13:J13)) -> -26723 | L13: -27941 | M13: -27121 | N13: -26661 | O13: =SUM(E13-SUM(L13:N13)) -> -28221 | P13: -30015 | Q13: -30935 | R13: -34349 | S13: =SUM(F13-SUM(P13:R13)) -> -34169 | T13: -33971 | U13: -35750 | V13: -38013 | X13: =SUM(I13:L13) -> -105253 | Y13: =SUM(J13:M13) -> -107170 | Z13: =SUM(K13:N13) -> -108446 | AA13: =SUM(L13:O13) -> -109944 | AB13: =SUM(M13:P13) -> -112018 | AC13: =SUM(N13:Q13) -> -115832 | AD13: =SUM(N13:Q13) -> -115832 | AE13: =SUM(O13:R13) -> -123520 | AF13: =SUM(P13:S13) -> -129468 | AG13: =SUM(Q13:T13) -> -133424 | AH13: =SUM(R13:U13) -> -138239 | AI13: =SUM(S13:V13) -> -141903 | AK13: =SUM(AH13/AD13)-1 -> 0.19344395
B14: Gross Profit | C14: =+SUM(C11+SUM(C13:C13)) -> 418853 | D14: =+SUM(D11+SUM(D13:D13)) -> 396275 | E14: =+SUM(E11+SUM(E13:E13)) -> 386317 | F14: =+SUM(F11+SUM(F13:F13)) -> 333988 | H14: =+SUM(H11+SUM(H13:H13)) -> 93600 | I14: =+SUM(I11+SUM(I13:I13)) -> 96869 | J14: =+SUM(J11+SUM(J13:J13)) -> 99975 | K14: =+SUM(K11+SUM(K13:K13)) -> 105831 | L14: =+SUM(L11+SUM(L13:L13)) -> 93974 | M14: =+SUM(M11+SUM(M13:M13)) -> 93279 | N14: =+SUM(N11+SUM(N13:N13)) -> 102801 | O14: =+SUM(O11+SUM(O13:O13)) -> 96263 | ... V14: =+SUM(V11+SUM(V13:V13)) -> 90678 | X14: =+SUM(X11+SUM(X13:X13)) -> 394011 | Y14: =+SUM(Y11+SUM(Y13:Y13)) -> 394732 | Z14: =+SUM(Z11+SUM(Z13:Z13)) -> 391783 | AA14: =+SUM(AA11+SUM(AA13:AA13)) -> 394387 | AB14: =+SUM(AB11+SUM(AB13:AB13)) -> 384243 | AC14: =+SUM(AC11+SUM(AC13:AC13)) -> 373760 | AD14: =+SUM(AD11+SUM(AD13:AD13)) -> 364802 | AE14: =+SUM(AE11+SUM(AE13:AE13)) -> 343723 | ... AI14: =+SUM(AI11+SUM(AI13:AI13)) -> 333039 | AK14: =SUM(AH14/AD14)-1 -> -0.11161945
B15: Gross Margin (%) | C15: =C14/C11 -> 0.82005513 | D15: =D14/D11 -> 0.79371835 | E15: =E14/E11 -> 0.77845529 | F15: =F14/F11 -> 0.72064662 | H15: =H14/H11 -> 0.78472799 | I15: =I14/I11 -> 0.79353338 | J15: =J14/J11 -> 0.79750319 | K15: =K14/K11 -> 0.79839914 | L15: =L14/L11 -> 0.77081573 | M15: =M14/M11 -> 0.77474252 | N15: =N14/N11 -> 0.79406312 | O15: =O14/O11 -> 0.77329617 | ... V15: =V14/V11 -> 0.70461804 | X15: =X14/X11 -> 0.78918368 | Y15: =Y14/Y11 -> 0.78647226 | Z15: =Z14/Z11 -> 0.78320729 | AA15: =AA14/AA11 -> 0.78200031 | AB15: =AB14/AB11 -> 0.77427604 | AC15: =AC14/AC11 -> 0.76341117 | AD15: =AD14/AD11 -> 0.75900165 | AE15: =AE14/AE11 -> 0.73564077 | ... AI15: =AI14/AI11 -> 0.70122036 | AK15: =SUM(AH15-AD15)*1000 -> -58.011866
B17: Sales and marketing | C17: -160141 | D17: -146882 | E17: -149671 | F17: -138081 | H17: -33240 | I17: -36862 | J17: -35409 | K17: =SUM(D17-SUM(H17:J17)) -> -41371 | L17: -36106 | M17: -37660 | N17: -35606 | O17: =SUM(E17-SUM(L17:N17)) -> -40299 | P17: -33451 | Q17: -34251 | R17: -35414 | S17: =SUM(F17-SUM(P17:R17)) -> -34965 | T17: -27532 | U17: -33691 | V17: -29908 | X17: =SUM(I17:L17) -> -149748 | Y17: =SUM(J17:M17) -> -150546 | Z17: =SUM(K17:N17) -> -150743 | AA17: =SUM(L17:O17) -> -149671 | AB17: =SUM(M17:P17) -> -147016 | AC17: =SUM(N17:Q17) -> -143607 | AD17: =SUM(N17:Q17) -> -143607 | AE17: =SUM(O17:R17) -> -143415 | AF17: =SUM(P17:S17) -> -138081 | AG17: =SUM(Q17:T17) -> -132162 | AH17: =SUM(R17:U17) -> -131602 | AI17: =SUM(S17:V17) -> -126096 | AK17: =SUM(AH17/AD17)-1 -> -0.083596204
B18: Research and development | C18: -117117 | D18: -127428 | E18: -120530 | F18: -118486 | H18: -33523 | I18: -31790 | J18: -30498 | K18: =SUM(D18-SUM(H18:J18)) -> -31617 | L18: -31358 | M18: -29354 | N18: -29660 | O18: =SUM(E18-SUM(L18:N18)) -> -30158 | P18: -29183 | Q18: -30311 | R18: -33301 | S18: =SUM(F18-SUM(P18:R18)) -> -25691 | T18: -24423 | U18: -24071 | V18: -22602 | X18: =SUM(I18:L18) -> -125263 | Y18: =SUM(J18:M18) -> -122827 | Z18: =SUM(K18:N18) -> -121989 | AA18: =SUM(L18:O18) -> -120530 | AB18: =SUM(M18:P18) -> -118355 | AC18: =SUM(N18:Q18) -> -119312 | AD18: =SUM(N18:Q18) -> -119312 | AE18: =SUM(O18:R18) -> -122953 | AF18: =SUM(P18:S18) -> -118486 | AG18: =SUM(Q18:T18) -> -113726 | AH18: =SUM(R18:U18) -> -107486 | AI18: =SUM(S18:V18) -> -96787 | AK18: =SUM(AH18/AD18)-1 -> -0.099118278
B19: General and administrative | C19: -95501 | D19: -111421 | E19: -115312 | F19: -140537 | H19: -26706 | I19: -28502 | J19: -27283 | K19: =SUM(D19-SUM(H19:J19)) -> -28930 | L19: -27906 | M19: -28830 | N19: -29223 | O19: =SUM(E19-SUM(L19:N19)) -> -29353 | P19: -34666 | Q19: -36129 | R19: -33505 | S19: =SUM(F19-SUM(P19:R19)) -> -36237 | T19: -40547 | U19: -36500 | V19: -38173 | X19: =SUM(I19:L19) -> -112621 | Y19: =SUM(J19:M19) -> -112949 | Z19: =SUM(K19:N19) -> -114889 | AA19: =SUM(L19:O19) -> -115312 | AB19: =SUM(M19:P19) -> -122072 | AC19: =SUM(N19:Q19) -> -129371 | AD19: =SUM(N19:Q19) -> -129371 | AE19: =SUM(O19:R19) -> -133653 | AF19: =SUM(P19:S19) -> -140537 | AG19: =SUM(Q19:T19) -> -146418 | AH19: =SUM(R19:U19) -> -146789 | AI19: =SUM(S19:V19) -> -151457 | AK19: =SUM(AH19/AD19)-1 -> 0.13463605
B20: Unrealized gain on digital assets | C20: 0 | D20: 0 | E20: 0 | F20: 0 | H20: 0 | I20: 0 | J20: 0 | K20: =SUM(D20-SUM(H20:J20)) -> 0 | L20: 0 | M20: 0 | N20: 0 | O20: =SUM(E20-SUM(L20:N20)) -> 0 | P20: 0 | Q20: 0 | R20: 0 | S20: =SUM(F20-SUM(P20:R20)) -> 0 | T20: -5906005 | U20: 14047514 | V20: 3890847 | X20: =SUM(I20:L20) -> 0 | Y20: =SUM(J20:M20) -> 0 | Z20: =SUM(K20:N20) -> 0 | AA20: =SUM(L20:O20) -> 0 | AB20: =SUM(M20:P20) -> 0 | AC20: =SUM(N20:Q20) -> 0 | AD20: =SUM(N20:Q20) -> 0 | AE20: =SUM(O20:R20) -> 0 | AF20: =SUM(P20:S20) -> 0 | AG20: =SUM(Q20:T20) -> -5906005 | AH20: =SUM(R20:U20) -> 8141509 | AI20: =SUM(S20:V20) -> 12032356 | AK20: =SUM(AH20/AD20)-1 -> #DIV/0!
B21: Digital asset impairment gains (losses on sale), net | C21: -830621 | D21: -1286286 | E21: -115851 | F21: -1789862 | H21: -170091 | I21: -917838 | J21: -727 | K21: =SUM(D21-SUM(H21:J21)) -> -197630 | L21: -18911 | M21: -24143 | N21: -33559 | O21: =SUM(E21-SUM(L21:N21)) -> -39238 | P21: -191633 | Q21: -180090 | R21: -412084 | S21: =SUM(F21-SUM(P21:R21)) -> -1006055 | T21: 0 | U21: 0 | V21: 0 | X21: =SUM(I21:L21) -> -1135106 | Y21: =SUM(J21:M21) -> -241411 | Z21: =SUM(K21:N21) -> -274243 | AA21: =SUM(L21:O21) -> -115851 | AB21: =SUM(M21:P21) -> -288573 | AC21: =SUM(N21:Q21) -> -444520 | AD21: =SUM(N21:Q21) -> -444520 | AE21: =SUM(O21:R21) -> -823045 | AF21: =SUM(P21:S21) -> -1789862 | AG21: =SUM(Q21:T21) -> -1598229 | AH21: =SUM(R21:U21) -> -1418139 | AI21: =SUM(S21:V21) -> -1006055 | AK21: =SUM(AH21/AD21)-1 -> 2.1902704
B22: Operating Profit | C22: =+SUM(C14+SUM(C17:C21)) -> -784527 | D22: =+SUM(D14+SUM(D17:D21)) -> -1275742 | E22: =+SUM(E14+SUM(E17:E21)) -> -115047 | F22: =+SUM(F14+SUM(F17:F21)) -> -1852978 | H22: =+SUM(H14+SUM(H17:H21)) -> -169960 | I22: =+SUM(I14+SUM(I17:I21)) -> -918123 | J22: =+SUM(J14+SUM(J17:J21)) -> 6058 | K22: =+SUM(K14+SUM(K17:K21)) -> -193717 | L22: =+SUM(L14+SUM(L17:L21)) -> -20307 | M22: =+SUM(M14+SUM(M17:M21)) -> -26708 | N22: =+SUM(N14+SUM(N17:N21)) -> -25247 | O22: =+SUM(O14+SUM(O17:O21)) -> -42785 | ... V22: =+SUM(V14+SUM(V17:V21)) -> 3890842 | X22: =+SUM(X14+SUM(X17:X21)) -> -1128727 | Y22: =+SUM(Y14+SUM(Y17:Y21)) -> -233001 | Z22: =+SUM(Z14+SUM(Z17:Z21)) -> -270081 | AA22: =+SUM(AA14+SUM(AA17:AA21)) -> -106977 | AB22: =+SUM(AB14+SUM(AB17:AB21)) -> -291773 | AC22: =+SUM(AC14+SUM(AC17:AC21)) -> -463050 | AD22: =+SUM(AD14+SUM(AD17:AD21)) -> -472008 | AE22: =+SUM(AE14+SUM(AE17:AE21)) -> -879343 | ... AI22: =+SUM(AI14+SUM(AI17:AI21)) -> 10985000 | AK22: =SUM(AH22/AD22)-1 -> -15.113269
B23: Operating Margin (%) | C23: =C22/C11 -> -1.5359933 | D23: =D22/D11 -> -2.5552453 | E23: =E22/E11 -> -0.23182761 | F23: =F22/F11 -> -3.9981746 | H23: =H22/H11 -> -1.4249185 | I23: =I22/I11 -> -7.521098 | J23: =J22/J11 -> 0.048324825 | K23: =K22/K11 -> -1.4614195 | L23: =L22/L11 -> -0.16656687 | M23: =M22/M11 -> -0.22182724 | N23: =N22/N11 -> -0.19501475 | O23: =O22/O11 -> -0.34369879 | ... V23: =V22/V11 -> 30.233987 | X23: =X22/X11 -> -2.2607819 | Y23: =Y22/Y11 -> -0.46423605 | Z23: =Z22/Z11 -> -0.53991472 | AA23: =AA22/AA11 -> -0.21211665 | AB23: =AB22/AB11 -> -0.58794264 | AC23: =AC22/AC11 -> -0.94578751 | AD23: =AD22/AD11 -> -0.98205287 | AE23: =AE22/AE11 -> -1.8819822 | ... AI23: =AI22/AI11 -> 23.12914 | AK23: =SUM(AH23-AD23)*1000 -> 15391.006
B25: Interest expense, net | C25: -29149 | D25: -53136 | E25: -48960 | F25: -61941 | H25: -11039 | I25: -13187 | J25: -14073 | K25: =SUM(D25-SUM(H25:J25)) -> -14837 | L25: -14930 | M25: -11095 | N25: -11006 | O25: =SUM(E25-SUM(L25:N25)) -> -11929 | P25: -11881 | Q25: -15466 | R25: -18129 | S25: =SUM(F25-SUM(P25:R25)) -> -16465 | T25: -17106 | U25: -17897 | V25: -18890 | X25: =SUM(I25:L25) -> -57027 | Y25: =SUM(J25:M25) -> -54935 | Z25: =SUM(K25:N25) -> -51868 | AA25: =SUM(L25:O25) -> -48960 | AB25: =SUM(M25:P25) -> -45911 | AC25: =SUM(N25:Q25) -> -50282 | AD25: =SUM(N25:Q25) -> -50282 | AE25: =SUM(O25:R25) -> -57405 | AF25: =SUM(P25:S25) -> -61941 | AG25: =SUM(Q25:T25) -> -67166 | AH25: =SUM(R25:U25) -> -69597 | AI25: =SUM(S25:V25) -> -70358 | AK25: =SUM(AH25/AD25)-1 -> 0.38413349
B26: Gain (Loss) on debt extinguishment | C26: 0 | D26: 0 | E26: 44686 | F26: -22933 | H26: 0 | I26: 0 | J26: 0 | K26: =SUM(D26-SUM(H26:J26)) -> 0 | L26: 44686 | M26: 0 | N26: 0 | O26: =SUM(E26-SUM(L26:N26)) -> 0 | P26: 0 | Q26: 0 | R26: -22933 | S26: =SUM(F26-SUM(P26:R26)) -> 0 | T26: 0 | U26: 0 | V26: 0 | X26: =SUM(I26:L26) -> 44686 | Y26: =SUM(J26:M26) -> 44686 | Z26: =SUM(K26:N26) -> 44686 | AA26: =SUM(L26:O26) -> 44686 | AB26: =SUM(M26:P26) -> 0 | AC26: =SUM(N26:Q26) -> 0 | AD26: =SUM(N26:Q26) -> 0 | AE26: =SUM(O26:R26) -> -22933 | AF26: =SUM(P26:S26) -> -22933 | AG26: =SUM(Q26:T26) -> -22933 | AH26: =SUM(R26:U26) -> -22933 | AI26: =SUM(S26:V26) -> 0 | AK26: =SUM(AH26/AD26)-1 -> #DIV/0!
B27: Other income (expense), net | C27: 2287 | D27: 6413 | E27: -5204 | F27: 3506 | H27: 2225 | I27: 5120 | J27: 4897 | K27: =SUM(D27-SUM(H27:J27)) -> -5829 | L27: -1443 | M27: -250 | N27: 2419 | O27: =SUM(E27-SUM(L27:N27)) -> -5930 | P27: 1696 | Q27: 694 | R27: -5034 | S27: =SUM(F27-SUM(P27:R27)) -> 6150 | T27: -3936 | U27: -8271 | V27: -716 | X27: =SUM(I27:L27) -> 2745 | Y27: =SUM(J27:M27) -> -2625 | Z27: =SUM(K27:N27) -> -5103 | AA27: =SUM(L27:O27) -> -5204 | AB27: =SUM(M27:P27) -> -2065 | AC27: =SUM(N27:Q27) -> -1121 | AD27: =SUM(N27:Q27) -> -1121 | AE27: =SUM(O27:R27) -> -8574 | AF27: =SUM(P27:S27) -> 3506 | AG27: =SUM(Q27:T27) -> -2126 | AH27: =SUM(R27:U27) -> -11091 | AI27: =SUM(S27:V27) -> -6773 | AK27: =SUM(AH27/AD27)-1 -> 8.8938448
B28: Earning Before Taxes | C28: =SUM(C22+SUM(C25:C27)) -> -811389 | D28: =SUM(D22+SUM(D25:D27)) -> -1322465 | E28: =SUM(E22+SUM(E25:E27)) -> -124525 | F28: =SUM(F22+SUM(F25:F27)) -> -1934346 | H28: =SUM(H22+SUM(H25:H27)) -> -178774 | I28: =SUM(I22+SUM(I25:I27)) -> -926190 | J28: =SUM(J22+SUM(J25:J27)) -> -3118 | K28: =SUM(K22+SUM(K25:K27)) -> -214383 | L28: =SUM(L22+SUM(L25:L27)) -> 8006 | M28: =SUM(M22+SUM(M25:M27)) -> -38053 | N28: =SUM(N22+SUM(N25:N27)) -> -33834 | O28: =SUM(O22+SUM(O25:O27)) -> -60644 | ... V28: =SUM(V22+SUM(V25:V27)) -> 3871236 | X28: =SUM(X22+SUM(X25:X27)) -> -1138323 | Y28: =SUM(Y22+SUM(Y25:Y27)) -> -245875 | Z28: =SUM(Z22+SUM(Z25:Z27)) -> -282366 | AA28: =SUM(AA22+SUM(AA25:AA27)) -> -116455 | AB28: =SUM(AB22+SUM(AB25:AB27)) -> -339749 | AC28: =SUM(AC22+SUM(AC25:AC27)) -> -514453 | AD28: =SUM(AD22+SUM(AD25:AD27)) -> -523411 | AE28: =SUM(AE22+SUM(AE25:AE27)) -> -968255 | ... AI28: =SUM(AI22+SUM(AI25:AI27)) -> 10907869 | AK28: =SUM(AH28/AD28)-1 -> -13.529265
B29: EBT Margin (%) | C29: =C28/C11 -> -1.5885853 | D29: =D28/D11 -> -2.6488291 | E29: =E28/E11 -> -0.25092643 | F29: =F28/F11 -> -4.1737425 | H29: =H28/H11 -> -1.4988137 | I29: =I28/I11 -> -7.5871814 | J29: =J28/J11 -> -0.024872368 | K29: =K28/K11 -> -1.6173258 | L29: =L28/L11 -> 0.065668704 | M29: =M28/M11 -> -0.31605482 | N29: =N28/N11 -> -0.2613431 | O29: =O28/O11 -> -0.48716301 | ... V29: =V28/V11 -> 30.081637 | X29: =X28/X11 -> -2.2800022 | Y29: =Y28/Y11 -> -0.48988647 | Z29: =Z28/Z11 -> -0.56447347 | AA29: =AA28/AA11 -> -0.23090986 | AB29: =AB28/AB11 -> -0.68461757 | AC29: =AC28/AC11 -> -1.050779 | AD29: =AD28/AD11 -> -1.0890012 | AE29: =AE28/AE11 -> -2.0722729 | ... AI29: =AI28/AI11 -> 22.966739 | AK29: =SUM(AH29-AD29)*1000 -> 15273.823
B31: Provision for income taxes | C31: 275909 | D31: -147332 | E31: 553646 | F31: 767685 | H31: 48023 | I31: -136108 | J31: -23961 | K31: =SUM(D31-SUM(H31:J31)) -> -35286 | L31: 453187 | M31: 60296 | N31: -109607 | O31: =SUM(E31-SUM(L31:N31)) -> 149770 | P31: 160769 | Q31: 112487 | R31: 138504 | S31: =SUM(F31-SUM(P31:R31)) -> 355925 | T31: 1725084 | U31: -3984976 | V31: -1086212 | X31: =SUM(I31:L31) -> 257832 | Y31: =SUM(J31:M31) -> 454236 | Z31: =SUM(K31:N31) -> 368590 | AA31: =SUM(L31:O31) -> 553646 | AB31: =SUM(M31:P31) -> 261228 | AC31: =SUM(N31:Q31) -> 313419 | AD31: =SUM(N31:Q31) -> 313419 | AE31: =SUM(O31:R31) -> 561530 | AF31: =SUM(P31:S31) -> 767685 | AG31: =SUM(Q31:T31) -> 2332000 | AH31: =SUM(R31:U31) -> -1765463 | AI31: =SUM(S31:V31) -> -2990179 | AK31: =SUM(AH31/AD31)-1 -> -6.6329163
B32: Net Income | C32: =SUM(C31+C28) -> -535480 | D32: =SUM(D31+D28) -> -1469797 | E32: =SUM(E31+E28) -> 429121 | F32: =SUM(F31+F28) -> -1166661 | H32: =SUM(H31+H28) -> -130751 | I32: =SUM(I31+I28) -> -1062298 | J32: =SUM(J31+J28) -> -27079 | K32: =SUM(K31+K28) -> -249669 | L32: =SUM(L31+L28) -> 461193 | M32: =SUM(M31+M28) -> 22243 | N32: =SUM(N31+N28) -> -143441 | O32: =SUM(O31+O28) -> 89126 | ... V32: =SUM(V31+V28) -> 2785024 | X32: =SUM(X31+X28) -> -880491 | Y32: =SUM(Y31+Y28) -> 208361 | Z32: =SUM(Z31+Z28) -> 86224 | AA32: =SUM(AA31+AA28) -> 437191 | AB32: =SUM(AB31+AB28) -> -78521 | AC32: =SUM(AC31+AC28) -> -201034 | AD32: =SUM(AD31+AD28) -> -209992 | AE32: =SUM(AE31+AE28) -> -406725 | ... AI32: =SUM(AI31+AI28) -> 7917690 | AK32: =SUM(AH32/AD32)-1 -> -23.82226
B33: Margin (%) | C33: =C32/C11 -> -1.0483944 | D33: =D32/D11 -> -2.9439275 | E33: =E32/E11 -> 0.86470829 | F33: =F32/F11 -> -2.5173069 | H33: =H32/H11 -> -1.0961962 | I33: =I32/I11 -> -8.7021536 | J33: =J32/J11 -> -0.21600989 | K33: =K32/K11 -> -1.8835267 | L33: =L32/L11 -> 3.7829061 | M33: =M32/M11 -> 0.18474252 | N33: =N32/N11 -> -1.1079776 | O33: =O32/O11 -> 0.7159635 | ... V33: =V32/V11 -> 21.641171 | X33: =X32/X11 -> -1.763578 | Y33: =Y32/Y11 -> 0.4151428 | Z33: =Z32/Z11 -> 0.17236905 | AA33: =AA32/AA11 -> 0.86687314 | AB33: =AB32/AB11 -> -0.15822521 | AC33: =AC32/AC11 -> -0.41061537 | AD33: =AD32/AD11 -> -0.43690625 | AE33: =AE32/AE11 -> -0.87047853 | ... AI33: =AI32/AI11 -> 16.670857 | AK33: =SUM(AH33-AD33)*1000 -> 10803.041
B35: Basic shares | C35: 10020 | D35: 113209 | E35: 136706 | F35: 192549 | H35: 11289 | I35: 11300 | J35: 11308 | K35: =D35 -> 113209 | L35: 11834 | M35: 13247 | N35: 142214 | O35: =E35 -> 136706 | P35: 171942 | Q35: 178607 | R35: 197273 | S35: =F35 -> 192549 | T35: 256473 | U35: 275244 | V35: 284376 | X35: =K35 -> 113209 | Y35: =L35 -> 11834 | Z35: =M35 -> 13247 | AA35: =N35 -> 142214 | AB35: =O35 -> 136706 | AC35: =P35 -> 171942 | AD35: =Q35 -> 178607 | AE35: =R35 -> 197273 | ... AI35: =V35 -> 284376 | AK35: =SUM(AH35/AD35)-1 -> 0.54105942
B36: Basic EPS | C36: =C32/C35 -> -53.441118 | D36: =D32/D35 -> -12.98304 | E36: =E32/E35 -> 3.1390063 | F36: =F32/F35 -> -6.0590343 | H36: =H32/H35 -> -11.58216 | I36: =I32/I35 -> -94.008673 | J36: =J32/J35 -> -2.3946763 | K36: =K32/K35 -> -2.2053812 | L36: =L32/L35 -> 38.971861 | M36: =M32/M35 -> 1.6790972 | N36: =N32/N35 -> -1.0086278 | O36: =O32/O35 -> 0.65195383 | ... V36: =V32/V35 -> 9.7934566 | X36: =X32/X35 -> -7.7775707 | Y36: =Y32/Y35 -> 17.60698 | Z36: =Z32/Z35 -> 6.5089454 | AA36: =AA32/AA35 -> 3.0741769 | AB36: =AB32/AB35 -> -0.57437859 | AC36: =AC32/AC35 -> -1.1691966 | AD36: =AD32/AD35 -> -1.175721 | AE36: =AE32/AE35 -> -2.0617368 | ... AI36: =AI32/AI35 -> 27.842328 | AK36: =SUM(AH36/AD36)-1 -> -15.809461
B38: Fully Diluted Shares | C38: 10020 | D38: 113209 | E38: 165662 | F38: 192549 | H38: 11289 | I38: 11300 | J38: 11308 | K38: =D38 -> 113209 | L38: 14575 | M38: 16095 | N38: 142214 | O38: =E38 -> 165662 | P38: 171942 | Q38: 178607 | R38: 197273 | S38: =F38 -> 192549 | T38: 256473 | U38: 306764 | V38: 315393 | X38: =L38 -> 14575 | Y38: =M38 -> 16095 | Z38: =N38 -> 142214 | AA38: =O38 -> 165662 | AB38: =P38 -> 171942 | AC38: =Q38 -> 178607 | AD38: =Q38 -> 178607 | AE38: =R38 -> 197273 | AF38: =S38 -> 192549 | AG38: =T38 -> 256473 | AH38: =U38 -> 306764 | AI38: =V38 -> 315393 | AK38: =SUM(AH38/AD38)-1 -> 0.71753627
B39: Diluted EPS | C39: =C32/C38 -> -53.441118 | D39: =D32/D38 -> -12.98304 | E39: =E32/E38 -> 2.5903406 | F39: =F32/F38 -> -6.0590343 | H39: =H32/H38 -> -11.58216 | I39: =I32/I38 -> -94.008673 | J39: =J32/J38 -> -2.3946763 | K39: =K32/K38 -> -2.2053812 | L39: =L32/L38 -> 31.642744 | M39: =M32/M38 -> 1.381982 | N39: =N32/N38 -> -1.0086278 | O39: =O32/O38 -> 0.53799906 | ... V39: =V32/V38 -> 8.8303291 | X39: =X32/X38 -> -60.411046 | Y39: =Y32/Y38 -> 12.945697 | Z39: =Z32/Z38 -> 0.60629755 | AA39: =AA32/AA38 -> 2.6390542 | AB39: =AB32/AB38 -> -0.45667144 | AC39: =AC32/AC38 -> -1.1255662 | AD39: =AD32/AD38 -> -1.175721 | AE39: =AE32/AE38 -> -2.0617368 | ... AI39: =AI32/AI38 -> 25.104203 | AK39: =SUM(AH39/AD39)-1 -> -14.287789
A41: X | B41: Balance Sheet | D41: FYE | H41: Quarterly | R41: Quarterly | AD41: LTM | AK41: Variance
B42: =B7 -> Fiscal Period | C42: =C7 -> 2021 | D42: =D7 -> 2022 | E42: =E7 -> 2023 | F42: =F7 -> 2024 | H42: =H7 -> 1Q22 | I42: =I7 -> 2Q22 | J42: =J7 -> 3Q22 | K42: =K7 -> 4Q22 | L42: =L7 -> 1Q23 | M42: =M7 -> 2Q23 | N42: =N7 -> 3Q23 | O42: =O7 -> 4Q23 | ... V42: =V7 -> 3Q25 | X42: =X7 -> 4Q22 | Y42: =Y7 -> 1Q23 | Z42: =Z7 -> 2Q23 | AA42: =AA7 -> 3Q23 | AB42: =AB7 -> 4Q23 | AC42: =AC7 -> 1Q24 | AD42: =AD7 -> 2Q24 | AE42: =AE7 -> 3Q24 | ... AI42: =AI7 -> 3Q25
B43: =B8 -> Fiscal Period End Date | C43: =C8 -> 44561 | D43: =D8 -> 44926 | E43: =E8 -> 45291 | F43: =F8 -> 45657 | H43: =H8 -> 44651 | I43: =I8 -> 44742 | J43: =J8 -> 44834 | K43: =K8 -> 44926 | L43: =L8 -> 45016 | M43: =M8 -> 45107 | N43: =N8 -> 45199 | O43: =O8 -> 45291 | ... V43: =V8 -> 45930 | X43: =X8 -> 44926 | Y43: =Y8 -> 45016 | Z43: =Z8 -> 45107 | AA43: =AA8 -> 45199 | AB43: =AB8 -> 45291 | AC43: =AC8 -> 45382 | AD43: =AD8 -> 45473 | AE43: =AE8 -> 45565 | ... AI43: =AI8 -> 45930
B45: Current Assets
B46: Cash and cash equivalents | C46: 63356 | D46: 43835 | E46: 46817 | F46: 38117 | H46: 92677 | I46: 69386 | J46: 60390 | K46: =D46 -> 43835 | L46: 94311 | M46: 65968 | N46: 45009 | O46: =E46 -> 46817 | P46: 81326 | Q46: 66923 | R46: 46343 | S46: =F46 -> 38117 | T46: 60298 | U46: 50095 | V46: 54285 | X46: =K46 -> 43835 | Y46: =L46 -> 94311 | Z46: =M46 -> 65968 | AA46: =N46 -> 45009 | AB46: =O46 -> 46817 | AC46: =P46 -> 81326 | AD46: =Q46 -> 66923 | AE46: =R46 -> 46343 | ... AI46: =V46 -> 54285 | AK46: =SUM(AH46/AD46)-1 -> -0.25145316
B47: Restricted cash | C47: 1078 | D47: 7033 | E47: 1856 | F47: 1780 | H47: 6265 | I47: 6155 | J47: 6578 | K47: =D47 -> 7033 | L47: 2153 | M47: 2085 | N47: 1865 | O47: =E47 -> 1856 | P47: 2402 | Q47: 1878 | R47: 1862 | S47: =F47 -> 1780 | T47: 1960 | U47: 2037 | V47: 1915 | X47: =K47 -> 7033 | Y47: =L47 -> 2153 | Z47: =M47 -> 2085 | AA47: =N47 -> 1865 | AB47: =O47 -> 1856 | AC47: =P47 -> 2402 | AD47: =Q47 -> 1878 | AE47: =R47 -> 1862 | ... AI47: =V47 -> 1915 | AK47: =SUM(AH47/AD47)-1 -> 0.084664537
B48: Accounts receivable, net | C48: 189280 | D48: 189280 | E48: 183815 | F48: 181203 | H48: 126930 | I48: 118645 | J48: 109926 | K48: =D48 -> 189280 | L48: 139178 | M48: 121901 | N48: 128650 | O48: =E48 -> 183815 | P48: 115150 | Q48: 112234 | R48: 107169 | S48: =F48 -> 181203 | T48: 104585 | U48: 117870 | V48: 113406 | X48: =K48 -> 189280 | Y48: =L48 -> 139178 | Z48: =M48 -> 121901 | AA48: =N48 -> 128650 | AB48: =O48 -> 183815 | AC48: =P48 -> 115150 | AD48: =Q48 -> 112234 | AE48: =R48 -> 107169 | ... AI48: =V48 -> 113406 | AK48: =SUM(AH48/AD48)-1 -> 0.050216512
B49: Prepaid expenses and other current assets | C49: 14251 | D49: 24418 | E49: 35407 | F49: 31224 | H49: 21116 | I49: 25496 | J49: 25399 | K49: =D49 -> 24418 | L49: 24034 | M49: 19680 | N49: 24041 | O49: =E49 -> 35407 | P49: 42714 | Q49: 27234 | R49: 30668 | S49: =F49 -> 31224 | T49: 36769 | U49: 43459 | V49: 44345 | X49: =K49 -> 24418 | Y49: =L49 -> 24034 | Z49: =M49 -> 19680 | AA49: =N49 -> 24041 | AB49: =O49 -> 35407 | AC49: =P49 -> 42714 | AD49: =Q49 -> 27234 | AE49: =R49 -> 30668 | ... AI49: =V49 -> 44345 | AK49: =SUM(AH49/AD49)-1 -> 0.59576265
B50: Total Current Assets | C50: =SUM(C46:C49) -> 267965 | D50: =SUM(D46:D49) -> 264566 | E50: =SUM(E46:E49) -> 267895 | F50: =SUM(F46:F49) -> 252324 | H50: =SUM(H46:H49) -> 246988 | I50: =SUM(I46:I49) -> 219682 | J50: =SUM(J46:J49) -> 202293 | K50: =SUM(K46:K49) -> 264566 | L50: =SUM(L46:L49) -> 259676 | M50: =SUM(M46:M49) -> 209634 | N50: =SUM(N46:N49) -> 199565 | O50: =SUM(O46:O49) -> 267895 | ... V50: =SUM(V46:V49) -> 213951 | X50: =SUM(X46:X49) -> 264566 | Y50: =SUM(Y46:Y49) -> 259676 | Z50: =SUM(Z46:Z49) -> 209634 | AA50: =SUM(AA46:AA49) -> 199565 | AB50: =SUM(AB46:AB49) -> 267895 | AC50: =SUM(AC46:AC49) -> 241592 | AD50: =SUM(AD46:AD49) -> 208269 | AE50: =SUM(AE46:AE49) -> 186042 | ... AI50: =SUM(AI46:AI49) -> 213951 | AK50: =SUM(AH50/AD50)-1 -> 0.024929298
B52: Non-Current Assets
...

Sheet Revenue Drivers
B2: ='Historical Financials'!B2 -> Microstrategy, Inc. (NASDAQ: MSTR) | D2: FYE | H2: Quarterly | R2: Quarterly | AC2: LTM
B3: Segment Anaysis | C3: ='Historical Financials'!C7 -> 2021 | D3: ='Historical Financials'!D7 -> 2022 | E3: ='Historical Financials'!E7 -> 2023 | F3: ='Historical Financials'!F7 -> 2024 | H3: ='Historical Financials'!H7 -> 1Q22 | I3: ='Historical Financials'!I7 -> 2Q22 | J3: ='Historical Financials'!J7 -> 3Q22 | K3: ='Historical Financials'!K7 -> 4Q22 | L3: ='Historical Financials'!L7 -> 1Q23 | M3: ='Historical Financials'!M7 -> 2Q23 | N3: ='Historical Financials'!N7 -> 3Q23 | O3: ='Historical Financials'!O7 -> 4Q23 | ... V3: ='Historical Financials'!V7 -> 3Q25 | X3: =M3 -> 2Q23 | Y3: =N3 -> 3Q23 | Z3: =O3 -> 4Q23 | AA3: =P3 -> 1Q24 | AB3: =Q3 -> 2Q24 | AC3: =R3 -> 3Q24 | AD3: =S3 -> 4Q24 | AE3: =T3 -> 1Q25 | ... AG3: =V3 -> 3Q25
B4: ($ In Thousands) | C4: ='Historical Financials'!C8 -> 44561 | D4: ='Historical Financials'!D8 -> 44926 | E4: ='Historical Financials'!E8 -> 45291 | F4: ='Historical Financials'!F8 -> 45657 | H4: ='Historical Financials'!H8 -> 44651 | I4: ='Historical Financials'!I8 -> 44742 | J4: ='Historical Financials'!J8 -> 44834 | K4: ='Historical Financials'!K8 -> 44926 | L4: ='Historical Financials'!L8 -> 45016 | M4: ='Historical Financials'!M8 -> 45107 | N4: ='Historical Financials'!N8 -> 45199 | O4: ='Historical Financials'!O8 -> 45291 | ... V4: ='Historical Financials'!V8 -> 45930 | X4: =M4 -> 45107 | Y4: =N4 -> 45199 | Z4: =O4 -> 45291 | AA4: =P4 -> 45382 | AB4: =Q4 -> 45473 | AC4: =R4 -> 45565 | AD4: =S4 -> 45657 | AE4: =T4 -> 45747 | ... AG4: =V4 -> 45930
A6: X | B6: Offerings Drivers
A8: X | B8: Revenue Segment Anaysis
B9: Product Licenses and Subscription Services | C9: 144873 | D9: 147244 | E9: 156530 | F9: 155343 | H9: 29358 | I9: 34146 | J9: 38700 | K9: =SUM(D9-SUM(H9:J9)) -> 45040 | L9: 36222 | M9: 35400 | N9: 45019 | O9: =SUM(E9-SUM(L9:N9)) -> 39889 | P9: 35904 | Q9: 33366 | R9: 38887 | S9: =SUM(F9-SUM(P9:R9)) -> 47186 | T9: 44373 | U9: 48001 | V9: 63345 | X9: =SUM(J9:M9) -> 155362 | Y9: =SUM(K9:N9) -> 161681 | Z9: =SUM(L9:O9) -> 156530 | AA9: =SUM(M9:P9) -> 156212 | AB9: =SUM(N9:Q9) -> 154178 | AC9: =SUM(O9:R9) -> 148046 | AD9: =SUM(P9:S9) -> 155343 | AE9: =SUM(Q9:T9) -> 163812 | ... AG9: =SUM(S9:V9) -> 202905
B10: Product support | C10: 281209 | D10: 266521 | E10: 263888 | F10: 243805 | H10: 67151 | I10: 66521 | J10: 66010 | K10: =SUM(D10-SUM(H10:J10)) -> 66839 | L10: 65481 | M10: 66081 | N10: 66860 | O10: =SUM(E10-SUM(L10:N10)) -> 65466 | P10: 62685 | Q10: 61740 | R10: 61015 | S10: =SUM(F10-SUM(P10:R10)) -> 58365 | T10: 52529 | U10: 52081 | V10: 51118 | X10: =SUM(J10:M10) -> 264411 | Y10: =SUM(K10:N10) -> 265261 | Z10: =SUM(L10:O10) -> 263888 | AA10: =SUM(M10:P10) -> 261092 | AB10: =SUM(N10:Q10) -> 256751 | AC10: =SUM(O10:R10) -> 250906 | AD10: =SUM(P10:S10) -> 243805 | AE10: =SUM(Q10:T10) -> 233649 | ... AG10: =SUM(S10:V10) -> 214093
B11: Other services | C11: 84680 | D11: 85499 | E11: 75843 | F11: 64308 | H11: 22768 | I11: 21406 | J11: 20650 | K11: =SUM(D11-SUM(H11:J11)) -> 20675 | L11: 20212 | M11: 18919 | N11: 17583 | O11: =SUM(E11-SUM(L11:N11)) -> 19129 | P11: 16657 | Q11: 16336 | R11: 16169 | S11: =SUM(F11-SUM(P11:R11)) -> 15146 | T11: 14164 | U11: 14406 | V11: 14228 | X11: =SUM(J11:M11) -> 80456 | Y11: =SUM(K11:N11) -> 77389 | Z11: =SUM(L11:O11) -> 75843 | AA11: =SUM(M11:P11) -> 72288 | AB11: =SUM(N11:Q11) -> 69705 | AC11: =SUM(O11:R11) -> 68291 | AD11: =SUM(P11:S11) -> 64308 | AE11: =SUM(Q11:T11) -> 61815 | ... AG11: =SUM(S11:V11) -> 57944
B12: Total Net Revenue | C12: =SUM(C9:C11) -> 510762 | D12: =SUM(D9:D11) -> 499264 | E12: =SUM(E9:E11) -> 496261 | F12: =SUM(F9:F11) -> 463456 | H12: =SUM(H9:H11) -> 119277 | I12: =SUM(I9:I11) -> 122073 | J12: =SUM(J9:J11) -> 125360 | K12: =SUM(K9:K11) -> 132554 | L12: =SUM(L9:L11) -> 121915 | M12: =SUM(M9:M11) -> 120400 | N12: =SUM(N9:N11) -> 129462 | O12: =SUM(O9:O11) -> 124484 | ... V12: =SUM(V9:V11) -> 128691 | X12: =SUM(X9:X11) -> 500229 | Y12: =SUM(Y9:Y11) -> 504331 | Z12: =SUM(Z9:Z11) -> 496261 | AA12: =SUM(AA9:AA11) -> 489592 | AB12: =SUM(AB9:AB11) -> 480634 | AC12: =SUM(AC9:AC11) -> 467243 | AD12: =SUM(AD9:AD11) -> 463456 | AE12: =SUM(AE9:AE11) -> 459276 | ... AG12: =SUM(AG9:AG11) -> 474942
B13: Balance Check | C13: =C12-'Historical Financials'!C11 -> 0 | D13: =D12-'Historical Financials'!D11 -> 0 | E13: =E12-'Historical Financials'!E11 -> 0 | F13: =F12-'Historical Financials'!F11 -> 0 | H13: =H12-'Historical Financials'!H11 -> 0 | I13: =I12-'Historical Financials'!I11 -> 0 | J13: =J12-'Historical Financials'!J11 -> 0 | K13: =K12-'Historical Financials'!K11 -> 0 | L13: =L12-'Historical Financials'!L11 -> 0 | M13: =M12-'Historical Financials'!M11 -> 0 | N13: =N12-'Historical Financials'!N11 -> 0 | O13: =O12-'Historical Financials'!O11 -> 0 | ... V13: =V12-'Historical Financials'!V11 -> 0 | X13: =X12-'Historical Financials'!Z11 -> 0 | Y13: =Y12-'Historical Financials'!AA11 -> 0 | Z13: =Z12-'Historical Financials'!AB11 -> 0 | AA13: =AA12-'Historical Financials'!AC11 -> 0 | AB13: =AB12-'Historical Financials'!AD11 -> 0 | AC13: =AC12-'Historical Financials'!AE11 -> 0 | AD13: =AD12-'Historical Financials'!AF11 -> 0 | AE13: =AE12-'Historical Financials'!AG11 -> 0 | ... AG13: =AG12-'Historical Financials'!AI11 -> 0
B15: =B9&"(%)" -> Product Licenses and Subscription Services(%) | C15: =C9/C$12 -> 0.28364091 | D15: =D9/D$12 -> 0.29492213 | E15: =E9/E$12 -> 0.3154187 | F15: =F9/F$12 -> 0.33518392 | H15: =H9/H$12 -> 0.24613295 | I15: =I9/I$12 -> 0.27971787 | J15: =J9/J$12 -> 0.30871091 | K15: =K9/K$12 -> 0.33978605 | L15: =L9/L$12 -> 0.29710864 | M15: =M9/M$12 -> 0.29401993 | N15: =N9/N$12 -> 0.3477391 | O15: =O9/O$12 -> 0.32043475 | ... V15: =V9/V$12 -> 0.49222556 | X15: =M15 -> 0.29401993 | Y15: =N15 -> 0.3477391 | Z15: =O15 -> 0.32043475 | AA15: =P15 -> 0.31154227 | AB15: =Q15 -> 0.29940238 | AC15: =R15 -> 0.3350277 | AD15: =S15 -> 0.39094592 | AE15: =T15 -> 0.3995192 | ... AG15: =V15 -> 0.49222556
B16: =B10&"(%)" -> Product support(%) | C16: =C10/C$12 -> 0.55056758 | D16: =D10/D$12 -> 0.53382779 | E16: =E10/E$12 -> 0.53175244 | F16: =F10/F$12 -> 0.52605857 | H16: =H10/H$12 -> 0.56298364 | I16: =I10/I$12 -> 0.54492803 | J16: =J10/J$12 -> 0.5265635 | K16: =K10/K$12 -> 0.50423978 | L16: =L10/L$12 -> 0.53710372 | M16: =M10/M$12 -> 0.54884551 | N16: =N10/N$12 -> 0.51644498 | O16: =O10/O$12 -> 0.52589891 | ... V16: =V10/V$12 -> 0.39721503 | X16: =M16 -> 0.54884551 | Y16: =N16 -> 0.51644498 | Z16: =O16 -> 0.52589891 | AA16: =P16 -> 0.54392343 | AB16: =Q16 -> 0.55401016 | AC16: =R16 -> 0.52566963 | AD16: =S16 -> 0.48356629 | AE16: =T16 -> 0.47295302 | ... AG16: =V16 -> 0.39721503
B17: =B11&"(%)" -> Other services(%) | C17: =C11/C$12 -> 0.1657915 | D17: =D11/D$12 -> 0.17125008 | E17: =E11/E$12 -> 0.15282885 | F17: =F11/F$12 -> 0.13875751 | H17: =H11/H$12 -> 0.19088341 | I17: =I11/I$12 -> 0.17535409 | J17: =J11/J$12 -> 0.16472559 | K17: =K11/K$12 -> 0.15597417 | L17: =L11/L$12 -> 0.16578764 | M17: =M11/M$12 -> 0.15713455 | N17: =N11/N$12 -> 0.13581592 | O17: =O11/O$12 -> 0.15366633 | ... V17: =V11/V$12 -> 0.1105594 | X17: =M17 -> 0.15713455 | Y17: =N17 -> 0.13581592 | Z17: =O17 -> 0.15366633 | AA17: =P17 -> 0.1445343 | AB17: =Q17 -> 0.14658746 | AC17: =R17 -> 0.13930267 | AD17: =S17 -> 0.12548779 | AE17: =T17 -> 0.12752778 | ... AG17: =V17 -> 0.1105594
A19: X | B19: Product Licenses and Subscription Services
B20: Product licenses | C20: 101804 | D20: 86498 | E20: 75351 | F20: 48567 | H20: 16513 | I20: 20129 | J20: 22286 | K20: =SUM(D20-SUM(H20:J20)) -> 27570 | L20: 17412 | M20: 15522 | N20: 24045 | O20: =SUM(E20-SUM(L20:N20)) -> 18372 | P20: 12938 | Q20: 9286 | R20: 11087 | S20: =SUM(F20-SUM(P20:R20)) -> 15256 | T20: 7270 | U20: 7177 | V20: 17373 | X20: =SUM(J20:M20) -> 82790 | Y20: =SUM(K20:N20) -> 84549 | Z20: =SUM(L20:O20) -> 75351 | AA20: =SUM(M20:P20) -> 70877 | AB20: =SUM(N20:Q20) -> 64641 | AC20: =SUM(O20:R20) -> 51683 | AD20: =SUM(P20:S20) -> 48567 | AE20: =SUM(Q20:T20) -> 42899 | ... AG20: =SUM(S20:V20) -> 47076
B21: Subscription services | C21: 43069 | D21: 60746 | E21: 81179 | F21: 106776 | H21: 12845 | I21: 14017 | J21: 16414 | K21: =SUM(D21-SUM(H21:J21)) -> 17470 | L21: 18810 | M21: 19878 | N21: 20974 | O21: =SUM(E21-SUM(L21:N21)) -> 21517 | P21: 22966 | Q21: 24080 | R21: 27800 | S21: =SUM(F21-SUM(P21:R21)) -> 31930 | T21: 37103 | U21: 40824 | V21: 45972 | X21: =SUM(J21:M21) -> 72572 | Y21: =SUM(K21:N21) -> 77132 | Z21: =SUM(L21:O21) -> 81179 | AA21: =SUM(M21:P21) -> 85335 | AB21: =SUM(N21:Q21) -> 89537 | AC21: =SUM(O21:R21) -> 96363 | AD21: =SUM(P21:S21) -> 106776 | AE21: =SUM(Q21:T21) -> 120913 | ... AG21: =SUM(S21:V21) -> 155829
B22: Total Net Revenue | C22: =SUM(C20:C21) -> 144873 | D22: =SUM(D20:D21) -> 147244 | E22: =SUM(E20:E21) -> 156530 | F22: =SUM(F20:F21) -> 155343 | H22: =SUM(H20:H21) -> 29358 | I22: =SUM(I20:I21) -> 34146 | J22: =SUM(J20:J21) -> 38700 | K22: =SUM(K20:K21) -> 45040 | L22: =SUM(L20:L21) -> 36222 | M22: =SUM(M20:M21) -> 35400 | N22: =SUM(N20:N21) -> 45019 | O22: =SUM(O20:O21) -> 39889 | ... V22: =SUM(V20:V21) -> 63345 | X22: =SUM(X20:X21) -> 155362 | Y22: =SUM(Y20:Y21) -> 161681 | Z22: =SUM(Z20:Z21) -> 156530 | AA22: =SUM(AA20:AA21) -> 156212 | AB22: =SUM(AB20:AB21) -> 154178 | AC22: =SUM(AC20:AC21) -> 148046 | AD22: =SUM(AD20:AD21) -> 155343 | AE22: =SUM(AE20:AE21) -> 163812 | ... AG22: =SUM(AG20:AG21) -> 202905
B23: Balance Check | C23: =+C22-C9 -> 0 | D23: =+D22-D9 -> 0 | E23: =+E22-E9 -> 0 | F23: =+F22-F9 -> 0 | H23: =+H22-H9 -> 0 | I23: =+I22-I9 -> 0 | J23: =+J22-J9 -> 0 | K23: =+K22-K9 -> 0 | L23: =+L22-L9 -> 0 | M23: =+M22-M9 -> 0 | N23: =+N22-N9 -> 0 | O23: =+O22-O9 -> 0 | ... V23: =+V22-V9 -> 0 | X23: =+X22-X9 -> 0 | Y23: =+Y22-Y9 -> 0 | Z23: =+Z22-Z9 -> 0 | AA23: =+AA22-AA9 -> 0 | AB23: =+AB22-AB9 -> 0 | AC23: =+AC22-AC9 -> 0 | AD23: =+AD22-AD9 -> 0 | AE23: =+AE22-AE9 -> 0 | ... AG23: =+AG22-AG9 -> 0
B25: =B20&"(%)" -> Product licenses(%) | C25: =C20/C$22 -> 0.70271203 | D25: =D20/D$22 -> 0.58744669 | E25: =E20/E$22 -> 0.48138376 | F25: =F20/F$22 -> 0.31264363 | H25: =H20/H$22 -> 0.5624702 | I25: =I20/I$22 -> 0.58949804 | J25: =J20/J$22 -> 0.57586563 | K25: =K20/K$22 -> 0.61212256 | L25: =L20/L$22 -> 0.48070234 | M25: =M20/M$22 -> 0.43847458 | N25: =N20/N$22 -> 0.53410782 | O25: =O20/O$22 -> 0.4605781 | ... V25: =V20/V$22 -> 0.27426 | X25: =M25 -> 0.43847458 | Y25: =N25 -> 0.53410782 | Z25: =O25 -> 0.4605781 | AA25: =P25 -> 0.36034982 | AB25: =Q25 -> 0.27830726 | AC25: =R25 -> 0.28510813 | AD25: =S25 -> 0.32331624 | AE25: =T25 -> 0.16383837 | ... AG25: =V25 -> 0.27426
B26: =B21&"(%)" -> Subscription services(%) | C26: =C21/C$22 -> 0.29728797 | D26: =D21/D$22 -> 0.41255331 | E26: =E21/E$22 -> 0.51861624 | F26: =F21/F$22 -> 0.68735637 | H26: =H21/H$22 -> 0.4375298 | I26: =I21/I$22 -> 0.41050196 | J26: =J21/J$22 -> 0.42413437 | K26: =K21/K$22 -> 0.38787744 | L26: =L21/L$22 -> 0.51929766 | M26: =M21/M$22 -> 0.56152542 | N26: =N21/N$22 -> 0.46589218 | O26: =O21/O$22 -> 0.5394219 | ... V26: =V21/V$22 -> 0.72574 | X26: =M26 -> 0.56152542 | Y26: =N26 -> 0.46589218 | Z26: =O26 -> 0.5394219 | AA26: =P26 -> 0.63965018 | AB26: =Q26 -> 0.72169274 | AC26: =R26 -> 0.71489187 | AD26: =S26 -> 0.67668376 | AE26: =T26 -> 0.83616163 | ... AG26: =V26 -> 0.72574

Sheet FCF
B2: ='Historical Financials'!B2 -> Microstrategy, Inc. (NASDAQ: MSTR) | D2: FYE | H2: Quarterly | L2: Quarterly | R2: Quarterly | X2: LTM | AE2: LTM | AK2: Variance
B3: FCF Analysis | C3: ='Historical Financials'!C7 -> 2021 | D3: ='Historical Financials'!D7 -> 2022 | E3: ='Historical Financials'!E7 -> 2023 | F3: ='Historical Financials'!F7 -> 2024 | H3: ='Historical Financials'!H7 -> 1Q22 | I3: ='Historical Financials'!I7 -> 2Q22 | J3: ='Historical Financials'!J7 -> 3Q22 | K3: ='Historical Financials'!K7 -> 4Q22 | L3: ='Historical Financials'!L7 -> 1Q23 | M3: ='Historical Financials'!M7 -> 2Q23 | N3: ='Historical Financials'!N7 -> 3Q23 | O3: ='Historical Financials'!O7 -> 4Q23 | ... V3: ='Historical Financials'!V7 -> 3Q25 | X3: =K3 -> 4Q22 | Y3: =L3 -> 1Q23 | Z3: =M3 -> 2Q23 | AA3: =N3 -> 3Q23 | AB3: =O3 -> 4Q23 | AC3: =P3 -> 1Q24 | AD3: =Q3 -> 2Q24 | AE3: =R3 -> 3Q24 | ... AI3: =V3 -> 3Q25
B4: ($ In Millions) | C4: ='Historical Financials'!C8 -> 44561 | D4: ='Historical Financials'!D8 -> 44926 | E4: ='Historical Financials'!E8 -> 45291 | F4: ='Historical Financials'!F8 -> 45657 | H4: ='Historical Financials'!H8 -> 44651 | I4: ='Historical Financials'!I8 -> 44742 | J4: ='Historical Financials'!J8 -> 44834 | K4: ='Historical Financials'!K8 -> 44926 | L4: ='Historical Financials'!L8 -> 45016 | M4: ='Historical Financials'!M8 -> 45107 | N4: ='Historical Financials'!N8 -> 45199 | O4: ='Historical Financials'!O8 -> 45291 | ... V4: ='Historical Financials'!V8 -> 45930 | X4: =K4 -> 44926 | Y4: =L4 -> 45016 | Z4: =M4 -> 45107 | AA4: =N4 -> 45199 | AB4: =O4 -> 45291 | AC4: =P4 -> 45382 | AD4: =Q4 -> 45473 | AE4: =R4 -> 45565 | ... AI4: =V4 -> 45930
B6: ='Revenue Drivers'!B9 -> Product Licenses and Subscription Services | C6: ='Revenue Drivers'!C9 -> 144873 | D6: ='Revenue Drivers'!D9 -> 147244 | E6: ='Revenue Drivers'!E9 -> 156530 | F6: ='Revenue Drivers'!F9 -> 155343 | H6: ='Revenue Drivers'!H9 -> 29358 | I6: ='Revenue Drivers'!I9 -> 34146 | J6: ='Revenue Drivers'!J9 -> 38700 | K6: ='Revenue Drivers'!K9 -> 45040 | L6: ='Revenue Drivers'!L9 -> 36222 | M6: ='Revenue Drivers'!M9 -> 35400 | N6: ='Revenue Drivers'!N9 -> 45019 | O6: ='Revenue Drivers'!O9 -> 39889 | ... V6: ='Revenue Drivers'!V9 -> 63345 | X6: =SUM(H6:K6) -> 147244 | Y6: =SUM(I6:L6) -> 154108 | Z6: =SUM(J6:M6) -> 155362 | AA6: =SUM(K6:N6) -> 161681 | AB6: =SUM(L6:O6) -> 156530 | AC6: =SUM(M6:P6) -> 156212 | AD6: =SUM(N6:Q6) -> 154178 | AE6: =SUM(O6:R6) -> 148046 | ... AI6: =SUM(S6:V6) -> 202905 | AK6: =SUM(AI6/AE6)-1 -> 0.37055375
B7: Product support | C7: ='Revenue Drivers'!C10 -> 281209 | D7: ='Revenue Drivers'!D10 -> 266521 | E7: ='Revenue Drivers'!E10 -> 263888 | F7: ='Revenue Drivers'!F10 -> 243805 | H7: ='Revenue Drivers'!H10 -> 67151 | I7: ='Revenue Drivers'!I10 -> 66521 | J7: ='Revenue Drivers'!J10 -> 66010 | K7: ='Revenue Drivers'!K10 -> 66839 | L7: ='Revenue Drivers'!L10 -> 65481 | M7: ='Revenue Drivers'!M10 -> 66081 | N7: ='Revenue Drivers'!N10 -> 66860 | O7: ='Revenue Drivers'!O10 -> 65466 | ... V7: ='Revenue Drivers'!V10 -> 51118 | X7: =SUM(H7:K7) -> 266521 | Y7: =SUM(I7:L7) -> 264851 | Z7: =SUM(J7:M7) -> 264411 | AA7: =SUM(K7:N7) -> 265261 | AB7: =SUM(L7:O7) -> 263888 | AC7: =SUM(M7:P7) -> 261092 | AD7: =SUM(N7:Q7) -> 256751 | AE7: =SUM(O7:R7) -> 250906 | ... AI7: =SUM(S7:V7) -> 214093 | AK7: =SUM(AI7/AE7)-1 -> -0.14672029
B8: Other services | C8: ='Revenue Drivers'!C11 -> 84680 | D8: ='Revenue Drivers'!D11 -> 85499 | E8: ='Revenue Drivers'!E11 -> 75843 | F8: ='Revenue Drivers'!F11 -> 64308 | H8: ='Revenue Drivers'!H11 -> 22768 | I8: ='Revenue Drivers'!I11 -> 21406 | J8: ='Revenue Drivers'!J11 -> 20650 | K8: ='Revenue Drivers'!K11 -> 20675 | L8: ='Revenue Drivers'!L11 -> 20212 | M8: ='Revenue Drivers'!M11 -> 18919 | N8: ='Revenue Drivers'!N11 -> 17583 | O8: ='Revenue Drivers'!O11 -> 19129 | ... V8: ='Revenue Drivers'!V11 -> 14228 | X8: =SUM(H8:K8) -> 85499 | Y8: =SUM(I8:L8) -> 82943 | Z8: =SUM(J8:M8) -> 80456 | AA8: =SUM(K8:N8) -> 77389 | AB8: =SUM(L8:O8) -> 75843 | AC8: =SUM(M8:P8) -> 72288 | AD8: =SUM(N8:Q8) -> 69705 | AE8: =SUM(O8:R8) -> 68291 | ... AI8: =SUM(S8:V8) -> 57944 | AK8: =SUM(AI8/AE8)-1 -> -0.15151338
B9: Total Revenue | C9: =SUM(C6:C8) -> 510762 | D9: =SUM(D6:D8) -> 499264 | E9: =SUM(E6:E8) -> 496261 | F9: =SUM(F6:F8) -> 463456 | H9: =SUM(H6:H8) -> 119277 | I9: =SUM(I6:I8) -> 122073 | J9: =SUM(J6:J8) -> 125360 | K9: =SUM(K6:K8) -> 132554 | L9: =SUM(L6:L8) -> 121915 | M9: =SUM(M6:M8) -> 120400 | N9: =SUM(N6:N8) -> 129462 | O9: =SUM(O6:O8) -> 124484 | ... V9: =SUM(V6:V8) -> 128691 | X9: =SUM(X6:X8) -> 499264 | Y9: =SUM(Y6:Y8) -> 501902 | Z9: =SUM(Z6:Z8) -> 500229 | AA9: =SUM(AA6:AA8) -> 504331 | AB9: =SUM(AB6:AB8) -> 496261 | AC9: =SUM(AC6:AC8) -> 489592 | AD9: =SUM(AD6:AD8) -> 480634 | AE9: =SUM(AE6:AE8) -> 467243 | ... AI9: =SUM(AI6:AI8) -> 474942 | AK9: =SUM(AI9/AE9)-1 -> 0.016477507
B10: Y/Y Growth (%) | D10: =SUM(D9/C9)-1 -> -0.022511463 | E10: =SUM(E9/D9)-1 -> -0.0060148539 | F10: =SUM(F9/E9)-1 -> -0.066104328 | L10: =SUM(L9/H9)-1 -> 0.022116586 | M10: =SUM(M9/I9)-1 -> -0.013704914 | N10: =SUM(N9/J9)-1 -> 0.032721761 | O10: =SUM(O9/K9)-1 -> -0.060880849 | P10: =SUM(P9/L9)-1 -> -0.054702047 | Q10: =SUM(Q9/M9)-1 -> -0.074401993 | R10: =SUM(R9/N9)-1 -> -0.10343576 | S10: =SUM(S9/O9)-1 -> -0.03042158 | ... V10: =SUM(V9/R9)-1 -> 0.10872656 | X10: =SUM(X9/U9)-1 -> 3.3608413 | Y10: =SUM(Y9/V9)-1 -> 2.9000552 | Z10: =SUM(Z9/W9)-1 -> #DIV/0! | AA10: =SUM(AA9/#REF!)-1 -> #REF! | AB10: =SUM(AB9/X9)-1 -> -0.0060148539 | AC10: =SUM(AC9/Y9)-1 -> -0.0245267 | AD10: =SUM(AD9/Z9)-1 -> -0.039172059 | AE10: =SUM(AE9/AA9)-1 -> -0.073539005 | AF10: =SUM(AF9/AB9)-1 -> -0.066104328 | AG10: =SUM(AG9/AC9)-1 -> -0.061920946 | AH10: =SUM(AH9/AD9)-1 -> -0.038099677 | AI10: =SUM(AI9/AE9)-1 -> 0.016477507 | AK10: =SUM(AI10-AE10)*10000 -> 900.16513
B11: Q/Q Growth (%) | C11: N/A | D11: N/A | E11: N/A | F11: N/A | I11: =SUM(I9/H9)-1 -> 0.023441233 | J11: =SUM(J9/I9)-1 -> 0.026926511 | K11: =SUM(K9/J9)-1 -> 0.057386726 | L11: =SUM(L9/K9)-1 -> -0.080261629 | M11: =SUM(M9/L9)-1 -> -0.012426691 | N11: =SUM(N9/M9)-1 -> 0.075265781 | O11: =SUM(O9/N9)-1 -> -0.038451437 | P11: =SUM(P9/O9)-1 -> -0.07421034 | ... V11: =SUM(V9/U9)-1 -> 0.12405667 | X11: N/A | Y11: N/A | Z11: N/A | AA11: N/A | AB11: N/A | AC11: N/A | AD11: N/A | AE11: N/A | AF11: N/A | AG11: N/A | AH11: N/A | AI11: N/A
B13: (-) Cost of Revenues | C13: ='Historical Financials'!C13 -> -91909 | D13: ='Historical Financials'!D13 -> -102989 | E13: ='Historical Financials'!E13 -> -109944 | F13: ='Historical Financials'!F13 -> -129468 | H13: ='Historical Financials'!H13 -> -25677 | I13: ='Historical Financials'!I13 -> -25204 | J13: ='Historical Financials'!J13 -> -25385 | K13: ='Historical Financials'!K13 -> -26723 | L13: ='Historical Financials'!L13 -> -27941 | M13: ='Historical Financials'!M13 -> -27121 | N13: ='Historical Financials'!N13 -> -26661 | O13: ='Historical Financials'!O13 -> -28221 | ... V13: ='Historical Financials'!V13 -> -38013 | X13: =SUM(H13:K13) -> -102989 | Y13: =SUM(I13:L13) -> -105253 | Z13: =SUM(J13:M13) -> -107170 | AA13: =SUM(K13:N13) -> -108446 | AB13: =SUM(L13:O13) -> -109944 | AC13: =SUM(M13:P13) -> -112018 | AD13: =SUM(N13:Q13) -> -115832 | AE13: =SUM(O13:R13) -> -123520 | ... AI13: =SUM(S13:V13) -> -141903 | AK13: =SUM(AI13/AE13)-1 -> 0.1488261
B14: Gross Profit | C14: =SUM(C9+SUM(C13:C13)) -> 418853 | D14: =SUM(D9+SUM(D13:D13)) -> 396275 | E14: =SUM(E9+SUM(E13:E13)) -> 386317 | F14: =SUM(F9+SUM(F13:F13)) -> 333988 | H14: =SUM(H9+SUM(H13:H13)) -> 93600 | I14: =SUM(I9+SUM(I13:I13)) -> 96869 | J14: =SUM(J9+SUM(J13:J13)) -> 99975 | K14: =SUM(K9+SUM(K13:K13)) -> 105831 | L14: =SUM(L9+SUM(L13:L13)) -> 93974 | M14: =SUM(M9+SUM(M13:M13)) -> 93279 | N14: =SUM(N9+SUM(N13:N13)) -> 102801 | O14: =SUM(O9+SUM(O13:O13)) -> 96263 | ... V14: =SUM(V9+SUM(V13:V13)) -> 90678 | X14: =SUM(X9+SUM(X13:X13)) -> 396275 | Y14: =SUM(Y9+SUM(Y13:Y13)) -> 396649 | Z14: =SUM(Z9+SUM(Z13:Z13)) -> 393059 | AA14: =SUM(AA9+SUM(AA13:AA13)) -> 395885 | AB14: =SUM(AB9+SUM(AB13:AB13)) -> 386317 | AC14: =SUM(AC9+SUM(AC13:AC13)) -> 377574 | AD14: =SUM(AD9+SUM(AD13:AD13)) -> 364802 | AE14: =SUM(AE9+SUM(AE13:AE13)) -> 343723 | ... AI14: =SUM(AI9+SUM(AI13:AI13)) -> 333039 | AK14: =SUM(AI14/AE14)-1 -> -0.031083169
B15: Gross Margin (%) | C15: =C14/C9 -> 0.82005513 | D15: =D14/D9 -> 0.79371835 | E15: =E14/E9 -> 0.77845529 | F15: =F14/F9 -> 0.72064662 | H15: =H14/H9 -> 0.78472799 | I15: =I14/I9 -> 0.79353338 | J15: =J14/J9 -> 0.79750319 | K15: =K14/K9 -> 0.79839914 | L15: =L14/L9 -> 0.77081573 | M15: =M14/M9 -> 0.77474252 | N15: =N14/N9 -> 0.79406312 | O15: =O14/O9 -> 0.77329617 | ... V15: =V14/V9 -> 0.70461804 | X15: =X14/X9 -> 0.79371835 | Y15: =Y14/Y9 -> 0.79029173 | Z15: =Z14/Z9 -> 0.78575812 | AA15: =AA14/AA9 -> 0.78497058 | AB15: =AB14/AB9 -> 0.77845529 | AC15: =AC14/AC9 -> 0.77120133 | AD15: =AD14/AD9 -> 0.75900165 | AE15: =AE14/AE9 -> 0.73564077 | ... AI15: =AI14/AI9 -> 0.70122036 | AK15: =SUM(AI15-AE15)*10000 -> -344.2041
B17: (-) Sales and marketing | C17: ='Historical Financials'!C17 -> -160141 | D17: ='Historical Financials'!D17 -> -146882 | E17: ='Historical Financials'!E17 -> -149671 | F17: ='Historical Financials'!F17 -> -138081 | H17: ='Historical Financials'!H17 -> -33240 | I17: ='Historical Financials'!I17 -> -36862 | J17: ='Historical Financials'!J17 -> -35409 | K17: ='Historical Financials'!K17 -> -41371 | L17: ='Historical Financials'!L17 -> -36106 | M17: ='Historical Financials'!M17 -> -37660 | N17: ='Historical Financials'!N17 -> -35606 | O17: ='Historical Financials'!O17 -> -40299 | ... V17: ='Historical Financials'!V17 -> -29908 | X17: =SUM(H17:K17) -> -146882 | Y17: =SUM(I17:L17) -> -149748 | Z17: =SUM(J17:M17) -> -150546 | AA17: =SUM(K17:N17) -> -150743 | AB17: =SUM(L17:O17) -> -149671 | AC17: =SUM(M17:P17) -> -147016 | AD17: =SUM(N17:Q17) -> -143607 | AE17: =SUM(O17:R17) -> -143415 | ... AI17: =SUM(S17:V17) -> -126096 | AK17: =SUM(AI17/AE17)-1 -> -0.12076143
B18: (-) Research and development | C18: ='Historical Financials'!C18 -> -117117 | D18: ='Historical Financials'!D18 -> -127428 | E18: ='Historical Financials'!E18 -> -120530 | F18: ='Historical Financials'!F18 -> -118486 | H18: ='Historical Financials'!H18 -> -33523 | I18: ='Historical Financials'!I18 -> -31790 | J18: ='Historical Financials'!J18 -> -30498 | K18: ='Historical Financials'!K18 -> -31617 | L18: ='Historical Financials'!L18 -> -31358 | M18: ='Historical Financials'!M18 -> -29354 | N18: ='Historical Financials'!N18 -> -29660 | O18: ='Historical Financials'!O18 -> -30158 | ... V18: ='Historical Financials'!V18 -> -22602 | X18: =SUM(H18:K18) -> -127428 | Y18: =SUM(I18:L18) -> -125263 | Z18: =SUM(J18:M18) -> -122827 | AA18: =SUM(K18:N18) -> -121989 | AB18: =SUM(L18:O18) -> -120530 | AC18: =SUM(M18:P18) -> -118355 | AD18: =SUM(N18:Q18) -> -119312 | AE18: =SUM(O18:R18) -> -122953 | ... AI18: =SUM(S18:V18) -> -96787 | AK18: =SUM(AI18/AE18)-1 -> -0.21281303
B19: (-) General and administrative | C19: ='Historical Financials'!C19 -> -95501 | D19: ='Historical Financials'!D19 -> -111421 | E19: ='Historical Financials'!E19 -> -115312 | F19: ='Historical Financials'!F19 -> -140537 | H19: ='Historical Financials'!H19 -> -26706 | I19: ='Historical Financials'!I19 -> -28502 | J19: ='Historical Financials'!J19 -> -27283 | K19: ='Historical Financials'!K19 -> -28930 | L19: ='Historical Financials'!L19 -> -27906 | M19: ='Historical Financials'!M19 -> -28830 | N19: ='Historical Financials'!N19 -> -29223 | O19: ='Historical Financials'!O19 -> -29353 | ... V19: ='Historical Financials'!V19 -> -38173 | X19: =SUM(H19:K19) -> -111421 | Y19: =SUM(I19:L19) -> -112621 | Z19: =SUM(J19:M19) -> -112949 | AA19: =SUM(K19:N19) -> -114889 | AB19: =SUM(L19:O19) -> -115312 | AC19: =SUM(M19:P19) -> -122072 | AD19: =SUM(N19:Q19) -> -129371 | AE19: =SUM(O19:R19) -> -133653 | ... AI19: =SUM(S19:V19) -> -151457 | AK19: =SUM(AI19/AE19)-1 -> 0.13321063
B20: (-) Unrealized gain on digital assets | C20: ='Historical Financials'!C20 -> 0 | D20: ='Historical Financials'!D20 -> 0 | E20: ='Historical Financials'!E20 -> 0 | F20: ='Historical Financials'!F20 -> 0 | H20: ='Historical Financials'!H20 -> 0 | I20: ='Historical Financials'!I20 -> 0 | J20: ='Historical Financials'!J20 -> 0 | K20: ='Historical Financials'!K20 -> 0 | L20: ='Historical Financials'!L20 -> 0 | M20: ='Historical Financials'!M20 -> 0 | N20: ='Historical Financials'!N20 -> 0 | O20: ='Historical Financials'!O20 -> 0 | ... V20: ='Historical Financials'!V20 -> 3890847 | X20: =SUM(H20:K20) -> 0 | Y20: =SUM(I20:L20) -> 0 | Z20: =SUM(J20:M20) -> 0 | AA20: =SUM(K20:N20) -> 0 | AB20: =SUM(L20:O20) -> 0 | AC20: =SUM(M20:P20) -> 0 | AD20: =SUM(N20:Q20) -> 0 | AE20: =SUM(O20:R20) -> 0 | ... AI20: =SUM(S20:V20) -> 12032356 | AK20: =SUM(AI20/AE20)-1 -> #DIV/0!
B21: (-) Digital asset impairment gains (losses on sale), net | C21: ='Historical Financials'!C21 -> -830621 | D21: ='Historical Financials'!D21 -> -1286286 | E21: ='Historical Financials'!E21 -> -115851 | F21: ='Historical Financials'!F21 -> -1789862 | H21: ='Historical Financials'!H21 -> -170091 | I21: ='Historical Financials'!I21 -> -917838 | J21: ='Historical Financials'!J21 -> -727 | K21: ='Historical Financials'!K21 -> -197630 | L21: ='Historical Financials'!L21 -> -18911 | M21: ='Historical Financials'!M21 -> -24143 | N21: ='Historical Financials'!N21 -> -33559 | O21: ='Historical Financials'!O21 -> -39238 | ... V21: ='Historical Financials'!V21 -> 0 | X21: =SUM(H21:K21) -> -1286286 | Y21: =SUM(I21:L21) -> -1135106 | Z21: =SUM(J21:M21) -> -241411 | AA21: =SUM(K21:N21) -> -274243 | AB21: =SUM(L21:O21) -> -115851 | AC21: =SUM(M21:P21) -> -288573 | AD21: =SUM(N21:Q21) -> -444520 | AE21: =SUM(O21:R21) -> -823045 | ... AI21: =SUM(S21:V21) -> -1006055 | AK21: =SUM(AI21/AE21)-1 -> 0.22235722
B22: Earning before Interest & Taxes (EBIT) | C22: =SUM(C14+SUM(C17:C21)) -> -784527 | D22: =SUM(D14+SUM(D17:D21)) -> -1275742 | E22: =SUM(E14+SUM(E17:E21)) -> -115047 | F22: =SUM(F14+SUM(F17:F21)) -> -1852978 | H22: =SUM(H14+SUM(H17:H21)) -> -169960 | I22: =SUM(I14+SUM(I17:I21)) -> -918123 | J22: =SUM(J14+SUM(J17:J21)) -> 6058 | K22: =SUM(K14+SUM(K17:K21)) -> -193717 | L22: =SUM(L14+SUM(L17:L21)) -> -20307 | M22: =SUM(M14+SUM(M17:M21)) -> -26708 | N22: =SUM(N14+SUM(N17:N21)) -> -25247 | O22: =SUM(O14+SUM(O17:O21)) -> -42785 | ... V22: =SUM(V14+SUM(V17:V21)) -> 3890842 | X22: =SUM(X14+SUM(X17:X21)) -> -1275742 | Y22: =SUM(Y14+SUM(Y17:Y21)) -> -1126089 | Z22: =SUM(Z14+SUM(Z17:Z21)) -> -234674 | AA22: =SUM(AA14+SUM(AA17:AA21)) -> -265979 | AB22: =SUM(AB14+SUM(AB17:AB21)) -> -115047 | AC22: =SUM(AC14+SUM(AC17:AC21)) -> -298442 | AD22: =SUM(AD14+SUM(AD17:AD21)) -> -472008 | AE22: =SUM(AE14+SUM(AE17:AE21)) -> -879343 | ... AI22: =SUM(AI14+SUM(AI17:AI21)) -> 10985000 | AK22: =SUM(AI22/AE22)-1 -> -13.492281
B23: Operating Margin (%) | C23: =C22/C9 -> -1.5359933 | D23: =D22/D9 -> -2.5552453 | E23: =E22/E9 -> -0.23182761 | F23: =F22/F9 -> -3.9981746 | H23: =H22/H9 -> -1.4249185 | I23: =I22/I9 -> -7.521098 | J23: =J22/J9 -> 0.048324825 | K23: =K22/K9 -> -1.4614195 | L23: =L22/L9 -> -0.16656687 | M23: =M22/M9 -> -0.22182724 | N23: =N22/N9 -> -0.19501475 | O23: =O22/O9 -> -0.34369879 | ... V23: =V22/V9 -> 30.233987 | X23: =X22/X9 -> -2.5552453 | Y23: =Y22/Y9 -> -2.2436432 | Z23: =Z22/Z9 -> -0.46913314 | AA23: =AA22/AA9 -> -0.52738975 | AB23: =AB22/AB9 -> -0.23182761 | AC23: =AC22/AC9 -> -0.60957287 | AD23: =AD22/AD9 -> -0.98205287 | AE23: =AE22/AE9 -> -1.8819822 | ... AI23: =AI22/AI9 -> 23.12914 | AK23: =SUM(AI23-AE23)*10000 -> 250111.22
B25: (+) Depreciation and Amortization | C25: ='Historical Financials'!C97 -> 11358 | D25: ='Historical Financials'!D97 -> 10874 | E25: ='Historical Financials'!E97 -> 14527 | F25: ='Historical Financials'!F97 -> 17808 | H25: ='Historical Financials'!H97 -> 2691 | I25: ='Historical Financials'!I97 -> 2076 | J25: ='Historical Financials'!J97 -> 2150 | K25: ='Historical Financials'!K97 -> 3957 | L25: ='Historical Financials'!L97 -> 3431 | M25: ='Historical Financials'!M97 -> 3230 | N25: ='Historical Financials'!N97 -> 2744 | O25: ='Historical Financials'!O97 -> 5122 | ... V25: ='Historical Financials'!V97 -> 4195 | X25: =SUM(H25:K25) -> 10874 | Y25: =SUM(I25:L25) -> 11614 | Z25: =SUM(J25:M25) -> 12768 | AA25: =SUM(K25:N25) -> 13362 | AB25: =SUM(L25:O25) -> 14527 | AC25: =SUM(M25:P25) -> 14146 | AD25: =SUM(N25:Q25) -> 14567 | AE25: =SUM(O25:R25) -> 17801 | ... AI25: =SUM(S25:V25) -> 25017 | AK25: =SUM(AI25/AE25)-1 -> 0.40537048
B26: EBITDA | C26: =SUM(C22+SUM(C25:C25)) -> -773169 | D26: =SUM(D22+SUM(D25:D25)) -> -1264868 | E26: =SUM(E22+SUM(E25:E25)) -> -100520 | F26: =SUM(F22+SUM(F25:F25)) -> -1835170 | H26: =SUM(H22+SUM(H25:H25)) -> -167269 | I26: =SUM(I22+SUM(I25:I25)) -> -916047 | J26: =SUM(J22+SUM(J25:J25)) -> 8208 | K26: =SUM(K22+SUM(K25:K25)) -> -189760 | L26: =SUM(L22+SUM(L25:L25)) -> -16876 | M26: =SUM(M22+SUM(M25:M25)) -> -23478 | N26: =SUM(N22+SUM(N25:N25)) -> -22503 | O26: =SUM(O22+SUM(O25:O25)) -> -37663 | ... V26: =SUM(V22+SUM(V25:V25)) -> 3895037 | X26: =SUM(X22+SUM(X25:X25)) -> -1264868 | Y26: =SUM(Y22+SUM(Y25:Y25)) -> -1114475 | Z26: =SUM(Z22+SUM(Z25:Z25)) -> -221906 | AA26: =SUM(AA22+SUM(AA25:AA25)) -> -252617 | AB26: =SUM(AB22+SUM(AB25:AB25)) -> -100520 | AC26: =SUM(AC22+SUM(AC25:AC25)) -> -284296 | AD26: =SUM(AD22+SUM(AD25:AD25)) -> -457441 | AE26: =SUM(AE22+SUM(AE25:AE25)) -> -861542 | ... AI26: =SUM(AI22+SUM(AI25:AI25)) -> 11010017 | AK26: =SUM(AI26/AE26)-1 -> -13.779432
B27: EBITDA Margin (%) | C27: =C26/C9 -> -1.5137559 | D27: =D26/D9 -> -2.5334653 | E27: =E26/E9 -> -0.2025547 | F27: =F26/F9 -> -3.9597502 | H27: =H26/H9 -> -1.4023575 | I27: =I26/I9 -> -7.5040918 | J27: =J26/J9 -> 0.065475431 | K27: =K26/K9 -> -1.4315675 | L27: =L26/L9 -> -0.13842431 | M27: =M26/M9 -> -0.195 | N27: =N26/N9 -> -0.17381934 | O27: =O26/O9 -> -0.30255294 | ... V27: =V26/V9 -> 30.266584 | X27: =X26/X9 -> -2.5334653 | Y27: =Y26/Y9 -> -2.2205032 | Z27: =Z26/Z9 -> -0.44360883 | AA27: =AA26/AA9 -> -0.50089525 | AB27: =AB26/AB9 -> -0.2025547 | AC27: =AC26/AC9 -> -0.58067942 | AD27: =AD26/AD9 -> -0.95174499 | AE27: =AE26/AE9 -> -1.8438842 | ... AI27: =AI26/AI9 -> 23.181814 | AK27: =SUM(AI27-AE27)*10000 -> 250256.98
B29: (+) Share-Based Compensation (SBC) | C29: ='Historical Financials'!C100 -> 44126 | D29: ='Historical Financials'!D100 -> 63619 | E29: ='Historical Financials'!E100 -> 69571 | F29: ='Historical Financials'!F100 -> 77124 | H29: ='Historical Financials'!H100 -> 14394 | I29: ='Historical Financials'!I100 -> 15294 | J29: ='Historical Financials'!J100 -> 16899 | K29: ='Historical Financials'!K100 -> 17032 | L29: ='Historical Financials'!L100 -> 17555 | M29: ='Historical Financials'!M100 -> 15494 | N29: ='Historical Financials'!N100 -> 16806 | O29: ='Historical Financials'!O100 -> 19716 | ... V29: ='Historical Financials'!V100 -> 15483 | X29: =SUM(H29:K29) -> 63619 | Y29: =SUM(I29:L29) -> 66780 | Z29: =SUM(J29:M29) -> 66980 | AA29: =SUM(K29:N29) -> 66887 | AB29: =SUM(L29:O29) -> 69571 | AC29: =SUM(M29:P29) -> 69807 | AD29: =SUM(N29:Q29) -> 74934 | AE29: =SUM(O29:R29) -> 77505 | ... AI29: =SUM(S29:V29) -> 62379 | AK29: =SUM(AI29/AE29)-1 -> -0.1951616
B30: Adj. EBITDA | C30: =SUM(C26+SUM(C29:C29)) -> -729043 | D30: =SUM(D26+SUM(D29:D29)) -> -1201249 | E30: =SUM(E26+SUM(E29:E29)) -> -30949 | F30: =SUM(F26+SUM(F29:F29)) -> -1758046 | H30: =SUM(H26+SUM(H29:H29)) -> -152875 | I30: =SUM(I26+SUM(I29:I29)) -> -900753 | J30: =SUM(J26+SUM(J29:J29)) -> 25107 | K30: =SUM(K26+SUM(K29:K29)) -> -172728 | L30: =SUM(L26+SUM(L29:L29)) -> 679 | M30: =SUM(M26+SUM(M29:M29)) -> -7984 | N30: =SUM(N26+SUM(N29:N29)) -> -5697 | O30: =SUM(O26+SUM(O29:O29)) -> -17947 | ... V30: =SUM(V26+SUM(V29:V29)) -> 3910520 | X30: =SUM(X26+SUM(X29:X29)) -> -1201249 | Y30: =SUM(Y26+SUM(Y29:Y29)) -> -1047695 | Z30: =SUM(Z26+SUM(Z29:Z29)) -> -154926 | AA30: =SUM(AA26+SUM(AA29:AA29)) -> -185730 | AB30: =SUM(AB26+SUM(AB29:AB29)) -> -30949 | AC30: =SUM(AC26+SUM(AC29:AC29)) -> -214489 | AD30: =SUM(AD26+SUM(AD29:AD29)) -> -382507 | AE30: =SUM(AE26+SUM(AE29:AE29)) -> -784037 | ... AI30: =SUM(AI26+SUM(AI29:AI29)) -> 11072396 | AK30: =SUM(AI30/AE30)-1 -> -15.122288
B31: Adj. EBITDA Margin (%) | C31: =C30/C9 -> -1.4273634 | D31: =D30/D9 -> -2.4060397 | E31: =E30/E9 -> -0.062364361 | F31: =F30/F9 -> -3.7933396 | H31: =H30/H9 -> -1.2816805 | I31: =I30/I9 -> -7.3788061 | J31: =J30/J9 -> 0.2002792 | K31: =K30/K9 -> -1.3030765 | L31: =L30/L9 -> 0.0055694541 | M31: =M30/M9 -> -0.066312292 | N31: =N30/N9 -> -0.044005191 | O31: =O30/O9 -> -0.14417114 | ... V31: =V30/V9 -> 30.386896 | X31: =X30/X9 -> -2.4060397 | Y31: =Y30/Y9 -> -2.0874493 | Z31: =Z30/Z9 -> -0.30971015 | AA31: =AA30/AA9 -> -0.36827004 | AB31: =AB30/AB9 -> -0.062364361 | AC31: =AC30/AC9 -> -0.43809744 | AD31: =AD30/AD9 -> -0.79583841 | AE31: =AE30/AE9 -> -1.6780069 | ... AI31: =AI30/AI9 -> 23.313154 | AK31: =SUM(AI31-AE31)*10000 -> 249911.61
B33: (-) Capital Expenditures | C33: =SUM('Historical Financials'!C118,'Historical Financials'!C119) -> -2629235 | D33: =SUM('Historical Financials'!D118,'Historical Financials'!D119) -> -290407 | E33: =SUM('Historical Financials'!E118,'Historical Financials'!E119) -> -1905237 | F33: =SUM('Historical Financials'!F118,'Historical Financials'!F119) -> -22075737 | H33: =SUM('Historical Financials'!H118,'Historical Financials'!H119) -> -216141 | I33: =SUM('Historical Financials'!I118,'Historical Financials'!I119) -> -10878 | J33: =SUM('Historical Financials'!J118,'Historical Financials'!J119) -> -6310 | K33: =SUM('Historical Financials'!K118,'Historical Financials'!K119) -> -57078 | L33: =SUM('Historical Financials'!L118,'Historical Financials'!L119) -> -179774 | M33: =SUM('Historical Financials'!M118,'Historical Financials'!M119) -> -347642 | N33: =SUM('Historical Financials'!N118,'Historical Financials'!N119) -> -163134 | O33: =SUM('Historical Financials'!O118,'Historical Financials'!O119) -> -1214687 | ... V33: =SUM('Historical Financials'!V118,'Historical Financials'!V119) -> -4954877 | X33: =SUM(H33:K33) -> -290407 | Y33: =SUM(I33:L33) -> -254040 | Z33: =SUM(J33:M33) -> -590804 | AA33: =SUM(K33:N33) -> -747628 | AB33: =SUM(L33:O33) -> -1905237 | AC33: =SUM(M33:P33) -> -3366317 | AD33: =SUM(N33:Q33) -> -3813226 | AE33: =SUM(O33:R33) -> -5225591 | ... AI33: =SUM(S33:V33) -> -37455409 | AK33: =SUM(AI33/AE33)-1 -> 6.1676886
B34: (-) Cash Taxes | C34: =-'Historical Financials'!C146 -> -7010 | D34: =-'Historical Financials'!D146 -> -21973 | E34: =-'Historical Financials'!E146 -> -30318 | F34: =-'Historical Financials'!F146 -> -1059 | H34: ='Historical Financials'!H31 -> 48023 | I34: ='Historical Financials'!I31 -> -136108 | J34: ='Historical Financials'!J31 -> -23961 | K34: ='Historical Financials'!K31 -> -35286 | L34: ='Historical Financials'!L31 -> 453187 | M34: ='Historical Financials'!M31 -> 60296 | N34: ='Historical Financials'!N31 -> -109607 | O34: ='Historical Financials'!O31 -> 149770 | ... V34: ='Historical Financials'!V31 -> -1086212 | X34: =SUM(H34:K34) -> -147332 | Y34: =SUM(I34:L34) -> 257832 | Z34: =SUM(J34:M34) -> 454236 | AA34: =SUM(K34:N34) -> 368590 | AB34: =SUM(L34:O34) -> 553646 | AC34: =SUM(M34:P34) -> 261228 | AD34: =SUM(N34:Q34) -> 313419 | AE34: =SUM(O34:R34) -> 561530 | ... AI34: =SUM(S34:V34) -> -2990179 | AK34: =SUM(AI34/AE34)-1 -> -6.3250565
B35: (-) Cash Interest | C35: =-'Historical Financials'!C145 -> -20416 | D35: =-'Historical Financials'!D145 -> -43448 | E35: =-'Historical Financials'!E145 -> -41229 | F35: =-'Historical Financials'!F145 -> -44571 | H35: ='Historical Financials'!H25 -> -11039 | I35: ='Historical Financials'!I25 -> -13187 | J35: ='Historical Financials'!J25 -> -14073 | K35: ='Historical Financials'!K25 -> -14837 | L35: ='Historical Financials'!L25 -> -14930 | M35: ='Historical Financials'!M25 -> -11095 | N35: ='Historical Financials'!N25 -> -11006 | O35: ='Historical Financials'!O25 -> -11929 | ... V35: ='Historical Financials'!V25 -> -18890 | X35: =SUM(H35:K35) -> -53136 | Y35: =SUM(I35:L35) -> -57027 | Z35: =SUM(J35:M35) -> -54935 | AA35: =SUM(K35:N35) -> -51868 | AB35: =SUM(L35:O35) -> -48960 | AC35: =SUM(M35:P35) -> -45911 | AD35: =SUM(N35:Q35) -> -50282 | AE35: =SUM(O35:R35) -> -57405 | ... AI35: =SUM(S35:V35) -> -70358 | AK35: =SUM(AI35/AE35)-1 -> 0.22564237
