Workbook

Sheet 3-Statement Model
B2: Microstrategy, Inc. (NASDAQ: MSTR) | C2: FYE | D2: FYE | H2: Quarterly | N2: Quarterly | Q2: Quarterly | W2: LTM | Z2: Variance
B3: 3-Statement Model | C3: 2021 | D3: 2022 | E3: 2023 | F3: 2024 | H3: 1Q22 | I3: 2Q22 | J3: 3Q22 | K3: 4Q22 | L3: 1Q23 | M3: 2Q23 | N3: 3Q23 | O3: 4Q23 | P3: 1Q24 | Q3: 2Q24 | R3: 3Q24 | S3: 4Q24 | T3: 1Q25 | U3: 2Q25 | W3: 3Q24 | X3: 3Q24
B4: ($ In Thousands) | C4: 44561 | D4: 44926 | E4: 45291 | F4: 45657 | H4: 44651 | I4: 44742 | J4: 44834 | K4: 44926 | L4: 45016 | M4: 45107 | N4: 45199 | O4: 45291 | P4: 45382 | Q4: 45473 | R4: 45565 | S4: 45657 | T4: 45747 | U4: 45838 | W4: 45565 | X4: 45565
A6: X | B6: Income Statement
B8: Product licenses | C8: 101804 | D8: 86498 | E8: 75351 | F8: 48567 | H8: 16513 | I8: 20129 | J8: 22286 | K8: =SUM(D8-SUM(H8:J8)) -> 27570 | L8: 17412 | M8: 15522 | N8: 24045 | O8: =SUM(E8-SUM(L8:N8)) -> 18372 | P8: 12938 | Q8: 9286 | R8: 11087 | S8: =SUM(F8-SUM(P8:R8)) -> 15256 | T8: 7270 | U8: 7177 | W8: =SUM(K8:N8) -> 84549 | X8: =SUM(O8:R8) -> 51683
B9: Subscription services | C9: 43069 | D9: 60746 | E9: 81179 | F9: 106776 | H9: 12845 | I9: 14017 | J9: 16414 | K9: =SUM(D9-SUM(H9:J9)) -> 17470 | L9: 18810 | M9: 19878 | N9: 20974 | O9: =SUM(E9-SUM(L9:N9)) -> 21517 | P9: 22966 | Q9: 24080 | R9: 27800 | S9: =SUM(F9-SUM(P9:R9)) -> 31930 | T9: 37103 | U9: 40824 | W9: =SUM(K9:N9) -> 77132 | X9: =SUM(O9:R9) -> 96363
B10: Total product licenses and subscription services | C10: =SUM(C8:C9) -> 144873 | D10: =SUM(D8:D9) -> 147244 | E10: =SUM(E8:E9) -> 156530 | F10: =SUM(F8:F9) -> 155343 | H10: =SUM(H8:H9) -> 29358 | I10: =SUM(I8:I9) -> 34146 | J10: =SUM(J8:J9) -> 38700 | K10: =SUM(K8:K9) -> 45040 | L10: =SUM(L8:L9) -> 36222 | M10: =SUM(M8:M9) -> 35400 | N10: =SUM(N8:N9) -> 45019 | O10: =SUM(O8:O9) -> 39889 | ... U10: =SUM(U8:U9) -> 48001 | W10: =SUM(W8:W9) -> 161681 | X10: =SUM(X8:X9) -> 148046
B11: Product support | C11: 281209 | D11: 266521 | E11: 263888 | F11: 243805 | H11: 67151 | I11: 66521 | J11: 66010 | K11: =SUM(D11-SUM(H11:J11)) -> 66839 | L11: 65481 | M11: 66081 | N11: 66860 | O11: =SUM(E11-SUM(L11:N11)) -> 65466 | P11: 62685 | Q11: 61740 | R11: 61015 | S11: =SUM(F11-SUM(P11:R11)) -> 58365 | T11: 52529 | U11: 52081 | W11: =SUM(K11:N11) -> 265261 | X11: =SUM(O11:R11) -> 250906
B12: Other services | C12: 84680 | D12: 85499 | E12: 75843 | F12: 64308 | H12: 22768 | I12: 21406 | J12: 20650 | K12: =SUM(D12-SUM(H12:J12)) -> 20675 | L12: 20212 | M12: 18919 | N12: 17583 | O12: =SUM(E12-SUM(L12:N12)) -> 19129 | P12: 16657 | Q12: 16336 | R12: 16169 | S12: =SUM(F12-SUM(P12:R12)) -> 15146 | T12: 14164 | U12: 14406 | W12: =SUM(K12:N12) -> 77389 | X12: =SUM(O12:R12) -> 68291
B13: Total Revenue | C13: =+C10+SUM(C11:C12) -> 510762 | D13: =+D10+SUM(D11:D12) -> 499264 | E13: =+E10+SUM(E11:E12) -> 496261 | F13: =+F10+SUM(F11:F12) -> 463456 | H13: =+H10+SUM(H11:H12) -> 119277 | I13: =+I10+SUM(I11:I12) -> 122073 | J13: =+J10+SUM(J11:J12) -> 125360 | K13: =+K10+SUM(K11:K12) -> 132554 | L13: =+L10+SUM(L11:L12) -> 121915 | M13: =+M10+SUM(M11:M12) -> 120400 | N13: =+N10+SUM(N11:N12) -> 129462 | O13: =+O10+SUM(O11:O12) -> 124484 | ... U13: =+U10+SUM(U11:U12) -> 114488 | W13: =+W10+SUM(W11:W12) -> 504331 | X13: =+X10+SUM(X11:X12) -> 467243
B15: Product licenses | C15: -1721 | D15: -1672 | E15: -1929 | F15: -3060 | H15: -477 | I15: -431 | J15: -406 | K15: =SUM(D15-SUM(H15:J15)) -> -358 | L15: -534 | M15: -444 | N15: -342 | O15: =SUM(E15-SUM(L15:N15)) -> -609 | P15: -567 | Q15: -794 | R15: -769 | S15: =SUM(F15-SUM(P15:R15)) -> -930 | T15: -964 | U15: -1169 | W15: =SUM(K15:N15) -> -1678 | X15: =SUM(O15:R15) -> -2739
B16: Subscription services | C16: -16901 | D16: -24770 | E16: -31776 | F16: -42440 | H16: -5410 | I16: -5498 | J16: -6395 | K16: =SUM(D16-SUM(H16:J16)) -> -7467 | L16: -7856 | M16: -7216 | N16: -8028 | O16: =SUM(E16-SUM(L16:N16)) -> -8676 | P16: -8604 | Q16: -9560 | R16: -11454 | S16: =SUM(F16-SUM(P16:R16)) -> -12822 | T16: -14429 | U16: -15906 | W16: =SUM(K16:N16) -> -30567 | X16: =SUM(O16:R16) -> -38294
B17: Total product licenses and subscription services | C17: =SUM(C15:C16) -> -18622 | D17: =SUM(D15:D16) -> -26442 | E17: =SUM(E15:E16) -> -33705 | F17: =SUM(F15:F16) -> -45500 | H17: =SUM(H15:H16) -> -5887 | I17: =SUM(I15:I16) -> -5929 | J17: =SUM(J15:J16) -> -6801 | K17: =SUM(K15:K16) -> -7825 | L17: =SUM(L15:L16) -> -8390 | M17: =SUM(M15:M16) -> -7660 | N17: =SUM(N15:N16) -> -8370 | O17: =SUM(O15:O16) -> -9285 | ... U17: =SUM(U15:U16) -> -17075 | W17: =SUM(W15:W16) -> -32245 | X17: =SUM(X15:X16) -> -41033
B18: Product support | C18: -19254 | D18: -21264 | E18: -22434 | F18: -33289 | H18: -5191 | I18: -5127 | J18: -5224 | K18: =SUM(D18-SUM(H18:J18)) -> -5722 | L18: -5768 | M18: -5816 | N18: -5531 | O18: =SUM(E18-SUM(L18:N18)) -> -5319 | P18: -8547 | Q18: -8193 | R18: -8572 | S18: =SUM(F18-SUM(P18:R18)) -> -7977 | T18: -7354 | U18: -7291 | W18: =SUM(K18:N18) -> -22837 | X18: =SUM(O18:R18) -> -30631
B19: Other services | C19: -54033 | D19: -55283 | E19: -53805 | F19: -50679 | H19: -14599 | I19: -14148 | J19: -13360 | K19: =SUM(D19-SUM(H19:J19)) -> -13176 | L19: -13783 | M19: -13645 | N19: -12760 | O19: =SUM(E19-SUM(L19:N19)) -> -13617 | P19: -12297 | Q19: -12388 | R19: -13554 | S19: =SUM(F19-SUM(P19:R19)) -> -12440 | T19: -11224 | U19: -11384 | W19: =SUM(K19:N19) -> -53364 | X19: =SUM(O19:R19) -> -51856
B20: Gross Profit | C20: =+SUM(C13+SUM(C17:C19)) -> 418853 | D20: =+SUM(D13+SUM(D17:D19)) -> 396275 | E20: =+SUM(E13+SUM(E17:E19)) -> 386317 | F20: =+SUM(F13+SUM(F17:F19)) -> 333988 | H20: =+SUM(H13+SUM(H17:H19)) -> 93600 | I20: =+SUM(I13+SUM(I17:I19)) -> 96869 | J20: =+SUM(J13+SUM(J17:J19)) -> 99975 | K20: =+SUM(K13+SUM(K17:K19)) -> 105831 | L20: =+SUM(L13+SUM(L17:L19)) -> 93974 | M20: =+SUM(M13+SUM(M17:M19)) -> 93279 | N20: =+SUM(N13+SUM(N17:N19)) -> 102801 | O20: =+SUM(O13+SUM(O17:O19)) -> 96263 | ... U20: =+SUM(U13+SUM(U17:U19)) -> 78738 | W20: =+SUM(W13+SUM(W17:W19)) -> 395885 | X20: =+SUM(X13+SUM(X17:X19)) -> 343723
B21: Gross Margin | C21: =C20/C13 -> 0.82005513 | D21: =D20/D13 -> 0.79371835 | E21: =E20/E13 -> 0.77845529 | F21: =F20/F13 -> 0.72064662 | H21: =H20/H13 -> 0.78472799 | I21: =I20/I13 -> 0.79353338 | J21: =J20/J13 -> 0.79750319 | K21: =K20/K13 -> 0.79839914 | L21: =L20/L13 -> 0.77081573 | M21: =M20/M13 -> 0.77474252 | N21: =N20/N13 -> 0.79406312 | O21: =O20/O13 -> 0.77329617 | ... U21: =U20/U13 -> 0.6877402 | W21: =W20/W13 -> 0.78497058 | X21: =X20/X13 -> 0.73564077
B23: Sales and marketing | C23: -160141 | D23: -146882 | E23: -149671 | F23: -138081 | H23: -33240 | I23: -36862 | J23: -35409 | K23: =SUM(D23-SUM(H23:J23)) -> -41371 | L23: -36106 | M23: -37660 | N23: -35606 | O23: =SUM(E23-SUM(L23:N23)) -> -40299 | P23: -33451 | Q23: -34251 | R23: -35414 | S23: =SUM(F23-SUM(P23:R23)) -> -34965 | T23: -27532 | U23: -33691 | W23: =SUM(K23:N23) -> -150743 | X23: =SUM(O23:R23) -> -143415
B24: Research and development | C24: -117117 | D24: -127428 | E24: -120530 | F24: -118486 | H24: -33523 | I24: -31790 | J24: -30498 | K24: =SUM(D24-SUM(H24:J24)) -> -31617 | L24: -31358 | M24: -29354 | N24: -29660 | O24: =SUM(E24-SUM(L24:N24)) -> -30158 | P24: -29183 | Q24: -30311 | R24: -33301 | S24: =SUM(F24-SUM(P24:R24)) -> -25691 | T24: -24423 | U24: =-24071 -> -24071 | W24: =SUM(K24:N24) -> -121989 | X24: =SUM(O24:R24) -> -122953
B25: General and administrative | C25: -95501 | D25: -111421 | E25: -115312 | F25: -140537 | H25: -26706 | I25: -28502 | J25: -27283 | K25: =SUM(D25-SUM(H25:J25)) -> -28930 | L25: -27906 | M25: -28830 | N25: -29223 | O25: =SUM(E25-SUM(L25:N25)) -> -29353 | P25: -34666 | Q25: -36129 | R25: -33505 | S25: =SUM(F25-SUM(P25:R25)) -> -36237 | T25: -40547 | U25: -36500 | W25: =SUM(K25:N25) -> -114889 | X25: =SUM(O25:R25) -> -133653
B26: Unrealized gain on digital assets | C26: 0 | D26: 0 | E26: 0 | F26: 0 | H26: 0 | I26: 0 | J26: 0 | K26: 0 | L26: 0 | M26: 0 | N26: 0 | O26: 0 | P26: 0 | Q26: 0 | R26: 0 | S26: 0 | T26: =-5906005 -> -5906005 | U26: 14047514
B27: Digital asset impairment gains (losses on sale), net | C27: -830621 | D27: -1286286 | E27: -115851 | F27: -1789862 | H27: -170091 | I27: -917838 | J27: -727 | K27: =SUM(D27-SUM(H27:J27)) -> -197630 | L27: -18911 | M27: -24143 | N27: -33559 | O27: =SUM(E27-SUM(L27:N27)) -> -39238 | P27: -191633 | Q27: -180090 | R27: -412084 | S27: =SUM(F27-SUM(P27:R27)) -> -1006055 | T27: 0 | U27: 0 | W27: =SUM(K27:N27) -> -274243 | X27: =SUM(O27:R27) -> -823045
B28: Profit From Operations | C28: =SUM(C20+SUM(C23:C27)) -> -784527 | D28: =SUM(D20+SUM(D23:D27)) -> -1275742 | E28: =SUM(E20+SUM(E23:E27)) -> -115047 | F28: =SUM(F20+SUM(F23:F27)) -> -1852978 | H28: =SUM(H20+SUM(H23:H27)) -> -169960 | I28: =SUM(I20+SUM(I23:I27)) -> -918123 | J28: =SUM(J20+SUM(J23:J27)) -> 6058 | K28: =SUM(K20+SUM(K23:K27)) -> -193717 | L28: =SUM(L20+SUM(L23:L27)) -> -20307 | M28: =SUM(M20+SUM(M23:M27)) -> -26708 | N28: =SUM(N20+SUM(N23:N27)) -> -25247 | O28: =SUM(O20+SUM(O23:O27)) -> -42785 | ... U28: =SUM(U20+SUM(U23:U27)) -> 14031990 | W28: =SUM(W20+SUM(W23:W27)) -> -265979 | X28: =SUM(X20+SUM(X23:X27)) -> -879343
B29: Operating Margin | C29: =C28/C13 -> -1.5359933 | D29: =D28/D13 -> -2.5552453 | E29: =E28/E13 -> -0.23182761 | F29: =F28/F13 -> -3.9981746 | H29: =H28/H13 -> -1.4249185 | I29: =I28/I13 -> -7.521098 | J29: =J28/J13 -> 0.048324825 | K29: =K28/K13 -> -1.4614195 | L29: =L28/L13 -> -0.16656687 | M29: =M28/M13 -> -0.22182724 | N29: =N28/N13 -> -0.19501475 | O29: =O28/O13 -> -0.34369879 | ... U29: =U28/U13 -> 122.56298 | W29: =W28/W13 -> -0.52738975 | X29: =X28/X13 -> -1.8819822
B31: Interest expense, net | C31: -29149 | D31: -53136 | E31: -48960 | F31: -61941 | H31: -11039 | I31: -13187 | J31: -14073 | K31: =SUM(D31-SUM(H31:J31)) -> -14837 | L31: -14930 | M31: -11095 | N31: -11006 | O31: =SUM(E31-SUM(L31:N31)) -> -11929 | P31: -11881 | Q31: -15466 | R31: -18129 | S31: =SUM(F31-SUM(P31:R31)) -> -16465 | T31: -17106 | U31: -17897 | W31: =SUM(K31:N31) -> -51868 | X31: =SUM(L31:O31) -> -48960
B32: Gain (Loss) on debt extinguishment | C32: 0 | D32: 0 | E32: 44686 | F32: -22933 | H32: 0 | I32: 0 | J32: 0 | K32: =SUM(D32-SUM(H32:J32)) -> 0 | L32: 44686 | M32: 0 | N32: 0 | O32: =SUM(E32-SUM(L32:N32)) -> 0 | P32: 0 | Q32: 0 | R32: -22933 | S32: =SUM(F32-SUM(P32:R32)) -> 0 | T32: 0 | U32: 0 | W32: =SUM(K32:N32) -> 44686 | X32: =SUM(L32:O32) -> 44686
B33: Other income (expense), net | C33: 2287 | D33: 6413 | E33: -5204 | F33: 3506 | H33: 2225 | I33: 5120 | J33: 4897 | K33: =SUM(D33-SUM(H33:J33)) -> -5829 | L33: -1443 | M33: -250 | N33: 2419 | O33: =SUM(E33-SUM(L33:N33)) -> -5930 | P33: 1696 | Q33: 694 | R33: -5034 | S33: =SUM(F33-SUM(P33:R33)) -> 6150 | T33: -3936 | U33: -8271 | W33: =SUM(K33:N33) -> -5103 | X33: =SUM(L33:O33) -> -5204
B34: Net loss before provision for income taxes | C34: =SUM(C31:C33)+C28 -> -811389 | D34: =SUM(D31:D33)+D28 -> -1322465 | E34: =SUM(E31:E33)+E28 -> -124525 | F34: =SUM(F31:F33)+F28 -> -1934346 | H34: =SUM(H31:H33)+H28 -> -178774 | I34: =SUM(I31:I33)+I28 -> -926190 | J34: =SUM(J31:J33)+J28 -> -3118 | K34: =SUM(K31:K33)+K28 -> -214383 | L34: =SUM(L31:L33)+L28 -> 8006 | M34: =SUM(M31:M33)+M28 -> -38053 | N34: =SUM(N31:N33)+N28 -> -33834 | O34: =SUM(O31:O33)+O28 -> -60644 | ... U34: =SUM(U31:U33)+U28 -> 14005822 | W34: =SUM(W31:W33)+W28 -> -278264 | X34: =SUM(X31:X33)+X28 -> -888821
B36: Benefit (Expense) from provision for income taxes | C36: 275909 | D36: -147332 | E36: 553646 | F36: 767685 | H36: 48023 | I36: -136108 | J36: -23961 | K36: -35286 | L36: 453187 | M36: 60296 | N36: -109607 | O36: =SUM(E36-SUM(L36:N36)) -> 149770 | P36: 160769 | Q36: 112487 | R36: 138504 | S36: =SUM(F36-SUM(P36:R36)) -> 355925 | T36: 1725084 | U36: -3984976 | W36: =SUM(K36:N36) -> 368590 | X36: =SUM(L36:O36) -> 553646
B37: Net loss | C37: =SUM(C34+C36) -> -535480 | D37: =SUM(D34+D36) -> -1469797 | E37: =SUM(E34+E36) -> 429121 | F37: =SUM(F34+F36) -> -1166661 | H37: =SUM(H34+H36) -> -130751 | I37: =SUM(I34+I36) -> -1062298 | J37: =SUM(J34+J36) -> -27079 | K37: =SUM(K34+K36) -> -249669 | L37: =SUM(L34+L36) -> 461193 | M37: =SUM(M34+M36) -> 22243 | N37: =SUM(N34+N36) -> -143441 | O37: =SUM(O34+O36) -> 89126 | ... U37: =SUM(U34+U36) -> 10020846 | W37: =SUM(W34+W36) -> 90326 | X37: =SUM(X34+X36) -> -335175
B38: Net Margin | C38: =C37/C13 -> -1.0483944 | D38: =D37/D13 -> -2.9439275 | E38: =E37/E13 -> 0.86470829 | F38: =F37/F13 -> -2.5173069 | H38: =H37/H13 -> -1.0961962 | I38: =I37/I13 -> -8.7021536 | J38: =J37/J13 -> -0.21600989 | K38: =K37/K13 -> -1.8835267 | L38: =L37/L13 -> 3.7829061 | M38: =M37/M13 -> 0.18474252 | N38: =N37/N13 -> -1.1079776 | O38: =O37/O13 -> 0.7159635 | ... U38: =U37/U13 -> 87.527479 | W38: =W37/W13 -> 0.17910063 | X38: =X37/X13 -> -0.71734622
A40: X | B40: Balance Sheet Statement
B42: Cash and cash equivalents | C42: 63356 | D42: 43835 | E42: 46817 | F42: 38117 | H42: 92677 | I42: 69386 | J42: 60390 | K42: =D42 -> 43835 | L42: 94311 | M42: 65968 | N42: 45009 | O42: =E42 -> 46817 | P42: 81326 | Q42: 66923 | R42: 46343 | S42: =F42 -> 38117 | T42: 60298 | U42: 50095 | W42: =SUM(K42:N42) -> 249123 | X42: =SUM(O42:R42) -> 241409
B43: Restricted cash | C43: 1078 | D43: 7033 | E43: 1856 | F43: 1780 | H43: 6265 | I43: 6155 | J43: 6578 | K43: =D43 -> 7033 | L43: 2153 | M43: 2085 | N43: 1865 | O43: =E43 -> 1856 | P43: 2402 | Q43: 1878 | R43: 1862 | S43: =F43 -> 1780 | T43: 1960 | U43: 2037 | W43: =SUM(K43:N43) -> 13136 | X43: =SUM(O43:R43) -> 7998
B44: Accounts receivable, net | C44: 189280 | D44: 189280 | E44: 183815 | F44: 181203 | H44: 126930 | I44: 118645 | J44: 109926 | K44: =D44 -> 189280 | L44: 139178 | M44: 121901 | N44: 128650 | O44: =E44 -> 183815 | P44: 115150 | Q44: 112234 | R44: 107169 | S44: =F44 -> 181203 | T44: 104585 | U44: 117870 | W44: =SUM(K44:N44) -> 579009 | X44: =SUM(O44:R44) -> 518368
B45: Prepaid expenses and other current assets | C45: 14251 | D45: 24418 | E45: 35407 | F45: 31224 | H45: 21116 | I45: 25496 | J45: 25399 | K45: =D45 -> 24418 | L45: 24034 | M45: 19680 | N45: 24041 | O45: =E45 -> 35407 | P45: 42714 | Q45: 27234 | R45: 30668 | S45: =F45 -> 31224 | T45: 36769 | U45: 43459 | W45: =SUM(K45:N45) -> 92173 | X45: =SUM(O45:R45) -> 136023
B46: Total Current Assets | C46: =SUM(C42:C45) -> 267965 | D46: =SUM(D42:D45) -> 264566 | E46: =SUM(E42:E45) -> 267895 | F46: =SUM(F42:F45) -> 252324 | H46: =SUM(H42:H45) -> 246988 | I46: =SUM(I42:I45) -> 219682 | J46: =SUM(J42:J45) -> 202293 | K46: =SUM(K42:K45) -> 264566 | L46: =SUM(L42:L45) -> 259676 | M46: =SUM(M42:M45) -> 209634 | N46: =SUM(N42:N45) -> 199565 | O46: =SUM(O42:O45) -> 267895 | ... U46: =SUM(U42:U45) -> 213461 | W46: =SUM(W42:W45) -> 933441 | X46: =SUM(X42:X45) -> 903798
B48: Digital assets | C48: 2850210 | D48: 1840028 | E48: 3626476 | F48: 23909373 | H48: 2895619 | I48: 1987781 | J48: 1993032 | K48: =D48 -> 1840028 | L48: 2000392 | M48: 2323252 | N48: 2451374 | O48: =E48 -> 3626476 | P48: 5074152 | Q48: 5687890 | R48: 6850879 | S48: =F48 -> 23909373 | T48: 43546079 | U48: 64362798 | W48: =SUM(K48:N48) -> 8615046 | X48: =SUM(O48:R48) -> 21239397
B49: Property and equipment, net | C49: 36587 | D49: 32311 | E49: 28941 | F49: 26327 | H49: 35680 | I49: 34580 | J49: 33033 | K49: =D49 -> 32311 | L49: 31338 | M49: 30507 | N49: 30192 | O49: =E49 -> 28941 | P49: 29108 | Q49: 28332 | R49: 27517 | S49: =F49 -> 26327 | T49: 28335 | U49: 30203 | W49: =SUM(K49:N49) -> 124348 | X49: =SUM(O49:R49) -> 113898
B50: Right-of-use assets | C50: 66760 | D50: 61299 | E50: 57343 | F50: 54560 | H50: 64637 | I50: 65169 | J50: 62902 | K50: =D50 -> 61299 | L50: 59655 | M50: 58264 | N50: 54542 | O50: =E50 -> 57343 | P50: 55093 | Q50: 53591 | R50: 55308 | S50: =F50 -> 54560 | T50: 53070 | U50: 51573 | W50: =SUM(K50:N50) -> 233760 | X50: =SUM(O50:R50) -> 221335
...

Sheet FCF Analysis
B2: Microstrategy, Inc. (NASDAQ: MSTR) | C2: FYE | D2: FYE | H2: Quarterly | P2: Quarterly | Q2: Quarterly | W2: LTM | AA2: LTM | AI2: Variance
B3: FCF Analysis | C3: 2021 | D3: 2022 | E3: 2023 | F3: 2024 | H3: 1Q22 | I3: 2Q22 | J3: 3Q22 | K3: 4Q22 | L3: 1Q23 | M3: 2Q23 | N3: 3Q23 | O3: 4Q23 | P3: 1Q24 | Q3: 2Q24 | R3: 3Q24 | S3: 4Q24 | T3: 1Q25 | U3: 2Q25 | W3: =K3 -> 4Q22 | X3: =L3 -> 1Q23 | Y3: =M3 -> 2Q23 | Z3: =N3 -> 3Q23 | AA3: =O3 -> 4Q23 | AB3: =P3 -> 1Q24 | AC3: =Q3 -> 2Q24 | AD3: =R3 -> 3Q24 | ... AG3: =U3 -> 2Q25
B4: ($ In Thousands) | C4: 44561 | D4: 44926 | E4: 45291 | F4: 45657 | H4: 44651 | I4: 44742 | J4: 44834 | K4: 44926 | L4: 45016 | M4: 45107 | N4: 45199 | O4: 45291 | P4: 45382 | Q4: 45473 | R4: 45565 | S4: 45657 | T4: 45747 | U4: 45838 | W4: =K4 -> 44926 | X4: =L4 -> 45016 | Y4: =M4 -> 45107 | Z4: =N4 -> 45199 | AA4: =O4 -> 45291 | AB4: =P4 -> 45382 | AC4: =Q4 -> 45473 | AD4: =R4 -> 45565 | ... AG4: =U4 -> 45838
B6: Product licenses | C6: ='3-Statement Model'!C8 -> 101804 | D6: ='3-Statement Model'!D8 -> 86498 | E6: ='3-Statement Model'!E8 -> 75351 | F6: ='3-Statement Model'!F8 -> 48567 | H6: ='3-Statement Model'!H8 -> 16513 | I6: ='3-Statement Model'!I8 -> 20129 | J6: ='3-Statement Model'!J8 -> 22286 | K6: ='3-Statement Model'!K8 -> 27570 | L6: ='3-Statement Model'!L8 -> 17412 | M6: ='3-Statement Model'!M8 -> 15522 | N6: ='3-Statement Model'!N8 -> 24045 | O6: ='3-Statement Model'!O8 -> 18372 | ... U6: ='3-Statement Model'!U8 -> 7177 | W6: =SUM(H6:K6) -> 86498 | X6: =SUM(I6:L6) -> 87397 | Y6: =SUM(J6:M6) -> 82790 | Z6: =SUM(K6:N6) -> 84549 | AA6: =SUM(L6:O6) -> 75351 | AB6: =SUM(M6:P6) -> 70877 | AC6: =SUM(N6:Q6) -> 64641 | AD6: =SUM(O6:R6) -> 51683 | ... AG6: =SUM(R6:U6) -> 40790 | AI6: =SUM(AG6/AC6)-1 -> -0.36897635
B7: Subscription services | C7: ='3-Statement Model'!C9 -> 43069 | D7: ='3-Statement Model'!D9 -> 60746 | E7: ='3-Statement Model'!E9 -> 81179 | F7: ='3-Statement Model'!F9 -> 106776 | H7: ='3-Statement Model'!H9 -> 12845 | I7: ='3-Statement Model'!I9 -> 14017 | J7: ='3-Statement Model'!J9 -> 16414 | K7: ='3-Statement Model'!K9 -> 17470 | L7: ='3-Statement Model'!L9 -> 18810 | M7: ='3-Statement Model'!M9 -> 19878 | N7: ='3-Statement Model'!N9 -> 20974 | O7: ='3-Statement Model'!O9 -> 21517 | ... U7: ='3-Statement Model'!U9 -> 40824 | W7: =SUM(H7:K7) -> 60746 | X7: =SUM(I7:L7) -> 66711 | Y7: =SUM(J7:M7) -> 72572 | Z7: =SUM(K7:N7) -> 77132 | AA7: =SUM(L7:O7) -> 81179 | AB7: =SUM(M7:P7) -> 85335 | AC7: =SUM(N7:Q7) -> 89537 | AD7: =SUM(O7:R7) -> 96363 | ... AG7: =SUM(R7:U7) -> 137657 | AI7: =SUM(AG7/AC7)-1 -> 0.53743145
B8: Product support | C8: ='3-Statement Model'!C11 -> 281209 | D8: ='3-Statement Model'!D11 -> 266521 | E8: ='3-Statement Model'!E11 -> 263888 | F8: ='3-Statement Model'!F11 -> 243805 | H8: ='3-Statement Model'!H11 -> 67151 | I8: ='3-Statement Model'!I11 -> 66521 | J8: ='3-Statement Model'!J11 -> 66010 | K8: ='3-Statement Model'!K11 -> 66839 | L8: ='3-Statement Model'!L11 -> 65481 | M8: ='3-Statement Model'!M11 -> 66081 | N8: ='3-Statement Model'!N11 -> 66860 | O8: ='3-Statement Model'!O11 -> 65466 | ... U8: ='3-Statement Model'!U11 -> 52081 | W8: =SUM(H8:K8) -> 266521 | X8: =SUM(I8:L8) -> 264851 | Y8: =SUM(J8:M8) -> 264411 | Z8: =SUM(K8:N8) -> 265261 | AA8: =SUM(L8:O8) -> 263888 | AB8: =SUM(M8:P8) -> 261092 | AC8: =SUM(N8:Q8) -> 256751 | AD8: =SUM(O8:R8) -> 250906 | ... AG8: =SUM(R8:U8) -> 223990 | AI8: =SUM(AG8/AC8)-1 -> -0.12759833
B9: Other services | C9: ='3-Statement Model'!C12 -> 84680 | D9: ='3-Statement Model'!D12 -> 85499 | E9: ='3-Statement Model'!E12 -> 75843 | F9: ='3-Statement Model'!F12 -> 64308 | H9: ='3-Statement Model'!H12 -> 22768 | I9: ='3-Statement Model'!I12 -> 21406 | J9: ='3-Statement Model'!J12 -> 20650 | K9: ='3-Statement Model'!K12 -> 20675 | L9: ='3-Statement Model'!L12 -> 20212 | M9: ='3-Statement Model'!M12 -> 18919 | N9: ='3-Statement Model'!N12 -> 17583 | O9: ='3-Statement Model'!O12 -> 19129 | ... U9: ='3-Statement Model'!U12 -> 14406 | W9: =SUM(H9:K9) -> 85499 | X9: =SUM(I9:L9) -> 82943 | Y9: =SUM(J9:M9) -> 80456 | Z9: =SUM(K9:N9) -> 77389 | AA9: =SUM(L9:O9) -> 75843 | AB9: =SUM(M9:P9) -> 72288 | AC9: =SUM(N9:Q9) -> 69705 | AD9: =SUM(O9:R9) -> 68291 | ... AG9: =SUM(R9:U9) -> 59885 | AI9: =SUM(AG9/AC9)-1 -> -0.14087942
B10: Total Revenue | C10: =SUM(C6:C9) -> 510762 | D10: =SUM(D6:D9) -> 499264 | E10: =SUM(E6:E9) -> 496261 | F10: =SUM(F6:F9) -> 463456 | H10: =SUM(H6:H9) -> 119277 | I10: =SUM(I6:I9) -> 122073 | J10: =SUM(J6:J9) -> 125360 | K10: =SUM(K6:K9) -> 132554 | L10: =SUM(L6:L9) -> 121915 | M10: =SUM(M6:M9) -> 120400 | N10: =SUM(N6:N9) -> 129462 | O10: =SUM(O6:O9) -> 124484 | ... U10: =SUM(U6:U9) -> 114488 | W10: =SUM(W6:W9) -> 499264 | X10: =SUM(X6:X9) -> 501902 | Y10: =SUM(Y6:Y9) -> 500229 | Z10: =SUM(Z6:Z9) -> 504331 | AA10: =SUM(AA6:AA9) -> 496261 | AB10: =SUM(AB6:AB9) -> 489592 | AC10: =SUM(AC6:AC9) -> 480634 | AD10: =SUM(AD6:AD9) -> 467243 | ... AG10: =SUM(AG6:AG9) -> 462322 | AI10: =SUM(AG10/AC10)-1 -> -0.038099677
B11: Y/Y Growth (%) | D11: =SUM(D10/C10)-1 -> -0.022511463 | E11: =SUM(E10/D10)-1 -> -0.0060148539 | F11: =SUM(F10/E10)-1 -> -0.066104328 | L11: =SUM(L10/H10)-1 -> 0.022116586 | M11: =SUM(M10/I10)-1 -> -0.013704914 | N11: =SUM(N10/J10)-1 -> 0.032721761 | O11: =SUM(O10/K10)-1 -> -0.060880849 | P11: =SUM(P10/L10)-1 -> -0.054702047 | Q11: =SUM(Q10/M10)-1 -> -0.074401993 | R11: =SUM(R10/N10)-1 -> -0.10343576 | S11: =SUM(S10/O10)-1 -> -0.03042158 | ... U11: =SUM(U10/Q10)-1 -> 0.027332604 | AA11: =SUM(AA10/W10)-1 -> -0.0060148539 | AB11: =SUM(AB10/X10)-1 -> -0.0245267 | AC11: =SUM(AC10/Y10)-1 -> -0.039172059 | AD11: =SUM(AD10/Z10)-1 -> -0.073539005 | AE11: =SUM(AE10/AA10)-1 -> -0.066104328 | AF11: =SUM(AF10/AB10)-1 -> -0.061920946 | AG11: =SUM(AG10/AC10)-1 -> -0.038099677 | AI11: =SUM(AG11-AC11)*10000 -> 10.723825
B12: Q/Q Growth (%) | C12: N/A | D12: N/A | E12: N/A | F12: N/A | I12: =SUM(I10/H10)-1 -> 0.023441233 | J12: =SUM(J10/I10)-1 -> 0.026926511 | K12: =SUM(K10/J10)-1 -> 0.057386726 | L12: =SUM(L10/K10)-1 -> -0.080261629 | M12: =SUM(M10/L10)-1 -> -0.012426691 | N12: =SUM(N10/M10)-1 -> 0.075265781 | O12: =SUM(O10/N10)-1 -> -0.038451437 | P12: =SUM(P10/O10)-1 -> -0.07421034 | ... U12: =SUM(U10/T10)-1 -> 0.030810509 | W12: N/A | X12: N/A | Y12: N/A | Z12: N/A | AA12: N/A | AB12: N/A | AC12: N/A | AD12: N/A | AE12: N/A | AF12: N/A | AG12: N/A
B14: (-) Product licenses | C14: ='3-Statement Model'!C15 -> -1721 | D14: ='3-Statement Model'!D15 -> -1672 | E14: ='3-Statement Model'!E15 -> -1929 | F14: ='3-Statement Model'!F15 -> -3060 | H14: ='3-Statement Model'!H15 -> -477 | I14: ='3-Statement Model'!I15 -> -431 | J14: ='3-Statement Model'!J15 -> -406 | K14: ='3-Statement Model'!K15 -> -358 | L14: ='3-Statement Model'!L15 -> -534 | M14: ='3-Statement Model'!M15 -> -444 | N14: ='3-Statement Model'!N15 -> -342 | O14: ='3-Statement Model'!O15 -> -609 | ... U14: ='3-Statement Model'!U15 -> -1169 | W14: =SUM(H14:K14) -> -1672 | X14: =SUM(I14:L14) -> -1729 | Y14: =SUM(J14:M14) -> -1742 | Z14: =SUM(K14:N14) -> -1678 | AA14: =SUM(L14:O14) -> -1929 | AB14: =SUM(M14:P14) -> -1962 | AC14: =SUM(N14:Q14) -> -2312 | AD14: =SUM(O14:R14) -> -2739 | ... AG14: =SUM(R14:U14) -> -3832 | AI14: =SUM(AG14/AC14)-1 -> 0.65743945
B15: (-) Subscription services | C15: ='3-Statement Model'!C16 -> -16901 | D15: ='3-Statement Model'!D16 -> -24770 | E15: ='3-Statement Model'!E16 -> -31776 | F15: ='3-Statement Model'!F16 -> -42440 | H15: ='3-Statement Model'!H16 -> -5410 | I15: ='3-Statement Model'!I16 -> -5498 | J15: ='3-Statement Model'!J16 -> -6395 | K15: ='3-Statement Model'!K16 -> -7467 | L15: ='3-Statement Model'!L16 -> -7856 | M15: ='3-Statement Model'!M16 -> -7216 | N15: ='3-Statement Model'!N16 -> -8028 | O15: ='3-Statement Model'!O16 -> -8676 | ... U15: ='3-Statement Model'!U16 -> -15906 | W15: =SUM(H15:K15) -> -24770 | X15: =SUM(I15:L15) -> -27216 | Y15: =SUM(J15:M15) -> -28934 | Z15: =SUM(K15:N15) -> -30567 | AA15: =SUM(L15:O15) -> -31776 | AB15: =SUM(M15:P15) -> -32524 | AC15: =SUM(N15:Q15) -> -34868 | AD15: =SUM(O15:R15) -> -38294 | ... AG15: =SUM(R15:U15) -> -54611 | AI15: =SUM(AG15/AC15)-1 -> 0.56622118
B16: (-) Product support | C16: ='3-Statement Model'!C18 -> -19254 | D16: ='3-Statement Model'!D18 -> -21264 | E16: ='3-Statement Model'!E18 -> -22434 | F16: ='3-Statement Model'!F18 -> -33289 | H16: ='3-Statement Model'!H18 -> -5191 | I16: ='3-Statement Model'!I18 -> -5127 | J16: ='3-Statement Model'!J18 -> -5224 | K16: ='3-Statement Model'!K18 -> -5722 | L16: ='3-Statement Model'!L18 -> -5768 | M16: ='3-Statement Model'!M18 -> -5816 | N16: ='3-Statement Model'!N18 -> -5531 | O16: ='3-Statement Model'!O18 -> -5319 | ... U16: ='3-Statement Model'!U18 -> -7291 | W16: =SUM(H16:K16) -> -21264 | X16: =SUM(I16:L16) -> -21841 | Y16: =SUM(J16:M16) -> -22530 | Z16: =SUM(K16:N16) -> -22837 | AA16: =SUM(L16:O16) -> -22434 | AB16: =SUM(M16:P16) -> -25213 | AC16: =SUM(N16:Q16) -> -27590 | AD16: =SUM(O16:R16) -> -30631 | ... AG16: =SUM(R16:U16) -> -31194 | AI16: =SUM(AG16/AC16)-1 -> 0.13062704
B17: (-) Other services | C17: ='3-Statement Model'!C19 -> -54033 | D17: ='3-Statement Model'!D19 -> -55283 | E17: ='3-Statement Model'!E19 -> -53805 | F17: ='3-Statement Model'!F19 -> -50679 | H17: ='3-Statement Model'!H19 -> -14599 | I17: ='3-Statement Model'!I19 -> -14148 | J17: ='3-Statement Model'!J19 -> -13360 | K17: ='3-Statement Model'!K19 -> -13176 | L17: ='3-Statement Model'!L19 -> -13783 | M17: ='3-Statement Model'!M19 -> -13645 | N17: ='3-Statement Model'!N19 -> -12760 | O17: ='3-Statement Model'!O19 -> -13617 | ... U17: ='3-Statement Model'!U19 -> -11384 | W17: =SUM(H17:K17) -> -55283 | X17: =SUM(I17:L17) -> -54467 | Y17: =SUM(J17:M17) -> -53964 | Z17: =SUM(K17:N17) -> -53364 | AA17: =SUM(L17:O17) -> -53805 | AB17: =SUM(M17:P17) -> -52319 | AC17: =SUM(N17:Q17) -> -51062 | AD17: =SUM(O17:R17) -> -51856 | ... AG17: =SUM(R17:U17) -> -48602 | AI17: =SUM(AG17/AC17)-1 -> -0.048176726
B18: (-) Cost of Sales | C18: =SUM(C14:C17) -> -91909 | D18: =SUM(D14:D17) -> -102989 | E18: =SUM(E14:E17) -> -109944 | F18: =SUM(F14:F17) -> -129468 | H18: =SUM(H14:H17) -> -25677 | I18: =SUM(I14:I17) -> -25204 | J18: =SUM(J14:J17) -> -25385 | K18: =SUM(K14:K17) -> -26723 | L18: =SUM(L14:L17) -> -27941 | M18: =SUM(M14:M17) -> -27121 | N18: =SUM(N14:N17) -> -26661 | O18: =SUM(O14:O17) -> -28221 | ... U18: =SUM(U14:U17) -> -35750 | W18: =SUM(H18:K18) -> -102989 | X18: =SUM(I18:L18) -> -105253 | Y18: =SUM(J18:M18) -> -107170 | Z18: =SUM(K18:N18) -> -108446 | AA18: =SUM(L18:O18) -> -109944 | AB18: =SUM(M18:P18) -> -112018 | AC18: =SUM(N18:Q18) -> -115832 | AD18: =SUM(O18:R18) -> -123520 | ... AG18: =SUM(R18:U18) -> -138239 | AI18: =SUM(AG18/AC18)-1 -> 0.19344395
B19: Gross Profit | C19: =+C10+C18 -> 418853 | D19: =+D10+D18 -> 396275 | E19: =+E10+E18 -> 386317 | F19: =+F10+F18 -> 333988 | H19: =+H10+H18 -> 93600 | I19: =+I10+I18 -> 96869 | J19: =+J10+J18 -> 99975 | K19: =+K10+K18 -> 105831 | L19: =+L10+L18 -> 93974 | M19: =+M10+M18 -> 93279 | N19: =+N10+N18 -> 102801 | O19: =+O10+O18 -> 96263 | ... U19: =+U10+U18 -> 78738 | W19: =+W10+W18 -> 396275 | X19: =+X10+X18 -> 396649 | Y19: =+Y10+Y18 -> 393059 | Z19: =+Z10+Z18 -> 395885 | AA19: =+AA10+AA18 -> 386317 | AB19: =+AB10+AB18 -> 377574 | AC19: =+AC10+AC18 -> 364802 | AD19: =+AD10+AD18 -> 343723 | ... AG19: =+AG10+AG18 -> 324083 | AI19: =SUM(AG19/AC19)-1 -> -0.11161945
B20: Gross Margin (%) | C20: =C19/C10 -> 0.82005513 | D20: =D19/D10 -> 0.79371835 | E20: =E19/E10 -> 0.77845529 | F20: =F19/F10 -> 0.72064662 | H20: =H19/H10 -> 0.78472799 | I20: =I19/I10 -> 0.79353338 | J20: =J19/J10 -> 0.79750319 | K20: =K19/K10 -> 0.79839914 | L20: =L19/L10 -> 0.77081573 | M20: =M19/M10 -> 0.77474252 | N20: =N19/N10 -> 0.79406312 | O20: =O19/O10 -> 0.77329617 | ... U20: =U19/U10 -> 0.6877402 | W20: =W19/W10 -> 0.79371835 | X20: =X19/X10 -> 0.79029173 | Y20: =Y19/Y10 -> 0.78575812 | Z20: =Z19/Z10 -> 0.78497058 | AA20: =AA19/AA10 -> 0.77845529 | AB20: =AB19/AB10 -> 0.77120133 | AC20: =AC19/AC10 -> 0.75900165 | AD20: =AD19/AD10 -> 0.73564077 | ... AG20: =AG19/AG10 -> 0.70098979 | AI20: =SUM(AG20-AC20)*10000 -> -580.11866
B22: (-) Sales and Marketing | C22: ='3-Statement Model'!C23 -> -160141 | D22: ='3-Statement Model'!D23 -> -146882 | E22: ='3-Statement Model'!E23 -> -149671 | F22: ='3-Statement Model'!F23 -> -138081 | G22: ='3-Statement Model'!G23 -> 0 | H22: ='3-Statement Model'!H23 -> -33240 | I22: ='3-Statement Model'!I23 -> -36862 | J22: ='3-Statement Model'!J23 -> -35409 | ... U22: ='3-Statement Model'!U23 -> -33691 | W22: =SUM(H22:K22) -> -146882 | X22: =SUM(I22:L22) -> -149748 | Y22: =SUM(J22:M22) -> -150546 | Z22: =SUM(K22:N22) -> -150743 | AA22: =SUM(L22:O22) -> -149671 | AB22: =SUM(M22:P22) -> -147016 | AC22: =SUM(N22:Q22) -> -143607 | AD22: =SUM(O22:R22) -> -143415 | ... AG22: =SUM(R22:U22) -> -131602 | AI22: =SUM(AG22/AC22)-1 -> -0.083596204
B23: (-) Research and Development | C23: ='3-Statement Model'!C24 -> -117117 | D23: ='3-Statement Model'!D24 -> -127428 | E23: ='3-Statement Model'!E24 -> -120530 | F23: ='3-Statement Model'!F24 -> -118486 | G23: ='3-Statement Model'!G24 -> 0 | H23: ='3-Statement Model'!H24 -> -33523 | I23: ='3-Statement Model'!I24 -> -31790 | J23: ='3-Statement Model'!J24 -> -30498 | ... U23: ='3-Statement Model'!U24 -> -24071 | W23: =SUM(H23:K23) -> -127428 | X23: =SUM(I23:L23) -> -125263 | Y23: =SUM(J23:M23) -> -122827 | Z23: =SUM(K23:N23) -> -121989 | AA23: =SUM(L23:O23) -> -120530 | AB23: =SUM(M23:P23) -> -118355 | AC23: =SUM(N23:Q23) -> -119312 | AD23: =SUM(O23:R23) -> -122953 | ... AG23: =SUM(R23:U23) -> -107486 | AI23: =SUM(AG23/AC23)-1 -> -0.099118278
B24: (-) General and Administrative | C24: ='3-Statement Model'!C25 -> -95501 | D24: ='3-Statement Model'!D25 -> -111421 | E24: ='3-Statement Model'!E25 -> -115312 | F24: ='3-Statement Model'!F25 -> -140537 | G24: ='3-Statement Model'!G25 -> 0 | H24: ='3-Statement Model'!H25 -> -26706 | I24: ='3-Statement Model'!I25 -> -28502 | J24: ='3-Statement Model'!J25 -> -27283 | ... U24: ='3-Statement Model'!U25 -> -36500 | W24: =SUM(H24:K24) -> -111421 | X24: =SUM(I24:L24) -> -112621 | Y24: =SUM(J24:M24) -> -112949 | Z24: =SUM(K24:N24) -> -114889 | AA24: =SUM(L24:O24) -> -115312 | AB24: =SUM(M24:P24) -> -122072 | AC24: =SUM(N24:Q24) -> -129371 | AD24: =SUM(O24:R24) -> -133653 | ... AG24: =SUM(R24:U24) -> -146789 | AI24: =SUM(AG24/AC24)-1 -> 0.13463605
B25: (-) Unrealized gain on digital assets | C25: ='3-Statement Model'!C26 -> 0 | D25: ='3-Statement Model'!D26 -> 0 | E25: ='3-Statement Model'!E26 -> 0 | F25: ='3-Statement Model'!F26 -> 0 | G25: ='3-Statement Model'!G26 -> 0 | H25: ='3-Statement Model'!H26 -> 0 | I25: ='3-Statement Model'!I26 -> 0 | J25: ='3-Statement Model'!J26 -> 0 | ... U25: ='3-Statement Model'!U26 -> 14047514 | AC25: =SUM(N25:Q25) -> 0 | AD25: =SUM(O25:R25) -> 0 | AE25: =SUM(P25:S25) -> 0 | AF25: =SUM(Q25:T25) -> -5906005 | AG25: =SUM(R25:U25) -> 8141509 | AI25: =SUM(AG25/AC25)-1 -> #DIV/0!
B26: (-) Digital asset impairment gains (losses on sale), net | C26: ='3-Statement Model'!C27 -> -830621 | D26: ='3-Statement Model'!D27 -> -1286286 | E26: ='3-Statement Model'!E27 -> -115851 | F26: ='3-Statement Model'!F27 -> -1789862 | G26: ='3-Statement Model'!G27 -> 0 | H26: ='3-Statement Model'!H27 -> -170091 | I26: ='3-Statement Model'!I27 -> -917838 | J26: ='3-Statement Model'!J27 -> -727 | ... U26: ='3-Statement Model'!U27 -> 0 | W26: =SUM(H26:K26) -> -1286286 | X26: =SUM(I26:L26) -> -1135106 | Y26: =SUM(J26:M26) -> -241411 | Z26: =SUM(K26:N26) -> -274243 | AA26: =SUM(L26:O26) -> -115851 | AB26: =SUM(M26:P26) -> -288573 | AC26: =SUM(N26:Q26) -> -444520 | AD26: =SUM(O26:R26) -> -823045 | ... AG26: =SUM(R26:U26) -> -1418139 | AI26: =SUM(AG26/AC26)-1 -> 2.1902704
B27: Earning before Interest & Taxes (EBIT) | C27: =SUM(C19+SUM(C22:C26)) -> -784527 | D27: =SUM(D19+SUM(D22:D26)) -> -1275742 | E27: =SUM(E19+SUM(E22:E26)) -> -115047 | F27: =SUM(F19+SUM(F22:F26)) -> -1852978 | H27: =SUM(H19+SUM(H22:H26)) -> -169960 | I27: =SUM(I19+SUM(I22:I26)) -> -918123 | J27: =SUM(J19+SUM(J22:J26)) -> 6058 | K27: =SUM(K19+SUM(K22:K26)) -> -193717 | L27: =SUM(L19+SUM(L22:L26)) -> -20307 | M27: =SUM(M19+SUM(M22:M26)) -> -26708 | N27: =SUM(N19+SUM(N22:N26)) -> -25247 | O27: =SUM(O19+SUM(O22:O26)) -> -42785 | ... U27: =SUM(U19+SUM(U22:U26)) -> 14031990 | W27: =SUM(W19+SUM(W22:W26)) -> -1275742 | X27: =SUM(X19+SUM(X22:X26)) -> -1126089 | Y27: =SUM(Y19+SUM(Y22:Y26)) -> -234674 | Z27: =SUM(Z19+SUM(Z22:Z26)) -> -265979 | AA27: =SUM(AA19+SUM(AA22:AA26)) -> -115047 | AB27: =SUM(AB19+SUM(AB22:AB26)) -> -298442 | AC27: =SUM(AC19+SUM(AC22:AC26)) -> -472008 | AD27: =SUM(AD19+SUM(AD22:AD26)) -> -879343 | ... AG27: =SUM(AG19+SUM(AG22:AG26)) -> 6661576 | AI27: =SUM(AG27/AC27)-1 -> -15.113269
B28: Operating Margin (%) | C28: =C27/C10 -> -1.5359933 | D28: =D27/D10 -> -2.5552453 | E28: =E27/E10 -> -0.23182761 | F28: =F27/F10 -> -3.9981746 | H28: =H27/H10 -> -1.4249185 | I28: =I27/I10 -> -7.521098 | J28: =J27/J10 -> 0.048324825 | K28: =K27/K10 -> -1.4614195 | L28: =L27/L10 -> -0.16656687 | M28: =M27/M10 -> -0.22182724 | N28: =N27/N10 -> -0.19501475 | O28: =O27/O10 -> -0.34369879 | ... U28: =U27/U10 -> 122.56298 | W28: =W27/W10 -> -2.5552453 | X28: =X27/X10 -> -2.2436432 | Y28: =Y27/Y10 -> -0.46913314 | Z28: =Z27/Z10 -> -0.52738975 | AA28: =AA27/AA10 -> -0.23182761 | AB28: =AB27/AB10 -> -0.60957287 | AC28: =AC27/AC10 -> -0.98205287 | AD28: =AD27/AD10 -> -1.8819822 | ... AG28: =AG27/AG10 -> 14.408953 | AI28: =SUM(AG28-AC28)*10000 -> 153910.06
B30: (+) Depreciation and Amortization | C30: ='3-Statement Model'!C88 -> 11358 | D30: ='3-Statement Model'!D88 -> 10874 | E30: ='3-Statement Model'!E88 -> 14527 | F30: ='3-Statement Model'!F88 -> 17808 | H30: ='3-Statement Model'!H88 -> 2691 | I30: ='3-Statement Model'!I88 -> 2076 | J30: ='3-Statement Model'!J88 -> 2150 | K30: ='3-Statement Model'!K88 -> 3957 | L30: ='3-Statement Model'!L88 -> 3431 | M30: ='3-Statement Model'!M88 -> 3230 | N30: ='3-Statement Model'!N88 -> 2744 | O30: ='3-Statement Model'!O88 -> 5122 | ... U30: ='3-Statement Model'!U88 -> 9118 | W30: =SUM(H30:K30) -> 10874 | X30: =SUM(I30:L30) -> 11614 | Y30: =SUM(J30:M30) -> 12768 | Z30: =SUM(K30:N30) -> 13362 | AA30: =SUM(L30:O30) -> 14527 | AB30: =SUM(M30:P30) -> 14146 | AC30: =SUM(N30:Q30) -> 14567 | AD30: =SUM(O30:R30) -> 17801 | ... AG30: =SUM(R30:U30) -> 26800 | AI30: =SUM(AG30/AC30)-1 -> 0.83977483
B31: EBITDA | C31: =SUM(C27+C30) -> -773169 | D31: =SUM(D27+D30) -> -1264868 | E31: =SUM(E27+E30) -> -100520 | F31: =SUM(F27+F30) -> -1835170 | H31: =SUM(H27+H30) -> -167269 | I31: =SUM(I27+I30) -> -916047 | J31: =SUM(J27+J30) -> 8208 | K31: =SUM(K27+K30) -> -189760 | L31: =SUM(L27+L30) -> -16876 | M31: =SUM(M27+M30) -> -23478 | N31: =SUM(N27+N30) -> -22503 | O31: =SUM(O27+O30) -> -37663 | ... U31: =SUM(U27+U30) -> 14041108 | W31: =SUM(W27+W30) -> -1264868 | X31: =SUM(X27+X30) -> -1114475 | Y31: =SUM(Y27+Y30) -> -221906 | Z31: =SUM(Z27+Z30) -> -252617 | AA31: =SUM(AA27+AA30) -> -100520 | AB31: =SUM(AB27+AB30) -> -284296 | AC31: =SUM(AC27+AC30) -> -457441 | AD31: =SUM(AD27+AD30) -> -861542 | ... AG31: =SUM(AG27+AG30) -> 6688376 | AI31: =SUM(AG31/AC31)-1 -> -15.621287
B32: EBITDA Margin (%) | C32: =C31/C10 -> -1.5137559 | D32: =D31/D10 -> -2.5334653 | E32: =E31/E10 -> -0.2025547 | F32: =F31/F10 -> -3.9597502 | H32: =H31/H10 -> -1.4023575 | I32: =I31/I10 -> -7.5040918 | J32: =J31/J10 -> 0.065475431 | K32: =K31/K10 -> -1.4315675 | L32: =L31/L10 -> -0.13842431 | M32: =M31/M10 -> -0.195 | N32: =N31/N10 -> -0.17381934 | O32: =O31/O10 -> -0.30255294 | ... U32: =U31/U10 -> 122.64262 | W32: =W31/W10 -> -2.5334653 | X32: =X31/X10 -> -2.2205032 | Y32: =Y31/Y10 -> -0.44360883 | Z32: =Z31/Z10 -> -0.50089525 | AA32: =AA31/AA10 -> -0.2025547 | AB32: =AB31/AB10 -> -0.58067942 | AC32: =AC31/AC10 -> -0.95174499 | AD32: =AD31/AD10 -> -1.8438842 | ... AG32: =AG31/AG10 -> 14.466921 | AI32: =SUM(AG32-AC32)*10000 -> 154186.66
B34: (+) Share-based Compensation | C34: ='3-Statement Model'!C96 -> 7201 | D34: ='3-Statement Model'!D96 -> 8694 | E34: ='3-Statement Model'!E96 -> 8808 | F34: ='3-Statement Model'!F96 -> 15336 | H34: ='3-Statement Model'!H96 -> 2129 | I34: ='3-Statement Model'!I96 -> 2168 | J34: ='3-Statement Model'!J96 -> 2193 | K34: ='3-Statement Model'!K96 -> 2204 | L34: ='3-Statement Model'!L96 -> 2210 | M34: ='3-Statement Model'!M96 -> 2190 | N34: ='3-Statement Model'!N96 -> 2199 | O34: ='3-Statement Model'!O96 -> 2209 | ... U34: ='3-Statement Model'!U96 -> 6397 | W34: =SUM(H34:K34) -> 8694 | X34: =SUM(I34:L34) -> 8775 | Y34: =SUM(J34:M34) -> 8797 | Z34: =SUM(K34:N34) -> 8803 | AA34: =SUM(L34:O34) -> 8808 | AB34: =SUM(M34:P34) -> 9155 | AC34: =SUM(N34:Q34) -> 10807 | AD34: =SUM(O34:R34) -> 12440 | ... AG34: =SUM(R34:U34) -> 21382 | AI34: =SUM(AG34/AC34)-1 -> 0.97853243
B35: (+/-) Digital asset impairment Losses (Gains), net | C35: =-C26 -> 830621 | D35: =-D26 -> 1286286 | E35: =-E26 -> 115851 | F35: =-F26 -> 1789862 | H35: =-H26 -> 170091 | I35: =-I26 -> 917838 | J35: =-J26 -> 727 | K35: =-K26 -> 197630 | L35: =-L26 -> 18911 | M35: =-M26 -> 24143 | N35: =-N26 -> 33559 | O35: =-O26 -> 39238 | ... U35: =-U26 -> 0 | W35: =SUM(H35:K35) -> 1286286 | X35: =SUM(I35:L35) -> 1135106 | Y35: =SUM(J35:M35) -> 241411 | Z35: =SUM(K35:N35) -> 274243 | AA35: =SUM(L35:O35) -> 115851 | AB35: =SUM(M35:P35) -> 288573 | AC35: =SUM(N35:Q35) -> 444520 | AD35: =SUM(O35:R35) -> 823045 | ... AG35: =SUM(R35:U35) -> 1418139 | AI35: =SUM(AG35/AC35)-1 -> 2.1902704
B36: (+/-) Unrealized Loss (Gain) on digital assets | C36: =-C25 -> 0 | D36: =-D25 -> 0 | E36: =-E25 -> 0 | F36: =-F25 -> 0 | G36: =-G25 -> 0 | H36: =-H25 -> 0 | I36: =-I25 -> 0 | J36: =-J25 -> 0 | ... U36: =-U25 -> -14047514 | AC36: =SUM(N36:Q36) -> 0 | AD36: =SUM(O36:R36) -> 0 | AE36: =SUM(P36:S36) -> 0 | AF36: =SUM(Q36:T36) -> 5906005 | AG36: =SUM(R36:U36) -> -8141509 | AI36: =SUM(AG36/AC36)-1 -> #DIV/0!
B37: Adj. EBITDA | C37: =+SUM(C31+SUM(C34:C36)) -> 64653 | D37: =+SUM(D31+SUM(D34:D36)) -> 30112 | E37: =+SUM(E31+SUM(E34:E36)) -> 24139 | F37: =+SUM(F31+SUM(F34:F36)) -> -29972 | H37: =+SUM(H31+SUM(H34:H36)) -> 4951 | I37: =+SUM(I31+SUM(I34:I36)) -> 3959 | J37: =+SUM(J31+SUM(J34:J36)) -> 11128 | K37: =+SUM(K31+SUM(K34:K36)) -> 10074 | L37: =+SUM(L31+SUM(L34:L36)) -> 4245 | M37: =+SUM(M31+SUM(M34:M36)) -> 2855 | N37: =+SUM(N31+SUM(N34:N36)) -> 13255 | O37: =+SUM(O31+SUM(O34:O36)) -> 3784 | ... U37: =+SUM(U31+SUM(U34:U36)) -> -9 | W37: =+SUM(W31+SUM(W34:W35)) -> 30112 | X37: =+SUM(X31+SUM(X34:X35)) -> 29406 | Y37: =+SUM(Y31+SUM(Y34:Y35)) -> 28302 | Z37: =+SUM(Z31+SUM(Z34:Z35)) -> 30429 | AA37: =+SUM(AA31+SUM(AA34:AA35)) -> 24139 | AB37: =+SUM(AB31+SUM(AB34:AB35)) -> 13432 | AC37: =+SUM(AC31+SUM(AC34:AC36)) -> -2114 | AD37: =+SUM(AD31+SUM(AD34:AD36)) -> -26057 | AE37: =+SUM(AE31+SUM(AE34:AE36)) -> -29972 | AF37: =+SUM(AF31+SUM(AF34:AF36)) -> -26294 | AG37: =+SUM(AG31+SUM(AG34:AG36)) -> -13612 | AI37: =SUM(AG37/AC37)-1 -> 5.4389782
B38: Adj. EBITDA Margin (%) | C38: =C37/C10 -> 0.12658146 | D38: =D37/D10 -> 0.06031278 | E38: =E37/E10 -> 0.048641743 | F38: =F37/F10 -> -0.064670648 | H38: =H37/H10 -> 0.041508422 | I38: =I37/I10 -> 0.032431414 | J38: =J37/J10 -> 0.088768347 | K38: =K37/K10 -> 0.075999215 | L38: =L37/L10 -> 0.034819341 | M38: =M37/M10 -> 0.023712625 | N38: =N37/N10 -> 0.10238526 | O38: =O37/O10 -> 0.030397481 | ... U38: =U37/U10 -> -7.8610859e-05 | W38: =W37/W10 -> 0.06031278 | X38: =X37/X10 -> 0.058589127 | Y38: =Y37/Y10 -> 0.056578087 | Z38: =Z37/Z10 -> 0.060335375 | AA38: =AA37/AA10 -> 0.048641743 | AB38: =AB37/AB10 -> 0.027435089 | AC38: =AC37/AC10 -> -0.0043983572 | AD38: =AD37/AD10 -> -0.055767556 | ... AG38: =AG37/AG10 -> -0.029442683 | AI38: =SUM(AG38-AC38)*10000 -> -250.44326
B40: (-) Capital Expenditures | C40: ='3-Statement Model'!C114 -> -2706 | D40: ='3-Statement Model'!D114 -> -2486 | E40: ='3-Statement Model'!E114 -> -2938 | F40: ='3-Statement Model'!F114 -> -2978 | H40: ='3-Statement Model'!H114 -> -641 | I40: ='3-Statement Model'!I114 -> -878 | J40: ='3-Statement Model'!J114 -> -332 | K40: ='3-Statement Model'!K114 -> -635 | L40: ='3-Statement Model'!L114 -> -499 | M40: ='3-Statement Model'!M114 -> -639 | N40: ='3-Statement Model'!N114 -> -1453 | O40: ='3-Statement Model'!O114 -> -347 | ... U40: ='3-Statement Model'!U114 -> -2094 | W40: =SUM(H40:K40) -> -2486 | X40: =SUM(I40:L40) -> -2344 | Y40: =SUM(J40:M40) -> -2105 | Z40: =SUM(K40:N40) -> -3226 | AA40: =SUM(L40:O40) -> -2938 | AB40: =SUM(M40:P40) -> -3984 | AC40: =SUM(N40:Q40) -> -4068 | AD40: =SUM(O40:R40) -> -3041 | ... AG40: =SUM(R40:U40) -> -5541 | AI40: =SUM(AG40/AC40)-1 -> 0.3620944
B41: (-) Cash Interest | C41: =-'3-Statement Model'!C134 -> -20416 | D41: =-'3-Statement Model'!D134 -> -43448 | E41: =-'3-Statement Model'!E134 -> -41229 | F41: =-'3-Statement Model'!F134 -> -44571 | H41: =SUM($D$41/4) -> -10862 | I41: =SUM($D$41/4) -> -10862 | J41: =SUM($D$41/4) -> -10862 | K41: =SUM($D$41/4) -> -10862 | L41: =SUM($E$41/4) -> -10307.25 | M41: =SUM($E$41/4) -> -10307.25 | N41: =SUM($E$41/4) -> -10307.25 | O41: =SUM($E$41/4) -> -10307.25 | P41: =SUM($F$41/4) -> -11142.75 | Q41: =SUM($F$41/4) -> -11142.75 | R41: =SUM($F$41/4) -> -11142.75 | S41: =SUM($F$41/4) -> -11142.75 | T41: =S41 -> -11142.75 | U41: =T41 -> -11142.75 | W41: =SUM(H41:K41) -> -43448 | X41: =SUM(I41:L41) -> -42893.25 | Y41: =SUM(J41:M41) -> -42338.5 | Z41: =SUM(K41:N41) -> -41783.75 | AA41: =SUM(L41:O41) -> -41229 | AB41: =SUM(M41:P41) -> -42064.5 | AC41: =SUM(N41:Q41) -> -42900 | AD41: =SUM(O41:R41) -> -43735.5 | ... AG41: =SUM(R41:U41) -> -44571 | AI41: =SUM(AG41/AC41)-1 -> 0.038951049
B42: (-) Cash Taxes | C42: =-'3-Statement Model'!C135 -> -7010 | D42: =-'3-Statement Model'!D135 -> -21973 | E42: =-'3-Statement Model'!E135 -> -30318 | F42: =-'3-Statement Model'!F135 -> -1059 | H42: =SUM($D$42/4) -> -5493.25 | I42: =SUM($D$42/4) -> -5493.25 | J42: =SUM($D$42/4) -> -5493.25 | K42: =SUM($D$42/4) -> -5493.25 | L42: =SUM($E$42/4) -> -7579.5 | M42: =SUM($E$42/4) -> -7579.5 | N42: =SUM($E$42/4) -> -7579.5 | O42: =SUM($E$42/4) -> -7579.5 | P42: =SUM($F$42/4) -> -264.75 | Q42: =SUM($F$42/4) -> -264.75 | R42: =SUM($F$42/4) -> -264.75 | S42: =SUM($F$42/4) -> -264.75 | T42: =S42 -> -264.75 | U42: =T42 -> -264.75 | W42: =SUM(H42:K42) -> -21973 | X42: =SUM(I42:L42) -> -24059.25 | Y42: =SUM(J42:M42) -> -26145.5 | Z42: =SUM(K42:N42) -> -28231.75 | AA42: =SUM(L42:O42) -> -30318 | AB42: =SUM(M42:P42) -> -23003.25 | AC42: =SUM(N42:Q42) -> -15688.5 | AD42: =SUM(O42:R42) -> -8373.75 | ... AG42: =SUM(R42:U42) -> -1059 | AI42: =SUM(AG42/AC42)-1 -> -0.93249833
B43: (-) Mandatory Amortization | C43: 0 | D43: 0 | E43: 0 | F43: 0 | H43: 0 | I43: 0 | J43: 0 | K43: 0 | L43: 0 | M43: 0 | N43: 0 | O43: 0 | P43: 0 | Q43: 0 | R43: 0 | S43: 0 | T43: 0 | U43: 0 | W43: =SUM(H43:K43) -> 0 | X43: =SUM(I43:L43) -> 0 | Y43: =SUM(J43:M43) -> 0 | Z43: =SUM(K43:N43) -> 0 | AA43: =SUM(L43:O43) -> 0 | AB43: =SUM(M43:P43) -> 0 | AC43: =SUM(N43:Q43) -> 0 | AD43: =SUM(O43:R43) -> 0 | ... AG43: =SUM(R43:U43) -> 0 | AI43: =SUM(AG43/AC43)-1 -> #DIV/0!
B44: (+/-) Changes in NWC | C44: =SUM('3-Statement Model'!C100:C108) -> 11091 | D44: =SUM('3-Statement Model'!D100:D108) -> -36609 | E44: =SUM('3-Statement Model'!E100:E108) -> -21055 | F44: =SUM('3-Statement Model'!F100:F108) -> -42707 | H44: =SUM('3-Statement Model'!H100:H108) -> 40307 | I44: =SUM('3-Statement Model'!I100:I108) -> -31781 | J44: =SUM('3-Statement Model'!J100:J108) -> -13014 | K44: =SUM('3-Statement Model'!K100:K108) -> -32121 | L44: =SUM('3-Statement Model'!L100:L108) -> 36801 | M44: =SUM('3-Statement Model'!M100:M108) -> -17818 | N44: =SUM('3-Statement Model'!N100:N108) -> -26278 | O44: =SUM('3-Statement Model'!O100:O108) -> -13760 | ... U44: =SUM('3-Statement Model'!U100:U108) -> -13701 | W44: =SUM(H44:K44) -> -36609 | X44: =SUM(I44:L44) -> -40115 | Y44: =SUM(J44:M44) -> -26152 | Z44: =SUM(K44:N44) -> -39416 | AA44: =SUM(L44:O44) -> -21055 | AB44: =SUM(M44:P44) -> -32146 | AC44: =SUM(N44:Q44) -> -28280 | AD44: =SUM(O44:R44) -> -27508 | ... AG44: =SUM(R44:U44) -> -57509 | AI44: =SUM(AG44/AC44)-1 -> 1.0335573
B45: Discretionary Cash-Flows | C45: =SUM(C37+SUM(C40:C44)) -> 45612 | D45: =SUM(D37+SUM(D40:D44)) -> -74404 | E45: =SUM(E37+SUM(E40:E44)) -> -71401 | F45: =SUM(F37+SUM(F40:F44)) -> -121287 | H45: =SUM(H37+SUM(H40:H44)) -> 28261.75 | I45: =SUM(I37+SUM(I40:I44)) -> -45055.25 | J45: =SUM(J37+SUM(J40:J44)) -> -18573.25 | K45: =SUM(K37+SUM(K40:K44)) -> -39037.25 | L45: =SUM(L37+SUM(L40:L44)) -> 22660.25 | M45: =SUM(M37+SUM(M40:M44)) -> -33488.75 | N45: =SUM(N37+SUM(N40:N44)) -> -32362.75 | O45: =SUM(O37+SUM(O40:O44)) -> -28209.75 | ... U45: =SUM(U37+SUM(U40:U44)) -> -27211.5 | W45: =SUM(W37+SUM(W40:W44)) -> -74404 | X45: =SUM(X37+SUM(X40:X44)) -> -80005.5 | Y45: =SUM(Y37+SUM(Y40:Y44)) -> -68439 | Z45: =SUM(Z37+SUM(Z40:Z44)) -> -82228.5 | AA45: =SUM(AA37+SUM(AA40:AA44)) -> -71401 | AB45: =SUM(AB37+SUM(AB40:AB44)) -> -87765.75 | AC45: =SUM(AC37+SUM(AC40:AC44)) -> -93050.5 | AD45: =SUM(AD37+SUM(AD40:AD44)) -> -108715.25 | ... AG45: =SUM(AG37+SUM(AG40:AG44)) -> -122292 | AI45: =SUM(AG45/AC45)-1 -> 0.31425409
B47: (+/-) Issuance / (Repayment) from convertible senior notes, net | C47: ='3-Statement Model'!C120 -> 1025204 | D47: ='3-Statement Model'!D120 -> 0 | E47: ='3-Statement Model'!E120 -> 0 | F47: ='3-Statement Model'!F120 -> 6132319 | H47: ='3-Statement Model'!H120 -> 0 | I47: ='3-Statement Model'!I120 -> 0 | J47: ='3-Statement Model'!J120 -> 0 | K47: ='3-Statement Model'!K120 -> 0 | L47: ='3-Statement Model'!L120 -> 0 | M47: ='3-Statement Model'!M120 -> 0 | N47: ='3-Statement Model'!N120 -> 0 | O47: ='3-Statement Model'!O120 -> 0 | ... U47: ='3-Statement Model'!U120 -> -646 | W47: =SUM(H47:K47) -> 0 | X47: =SUM(I47:L47) -> 0 | Y47: =SUM(J47:M47) -> 0 | Z47: =SUM(K47:N47) -> 0 | AA47: =SUM(L47:O47) -> 0 | AB47: =SUM(M47:P47) -> 1375679 | AC47: =SUM(N47:Q47) -> 2161698 | AD47: =SUM(O47:R47) -> 3159828 | ... AG47: =SUM(R47:U47) -> 5955699
B48: (+/-) Issuance / (Repayment) from senior secured notes, net | C48: ='3-Statement Model'!C121 -> 487208 | D48: ='3-Statement Model'!D121 -> 0 | E48: ='3-Statement Model'!E121 -> 0 | F48: ='3-Statement Model'!F121 -> 0 | H48: ='3-Statement Model'!H121 -> 0 | I48: ='3-Statement Model'!I121 -> 0 | J48: ='3-Statement Model'!J121 -> 0 | K48: ='3-Statement Model'!K121 -> 0 | L48: ='3-Statement Model'!L121 -> 0 | M48: ='3-Statement Model'!M121 -> 0 | N48: ='3-Statement Model'!N121 -> 0 | O48: ='3-Statement Model'!O121 -> 0 | ... U48: ='3-Statement Model'!U121 -> 0 | W48: =SUM(H48:K48) -> 0 | X48: =SUM(I48:L48) -> 0 | Y48: =SUM(J48:M48) -> 0 | Z48: =SUM(K48:N48) -> 0 | AA48: =SUM(L48:O48) -> 0 | AB48: =SUM(M48:P48) -> 0 | AC48: =SUM(N48:Q48) -> 0 | AD48: =SUM(O48:R48) -> 0 | ... AG48: =SUM(R48:U48) -> 0
...
