Workbook

Sheet Historical Financials
B2: Warner Bros Discovery Inc (NASDAQ: WBD)
B3: Historical Financials
B4: ($ In Millions, except EPS)
A6: X | B6: Income Statement | E6: FYE | I6: Quarterly | O6: Quarterly | X6: LTM | AD6: Variance
B7: Fiscal Period | C7: 2020 | D7: 2021 | E7: 2022 | F7: 2023 | G7: 2024 | I7: 1Q23 | J7: 2Q23 | K7: 3Q23 | L7: 4Q23 | M7: 1Q24 | N7: 2Q24 | O7: 3Q24 | P7: 4Q24 | Q7: 1Q25 | R7: 2Q25 | S7: 3Q25 | U7: =L7 -> 4Q23 | V7: =M7 -> 1Q24 | W7: =N7 -> 2Q24 | X7: =O7 -> 3Q24 | Y7: =P7 -> 4Q24 | Z7: =Q7 -> 1Q25 | AA7: =R7 -> 2Q25 | AB7: =S7 -> 3Q25
B8: Fiscal Period End Date | C8: 44196 | D8: 44561 | E8: 44926 | F8: 45291 | G8: 45657 | I8: 45016 | J8: 45107 | K8: 45199 | L8: =E8 -> 44926 | M8: 45382 | N8: 45473 | O8: 45565 | P8: =F8 -> 45291 | Q8: 45747 | R8: 45838 | S8: 45930 | U8: =L8 -> 44926 | V8: =M8 -> 45382 | W8: =N8 -> 45473 | X8: =O8 -> 45565 | Y8: =P8 -> 45291 | Z8: =Q8 -> 45747 | AA8: =R8 -> 45838 | AB8: =S8 -> 45930
B10: Consolidated Revenue | C10: 10671 | D10: 12191 | E10: 33817 | F10: 41321 | G10: 39321 | I10: 10700 | J10: 10358 | K10: 9979 | L10: =SUM(F10-SUM(I10:K10)) -> 10284 | M10: 9958 | N10: 9713 | O10: 9623 | P10: =SUM(G10-SUM(M10:O10)) -> 10027 | Q10: 8979 | R10: 9812 | S10: 9045 | U10: =SUM(I10:L10) -> 41321 | V10: =SUM(J10:M10) -> 40579 | W10: =SUM(K10:N10) -> 39934 | X10: =SUM(L10:O10) -> 39578 | Y10: =SUM(M10:P10) -> 39321 | Z10: =SUM(N10:Q10) -> 38342 | AA10: =SUM(O10:R10) -> 38441 | AB10: =SUM(P10:S10) -> 37863 | AD10: =SUM(AB10/X10)-1 -> -0.043332154
B11: Total Revenue | C11: =+SUM(C10:C10) -> 10671 | D11: =+SUM(D10:D10) -> 12191 | E11: =+SUM(E10:E10) -> 33817 | F11: =+SUM(F10:F10) -> 41321 | G11: =+SUM(G10:G10) -> 39321 | I11: =+SUM(I10:I10) -> 10700 | J11: =+SUM(J10:J10) -> 10358 | K11: =+SUM(K10:K10) -> 9979 | L11: =+SUM(L10:L10) -> 10284 | M11: =+SUM(M10:M10) -> 9958 | N11: =+SUM(N10:N10) -> 9713 | O11: =+SUM(O10:O10) -> 9623 | P11: =+SUM(P10:P10) -> 10027 | ... S11: =+SUM(S10:S10) -> 9045 | U11: =+SUM(U10:U10) -> 41321 | V11: =+SUM(V10:V10) -> 40579 | W11: =+SUM(W10:W10) -> 39934 | X11: =+SUM(X10:X10) -> 39578 | Y11: =+SUM(Y10:Y10) -> 39321 | Z11: =+SUM(Z10:Z10) -> 38342 | AA11: =+SUM(AA10:AA10) -> 38441 | AB11: =+SUM(AB10:AB10) -> 37863 | AD11: =SUM(AB11/X11)-1 -> -0.043332154
B13: Costs of revenues, excluding depreciation and amortization | C13: -3860 | D13: -4620 | E13: -20442 | F13: -24526 | G13: -22970 | I13: -6685 | J13: -6636 | K13: -5309 | L13: =SUM(F13-SUM(I13:K13)) -> -5896 | M13: -6058 | N13: -6204 | O13: -5181 | P13: =SUM(G13-SUM(M13:O13)) -> -5527 | Q13: -5131 | R13: -5967 | S13: -4564 | U13: =SUM(I13:L13) -> -24526 | V13: =SUM(J13:M13) -> -23899 | W13: =SUM(K13:N13) -> -23467 | X13: =SUM(L13:O13) -> -23339 | Y13: =SUM(M13:P13) -> -22970 | Z13: =SUM(N13:Q13) -> -22043 | AA13: =SUM(O13:R13) -> -21806 | AB13: =SUM(P13:S13) -> -21189 | AD13: =SUM(AB13/X13)-1 -> -0.092120485
B14: Gross Profit | C14: =SUM(C11+C13) -> 6811 | D14: =SUM(D11+D13) -> 7571 | E14: =SUM(E11+E13) -> 13375 | F14: =SUM(F11+F13) -> 16795 | G14: =SUM(G11+G13) -> 16351 | I14: =SUM(I11+I13) -> 4015 | J14: =SUM(J11+J13) -> 3722 | K14: =SUM(K11+K13) -> 4670 | L14: =SUM(L11+L13) -> 4388 | M14: =SUM(M11+M13) -> 3900 | N14: =SUM(N11+N13) -> 3509 | O14: =SUM(O11+O13) -> 4442 | P14: =SUM(P11+P13) -> 4500 | ... S14: =SUM(S11+S13) -> 4481 | U14: =SUM(U11+U13) -> 16795 | V14: =SUM(V11+V13) -> 16680 | W14: =SUM(W11+W13) -> 16467 | X14: =SUM(X11+X13) -> 16239 | Y14: =SUM(Y11+Y13) -> 16351 | Z14: =SUM(Z11+Z13) -> 16299 | AA14: =SUM(AA11+AA13) -> 16635 | AB14: =SUM(AB11+AB13) -> 16674 | AD14: =SUM(AB14/X14)-1 -> 0.026787364
B15: Gross Margin (%) | C15: =C14/C11 -> 0.63827195 | D15: =D14/D11 -> 0.62103191 | E15: =E14/E11 -> 0.39551113 | F15: =F14/F11 -> 0.40645193 | G15: =G14/G11 -> 0.41583378 | I15: =I14/I11 -> 0.37523364 | J15: =J14/J11 -> 0.35933578 | K15: =K14/K11 -> 0.46798276 | L15: =L14/L11 -> 0.42668222 | M15: =M14/M11 -> 0.39164491 | N15: =N14/N11 -> 0.3612684 | O15: =O14/O11 -> 0.46160241 | P15: =P14/P11 -> 0.44878827 | ... S15: =S14/S11 -> 0.49541183 | U15: =U14/U11 -> 0.40645193 | V15: =V14/V11 -> 0.41105005 | W15: =W14/W11 -> 0.41235539 | X15: =X14/X11 -> 0.4103037 | Y15: =Y14/Y11 -> 0.41583378 | Z15: =Z14/Z11 -> 0.4250952 | AA15: =AA14/AA11 -> 0.43274108 | AB15: =AB14/AB11 -> 0.44037715 | AD15: =SUM(AB15-X15)*1000 -> 30.073445
B17: Selling, general and administrative | C17: -2722 | D17: -4016 | E17: -9678 | F17: -9696 | G17: -9296 | I17: -2388 | J17: -2562 | K17: -2291 | L17: =SUM(F17-SUM(I17:K17)) -> -2455 | M17: -2232 | N17: -2461 | O17: -2385 | P17: =SUM(G17-SUM(M17:O17)) -> -2218 | Q17: -2194 | R17: -2477 | S17: -2361 | U17: =SUM(I17:L17) -> -9696 | V17: =SUM(J17:M17) -> -9540 | W17: =SUM(K17:N17) -> -9439 | X17: =SUM(L17:O17) -> -9533 | Y17: =SUM(M17:P17) -> -9296 | Z17: =SUM(N17:Q17) -> -9258 | AA17: =SUM(O17:R17) -> -9274 | AB17: =SUM(P17:S17) -> -9250 | AD17: =SUM(AB17/X17)-1 -> -0.029686353
B18: Depreciation and amortization | C18: -1359 | D18: -1582 | E18: -7193 | F18: -7985 | G18: -7037 | I18: -2058 | J18: -1914 | K18: -1989 | L18: =SUM(F18-SUM(I18:K18)) -> -2024 | M18: -1888 | N18: -1744 | O18: -1762 | P18: =SUM(G18-SUM(M18:O18)) -> -1643 | Q18: -1547 | R18: -1447 | S18: -1375 | U18: =SUM(I18:L18) -> -7985 | V18: =SUM(J18:M18) -> -7815 | W18: =SUM(K18:N18) -> -7645 | X18: =SUM(L18:O18) -> -7418 | Y18: =SUM(M18:P18) -> -7037 | Z18: =SUM(N18:Q18) -> -6696 | AA18: =SUM(O18:R18) -> -6399 | AB18: =SUM(P18:S18) -> -6012 | AD18: =SUM(AB18/X18)-1 -> -0.18953896
B19: Restructuring and other charges | C19: -91 | D19: -32 | E19: -3757 | F19: -585 | G19: -447 | I19: -95 | J19: -146 | K19: -269 | L19: =SUM(F19-SUM(I19:K19)) -> -75 | M19: -35 | N19: -117 | O19: -9 | P19: =SUM(G19-SUM(M19:O19)) -> -286 | Q19: -54 | R19: -80 | S19: -88 | U19: =SUM(I19:L19) -> -585 | V19: =SUM(J19:M19) -> -525 | W19: =SUM(K19:N19) -> -496 | X19: =SUM(L19:O19) -> -236 | Y19: =SUM(M19:P19) -> -447 | Z19: =SUM(N19:Q19) -> -466 | AA19: =SUM(O19:R19) -> -429 | AB19: =SUM(P19:S19) -> -508 | AD19: =SUM(AB19/X19)-1 -> 1.1525424
B20: Impairments and loss on dispositions | C20: -124 | D20: 71 | E20: -117 | F20: -77 | G20: -9603 | I20: -31 | J20: -6 | K20: -24 | L20: =SUM(F20-SUM(I20:K20)) -> -16 | M20: -12 | N20: -9395 | O20: -5 | P20: =SUM(G20-SUM(M20:O20)) -> -191 | Q20: -90 | R20: -26 | S20: -46 | U20: =SUM(I20:L20) -> -77 | V20: =SUM(J20:M20) -> -58 | W20: =SUM(K20:N20) -> -9447 | X20: =SUM(L20:O20) -> -9428 | Y20: =SUM(M20:P20) -> -9603 | Z20: =SUM(N20:Q20) -> -9681 | AA20: =SUM(O20:R20) -> -312 | AB20: =SUM(P20:S20) -> -353 | AD20: =SUM(AB20/X20)-1 -> -0.96255834
B21: Operating Profit | C21: =+SUM(C14+SUM(C17:C20)) -> 2515 | D21: =+SUM(D14+SUM(D17:D20)) -> 2012 | E21: =+SUM(E14+SUM(E17:E20)) -> -7370 | F21: =+SUM(F14+SUM(F17:F20)) -> -1548 | G21: =+SUM(G14+SUM(G17:G20)) -> -10032 | I21: =+SUM(I14+SUM(I17:I20)) -> -557 | J21: =+SUM(J14+SUM(J17:J20)) -> -906 | K21: =+SUM(K14+SUM(K17:K20)) -> 97 | L21: =+SUM(L14+SUM(L17:L20)) -> -182 | M21: =+SUM(M14+SUM(M17:M20)) -> -267 | N21: =+SUM(N14+SUM(N17:N20)) -> -10208 | O21: =+SUM(O14+SUM(O17:O20)) -> 281 | P21: =+SUM(P14+SUM(P17:P20)) -> 162 | ... S21: =+SUM(S14+SUM(S17:S20)) -> 611 | U21: =+SUM(U14+SUM(U17:U20)) -> -1548 | V21: =+SUM(V14+SUM(V17:V20)) -> -1258 | W21: =+SUM(W14+SUM(W17:W20)) -> -10560 | X21: =+SUM(X14+SUM(X17:X20)) -> -10376 | Y21: =+SUM(Y14+SUM(Y17:Y20)) -> -10032 | Z21: =+SUM(Z14+SUM(Z17:Z20)) -> -9802 | AA21: =+SUM(AA14+SUM(AA17:AA20)) -> 221 | AB21: =+SUM(AB14+SUM(AB17:AB20)) -> 551 | AD21: =SUM(AB21/X21)-1 -> -1.0531033
B22: Operating Margin (%) | C22: =C21/C11 -> 0.2356855 | D22: =D21/D11 -> 0.16503978 | E22: =E21/E11 -> -0.21793772 | F22: =F21/F11 -> -0.037462791 | G22: =G21/G11 -> -0.25513085 | I22: =I21/I11 -> -0.052056075 | J22: =J21/J11 -> -0.087468623 | K22: =K21/K11 -> 0.0097204129 | L22: =L21/L11 -> -0.017697394 | M22: =M21/M11 -> -0.026812613 | N22: =N21/N11 -> -1.0509626 | O22: =O21/O11 -> 0.029200873 | P22: =P21/P11 -> 0.016156378 | ... S22: =S21/S11 -> 0.067551133 | U22: =U21/U11 -> -0.037462791 | V22: =V21/V11 -> -0.031001257 | W22: =W21/W11 -> -0.26443632 | X22: =X21/X11 -> -0.26216585 | Y22: =Y21/Y11 -> -0.25513085 | Z22: =Z21/Z11 -> -0.25564655 | AA22: =AA21/AA11 -> 0.00574907 | AB22: =AB21/AB11 -> 0.014552465 | AD22: =SUM(AB22-X22)*1000 -> 276.71832
B24: Interest expense, net | C24: -648 | D24: -633 | E24: -1777 | F24: -2221 | G24: -2017 | I24: -571 | J24: -574 | K24: -574 | L24: =SUM(F24-SUM(I24:K24)) -> -502 | M24: -515 | N24: -518 | O24: -494 | P24: =SUM(G24-SUM(M24:O24)) -> -490 | Q24: -468 | R24: -463 | S24: -570 | U24: =SUM(I24:L24) -> -2221 | V24: =SUM(J24:M24) -> -2165 | W24: =SUM(K24:N24) -> -2109 | X24: =SUM(L24:O24) -> -2029 | Y24: =SUM(M24:P24) -> -2017 | Z24: =SUM(N24:Q24) -> -1970 | AA24: =SUM(O24:R24) -> -1915 | AB24: =SUM(P24:S24) -> -1991 | AD24: =SUM(AB24/X24)-1 -> -0.018728438
B25: Gain on extinguishment of debt | C25: 0 | D25: 0 | E25: 0 | F25: 17 | G25: 632 | I25: 0 | J25: -5 | K25: 22 | L25: =SUM(F25-SUM(I25:K25)) -> 0 | M25: 0 | N25: 542 | O25: 23 | P25: =SUM(G25-SUM(M25:O25)) -> 67 | Q25: -4 | R25: 2958 | S25: -1 | U25: =SUM(I25:L25) -> 17 | V25: =SUM(J25:M25) -> 17 | W25: =SUM(K25:N25) -> 564 | X25: =SUM(L25:O25) -> 565 | Y25: =SUM(M25:P25) -> 632 | Z25: =SUM(N25:Q25) -> 628 | AA25: =SUM(O25:R25) -> 3044 | AB25: =SUM(P25:S25) -> 3020 | AD25: =SUM(AB25/X25)-1 -> 4.3451327
B26: Loss from equity investees, net | C26: -105 | D26: -18 | E26: -160 | F26: -82 | G26: -121 | I26: -37 | J26: -22 | K26: -14 | L26: =SUM(F26-SUM(I26:K26)) -> -9 | M26: -48 | N26: -23 | O26: -18 | P26: =SUM(G26-SUM(M26:O26)) -> -32 | Q26: -7 | R26: 5 | S26: 17 | U26: =SUM(I26:L26) -> -82 | V26: =SUM(J26:M26) -> -93 | W26: =SUM(K26:N26) -> -94 | X26: =SUM(L26:O26) -> -98 | Y26: =SUM(M26:P26) -> -121 | Z26: =SUM(N26:Q26) -> -80 | AA26: =SUM(O26:R26) -> -52 | AB26: =SUM(P26:S26) -> -17 | AD26: =SUM(AB26/X26)-1 -> -0.82653061
B27: Other income (expense), net | C27: -34 | D27: 72 | E27: 347 | F27: -29 | G27: 150 | I27: -73 | J27: 27 | K27: -63 | L27: =SUM(F27-SUM(I27:K27)) -> 80 | M27: 11 | N27: 172 | O27: 30 | P27: =SUM(G27-SUM(M27:O27)) -> -63 | Q27: 82 | R27: 139 | S27: -30 | U27: =SUM(I27:L27) -> -29 | V27: =SUM(J27:M27) -> 55 | W27: =SUM(K27:N27) -> 200 | X27: =SUM(L27:O27) -> 293 | Y27: =SUM(M27:P27) -> 150 | Z27: =SUM(N27:Q27) -> 221 | AA27: =SUM(O27:R27) -> 188 | AB27: =SUM(P27:S27) -> 128 | AD27: =SUM(AB27/X27)-1 -> -0.56313993
B28: Loss before income taxes | C28: =SUM(C24:C27)+C21 -> 1728 | D28: =SUM(D24:D27)+D21 -> 1433 | E28: =SUM(E24:E27)+E21 -> -8960 | F28: =SUM(F24:F27)+F21 -> -3863 | G28: =SUM(G24:G27)+G21 -> -11388 | I28: =SUM(I24:I27)+I21 -> -1238 | J28: =SUM(J24:J27)+J21 -> -1480 | K28: =SUM(K24:K27)+K21 -> -532 | L28: =SUM(L24:L27)+L21 -> -613 | M28: =SUM(M24:M27)+M21 -> -819 | N28: =SUM(N24:N27)+N21 -> -10035 | O28: =SUM(O24:O27)+O21 -> -178 | P28: =SUM(P24:P27)+P21 -> -356 | ... S28: =SUM(S24:S27)+S21 -> 27 | U28: =SUM(U24:U27)+U21 -> -3863 | V28: =SUM(V24:V27)+V21 -> -3444 | W28: =SUM(W24:W27)+W21 -> -11999 | X28: =SUM(X24:X27)+X21 -> -11645 | Y28: =SUM(Y24:Y27)+Y21 -> -11388 | Z28: =SUM(Z24:Z27)+Z21 -> -11003 | AA28: =SUM(AA24:AA27)+AA21 -> 1486 | AB28: =SUM(AB24:AB27)+AB21 -> 1691 | AD28: =SUM(AB28/X28)-1 -> -1.1452125
B29: EBT Margin (%) | C29: =C28/C11 -> 0.16193421 | D29: =D28/D11 -> 0.11754573 | E29: =E28/E11 -> -0.2649555 | F29: =F28/F11 -> -0.093487573 | G29: =G28/G11 -> -0.28961624 | I29: =I28/I11 -> -0.11570093 | J29: =J28/J11 -> -0.14288473 | K29: =K28/K11 -> -0.053311955 | L29: =L28/L11 -> -0.059607157 | M29: =M28/M11 -> -0.082245431 | N29: =N28/N11 -> -1.0331514 | O29: =O28/O11 -> -0.01849735 | P29: =P28/P11 -> -0.035504139 | ... S29: =S28/S11 -> 0.0029850746 | U29: =U28/U11 -> -0.093487573 | V29: =V28/V11 -> -0.084871485 | W29: =W28/W11 -> -0.30047078 | X29: =X28/X11 -> -0.29422912 | Y29: =Y28/Y11 -> -0.28961624 | Z29: =Z28/Z11 -> -0.2869699 | AA29: =AA28/AA11 -> 0.038656643 | AB29: =AB28/AB11 -> 0.044661015 | AD29: =SUM(AB29-X29)*1000 -> 338.89013
B31: Income tax expense | C31: -373 | D31: -236 | E31: 1663 | F31: 784 | G31: -94 | I31: 178 | J31: 260 | K31: 125 | L31: =SUM(F31-SUM(I31:K31)) -> 221 | M31: -136 | N31: 7 | O31: 319 | P31: =SUM(G31-SUM(M31:O31)) -> -284 | Q31: -15 | R31: -866 | S31: -170 | U31: =SUM(I31:L31) -> 784 | V31: =SUM(J31:M31) -> 470 | W31: =SUM(K31:N31) -> 217 | X31: =SUM(L31:O31) -> 411 | Y31: =SUM(M31:P31) -> -94 | Z31: =SUM(N31:Q31) -> 27 | AA31: =SUM(O31:R31) -> -846 | AB31: =SUM(P31:S31) -> -1335 | AD31: =SUM(AB31/X31)-1 -> -4.2481752
B32: Net Income | C32: =SUM(C28+SUM(C31:C31)) -> 1355 | D32: =SUM(D28+SUM(D31:D31)) -> 1197 | E32: =SUM(E28+SUM(E31:E31)) -> -7297 | F32: =SUM(F28+SUM(F31:F31)) -> -3079 | G32: =SUM(G28+SUM(G31:G31)) -> -11482 | I32: =SUM(I28+SUM(I31:I31)) -> -1060 | J32: =SUM(J28+SUM(J31:J31)) -> -1220 | K32: =SUM(K28+SUM(K31:K31)) -> -407 | L32: =SUM(L28+SUM(L31:L31)) -> -392 | M32: =SUM(M28+SUM(M31:M31)) -> -955 | N32: =SUM(N28+SUM(N31:N31)) -> -10028 | O32: =SUM(O28+SUM(O31:O31)) -> 141 | P32: =SUM(P28+SUM(P31:P31)) -> -640 | ... S32: =SUM(S28+SUM(S31:S31)) -> -143 | U32: =SUM(U24+SUM(U31:U31)) -> -1437 | V32: =SUM(V24+SUM(V31:V31)) -> -1695 | W32: =SUM(W24+SUM(W31:W31)) -> -1892 | X32: =SUM(X24+SUM(X31:X31)) -> -1618 | Y32: =SUM(Y24+SUM(Y31:Y31)) -> -2111 | Z32: =SUM(Z24+SUM(Z31:Z31)) -> -1943 | AA32: =SUM(AA24+SUM(AA31:AA31)) -> -2761 | AB32: =SUM(AB24+SUM(AB31:AB31)) -> -3326 | AD32: =SUM(AB32/X32)-1 -> 1.0556242
B34: Net loss (income) attributable to noncontrolling interests | C34: -124 | D34: -138 | E34: -68 | F34: -38 | G34: 129 | I34: -8 | J34: -16 | K34: -8 | L34: =SUM(F34-SUM(I34:K34)) -> -6 | M34: -7 | N34: -10 | O34: -3 | P34: =SUM(G34-SUM(M34:O34)) -> 149 | Q34: -8 | R34: -7 | S34: -4 | U34: =SUM(I34:L34) -> -38 | V34: =SUM(J34:M34) -> -37 | W34: =SUM(K34:N34) -> -31 | X34: =SUM(L34:O34) -> -26 | Y34: =SUM(M34:P34) -> 129 | Z34: =SUM(N34:Q34) -> 128 | AA34: =SUM(O34:R34) -> 131 | AB34: =SUM(P34:S34) -> 130 | AD34: =SUM(AB34/X34)-1 -> -6
B35: Net loss (income) attributable to redeemable noncontrolling interests | C35: -12 | D35: -53 | E35: -6 | F35: -9 | G35: 42 | I35: -1 | J35: -4 | K35: -2 | L35: =SUM(F35-SUM(I35:K35)) -> -2 | M35: -4 | N35: 52 | O35: -3 | P35: =SUM(G35-SUM(M35:O35)) -> -3 | Q35: 4 | R35: -1 | S35: -1 | U35: =SUM(I35:L35) -> -9 | V35: =SUM(J35:M35) -> -12 | W35: =SUM(K35:N35) -> 44 | X35: =SUM(L35:O35) -> 43 | Y35: =SUM(M35:P35) -> 42 | Z35: =SUM(N35:Q35) -> 50 | AA35: =SUM(O35:R35) -> -3 | AB35: =SUM(P35:S35) -> -1
B36: Net loss available to Warner Bros. Discovery, Inc. | C36: =SUM(C32)+SUM(C34:C35) -> 1219 | D36: =SUM(D32)+SUM(D34:D35) -> 1006 | E36: =SUM(E32)+SUM(E34:E35) -> -7371 | F36: =SUM(F32)+SUM(F34:F35) -> -3126 | G36: =SUM(G32)+SUM(G34:G35) -> -11311 | I36: =SUM(I32)+SUM(I34:I35) -> -1069 | J36: =SUM(J32)+SUM(J34:J35) -> -1240 | K36: =SUM(K32)+SUM(K34:K35) -> -417 | L36: =SUM(L32)+SUM(L34:L35) -> -400 | M36: =SUM(M32)+SUM(M34:M35) -> -966 | N36: =SUM(N32)+SUM(N34:N35) -> -9986 | O36: =SUM(O32)+SUM(O34:O35) -> 135 | P36: =SUM(P32)+SUM(P34:P35) -> -494 | ... S36: =SUM(S32)+SUM(S34:S35) -> -148 | U36: =SUM(U32)+SUM(U34:U35) -> -1484 | V36: =SUM(V32)+SUM(V34:V35) -> -1744 | W36: =SUM(W32)+SUM(W34:W35) -> -1879 | X36: =SUM(X32)+SUM(X34:X35) -> -1601 | Y36: =SUM(Y32)+SUM(Y34:Y35) -> -1940 | Z36: =SUM(Z32)+SUM(Z34:Z35) -> -1765 | AA36: =SUM(AA32)+SUM(AA34:AA35) -> -2633 | AB36: =SUM(AB32)+SUM(AB34:AB35) -> -3197 | AD36: =SUM(AB36/X36)-1 -> 0.99687695
B38: Basic shares | C38: 599 | D38: 588 | E38: 1940 | F38: 2436 | G38: 2450 | I38: 2432 | J38: 2437 | K38: 2438 | L38: =F38 -> 2436 | M38: 2443 | N38: 2451 | O38: 2453 | P38: =G38 -> 2450 | Q38: 2462 | R38: 2477 | S38: 2479 | U38: =L38 -> 2436 | V38: =M38 -> 2443 | W38: =N38 -> 2451 | X38: =O38 -> 2453 | Y38: =P38 -> 2450 | Z38: =Q38 -> 2462 | AA38: =R38 -> 2477 | AB38: =S38 -> 2479 | AD38: =SUM(AB38/X38)-1 -> 0.010599266
B39: Basic EPS | C39: =C36/C38 -> 2.0350584 | D39: =D36/D38 -> 1.7108844 | E39: =E36/E38 -> -3.7994845 | F39: =F36/F38 -> -1.2832512 | G39: =G36/G38 -> -4.6167347 | I39: =I36/I38 -> -0.43955592 | J39: =J36/J38 -> -0.50882232 | K39: =K36/K38 -> -0.17104184 | L39: =L36/L38 -> -0.16420361 | M39: =M36/M38 -> -0.39541547 | N39: =N36/N38 -> -4.0742554 | O39: =O36/O38 -> 0.055034651 | P39: =P36/P38 -> -0.20163265 | ... S39: =S36/S38 -> -0.059701493 | U39: =U36/U38 -> -0.6091954 | V39: =V36/V38 -> -0.71387638 | W39: =W36/W38 -> -0.76662587 | X39: =X36/X38 -> -0.6526702 | Y39: =Y36/Y38 -> -0.79183673 | Z39: =Z36/Z38 -> -0.71689683 | AA39: =AA36/AA38 -> -1.0629794 | AB39: =AB36/AB38 -> -1.2896329 | AD39: =SUM(AB39/X39)-1 -> 0.97593351
B41: Fully Diluted Shares | C41: 672 | D41: 664 | E41: 1940 | F41: 2436 | G41: 2450 | I41: 2432 | J41: 2437 | K41: 2438 | L41: =F41 -> 2436 | M41: 2443 | N41: 2451 | O41: 2470 | P41: =G41 -> 2450 | Q41: 2462 | R41: 2499 | S41: 2479 | U41: =L41 -> 2436 | V41: =M41 -> 2443 | W41: =N41 -> 2451 | X41: =O41 -> 2470 | Y41: =P41 -> 2450 | Z41: =Q41 -> 2462 | AA41: =R41 -> 2499 | AB41: =S41 -> 2479 | AD41: =SUM(AB41/X41)-1 -> 0.0036437247
B42: Diluted EPS | C42: =C36/C41 -> 1.8139881 | D42: =D36/D41 -> 1.5150602 | E42: =E36/E41 -> -3.7994845 | F42: =F36/F41 -> -1.2832512 | G42: =G36/G41 -> -4.6167347 | I42: =I36/I41 -> -0.43955592 | J42: =J36/J41 -> -0.50882232 | K42: =K36/K41 -> -0.17104184 | L42: =L36/L41 -> -0.16420361 | M42: =M36/M41 -> -0.39541547 | N42: =N36/N41 -> -4.0742554 | O42: =O36/O41 -> 0.05465587 | P42: =P36/P41 -> -0.20163265 | ... S42: =S36/S41 -> -0.059701493 | U42: =U36/U41 -> -0.6091954 | V42: =V36/V41 -> -0.71387638 | W42: =W36/W41 -> -0.76662587 | X42: =X36/X41 -> -0.64817814 | Y42: =Y36/Y41 -> -0.79183673 | Z42: =Z36/Z41 -> -0.71689683 | AA42: =AA36/AA41 -> -1.0536214 | AB42: =AB36/AB41 -> -1.2896329 | AD42: =SUM(AB42/X42)-1 -> 0.9896273
A44: X | B44: Balance Sheet | C44: FYE | D44: FYE | O44: Quarterly | X44: LTM | AD44: Variance
B45: =B7 -> Fiscal Period | C45: =C7 -> 2020 | D45: =D7 -> 2021 | E45: =E7 -> 2022 | F45: =F7 -> 2023 | G45: =G7 -> 2024 | I45: =I7 -> 1Q23 | J45: =J7 -> 2Q23 | K45: =K7 -> 3Q23 | L45: =L7 -> 4Q23 | M45: =M7 -> 1Q24 | N45: =N7 -> 2Q24 | O45: =O7 -> 3Q24 | P45: =P7 -> 4Q24 | ... S45: =S7 -> 3Q25 | U45: =U7 -> 4Q23 | V45: =V7 -> 1Q24 | W45: =W7 -> 2Q24 | X45: =X7 -> 3Q24 | Y45: =Y7 -> 4Q24 | Z45: =Z7 -> 1Q25 | AA45: =AA7 -> 2Q25 | AB45: =AB7 -> 3Q25
B46: =B8 -> Fiscal Period End Date | C46: =C8 -> 44196 | D46: =D8 -> 44561 | E46: =E8 -> 44926 | F46: =F8 -> 45291 | G46: =G8 -> 45657 | I46: =I8 -> 45016 | J46: =J8 -> 45107 | K46: =K8 -> 45199 | L46: =L8 -> 44926 | M46: =M8 -> 45382 | N46: =N8 -> 45473 | O46: =O8 -> 45565 | P46: =P8 -> 45291 | ... S46: =S8 -> 45930 | U46: =U8 -> 44926 | V46: =V8 -> 45382 | W46: =W8 -> 45473 | X46: =X8 -> 45565 | Y46: =Y8 -> 45291 | Z46: =Z8 -> 45747 | AA46: =AA8 -> 45838 | AB46: =AB8 -> 45930
B48: Current Assets
B49: Cash and cash equivalents | C49: 2091 | D49: 3905 | E49: 3731 | F49: 3780 | G49: 5312 | I49: 2594 | J49: 3027 | K49: 2383 | L49: =F49 -> 3780 | M49: 2976 | N49: 3613 | O49: 3336 | P49: =G49 -> 5312 | Q49: 3868 | R49: 4888 | S49: 4294 | U49: =L49 -> 3780 | V49: =M49 -> 2976 | W49: =N49 -> 3613 | X49: =O49 -> 3336 | Y49: =P49 -> 5312 | Z49: =Q49 -> 3868 | AA49: =R49 -> 4888 | AB49: =S49 -> 4294 | AD49: =SUM(AB49/X49)-1 -> 0.28717026
B50: Receivables, net | C50: 2537 | D50: 2446 | E50: 6380 | F50: 6047 | G50: 4947 | I50: 6833 | J50: 6770 | K50: 6312 | L50: =F50 -> 6047 | M50: 6303 | N50: 6166 | O50: 5534 | P50: =G50 -> 4947 | Q50: 4664 | R50: 5383 | S50: 5128 | U50: =L50 -> 6047 | V50: =M50 -> 6303 | W50: =N50 -> 6166 | X50: =O50 -> 5534 | Y50: =P50 -> 4947 | Z50: =Q50 -> 4664 | AA50: =R50 -> 5383 | AB50: =S50 -> 5128 | AD50: =SUM(AB50/X50)-1 -> -0.073364655
B51: Prepaid expenses and other current assets | C51: =970+532 -> 1502 | D51: 913 | E51: 3888 | F51: 4391 | G51: 3819 | I51: 4300 | J51: 3976 | K51: 4136 | L51: =F51 -> 4391 | M51: 4623 | N51: 3651 | O51: 3635 | P51: =G51 -> 3819 | Q51: 4250 | R51: 3340 | S51: 3640 | U51: =L51 -> 4391 | V51: =M51 -> 4623 | W51: =N51 -> 3651 | X51: =O51 -> 3635 | Y51: =P51 -> 3819 | Z51: =Q51 -> 4250 | AA51: =R51 -> 3340 | AB51: =S51 -> 3640 | AD51: =SUM(AB51/X51)-1 -> 0.0013755158
B52: Total Current Assets | C52: =SUM(C49:C51) -> 6130 | D52: =SUM(D49:D51) -> 7264 | E52: =SUM(E49:E51) -> 13999 | F52: =SUM(F49:F51) -> 14218 | G52: =SUM(G49:G51) -> 14078 | I52: =SUM(I49:I51) -> 13727 | J52: =SUM(J49:J51) -> 13773 | K52: =SUM(K49:K51) -> 12831 | L52: =SUM(L49:L51) -> 14218 | M52: =SUM(M49:M51) -> 13902 | N52: =SUM(N49:N51) -> 13430 | O52: =SUM(O49:O51) -> 12505 | P52: =SUM(P49:P51) -> 14078 | ... S52: =SUM(S49:S51) -> 13062 | U52: =SUM(U49:U51) -> 14218 | V52: =SUM(V49:V51) -> 13902 | W52: =SUM(W49:W51) -> 13430 | X52: =SUM(X49:X51) -> 12505 | Y52: =SUM(Y49:Y51) -> 14078 | Z52: =SUM(Z49:Z51) -> 12782 | AA52: =SUM(AA49:AA51) -> 13611 | AB52: =SUM(AB49:AB51) -> 13062 | AD52: =SUM(AB52/X52)-1 -> 0.044542183
...

Sheet Revenue Segment Analysis
B2: ='Historical Financials'!B2 -> Warner Bros Discovery Inc (NASDAQ: WBD) | C2: FYE | D2: FYE | O2: Quarterly | X2: LTM
B3: Segment Anaysis | C3: ='Historical Financials'!C7 -> 2020 | D3: ='Historical Financials'!D7 -> 2021 | E3: ='Historical Financials'!E7 -> 2022 | F3: ='Historical Financials'!F7 -> 2023 | G3: ='Historical Financials'!G7 -> 2024 | I3: ='Historical Financials'!I7 -> 1Q23 | J3: ='Historical Financials'!J7 -> 2Q23 | K3: ='Historical Financials'!K7 -> 3Q23 | L3: ='Historical Financials'!L7 -> 4Q23 | M3: ='Historical Financials'!M7 -> 1Q24 | N3: ='Historical Financials'!N7 -> 2Q24 | O3: ='Historical Financials'!O7 -> 3Q24 | P3: ='Historical Financials'!P7 -> 4Q24 | ... S3: ='Historical Financials'!S7 -> 3Q25 | U3: =L3 -> 4Q23 | V3: =M3 -> 1Q24 | W3: =N3 -> 2Q24 | X3: =O3 -> 3Q24 | Y3: =P3 -> 4Q24 | Z3: =Q3 -> 1Q25 | AA3: =R3 -> 2Q25 | AB3: =S3 -> 3Q25
B4: ($ In Millions) | C4: ='Historical Financials'!C8 -> 44196 | D4: ='Historical Financials'!D8 -> 44561 | E4: ='Historical Financials'!E8 -> 44926 | F4: ='Historical Financials'!F8 -> 45291 | G4: ='Historical Financials'!G8 -> 45657 | I4: ='Historical Financials'!I8 -> 45016 | J4: ='Historical Financials'!J8 -> 45107 | K4: ='Historical Financials'!K8 -> 45199 | L4: ='Historical Financials'!L8 -> 44926 | M4: ='Historical Financials'!M8 -> 45382 | N4: ='Historical Financials'!N8 -> 45473 | O4: ='Historical Financials'!O8 -> 45565 | P4: ='Historical Financials'!P8 -> 45291 | ... S4: ='Historical Financials'!S8 -> 45930 | U4: =L4 -> 44926 | V4: =M4 -> 45382 | W4: =N4 -> 45473 | X4: =O4 -> 45565 | Y4: =P4 -> 45291 | Z4: =Q4 -> 45747 | AA4: =R4 -> 45838 | AB4: =S4 -> 45930
A6: X | B6: Revenue by reportable segment
A8: X | B8: Revenue by Type
B9: Distribution | C9: 5572 | D9: 5202 | E9: 16142 | F9: 20237 | G9: 19701 | I9: 5163 | J9: 5135 | K9: 5026 | L9: =SUM(F9-SUM(I9:K9)) -> 4913 | M9: 4985 | N9: 4879 | O9: 4920 | P9: =SUM(G9-SUM(M9:O9)) -> 4917 | Q9: 4886 | R9: 4885 | S9: 4702 | U9: =SUM(I9:L9) -> 20237 | V9: =SUM(J9:M9) -> 20059 | W9: =SUM(K9:N9) -> 19803 | X9: =SUM(L9:O9) -> 19697 | Y9: =SUM(M9:P9) -> 19701 | Z9: =SUM(N9:Q9) -> 19602 | AA9: =SUM(O9:R9) -> 19608 | AB9: =SUM(P9:S9) -> 19390
B10: Advertising | C10: 4686 | D10: 6194 | E10: 8524 | F10: 8700 | G10: 8090 | I10: 2298 | J10: 2519 | K10: 1796 | L10: =SUM(F10-SUM(I10:K10)) -> 2087 | M10: 2148 | N10: 2430 | O10: 1682 | P10: =SUM(G10-SUM(M10:O10)) -> 1830 | Q10: 1980 | R10: 2216 | S10: 1407 | U10: =SUM(I10:L10) -> 8700 | V10: =SUM(J10:M10) -> 8550 | W10: =SUM(K10:N10) -> 8461 | X10: =SUM(L10:O10) -> 8347 | Y10: =SUM(M10:P10) -> 8090 | Z10: =SUM(N10:Q10) -> 7922 | AA10: =SUM(O10:R10) -> 7708 | AB10: =SUM(P10:S10) -> 7433
B11: Content | C11: 355 | D11: 737 | E11: 8360 | F11: 11203 | G11: 10297 | I11: 2954 | J11: 2446 | K11: 2840 | L11: =SUM(F11-SUM(I11:K11)) -> 2963 | M11: 2558 | N11: 2109 | O11: 2721 | P11: =SUM(G11-SUM(M11:O11)) -> 2909 | Q11: 1866 | R11: 2471 | S11: 2649 | U11: =SUM(I11:L11) -> 11203 | V11: =SUM(J11:M11) -> 10807 | W11: =SUM(K11:N11) -> 10470 | X11: =SUM(L11:O11) -> 10351 | Y11: =SUM(M11:P11) -> 10297 | Z11: =SUM(N11:Q11) -> 9605 | AA11: =SUM(O11:R11) -> 9967 | AB11: =SUM(P11:S11) -> 9895
B12: Other | C12: 58 | D12: 58 | E12: 791 | F12: 1181 | G12: 1233 | I12: 285 | J12: 258 | K12: 317 | L12: =SUM(F12-SUM(I12:K12)) -> 321 | M12: 267 | N12: 295 | O12: 300 | P12: =SUM(G12-SUM(M12:O12)) -> 371 | Q12: 247 | R12: 240 | S12: 287 | U12: =SUM(I12:L12) -> 1181 | V12: =SUM(J12:M12) -> 1163 | W12: =SUM(K12:N12) -> 1200 | X12: =SUM(L12:O12) -> 1183 | Y12: =SUM(M12:P12) -> 1233 | Z12: =SUM(N12:Q12) -> 1213 | AA12: =SUM(O12:R12) -> 1158 | AB12: =SUM(P12:S12) -> 1145
B13: Total Net Revenue | C13: =SUM(C9:C12) -> 10671 | D13: =SUM(D9:D12) -> 12191 | E13: =SUM(E9:E12) -> 33817 | F13: =SUM(F9:F12) -> 41321 | G13: =SUM(G9:G12) -> 39321 | I13: =SUM(I9:I12) -> 10700 | J13: =SUM(J9:J12) -> 10358 | K13: =SUM(K9:K12) -> 9979 | L13: =SUM(L9:L12) -> 10284 | M13: =SUM(M9:M12) -> 9958 | N13: =SUM(N9:N12) -> 9713 | O13: =SUM(O9:O12) -> 9623 | P13: =SUM(P9:P12) -> 10027 | ... S13: =SUM(S9:S12) -> 9045 | U13: =SUM(U9:U12) -> 41321 | V13: =SUM(V9:V12) -> 40579 | W13: =SUM(W9:W12) -> 39934 | X13: =SUM(X9:X12) -> 39578 | Y13: =SUM(Y9:Y12) -> 39321 | Z13: =SUM(Z9:Z12) -> 38342 | AA13: =SUM(AA9:AA12) -> 38441 | AB13: =SUM(AB9:AB12) -> 37863
B14: Variance Check | C14: =+C13-'Historical Financials'!C11 -> 0 | D14: =+D13-'Historical Financials'!D11 -> 0 | E14: =+E13-'Historical Financials'!E11 -> 0 | F14: =+F13-'Historical Financials'!F11 -> 0 | G14: =+G13-'Historical Financials'!G11 -> 0 | I14: =+I13-'Historical Financials'!I11 -> 0 | J14: =+J13-'Historical Financials'!J11 -> 0 | K14: =+K13-'Historical Financials'!K11 -> 0 | L14: =+L13-'Historical Financials'!L11 -> 0 | M14: =+M13-'Historical Financials'!M11 -> 0 | N14: =+N13-'Historical Financials'!N11 -> 0 | O14: =+O13-'Historical Financials'!O11 -> 0 | P14: =+P13-'Historical Financials'!P11 -> 0 | ... S14: =+S13-'Historical Financials'!S11 -> 0 | U14: =+U13-'Historical Financials'!U11 -> 0 | V14: =+V13-'Historical Financials'!V11 -> 0 | W14: =+W13-'Historical Financials'!W11 -> 0 | X14: =+X13-'Historical Financials'!X11 -> 0 | Y14: =+Y13-'Historical Financials'!Y11 -> 0 | Z14: =+Z13-'Historical Financials'!Z11 -> 0 | AA14: =+AA13-'Historical Financials'!AA11 -> 0 | AB14: =+AB13-'Historical Financials'!AB11 -> 0
B16: =B9&"(%)" -> Distribution(%) | C16: =SUM(C9/C$13) -> 0.52216287 | D16: =SUM(D9/D$13) -> 0.42670823 | E16: =SUM(E9/E$13) -> 0.47733389 | F16: =SUM(F9/F$13) -> 0.48975097 | G16: =SUM(G9/G$13) -> 0.50102998 | I16: =SUM(I9/I$13) -> 0.48252336 | J16: =SUM(J9/J$13) -> 0.49575208 | K16: =SUM(K9/K$13) -> 0.50365768 | L16: =SUM(L9/L$13) -> 0.4777324 | M16: =SUM(M9/M$13) -> 0.50060253 | N16: =SUM(N9/N$13) -> 0.50231648 | O16: =SUM(O9/O$13) -> 0.51127507 | P16: =SUM(P9/P$13) -> 0.49037598 | ... S16: =SUM(S9/S$13) -> 0.51984522 | U16: =L16 -> 0.4777324 | V16: =M16 -> 0.50060253 | W16: =N16 -> 0.50231648 | X16: =O16 -> 0.51127507 | Y16: =P16 -> 0.49037598 | Z16: =Q16 -> 0.54415859 | AA16: =R16 -> 0.49785976 | AB16: =S16 -> 0.51984522
B17: =B10&"(%)" -> Advertising(%) | C17: =SUM(C10/C$13) -> 0.4391341 | D17: =SUM(D10/D$13) -> 0.50807973 | E17: =SUM(E10/E$13) -> 0.25206257 | F17: =SUM(F10/F$13) -> 0.2105467 | G17: =SUM(G10/G$13) -> 0.20574248 | I17: =SUM(I10/I$13) -> 0.21476636 | J17: =SUM(J10/J$13) -> 0.24319367 | K17: =SUM(K10/K$13) -> 0.17997795 | L17: =SUM(L10/L$13) -> 0.2029366 | M17: =SUM(M10/M$13) -> 0.21570597 | N17: =SUM(N10/N$13) -> 0.25018017 | O17: =SUM(O10/O$13) -> 0.17478957 | P17: =SUM(P10/P$13) -> 0.18250723 | ... S17: =SUM(S10/S$13) -> 0.15555556 | U17: =L17 -> 0.2029366 | V17: =M17 -> 0.21570597 | W17: =N17 -> 0.25018017 | X17: =O17 -> 0.17478957 | Y17: =P17 -> 0.18250723 | Z17: =Q17 -> 0.22051453 | AA17: =R17 -> 0.2258459 | AB17: =S17 -> 0.15555556
B18: =B11&"(%)" -> Content(%) | C18: =SUM(C11/C$13) -> 0.033267735 | D18: =SUM(D11/D$13) -> 0.060454434 | E18: =SUM(E11/E$13) -> 0.24721294 | F18: =SUM(F11/F$13) -> 0.27112122 | G18: =SUM(G11/G$13) -> 0.26187025 | I18: =SUM(I11/I$13) -> 0.27607477 | J18: =SUM(J11/J$13) -> 0.23614597 | K18: =SUM(K11/K$13) -> 0.28459766 | L18: =SUM(L11/L$13) -> 0.28811746 | M18: =SUM(M11/M$13) -> 0.25687889 | N18: =SUM(N11/N$13) -> 0.21713168 | O18: =SUM(O11/O$13) -> 0.28276005 | P18: =SUM(P11/P$13) -> 0.29011668 | ... S18: =SUM(S11/S$13) -> 0.29286899 | U18: =L18 -> 0.28811746 | V18: =M18 -> 0.25687889 | W18: =N18 -> 0.21713168 | X18: =O18 -> 0.28276005 | Y18: =P18 -> 0.29011668 | Z18: =Q18 -> 0.20781824 | AA18: =R18 -> 0.25183449 | AB18: =S18 -> 0.29286899
B19: =B12&"(%)" -> Other(%) | C19: =SUM(C12/C$13) -> 0.0054352919 | D19: =SUM(D12/D$13) -> 0.0047576081 | E19: =SUM(E12/E$13) -> 0.023390602 | F19: =SUM(F12/F$13) -> 0.028581109 | G19: =SUM(G12/G$13) -> 0.03135729 | I19: =SUM(I12/I$13) -> 0.026635514 | J19: =SUM(J12/J$13) -> 0.024908283 | K19: =SUM(K12/K$13) -> 0.03176671 | L19: =SUM(L12/L$13) -> 0.031213536 | M19: =SUM(M12/M$13) -> 0.026812613 | N19: =SUM(N12/N$13) -> 0.030371667 | O19: =SUM(O12/O$13) -> 0.031175309 | P19: =SUM(P12/P$13) -> 0.0370001 | ... S19: =SUM(S12/S$13) -> 0.031730238 | U19: =L19 -> 0.031213536 | V19: =M19 -> 0.026812613 | W19: =N19 -> 0.030371667 | X19: =O19 -> 0.031175309 | Y19: =P19 -> 0.0370001 | Z19: =Q19 -> 0.027508631 | AA19: =R19 -> 0.024459845 | AB19: =S19 -> 0.031730238
A22: X | B22: Revenue By End Market Channel
A24: X | B24: Revenue by End Market Channel
B25: Studios | C25: =C43 -> 12 | D25: =D43 -> 20 | E25: =E43 -> 9731 | F25: =F43 -> 12192 | G25: =G43 -> 11607 | I25: =I43 -> 3212 | J25: =J43 -> 2581 | K25: =K43 -> 3226 | L25: =SUM(F25-SUM(I25:K25)) -> 3173 | M25: =M43 -> 2821 | N25: =N43 -> 2449 | O25: =O43 -> 2680 | P25: =SUM(G25-SUM(M25:O25)) -> 3657 | Q25: =Q43 -> 2314 | R25: =R43 -> 3801 | S25: =S43 -> 3321 | U25: =SUM(I25:L25) -> 12192 | V25: =SUM(J25:M25) -> 11801 | W25: =SUM(K25:N25) -> 11669 | X25: =SUM(L25:O25) -> 11123 | Y25: =SUM(M25:P25) -> 11607 | Z25: =SUM(N25:Q25) -> 11100 | AA25: =SUM(O25:R25) -> 12452 | AB25: =SUM(P25:S25) -> 13093
B26: Networks | C26: =C85 -> 10439 | D26: =D85 -> 11311 | E26: =E85 -> 19348 | F26: =F85 -> 21244 | G26: =G85 -> 20175 | I26: =I85 -> 5581 | J26: =J85 -> 5758 | K26: =K85 -> 4868 | L26: =SUM(F26-SUM(I26:K26)) -> 5037 | M26: =M85 -> 5125 | N26: =N85 -> 5272 | O26: =O85 -> 5010 | P26: =SUM(G26-SUM(M26:O26)) -> 4768 | Q26: =Q85 -> 4774 | R26: =R85 -> 4803 | S26: =S85 -> 3883 | U26: =SUM(I26:L26) -> 21244 | V26: =SUM(J26:M26) -> 20788 | W26: =SUM(K26:N26) -> 20302 | X26: =SUM(L26:O26) -> 20444 | Y26: =SUM(M26:P26) -> 20175 | Z26: =SUM(N26:Q26) -> 19824 | AA26: =SUM(O26:R26) -> 19355 | AB26: =SUM(P26:S26) -> 18228
B27: Streaming | C27: =C124 -> 220 | D27: =D124 -> 860 | E27: =E124 -> 7274 | F27: =F124 -> 10154 | G27: =G124 -> 10313 | I27: =I124 -> 2455 | J27: =J124 -> 2732 | K27: =K124 -> 2438 | L27: =SUM(F27-SUM(I27:K27)) -> 2529 | M27: =M124 -> 2460 | N27: =N124 -> 2568 | O27: =O124 -> 2634 | P27: =SUM(G27-SUM(M27:O27)) -> 2651 | Q27: =Q124 -> 2656 | R27: =R124 -> 2793 | S27: =S124 -> 2633 | U27: =SUM(I27:L27) -> 10154 | V27: =SUM(J27:M27) -> 10159 | W27: =SUM(K27:N27) -> 9995 | X27: =SUM(L27:O27) -> 10191 | Y27: =SUM(M27:P27) -> 10313 | Z27: =SUM(N27:Q27) -> 10509 | AA27: =SUM(O27:R27) -> 10734 | AB27: =SUM(P27:S27) -> 10733
B28: Corporate and Inter-segment eliminations | C28: 0 | D28: 0 | E28: -2536 | F28: -2269 | G28: -2774 | I28: -548 | J28: -713 | K28: -553 | L28: =SUM(F28-SUM(I28:K28)) -> -455 | M28: -448 | N28: -576 | O28: -701 | P28: =SUM(G28-SUM(M28:O28)) -> -1049 | Q28: -765 | R28: -1585 | S28: -792 | U28: =SUM(I28:L28) -> -2269 | V28: =SUM(J28:M28) -> -2169 | W28: =SUM(K28:N28) -> -2032 | X28: =SUM(L28:O28) -> -2180 | Y28: =SUM(M28:P28) -> -2774 | Z28: =SUM(N28:Q28) -> -3091 | AA28: =SUM(O28:R28) -> -4100 | AB28: =SUM(P28:S28) -> -4191
B29: Total Net Revenue | C29: =SUM(C25:C28) -> 10671 | D29: =SUM(D25:D28) -> 12191 | E29: =SUM(E25:E28) -> 33817 | F29: =SUM(F25:F28) -> 41321 | G29: =SUM(G25:G28) -> 39321 | I29: =SUM(I25:I28) -> 10700 | J29: =SUM(J25:J28) -> 10358 | K29: =SUM(K25:K28) -> 9979 | L29: =SUM(L25:L28) -> 10284 | M29: =SUM(M25:M28) -> 9958 | N29: =SUM(N25:N28) -> 9713 | O29: =SUM(O25:O28) -> 9623 | P29: =SUM(P25:P28) -> 10027 | ... S29: =SUM(S25:S28) -> 9045 | U29: =SUM(U25:U28) -> 41321 | V29: =SUM(V25:V28) -> 40579 | W29: =SUM(W25:W28) -> 39934 | X29: =SUM(X25:X28) -> 39578 | Y29: =SUM(Y25:Y28) -> 39321 | Z29: =SUM(Z25:Z28) -> 38342 | AA29: =SUM(AA25:AA28) -> 38441 | AB29: =SUM(AB25:AB28) -> 37863
B30: Variance Check | C30: =+C29-C13 -> 0 | D30: =+D29-D13 -> 0 | E30: =+E29-E13 -> 0 | F30: =+F29-F13 -> 0 | G30: =+G29-G13 -> 0 | I30: =+I29-I13 -> 0 | J30: =+J29-J13 -> 0 | K30: =+K29-K13 -> 0 | L30: =+L29-L13 -> 0 | M30: =+M29-M13 -> 0 | N30: =+N29-N13 -> 0 | O30: =+O29-O13 -> 0 | P30: =+P29-P13 -> 0 | ... S30: =+S29-S13 -> 0 | U30: =+U29-U13 -> 0 | V30: =+V29-V13 -> 0 | W30: =+W29-W13 -> 0 | X30: =+X29-X13 -> 0 | Y30: =+Y29-Y13 -> 0 | Z30: =+Z29-Z13 -> 0 | AA30: =+AA29-AA13 -> 0 | AB30: =+AB29-AB13 -> 0
B32: =B25&"(%)" -> Studios(%) | C32: =SUM(C25/C$29) -> 0.0011245432 | D32: =SUM(D25/D$29) -> 0.0016405545 | E32: =SUM(E25/E$13) -> 0.28775468 | F32: =SUM(F25/F$13) -> 0.29505578 | G32: =SUM(G25/G$13) -> 0.29518578 | I32: =SUM(I25/I$13) -> 0.30018692 | J32: =SUM(J25/J$13) -> 0.24917938 | K32: =SUM(K25/K$13) -> 0.32327889 | L32: =SUM(L25/L$13) -> 0.30853753 | M32: =SUM(M25/M$13) -> 0.28328982 | N32: =SUM(N25/N$13) -> 0.25213631 | O32: =SUM(O25/O$13) -> 0.27849943 | P32: =SUM(P25/P$13) -> 0.36471527 | ... S32: =SUM(S25/S$13) -> 0.36716418 | U32: =L32 -> 0.30853753 | V32: =M32 -> 0.28328982 | W32: =N32 -> 0.25213631 | X32: =O32 -> 0.27849943 | Y32: =P32 -> 0.36471527 | Z32: =Q32 -> 0.25771244 | AA32: =R32 -> 0.3873828 | AB32: =S32 -> 0.36716418
B33: =B26&"(%)" -> Networks(%) | C33: =SUM(C26/C$29) -> 0.97825883 | D33: =SUM(D26/D$29) -> 0.9278156 | E33: =SUM(E26/E$13) -> 0.57213827 | F33: =SUM(F26/F$13) -> 0.51412115 | G33: =SUM(G26/G$13) -> 0.51308461 | I33: =SUM(I26/I$13) -> 0.52158879 | J33: =SUM(J26/J$13) -> 0.55589882 | K33: =SUM(K26/K$13) -> 0.48782443 | L33: =SUM(L26/L$13) -> 0.48978996 | M33: =SUM(M26/M$13) -> 0.51466158 | N33: =SUM(N26/N$13) -> 0.54277772 | O33: =SUM(O26/O$13) -> 0.52062766 | P33: =SUM(P26/P$13) -> 0.47551611 | ... S33: =SUM(S26/S$13) -> 0.42929795 | U33: =L33 -> 0.48978996 | V33: =M33 -> 0.51466158 | W33: =N33 -> 0.54277772 | X33: =O33 -> 0.52062766 | Y33: =P33 -> 0.47551611 | Z33: =Q33 -> 0.53168504 | AA33: =R33 -> 0.48950265 | AB33: =S33 -> 0.42929795
B34: =B27&"(%)" -> Streaming(%) | C34: =SUM(C27/C$29) -> 0.020616624 | D34: =SUM(D27/D$29) -> 0.070543844 | E34: =SUM(E27/E$13) -> 0.21509891 | F34: =SUM(F27/F$13) -> 0.24573461 | G34: =SUM(G27/G$13) -> 0.26227715 | I34: =SUM(I27/I$13) -> 0.22943925 | J34: =SUM(J27/J$13) -> 0.26375748 | K34: =SUM(K27/K$13) -> 0.24431306 | L34: =SUM(L27/L$13) -> 0.24591599 | M34: =SUM(M27/M$13) -> 0.24703756 | N34: =SUM(N27/N$13) -> 0.26438793 | O34: =SUM(O27/O$13) -> 0.27371921 | P34: =SUM(P27/P$13) -> 0.26438616 | ... S34: =SUM(S27/S$13) -> 0.29110006 | U34: =L34 -> 0.24591599 | V34: =M34 -> 0.24703756 | W34: =N34 -> 0.26438793 | X34: =O34 -> 0.27371921 | Y34: =P34 -> 0.26438616 | Z34: =Q34 -> 0.29580131 | AA34: =R34 -> 0.28465145 | AB34: =S34 -> 0.29110006
A36: X | B36: Studios Segment Analysis
A38: X | B38: Revenue by Type: Studios Segment
B39: Distribution | C39: 0 | D39: 0 | E39: 12 | F39: 17 | G39: 8 | I39: 3 | J39: 3 | K39: 13 | L39: =SUM(F39-SUM(I39:K39)) -> -2 | M39: 5 | N39: 3 | O39: 6 | P39: =SUM(G39-SUM(M39:O39)) -> -6 | Q39: 1 | R39: 1 | S39: 2 | U39: =SUM(I39:L39) -> 17 | V39: =SUM(J39:M39) -> 19 | W39: =SUM(K39:N39) -> 19 | X39: =SUM(L39:O39) -> 12 | Y39: =SUM(M39:P39) -> 8 | Z39: =SUM(N39:Q39) -> 4 | AA39: =SUM(O39:R39) -> 2 | AB39: =SUM(P39:S39) -> -2
B40: Advertising | C40: 0 | D40: 0 | E40: 15 | F40: 15 | G40: 5 | I40: 3 | J40: 4 | K40: 4 | L40: =SUM(F40-SUM(I40:K40)) -> 4 | M40: 4 | N40: 0 | O40: 1 | P40: =SUM(G40-SUM(M40:O40)) -> 0 | Q40: 1 | R40: 0 | S40: 0 | U40: =SUM(I40:L40) -> 15 | V40: =SUM(J40:M40) -> 16 | W40: =SUM(K40:N40) -> 12 | X40: =SUM(L40:O40) -> 9 | Y40: =SUM(M40:P40) -> 5 | Z40: =SUM(N40:Q40) -> 2 | AA40: =SUM(O40:R40) -> 2 | AB40: =SUM(P40:S40) -> 1
B41: Content | C41: 12 | D41: 20 | E41: 9156 | F41: 11358 | G41: 10717 | I41: 3027 | J41: 2398 | K41: 3000 | L41: =SUM(F41-SUM(I41:K41)) -> 2933 | M41: 2623 | N41: 2237 | O41: 2463 | P41: =SUM(G41-SUM(M41:O41)) -> 3394 | Q41: 2139 | R41: 3591 | S41: 3111 | U41: =SUM(I41:L41) -> 11358 | V41: =SUM(J41:M41) -> 10954 | W41: =SUM(K41:N41) -> 10793 | X41: =SUM(L41:O41) -> 10256 | Y41: =SUM(M41:P41) -> 10717 | Z41: =SUM(N41:Q41) -> 10233 | AA41: =SUM(O41:R41) -> 11587 | AB41: =SUM(P41:S41) -> 12235
B42: Other | C42: 0 | D42: 0 | E42: 548 | F42: 802 | G42: 877 | I42: 179 | J42: 176 | K42: 209 | L42: =SUM(F42-SUM(I42:K42)) -> 238 | M42: 189 | N42: 209 | O42: 210 | P42: =SUM(G42-SUM(M42:O42)) -> 269 | Q42: 173 | R42: 209 | S42: 208 | U42: =SUM(I42:L42) -> 802 | V42: =SUM(J42:M42) -> 812 | W42: =SUM(K42:N42) -> 845 | X42: =SUM(L42:O42) -> 846 | Y42: =SUM(M42:P42) -> 877 | Z42: =SUM(N42:Q42) -> 861 | AA42: =SUM(O42:R42) -> 861 | AB42: =SUM(P42:S42) -> 859
B43: Total Net Revenue from Studios Segment | C43: =SUM(C39:C42) -> 12 | D43: =SUM(D39:D42) -> 20 | E43: =SUM(E39:E42) -> 9731 | F43: =SUM(F39:F42) -> 12192 | G43: =SUM(G39:G42) -> 11607 | I43: =SUM(I39:I42) -> 3212 | J43: =SUM(J39:J42) -> 2581 | K43: =SUM(K39:K42) -> 3226 | L43: =SUM(L39:L42) -> 3173 | M43: =SUM(M39:M42) -> 2821 | N43: =SUM(N39:N42) -> 2449 | O43: =SUM(O39:O42) -> 2680 | P43: =SUM(P39:P42) -> 3657 | ... S43: =SUM(S39:S42) -> 3321 | U43: =SUM(U39:U42) -> 12192 | V43: =SUM(V39:V42) -> 11801 | W43: =SUM(W39:W42) -> 11669 | X43: =SUM(X39:X42) -> 11123 | Y43: =SUM(Y39:Y42) -> 11607 | Z43: =SUM(Z39:Z42) -> 11100 | AA43: =SUM(AA39:AA42) -> 12452 | AB43: =SUM(AB39:AB42) -> 13093
B44: Variance Check | C44: =+C43-C25 -> 0 | D44: =+D43-D25 -> 0 | E44: =+E43-E25 -> 0 | F44: =+F43-F25 -> 0 | G44: =+G43-G25 -> 0 | I44: =+I43-I25 -> 0 | J44: =+J43-J25 -> 0 | K44: =+K43-K25 -> 0 | L44: =+L43-L25 -> 0 | M44: =+M43-M25 -> 0 | N44: =+N43-N25 -> 0 | O44: =+O43-O25 -> 0 | P44: =+P43-P25 -> 0 | ... S44: =+S43-S25 -> 0 | U44: =+U43-U25 -> 0 | V44: =+V43-V25 -> 0 | W44: =+W43-W25 -> 0 | X44: =+X43-X25 -> 0 | Y44: =+Y43-Y25 -> 0 | Z44: =+Z43-Z25 -> 0 | AA44: =+AA43-AA25 -> 0 | AB44: =+AB43-AB25 -> 0
B46: =B39&"(%)" -> Distribution(%) | C46: =SUM(C39/C$43) -> 0 | D46: =SUM(D39/D$43) -> 0 | E46: =SUM(E39/E$43) -> 0.0012331723 | F46: =SUM(F39/F$43) -> 0.001394357 | G46: =SUM(G39/G$43) -> 0.00068923925 | I46: =SUM(I39/I$43) -> 0.00093399751 | J46: =SUM(J39/J$43) -> 0.0011623402 | K46: =SUM(K39/K$43) -> 0.0040297582 | L46: =SUM(L39/L$43) -> -0.00063031831 | M46: =SUM(M39/M$43) -> 0.0017724211 | N46: =SUM(N39/N$43) -> 0.0012249898 | O46: =SUM(O39/O$43) -> 0.002238806 | P46: =SUM(P39/P$43) -> -0.0016406891 | ... S46: =SUM(S39/S$43) -> 0.00060222824 | U46: =SUM(U39/U$43) -> 0.001394357 | V46: =SUM(V39/V$43) -> 0.001610033 | W46: =SUM(W39/W$43) -> 0.0016282458 | X46: =SUM(X39/X$43) -> 0.0010788456 | Y46: =SUM(Y39/Y$43) -> 0.00068923925 | Z46: =SUM(Z39/Z$43) -> 0.00036036036 | AA46: =SUM(AA39/AA$43) -> 0.00016061677 | AB46: =SUM(AB39/AB$43) -> -0.00015275338
B47: =B40&"(%)" -> Advertising(%) | C47: =SUM(C40/C$43) -> 0 | D47: =SUM(D40/D$43) -> 0 | E47: =SUM(E40/E$43) -> 0.0015414654 | F47: =SUM(F40/F$43) -> 0.001230315 | G47: =SUM(G40/G$43) -> 0.00043077453 | I47: =SUM(I40/I$43) -> 0.00093399751 | J47: =SUM(J40/J$43) -> 0.0015497869 | K47: =SUM(K40/K$43) -> 0.0012399256 | L47: =SUM(L40/L$43) -> 0.0012606366 | M47: =SUM(M40/M$43) -> 0.0014179369 | N47: =SUM(N40/N$43) -> 0 | O47: =SUM(O40/O$43) -> 0.00037313433 | P47: =SUM(P40/P$43) -> 0 | ... S47: =SUM(S40/S$43) -> 0 | U47: =SUM(U40/U$43) -> 0.001230315 | V47: =SUM(V40/V$43) -> 0.0013558173 | W47: =SUM(W40/W$43) -> 0.0010283658 | X47: =SUM(X40/X$43) -> 0.00080913423 | Y47: =SUM(Y40/Y$43) -> 0.00043077453 | Z47: =SUM(Z40/Z$43) -> 0.00018018018 | AA47: =SUM(AA40/AA$43) -> 0.00016061677 | AB47: =SUM(AB40/AB$43) -> 7.637669e-05
B48: =B41&"(%)" -> Content(%) | C48: =SUM(C41/C$43) -> 1 | D48: =SUM(D41/D$43) -> 1 | E48: =SUM(E41/E$43) -> 0.94091049 | F48: =SUM(F41/F$43) -> 0.93159449 | G48: =SUM(G41/G$43) -> 0.92332213 | I48: =SUM(I41/I$43) -> 0.94240349 | J48: =SUM(J41/J$43) -> 0.92909725 | K48: =SUM(K41/K$43) -> 0.9299442 | L48: =SUM(L41/L$43) -> 0.9243618 | M48: =SUM(M41/M$43) -> 0.92981212 | N48: =SUM(N41/N$43) -> 0.91343405 | O48: =SUM(O41/O$43) -> 0.91902985 | P48: =SUM(P41/P$43) -> 0.92808313 | ... S48: =SUM(S41/S$43) -> 0.93676603 | U48: =SUM(U41/U$43) -> 0.93159449 | V48: =SUM(V41/V$43) -> 0.92822642 | W48: =SUM(W41/W$43) -> 0.9249293 | X48: =SUM(X41/X$43) -> 0.9220534 | Y48: =SUM(Y41/Y$43) -> 0.92332213 | Z48: =SUM(Z41/Z$43) -> 0.92189189 | AA48: =SUM(AA41/AA$43) -> 0.93053325 | AB48: =SUM(AB41/AB$43) -> 0.9344688
B49: =B42&"(%)" -> Other(%) | C49: =SUM(C42/C$43) -> 0 | D49: =SUM(D42/D$43) -> 0 | E49: =SUM(E42/E$43) -> 0.05631487 | F49: =SUM(F42/F$43) -> 0.06578084 | G49: =SUM(G42/G$43) -> 0.075557853 | I49: =SUM(I42/I$43) -> 0.055728518 | J49: =SUM(J42/J$43) -> 0.068190624 | K49: =SUM(K42/K$43) -> 0.064786113 | L49: =SUM(L42/L$43) -> 0.075007879 | M49: =SUM(M42/M$43) -> 0.066997519 | N49: =SUM(N42/N$43) -> 0.085340955 | O49: =SUM(O42/O$43) -> 0.078358209 | P49: =SUM(P42/P$43) -> 0.073557561 | ... S49: =SUM(S42/S$43) -> 0.062631737 | U49: =SUM(U42/U$43) -> 0.06578084 | V49: =SUM(V42/V$43) -> 0.068807728 | W49: =SUM(W42/W$43) -> 0.072414089 | X49: =SUM(X42/X$43) -> 0.076058617 | Y49: =SUM(Y42/Y$43) -> 0.075557853 | Z49: =SUM(Z42/Z$43) -> 0.077567568 | AA49: =SUM(AA42/AA$43) -> 0.069145519 | AB49: =SUM(AB42/AB$43) -> 0.065607577
A51: X | B51: Studios Segment: Operating Income & Adj. EBITDA Analysis
B52: =B39 -> Distribution | C52: =C39 -> 0 | D52: =D39 -> 0 | E52: =E39 -> 12 | F52: =F39 -> 17 | G52: =G39 -> 8 | I52: =I39 -> 3 | J52: =J39 -> 3 | K52: =K39 -> 13 | L52: =SUM(F52-SUM(I52:K52)) -> -2 | M52: =M39 -> 5 | N52: =N39 -> 3 | O52: =O39 -> 6 | P52: =SUM(G52-SUM(M52:O52)) -> -6 | Q52: =Q39 -> 1 | R52: =R39 -> 1 | S52: =S39 -> 2 | U52: =SUM(I52:L52) -> 17 | V52: =SUM(J52:M52) -> 19 | W52: =SUM(K52:N52) -> 19 | X52: =SUM(L52:O52) -> 12 | Y52: =SUM(M52:P52) -> 8 | Z52: =SUM(N52:Q52) -> 4 | AA52: =SUM(O52:R52) -> 2 | AB52: =SUM(P52:S52) -> -2
...

Sheet FCF
B2: ='Historical Financials'!B2 -> Warner Bros Discovery Inc (NASDAQ: WBD) | E2: FYE | I2: Quarterly | S2: Quarterly | W2: LTM | X2: LTM | AD2: Variance
B3: FCF Analysis | C3: ='Historical Financials'!C7 -> 2020 | D3: ='Historical Financials'!D7 -> 2021 | E3: ='Historical Financials'!E7 -> 2022 | F3: ='Historical Financials'!F7 -> 2023 | G3: ='Historical Financials'!G7 -> 2024 | I3: ='Historical Financials'!I7 -> 1Q23 | J3: ='Historical Financials'!J7 -> 2Q23 | K3: ='Historical Financials'!K7 -> 3Q23 | L3: ='Historical Financials'!L7 -> 4Q23 | M3: ='Historical Financials'!M7 -> 1Q24 | N3: ='Historical Financials'!N7 -> 2Q24 | O3: ='Historical Financials'!O7 -> 3Q24 | P3: ='Historical Financials'!P7 -> 4Q24 | ... S3: ='Historical Financials'!S7 -> 3Q25 | U3: =L3 -> 4Q23 | V3: =M3 -> 1Q24 | W3: =N3 -> 2Q24 | X3: =O3 -> 3Q24 | Y3: =P3 -> 4Q24 | Z3: =Q3 -> 1Q25 | AA3: =R3 -> 2Q25 | AB3: =S3 -> 3Q25
B4: ($ In Millions) | C4: ='Historical Financials'!C8 -> 44196 | D4: ='Historical Financials'!D8 -> 44561 | E4: ='Historical Financials'!E8 -> 44926 | F4: ='Historical Financials'!F8 -> 45291 | G4: ='Historical Financials'!G8 -> 45657 | I4: ='Historical Financials'!I8 -> 45016 | J4: ='Historical Financials'!J8 -> 45107 | K4: ='Historical Financials'!K8 -> 45199 | L4: ='Historical Financials'!L8 -> 44926 | M4: ='Historical Financials'!M8 -> 45382 | N4: ='Historical Financials'!N8 -> 45473 | O4: ='Historical Financials'!O8 -> 45565 | P4: ='Historical Financials'!P8 -> 45291 | ... S4: ='Historical Financials'!S8 -> 45930 | U4: =L4 -> 44926 | V4: =M4 -> 45382 | W4: =N4 -> 45473 | X4: =O4 -> 45565 | Y4: =P4 -> 45291 | Z4: =Q4 -> 45747 | AA4: =R4 -> 45838 | AB4: =S4 -> 45930
B6: ='Revenue Segment Analysis'!B9 -> Distribution | C6: ='Revenue Segment Analysis'!C9 -> 5572 | D6: ='Revenue Segment Analysis'!D9 -> 5202 | E6: ='Revenue Segment Analysis'!E9 -> 16142 | F6: ='Revenue Segment Analysis'!F9 -> 20237 | G6: ='Revenue Segment Analysis'!G9 -> 19701 | I6: ='Revenue Segment Analysis'!I9 -> 5163 | J6: ='Revenue Segment Analysis'!J9 -> 5135 | K6: ='Revenue Segment Analysis'!K9 -> 5026 | L6: ='Revenue Segment Analysis'!L9 -> 4913 | M6: ='Revenue Segment Analysis'!M9 -> 4985 | N6: ='Revenue Segment Analysis'!N9 -> 4879 | O6: ='Revenue Segment Analysis'!O9 -> 4920 | P6: ='Revenue Segment Analysis'!P9 -> 4917 | ... S6: ='Revenue Segment Analysis'!S9 -> 4702 | T6: =SUM(H6:K6) -> 15324 | U6: =SUM(I6:L6) -> 20237 | V6: =SUM(J6:M6) -> 20059 | W6: =SUM(K6:N6) -> 19803 | X6: =SUM(L6:O6) -> 19697 | Y6: =SUM(M6:P6) -> 19701 | Z6: =SUM(N6:Q6) -> 19602 | AA6: =SUM(O6:R6) -> 19608 | AB6: =SUM(P6:S6) -> 19390 | AD6: =SUM(AB6/X6)-1 -> -0.01558613
B7: ='Revenue Segment Analysis'!B10 -> Advertising | C7: ='Revenue Segment Analysis'!C10 -> 4686 | D7: ='Revenue Segment Analysis'!D10 -> 6194 | E7: ='Revenue Segment Analysis'!E10 -> 8524 | F7: ='Revenue Segment Analysis'!F10 -> 8700 | G7: ='Revenue Segment Analysis'!G10 -> 8090 | I7: ='Revenue Segment Analysis'!I10 -> 2298 | J7: ='Revenue Segment Analysis'!J10 -> 2519 | K7: ='Revenue Segment Analysis'!K10 -> 1796 | L7: ='Revenue Segment Analysis'!L10 -> 2087 | M7: ='Revenue Segment Analysis'!M10 -> 2148 | N7: ='Revenue Segment Analysis'!N10 -> 2430 | O7: ='Revenue Segment Analysis'!O10 -> 1682 | P7: ='Revenue Segment Analysis'!P10 -> 1830 | ... S7: ='Revenue Segment Analysis'!S10 -> 1407 | T7: =SUM(H7:K7) -> 6613 | U7: =SUM(I7:L7) -> 8700 | V7: =SUM(J7:M7) -> 8550 | W7: =SUM(K7:N7) -> 8461 | X7: =SUM(L7:O7) -> 8347 | Y7: =SUM(M7:P7) -> 8090 | Z7: =SUM(N7:Q7) -> 7922 | AA7: =SUM(O7:R7) -> 7708 | AB7: =SUM(P7:S7) -> 7433 | AD7: =SUM(AB7/X7)-1 -> -0.10950042
B8: ='Revenue Segment Analysis'!B11 -> Content | C8: ='Revenue Segment Analysis'!C11 -> 355 | D8: ='Revenue Segment Analysis'!D11 -> 737 | E8: ='Revenue Segment Analysis'!E11 -> 8360 | F8: ='Revenue Segment Analysis'!F11 -> 11203 | G8: ='Revenue Segment Analysis'!G11 -> 10297 | I8: ='Revenue Segment Analysis'!I11 -> 2954 | J8: ='Revenue Segment Analysis'!J11 -> 2446 | K8: ='Revenue Segment Analysis'!K11 -> 2840 | L8: ='Revenue Segment Analysis'!L11 -> 2963 | M8: ='Revenue Segment Analysis'!M11 -> 2558 | N8: ='Revenue Segment Analysis'!N11 -> 2109 | O8: ='Revenue Segment Analysis'!O11 -> 2721 | P8: ='Revenue Segment Analysis'!P11 -> 2909 | ... S8: ='Revenue Segment Analysis'!S11 -> 2649 | T8: =SUM(H8:K8) -> 8240 | U8: =SUM(I8:L8) -> 11203 | V8: =SUM(J8:M8) -> 10807 | W8: =SUM(K8:N8) -> 10470 | X8: =SUM(L8:O8) -> 10351 | Y8: =SUM(M8:P8) -> 10297 | Z8: =SUM(N8:Q8) -> 9605 | AA8: =SUM(O8:R8) -> 9967 | AB8: =SUM(P8:S8) -> 9895 | AD8: =SUM(AB8/X8)-1 -> -0.044053715
B9: ='Revenue Segment Analysis'!B12 -> Other | C9: ='Revenue Segment Analysis'!C12 -> 58 | D9: ='Revenue Segment Analysis'!D12 -> 58 | E9: ='Revenue Segment Analysis'!E12 -> 791 | F9: ='Revenue Segment Analysis'!F12 -> 1181 | G9: ='Revenue Segment Analysis'!G12 -> 1233 | I9: ='Revenue Segment Analysis'!I12 -> 285 | J9: ='Revenue Segment Analysis'!J12 -> 258 | K9: ='Revenue Segment Analysis'!K12 -> 317 | L9: ='Revenue Segment Analysis'!L12 -> 321 | M9: ='Revenue Segment Analysis'!M12 -> 267 | N9: ='Revenue Segment Analysis'!N12 -> 295 | O9: ='Revenue Segment Analysis'!O12 -> 300 | P9: ='Revenue Segment Analysis'!P12 -> 371 | ... S9: ='Revenue Segment Analysis'!S12 -> 287 | T9: =SUM(H9:K9) -> 860 | U9: =SUM(I9:L9) -> 1181 | V9: =SUM(J9:M9) -> 1163 | W9: =SUM(K9:N9) -> 1200 | X9: =SUM(L9:O9) -> 1183 | Y9: =SUM(M9:P9) -> 1233 | Z9: =SUM(N9:Q9) -> 1213 | AA9: =SUM(O9:R9) -> 1158 | AB9: =SUM(P9:S9) -> 1145 | AD9: =SUM(AB9/X9)-1 -> -0.032121724
B10: Total Revenue | C10: =SUM(C6:C9) -> 10671 | D10: =SUM(D6:D9) -> 12191 | E10: =SUM(E6:E9) -> 33817 | F10: =SUM(F6:F9) -> 41321 | G10: =SUM(G6:G9) -> 39321 | I10: =SUM(I6:I9) -> 10700 | J10: =SUM(J6:J9) -> 10358 | K10: =SUM(K6:K9) -> 9979 | L10: =SUM(L6:L9) -> 10284 | M10: =SUM(M6:M9) -> 9958 | N10: =SUM(N6:N9) -> 9713 | O10: =SUM(O6:O9) -> 9623 | P10: =SUM(P6:P9) -> 10027 | ... S10: =SUM(S6:S9) -> 9045 | U10: =SUM(U6:U9) -> 41321 | V10: =SUM(V6:V9) -> 40579 | W10: =SUM(W6:W9) -> 39934 | X10: =SUM(X6:X9) -> 39578 | Y10: =SUM(Y6:Y9) -> 39321 | Z10: =SUM(Z6:Z9) -> 38342 | AA10: =SUM(AA6:AA9) -> 38441 | AB10: =SUM(AB6:AB9) -> 37863 | AD10: =SUM(AB10/X10)-1 -> -0.043332154
B11: Y/Y Growth (%) | D11: =SUM(D10/C10)-1 -> 0.14244213 | E11: =SUM(E10/D10)-1 -> 1.7739316 | F11: =SUM(F10/E10)-1 -> 0.22190023 | G11: =SUM(G10/F10)-1 -> -0.048401539 | M11: =SUM(M10/I10)-1 -> -0.069345794 | N11: =SUM(N10/J10)-1 -> -0.062270709 | O11: =SUM(O10/K10)-1 -> -0.035674917 | P11: =SUM(P10/L10)-1 -> -0.024990276 | Q11: =SUM(Q10/M10)-1 -> -0.098312914 | R11: =SUM(R10/N10)-1 -> 0.010192525 | S11: =SUM(S10/O10)-1 -> -0.060064429 | Y11: =SUM(Y10/U10)-1 -> -0.048401539 | Z11: =SUM(Z10/V10)-1 -> -0.055127036 | AA11: =SUM(AA10/W10)-1 -> -0.037386688 | AB11: =SUM(AB10/X10)-1 -> -0.043332154 | AD11: =SUM(AB11-X11)*10000 -> -433.32154
B12: Q/Q Growth (%) | C12: N/A | D12: N/A | E12: N/A | F12: N/A | G12: N/A | J12: =SUM(J10/I10)-1 -> -0.031962617 | K12: =SUM(K10/J10)-1 -> -0.036590075 | L12: =SUM(L10/K10)-1 -> 0.030564185 | M12: =SUM(M10/L10)-1 -> -0.031699728 | N12: =SUM(N10/M10)-1 -> -0.024603334 | O12: =SUM(O10/N10)-1 -> -0.0092659323 | P12: =SUM(P10/O10)-1 -> 0.04198275 | Q12: =SUM(Q10/P10)-1 -> -0.1045178 | ... S12: =SUM(S10/R10)-1 -> -0.078169588 | U12: N/A | V12: N/A | W12: N/A | X12: N/A | Y12: N/A | Z12: N/A | AA12: N/A | AB12: N/A
B14: (-) Cost of Sales | C14: ='Historical Financials'!C13 -> -3860 | D14: ='Historical Financials'!D13 -> -4620 | E14: ='Historical Financials'!E13 -> -20442 | F14: ='Historical Financials'!F13 -> -24526 | G14: ='Historical Financials'!G13 -> -22970 | I14: ='Historical Financials'!I13 -> -6685 | J14: ='Historical Financials'!J13 -> -6636 | K14: ='Historical Financials'!K13 -> -5309 | L14: ='Historical Financials'!L13 -> -5896 | M14: ='Historical Financials'!M13 -> -6058 | N14: ='Historical Financials'!N13 -> -6204 | O14: ='Historical Financials'!O13 -> -5181 | P14: ='Historical Financials'!P13 -> -5527 | ... S14: ='Historical Financials'!S13 -> -4564 | T14: =SUM(H14:K14) -> -18630 | U14: =SUM(I14:L14) -> -24526 | V14: =SUM(J14:M14) -> -23899 | W14: =SUM(K14:N14) -> -23467 | X14: =SUM(L14:O14) -> -23339 | Y14: =SUM(M14:P14) -> -22970 | Z14: =SUM(N14:Q14) -> -22043 | AA14: =SUM(O14:R14) -> -21806 | AB14: =SUM(P14:S14) -> -21189 | AD14: =SUM(AB14/X14)-1 -> -0.092120485
B15: Gross Profit | C15: =SUM(C10+SUM(C14:C14)) -> 6811 | D15: =SUM(D10+SUM(D14:D14)) -> 7571 | E15: =SUM(E10+SUM(E14:E14)) -> 13375 | F15: =SUM(F10+SUM(F14:F14)) -> 16795 | G15: =SUM(G10+SUM(G14:G14)) -> 16351 | I15: =SUM(I10+SUM(I14:I14)) -> 4015 | J15: =SUM(J10+SUM(J14:J14)) -> 3722 | K15: =SUM(K10+SUM(K14:K14)) -> 4670 | L15: =SUM(L10+SUM(L14:L14)) -> 4388 | M15: =SUM(M10+SUM(M14:M14)) -> 3900 | N15: =SUM(N10+SUM(N14:N14)) -> 3509 | O15: =SUM(O10+SUM(O14:O14)) -> 4442 | P15: =SUM(P10+SUM(P14:P14)) -> 4500 | ... S15: =SUM(S10+SUM(S14:S14)) -> 4481 | U15: =SUM(U10+SUM(U14:U14)) -> 16795 | V15: =SUM(V10+SUM(V14:V14)) -> 16680 | W15: =SUM(W10+SUM(W14:W14)) -> 16467 | X15: =SUM(X10+SUM(X14:X14)) -> 16239 | Y15: =SUM(Y10+SUM(Y14:Y14)) -> 16351 | Z15: =SUM(Z10+SUM(Z14:Z14)) -> 16299 | AA15: =SUM(AA10+SUM(AA14:AA14)) -> 16635 | AB15: =SUM(AB10+SUM(AB14:AB14)) -> 16674 | AD15: =SUM(AB15/X15)-1 -> 0.026787364
B16: Gross Margin (%) | C16: =C15/C10 -> 0.63827195 | D16: =D15/D10 -> 0.62103191 | E16: =E15/E10 -> 0.39551113 | F16: =F15/F10 -> 0.40645193 | G16: =G15/G10 -> 0.41583378 | I16: =I15/I10 -> 0.37523364 | J16: =J15/J10 -> 0.35933578 | K16: =K15/K10 -> 0.46798276 | L16: =L15/L10 -> 0.42668222 | M16: =M15/M10 -> 0.39164491 | N16: =N15/N10 -> 0.3612684 | O16: =O15/O10 -> 0.46160241 | P16: =P15/P10 -> 0.44878827 | ... S16: =S15/S10 -> 0.49541183 | U16: =U15/U10 -> 0.40645193 | V16: =V15/V10 -> 0.41105005 | W16: =W15/W10 -> 0.41235539 | X16: =X15/X10 -> 0.4103037 | Y16: =Y15/Y10 -> 0.41583378 | Z16: =Z15/Z10 -> 0.4250952 | AA16: =AA15/AA10 -> 0.43274108 | AB16: =AB15/AB10 -> 0.44037715 | AD16: =SUM(AB16-X16)*10000 -> 300.73445
B18: (-) Selling, general and administrative | C18: ='Historical Financials'!C17 -> -2722 | D18: ='Historical Financials'!D17 -> -4016 | E18: ='Historical Financials'!E17 -> -9678 | F18: ='Historical Financials'!F17 -> -9696 | G18: ='Historical Financials'!G17 -> -9296 | I18: ='Historical Financials'!I17 -> -2388 | J18: ='Historical Financials'!J17 -> -2562 | K18: ='Historical Financials'!K17 -> -2291 | L18: ='Historical Financials'!L17 -> -2455 | M18: ='Historical Financials'!M17 -> -2232 | N18: ='Historical Financials'!N17 -> -2461 | O18: ='Historical Financials'!O17 -> -2385 | P18: ='Historical Financials'!P17 -> -2218 | ... S18: ='Historical Financials'!S17 -> -2361 | T18: =SUM(H18:K18) -> -7241 | U18: =SUM(I18:L18) -> -9696 | V18: =SUM(J18:M18) -> -9540 | W18: =SUM(K18:N18) -> -9439 | X18: =SUM(L18:O18) -> -9533 | Y18: =SUM(M18:P18) -> -9296 | Z18: =SUM(N18:Q18) -> -9258 | AA18: =SUM(O18:R18) -> -9274 | AB18: =SUM(P18:S18) -> -9250 | AD18: =SUM(AB18/X18)-1 -> -0.029686353
B19: (-) Depreciation and amortization | C19: ='Historical Financials'!C18 -> -1359 | D19: ='Historical Financials'!D18 -> -1582 | E19: ='Historical Financials'!E18 -> -7193 | F19: ='Historical Financials'!F18 -> -7985 | G19: ='Historical Financials'!G18 -> -7037 | I19: ='Historical Financials'!I18 -> -2058 | J19: ='Historical Financials'!J18 -> -1914 | K19: ='Historical Financials'!K18 -> -1989 | L19: ='Historical Financials'!L18 -> -2024 | M19: ='Historical Financials'!M18 -> -1888 | N19: ='Historical Financials'!N18 -> -1744 | O19: ='Historical Financials'!O18 -> -1762 | P19: ='Historical Financials'!P18 -> -1643 | ... S19: ='Historical Financials'!S18 -> -1375 | T19: =SUM(H19:K19) -> -5961 | U19: =SUM(I19:L19) -> -7985 | V19: =SUM(J19:M19) -> -7815 | W19: =SUM(K19:N19) -> -7645 | X19: =SUM(L19:O19) -> -7418 | Y19: =SUM(M19:P19) -> -7037 | Z19: =SUM(N19:Q19) -> -6696 | AA19: =SUM(O19:R19) -> -6399 | AB19: =SUM(P19:S19) -> -6012 | AD19: =SUM(AB19/X19)-1 -> -0.18953896
B20: (-) Restructuring and other charges | C20: ='Historical Financials'!C19 -> -91 | D20: ='Historical Financials'!D19 -> -32 | E20: ='Historical Financials'!E19 -> -3757 | F20: ='Historical Financials'!F19 -> -585 | G20: ='Historical Financials'!G19 -> -447 | I20: ='Historical Financials'!I19 -> -95 | J20: ='Historical Financials'!J19 -> -146 | K20: ='Historical Financials'!K19 -> -269 | L20: ='Historical Financials'!L19 -> -75 | M20: ='Historical Financials'!M19 -> -35 | N20: ='Historical Financials'!N19 -> -117 | O20: ='Historical Financials'!O19 -> -9 | P20: ='Historical Financials'!P19 -> -286 | ... S20: ='Historical Financials'!S19 -> -88 | T20: =SUM(H20:K20) -> -510 | U20: =SUM(I20:L20) -> -585 | V20: =SUM(J20:M20) -> -525 | W20: =SUM(K20:N20) -> -496 | X20: =SUM(L20:O20) -> -236 | Y20: =SUM(M20:P20) -> -447 | Z20: =SUM(N20:Q20) -> -466 | AA20: =SUM(O20:R20) -> -429 | AB20: =SUM(P20:S20) -> -508 | AD20: =SUM(AB20/X20)-1 -> 1.1525424
B21: (-) Impairments and loss on dispositions | C21: ='Historical Financials'!C20 -> -124 | D21: ='Historical Financials'!D20 -> 71 | E21: ='Historical Financials'!E20 -> -117 | F21: ='Historical Financials'!F20 -> -77 | G21: ='Historical Financials'!G20 -> -9603 | I21: ='Historical Financials'!I20 -> -31 | J21: ='Historical Financials'!J20 -> -6 | K21: ='Historical Financials'!K20 -> -24 | L21: ='Historical Financials'!L20 -> -16 | M21: ='Historical Financials'!M20 -> -12 | N21: ='Historical Financials'!N20 -> -9395 | O21: ='Historical Financials'!O20 -> -5 | P21: ='Historical Financials'!P20 -> -191 | ... S21: ='Historical Financials'!S20 -> -46 | T21: =SUM(H21:K21) -> -61 | U21: =SUM(I21:L21) -> -77 | V21: =SUM(J21:M21) -> -58 | W21: =SUM(K21:N21) -> -9447 | X21: =SUM(L21:O21) -> -9428 | Y21: =SUM(M21:P21) -> -9603 | Z21: =SUM(N21:Q21) -> -9681 | AA21: =SUM(O21:R21) -> -312 | AB21: =SUM(P21:S21) -> -353 | AD21: =SUM(AB21/X21)-1 -> -0.96255834
B22: Earning before Interest & Taxes (EBIT) | C22: =SUM(C15+SUM(C18:C21)) -> 2515 | D22: =SUM(D15+SUM(D18:D21)) -> 2012 | E22: =SUM(E15+SUM(E18:E21)) -> -7370 | F22: =SUM(F15+SUM(F18:F21)) -> -1548 | G22: =SUM(G15+SUM(G18:G21)) -> -10032 | I22: =SUM(I15+SUM(I18:I21)) -> -557 | J22: =SUM(J15+SUM(J18:J21)) -> -906 | K22: =SUM(K15+SUM(K18:K21)) -> 97 | L22: =SUM(L15+SUM(L18:L21)) -> -182 | M22: =SUM(M15+SUM(M18:M21)) -> -267 | N22: =SUM(N15+SUM(N18:N21)) -> -10208 | O22: =SUM(O15+SUM(O18:O21)) -> 281 | P22: =SUM(P15+SUM(P18:P21)) -> 162 | ... S22: =SUM(S15+SUM(S18:S21)) -> 611 | U22: =SUM(U15+SUM(U18:U21)) -> -1548 | V22: =SUM(V15+SUM(V18:V21)) -> -1258 | W22: =SUM(W15+SUM(W18:W21)) -> -10560 | X22: =SUM(X15+SUM(X18:X21)) -> -10376 | Y22: =SUM(Y15+SUM(Y18:Y21)) -> -10032 | Z22: =SUM(Z15+SUM(Z18:Z21)) -> -9802 | AA22: =SUM(AA15+SUM(AA18:AA21)) -> 221 | AB22: =SUM(AB15+SUM(AB18:AB21)) -> 551 | AD22: =SUM(AB22/X22)-1 -> -1.0531033
B23: Operating Margin (%) | C23: =C22/C10 -> 0.2356855 | D23: =D22/D10 -> 0.16503978 | E23: =E22/E10 -> -0.21793772 | F23: =F22/F10 -> -0.037462791 | G23: =G22/G10 -> -0.25513085 | I23: =I22/I10 -> -0.052056075 | J23: =J22/J10 -> -0.087468623 | K23: =K22/K10 -> 0.0097204129 | L23: =L22/L10 -> -0.017697394 | M23: =M22/M10 -> -0.026812613 | N23: =N22/N10 -> -1.0509626 | O23: =O22/O10 -> 0.029200873 | P23: =P22/P10 -> 0.016156378 | ... S23: =S22/S10 -> 0.067551133 | U23: =U22/U10 -> -0.037462791 | V23: =V22/V10 -> -0.031001257 | W23: =W22/W10 -> -0.26443632 | X23: =X22/X10 -> -0.26216585 | Y23: =Y22/Y10 -> -0.25513085 | Z23: =Z22/Z10 -> -0.25564655 | AA23: =AA22/AA10 -> 0.00574907 | AB23: =AB22/AB10 -> 0.014552465 | AD23: =SUM(AB23-X23)*10000 -> 2767.1832
B25: (+) Depreciation and Amortization (D&A) | C25: =-C19 -> 1359 | D25: =-D19 -> 1582 | E25: =-E19 -> 7193 | F25: =-F19 -> 7985 | G25: =-G19 -> 7037 | I25: =-I19 -> 2058 | J25: =-J19 -> 1914 | K25: =-K19 -> 1989 | L25: =-L19 -> 2024 | M25: =-M19 -> 1888 | N25: =-N19 -> 1744 | O25: =-O19 -> 1762 | P25: =-P19 -> 1643 | ... S25: =-S19 -> 1375 | T25: =SUM(H25:K25) -> 5961 | U25: =SUM(I25:L25) -> 7985 | V25: =SUM(J25:M25) -> 7815 | W25: =SUM(K25:N25) -> 7645 | X25: =SUM(L25:O25) -> 7418 | Y25: =SUM(M25:P25) -> 7037 | Z25: =SUM(N25:Q25) -> 6696 | AA25: =SUM(O25:R25) -> 6399 | AB25: =SUM(P25:S25) -> 6012 | AD25: =SUM(AB25/X25)-1 -> -0.18953896
B26: EBITDA | C26: =SUM(C22+SUM(C25:C25)) -> 3874 | D26: =SUM(D22+SUM(D25:D25)) -> 3594 | E26: =SUM(E22+SUM(E25:E25)) -> -177 | F26: =SUM(F22+SUM(F25:F25)) -> 6437 | G26: =SUM(G22+SUM(G25:G25)) -> -2995 | I26: =SUM(I22+SUM(I25:I25)) -> 1501 | J26: =SUM(J22+SUM(J25:J25)) -> 1008 | K26: =SUM(K22+SUM(K25:K25)) -> 2086 | L26: =SUM(L22+SUM(L25:L25)) -> 1842 | M26: =SUM(M22+SUM(M25:M25)) -> 1621 | N26: =SUM(N22+SUM(N25:N25)) -> -8464 | O26: =SUM(O22+SUM(O25:O25)) -> 2043 | P26: =SUM(P22+SUM(P25:P25)) -> 1805 | ... S26: =SUM(S22+SUM(S25:S25)) -> 1986 | U26: =SUM(U22+SUM(U25:U25)) -> 6437 | V26: =SUM(V22+SUM(V25:V25)) -> 6557 | W26: =SUM(W22+SUM(W25:W25)) -> -2915 | X26: =SUM(X22+SUM(X25:X25)) -> -2958 | Y26: =SUM(Y22+SUM(Y25:Y25)) -> -2995 | Z26: =SUM(Z22+SUM(Z25:Z25)) -> -3106 | AA26: =SUM(AA22+SUM(AA25:AA25)) -> 6620 | AB26: =SUM(AB22+SUM(AB25:AB25)) -> 6563 | AD26: =SUM(AB26/X26)-1 -> -3.2187289
