Workbook

Sheet Historical Financials
B2: Paramount Global (NASDAQ: PARA)
B3: Historical Financials
B4: ($ In Millions, except EPS)
A6: X | B6: Income Statement | D6: FYE | H6: Quarterly | N6: Quarterly | U6: LTM | AA6: Variance
B7: Fiscal Period | C7: 2021 | D7: 2022 | E7: 2023 | F7: 2024 | H7: 1Q23 | I7: 2Q23 | J7: 3Q23 | K7: 4Q23 | L7: 1Q24 | M7: 2Q24 | N7: 3Q24 | O7: 4Q24 | P7: 1Q25 | Q7: 2Q25 | S7: =K7 -> 4Q23 | T7: =L7 -> 1Q24 | U7: =M7 -> 2Q24 | V7: =N7 -> 3Q24 | W7: =O7 -> 4Q24 | X7: =P7 -> 1Q25 | Y7: =Q7 -> 2Q25
B8: Fiscal Period End Date | C8: 44561 | D8: 44926 | E8: 45291 | F8: 45657 | H8: 45016 | I8: 45107 | J8: 45199 | K8: =D8 -> 44926 | L8: 45382 | M8: 45473 | N8: 45565 | O8: =E8 -> 45291 | P8: 45747 | Q8: 45838 | S8: =K8 -> 44926 | T8: =L8 -> 45382 | U8: =M8 -> 45473 | V8: =N8 -> 45565 | W8: =O8 -> 45291 | X8: =P8 -> 45747 | Y8: =Q8 -> 45838
B10: Consolidated Revenue | C10: 28586 | D10: 30154 | E10: 29652 | F10: 29213 | H10: 7265 | I10: 7616 | J10: 7133 | K10: =SUM(E10-SUM(H10:J10)) -> 7638 | L10: 7685 | M10: 6813 | N10: 6731 | O10: =SUM(F10-SUM(L10:N10)) -> 7984 | P10: 7192 | Q10: 6849 | S10: =SUM(H10:K10) -> 29652 | T10: =SUM(I10:L10) -> 30072 | U10: =SUM(J10:M10) -> 29269 | V10: =SUM(K10:N10) -> 28867 | W10: =SUM(L10:O10) -> 29213 | X10: =SUM(M10:P10) -> 28720 | Y10: =SUM(N10:Q10) -> 28756 | AA10: =SUM(Y10/U10)-1 -> -0.017527076
B11: Total Revenue | C11: =+SUM(C10:C10) -> 28586 | D11: =+SUM(D10:D10) -> 30154 | E11: =+SUM(E10:E10) -> 29652 | F11: =+SUM(F10:F10) -> 29213 | H11: =+SUM(H10:H10) -> 7265 | I11: =+SUM(I10:I10) -> 7616 | J11: =+SUM(J10:J10) -> 7133 | K11: =+SUM(K10:K10) -> 7638 | L11: =+SUM(L10:L10) -> 7685 | M11: =+SUM(M10:M10) -> 6813 | N11: =+SUM(N10:N10) -> 6731 | O11: =+SUM(O10:O10) -> 7984 | ... Q11: =+SUM(Q10:Q10) -> 6849 | S11: =+SUM(S10:S10) -> 29652 | T11: =+SUM(T10:T10) -> 30072 | U11: =+SUM(U10:U10) -> 29269 | V11: =+SUM(V10:V10) -> 28867 | W11: =+SUM(W10:W10) -> 29213 | X11: =+SUM(X10:X10) -> 28720 | Y11: =+SUM(Y10:Y10) -> 28756 | AA11: =SUM(Y11/U11)-1 -> -0.017527076
B13: Operating expenses | C13: -17744 | D13: -19845 | E13: -20017 | F13: -19437 | H13: -4964 | I13: -5227 | J13: -4681 | K13: =SUM(E13-SUM(H13:J13)) -> -5145 | L13: -5036 | M13: -4367 | N13: -4342 | O13: =SUM(F13-SUM(L13:N13)) -> -5692 | P13: -4961 | Q13: -4624 | S13: =SUM(H13:K13) -> -20017 | T13: =SUM(I13:L13) -> -20089 | U13: =SUM(J13:M13) -> -19229 | V13: =SUM(K13:N13) -> -18890 | W13: =SUM(L13:O13) -> -19437 | X13: =SUM(M13:P13) -> -19362 | Y13: =SUM(N13:Q13) -> -19619 | AA13: =SUM(Y13/U13)-1 -> 0.020281866
B14: Programming charges | C14: 0 | D14: 0 | E14: -2371 | F14: -1118 | H14: -1674 | I14: -697 | J14: 0 | K14: =SUM(E14-SUM(H14:J14)) -> 0 | L14: -1118 | M14: 0 | N14: 0 | O14: =SUM(F14-SUM(L14:N14)) -> 0 | P14: 0 | Q14: 0 | S14: =SUM(H14:K14) -> -2371 | T14: =SUM(I14:L14) -> -1815 | U14: =SUM(J14:M14) -> -1118 | V14: =SUM(K14:N14) -> -1118 | W14: =SUM(L14:O14) -> -1118 | X14: =SUM(M14:P14) -> 0 | Y14: =SUM(N14:Q14) -> 0 | AA14: =SUM(Y14/U14)-1 -> -1
B15: Selling, general and administrative | C15: -6398 | D15: -7033 | E15: -7245 | F15: -6658 | H15: -1753 | I15: -1783 | J15: -1736 | K15: =SUM(E15-SUM(H15:J15)) -> -1973 | L15: -1662 | M15: -1579 | N15: -1531 | O15: =SUM(F15-SUM(L15:N15)) -> -1886 | P15: -1543 | Q15: -1401 | S15: =SUM(H15:K15) -> -7245 | T15: =SUM(I15:L15) -> -7154 | U15: =SUM(J15:M15) -> -6950 | V15: =SUM(K15:N15) -> -6745 | W15: =SUM(L15:O15) -> -6658 | X15: =SUM(M15:P15) -> -6539 | Y15: =SUM(N15:Q15) -> -6361 | AA15: =SUM(Y15/U15)-1 -> -0.084748201
B16: Depreciation and amortization | C16: -390 | D16: -378 | E16: -418 | F16: -392 | H16: -100 | I16: -105 | J16: -105 | K16: =SUM(E16-SUM(H16:J16)) -> -108 | L16: -100 | M16: -101 | N16: -96 | O16: =SUM(F16-SUM(L16:N16)) -> -95 | P16: -88 | Q16: -87 | S16: =SUM(H16:K16) -> -418 | T16: =SUM(I16:L16) -> -418 | U16: =SUM(J16:M16) -> -414 | V16: =SUM(K16:N16) -> -405 | W16: =SUM(L16:O16) -> -392 | X16: =SUM(M16:P16) -> -380 | Y16: =SUM(N16:Q16) -> -366 | AA16: =SUM(Y16/U16)-1 -> -0.11594203
B17: Impairment charges | C17: 0 | D17: -27 | E17: -83 | F17: -6130 | H17: 0 | I17: 0 | J17: 0 | K17: =SUM(E17-SUM(H17:J17)) -> -83 | L17: -186 | M17: -5996 | N17: -104 | O17: =SUM(F17-SUM(L17:N17)) -> 156 | P17: 0 | Q17: -157 | S17: =SUM(H17:K17) -> -83 | T17: =SUM(I17:L17) -> -269 | U17: =SUM(J17:M17) -> -6265 | V17: =SUM(K17:N17) -> -6369 | W17: =SUM(L17:O17) -> -6130 | X17: =SUM(M17:P17) -> -5944 | Y17: =SUM(N17:Q17) -> -105 | AA17: =SUM(Y17/U17)-1 -> -0.98324022
B18: Restructuring, transaction-related items, and other corporate matters | C18: -100 | D18: -585 | E18: 31 | F18: -747 | H18: 0 | I18: -54 | J18: 10 | K18: =SUM(E18-SUM(H18:J18)) -> 75 | L18: 0 | M18: -88 | N18: -321 | O18: =SUM(F18-SUM(L18:N18)) -> -338 | P18: -85 | Q18: -181 | S18: =SUM(H18:K18) -> 31 | T18: =SUM(I18:L18) -> 31 | U18: =SUM(J18:M18) -> -3 | V18: =SUM(K18:N18) -> -334 | W18: =SUM(L18:O18) -> -747 | X18: =SUM(M18:P18) -> -832 | Y18: =SUM(N18:Q18) -> -925 | AA18: =SUM(Y18/U18)-1 -> 307.33333
B19: Gains on dispositions | C19: 2343 | D19: 56 | E19: 0 | F19: 0 | H19: 0 | I19: 0 | J19: 0 | K19: =SUM(E19-SUM(H19:J19)) -> 0 | L19: 0 | M19: 0 | N19: 0 | O19: =SUM(F19-SUM(L19:N19)) -> 0 | P19: 35 | Q19: 0 | S19: =SUM(H19:K19) -> 0 | T19: =SUM(I19:L19) -> 0 | U19: =SUM(J19:M19) -> 0 | V19: =SUM(K19:N19) -> 0 | W19: =SUM(L19:O19) -> 0 | X19: =SUM(M19:P19) -> 35 | Y19: =SUM(N19:Q19) -> 35 | AA19: =SUM(Y19/U19)-1 -> #DIV/0!
B20: Operating Profit | C20: =+SUM(C11+SUM(C13:C19)) -> 6297 | D20: =+SUM(D11+SUM(D13:D19)) -> 2342 | E20: =+SUM(E11+SUM(E13:E19)) -> -451 | F20: =+SUM(F11+SUM(F13:F19)) -> -5269 | H20: =+SUM(H11+SUM(H13:H19)) -> -1226 | I20: =+SUM(I11+SUM(I13:I19)) -> -250 | J20: =+SUM(J11+SUM(J13:J19)) -> 621 | K20: =+SUM(K11+SUM(K13:K19)) -> 404 | L20: =+SUM(L11+SUM(L13:L19)) -> -417 | M20: =+SUM(M11+SUM(M13:M19)) -> -5318 | N20: =+SUM(N11+SUM(N13:N19)) -> 337 | O20: =+SUM(O11+SUM(O13:O19)) -> 129 | ... Q20: =+SUM(Q11+SUM(Q13:Q19)) -> 399 | S20: =+SUM(S11+SUM(S13:S19)) -> -451 | T20: =+SUM(T11+SUM(T13:T19)) -> 358 | U20: =+SUM(U11+SUM(U13:U19)) -> -4710 | V20: =+SUM(V11+SUM(V13:V19)) -> -4994 | W20: =+SUM(W11+SUM(W13:W19)) -> -5269 | X20: =+SUM(X11+SUM(X13:X19)) -> -4302 | Y20: =+SUM(Y11+SUM(Y13:Y19)) -> 1415 | AA20: =SUM(Y20/U20)-1 -> -1.3004246
B21: Operating Margin (%) | C21: =C20/C11 -> 0.22028266 | D21: =D20/D11 -> 0.077667971 | E21: =E20/E11 -> -0.015209767 | F21: =F20/F11 -> -0.18036491 | H21: =H20/H11 -> -0.1687543 | I21: =I20/I11 -> -0.03282563 | J21: =J20/J11 -> 0.087060143 | K21: =K20/K11 -> 0.052893428 | L21: =L20/L11 -> -0.054261548 | M21: =M20/M11 -> -0.78056656 | N21: =N20/N11 -> 0.050066855 | O21: =O20/O11 -> 0.016157315 | ... Q21: =Q20/Q11 -> 0.05825668 | S21: =S20/S11 -> -0.015209767 | T21: =T20/T11 -> 0.011904762 | U21: =U20/U11 -> -0.16092111 | V21: =V20/V11 -> -0.17300031 | W21: =W20/W11 -> -0.18036491 | X21: =X20/X11 -> -0.14979109 | Y21: =Y20/Y11 -> 0.049207122 | AA21: =SUM(Y21-U21)*1000 -> 210.12823
B23: Interest expense | C23: -986 | D23: -931 | E23: -920 | F23: -860 | H23: -226 | I23: -240 | J23: -232 | K23: =SUM(E23-SUM(H23:J23)) -> -222 | L23: -221 | M23: -215 | N23: -209 | O23: =SUM(F23-SUM(L23:N23)) -> -215 | P23: -217 | Q23: -214 | S23: =SUM(H23:K23) -> -920 | T23: =SUM(I23:L23) -> -915 | U23: =SUM(J23:M23) -> -890 | V23: =SUM(K23:N23) -> -867 | W23: =SUM(L23:O23) -> -860 | X23: =SUM(M23:P23) -> -856 | Y23: =SUM(N23:Q23) -> -855 | AA23: =SUM(Y23/U23)-1 -> -0.039325843
B24: Interest income | C24: 53 | D24: 108 | E24: 137 | F24: 151 | H24: 35 | I24: 33 | J24: 29 | K24: =SUM(E24-SUM(H24:J24)) -> 40 | L24: 45 | M24: 35 | N24: 31 | O24: =SUM(F24-SUM(L24:N24)) -> 40 | P24: 38 | Q24: 32 | S24: =SUM(H24:K24) -> 137 | T24: =SUM(I24:L24) -> 147 | U24: =SUM(J24:M24) -> 149 | V24: =SUM(K24:N24) -> 151 | W24: =SUM(L24:O24) -> 151 | X24: =SUM(M24:P24) -> 144 | Y24: =SUM(N24:Q24) -> 141 | AA24: =SUM(Y24/U24)-1 -> -0.053691275
B25: Gain (loss) from investments | C25: 47 | D25: -9 | E25: 168 | F25: -17 | H25: 0 | I25: 168 | J25: 0 | K25: =SUM(E25-SUM(H25:J25)) -> 0 | L25: -4 | M25: 0 | N25: 0 | O25: =SUM(F25-SUM(L25:N25)) -> -13 | P25: 0 | Q25: 0 | S25: =SUM(H25:K25) -> 168 | T25: =SUM(I25:L25) -> 164 | U25: =SUM(J25:M25) -> -4 | V25: =SUM(K25:N25) -> -4 | W25: =SUM(L25:O25) -> -17 | X25: =SUM(M25:P25) -> -13 | Y25: =SUM(N25:Q25) -> -13 | AA25: =SUM(Y25/U25)-1 -> 2.25
B26: Gain (loss) on extinguishment of debt | C26: -128 | D26: -120 | E26: 29 | F26: 0 | H26: 0 | I26: 0 | J26: 0 | K26: =SUM(E26-SUM(H26:J26)) -> 29 | L26: 0 | M26: 0 | N26: 0 | O26: =SUM(F26-SUM(L26:N26)) -> 0 | P26: 0 | Q26: 0 | S26: =SUM(H26:K26) -> 29 | T26: =SUM(I26:L26) -> 29 | U26: =SUM(J26:M26) -> 29 | V26: =SUM(K26:N26) -> 29 | W26: =SUM(L26:O26) -> 0 | X26: =SUM(M26:P26) -> 0 | Y26: =SUM(N26:Q26) -> 0 | AA26: =SUM(Y26/U26)-1 -> -1
B27: Other items, net | C27: -77 | D27: -124 | E27: -216 | F27: -182 | H27: -46 | I27: -60 | J27: -42 | K27: =SUM(E27-SUM(H27:J27)) -> -68 | L27: -38 | M27: -49 | N27: -39 | O27: =SUM(F27-SUM(L27:N27)) -> -56 | P27: -37 | Q27: -39 | S27: =SUM(H27:K27) -> -216 | T27: =SUM(I27:L27) -> -208 | U27: =SUM(J27:M27) -> -197 | V27: =SUM(K27:N27) -> -194 | W27: =SUM(L27:O27) -> -182 | X27: =SUM(M27:P27) -> -181 | Y27: =SUM(N27:Q27) -> -171 | AA27: =SUM(Y27/U27)-1 -> -0.1319797
B28: Earnings (loss) from Continuing Operations before Taxes & Equity | C28: =SUM(C23:C27)+C20 -> 5206 | D28: =SUM(D23:D27)+D20 -> 1266 | E28: =SUM(E23:E27)+E20 -> -1253 | F28: =SUM(F23:F27)+F20 -> -6177 | H28: =SUM(H23:H27)+H20 -> -1463 | I28: =SUM(I23:I27)+I20 -> -349 | J28: =SUM(J23:J27)+J20 -> 376 | K28: =SUM(K23:K27)+K20 -> 183 | L28: =SUM(L23:L27)+L20 -> -635 | M28: =SUM(M23:M27)+M20 -> -5547 | N28: =SUM(N23:N27)+N20 -> 120 | O28: =SUM(O23:O27)+O20 -> -115 | ... Q28: =SUM(Q23:Q27)+Q20 -> 178 | S28: =SUM(S23:S27)+S20 -> -1253 | T28: =SUM(T23:T27)+T20 -> -425 | U28: =SUM(U23:U27)+U20 -> -5623 | V28: =SUM(V23:V27)+V20 -> -5879 | W28: =SUM(W23:W27)+W20 -> -6177 | X28: =SUM(X23:X27)+X20 -> -5208 | Y28: =SUM(Y23:Y27)+Y20 -> 517 | AA28: =SUM(Y28/U28)-1 -> -1.0919438
B29: EBT Margin (%) | C29: =C28/C11 -> 0.18211712 | D29: =D28/D11 -> 0.04198448 | E29: =E28/E11 -> -0.042256846 | F29: =F28/F11 -> -0.21144696 | H29: =H28/H11 -> -0.20137646 | I29: =I28/I11 -> -0.04582458 | J29: =J28/J11 -> 0.052712744 | K29: =K28/K11 -> 0.023959152 | L29: =L28/L11 -> -0.082628497 | M29: =M28/M11 -> -0.81417878 | N29: =N28/N11 -> 0.01782796 | O29: =O28/O11 -> -0.014403808 | ... Q29: =Q28/Q11 -> 0.025989196 | S29: =S28/S11 -> -0.042256846 | T29: =T28/T11 -> -0.014132748 | U29: =U28/U11 -> -0.19211452 | V29: =V28/V11 -> -0.20365816 | W29: =W28/W11 -> -0.21144696 | X29: =X28/X11 -> -0.18133705 | Y29: =Y28/Y11 -> 0.017978857 | AA29: =SUM(Y29-U29)*1000 -> 210.09338
B31: Income tax expense | C31: -646 | D31: -227 | E31: 361 | F31: 305 | H31: 381 | I31: 95 | J31: -40 | K31: =SUM(E31-SUM(H31:J31)) -> -75 | L31: 172 | M31: 215 | N31: -45 | O31: =SUM(F31-SUM(L31:N31)) -> -37 | P31: -100 | Q31: -50 | S31: =SUM(H31:K31) -> 361 | T31: =SUM(I31:L31) -> 152 | U31: =SUM(J31:M31) -> 272 | V31: =SUM(K31:N31) -> 267 | W31: =SUM(L31:O31) -> 305 | X31: =SUM(M31:P31) -> 33 | Y31: =SUM(N31:Q31) -> -232 | AA31: =SUM(Y31/U31)-1 -> -1.8529412
B32: Equity in loss of investee companies, net of tax | C32: -91 | D32: -204 | E32: -360 | F32: -291 | H32: -75 | I32: -109 | J32: -75 | K32: =SUM(E32-SUM(H32:J32)) -> -101 | L32: -90 | M32: -72 | N32: -59 | O32: =SUM(F32-SUM(L32:N32)) -> -70 | P32: -73 | Q32: -67 | S32: =SUM(H32:K32) -> -360 | T32: =SUM(I32:L32) -> -375 | U32: =SUM(J32:M32) -> -338 | V32: =SUM(K32:N32) -> -322 | W32: =SUM(L32:O32) -> -291 | X32: =SUM(M32:P32) -> -274 | Y32: =SUM(N32:Q32) -> -269
B33: Net earnings (loss) from continuing operations | C33: =SUM(C28+SUM(C31:C32)) -> 4469 | D33: =SUM(D28+SUM(D31:D32)) -> 835 | E33: =SUM(E28+SUM(E31:E32)) -> -1252 | F33: =SUM(F28+SUM(F31:F32)) -> -6163 | H33: =SUM(H28+SUM(H31:H32)) -> -1157 | I33: =SUM(I28+SUM(I31:I32)) -> -363 | J33: =SUM(J28+SUM(J31:J32)) -> 261 | K33: =SUM(K28+SUM(K31:K32)) -> 7 | L33: =SUM(L28+SUM(L31:L32)) -> -553 | M33: =SUM(M28+SUM(M31:M32)) -> -5404 | N33: =SUM(N28+SUM(N31:N32)) -> 16 | O33: =SUM(O28+SUM(O31:O32)) -> -222 | ... Q33: =SUM(Q28+SUM(Q31:Q32)) -> 61 | S33: =SUM(S23+SUM(S31:S32)) -> -919 | T33: =SUM(T23+SUM(T31:T32)) -> -1138 | U33: =SUM(U23+SUM(U31:U32)) -> -956 | V33: =SUM(V23+SUM(V31:V32)) -> -922 | W33: =SUM(W23+SUM(W31:W32)) -> -846 | X33: =SUM(X23+SUM(X31:X32)) -> -1097 | Y33: =SUM(Y23+SUM(Y31:Y32)) -> -1356 | AA33: =SUM(Y33/U33)-1 -> 0.41841004
B35: Net earnings from discontinued operations, net of tax | C35: 162 | D35: 379 | E35: 676 | F35: 14 | H35: 45 | I35: 73 | J35: 48 | K35: =SUM(E35-SUM(H35:J35)) -> 510 | L35: 9 | M35: 0 | N35: 5 | O35: =SUM(F35-SUM(L35:N35)) -> 0 | P35: 0 | Q35: 0 | S35: =SUM(H35:K35) -> 676 | T35: =SUM(I35:L35) -> 640 | U35: =SUM(J35:M35) -> 567 | V35: =SUM(K35:N35) -> 524 | W35: =SUM(L35:O35) -> 14 | X35: =SUM(M35:P35) -> 5 | Y35: =SUM(N35:Q35) -> 5 | AA35: =SUM(Y35/U35)-1 -> -0.99118166
B36: Net earnings (loss) (Paramount and noncontrolling interests) | C36: =SUM(C33)+SUM(C35:C35) -> 4631 | D36: =SUM(D33)+SUM(D35:D35) -> 1214 | E36: =SUM(E33)+SUM(E35:E35) -> -576 | F36: =SUM(F33)+SUM(F35:F35) -> -6149 | H36: =SUM(H33)+SUM(H35:H35) -> -1112 | I36: =SUM(I33)+SUM(I35:I35) -> -290 | J36: =SUM(J33)+SUM(J35:J35) -> 309 | K36: =SUM(K33)+SUM(K35:K35) -> 517 | L36: =SUM(L33)+SUM(L35:L35) -> -544 | M36: =SUM(M33)+SUM(M35:M35) -> -5404 | N36: =SUM(N33)+SUM(N35:N35) -> 21 | O36: =SUM(O33)+SUM(O35:O35) -> -222 | ... Q36: =SUM(Q33)+SUM(Q35:Q35) -> 61 | S36: =SUM(S33)+SUM(S35:S35) -> -243 | T36: =SUM(T33)+SUM(T35:T35) -> -498 | U36: =SUM(U33)+SUM(U35:U35) -> -389 | V36: =SUM(V33)+SUM(V35:V35) -> -398 | W36: =SUM(W33)+SUM(W35:W35) -> -832 | X36: =SUM(X33)+SUM(X35:X35) -> -1092 | Y36: =SUM(Y33)+SUM(Y35:Y35) -> -1351 | AA36: =SUM(Y36/U36)-1 -> 2.4730077
B38: Net earnings attributable to noncontrolling interests | C38: -88 | D38: -110 | E38: -32 | F38: -41 | H38: -6 | I38: -9 | J38: -14 | K38: =SUM(E38-SUM(H38:J38)) -> -3 | L38: -10 | M38: -9 | N38: -20 | O38: =SUM(F38-SUM(L38:N38)) -> -2 | P38: -9 | Q38: -4 | S38: =SUM(H38:K38) -> -32 | T38: =SUM(I38:L38) -> -36 | U38: =SUM(J38:M38) -> -36 | V38: =SUM(K38:N38) -> -42 | W38: =SUM(L38:O38) -> -41 | X38: =SUM(M38:P38) -> -40 | Y38: =SUM(N38:Q38) -> -35 | AA38: =SUM(Y38/U38)-1 -> -0.027777778
B39: Net earnings (loss) attributable to Paramount | C39: =SUM(C36+SUM(C38:C38)) -> 4543 | D39: =SUM(D36+SUM(D38:D38)) -> 1104 | E39: =SUM(E36+SUM(E38:E38)) -> -608 | F39: =SUM(F36+SUM(F38:F38)) -> -6190 | H39: =SUM(H36+SUM(H38:H38)) -> -1118 | I39: =SUM(I36+SUM(I38:I38)) -> -299 | J39: =SUM(J36+SUM(J38:J38)) -> 295 | K39: =SUM(K36+SUM(K38:K38)) -> 514 | L39: =SUM(L36+SUM(L38:L38)) -> -554 | M39: =SUM(M36+SUM(M38:M38)) -> -5413 | N39: =SUM(N36+SUM(N38:N38)) -> 1 | O39: =SUM(O36+SUM(O38:O38)) -> -224 | ... Q39: =SUM(Q36+SUM(Q38:Q38)) -> 57 | S39: =SUM(S36+SUM(S38:S38)) -> -275 | T39: =SUM(T36+SUM(T38:T38)) -> -534 | U39: =SUM(U36+SUM(U38:U38)) -> -425 | V39: =SUM(V36+SUM(V38:V38)) -> -440 | W39: =SUM(W36+SUM(W38:W38)) -> -873 | X39: =SUM(X36+SUM(X38:X38)) -> -1132 | Y39: =SUM(Y36+SUM(Y38:Y38)) -> -1386 | AA39: =SUM(Y39/U39)-1 -> 2.2611765
B40: Net Margin (%) | C40: =C39/C11 -> 0.15892395 | D40: =D39/D11 -> 0.036612058 | E40: =E39/E11 -> -0.020504519 | F40: =F39/F11 -> -0.21189197 | H40: =H39/H11 -> -0.15388851 | I40: =I39/I11 -> -0.039259454 | J40: =J39/J11 -> 0.041357073 | K40: =K39/K11 -> 0.067295103 | L40: =L39/L11 -> -0.072088484 | M40: =M39/M11 -> -0.79451049 | N40: =N39/N11 -> 0.00014856633 | O40: =O39/O11 -> -0.028056112 | ... Q40: =Q39/Q11 -> 0.0083223828 | S40: =S39/S11 -> -0.0092742479 | T40: =T39/T11 -> -0.017757382 | U40: =U39/U11 -> -0.014520482 | V40: =V39/V11 -> -0.015242318 | W40: =W39/W11 -> -0.029883956 | X40: =X39/X11 -> -0.039415042 | Y40: =Y39/Y11 -> -0.048198637 | AA40: =SUM(Y40-U40)*1000 -> -33.678154
B42: Basic shares | C42: 641 | D42: 649 | E42: 652 | F42: 664 | H42: 651 | I42: 651 | J42: 652 | K42: =E42 -> 652 | L42: 654 | M42: 667 | N42: 667 | O42: =F42 -> 664 | P42: 672 | Q42: 675 | S42: =K42 -> 652 | T42: =L42 -> 654 | U42: =M42 -> 667 | V42: =N42 -> 667 | W42: =O42 -> 664 | X42: =P42 -> 672 | Y42: =Q42 -> 675 | AA42: =SUM(Y42/U42)-1 -> 0.011994003
B43: Basic EPS | C43: =C39/C42 -> 7.0873635 | D43: =D39/D42 -> 1.7010786 | E43: =E39/E42 -> -0.93251534 | F43: =F39/F42 -> -9.3222892 | H43: =H39/H42 -> -1.7173579 | I43: =I39/I42 -> -0.45929339 | J43: =J39/J42 -> 0.45245399 | K43: =K39/K42 -> 0.78834356 | L43: =L39/L42 -> -0.8470948 | M43: =M39/M42 -> -8.1154423 | N43: =N39/N42 -> 0.0014992504 | O43: =O39/O42 -> -0.3373494 | ... Q43: =Q39/Q42 -> 0.084444444 | S43: =S39/S42 -> -0.42177914 | T43: =T39/T42 -> -0.81651376 | U43: =U39/U42 -> -0.63718141 | V43: =V39/V42 -> -0.65967016 | W43: =W39/W42 -> -1.314759 | X43: =X39/X42 -> -1.6845238 | Y43: =Y39/Y42 -> -2.0533333 | AA43: =SUM(Y43/U43)-1 -> 2.2225255
B45: Fully Diluted Shares | C45: 655 | D45: 650 | E45: 652 | F45: 664 | H45: 651 | I45: 651 | J45: 652 | K45: =E45 -> 652 | L45: 654 | M45: 667 | N45: 670 | O45: =F45 -> 664 | P45: 678 | Q45: 680 | S45: =K45 -> 652 | T45: =L45 -> 654 | U45: =M45 -> 667 | V45: =N45 -> 670 | W45: =O45 -> 664 | X45: =P45 -> 678 | Y45: =Q45 -> 680 | AA45: =SUM(Y45/U45)-1 -> 0.019490255
B46: Diluted EPS | C46: =C39/C45 -> 6.9358779 | D46: =D39/D45 -> 1.6984615 | E46: =E39/E45 -> -0.93251534 | F46: =F39/F45 -> -9.3222892 | H46: =H39/H45 -> -1.7173579 | I46: =I39/I45 -> -0.45929339 | J46: =J39/J45 -> 0.45245399 | K46: =K39/K45 -> 0.78834356 | L46: =L39/L45 -> -0.8470948 | M46: =M39/M45 -> -8.1154423 | N46: =N39/N45 -> 0.0014925373 | O46: =O39/O45 -> -0.3373494 | ... Q46: =Q39/Q45 -> 0.083823529 | S46: =S39/S45 -> -0.42177914 | T46: =T39/T45 -> -0.81651376 | U46: =U39/U45 -> -0.63718141 | V46: =V39/V45 -> -0.65671642 | W46: =W39/W45 -> -1.314759 | X46: =X39/X45 -> -1.6696165 | Y46: =Y39/Y45 -> -2.0382353 | AA46: =SUM(Y46/U46)-1 -> 2.1988304
A48: X | B48: Balance Sheet | C48: FYE | N48: Quarterly | U48: LTM | AA48: Variance
B49: =B7 -> Fiscal Period | C49: =C7 -> 2021 | D49: =D7 -> 2022 | E49: =E7 -> 2023 | F49: =F7 -> 2024 | H49: =H7 -> 1Q23 | I49: =I7 -> 2Q23 | J49: =J7 -> 3Q23 | K49: =K7 -> 4Q23 | L49: =L7 -> 1Q24 | M49: =M7 -> 2Q24 | N49: =N7 -> 3Q24 | O49: =O7 -> 4Q24 | ... Q49: =Q7 -> 2Q25 | S49: =S7 -> 4Q23 | T49: =T7 -> 1Q24 | U49: =U7 -> 2Q24 | V49: =V7 -> 3Q24 | W49: =W7 -> 4Q24 | X49: =X7 -> 1Q25 | Y49: =Y7 -> 2Q25
B50: =B8 -> Fiscal Period End Date | C50: =C8 -> 44561 | D50: =D8 -> 44926 | E50: =E8 -> 45291 | F50: =F8 -> 45657 | H50: =H8 -> 45016 | I50: =I8 -> 45107 | J50: =J8 -> 45199 | K50: =K8 -> 44926 | L50: =L8 -> 45382 | M50: =M8 -> 45473 | N50: =N8 -> 45565 | O50: =O8 -> 45291 | ... Q50: =Q8 -> 45838 | S50: =S8 -> 44926 | T50: =T8 -> 45382 | U50: =U8 -> 45473 | V50: =V8 -> 45565 | W50: =W8 -> 45291 | X50: =X8 -> 45747 | Y50: =Y8 -> 45838
B52: Current Assets
...

Sheet Revenue Drivers
B2: ='Historical Financials'!B2 -> Paramount Global (NASDAQ: PARA) | C2: FYE | N2: Quarterly | U2: LTM
B3: Segment Anaysis | C3: ='Historical Financials'!C7 -> 2021 | D3: ='Historical Financials'!D7 -> 2022 | E3: ='Historical Financials'!E7 -> 2023 | F3: ='Historical Financials'!F7 -> 2024 | H3: ='Historical Financials'!H7 -> 1Q23 | I3: ='Historical Financials'!I7 -> 2Q23 | J3: ='Historical Financials'!J7 -> 3Q23 | K3: ='Historical Financials'!K7 -> 4Q23 | L3: ='Historical Financials'!L7 -> 1Q24 | M3: ='Historical Financials'!M7 -> 2Q24 | N3: ='Historical Financials'!N7 -> 3Q24 | O3: ='Historical Financials'!O7 -> 4Q24 | ... Q3: ='Historical Financials'!Q7 -> 2Q25 | S3: =K3 -> 4Q23 | T3: =L3 -> 1Q24 | U3: =M3 -> 2Q24 | V3: =N3 -> 3Q24 | W3: =O3 -> 4Q24 | X3: =P3 -> 1Q25 | Y3: =Q3 -> 2Q25
B4: ($ In Millions) | C4: ='Historical Financials'!C8 -> 44561 | D4: ='Historical Financials'!D8 -> 44926 | E4: ='Historical Financials'!E8 -> 45291 | F4: ='Historical Financials'!F8 -> 45657 | H4: ='Historical Financials'!H8 -> 45016 | I4: ='Historical Financials'!I8 -> 45107 | J4: ='Historical Financials'!J8 -> 45199 | K4: ='Historical Financials'!K8 -> 44926 | L4: ='Historical Financials'!L8 -> 45382 | M4: ='Historical Financials'!M8 -> 45473 | N4: ='Historical Financials'!N8 -> 45565 | O4: ='Historical Financials'!O8 -> 45291 | ... Q4: ='Historical Financials'!Q8 -> 45838 | S4: =K4 -> 44926 | T4: =L4 -> 45382 | U4: =M4 -> 45473 | V4: =N4 -> 45565 | W4: =O4 -> 45291 | X4: =P4 -> 45747 | Y4: =Q4 -> 45838
A6: X | B6: Revenue by reportable segment
A8: X | B8: Revenue by Type
B9: Advertising | C9: 11412 | D9: 10890 | E9: 9989 | F9: 10295 | H9: 2651 | I9: 2395 | J9: 2133 | K9: =SUM(E9-SUM(H9:J9)) -> 2810 | L9: 3096 | M9: 2251 | N9: 2174 | O9: =SUM(F9-SUM(L9:N9)) -> 2774 | P9: 2513 | Q9: 2152 | S9: =SUM(H9:K9) -> 9989 | T9: =SUM(I9:L9) -> 10434 | U9: =SUM(J9:M9) -> 10290 | V9: =SUM(K9:N9) -> 10331 | W9: =SUM(L9:O9) -> 10295 | X9: =SUM(M9:P9) -> 9712 | Y9: =SUM(N9:Q9) -> 9613
B10: Affiliate and subscription | C10: 10442 | D10: 11551 | E10: 13018 | F10: 13153 | H10: 3179 | I10: 3235 | J10: 3262 | K10: =SUM(E10-SUM(H10:J10)) -> 3342 | L10: 3357 | M10: 3275 | N10: 3215 | O10: =SUM(F10-SUM(L10:N10)) -> 3306 | P10: 3397 | Q10: 3445 | S10: =SUM(H10:K10) -> 13018 | T10: =SUM(I10:L10) -> 13196 | U10: =SUM(J10:M10) -> 13236 | V10: =SUM(K10:N10) -> 13189 | W10: =SUM(L10:O10) -> 13153 | X10: =SUM(M10:P10) -> 13193 | Y10: =SUM(N10:Q10) -> 13363
B11: Theatrical | C11: 241 | D11: 1223 | E11: 813 | F11: 813 | H11: 127 | I11: 231 | J11: 377 | K11: =SUM(E11-SUM(H11:J11)) -> 78 | L11: 153 | M11: 138 | N11: 108 | O11: =SUM(F11-SUM(L11:N11)) -> 414 | P11: 148 | Q11: 254 | S11: =SUM(H11:K11) -> 813 | T11: =SUM(I11:L11) -> 839 | U11: =SUM(J11:M11) -> 746 | V11: =SUM(K11:N11) -> 477 | W11: =SUM(L11:O11) -> 813 | X11: =SUM(M11:P11) -> 808 | Y11: =SUM(N11:Q11) -> 924
B12: Licensing and other | C12: 6491 | D12: 6490 | E12: 5832 | F12: 4952 | H12: 1308 | I12: 1755 | J12: 1361 | K12: =SUM(E12-SUM(H12:J12)) -> 1408 | L12: 1079 | M12: 1149 | N12: 1234 | O12: =SUM(F12-SUM(L12:N12)) -> 1490 | P12: 1134 | Q12: 998 | S12: =SUM(H12:K12) -> 5832 | T12: =SUM(I12:L12) -> 5603 | U12: =SUM(J12:M12) -> 4997 | V12: =SUM(K12:N12) -> 4870 | W12: =SUM(L12:O12) -> 4952 | X12: =SUM(M12:P12) -> 5007 | Y12: =SUM(N12:Q12) -> 4856
B13: Total Net Revenue | C13: =SUM(C9:C12) -> 28586 | D13: =SUM(D9:D12) -> 30154 | E13: =SUM(E9:E12) -> 29652 | F13: =SUM(F9:F12) -> 29213 | H13: =SUM(H9:H12) -> 7265 | I13: =SUM(I9:I12) -> 7616 | J13: =SUM(J9:J12) -> 7133 | K13: =SUM(K9:K12) -> 7638 | L13: =SUM(L9:L12) -> 7685 | M13: =SUM(M9:M12) -> 6813 | N13: =SUM(N9:N12) -> 6731 | O13: =SUM(O9:O12) -> 7984 | ... Q13: =SUM(Q9:Q12) -> 6849 | S13: =SUM(S9:S12) -> 29652 | T13: =SUM(T9:T12) -> 30072 | U13: =SUM(U9:U12) -> 29269 | V13: =SUM(V9:V12) -> 28867 | W13: =SUM(W9:W12) -> 29213 | X13: =SUM(X9:X12) -> 28720 | Y13: =SUM(Y9:Y12) -> 28756
B14: Variance Check | C14: =+C13-'Historical Financials'!C11 -> 0 | D14: =+D13-'Historical Financials'!D11 -> 0 | E14: =+E13-'Historical Financials'!E11 -> 0 | F14: =+F13-'Historical Financials'!F11 -> 0 | H14: =+H13-'Historical Financials'!H11 -> 0 | I14: =+I13-'Historical Financials'!I11 -> 0 | J14: =+J13-'Historical Financials'!J11 -> 0 | K14: =+K13-'Historical Financials'!K11 -> 0 | L14: =+L13-'Historical Financials'!L11 -> 0 | M14: =+M13-'Historical Financials'!M11 -> 0 | N14: =+N13-'Historical Financials'!N11 -> 0 | O14: =+O13-'Historical Financials'!O11 -> 0 | ... Q14: =+Q13-'Historical Financials'!Q11 -> 0 | S14: =+S13-'Historical Financials'!S11 -> 0 | T14: =+T13-'Historical Financials'!T11 -> 0 | U14: =+U13-'Historical Financials'!U11 -> 0 | V14: =+V13-'Historical Financials'!V11 -> 0 | W14: =+W13-'Historical Financials'!W11 -> 0 | X14: =+X13-'Historical Financials'!X11 -> 0 | Y14: =+Y13-'Historical Financials'!Y11 -> 0
B16: =B9&"(%)" -> Advertising(%) | C16: =SUM(C9/C$13) -> 0.3992164 | D16: =SUM(D9/D$13) -> 0.36114612 | E16: =SUM(E9/E$13) -> 0.33687441 | F16: =SUM(F9/F$13) -> 0.3524116 | H16: =SUM(H9/H$13) -> 0.36490021 | I16: =SUM(I9/I$13) -> 0.31446954 | J16: =SUM(J9/J$13) -> 0.29903267 | K16: =SUM(K9/K$13) -> 0.36789736 | L16: =SUM(L9/L$13) -> 0.40286272 | M16: =SUM(M9/M$13) -> 0.33039777 | N16: =SUM(N9/N$13) -> 0.32298321 | O16: =SUM(O9/O$13) -> 0.34744489 | ... Q16: =SUM(Q9/Q$13) -> 0.31420645 | S16: =SUM(S9/S$13) -> 0.33687441 | T16: =SUM(T9/T$13) -> 0.34696728 | U16: =SUM(U9/U$13) -> 0.3515665 | V16: =SUM(V9/V$13) -> 0.3578827 | W16: =SUM(W9/W$13) -> 0.3524116 | X16: =SUM(X9/X$13) -> 0.33816156 | Y16: =SUM(Y9/Y$13) -> 0.33429545
B17: =B10&"(%)" -> Affiliate and subscription(%) | C17: =SUM(C10/C$13) -> 0.36528371 | D17: =SUM(D10/D$13) -> 0.38306692 | E17: =SUM(E10/E$13) -> 0.43902604 | F17: =SUM(F10/F$13) -> 0.45024475 | H17: =SUM(H10/H$13) -> 0.43757743 | I17: =SUM(I10/I$13) -> 0.42476366 | J17: =SUM(J10/J$13) -> 0.45731109 | K17: =SUM(K10/K$13) -> 0.4375491 | L17: =SUM(L10/L$13) -> 0.43682498 | M17: =SUM(M10/M$13) -> 0.48069866 | N17: =SUM(N10/N$13) -> 0.47764077 | O17: =SUM(O10/O$13) -> 0.41407816 | ... Q17: =SUM(Q10/Q$13) -> 0.50299314 | S17: =SUM(S10/S$13) -> 0.43902604 | T17: =SUM(T10/T$13) -> 0.43881351 | U17: =SUM(U10/U$13) -> 0.45221907 | V17: =SUM(V10/V$13) -> 0.45688849 | W17: =SUM(W10/W$13) -> 0.45024475 | X17: =SUM(X10/X$13) -> 0.4593663 | Y17: =SUM(Y10/Y$13) -> 0.46470302
B18: =B11&"(%)" -> Theatrical(%) | C18: =SUM(C11/C$13) -> 0.0084307003 | D18: =SUM(D11/D$13) -> 0.040558467 | E18: =SUM(E11/E$13) -> 0.027418049 | F18: =SUM(F11/F$13) -> 0.027830076 | H18: =SUM(H11/H$13) -> 0.017481074 | I18: =SUM(I11/I$13) -> 0.030330882 | J18: =SUM(J11/J$13) -> 0.052852937 | K18: =SUM(K11/K$13) -> 0.010212097 | L18: =SUM(L11/L$13) -> 0.019908913 | M18: =SUM(M11/M$13) -> 0.020255394 | N18: =SUM(N11/N$13) -> 0.016045164 | O18: =SUM(O11/O$13) -> 0.051853707 | ... Q18: =SUM(Q11/Q$13) -> 0.037085706 | S18: =SUM(S11/S$13) -> 0.027418049 | T18: =SUM(T11/T$13) -> 0.027899707 | U18: =SUM(U11/U$13) -> 0.025487717 | V18: =SUM(V11/V$13) -> 0.016524059 | W18: =SUM(W11/W$13) -> 0.027830076 | X18: =SUM(X11/X$13) -> 0.028133705 | Y18: =SUM(Y11/Y$13) -> 0.032132425
B19: =B12&"(%)" -> Licensing and other(%) | C19: =SUM(C12/C$13) -> 0.22706919 | D19: =SUM(D12/D$13) -> 0.21522849 | E19: =SUM(E12/E$13) -> 0.19668151 | F19: =SUM(F12/F$13) -> 0.16951357 | H19: =SUM(H12/H$13) -> 0.18004129 | I19: =SUM(I12/I$13) -> 0.23043592 | J19: =SUM(J12/J$13) -> 0.19080331 | K19: =SUM(K12/K$13) -> 0.18434145 | L19: =SUM(L12/L$13) -> 0.14040338 | M19: =SUM(M12/M$13) -> 0.16864817 | N19: =SUM(N12/N$13) -> 0.18333086 | O19: =SUM(O12/O$13) -> 0.18662325 | ... Q19: =SUM(Q12/Q$13) -> 0.1457147 | S19: =SUM(S12/S$13) -> 0.19668151 | T19: =SUM(T12/T$13) -> 0.1863195 | U19: =SUM(U12/U$13) -> 0.17072671 | V19: =SUM(V12/V$13) -> 0.16870475 | W19: =SUM(W12/W$13) -> 0.16951357 | X19: =SUM(X12/X$13) -> 0.17433844 | Y19: =SUM(Y12/Y$13) -> 0.16886911
A21: X | B21: Revenue by Type
B22: TV Media | C22: 22734 | D22: 21732 | E22: 20085 | F22: 18779 | H22: 5193 | I22: 5157 | J22: 4567 | K22: =SUM(E22-SUM(H22:J22)) -> 5168 | L22: 5231 | M22: 4271 | N22: 4298 | O22: =SUM(F22-SUM(L22:N22)) -> 4979 | P22: 4538 | Q22: 4011 | S22: =SUM(H22:K22) -> 20085 | T22: =SUM(I22:L22) -> 20123 | U22: =SUM(J22:M22) -> 19237 | V22: =SUM(K22:N22) -> 18968 | W22: =SUM(L22:O22) -> 18779 | X22: =SUM(M22:P22) -> 18086 | Y22: =SUM(N22:Q22) -> 17826
B23: Direct-to-Consumer | C23: 3327 | D23: 4904 | E23: 6736 | F23: 7632 | H23: 1510 | I23: 1665 | J23: 1692 | K23: =SUM(E23-SUM(H23:J23)) -> 1869 | L23: 1879 | M23: 1880 | N23: 1860 | O23: =SUM(F23-SUM(L23:N23)) -> 2013 | P23: 2044 | Q23: 2160 | S23: =SUM(H23:K23) -> 6736 | T23: =SUM(I23:L23) -> 7105 | U23: =SUM(J23:M23) -> 7320 | V23: =SUM(K23:N23) -> 7488 | W23: =SUM(L23:O23) -> 7632 | X23: =SUM(M23:P23) -> 7797 | Y23: =SUM(N23:Q23) -> 8077
B24: Filmed Entertainment | C24: 2687 | D24: 3706 | E24: 2957 | F24: 2955 | H24: 588 | I24: 831 | J24: 891 | K24: =SUM(E24-SUM(H24:J24)) -> 647 | L24: 605 | M24: 679 | N24: 590 | O24: =SUM(F24-SUM(L24:N24)) -> 1081 | P24: 627 | Q24: 690 | S24: =SUM(H24:K24) -> 2957 | T24: =SUM(I24:L24) -> 2974 | U24: =SUM(J24:M24) -> 2822 | V24: =SUM(K24:N24) -> 2521 | W24: =SUM(L24:O24) -> 2955 | X24: =SUM(M24:P24) -> 2977 | Y24: =SUM(N24:Q24) -> 2988
B25: Eliminations | C25: -162 | D25: -188 | E25: -126 | F25: -153 | H25: -26 | I25: -37 | J25: -17 | K25: =SUM(E25-SUM(H25:J25)) -> -46 | L25: -30 | M25: -17 | N25: -17 | O25: =SUM(F25-SUM(L25:N25)) -> -89 | P25: -17 | Q25: -12 | S25: =SUM(H25:K25) -> -126 | T25: =SUM(I25:L25) -> -130 | U25: =SUM(J25:M25) -> -110 | V25: =SUM(K25:N25) -> -110 | W25: =SUM(L25:O25) -> -153 | X25: =SUM(M25:P25) -> -140 | Y25: =SUM(N25:Q25) -> -135
B26: Total Net Revenue | C26: =SUM(C22:C25) -> 28586 | D26: =SUM(D22:D25) -> 30154 | E26: =SUM(E22:E25) -> 29652 | F26: =SUM(F22:F25) -> 29213 | H26: =SUM(H22:H25) -> 7265 | I26: =SUM(I22:I25) -> 7616 | J26: =SUM(J22:J25) -> 7133 | K26: =SUM(K22:K25) -> 7638 | L26: =SUM(L22:L25) -> 7685 | M26: =SUM(M22:M25) -> 6813 | N26: =SUM(N22:N25) -> 6731 | O26: =SUM(O22:O25) -> 7984 | ... Q26: =SUM(Q22:Q25) -> 6849 | S26: =SUM(S22:S25) -> 29652 | T26: =SUM(T22:T25) -> 30072 | U26: =SUM(U22:U25) -> 29269 | V26: =SUM(V22:V25) -> 28867 | W26: =SUM(W22:W25) -> 29213 | X26: =SUM(X22:X25) -> 28720 | Y26: =SUM(Y22:Y25) -> 28756
B27: Variance Check | C27: =+C26-C13 -> 0 | D27: =+D26-D13 -> 0 | E27: =+E26-E13 -> 0 | F27: =+F26-F13 -> 0 | H27: =+H26-H13 -> 0 | I27: =+I26-I13 -> 0 | J27: =+J26-J13 -> 0 | K27: =+K26-K13 -> 0 | L27: =+L26-L13 -> 0 | M27: =+M26-M13 -> 0 | N27: =+N26-N13 -> 0 | O27: =+O26-O13 -> 0 | ... Q27: =+Q26-Q13 -> 0 | S27: =+S26-S13 -> 0 | T27: =+T26-T13 -> 0 | U27: =+U26-U13 -> 0 | V27: =+V26-V13 -> 0 | W27: =+W26-W13 -> 0 | X27: =+X26-X13 -> 0 | Y27: =+Y26-Y13 -> 0
B29: =B22&"(%)" -> TV Media(%) | C29: =SUM(C22/C$26) -> 0.7952844 | D29: =SUM(D22/D$26) -> 0.7207004 | E29: =SUM(E22/E$26) -> 0.67735735 | F29: =SUM(F22/F$26) -> 0.64283025 | H29: =SUM(H22/H$26) -> 0.71479697 | I29: =SUM(I22/I$26) -> 0.6771271 | J29: =SUM(J22/J$26) -> 0.64026356 | K29: =SUM(K22/K$26) -> 0.67661692 | L29: =SUM(L22/L$26) -> 0.68067664 | M29: =SUM(M22/M$26) -> 0.62688977 | N29: =SUM(N22/N$26) -> 0.63853811 | O29: =SUM(O22/O$26) -> 0.62362224 | ... Q29: =SUM(Q22/Q$26) -> 0.58563294 | S29: =SUM(S22/S$26) -> 0.67735735 | T29: =SUM(T22/T$26) -> 0.66916068 | U29: =SUM(U22/U$26) -> 0.65724828 | V29: =SUM(V22/V$26) -> 0.65708248 | W29: =SUM(W22/W$26) -> 0.64283025 | X29: =SUM(X22/X$26) -> 0.62973538 | Y29: =SUM(Y22/Y$26) -> 0.61990541
B30: =B23&"(%)" -> Direct-to-Consumer(%) | C30: =SUM(C23/C$26) -> 0.11638564 | D30: =SUM(D23/D$26) -> 0.16263182 | E30: =SUM(E23/E$26) -> 0.22716849 | F30: =SUM(F23/F$26) -> 0.26125355 | H30: =SUM(H23/H$26) -> 0.20784584 | I30: =SUM(I23/I$26) -> 0.2186187 | J30: =SUM(J23/J$26) -> 0.23720735 | K30: =SUM(K23/K$26) -> 0.24469756 | L30: =SUM(L23/L$26) -> 0.24450228 | M30: =SUM(M23/M$26) -> 0.27594305 | N30: =SUM(N23/N$26) -> 0.27633338 | O30: =SUM(O23/O$26) -> 0.25212926 | ... Q30: =SUM(Q23/Q$26) -> 0.31537451 | S30: =SUM(S23/S$26) -> 0.22716849 | T30: =SUM(T23/T$26) -> 0.23626629 | U30: =SUM(U23/U$26) -> 0.25009396 | V30: =SUM(V23/V$26) -> 0.25939654 | W30: =SUM(W23/W$26) -> 0.26125355 | X30: =SUM(X23/X$26) -> 0.27148329 | Y30: =SUM(Y23/Y$26) -> 0.28088051
B31: =B24&"(%)" -> Filmed Entertainment(%) | C31: =SUM(C24/C$26) -> 0.093997061 | D31: =SUM(D24/D$26) -> 0.12290243 | E31: =SUM(E24/E$26) -> 0.099723459 | F31: =SUM(F24/F$26) -> 0.1011536 | H31: =SUM(H24/H$26) -> 0.080935994 | I31: =SUM(I24/I$26) -> 0.10911239 | J31: =SUM(J24/J$26) -> 0.12491238 | K31: =SUM(K24/K$26) -> 0.084708039 | L31: =SUM(L24/L$26) -> 0.078724789 | M31: =SUM(M24/M$26) -> 0.09966241 | N31: =SUM(N24/N$26) -> 0.087654138 | O31: =SUM(O24/O$26) -> 0.13539579 | ... Q31: =SUM(Q24/Q$26) -> 0.10074463 | S31: =SUM(S24/S$26) -> 0.099723459 | T31: =SUM(T24/T$26) -> 0.098895983 | U31: =SUM(U24/U$26) -> 0.096416003 | V31: =SUM(V24/V$26) -> 0.087331555 | W31: =SUM(W24/W$26) -> 0.1011536 | X31: =SUM(X24/X$26) -> 0.10365599 | Y31: =SUM(Y24/Y$26) -> 0.10390875
A33: X | B33: Revenue by product category: Revenue by TV Media
A35: X | B35: Revenue by TV Media
B36: Advertising | C36: 10105 | D36: 9350 | E36: 8188 | F36: 8180 | H36: 2256 | I36: 1946 | J36: 1703 | K36: =SUM(E36-SUM(H36:J36)) -> 2283 | L36: 2582 | M36: 1733 | N36: 1666 | O36: =SUM(F36-SUM(L36:N36)) -> 2199 | P36: 2038 | Q36: 1657 | S36: =SUM(H36:K36) -> 8188 | T36: =SUM(I36:L36) -> 8514 | U36: =SUM(J36:M36) -> 8301 | V36: =SUM(K36:N36) -> 8264 | W36: =SUM(L36:O36) -> 8180 | X36: =SUM(M36:P36) -> 7636 | Y36: =SUM(N36:Q36) -> 7560
B37: Affiliate and subscription | C37: 8413 | D37: 8180 | E37: 8085 | F37: 7647 | H37: 2067 | I37: 2011 | J37: 2004 | K37: =SUM(E37-SUM(H37:J37)) -> 2003 | L37: 1998 | M37: 1908 | N37: 1872 | O37: =SUM(F37-SUM(L37:N37)) -> 1869 | P37: 1826 | Q37: 1780 | S37: =SUM(H37:K37) -> 8085 | T37: =SUM(I37:L37) -> 8016 | U37: =SUM(J37:M37) -> 7913 | V37: =SUM(K37:N37) -> 7781 | W37: =SUM(L37:O37) -> 7647 | X37: =SUM(M37:P37) -> 7475 | Y37: =SUM(N37:Q37) -> 7347
B38: Licensing and other | C38: 4216 | D38: 4202 | E38: 3812 | F38: 2952 | H38: 870 | I38: 1200 | J38: 860 | K38: =SUM(E38-SUM(H38:J38)) -> 882 | L38: 651 | M38: 630 | N38: 760 | O38: =SUM(F38-SUM(L38:N38)) -> 911 | P38: 674 | Q38: 574 | S38: =SUM(H38:K38) -> 3812 | T38: =SUM(I38:L38) -> 3593 | U38: =SUM(J38:M38) -> 3023 | V38: =SUM(K38:N38) -> 2923 | W38: =SUM(L38:O38) -> 2952 | X38: =SUM(M38:P38) -> 2975 | Y38: =SUM(N38:Q38) -> 2919
B39: Total Revenue from TV Media | C39: =SUM(C36:C38) -> 22734 | D39: =SUM(D36:D38) -> 21732 | E39: =SUM(E36:E38) -> 20085 | F39: =SUM(F36:F38) -> 18779 | H39: =SUM(H36:H38) -> 5193 | I39: =SUM(I36:I38) -> 5157 | J39: =SUM(J36:J38) -> 4567 | K39: =SUM(K36:K38) -> 5168 | L39: =SUM(L36:L38) -> 5231 | M39: =SUM(M36:M38) -> 4271 | N39: =SUM(N36:N38) -> 4298 | O39: =SUM(O36:O38) -> 4979 | ... Q39: =SUM(Q36:Q38) -> 4011 | S39: =SUM(S36:S38) -> 20085 | T39: =SUM(T36:T38) -> 20123 | U39: =SUM(U36:U38) -> 19237 | V39: =SUM(V36:V38) -> 18968 | W39: =SUM(W36:W38) -> 18779 | X39: =SUM(X36:X38) -> 18086 | Y39: =SUM(Y36:Y38) -> 17826
B40: Variance Check | C40: =+C39-C22 -> 0 | D40: =+D39-D22 -> 0 | E40: =+E39-E22 -> 0 | F40: =+F39-F22 -> 0 | H40: =+H39-H22 -> 0 | I40: =+I39-I22 -> 0 | J40: =+J39-J22 -> 0 | K40: =+K39-K22 -> 0 | L40: =+L39-L22 -> 0 | M40: =+M39-M22 -> 0 | N40: =+N39-N22 -> 0 | O40: =+O39-O22 -> 0 | ... Q40: =+Q39-Q22 -> 0 | S40: =+S39-S22 -> 0 | T40: =+T39-T22 -> 0 | U40: =+U39-U22 -> 0 | V40: =+V39-V22 -> 0 | W40: =+W39-W22 -> 0 | X40: =+X39-X22 -> 0 | Y40: =+Y39-Y22 -> 0
B42: =B36&"(%)" -> Advertising(%) | C42: =C36/C$39 -> 0.44448843 | D42: =D36/D$39 -> 0.43024112 | E42: =E36/E$39 -> 0.40766741 | F42: =F36/F$39 -> 0.43559295 | H42: =H36/H$39 -> 0.43443096 | I42: =I36/I$39 -> 0.37735117 | J42: =J36/J$39 -> 0.37289249 | K42: =K36/K$39 -> 0.44175697 | L42: =L36/L$39 -> 0.49359587 | M42: =M36/M$39 -> 0.40575978 | N42: =N36/N$39 -> 0.38762215 | O42: =O36/O$39 -> 0.44165495 | ... Q42: =Q36/Q$39 -> 0.41311394 | S42: =S36/S$39 -> 0.40766741 | T42: =T36/T$39 -> 0.42309795 | U42: =U36/U$39 -> 0.43151219 | V42: =V36/V$39 -> 0.43568115 | W42: =W36/W$39 -> 0.43559295 | X42: =X36/X$39 -> 0.42220502 | Y42: =Y36/Y$39 -> 0.42409963
B43: =B37&"(%)" -> Affiliate and subscription(%) | C43: =C37/C$39 -> 0.37006246 | D43: =D37/D$39 -> 0.37640346 | E43: =E37/E$39 -> 0.40253921 | F43: =F37/F$39 -> 0.40721018 | H43: =H37/H$39 -> 0.39803582 | I43: =I37/I$39 -> 0.3899554 | J43: =J37/J$39 -> 0.43880009 | K43: =K37/K$39 -> 0.3875774 | L43: =L37/L$39 -> 0.38195374 | M43: =M37/M$39 -> 0.44673379 | N43: =N37/N$39 -> 0.43555142 | O43: =O37/O$39 -> 0.37537658 | ... Q43: =Q37/Q$39 -> 0.44377961 | S43: =S37/S$39 -> 0.40253921 | T43: =T37/T$39 -> 0.39835015 | U43: =U37/U$39 -> 0.41134272 | V43: =V37/V$39 -> 0.41021721 | W43: =W37/W$39 -> 0.40721018 | X43: =X37/X$39 -> 0.41330311 | Y43: =Y37/Y$39 -> 0.41215079
B44: =B38&"(%)" -> Licensing and other(%) | C44: =C38/C$39 -> 0.18544911 | D44: =D38/D$39 -> 0.19335542 | E44: =E38/E$39 -> 0.18979338 | F44: =F38/F$39 -> 0.15719687 | H44: =H38/H$39 -> 0.16753322 | I44: =I38/I$39 -> 0.23269343 | J44: =J38/J$39 -> 0.18830742 | K44: =K38/K$39 -> 0.17066563 | L44: =L38/L$39 -> 0.12445039 | M44: =M38/M$39 -> 0.14750644 | N44: =N38/N$39 -> 0.17682643 | O44: =O38/O$39 -> 0.18296847 | ... Q44: =Q38/Q$39 -> 0.14310646 | S44: =S38/S$39 -> 0.18979338 | T44: =T38/T$39 -> 0.17855191 | U44: =U38/U$39 -> 0.15714508 | V44: =V38/V$39 -> 0.15410164 | W44: =W38/W$39 -> 0.15719687 | X44: =X38/X$39 -> 0.16449187 | Y44: =Y38/Y$39 -> 0.16374958
A46: X | B46: Revenue by product category: Direct to Consumer
A48: X | B48: Revenue by Direct-to-Consumer
B49: Advertising | C49: 1298 | D49: 1533 | E49: 1795 | F49: 2114 | H49: 398 | I49: 441 | J49: 430 | K49: =SUM(E49-SUM(H49:J49)) -> 526 | L49: 520 | M49: 513 | N49: 507 | O49: =SUM(F49-SUM(L49:N49)) -> 574 | P49: 473 | Q49: 494 | S49: =SUM(H49:K49) -> 1795 | T49: =SUM(I49:L49) -> 1917 | U49: =SUM(J49:M49) -> 1989 | V49: =SUM(K49:N49) -> 2066 | W49: =SUM(L49:O49) -> 2114 | X49: =SUM(M49:P49) -> 2067 | Y49: =SUM(N49:Q49) -> 2048
B50: Subscription & Licensing | C50: 2029 | D50: 3371 | E50: =4933+8 -> 4941 | F50: =5506+12 -> 5518 | H50: 1112 | I50: 1224 | J50: =1258+4 -> 1262 | K50: =SUM(E50-SUM(H50:J50)) -> 1343 | L50: 1359 | M50: 1367 | N50: =1343+10 -> 1353 | O50: =SUM(F50-SUM(L50:N50)) -> 1439 | P50: 1571 | Q50: =1665+1 -> 1666 | S50: =SUM(H50:K50) -> 4941 | T50: =SUM(I50:L50) -> 5188 | U50: =SUM(J50:M50) -> 5331 | V50: =SUM(K50:N50) -> 5422 | W50: =SUM(L50:O50) -> 5518 | X50: =SUM(M50:P50) -> 5730 | Y50: =SUM(N50:Q50) -> 6029
B51: Total Revenue from Direct-to-Consumer | C51: =SUM(C49:C50) -> 3327 | D51: =SUM(D49:D50) -> 4904 | E51: =SUM(E49:E50) -> 6736 | F51: =SUM(F49:F50) -> 7632 | H51: =SUM(H49:H50) -> 1510 | I51: =SUM(I49:I50) -> 1665 | J51: =SUM(J49:J50) -> 1692 | K51: =SUM(K49:K50) -> 1869 | L51: =SUM(L49:L50) -> 1879 | M51: =SUM(M49:M50) -> 1880 | N51: =SUM(N49:N50) -> 1860 | O51: =SUM(O49:O50) -> 2013 | ... Q51: =SUM(Q49:Q50) -> 2160 | S51: =SUM(S49:S50) -> 6736 | T51: =SUM(T49:T50) -> 7105 | U51: =SUM(U49:U50) -> 7320 | V51: =SUM(V49:V50) -> 7488 | W51: =SUM(W49:W50) -> 7632 | X51: =SUM(X49:X50) -> 7797 | Y51: =SUM(Y49:Y50) -> 8077
...

Sheet FCF
B2: ='Historical Financials'!B2 -> Paramount Global (NASDAQ: PARA) | D2: FYE | H2: Quarterly | T2: LTM | U2: LTM | AA2: Variance
B3: FCF Analysis | C3: ='Historical Financials'!C7 -> 2021 | D3: ='Historical Financials'!D7 -> 2022 | E3: ='Historical Financials'!E7 -> 2023 | F3: ='Historical Financials'!F7 -> 2024 | H3: ='Historical Financials'!H7 -> 1Q23 | I3: ='Historical Financials'!I7 -> 2Q23 | J3: ='Historical Financials'!J7 -> 3Q23 | K3: ='Historical Financials'!K7 -> 4Q23 | L3: ='Historical Financials'!L7 -> 1Q24 | M3: ='Historical Financials'!M7 -> 2Q24 | N3: ='Historical Financials'!N7 -> 3Q24 | O3: ='Historical Financials'!O7 -> 4Q24 | ... Q3: ='Historical Financials'!Q7 -> 2Q25 | S3: =K3 -> 4Q23 | T3: =L3 -> 1Q24 | U3: =M3 -> 2Q24 | V3: =N3 -> 3Q24 | W3: =O3 -> 4Q24 | X3: =P3 -> 1Q25 | Y3: =Q3 -> 2Q25
B4: ($ In Millions) | C4: ='Historical Financials'!C8 -> 44561 | D4: ='Historical Financials'!D8 -> 44926 | E4: ='Historical Financials'!E8 -> 45291 | F4: ='Historical Financials'!F8 -> 45657 | H4: ='Historical Financials'!H8 -> 45016 | I4: ='Historical Financials'!I8 -> 45107 | J4: ='Historical Financials'!J8 -> 45199 | K4: ='Historical Financials'!K8 -> 44926 | L4: ='Historical Financials'!L8 -> 45382 | M4: ='Historical Financials'!M8 -> 45473 | N4: ='Historical Financials'!N8 -> 45565 | O4: ='Historical Financials'!O8 -> 45291 | ... Q4: ='Historical Financials'!Q8 -> 45838 | S4: =K4 -> 44926 | T4: =L4 -> 45382 | U4: =M4 -> 45473 | V4: =N4 -> 45565 | W4: =O4 -> 45291 | X4: =P4 -> 45747 | Y4: =Q4 -> 45838
B6: ='Revenue Drivers'!B9 -> Advertising | C6: ='Revenue Drivers'!C9 -> 11412 | D6: ='Revenue Drivers'!D9 -> 10890 | E6: ='Revenue Drivers'!E9 -> 9989 | F6: ='Revenue Drivers'!F9 -> 10295 | H6: ='Revenue Drivers'!H9 -> 2651 | I6: ='Revenue Drivers'!I9 -> 2395 | J6: ='Revenue Drivers'!J9 -> 2133 | K6: ='Revenue Drivers'!K9 -> 2810 | L6: ='Revenue Drivers'!L9 -> 3096 | M6: ='Revenue Drivers'!M9 -> 2251 | N6: ='Revenue Drivers'!N9 -> 2174 | O6: ='Revenue Drivers'!O9 -> 2774 | ... Q6: ='Revenue Drivers'!Q9 -> 2152 | S6: =SUM(H6:K6) -> 9989 | T6: =SUM(I6:L6) -> 10434 | U6: =SUM(J6:M6) -> 10290 | V6: =SUM(K6:N6) -> 10331 | W6: =SUM(L6:O6) -> 10295 | X6: =SUM(M6:P6) -> 9712 | Y6: =SUM(N6:Q6) -> 9613 | AA6: =SUM(Y6/U6)-1 -> -0.065792031
B7: ='Revenue Drivers'!B10 -> Affiliate and subscription | C7: ='Revenue Drivers'!C10 -> 10442 | D7: ='Revenue Drivers'!D10 -> 11551 | E7: ='Revenue Drivers'!E10 -> 13018 | F7: ='Revenue Drivers'!F10 -> 13153 | H7: ='Revenue Drivers'!H10 -> 3179 | I7: ='Revenue Drivers'!I10 -> 3235 | J7: ='Revenue Drivers'!J10 -> 3262 | K7: ='Revenue Drivers'!K10 -> 3342 | L7: ='Revenue Drivers'!L10 -> 3357 | M7: ='Revenue Drivers'!M10 -> 3275 | N7: ='Revenue Drivers'!N10 -> 3215 | O7: ='Revenue Drivers'!O10 -> 3306 | ... Q7: ='Revenue Drivers'!Q10 -> 3445 | S7: =SUM(H7:K7) -> 13018 | T7: =SUM(I7:L7) -> 13196 | U7: =SUM(J7:M7) -> 13236 | V7: =SUM(K7:N7) -> 13189 | W7: =SUM(L7:O7) -> 13153 | X7: =SUM(M7:P7) -> 13193 | Y7: =SUM(N7:Q7) -> 13363 | AA7: =SUM(Y7/U7)-1 -> 0.0095950438
B8: ='Revenue Drivers'!B11 -> Theatrical | C8: ='Revenue Drivers'!C11 -> 241 | D8: ='Revenue Drivers'!D11 -> 1223 | E8: ='Revenue Drivers'!E11 -> 813 | F8: ='Revenue Drivers'!F11 -> 813 | H8: ='Revenue Drivers'!H11 -> 127 | I8: ='Revenue Drivers'!I11 -> 231 | J8: ='Revenue Drivers'!J11 -> 377 | K8: ='Revenue Drivers'!K11 -> 78 | L8: ='Revenue Drivers'!L11 -> 153 | M8: ='Revenue Drivers'!M11 -> 138 | N8: ='Revenue Drivers'!N11 -> 108 | O8: ='Revenue Drivers'!O11 -> 414 | ... Q8: ='Revenue Drivers'!Q11 -> 254 | S8: =SUM(H8:K8) -> 813 | T8: =SUM(I8:L8) -> 839 | U8: =SUM(J8:M8) -> 746 | V8: =SUM(K8:N8) -> 477 | W8: =SUM(L8:O8) -> 813 | X8: =SUM(M8:P8) -> 808 | Y8: =SUM(N8:Q8) -> 924 | AA8: =SUM(Y8/U8)-1 -> 0.2386059
B9: ='Revenue Drivers'!B12 -> Licensing and other | C9: ='Revenue Drivers'!C12 -> 6491 | D9: ='Revenue Drivers'!D12 -> 6490 | E9: ='Revenue Drivers'!E12 -> 5832 | F9: ='Revenue Drivers'!F12 -> 4952 | H9: ='Revenue Drivers'!H12 -> 1308 | I9: ='Revenue Drivers'!I12 -> 1755 | J9: ='Revenue Drivers'!J12 -> 1361 | K9: ='Revenue Drivers'!K12 -> 1408 | L9: ='Revenue Drivers'!L12 -> 1079 | M9: ='Revenue Drivers'!M12 -> 1149 | N9: ='Revenue Drivers'!N12 -> 1234 | O9: ='Revenue Drivers'!O12 -> 1490 | ... Q9: ='Revenue Drivers'!Q12 -> 998 | S9: =SUM(H9:K9) -> 5832 | T9: =SUM(I9:L9) -> 5603 | U9: =SUM(J9:M9) -> 4997 | V9: =SUM(K9:N9) -> 4870 | W9: =SUM(L9:O9) -> 4952 | X9: =SUM(M9:P9) -> 5007 | Y9: =SUM(N9:Q9) -> 4856 | AA9: =SUM(Y9/U9)-1 -> -0.02821693
B10: Total Revenue | C10: =SUM(C6:C9) -> 28586 | D10: =SUM(D6:D9) -> 30154 | E10: =SUM(E6:E9) -> 29652 | F10: =SUM(F6:F9) -> 29213 | H10: =SUM(H6:H9) -> 7265 | I10: =SUM(I6:I9) -> 7616 | J10: =SUM(J6:J9) -> 7133 | K10: =SUM(K6:K9) -> 7638 | L10: =SUM(L6:L9) -> 7685 | M10: =SUM(M6:M9) -> 6813 | N10: =SUM(N6:N9) -> 6731 | O10: =SUM(O6:O9) -> 7984 | ... Q10: =SUM(Q6:Q9) -> 6849 | S10: =SUM(S6:S9) -> 29652 | T10: =SUM(T6:T9) -> 30072 | U10: =SUM(U6:U9) -> 29269 | V10: =SUM(V6:V9) -> 28867 | W10: =SUM(W6:W9) -> 29213 | X10: =SUM(X6:X9) -> 28720 | Y10: =SUM(Y6:Y9) -> 28756 | AA10: =SUM(Y10/U10)-1 -> -0.017527076
B11: Y/Y Growth (%) | D11: =SUM(D10/C10)-1 -> 0.054852025 | E11: =SUM(E10/D10)-1 -> -0.016647874 | F11: =SUM(F10/E10)-1 -> -0.014805072 | L11: =SUM(L10/H10)-1 -> 0.057811425 | M11: =SUM(M10/I10)-1 -> -0.10543592 | N11: =SUM(N10/J10)-1 -> -0.056357774 | O11: =SUM(O10/K10)-1 -> 0.045299817 | P11: =SUM(P10/L10)-1 -> -0.064150943 | Q11: =SUM(Q10/M10)-1 -> 0.0052840159 | W11: =SUM(W10/S10)-1 -> -0.014805072 | X11: =SUM(X10/T10)-1 -> -0.044958766 | Y11: =SUM(Y10/U10)-1 -> -0.017527076 | AA11: =SUM(Y11-U11)*10000 -> -175.27076
B12: Q/Q Growth (%) | C12: N/A | D12: N/A | E12: N/A | F12: N/A | I12: =SUM(I10/H10)-1 -> 0.048313833 | J12: =SUM(J10/I10)-1 -> -0.063419118 | K12: =SUM(K10/J10)-1 -> 0.070797701 | L12: =SUM(L10/K10)-1 -> 0.0061534433 | M12: =SUM(M10/L10)-1 -> -0.11346779 | N12: =SUM(N10/M10)-1 -> -0.012035814 | O12: =SUM(O10/N10)-1 -> 0.18615362 | P12: =SUM(P10/O10)-1 -> -0.099198397 | Q12: =SUM(Q10/P10)-1 -> -0.04769188 | S12: N/A | T12: N/A | U12: N/A | V12: N/A | W12: N/A | X12: N/A | Y12: N/A
B14: (-) Operating Expenses | C14: ='Historical Financials'!C13 -> -17744 | D14: ='Historical Financials'!D13 -> -19845 | E14: ='Historical Financials'!E13 -> -20017 | F14: ='Historical Financials'!F13 -> -19437 | H14: ='Historical Financials'!H13 -> -4964 | I14: ='Historical Financials'!I13 -> -5227 | J14: ='Historical Financials'!J13 -> -4681 | K14: ='Historical Financials'!K13 -> -5145 | L14: ='Historical Financials'!L13 -> -5036 | M14: ='Historical Financials'!M13 -> -4367 | N14: ='Historical Financials'!N13 -> -4342 | O14: ='Historical Financials'!O13 -> -5692 | ... Q14: ='Historical Financials'!Q13 -> -4624 | S14: =SUM(H14:K14) -> -20017 | T14: =SUM(I14:L14) -> -20089 | U14: =SUM(J14:M14) -> -19229 | V14: =SUM(K14:N14) -> -18890 | W14: =SUM(L14:O14) -> -19437 | X14: =SUM(M14:P14) -> -19362 | Y14: =SUM(N14:Q14) -> -19619 | AA14: =SUM(Y14/U14)-1 -> 0.020281866
B15: (-) Programming charges | C15: ='Historical Financials'!C14 -> 0 | D15: ='Historical Financials'!D14 -> 0 | E15: ='Historical Financials'!E14 -> -2371 | F15: ='Historical Financials'!F14 -> -1118 | H15: ='Historical Financials'!H14 -> -1674 | I15: ='Historical Financials'!I14 -> -697 | J15: ='Historical Financials'!J14 -> 0 | K15: ='Historical Financials'!K14 -> 0 | L15: ='Historical Financials'!L14 -> -1118 | M15: ='Historical Financials'!M14 -> 0 | N15: ='Historical Financials'!N14 -> 0 | O15: ='Historical Financials'!O14 -> 0 | ... Q15: ='Historical Financials'!Q14 -> 0 | S15: =SUM(H15:K15) -> -2371 | T15: =SUM(I15:L15) -> -1815 | U15: =SUM(J15:M15) -> -1118 | V15: =SUM(K15:N15) -> -1118 | W15: =SUM(L15:O15) -> -1118 | X15: =SUM(M15:P15) -> 0 | Y15: =SUM(N15:Q15) -> 0 | AA15: =SUM(Y15/U15)-1 -> -1
B16: (-) Selling, general and administrative | C16: ='Historical Financials'!C15 -> -6398 | D16: ='Historical Financials'!D15 -> -7033 | E16: ='Historical Financials'!E15 -> -7245 | F16: ='Historical Financials'!F15 -> -6658 | H16: ='Historical Financials'!H15 -> -1753 | I16: ='Historical Financials'!I15 -> -1783 | J16: ='Historical Financials'!J15 -> -1736 | K16: ='Historical Financials'!K15 -> -1973 | L16: ='Historical Financials'!L15 -> -1662 | M16: ='Historical Financials'!M15 -> -1579 | N16: ='Historical Financials'!N15 -> -1531 | O16: ='Historical Financials'!O15 -> -1886 | ... Q16: ='Historical Financials'!Q15 -> -1401 | S16: =SUM(H16:K16) -> -7245 | T16: =SUM(I16:L16) -> -7154 | U16: =SUM(J16:M16) -> -6950 | V16: =SUM(K16:N16) -> -6745 | W16: =SUM(L16:O16) -> -6658 | X16: =SUM(M16:P16) -> -6539 | Y16: =SUM(N16:Q16) -> -6361 | AA16: =SUM(Y16/U16)-1 -> -0.084748201
B17: (-) Depreciation and amortization | C17: ='Historical Financials'!C16 -> -390 | D17: ='Historical Financials'!D16 -> -378 | E17: ='Historical Financials'!E16 -> -418 | F17: ='Historical Financials'!F16 -> -392 | H17: ='Historical Financials'!H16 -> -100 | I17: ='Historical Financials'!I16 -> -105 | J17: ='Historical Financials'!J16 -> -105 | K17: ='Historical Financials'!K16 -> -108 | L17: ='Historical Financials'!L16 -> -100 | M17: ='Historical Financials'!M16 -> -101 | N17: ='Historical Financials'!N16 -> -96 | O17: ='Historical Financials'!O16 -> -95 | ... Q17: ='Historical Financials'!Q16 -> -87 | S17: =SUM(H17:K17) -> -418 | T17: =SUM(I17:L17) -> -418 | U17: =SUM(J17:M17) -> -414 | V17: =SUM(K17:N17) -> -405 | W17: =SUM(L17:O17) -> -392 | X17: =SUM(M17:P17) -> -380 | Y17: =SUM(N17:Q17) -> -366 | AA17: =SUM(Y17/U17)-1 -> -0.11594203
B18: (-) Impairment charges | C18: ='Historical Financials'!C17 -> 0 | D18: ='Historical Financials'!D17 -> -27 | E18: ='Historical Financials'!E17 -> -83 | F18: ='Historical Financials'!F17 -> -6130 | H18: ='Historical Financials'!H17 -> 0 | I18: ='Historical Financials'!I17 -> 0 | J18: ='Historical Financials'!J17 -> 0 | K18: ='Historical Financials'!K17 -> -83 | L18: ='Historical Financials'!L17 -> -186 | M18: ='Historical Financials'!M17 -> -5996 | N18: ='Historical Financials'!N17 -> -104 | O18: ='Historical Financials'!O17 -> 156 | ... Q18: ='Historical Financials'!Q17 -> -157 | S18: =SUM(H18:K18) -> -83 | T18: =SUM(I18:L18) -> -269 | U18: =SUM(J18:M18) -> -6265 | V18: =SUM(K18:N18) -> -6369 | W18: =SUM(L18:O18) -> -6130 | X18: =SUM(M18:P18) -> -5944 | Y18: =SUM(N18:Q18) -> -105 | AA18: =SUM(Y18/U18)-1 -> -0.98324022
B19: (-) Restructuring, transaction-related items, and other corporate matters | C19: ='Historical Financials'!C18 -> -100 | D19: ='Historical Financials'!D18 -> -585 | E19: ='Historical Financials'!E18 -> 31 | F19: ='Historical Financials'!F18 -> -747 | H19: ='Historical Financials'!H18 -> 0 | I19: ='Historical Financials'!I18 -> -54 | J19: ='Historical Financials'!J18 -> 10 | K19: ='Historical Financials'!K18 -> 75 | L19: ='Historical Financials'!L18 -> 0 | M19: ='Historical Financials'!M18 -> -88 | N19: ='Historical Financials'!N18 -> -321 | O19: ='Historical Financials'!O18 -> -338 | ... Q19: ='Historical Financials'!Q18 -> -181 | S19: =SUM(H19:K19) -> 31 | T19: =SUM(I19:L19) -> 31 | U19: =SUM(J19:M19) -> -3 | V19: =SUM(K19:N19) -> -334 | W19: =SUM(L19:O19) -> -747 | X19: =SUM(M19:P19) -> -832 | Y19: =SUM(N19:Q19) -> -925 | AA19: =SUM(Y19/U19)-1 -> 307.33333
B20: (-) Gains on dispositions | C20: ='Historical Financials'!C19 -> 2343 | D20: ='Historical Financials'!D19 -> 56 | E20: ='Historical Financials'!E19 -> 0 | F20: ='Historical Financials'!F19 -> 0 | H20: ='Historical Financials'!H19 -> 0 | I20: ='Historical Financials'!I19 -> 0 | J20: ='Historical Financials'!J19 -> 0 | K20: ='Historical Financials'!K19 -> 0 | L20: ='Historical Financials'!L19 -> 0 | M20: ='Historical Financials'!M19 -> 0 | N20: ='Historical Financials'!N19 -> 0 | O20: ='Historical Financials'!O19 -> 0 | ... Q20: ='Historical Financials'!Q19 -> 0 | S20: =SUM(H20:K20) -> 0 | T20: =SUM(I20:L20) -> 0 | U20: =SUM(J20:M20) -> 0 | V20: =SUM(K20:N20) -> 0 | W20: =SUM(L20:O20) -> 0 | X20: =SUM(M20:P20) -> 35 | Y20: =SUM(N20:Q20) -> 35 | AA20: =SUM(Y20/U20)-1 -> #DIV/0!
B21: Earning before Interest & Taxes (EBIT) | C21: =SUM(C10+SUM(C14:C20)) -> 6297 | D21: =SUM(D10+SUM(D14:D20)) -> 2342 | E21: =SUM(E10+SUM(E14:E20)) -> -451 | F21: =SUM(F10+SUM(F14:F20)) -> -5269 | H21: =SUM(H10+SUM(H14:H20)) -> -1226 | I21: =SUM(I10+SUM(I14:I20)) -> -250 | J21: =SUM(J10+SUM(J14:J20)) -> 621 | K21: =SUM(K10+SUM(K14:K20)) -> 404 | L21: =SUM(L10+SUM(L14:L20)) -> -417 | M21: =SUM(M10+SUM(M14:M20)) -> -5318 | N21: =SUM(N10+SUM(N14:N20)) -> 337 | O21: =SUM(O10+SUM(O14:O20)) -> 129 | ... Q21: =SUM(Q10+SUM(Q14:Q20)) -> 399 | S21: =SUM(S10+SUM(S14:S20)) -> -451 | T21: =SUM(T10+SUM(T14:T20)) -> 358 | U21: =SUM(U10+SUM(U14:U20)) -> -4710 | V21: =SUM(V10+SUM(V14:V20)) -> -4994 | W21: =SUM(W10+SUM(W14:W20)) -> -5269 | X21: =SUM(X10+SUM(X14:X20)) -> -4302 | Y21: =SUM(Y10+SUM(Y14:Y20)) -> 1415 | AA21: =SUM(Y21/U21)-1 -> -1.3004246
B22: Operating Margin (%) | C22: =C21/C10 -> 0.22028266 | D22: =D21/D10 -> 0.077667971 | E22: =E21/E10 -> -0.015209767 | F22: =F21/F10 -> -0.18036491 | H22: =H21/H10 -> -0.1687543 | I22: =I21/I10 -> -0.03282563 | J22: =J21/J10 -> 0.087060143 | K22: =K21/K10 -> 0.052893428 | L22: =L21/L10 -> -0.054261548 | M22: =M21/M10 -> -0.78056656 | N22: =N21/N10 -> 0.050066855 | O22: =O21/O10 -> 0.016157315 | ... Q22: =Q21/Q10 -> 0.05825668 | S22: =S21/S10 -> -0.015209767 | T22: =T21/T10 -> 0.011904762 | U22: =U21/U10 -> -0.16092111 | V22: =V21/V10 -> -0.17300031 | W22: =W21/W10 -> -0.18036491 | X22: =X21/X10 -> -0.14979109 | Y22: =Y21/Y10 -> 0.049207122 | AA22: =SUM(Y22-U22)*10000 -> 2101.2823
B24: (+) Depreciation and Amortization (D&A) | C24: =-C17 -> 390 | D24: =-D17 -> 378 | E24: =-E17 -> 418 | F24: =-F17 -> 392 | H24: =-H17 -> 100 | I24: =-I17 -> 105 | J24: =-J17 -> 105 | K24: =-K17 -> 108 | L24: =-L17 -> 100 | M24: =-M17 -> 101 | N24: =-N17 -> 96 | O24: =-O17 -> 95 | ... Q24: =-Q17 -> 87 | S24: =SUM(H24:K24) -> 418 | T24: =SUM(I24:L24) -> 418 | U24: =SUM(J24:M24) -> 414 | V24: =SUM(K24:N24) -> 405 | W24: =SUM(L24:O24) -> 392 | X24: =SUM(M24:P24) -> 380 | Y24: =SUM(N24:Q24) -> 366 | AA24: =SUM(Y24/U24)-1 -> -0.11594203
B25: EBITDA | C25: =SUM(C21+SUM(C24:C24)) -> 6687 | D25: =SUM(D21+SUM(D24:D24)) -> 2720 | E25: =SUM(E21+SUM(E24:E24)) -> -33 | F25: =SUM(F21+SUM(F24:F24)) -> -4877 | H25: =SUM(H21+SUM(H24:H24)) -> -1126 | I25: =SUM(I21+SUM(I24:I24)) -> -145 | J25: =SUM(J21+SUM(J24:J24)) -> 726 | K25: =SUM(K21+SUM(K24:K24)) -> 512 | L25: =SUM(L21+SUM(L24:L24)) -> -317 | M25: =SUM(M21+SUM(M24:M24)) -> -5217 | N25: =SUM(N21+SUM(N24:N24)) -> 433 | O25: =SUM(O21+SUM(O24:O24)) -> 224 | ... Q25: =SUM(Q21+SUM(Q24:Q24)) -> 486 | S25: =SUM(S21+SUM(S24:S24)) -> -33 | T25: =SUM(T21+SUM(T24:T24)) -> 776 | U25: =SUM(U21+SUM(U24:U24)) -> -4296 | V25: =SUM(V21+SUM(V24:V24)) -> -4589 | W25: =SUM(W21+SUM(W24:W24)) -> -4877 | X25: =SUM(X21+SUM(X24:X24)) -> -3922 | Y25: =SUM(Y21+SUM(Y24:Y24)) -> 1781 | AA25: =SUM(Y25/U25)-1 -> -1.4145717
B26: EBITDA Margin (%) | C26: =C25/C10 -> 0.2339257 | D26: =D25/D10 -> 0.090203621 | E26: =E25/E10 -> -0.0011129098 | F26: =F25/F10 -> -0.16694622 | H26: =H25/H10 -> -0.15498968 | I26: =I25/I10 -> -0.019038866 | J26: =J25/J10 -> 0.10178046 | K26: =K25/K10 -> 0.067033255 | L26: =L25/L10 -> -0.041249187 | M26: =M25/M10 -> -0.76574196 | N26: =N25/N10 -> 0.064329223 | O26: =O25/O10 -> 0.028056112 | ... Q26: =Q25/Q10 -> 0.070959264 | S26: =S25/S10 -> -0.0011129098 | T26: =T25/T10 -> 0.025804735 | U26: =U25/U10 -> -0.14677645 | V26: =V25/V10 -> -0.15897045 | W26: =W25/W10 -> -0.16694622 | X26: =X25/X10 -> -0.13655989 | Y26: =Y25/Y10 -> 0.061934901 | AA26: =SUM(Y26-U26)*10000 -> 2087.1135
B28: (+) Stock-based compensation (SBC) | C28: ='Historical Financials'!C116 -> 192 | D28: ='Historical Financials'!D116 -> 172 | E28: ='Historical Financials'!E116 -> 177 | F28: ='Historical Financials'!F116 -> 245 | H28: ='Historical Financials'!H116 -> 39 | I28: ='Historical Financials'!I116 -> 49 | J28: ='Historical Financials'!J116 -> 43 | K28: ='Historical Financials'!K116 -> 46 | L28: ='Historical Financials'!L116 -> 47 | M28: ='Historical Financials'!M116 -> 62 | N28: ='Historical Financials'!N116 -> 66 | O28: ='Historical Financials'!O116 -> 70 | ... Q28: ='Historical Financials'!Q116 -> 43 | S28: =SUM(H28:K28) -> 177 | T28: =SUM(I28:L28) -> 185 | U28: =SUM(J28:M28) -> 198 | V28: =SUM(K28:N28) -> 221 | W28: =SUM(L28:O28) -> 245 | X28: =SUM(M28:P28) -> 242 | Y28: =SUM(N28:Q28) -> 223 | AA28: =SUM(Y28/U28)-1 -> 0.12626263
B29: (+) Impairment charges | C29: =-C18 -> 0 | D29: =-D18 -> 27 | E29: =-E18 -> 83 | F29: =-F18 -> 6130 | H29: =-H18 -> 0 | I29: =-I18 -> 0 | J29: =-J18 -> 0 | K29: =-K18 -> 83 | L29: =-L18 -> 186 | M29: =-M18 -> 5996 | N29: =-N18 -> 104 | O29: =-O18 -> -156 | ... Q29: =-Q18 -> 157 | S29: =SUM(H29:K29) -> 83 | T29: =SUM(I29:L29) -> 269 | U29: =SUM(J29:M29) -> 6265 | V29: =SUM(K29:N29) -> 6369 | W29: =SUM(L29:O29) -> 6130 | X29: =SUM(M29:P29) -> 5944 | Y29: =SUM(N29:Q29) -> 105 | AA29: =SUM(Y29/U29)-1 -> -0.98324022
B30: (+) Restructuring, transaction-related items, and other corporate matters | C30: =-C19 -> 100 | D30: =-D19 -> 585 | E30: =-E19 -> -31 | F30: =-F19 -> 747 | H30: =-H19 -> 0 | I30: =-I19 -> 54 | J30: =-J19 -> -10 | K30: =-K19 -> -75 | L30: =-L19 -> 0 | M30: =-M19 -> 88 | N30: =-N19 -> 321 | O30: =-O19 -> 338 | ... Q30: =-Q19 -> 181 | S30: =SUM(H30:K30) -> -31 | T30: =SUM(I30:L30) -> -31 | U30: =SUM(J30:M30) -> 3 | V30: =SUM(K30:N30) -> 334 | W30: =SUM(L30:O30) -> 747 | X30: =SUM(M30:P30) -> 832 | Y30: =SUM(N30:Q30) -> 925 | AA30: =SUM(Y30/U30)-1 -> 307.33333
B31: (+) Gains on dispositions | C31: =-C20 -> -2343 | D31: =-D20 -> -56 | E31: =-E20 -> 0 | F31: =-F20 -> 0 | H31: =-H20 -> 0 | I31: =-I20 -> 0 | J31: =-J20 -> 0 | K31: =-K20 -> 0 | L31: =-L20 -> 0 | M31: =-M20 -> 0 | N31: =-N20 -> 0 | O31: =-O20 -> 0 | ... Q31: =-Q20 -> 0 | S31: =SUM(H31:K31) -> 0 | T31: =SUM(I31:L31) -> 0 | U31: =SUM(J31:M31) -> 0 | V31: =SUM(K31:N31) -> 0 | W31: =SUM(L31:O31) -> 0 | X31: =SUM(M31:P31) -> -35 | Y31: =SUM(N31:Q31) -> -35 | AA31: =SUM(Y31/U31)-1 -> #DIV/0!
B32: Adj. EBITDA | C32: =+SUM(C25+SUM(C28:C28)) -> 6879 | D32: =+SUM(D25+SUM(D28:D28)) -> 2892 | E32: =+SUM(E25+SUM(E28:E28)) -> 144 | F32: =+SUM(F25+SUM(F28:F28)) -> -4632 | H32: =+SUM(H25+SUM(H28:H28)) -> -1087 | I32: =+SUM(I25+SUM(I28:I28)) -> -96 | J32: =+SUM(J25+SUM(J28:J28)) -> 769 | K32: =+SUM(K25+SUM(K28:K28)) -> 558 | L32: =+SUM(L25+SUM(L28:L28)) -> -270 | M32: =+SUM(M25+SUM(M28:M28)) -> -5155 | N32: =+SUM(N25+SUM(N28:N28)) -> 499 | O32: =+SUM(O25+SUM(O28:O28)) -> 294 | ... Q32: =+SUM(Q25+SUM(Q28:Q28)) -> 529 | S32: =+SUM(S25+SUM(S28:S28)) -> 144 | T32: =+SUM(T25+SUM(T28:T28)) -> 961 | U32: =+SUM(U25+SUM(U28:U28)) -> -4098 | V32: =+SUM(V25+SUM(V28:V28)) -> -4368 | W32: =+SUM(W25+SUM(W28:W28)) -> -4632 | X32: =+SUM(X25+SUM(X28:X28)) -> -3680 | Y32: =+SUM(Y25+SUM(Y28:Y28)) -> 2004 | AA32: =SUM(Y32/U32)-1 -> -1.489019
B33: Adj. EBITDA Margin (%) | C33: =C32/C10 -> 0.24064227 | D33: =D32/D10 -> 0.095907674 | E33: =E32/E10 -> 0.0048563335 | F33: =F32/F10 -> -0.15855955 | H33: =H32/H10 -> -0.14962147 | I33: =I32/I10 -> -0.012605042 | J33: =J32/J10 -> 0.10780878 | K33: =K32/K10 -> 0.073055774 | L33: =L32/L10 -> -0.035133377 | M33: =M32/M10 -> -0.75664171 | N33: =N32/N10 -> 0.074134601 | O33: =O32/O10 -> 0.036823647 | ... Q33: =Q32/Q10 -> 0.077237553 | S33: =S32/S10 -> 0.0048563335 | T33: =T32/T10 -> 0.031956637 | U33: =U32/U10 -> -0.14001162 | V33: =V32/V10 -> -0.15131465 | W33: =W32/W10 -> -0.15855955 | X33: =X32/X10 -> -0.1281337 | Y33: =Y32/Y10 -> 0.069689804 | AA33: =SUM(Y33-U33)*10000 -> 2097.0142
B35: (-) Capital Expenditures | C35: ='Historical Financials'!C128 -> -354 | D35: ='Historical Financials'!D128 -> -358 | E35: ='Historical Financials'!E128 -> -328 | F35: ='Historical Financials'!F128 -> -263 | H35: ='Historical Financials'!H128 -> -71 | I35: ='Historical Financials'!I128 -> -69 | J35: ='Historical Financials'!J128 -> -73 | K35: ='Historical Financials'!K128 -> -115 | L35: ='Historical Financials'!L128 -> -51 | M35: ='Historical Financials'!M128 -> -49 | N35: ='Historical Financials'!N128 -> -51 | O35: ='Historical Financials'!O128 -> -112 | ... Q35: ='Historical Financials'!Q128 -> -45 | S35: =SUM(H35:K35) -> -328 | T35: =SUM(I35:L35) -> -308 | U35: =SUM(J35:M35) -> -288 | V35: =SUM(K35:N35) -> -266 | W35: =SUM(L35:O35) -> -263 | X35: =SUM(M35:P35) -> -269 | Y35: =SUM(N35:Q35) -> -265 | AA35: =SUM(Y35/U35)-1 -> -0.079861111
B36: (-) Cash Taxes | C36: =-'Historical Financials'!C159 -> -334 | D36: =-'Historical Financials'!D159 -> -73 | E36: =-'Historical Financials'!E159 -> -107 | F36: =-'Historical Financials'!F159 -> -184 | H36: =-'Historical Financials'!H159 -> 6 | I36: =-'Historical Financials'!I159 -> -76 | J36: =-'Historical Financials'!J159 -> 68 | K36: =-'Historical Financials'!K159 -> -71 | L36: =-'Historical Financials'!L159 -> -27 | M36: =-'Historical Financials'!M159 -> -147 | N36: =-'Historical Financials'!N159 -> 106 | O36: =-'Historical Financials'!O159 -> -39 | ... Q36: =-'Historical Financials'!Q159 -> -153 | S36: =SUM(H36:K36) -> -73 | T36: =SUM(I36:L36) -> -106 | U36: =SUM(J36:M36) -> -177 | V36: =SUM(K36:N36) -> -139 | W36: =SUM(L36:O36) -> -107 | X36: =SUM(M36:P36) -> -107 | Y36: =SUM(N36:Q36) -> -113 | AA36: =SUM(Y36/U36)-1 -> -0.36158192
