Workbook

Sheet Cover
C12: Netflix, Inc. (NASDAQ: NFLX) Company Summary
C13: January 2026
C15: Scope | I15: Model Outputs
C16: Forecast horizon: | G16: 2020A-3031F | I16: Case Assumption: | M16: Base case
C17: Methods: | G17: DCF, Peer Comparables | I17: Target Price: | M17: TBD
C18: Valuation Weights: | G18: 70% DCF, 30% Peer Comparables | I18: Recommendation: | M18: TBD
C20: Company Info | I20: Business Snapshot
C21: Ticker: | G21: NFLX | I21: Primary platforms: | M21: iOS, macOS, iPadOS, watchOS, tvOS, visionOS
C22: Industry: | G22: Media & Entertainment / Streaming | I22: Hardware products: | M22: iPhone, Mac, iPad, Apple Watch, AirPods
C23: Headquarters: | G23: Los Gatos, California | I23: Services ecosystem: | M23: Store, Music, TV+, Arcade, Pay, iCloud, AppleCare
C24: Founded: | G24: 1997 (DVD), Streaming 2007 | I24: Installed base: | M24: >2.2B active devices (2025 est.)
C25: CEO: | G25: Ted Sarandos & Greg Peters (Co-CEOs) | I25: Revenue mix (FY2025): | M25: Hardware ~78% / Services ~22%
C26: CFO: | G26: Spencer Neumann | I26: Geographic exposure: | M26: Americas largest; China strategic
C27: Fiscal year end: | G27: December 31
C28: Employees: | G28: ≈13,000 (FY2025) | I28: Financial Profile
C29: Credit Ratings: | G29: S&P: BB+ / Moody’s: Ba1 / Fitch: BB+ | I29: Revenue CAGR (5yr): | M29: High-single to low-double digits
C30: Capital Structure: | G30: Term debt + content obligations; buybacks | I30: Gross Margins: | M30: ~40–45% consolidated
C31: Dividend Policy: | G31: No dividend | I31: OpEx Structure: | M31: Content > Tech > G&A
C32: Legal structure: | G32: C-Corporation (Delaware) | I32: Capital Returns: | M32: Buybacks only
C33: Exchange Listing: | G33: NASDAQ Global Select Market | I33: FCF: | M33: High-yield FCF
C35: Supply Chain & Production | I35: Regulatory & Risks
C36: Model: | G36: Vertical studio + licensed catalog | I36: Antitrust: | M36: Low structural risk vs app stores
C37: Studios: | G37: LA, Vancouver, Seoul, Tokyo, Madrid | I37: Data Privacy: | M37: GDPR, CCPA compliance
C38: Risks: | G38: Strikes, FX, regional censorship | I38: Censorship: | M38: Local edits/bans in EMEA/APAC
C40: Strategic Positioning | I40: Competition
C41: Advantages: | G41: Global scale, algorithms, localized content, pricing power | I41: Streaming: | M41: Disney+/Hulu, Prime Video, Max, Apple TV+, Paramount+, Peacock
C42: Risks: | G42: Content inflation, churn, FX exposure, competitive saturation | I42: Indirect: | M42: YouTube, TikTok, Linear TV
C44: Segments
C45: Reporting Regions: | G45: UCAN, EMEA, LATAM, APAC
C46: Product Segments: | G46: Ad-Free, Ad-Supported, Gaming (immaterial revenue)

Sheet Summary Assumptions
C12: Netflix, Inc. (NASDAQ: NFLX) Financial Model Summary Assumptions
C13: January 2026
C15: DCF Assumptions | L15: Revenue Segment Assumptions
D16: 2025 | E16: 2026 | F16: 2027 | G16: 2028 | H16: 2029 | I16: 2030 | J16: 2031 | M16: 2025 | N16: 2026 | O16: 2027 | P16: 2028 | Q16: 2029 | R16: 2030 | S16: 2031
C17: Revenue | L17: iPhone Revenue
C18: Y/Y Growth (%) | E18: =SUM(E17/D17)-1 -> #DIV/0! | F18: =SUM(F17/E17)-1 -> #DIV/0! | G18: =SUM(G17/F17)-1 -> #DIV/0! | H18: =SUM(H17/G17)-1 -> #DIV/0! | I18: =SUM(I17/H17)-1 -> #DIV/0! | J18: =SUM(J17/I17)-1 -> #DIV/0! | L18: Y/Y Growth (%) | N18: =SUM(N17/M17)-1 -> #DIV/0! | O18: =SUM(O17/N17)-1 -> #DIV/0! | P18: =SUM(P17/O17)-1 -> #DIV/0! | Q18: =SUM(Q17/P17)-1 -> #DIV/0! | R18: =SUM(R17/Q17)-1 -> #DIV/0! | S18: =SUM(S17/R17)-1 -> #DIV/0!
C19: EBITDA | L19: Mac Revenue
C20: Y/Y Growth (%) | E20: =SUM(E19/D19)-1 -> #DIV/0! | F20: =SUM(F19/E19)-1 -> #DIV/0! | G20: =SUM(G19/F19)-1 -> #DIV/0! | H20: =SUM(H19/G19)-1 -> #DIV/0! | I20: =SUM(I19/H19)-1 -> #DIV/0! | J20: =SUM(J19/I19)-1 -> #DIV/0! | L20: Y/Y Growth (%) | N20: =SUM(N19/M19)-1 -> #DIV/0! | O20: =SUM(O19/N19)-1 -> #DIV/0! | P20: =SUM(P19/O19)-1 -> #DIV/0! | Q20: =SUM(Q19/P19)-1 -> #DIV/0! | R20: =SUM(R19/Q19)-1 -> #DIV/0! | S20: =SUM(S19/R19)-1 -> #DIV/0!
C21: EBIT | L21: iPad Revenue
C22: Y/Y Growth (%) | E22: =SUM(E21/D21)-1 -> #DIV/0! | F22: =SUM(F21/E21)-1 -> #DIV/0! | G22: =SUM(G21/F21)-1 -> #DIV/0! | H22: =SUM(H21/G21)-1 -> #DIV/0! | I22: =SUM(I21/H21)-1 -> #DIV/0! | J22: =SUM(J21/I21)-1 -> #DIV/0! | L22: Y/Y Growth (%) | N22: =SUM(N21/M21)-1 -> #DIV/0! | O22: =SUM(O21/N21)-1 -> #DIV/0! | P22: =SUM(P21/O21)-1 -> #DIV/0! | Q22: =SUM(Q21/P21)-1 -> #DIV/0! | R22: =SUM(R21/Q21)-1 -> #DIV/0! | S22: =SUM(S21/R21)-1 -> #DIV/0!
C23: NOPAT | L23: Services Revenue
C24: Y/Y Growth (%) | E24: =SUM(E23/D23)-1 -> #DIV/0! | F24: =SUM(F23/E23)-1 -> #DIV/0! | G24: =SUM(G23/F23)-1 -> #DIV/0! | H24: =SUM(H23/G23)-1 -> #DIV/0! | I24: =SUM(I23/H23)-1 -> #DIV/0! | J24: =SUM(J23/I23)-1 -> #DIV/0! | L24: Y/Y Growth (%) | N24: =SUM(N23/M23)-1 -> #DIV/0! | O24: =SUM(O23/N23)-1 -> #DIV/0! | P24: =SUM(P23/O23)-1 -> #DIV/0! | Q24: =SUM(Q23/P23)-1 -> #DIV/0! | R24: =SUM(R23/Q23)-1 -> #DIV/0! | S24: =SUM(S23/R23)-1 -> #DIV/0!
C25: UFCF | L25: Other
C26: Y/Y Growth (%) | E26: =SUM(E25/D25)-1 -> #DIV/0! | F26: =SUM(F25/E25)-1 -> #DIV/0! | G26: =SUM(G25/F25)-1 -> #DIV/0! | H26: =SUM(H25/G25)-1 -> #DIV/0! | I26: =SUM(I25/H25)-1 -> #DIV/0! | J26: =SUM(J25/I25)-1 -> #DIV/0! | L26: Y/Y Growth (%) | N26: =SUM(N25/M25)-1 -> #DIV/0! | O26: =SUM(O25/N25)-1 -> #DIV/0! | P26: =SUM(P25/O25)-1 -> #DIV/0! | Q26: =SUM(Q25/P25)-1 -> #DIV/0! | R26: =SUM(R25/Q25)-1 -> #DIV/0! | S26: =SUM(S25/R25)-1 -> #DIV/0!
C28: Unit Economics | L28: ASP Economics
D29: 2025 | E29: 2026 | F29: 2027 | G29: 2028 | H29: 2029 | I29: 2030 | J29: 2031 | M29: 2025 | N29: 2026 | O29: 2027 | P29: 2028 | Q29: 2029 | R29: 2030 | S29: 2031
C30: iPhone Units | L30: iPhone ASP
C31: Y/Y Growth (%) | E31: =SUM(E30/D30)-1 -> #DIV/0! | F31: =SUM(F30/E30)-1 -> #DIV/0! | G31: =SUM(G30/F30)-1 -> #DIV/0! | H31: =SUM(H30/G30)-1 -> #DIV/0! | I31: =SUM(I30/H30)-1 -> #DIV/0! | J31: =SUM(J30/I30)-1 -> #DIV/0! | L31: Y/Y Growth (%) | N31: =SUM(N30/M30)-1 -> #DIV/0! | O31: =SUM(O30/N30)-1 -> #DIV/0! | P31: =SUM(P30/O30)-1 -> #DIV/0! | Q31: =SUM(Q30/P30)-1 -> #DIV/0! | R31: =SUM(R30/Q30)-1 -> #DIV/0! | S31: =SUM(S30/R30)-1 -> #DIV/0!
C32: iPad Units | L32: iPad ASP
C33: Y/Y Growth (%) | E33: =SUM(E32/D32)-1 -> #DIV/0! | F33: =SUM(F32/E32)-1 -> #DIV/0! | G33: =SUM(G32/F32)-1 -> #DIV/0! | H33: =SUM(H32/G32)-1 -> #DIV/0! | I33: =SUM(I32/H32)-1 -> #DIV/0! | J33: =SUM(J32/I32)-1 -> #DIV/0! | L33: Y/Y Growth (%) | N33: =SUM(N32/M32)-1 -> #DIV/0! | O33: =SUM(O32/N32)-1 -> #DIV/0! | P33: =SUM(P32/O32)-1 -> #DIV/0! | Q33: =SUM(Q32/P32)-1 -> #DIV/0! | R33: =SUM(R32/Q32)-1 -> #DIV/0! | S33: =SUM(S32/R32)-1 -> #DIV/0!
C34: Mac Units | L34: Mac ASP
C35: Y/Y Growth (%) | E35: =SUM(E34/D34)-1 -> #DIV/0! | F35: =SUM(F34/E34)-1 -> #DIV/0! | G35: =SUM(G34/F34)-1 -> #DIV/0! | H35: =SUM(H34/G34)-1 -> #DIV/0! | I35: =SUM(I34/H34)-1 -> #DIV/0! | J35: =SUM(J34/I34)-1 -> #DIV/0! | L35: Y/Y Growth (%) | N35: =SUM(N34/M34)-1 -> #DIV/0! | O35: =SUM(O34/N34)-1 -> #DIV/0! | P35: =SUM(P34/O34)-1 -> #DIV/0! | Q35: =SUM(Q34/P34)-1 -> #DIV/0! | R35: =SUM(R34/Q34)-1 -> #DIV/0! | S35: =SUM(S34/R34)-1 -> #DIV/0!
C37: P/E Forecast | L37: EPS Forecast
D38: 2025 | E38: 2026 | F38: 2027 | G38: 2028 | H38: 2029 | I38: 2030 | J38: 2031 | M38: 2025 | N38: 2026 | O38: 2027 | P38: 2028 | Q38: 2029 | R38: 2030 | S38: 2031
C39: Basic P/E | L39: Basic EPS
C40: Y/Y Growth (%) | E40: =SUM(E39/D39)-1 -> #DIV/0! | F40: =SUM(F39/E39)-1 -> #DIV/0! | G40: =SUM(G39/F39)-1 -> #DIV/0! | H40: =SUM(H39/G39)-1 -> #DIV/0! | I40: =SUM(I39/H39)-1 -> #DIV/0! | J40: =SUM(J39/I39)-1 -> #DIV/0! | L40: Y/Y Growth (%) | N40: =SUM(N39/M39)-1 -> #DIV/0! | O40: =SUM(O39/N39)-1 -> #DIV/0! | P40: =SUM(P39/O39)-1 -> #DIV/0! | Q40: =SUM(Q39/P39)-1 -> #DIV/0! | R40: =SUM(R39/Q39)-1 -> #DIV/0! | S40: =SUM(S39/R39)-1 -> #DIV/0!
C41: Diluted P/E | L41: Diluted EPS
C42: Y/Y Growth (%) | E42: =SUM(E41/D41)-1 -> #DIV/0! | F42: =SUM(F41/E41)-1 -> #DIV/0! | G42: =SUM(G41/F41)-1 -> #DIV/0! | H42: =SUM(H41/G41)-1 -> #DIV/0! | I42: =SUM(I41/H41)-1 -> #DIV/0! | J42: =SUM(J41/I41)-1 -> #DIV/0! | L42: Y/Y Growth (%) | N42: =SUM(N41/M41)-1 -> #DIV/0! | O42: =SUM(O41/N41)-1 -> #DIV/0! | P42: =SUM(P41/O41)-1 -> #DIV/0! | Q42: =SUM(Q41/P41)-1 -> #DIV/0! | R42: =SUM(R41/Q41)-1 -> #DIV/0! | S42: =SUM(S41/R41)-1 -> #DIV/0!

Sheet Summary Valuation
C12: Netflix, Inc. (NASDAQ: NFLX) Football Field Estimates
C13: January 2026
C15: Summary Valuation
E16: Low | F16: Delta | G16: High | H16: Mid
D17: Comparable Trading Analysis | F17: =G17-E17 -> 0 | H17: =MEDIAN(G17,E17) -> #NUM!
D18: DCF Valuation Analysis: Perpetuity Method | F18: =G18-E18 -> 0 | H18: =MEDIAN(G18,E18) -> #NUM!
D19: DCF Valuation Analysis: Multiple Method | F19: =G19-E19 -> 0 | H19: =MEDIAN(G19,E19) -> #NUM!
D20: 52 Week Trading | F20: =G20-E20 -> 0 | H20: =MEDIAN(G20,E20) -> #NUM!
D21: Street Consensus | F21: =G21-E21 -> 0 | H21: =MEDIAN(G21,E21) -> #NUM!
C23: Valuation Weighting
C24: Intrinsic Valuation | D24: Valuation | F24: Bear | G24: Relative | H24: Base | I24: Relative | J24: Bull | K24: Relative | L24: Weighted
C25: Method | D25: Weight | F25: Case | G25: Weight | H25: Case | I25: Weight | J25: Case | K25: Weight | L25: Value
C27: DCF: Perpetuity Method | F27: =E18 -> 0 | H27: =H18 -> #NUM! | J27: =G18 -> 0 | L27: =F27*G27+H27*I27+J27*K27 -> #NUM!
C28: DCF: Multiple Method | F28: =E19 -> 0 | H28: =H19 -> #NUM! | J28: =G19 -> 0 | L28: =F28*G28+H28*I28+J28*K28 -> #NUM!
C30: Valuation Weighting
C31: Market Based | D31: Valuation | F31: Bear | G31: Relative | H31: Base | I31: Relative | J31: Bull | K31: Relative | L31: Weighted
C32: Valuation Method | D32: Weight | F32: Case | G32: Weight | H32: Case | I32: Weight | J32: Case | K32: Weight | L32: Value
C33: Comparable Trading Analysis | L33: =F33*G33+H33*I33+J33*K33 -> 0
C35: Summary Weighted Valuation
C36: Target Price | D36: =D33*L33+D27*L27+D28*L28 -> #NUM!
C37: Current Price
C38: Upside (Downside) | D38: =(D36/D37)-1 -> #NUM!

Sheet Historical Financials
B2: Netflix, Inc. (NASDAQ: NFLX)
B3: Historical Financials
B4: $ in thousands except per share
A6: X | B6: Income Statement | G6: FYE | O6: Quarterly | S6: Quarterly | Y6: Quarterly | AN6: LTM | AO6: LTM | AU6: Variance
B7: Fiscal Period | C7: 2018 | D7: 2019 | E7: 2020 | F7: 2021 | G7: 2022 | H7: 2023 | I7: 2024 | K7: 1Q21 | L7: 2Q21 | M7: 3Q21 | N7: 4Q21 | O7: 1Q22 | P7: 2Q22 | Q7: 3Q22 | R7: 4Q22 | S7: 1Q23 | T7: 2Q23 | U7: 3Q23 | V7: 4Q23 | W7: 1Q24 | X7: 2Q24 | Y7: 3Q24 | Z7: 4Q24 | AA7: 1Q25 | AB7: 2Q25 | AC7: 3Q25 | AE7: =O7 -> 1Q22 | AF7: =P7 -> 2Q22 | AG7: =Q7 -> 3Q22 | AH7: =R7 -> 4Q22 | AI7: =S7 -> 1Q23 | AJ7: =T7 -> 2Q23 | AK7: =U7 -> 3Q23 | AL7: =V7 -> 4Q23 | ... AS7: =AC7 -> 3Q25
B8: Fiscal Period End Date | C8: 43465 | D8: 43830 | E8: 44196 | F8: 44561 | G8: 44926 | H8: 45291 | I8: 45657 | K8: 44286 | L8: 44377 | M8: 44469 | N8: =F8 -> 44561 | O8: 44651 | P8: 44742 | Q8: 44834 | R8: =G8 -> 44926 | S8: 45016 | T8: 45107 | U8: 45199 | V8: =H8 -> 45291 | W8: 45382 | X8: 45473 | Y8: 45565 | Z8: =I8 -> 45657 | AA8: 45747 | AB8: 45838 | AC8: 45930 | AE8: =O8 -> 44651 | AF8: =P8 -> 44742 | AG8: =Q8 -> 44834 | AH8: =R8 -> 44926 | AI8: =S8 -> 45016 | AJ8: =T8 -> 45107 | AK8: =U8 -> 45199 | AL8: =V8 -> 45291 | ... AS8: =AC8 -> 45930
B10: Consolidated Revenue | C10: 15794.341 | D10: 20156.447 | E10: 24996.056 | F10: 29697.844 | G10: 31615.55 | H10: 33723.297 | I10: 39000.966 | K10: 7163.282 | L10: 7341.777 | M10: 7483.467 | N10: =SUM(F10-SUM(K10:M10)) -> 7709.318 | O10: 7867.767 | P10: 7970.141 | Q10: 7925.589 | R10: =SUM(G10-SUM(O10:Q10)) -> 7852.053 | S10: 8161.503 | T10: 8187.301 | U10: 8541.668 | V10: =SUM(H10-SUM(S10:U10)) -> 8832.825 | W10: 9370.44 | X10: 9559.31 | Y10: 9824.703 | Z10: =SUM(I10-SUM(W10:Y10)) -> 10246.513 | AA10: 10542.801 | AB10: 11079.166 | AC10: 11510.307 | AE10: =SUM(L10:O10) -> 30402.329 | AF10: =SUM(M10:P10) -> 31030.693 | AG10: =SUM(N10:Q10) -> 31472.815 | AH10: =SUM(O10:R10) -> 31615.55 | AI10: =SUM(P10:S10) -> 31909.286 | AJ10: =SUM(Q10:T10) -> 32126.446 | AK10: =SUM(R10:U10) -> 32742.525 | AL10: =SUM(S10:V10) -> 33723.297 | ... AS10: =SUM(Z10:AC10) -> 43378.787 | AU10: =SUM(AS10/AO10)-1 -> 0.15408163
B11: Total Revenue | C11: =+SUM(C10:C10) -> 15794.341 | D11: =+SUM(D10:D10) -> 20156.447 | E11: =+SUM(E10:E10) -> 24996.056 | F11: =+SUM(F10:F10) -> 29697.844 | G11: =+SUM(G10:G10) -> 31615.55 | H11: =+SUM(H10:H10) -> 33723.297 | I11: =+SUM(I10:I10) -> 39000.966 | K11: =+SUM(K10:K10) -> 7163.282 | L11: =+SUM(L10:L10) -> 7341.777 | M11: =+SUM(M10:M10) -> 7483.467 | N11: =+SUM(N10:N10) -> 7709.318 | O11: =+SUM(O10:O10) -> 7867.767 | P11: =+SUM(P10:P10) -> 7970.141 | Q11: =+SUM(Q10:Q10) -> 7925.589 | R11: =+SUM(R10:R10) -> 7852.053 | ... AC11: =+SUM(AC10:AC10) -> 11510.307 | AE11: =+SUM(AE10:AE10) -> 30402.329 | AF11: =+SUM(AF10:AF10) -> 31030.693 | AG11: =+SUM(AG10:AG10) -> 31472.815 | AH11: =+SUM(AH10:AH10) -> 31615.55 | AI11: =+SUM(AI10:AI10) -> 31909.286 | AJ11: =+SUM(AJ10:AJ10) -> 32126.446 | AK11: =+SUM(AK10:AK10) -> 32742.525 | AL11: =+SUM(AL10:AL10) -> 33723.297 | ... AS11: =+SUM(AS10:AS10) -> 43378.787 | AU11: =SUM(AS11/AO11)-1 -> 0.15408163
B13: Amortization of content assets | C13: -7532.088 | D13: -9216.247 | E13: -10806.912 | F13: -12230.367 | G13: -14026.132 | H13: -14197.437 | I13: -15301.517 | K13: -2719.196 | L13: -2806.803 | M13: -2963.051 | N13: =SUM(F13-SUM(K13:M13)) -> -3741.317 | O13: -3166.365 | P13: -3261.348 | Q13: -3653.592 | R13: =SUM(G13-SUM(O13:Q13)) -> -3944.827 | S13: -3459.984 | T13: -3410.021 | U13: -3573.353 | V13: =SUM(H13-SUM(S13:U13)) -> -3754.079 | W13: -3670.805 | X13: -3769.69 | Y13: -3699.521 | Z13: =SUM(I13-SUM(W13:Y13)) -> -4161.501 | AA13: -3823.112 | AB13: -3832.074 | AC13: -4002.744 | AE13: =SUM(L13:O13) -> -12677.536 | AF13: =SUM(M13:P13) -> -13132.081 | AG13: =SUM(N13:Q13) -> -13822.622 | AH13: =SUM(O13:R13) -> -14026.132 | AI13: =SUM(P13:S13) -> -14319.751 | AJ13: =SUM(Q13:T13) -> -14468.424 | AK13: =SUM(R13:U13) -> -14388.185 | AL13: =SUM(S13:V13) -> -14197.437 | ... AS13: =SUM(Z13:AC13) -> -15819.431 | AU13: =SUM(AS13/AO13)-1 -> 0.062127709
B14: Other Cost of Revenues | C14: =+C15-C13 -> -2435.45 | D14: =+D15-D13 -> -3223.966 | E14: =+E15-E13 -> -4469.407 | F14: =+F15-F13 -> -5102.316 | G14: =+G15-G13 -> -5142.153 | H14: =+H15-H13 -> -5517.931 | I14: =+I15-I13 -> -5736.947 | K14: =+K15-K13 -> -1149.315 | L14: =+L15-L13 -> -1211.205 | M14: =+M15-M13 -> -1243.538 | N14: =SUM(F14-SUM(K14:M14)) -> -1498.258 | O14: =+O15-O13 -> -1118.34 | P14: =+P15-P13 -> -1429.407 | Q14: =+Q15-Q13 -> -1135.073 | R14: =+R15-R13 -> -1459.333 | S14: =+S15-S13 -> -1343.641 | T14: =+T15-T13 -> -1263.449 | U14: =+U15-U13 -> -1357.435 | V14: =+V15-V13 -> -1553.406 | ... AC14: =+AC15-AC13 -> -2161.506 | AE14: =SUM(L14:O14) -> -5071.341 | AF14: =SUM(M14:P14) -> -5289.543 | AG14: =SUM(N14:Q14) -> -5181.078 | AH14: =SUM(O14:R14) -> -5142.153 | AI14: =SUM(P14:S14) -> -5367.454 | AJ14: =SUM(Q14:T14) -> -5201.496 | AK14: =SUM(R14:U14) -> -5423.858 | AL14: =SUM(S14:V14) -> -5517.931 | ... AS14: =SUM(Z14:AC14) -> -6700.641 | AU14: =SUM(AS14/AO14)-1 -> 0.17875852
B15: Total Cost of Revenue | C15: -9967.538 | D15: -12440.213 | E15: -15276.319 | F15: -17332.683 | G15: -19168.285 | H15: -19715.368 | I15: -21038.464 | K15: -3868.511 | L15: -4018.008 | M15: -4206.589 | N15: =SUM(F15-SUM(K15:M15)) -> -5239.575 | O15: -4284.705 | P15: -4690.755 | Q15: -4788.665 | R15: =SUM(G15-SUM(O15:Q15)) -> -5404.16 | S15: -4803.625 | T15: -4673.47 | U15: -4930.788 | V15: =SUM(H15-SUM(S15:U15)) -> -5307.485 | W15: -4977.073 | X15: -5174.143 | Y15: -5119.884 | Z15: =SUM(I15-SUM(W15:Y15)) -> -5767.364 | AA15: -5263.147 | AB15: -5325.311 | AC15: -6164.25 | AE15: =SUM(L15:O15) -> -17748.877 | AF15: =SUM(M15:P15) -> -18421.624 | AG15: =SUM(N15:Q15) -> -19003.7 | AH15: =SUM(O15:R15) -> -19168.285 | AI15: =SUM(P15:S15) -> -19687.205 | AJ15: =SUM(Q15:T15) -> -19669.92 | AK15: =SUM(R15:U15) -> -19812.043 | AL15: =SUM(S15:V15) -> -19715.368 | ... AS15: =SUM(Z15:AC15) -> -22520.072 | AU15: =SUM(AS15/AO15)-1 -> 0.094345019
B16: Gross Profit | C16: =+SUM(C11+SUM(C13:C14)) -> 5826.803 | D16: =+SUM(D11+SUM(D13:D14)) -> 7716.234 | E16: =+SUM(E11+SUM(E13:E14)) -> 9719.737 | F16: =+SUM(F11+SUM(F13:F14)) -> 12365.161 | G16: =+SUM(G11+SUM(G13:G14)) -> 12447.265 | H16: =+SUM(H11+SUM(H13:H14)) -> 14007.929 | I16: =+SUM(I11+SUM(I13:I14)) -> 17962.502 | K16: =+SUM(K11+SUM(K13:K14)) -> 3294.771 | L16: =+SUM(L11+SUM(L13:L14)) -> 3323.769 | M16: =+SUM(M11+SUM(M13:M14)) -> 3276.878 | N16: =+SUM(N11+SUM(N13:N14)) -> 2469.743 | O16: =+SUM(O11+SUM(O13:O14)) -> 3583.062 | P16: =+SUM(P11+SUM(P13:P14)) -> 3279.386 | Q16: =+SUM(Q11+SUM(Q13:Q14)) -> 3136.924 | R16: =+SUM(R11+SUM(R13:R14)) -> 2447.893 | ... AC16: =+SUM(AC11+SUM(AC13:AC14)) -> 5346.057 | AE16: =+SUM(AE11+SUM(AE13:AE14)) -> 12653.452 | AF16: =+SUM(AF11+SUM(AF13:AF14)) -> 12609.069 | AG16: =+SUM(AG11+SUM(AG13:AG14)) -> 12469.115 | AH16: =+SUM(AH11+SUM(AH13:AH14)) -> 12447.265 | AI16: =+SUM(AI11+SUM(AI13:AI14)) -> 12222.081 | AJ16: =+SUM(AJ11+SUM(AJ13:AJ14)) -> 12456.526 | AK16: =+SUM(AK11+SUM(AK13:AK14)) -> 12930.482 | AL16: =+SUM(AL11+SUM(AL13:AL14)) -> 14007.929 | ... AS16: =+SUM(AS11+SUM(AS13:AS14)) -> 20858.715 | AU16: =SUM(AS16/AO16)-1 -> 0.22635613
B17: Gross Margin (%) | C17: =C16/C11 -> 0.36891713 | D17: =D16/D11 -> 0.38281717 | E17: =E16/E11 -> 0.38885083 | F17: =F16/F11 -> 0.41636561 | G17: =G16/G11 -> 0.39370705 | H17: =H16/H11 -> 0.4153784 | I17: =I16/I11 -> 0.46056557 | K17: =K16/K11 -> 0.45995271 | L17: =L16/L11 -> 0.45271996 | M17: =M16/M11 -> 0.43788233 | N17: =N16/N11 -> 0.32035817 | O17: =O16/O11 -> 0.45541028 | P17: =P16/P11 -> 0.41145897 | Q17: =Q16/Q11 -> 0.39579696 | R17: =R16/R11 -> 0.31175197 | ... AC17: =AC16/AC11 -> 0.46445825 | AE17: =AE16/AE11 -> 0.41620009 | AF17: =AF16/AF11 -> 0.40634184 | AG17: =AG16/AG11 -> 0.39618684 | AH17: =AH16/AH11 -> 0.39370705 | AI17: =AI16/AI11 -> 0.38302584 | AJ17: =AJ16/AJ11 -> 0.38773433 | AK17: =AK16/AK11 -> 0.39491401 | AL17: =AL16/AL11 -> 0.4153784 | ... AS17: =AS16/AS11 -> 0.48085058 | AU17: =SUM(AS17-AO17)*1000 -> 28.338618
B19: Marketing | C19: -2369.469 | D19: -2652.462 | E19: -2228.362 | F19: -2545.146 | G19: -2530.502 | H19: -2657.883 | I19: -2917.554 | K19: -512.512 | L19: -603.973 | M19: -635.948 | N19: =SUM(F19-SUM(K19:M19)) -> -792.713 | O19: -555.978 | P19: -574.96 | Q19: -567.954 | R19: =SUM(G19-SUM(O19:Q19)) -> -831.61 | S19: -555.362 | T19: -627.168 | U19: -558.736 | V19: =SUM(H19-SUM(S19:U19)) -> -916.617 | W19: -654.34 | X19: -644.084 | Y19: -642.926 | Z19: =SUM(I19-SUM(W19:Y19)) -> -976.204 | AA19: -688.37 | AB19: -713.265 | AC19: -786.295 | AE19: =SUM(L19:O19) -> -2588.612 | AF19: =SUM(M19:P19) -> -2559.599 | AG19: =SUM(N19:Q19) -> -2491.605 | AH19: =SUM(O19:R19) -> -2530.502 | AI19: =SUM(P19:S19) -> -2529.886 | AJ19: =SUM(Q19:T19) -> -2582.094 | AK19: =SUM(R19:U19) -> -2572.876 | AL19: =SUM(S19:V19) -> -2657.883 | ... AS19: =SUM(Z19:AC19) -> -3164.134 | AU19: =SUM(AS19/AO19)-1 -> 0.10712755
B20: Technology and Development (T&D) | C20: -1221.814 | D20: -1545.149 | E20: -1829.6 | F20: -2273.885 | G20: -2711.041 | H20: -2675.758 | I20: -2925.295 | K20: -525.207 | L20: -537.321 | M20: -563.887 | N20: =SUM(F20-SUM(K20:M20)) -> -647.47 | O20: -657.53 | P20: -716.846 | Q20: -662.739 | R20: =SUM(G20-SUM(O20:Q20)) -> -673.926 | S20: -687.275 | T20: -657.983 | U20: -657.159 | V20: =SUM(H20-SUM(S20:U20)) -> -673.341 | W20: -702.473 | X20: -711.254 | Y20: -735.063 | Z20: =SUM(I20-SUM(W20:Y20)) -> -776.505 | AA20: -822.823 | AB20: -824.683 | AC20: -853.584 | AE20: =SUM(L20:O20) -> -2406.208 | AF20: =SUM(M20:P20) -> -2585.733 | AG20: =SUM(N20:Q20) -> -2684.585 | AH20: =SUM(O20:R20) -> -2711.041 | AI20: =SUM(P20:S20) -> -2740.786 | AJ20: =SUM(Q20:T20) -> -2681.923 | AK20: =SUM(R20:U20) -> -2676.343 | AL20: =SUM(S20:V20) -> -2675.758 | ... AS20: =SUM(Z20:AC20) -> -3277.595 | AU20: =SUM(AS20/AO20)-1 -> 0.1613901
B21: General and Administrative (G&A) | C21: -630.294 | D21: -914.369 | E21: -1076.486 | F21: -1351.621 | G21: -1572.891 | H21: -1720.285 | I21: -1702.039 | K21: -297.196 | L21: -334.845 | M21: -321.79 | N21: =SUM(F21-SUM(K21:M21)) -> -397.79 | O21: -397.928 | P21: -409.297 | Q21: -373.213 | R21: =SUM(G21-SUM(O21:Q21)) -> -392.453 | S21: -400.924 | T21: -401.497 | U21: -478.591 | V21: =SUM(H21-SUM(S21:U21)) -> -439.273 | W21: -404.02 | X21: -426.992 | Y21: -417.353 | Z21: =SUM(I21-SUM(W21:Y21)) -> -453.674 | AA21: -421.462 | AB21: -441.213 | AC21: -457.931 | AE21: =SUM(L21:O21) -> -1452.353 | AF21: =SUM(M21:P21) -> -1526.805 | AG21: =SUM(N21:Q21) -> -1578.228 | AH21: =SUM(O21:R21) -> -1572.891 | AI21: =SUM(P21:S21) -> -1575.887 | AJ21: =SUM(Q21:T21) -> -1568.087 | AK21: =SUM(R21:U21) -> -1673.465 | AL21: =SUM(S21:V21) -> -1720.285 | ... AS21: =SUM(Z21:AC21) -> -1774.28 | AU21: =SUM(AS21/AO21)-1 -> 0.051339209
B22: Operating Profit | C22: =+SUM(C16+SUM(C19:C21)) -> 1605.226 | D22: =+SUM(D16+SUM(D19:D21)) -> 2604.254 | E22: =+SUM(E16+SUM(E19:E21)) -> 4585.289 | F22: =+SUM(F16+SUM(F19:F21)) -> 6194.509 | G22: =+SUM(G16+SUM(G19:G21)) -> 5632.831 | H22: =+SUM(H16+SUM(H19:H21)) -> 6954.003 | I22: =+SUM(I16+SUM(I19:I21)) -> 10417.614 | K22: =+SUM(K16+SUM(K19:K21)) -> 1959.856 | L22: =+SUM(L16+SUM(L19:L21)) -> 1847.63 | M22: =+SUM(M16+SUM(M19:M21)) -> 1755.253 | N22: =+SUM(N16+SUM(N19:N21)) -> 631.77 | O22: =+SUM(O16+SUM(O19:O21)) -> 1971.626 | P22: =+SUM(P16+SUM(P19:P21)) -> 1578.283 | Q22: =+SUM(Q16+SUM(Q19:Q21)) -> 1533.018 | R22: =+SUM(R16+SUM(R19:R21)) -> 549.904 | ... AC22: =+SUM(AC16+SUM(AC19:AC21)) -> 3248.247 | AE22: =+SUM(AE16+SUM(AE19:AE21)) -> 6206.279 | AF22: =+SUM(AF16+SUM(AF19:AF21)) -> 5936.932 | AG22: =+SUM(AG16+SUM(AG19:AG21)) -> 5714.697 | AH22: =+SUM(AH16+SUM(AH19:AH21)) -> 5632.831 | AI22: =+SUM(AI16+SUM(AI19:AI21)) -> 5375.522 | AJ22: =+SUM(AJ16+SUM(AJ19:AJ21)) -> 5624.422 | AK22: =+SUM(AK16+SUM(AK19:AK21)) -> 6007.798 | AL22: =+SUM(AL16+SUM(AL19:AL21)) -> 6954.003 | ... AS22: =+SUM(AS16+SUM(AS19:AS21)) -> 12642.706 | AU22: =SUM(AS22/AO22)-1 -> 0.31135384
B23: Operating Margin (%) | C23: =C22/C11 -> 0.10163298 | D23: =D22/D11 -> 0.12920204 | E23: =E22/E11 -> 0.1834405 | F23: =F22/F11 -> 0.20858447 | G23: =G22/G11 -> 0.17816647 | H23: =H22/H11 -> 0.20620768 | I23: =I22/I11 -> 0.26711169 | K23: =K22/K11 -> 0.27359749 | L23: =L22/L11 -> 0.25165978 | M23: =M22/M11 -> 0.23455078 | N23: =N22/N11 -> 0.081948883 | O23: =O22/O11 -> 0.25059537 | P23: =P22/P11 -> 0.19802448 | Q23: =Q22/Q11 -> 0.19342638 | R23: =R22/R11 -> 0.070033149 | ... AC23: =AC22/AC11 -> 0.28220333 | AE23: =AE22/AE11 -> 0.20413828 | AF23: =AF22/AF11 -> 0.19132451 | AG23: =AG22/AG11 -> 0.18157566 | AH23: =AH22/AH11 -> 0.17816647 | AI23: =AI22/AI11 -> 0.16846262 | AJ23: =AJ22/AJ11 -> 0.1750714 | AK23: =AK22/AK11 -> 0.18348609 | AL23: =AL22/AL11 -> 0.20620768 | ... AS23: =AS22/AS11 -> 0.29144904 | AU23: =SUM(AS23-AO23)*1000 -> 34.953828
B25: Interest Income | C25: 0 | D25: 0 | E25: 0 | F25: 0 | G25: 60 | H25: 281 | I25: 294 | K25: 0 | L25: 0 | M25: 0 | N25: =SUM(F25-SUM(K25:M25)) -> 0 | O25: 0 | P25: 0 | Q25: 0 | R25: =SUM(G25-SUM(O25:Q25)) -> 60 | S25: 0 | T25: 0 | U25: 0 | V25: =SUM(H25-SUM(S25:U25)) -> 281 | W25: 67 | X25: 63 | Y25: 76 | Z25: =SUM(I25-SUM(W25:Y25)) -> 88 | AA25: 82 | AB25: 72 | AC25: 67 | AE25: =SUM(L25:O25) -> 0 | AF25: =SUM(M25:P25) -> 0 | AG25: =SUM(N25:Q25) -> 0 | AH25: =SUM(O25:R25) -> 60 | AI25: =SUM(P25:S25) -> 60 | AJ25: =SUM(Q25:T25) -> 60 | AK25: =SUM(R25:U25) -> 60 | AL25: =SUM(S25:V25) -> 281 | ... AS25: =SUM(Z25:AC25) -> 309 | AU25: =SUM(AS25/AO25)-1 -> -0.36550308
B26: Interest Expense | C26: -420.493 | D26: -626.023 | E26: -767.499 | F26: -765.62 | G26: -706.212 | H26: -699.826 | I26: -718.733 | K26: -194.44 | L26: -191.322 | M26: -190.429 | N26: =SUM(F26-SUM(K26:M26)) -> -189.429 | O26: -187.579 | P26: -175.455 | Q26: -172.575 | R26: =SUM(G26-SUM(O26:Q26)) -> -170.603 | S26: -174.239 | T26: -174.812 | U26: -175.563 | V26: =SUM(H26-SUM(S26:U26)) -> -175.212 | W26: -173.314 | X26: -167.986 | Y26: -184.83 | Z26: =SUM(I26-SUM(W26:Y26)) -> -192.603 | AA26: -184.172 | AB26: -182.649 | AC26: -175.294 | AE26: =SUM(L26:O26) -> -758.759 | AF26: =SUM(M26:P26) -> -742.892 | AG26: =SUM(N26:Q26) -> -725.038 | AH26: =SUM(O26:R26) -> -706.212 | AI26: =SUM(P26:S26) -> -692.872 | AJ26: =SUM(Q26:T26) -> -692.229 | AK26: =SUM(R26:U26) -> -695.217 | AL26: =SUM(S26:V26) -> -699.826 | ... AS26: =SUM(Z26:AC26) -> -734.718 | AU26: =SUM(AS26/AO26)-1 -> 0.047588766
B27: Other Income & Expenses | C27: 41.725 | D27: 84 | E27: -618.441 | F27: 411.214 | G27: =(337.31-G25) -> 277.31 | H27: =(-48.772-H25) -> -329.772 | I27: =(266.776-I25) -> -27.224 | K27: 269.086 | L27: -62.519 | M27: 96.135 | N27: =SUM(F27-SUM(K27:M27)) -> 108.512 | O27: 195.645 | P27: 220.226 | Q27: 261.404 | R27: =SUM(G27-SUM(O27:Q27)) -> -399.965 | S27: -71.204 | T27: 26.961 | U27: 168.218 | V27: =SUM(H27-SUM(S27:U27)) -> -453.747 | W27: =155.359-W25 -> 88.359 | X27: =79.005-X25 -> 16.005 | Y27: =-21.693-Y25 -> -97.693 | Z27: =SUM(I27-SUM(W27:Y27)) -> -33.895 | AA27: =50.899-AA25 -> -31.101 | AB27: =39.63-AB25 -> -32.37 | AC27: =36.457-AC25 -> -30.543 | AE27: =SUM(L27:O27) -> 337.773 | AF27: =SUM(M27:P27) -> 620.518 | AG27: =SUM(N27:Q27) -> 785.787 | AH27: =SUM(O27:R27) -> 277.31 | AI27: =SUM(P27:S27) -> 10.461 | AJ27: =SUM(Q27:T27) -> -182.804 | AK27: =SUM(R27:U27) -> -275.99 | AL27: =SUM(S27:V27) -> -329.772 | ... AS27: =SUM(Z27:AC27) -> -127.909 | AU27: =SUM(AS27/AO27)-1 -> -0.71389876
B28: Earning Before Taxes | C28: =SUM(C22+SUM(C25:C27)) -> 1226.458 | D28: =SUM(D22+SUM(D25:D27)) -> 2062.231 | E28: =SUM(E22+SUM(E25:E27)) -> 3199.349 | F28: =SUM(F22+SUM(F25:F27)) -> 5840.103 | G28: =SUM(G22+SUM(G25:G27)) -> 5263.929 | H28: =SUM(H22+SUM(H25:H27)) -> 6205.405 | I28: =SUM(I22+SUM(I25:I27)) -> 9965.657 | K28: =SUM(K22+SUM(K25:K27)) -> 2034.502 | L28: =SUM(L22+SUM(L25:L27)) -> 1593.789 | M28: =SUM(M22+SUM(M25:M27)) -> 1660.959 | N28: =SUM(N22+SUM(N25:N27)) -> 550.853 | O28: =SUM(O22+SUM(O25:O27)) -> 1979.692 | P28: =SUM(P22+SUM(P25:P27)) -> 1623.054 | Q28: =SUM(Q22+SUM(Q25:Q27)) -> 1621.847 | R28: =SUM(R22+SUM(R25:R27)) -> 39.336 | ... AC28: =SUM(AC22+SUM(AC25:AC27)) -> 3109.41 | AE28: =SUM(AE22+SUM(AE25:AE27)) -> 5785.293 | AF28: =SUM(AF22+SUM(AF25:AF27)) -> 5814.558 | AG28: =SUM(AG22+SUM(AG25:AG27)) -> 5775.446 | AH28: =SUM(AH22+SUM(AH25:AH27)) -> 5263.929 | AI28: =SUM(AI22+SUM(AI25:AI27)) -> 4753.111 | AJ28: =SUM(AJ22+SUM(AJ25:AJ27)) -> 4809.389 | AK28: =SUM(AK22+SUM(AK25:AK27)) -> 5096.591 | AL28: =SUM(AL22+SUM(AL25:AL27)) -> 6205.405 | ... AS28: =SUM(AS22+SUM(AS25:AS27)) -> 12089.079 | AU28: =SUM(AS28/AO28)-1 -> 0.34629172
B29: EBT Margin (%) | C29: =C28/C11 -> 0.077651736 | D29: =D28/D11 -> 0.10231124 | E29: =E28/E11 -> 0.12799415 | F29: =F28/F11 -> 0.19665074 | G29: =G28/G11 -> 0.1664981 | H29: =H28/H11 -> 0.18400944 | I29: =I28/I11 -> 0.25552334 | K29: =K28/K11 -> 0.28401814 | L29: =L28/L11 -> 0.21708491 | M29: =M28/M11 -> 0.22195047 | N29: =N28/N11 -> 0.071452883 | O29: =O28/O11 -> 0.25162057 | P29: =P28/P11 -> 0.20364182 | Q29: =Q28/Q11 -> 0.20463425 | R29: =R28/R11 -> 0.0050096452 | ... AC29: =AC28/AC11 -> 0.27014136 | AE29: =AE28/AE11 -> 0.19029111 | AF29: =AF28/AF11 -> 0.18738086 | AG29: =AG28/AG11 -> 0.18350586 | AH29: =AH28/AH11 -> 0.1664981 | AI29: =AI28/AI11 -> 0.14895698 | AJ29: =AJ28/AJ11 -> 0.14970187 | AK29: =AK28/AK11 -> 0.15565663 | AL29: =AL28/AL11 -> 0.18400944 | ... AS29: =AS28/AS11 -> 0.27868642 | AU29: =SUM(AS29-AO29)*1000 -> 39.788065
B31: Provision for taxes | C31: -15.216 | D31: -195.315 | E31: -437.954 | F31: -723.875 | G31: -772.005 | H31: -797.415 | I31: -1254.026 | K31: -327.787 | L31: -240.776 | M31: -211.888 | N31: =SUM(F31-SUM(K31:M31)) -> 56.576 | O31: -382.245 | P31: -182.103 | Q31: -223.605 | R31: =SUM(G31-SUM(O31:Q31)) -> 15.948 | S31: -163.754 | T31: -191.722 | U31: -231.627 | V31: =SUM(H31-SUM(S31:U31)) -> -210.312 | W31: -282.37 | X31: -366.55 | Y31: -339.445 | Z31: =SUM(I31-SUM(W31:Y31)) -> -265.661 | AA31: -323.375 | AB31: -506.262 | AC31: -562.494 | AE31: =SUM(L31:O31) -> -778.333 | AF31: =SUM(M31:P31) -> -719.66 | AG31: =SUM(N31:Q31) -> -731.377 | AH31: =SUM(O31:R31) -> -772.005 | AI31: =SUM(P31:S31) -> -553.514 | AJ31: =SUM(Q31:T31) -> -563.133 | AK31: =SUM(R31:U31) -> -571.155 | AL31: =SUM(S31:V31) -> -797.415 | ... AS31: =SUM(Z31:AC31) -> -1657.792 | AU31: =SUM(AS31/AO31)-1 -> 0.38301811
B32: Net loss | C32: =SUM(C28+SUM(C31:C31)) -> 1211.242 | D32: =SUM(D28+SUM(D31:D31)) -> 1866.916 | E32: =SUM(E28+SUM(E31:E31)) -> 2761.395 | F32: =SUM(F28+SUM(F31:F31)) -> 5116.228 | G32: =SUM(G28+SUM(G31:G31)) -> 4491.924 | H32: =SUM(H28+SUM(H31:H31)) -> 5407.99 | I32: =SUM(I28+SUM(I31:I31)) -> 8711.631 | K32: =SUM(K28+SUM(K31:K31)) -> 1706.715 | L32: =SUM(L28+SUM(L31:L31)) -> 1353.013 | M32: =SUM(M28+SUM(M31:M31)) -> 1449.071 | N32: =SUM(N28+SUM(N31:N31)) -> 607.429 | O32: =SUM(O28+SUM(O31:O31)) -> 1597.447 | P32: =SUM(P28+SUM(P31:P31)) -> 1440.951 | Q32: =SUM(Q28+SUM(Q31:Q31)) -> 1398.242 | R32: =SUM(R28+SUM(R31:R31)) -> 55.284 | ... AC32: =SUM(AC28+SUM(AC31:AC31)) -> 2546.916 | AE32: =SUM(AE28+SUM(AE31:AE31)) -> 5006.96 | AF32: =SUM(AF28+SUM(AF31:AF31)) -> 5094.898 | AG32: =SUM(AG28+SUM(AG31:AG31)) -> 5044.069 | AH32: =SUM(AH28+SUM(AH31:AH31)) -> 4491.924 | AI32: =SUM(AI28+SUM(AI31:AI31)) -> 4199.597 | AJ32: =SUM(AJ28+SUM(AJ31:AJ31)) -> 4246.256 | AK32: =SUM(AK28+SUM(AK31:AK31)) -> 4525.436 | AL32: =SUM(AL28+SUM(AL31:AL31)) -> 5407.99 | ... AS32: =SUM(AS28+SUM(AS31:AS31)) -> 10431.287 | AU32: =SUM(AS32/AO32)-1 -> 0.34063385
B33: Net Margin (%) | C33: =C32/C11 -> 0.076688353 | D33: =D32/D11 -> 0.092621284 | E33: =E32/E11 -> 0.11047323 | F33: =F32/F11 -> 0.17227607 | G33: =G32/G11 -> 0.14207958 | H33: =H32/H11 -> 0.16036362 | I33: =I32/I11 -> 0.22336962 | K33: =K32/K11 -> 0.2382588 | L33: =L32/L11 -> 0.18428958 | M33: =M32/M11 -> 0.19363632 | N33: =N32/N11 -> 0.078791535 | O33: =O32/O11 -> 0.2030369 | P33: =P32/P11 -> 0.18079366 | Q33: =Q32/Q11 -> 0.17642121 | R33: =R32/R11 -> 0.0070407064 | ... AC33: =AC32/AC11 -> 0.22127264 | AE33: =AE32/AE11 -> 0.16469001 | AF33: =AF32/AF11 -> 0.16418899 | AG33: =AG32/AG11 -> 0.16026749 | AH33: =AH32/AH11 -> 0.14207958 | AI33: =AI32/AI11 -> 0.1316105 | AJ33: =AJ32/AJ11 -> 0.13217323 | AK33: =AK32/AK11 -> 0.1382128 | AL33: =AL32/AL11 -> 0.16036362 | ... AS33: =AS32/AS11 -> 0.24046977 | AU33: =SUM(AS33-AO33)*1000 -> 33.461911
B35: Basic Shares | E35: 440.922 | F35: 443.155 | G35: 444.698 | H35: 441.571 | I35: =(429519)/1000 -> 429.519 | K35: 443.224 | L35: 443.159 | M35: 442.778 | N35: =F35 -> 443.155 | O35: 444.146 | P35: 444.557 | Q35: 444.878 | R35: =G35 -> 444.698 | S35: 445.244 | T35: 443.881 | U35: 441.537 | V35: =K35 -> 443.224 | W35: 432.09 | X35: 430.065 | Y35: 428.239 | Z35: =I35 -> 429.519 | AA35: 427.27 | AB35: 425.211 | AC35: 424.455 | AE35: =O35 -> 444.146 | AF35: =P35 -> 444.557 | AG35: =Q35 -> 444.878 | AH35: =R35 -> 444.698 | AI35: =S35 -> 445.244 | AJ35: =T35 -> 443.881 | AK35: =U35 -> 441.537 | AL35: =V35 -> 443.224 | ... AS35: =AC35 -> 424.455 | AU35: =SUM(AS35/AO35)-1 -> -0.0088361873
B36: Basic EPS | E36: =E32/E35 -> 6.2627744 | F36: =F32/F35 -> 11.545008 | G36: =G32/G35 -> 10.101066 | H36: =H32/H35 -> 12.247158 | I36: =I32/I35 -> 20.282295 | K36: =K32/K35 -> 3.8506827 | L36: =L32/L35 -> 3.0531096 | M36: =M32/M35 -> 3.2726807 | N36: =N32/N35 -> 1.370692 | O36: =O32/O35 -> 3.5966709 | P36: =P32/P35 -> 3.2413189 | Q36: =Q32/Q35 -> 3.1429785 | R36: =R32/R35 -> 0.12431808 | ... AC36: =AC32/AC35 -> 6.0004382 | AE36: =AE32/AE35 -> 11.27323 | AF36: =AF32/AF35 -> 11.460618 | AG36: =AG32/AG35 -> 11.338095 | AH36: =AH32/AH35 -> 10.101066 | AI36: =AI32/AI35 -> 9.4321249 | AJ36: =AJ32/AJ35 -> 9.5662036 | AK36: =AK32/AK35 -> 10.249279 | AL36: =AL32/AL35 -> 12.201483 | ... AS36: =AS32/AS35 -> 24.575719 | AU36: =SUM(AS36/AO36)-1 -> 0.35258555
B38: Fully Diluted Shares | E38: 454.208 | F38: 455.372 | G38: 451.29 | H38: 449.498 | I38: 439.261 | K38: 455.641 | L38: 455.129 | M38: 454.925 | N38: =F38 -> 455.372 | O38: 452.984 | P38: 450.169 | Q38: 450.344 | R38: =G38 -> 451.29 | S38: 452.417 | T38: 451.572 | U38: 450.011 | V38: =K38 -> 455.641 | W38: 441.654 | X38: 439.739 | Y38: 437.898 | Z38: =I38 -> 439.261 | AA38: 436.962 | AB38: 434.883 | AC38: 434.039 | AE38: =O38 -> 452.984 | AF38: =P38 -> 450.169 | AG38: =Q38 -> 450.344 | AH38: =R38 -> 451.29 | AI38: =S38 -> 452.417 | AJ38: =T38 -> 451.572 | AK38: =U38 -> 450.011 | AL38: =V38 -> 455.641 | ... AS38: =AC38 -> 434.039 | AU38: =SUM(AS38/AO38)-1 -> -0.0088125545
B39: Fully Diluted EPS | E39: =E32/E38 -> 6.0795825 | F39: =F32/F38 -> 11.235271 | G39: =G32/G38 -> 9.9535199 | H39: =H32/H38 -> 12.031177 | I39: =I32/I38 -> 19.832471 | K39: =K32/K38 -> 3.745745 | L39: =L32/L38 -> 2.9728121 | M39: =M32/M38 -> 3.1852965 | N39: =N32/N38 -> 1.3339182 | O39: =O32/O38 -> 3.5264976 | P39: =P32/P38 -> 3.2009112 | Q39: =Q32/Q38 -> 3.104831 | R39: =R32/R38 -> 0.12250216 | ... AC39: =AC32/AC38 -> 5.8679427 | AE39: =AE32/AE38 -> 11.053282 | AF39: =AF32/AF38 -> 11.317745 | AG39: =AG32/AG38 -> 11.20048 | AH39: =AH32/AH38 -> 9.9535199 | AI39: =AI32/AI38 -> 9.28258 | AJ39: =AJ32/AJ38 -> 9.4032757 | AK39: =AK32/AK38 -> 10.056279 | AL39: =AL32/AL38 -> 11.868971 | ... AS39: =AS32/AS38 -> 24.033064 | AU39: =SUM(AS39/AO39)-1 -> 0.3525533
A41: X | B41: Balance Sheet | AN41: LTM | AU41: Variance
B42: =B7 -> Fiscal Period | C42: =C7 -> 2018 | D42: =D7 -> 2019 | E42: =E7 -> 2020 | F42: =F7 -> 2021 | G42: =G7 -> 2022 | H42: =H7 -> 2023 | I42: =I7 -> 2024 | K42: =K7 -> 1Q21 | L42: =L7 -> 2Q21 | M42: =M7 -> 3Q21 | N42: =N7 -> 4Q21 | O42: =O7 -> 1Q22 | P42: =P7 -> 2Q22 | Q42: =Q7 -> 3Q22 | R42: =R7 -> 4Q22 | ... AC42: =AC7 -> 3Q25 | AE42: =AE7 -> 1Q22 | AF42: =AF7 -> 2Q22 | AG42: =AG7 -> 3Q22 | AH42: =AH7 -> 4Q22 | AI42: =AI7 -> 1Q23 | AJ42: =AJ7 -> 2Q23 | AK42: =AK7 -> 3Q23 | AL42: =AL7 -> 4Q23 | ... AS42: =AS7 -> 3Q25
B43: =B8 -> Fiscal Period End Date | C43: =C8 -> 43465 | D43: =D8 -> 43830 | E43: =E8 -> 44196 | F43: =F8 -> 44561 | G43: =G8 -> 44926 | H43: =H8 -> 45291 | I43: =I8 -> 45657 | K43: =K8 -> 44286 | L43: =L8 -> 44377 | M43: =M8 -> 44469 | N43: =N8 -> 44561 | O43: =O8 -> 44651 | P43: =P8 -> 44742 | Q43: =Q8 -> 44834 | R43: =R8 -> 44926 | ... AC43: =AC8 -> 45930 | AE43: =AE8 -> 44651 | AF43: =AF8 -> 44742 | AG43: =AG8 -> 44834 | AH43: =AH8 -> 44926 | AI43: =AI8 -> 45016 | AJ43: =AJ8 -> 45107 | AK43: =AK8 -> 45199 | AL43: =AL8 -> 45291 | ... AS43: =AS8 -> 45930
B45: Current Assets
B46: Cash and cash equivalents | C46: 3794.483 | D46: 5018.437 | E46: 8205.55 | F46: 6027.804 | G46: 5147.176 | H46: 7116.913 | I46: 7804.733 | K46: 8403.705 | L46: 7777.53 | M46: 7526.681 | N46: =F46 -> 6027.804 | O46: 6008.946 | P46: 5819.449 | Q46: 6113.733 | R46: =G46 -> 5147.176 | S46: 6714.594 | T46: 7662.788 | U46: 7353.245 | V46: =H46 -> 7116.913 | W46: 7024.766 | X46: 6624.939 | Y46: 7457.025 | Z46: =I46 -> 7804.733 | AA46: 7199.848 | AB46: 8177.405 | AC46: 9287.287 | AE46: =O46 -> 6008.946 | AF46: =P46 -> 5819.449 | AG46: =Q46 -> 6113.733 | AH46: =R46 -> 5147.176 | AI46: =S46 -> 6714.594 | AJ46: =T46 -> 7662.788 | AK46: =U46 -> 7353.245 | AL46: =V46 -> 7116.913 | ... AS46: =AC46 -> 9287.287 | AU46: =SUM(AS46/AO46)-1 -> 0.24544131
B47: Other current assets | C47: 748.466 | D47: 1160.067 | E47: 1556.03 | F47: 2042.021 | G47: 3208.021 | H47: 2780.247 | I47: 3516.64 | K47: 1703.803 | L47: 1826.746 | M47: 1889.106 | N47: =F47 -> 2042.021 | O47: 2089.069 | P47: 2021.329 | Q47: 2703.17 | R47: =G47 -> 3208.021 | S47: 2655.119 | T47: 2929.347 | U47: 2912.028 | V47: =H47 -> 2780.247 | W47: 2875.574 | X47: 2959.641 | Y47: 2905.172 | Z47: =I47 -> 3516.64 | AA47: 3326.642 | AB47: 3602.586 | AC47: 3638.543 | AE47: =O47 -> 2089.069 | AF47: =P47 -> 2021.329 | AG47: =Q47 -> 2703.17 | AH47: =R47 -> 3208.021 | AI47: =S47 -> 2655.119 | AJ47: =T47 -> 2929.347 | AK47: =U47 -> 2912.028 | AL47: =V47 -> 2780.247 | ... AS47: =AC47 -> 3638.543 | AU47: =SUM(AS47/AO47)-1 -> 0.25243634
B48: Short-term investments | C48: 0 | D48: 0 | E48: 0 | F48: 0 | G48: 911.276 | H48: 20.973 | I48: 1779.006 | K48: 0 | L48: 0 | M48: 0 | N48: =F48 -> 0 | O48: 0 | P48: 0 | Q48: 0 | R48: =G48 -> 911.276 | S48: 1112.91 | T48: 914.201 | U48: 514.201 | V48: =H48 -> 20.973 | W48: 20.973 | X48: 30.973 | Y48: 1766.902 | Z48: =I48 -> 1779.006 | AA48: 1171.142 | AB48: 213.115 | AC48: 37.105 | AE48: =O48 -> 0 | AF48: =P48 -> 0 | AG48: =Q48 -> 0 | AH48: =R48 -> 911.276 | AI48: =S48 -> 1112.91 | AJ48: =T48 -> 914.201 | AK48: =U48 -> 514.201 | AL48: =V48 -> 20.973 | ... AS48: =AC48 -> 37.105 | AU48: =SUM(AS48/AO48)-1 -> -0.97899997
B49: Total Current Assets | C49: =SUM(C46:C48) -> 4542.949 | D49: =SUM(D46:D48) -> 6178.504 | E49: =SUM(E46:E48) -> 9761.58 | F49: =SUM(F46:F48) -> 8069.825 | G49: =SUM(G46:G48) -> 9266.473 | H49: =SUM(H46:H48) -> 9918.133 | I49: =SUM(I46:I48) -> 13100.379 | K49: =SUM(K46:K48) -> 10107.508 | L49: =SUM(L46:L48) -> 9604.276 | M49: =SUM(M46:M48) -> 9415.787 | N49: =SUM(N46:N48) -> 8069.825 | O49: =SUM(O46:O48) -> 8098.015 | P49: =SUM(P46:P48) -> 7840.778 | Q49: =SUM(Q46:Q48) -> 8816.903 | R49: =SUM(R46:R48) -> 9266.473 | ... AC49: =SUM(AC46:AC48) -> 12962.935 | AE49: =SUM(AE46:AE48) -> 8098.015 | AF49: =SUM(AF46:AF48) -> 7840.778 | AG49: =SUM(AG46:AG48) -> 8816.903 | AH49: =SUM(AH46:AH48) -> 9266.473 | AI49: =SUM(AI46:AI48) -> 10482.623 | AJ49: =SUM(AJ46:AJ48) -> 11506.336 | AK49: =SUM(AK46:AK48) -> 10779.474 | AL49: =SUM(AL46:AL48) -> 9918.133 | ... AS49: =SUM(AS46:AS48) -> 12962.935 | AU49: =SUM(AS49/AO49)-1 -> 0.068746739
B51: Non-Current Assets
B52: Content assets, net | C52: 20102.327 | D52: 24504.567 | E52: 25383.95 | F52: 30919.539 | G52: 32736.713 | H52: 31658.056 | I52: 32452.462 | K52: 26043.991 | L52: 27291.64 | M52: 28974.045 | N52: =F52 -> 30919.539 | O52: 31191.92 | P52: 32533.199 | Q52: 32777.34 | R52: =G52 -> 32736.713 | S52: 32349.184 | T52: 32520.774 | U52: 31749.861 | V52: =H52 -> 31658.056 | W52: 31662.1 | X52: 31927.355 | Y52: 32175.382 | Z52: =I52 -> 32452.462 | AA52: 32040.839 | AB52: 32089.394 | AC52: 32639.879 | AE52: =O52 -> 31191.92 | AF52: =P52 -> 32533.199 | AG52: =Q52 -> 32777.34 | AH52: =R52 -> 32736.713 | AI52: =S52 -> 32349.184 | AJ52: =T52 -> 32520.774 | AK52: =U52 -> 31749.861 | AL52: =V52 -> 31658.056 | ... AS52: =AC52 -> 32639.879 | AU52: =SUM(AS52/AO52)-1 -> 0.01443641
...

Sheet Revenue Drivers
B2: Netflix, Inc. (NASDAQ: NFLX) | C2: FYE | G2: FYE | K2: Quarterly | S2: Quarterly | T2: Quarterly | AA2: LTM | AE2: LTM | AG2: LTM | AM2: Variance
B3: Segment Anaysis | C3: ='Historical Financials'!C7 -> 2018 | D3: ='Historical Financials'!D7 -> 2019 | E3: ='Historical Financials'!E7 -> 2020 | F3: ='Historical Financials'!F7 -> 2021 | G3: ='Historical Financials'!G7 -> 2022 | H3: ='Historical Financials'!H7 -> 2023 | I3: ='Historical Financials'!I7 -> 2024 | K3: ='Historical Financials'!O7 -> 1Q22 | L3: ='Historical Financials'!P7 -> 2Q22 | M3: ='Historical Financials'!Q7 -> 3Q22 | N3: ='Historical Financials'!R7 -> 4Q22 | O3: ='Historical Financials'!S7 -> 1Q23 | P3: ='Historical Financials'!T7 -> 2Q23 | Q3: ='Historical Financials'!U7 -> 3Q23 | R3: ='Historical Financials'!V7 -> 4Q23 | ... Y3: ='Historical Financials'!AC7 -> 3Q25 | AA3: =O3 -> 1Q23 | AB3: =P3 -> 2Q23 | AC3: =Q3 -> 3Q23 | AD3: =R3 -> 4Q23 | AE3: =S3 -> 1Q24 | AF3: =T3 -> 2Q24 | AG3: =U3 -> 3Q24 | AH3: =V3 -> 4Q24 | ... AK3: =Y3 -> 3Q25
B4: $ in thousands except per share | C4: ='Historical Financials'!C8 -> 43465 | D4: ='Historical Financials'!D8 -> 43830 | E4: ='Historical Financials'!E8 -> 44196 | F4: ='Historical Financials'!F8 -> 44561 | G4: ='Historical Financials'!G8 -> 44926 | H4: ='Historical Financials'!H8 -> 45291 | I4: ='Historical Financials'!I8 -> 45657 | K4: ='Historical Financials'!O8 -> 44651 | L4: ='Historical Financials'!P8 -> 44742 | M4: ='Historical Financials'!Q8 -> 44834 | N4: ='Historical Financials'!R8 -> 44926 | O4: ='Historical Financials'!S8 -> 45016 | P4: ='Historical Financials'!T8 -> 45107 | Q4: ='Historical Financials'!U8 -> 45199 | R4: ='Historical Financials'!V8 -> 45291 | ... Y4: ='Historical Financials'!AC8 -> 45930 | AA4: =O4 -> 45016 | AB4: =P4 -> 45107 | AC4: =Q4 -> 45199 | AD4: =R4 -> 45291 | AE4: =S4 -> 45382 | AF4: =T4 -> 45473 | AG4: =U4 -> 45565 | AH4: =V4 -> 45657 | ... AK4: =Y4 -> 45930
A6: X | B6: Offerings Drivers
B8: Disaggregated Revenues
B9: UCAN Revenue | C9: 8281.532 | D9: 10051.208 | E9: 11455.396 | F9: 12972.1 | G9: 14084.643 | H9: 14873.783 | I9: 17359.369 | K9: 3350.424 | L9: 3537.863 | M9: 3601.565 | N9: =SUM(G9-SUM(K9:M9)) -> 3594.791 | O9: 3608.645 | P9: 3599.448 | Q9: 3735.133 | R9: =SUM(H9-SUM(O9:Q9)) -> 3930.557 | S9: 4224.315 | T9: 4295.56 | U9: 4322.476 | V9: =SUM(I9-SUM(S9:U9)) -> 4517.018 | W9: 4617.098 | X9: 4929.003 | Y9: 5071.781 | AA9: =SUM(L9:O9) -> 14342.864 | AB9: =SUM(M9:P9) -> 14404.449 | AC9: =SUM(N9:Q9) -> 14538.017 | AD9: =SUM(O9:R9) -> 14873.783 | AE9: =SUM(P9:S9) -> 15489.453 | AF9: =SUM(Q9:T9) -> 16185.565 | AG9: =SUM(R9:U9) -> 16772.908 | AH9: =SUM(S9:V9) -> 17359.369 | ... AK9: =SUM(V9:Y9) -> 19134.9 | AM9: =SUM(AK9/AG9)-1 -> 0.14082185
B10: EMEA Revenue | C10: 3963.707 | D10: 5543.067 | E10: 7772.252 | F10: 9699.819 | G10: 9745.015 | H10: 10556.487 | I10: 12387.035 | K10: 2561.831 | L10: 2457.235 | M10: 2375.814 | N10: =SUM(G10-SUM(K10:M10)) -> 2350.135 | O10: 2517.641 | P10: 2562.17 | Q10: 2693.146 | R10: =SUM(H10-SUM(O10:Q10)) -> 2783.53 | S10: 2958.193 | T10: 3007.772 | U10: 3133.466 | V10: =SUM(I10-SUM(S10:U10)) -> 3287.604 | W10: 3404.676 | X10: 3538.175 | Y10: 3699.052 | AG10: =SUM(R10:U10) -> 11882.961 | AH10: =SUM(S10:V10) -> 12387.035 | AI10: =SUM(T10:W10) -> 12833.518 | AJ10: =SUM(U10:X10) -> 13363.921 | AK10: =SUM(V10:Y10) -> 13929.507 | AM10: =SUM(AK10/AG10)-1 -> 0.17222526
B11: LATAM Revenue | C11: 2237.697 | D11: 2795.434 | E11: 3156.727 | F11: 3576.976 | G11: 4069.973 | H11: 4446.461 | I11: 4839.816 | K11: 998.948 | L11: 1030.234 | M11: 1023.945 | N11: =SUM(G11-SUM(K11:M11)) -> 1016.846 | O11: 1070.192 | P11: 1077.435 | Q11: 1142.811 | R11: =SUM(H11-SUM(O11:Q11)) -> 1156.023 | S11: 1165.008 | T11: 1204.145 | U11: 1240.892 | V11: =SUM(I11-SUM(S11:U11)) -> 1229.771 | W11: 1261.934 | X11: 1306.735 | Y11: 1370.913 | AG11: =SUM(R11:U11) -> 4766.068 | AH11: =SUM(S11:V11) -> 4839.816 | AI11: =SUM(T11:W11) -> 4936.742 | AJ11: =SUM(U11:X11) -> 5039.332 | AK11: =SUM(V11:Y11) -> 5169.353 | AM11: =SUM(AK11/AG11)-1 -> 0.084615872
B12: APAC Revenue | C12: 945.816 | D12: 1469.521 | E12: 2372.3 | F12: 3266.601 | G12: 3570.221 | H12: 3763.727 | I12: 4414.746 | K12: 916.754 | L12: 907.719 | M12: 889.037 | N12: =SUM(G12-SUM(K12:M12)) -> 856.711 | O12: 933.523 | P12: 919.273 | Q12: 948.216 | R12: =SUM(H12-SUM(O12:Q12)) -> 962.715 | S12: 1022.924 | T12: 1051.833 | U12: 1127.869 | V12: =SUM(I12-SUM(S12:U12)) -> 1212.12 | W12: 1259.093 | X12: 1305.253 | Y12: 1368.561 | AG12: =SUM(R12:U12) -> 4165.341 | AH12: =SUM(S12:V12) -> 4414.746 | AI12: =SUM(T12:W12) -> 4650.915 | AJ12: =SUM(U12:X12) -> 4904.335 | AK12: =SUM(V12:Y12) -> 5145.027 | AM12: =SUM(AK12/AG12)-1 -> 0.23519947
B13: Domestic DVD Revenue | C13: 365.589 | D13: 297.217 | E13: 239.381 | F13: 182.348 | G13: 145.698 | H13: 82.839 | I13: 0 | K13: 39.81 | L13: 37.09 | M13: 35.228 | N13: =SUM(G13-SUM(K13:M13)) -> 33.57 | O13: 31.502 | P13: 28.975 | Q13: 22.362 | R13: =SUM(H13-SUM(O13:Q13)) -> 0 | S13: 0 | T13: 0 | U13: 0 | V13: =SUM(I13-SUM(S13:U13)) -> 0 | W13: 0 | X13: 0 | Y13: 0 | AG13: =SUM(R13:U13) -> 0 | AH13: =SUM(S13:V13) -> 0 | AI13: =SUM(T13:W13) -> 0 | AJ13: =SUM(U13:X13) -> 0 | AK13: =SUM(V13:Y13) -> 0 | AM13: =SUM(AK13/AG13)-1 -> #DIV/0!
B14: Total Net Revenue | C14: =SUM(C9:C13) -> 15794.341 | D14: =SUM(D9:D13) -> 20156.447 | E14: =SUM(E9:E13) -> 24996.056 | F14: =SUM(F9:F13) -> 29697.844 | G14: =SUM(G9:G13) -> 31615.55 | H14: =SUM(H9:H13) -> 33723.297 | I14: =SUM(I9:I13) -> 39000.966 | K14: =SUM(K9:K13) -> 7867.767 | L14: =SUM(L9:L13) -> 7970.141 | M14: =SUM(M9:M13) -> 7925.589 | N14: =SUM(N9:N13) -> 7852.053 | O14: =SUM(O9:O13) -> 8161.503 | P14: =SUM(P9:P13) -> 8187.301 | Q14: =SUM(Q9:Q13) -> 8541.668 | R14: =SUM(R9:R13) -> 8832.825 | ... Y14: =SUM(Y9:Y13) -> 11510.307 | AA14: =SUM(AA9:AA13) -> 14342.864 | AB14: =SUM(AB9:AB13) -> 14404.449 | AC14: =SUM(AC9:AC13) -> 14538.017 | AD14: =SUM(AD9:AD13) -> 14873.783 | AE14: =SUM(AE9:AE13) -> 15489.453 | AF14: =SUM(AF9:AF13) -> 16185.565 | AG14: =SUM(AG9:AG13) -> 37587.278 | AH14: =SUM(AH9:AH13) -> 39000.966 | ... AK14: =SUM(AK9:AK13) -> 43378.787 | AM14: =SUM(AK14/AG14)-1 -> 0.15408163
B15: Variance Check | C15: =+C14-'Historical Financials'!C11 -> 0 | D15: =+D14-'Historical Financials'!D11 -> 0 | E15: =+E14-'Historical Financials'!E11 -> 0 | F15: =+F14-'Historical Financials'!F11 -> 0 | G15: =+G14-'Historical Financials'!G11 -> 0 | H15: =+H14-'Historical Financials'!H11 -> 0 | I15: =+I14-'Historical Financials'!I11 -> 0 | K15: =K14-'Historical Financials'!O11 -> 0 | L15: =L14-'Historical Financials'!P11 -> 0 | M15: =M14-'Historical Financials'!Q11 -> 0 | N15: =N14-'Historical Financials'!R11 -> 0 | O15: =O14-'Historical Financials'!S11 -> 0 | P15: =P14-'Historical Financials'!T11 -> 0 | Q15: =Q14-'Historical Financials'!U11 -> 0 | R15: =R14-'Historical Financials'!V11 -> 0 | ... Y15: =Y14-'Historical Financials'!AC11 -> 0 | AA15: =+AA14-'Historical Financials'!AI11 -> -17566.422 | AB15: =+AB14-'Historical Financials'!AJ11 -> -17721.997 | AC15: =+AC14-'Historical Financials'!AK11 -> -18204.508 | AD15: =+AD14-'Historical Financials'!AL11 -> -18849.514 | AE15: =+AE14-'Historical Financials'!AM11 -> -19442.781 | AF15: =+AF14-'Historical Financials'!AN11 -> -20118.678 | AG15: =+AG14-'Historical Financials'!AO11 -> 0 | AH15: =+AH14-'Historical Financials'!AP11 -> 0 | ... AJ15: =+AJ14-'Historical Financials'!AR11 -> 0 | AK15: =AK14-'Historical Financials'!AS11 -> 0

Sheet FCF
B2: ='Historical Financials'!B2 -> Netflix, Inc. (NASDAQ: NFLX) | C2: FYE | E2: FYE | I2: Quarterly | M2: Quarterly | S2: Quarterly | Y2: LTM | AF2: LTM | AG2: LTM | AM2: Variance
B3: FCF Analysis | C3: ='Historical Financials'!E7 -> 2020 | D3: ='Historical Financials'!F7 -> 2021 | E3: ='Historical Financials'!G7 -> 2022 | F3: ='Historical Financials'!H7 -> 2023 | G3: ='Historical Financials'!I7 -> 2024 | I3: ='Historical Financials'!O7 -> 1Q22 | J3: ='Historical Financials'!P7 -> 2Q22 | K3: ='Historical Financials'!Q7 -> 3Q22 | L3: ='Historical Financials'!R7 -> 4Q22 | M3: ='Historical Financials'!S7 -> 1Q23 | N3: ='Historical Financials'!T7 -> 2Q23 | O3: ='Historical Financials'!U7 -> 3Q23 | P3: ='Historical Financials'!V7 -> 4Q23 | ... W3: ='Historical Financials'!AC7 -> 3Q25 | Y3: =K3 -> 3Q22 | Z3: =L3 -> 4Q22 | AA3: =M3 -> 1Q23 | AB3: =N3 -> 2Q23 | AC3: =O3 -> 3Q23 | AD3: =P3 -> 4Q23 | AE3: =Q3 -> 1Q24 | AF3: =R3 -> 2Q24 | ... AK3: =W3 -> 3Q25
B4: $ mm except per share | C4: ='Historical Financials'!E8 -> 44196 | D4: ='Historical Financials'!F8 -> 44561 | E4: ='Historical Financials'!G8 -> 44926 | F4: ='Historical Financials'!H8 -> 45291 | G4: ='Historical Financials'!I8 -> 45657 | I4: ='Historical Financials'!O8 -> 44651 | J4: ='Historical Financials'!P8 -> 44742 | K4: ='Historical Financials'!Q8 -> 44834 | L4: ='Historical Financials'!R8 -> 44926 | M4: ='Historical Financials'!S8 -> 45016 | N4: ='Historical Financials'!T8 -> 45107 | O4: ='Historical Financials'!U8 -> 45199 | P4: ='Historical Financials'!V8 -> 45291 | ... W4: ='Historical Financials'!AC8 -> 45930 | Y4: =K4 -> 44834 | Z4: =L4 -> 44926 | AA4: =M4 -> 45016 | AB4: =N4 -> 45107 | AC4: =O4 -> 45199 | AD4: =P4 -> 45291 | AE4: =Q4 -> 45382 | AF4: =R4 -> 45473 | ... AK4: =W4 -> 45930
B6: ='Revenue Drivers'!B9 -> UCAN Revenue | C6: =('Revenue Drivers'!E9) -> 11455.396 | D6: =('Revenue Drivers'!F9) -> 12972.1 | E6: =('Revenue Drivers'!G9) -> 14084.643 | F6: =('Revenue Drivers'!H9) -> 14873.783 | G6: =('Revenue Drivers'!I9) -> 17359.369 | I6: =('Revenue Drivers'!K9) -> 3350.424 | J6: =('Revenue Drivers'!L9) -> 3537.863 | K6: =('Revenue Drivers'!M9) -> 3601.565 | L6: =('Revenue Drivers'!N9) -> 3594.791 | M6: =('Revenue Drivers'!O9) -> 3608.645 | N6: =('Revenue Drivers'!P9) -> 3599.448 | O6: =('Revenue Drivers'!Q9) -> 3735.133 | P6: =('Revenue Drivers'!R9) -> 3930.557 | ... W6: =('Revenue Drivers'!Y9) -> 5071.781 | Y6: =SUM(H6:K6) -> 10489.852 | Z6: =SUM(I6:L6) -> 14084.643 | AA6: =SUM(J6:M6) -> 14342.864 | AB6: =SUM(K6:N6) -> 14404.449 | AC6: =SUM(L6:O6) -> 14538.017 | AD6: =SUM(M6:P6) -> 14873.783 | AE6: =SUM(N6:Q6) -> 15489.453 | AF6: =SUM(O6:R6) -> 16185.565 | ... AK6: =SUM(T6:W6) -> 19134.9 | AM6: =SUM(AK6/AG6)-1 -> 0.14082185
B7: ='Revenue Drivers'!B10 -> EMEA Revenue | C7: =('Revenue Drivers'!E10) -> 7772.252 | D7: =('Revenue Drivers'!F10) -> 9699.819 | E7: =('Revenue Drivers'!G10) -> 9745.015 | F7: =('Revenue Drivers'!H10) -> 10556.487 | G7: =('Revenue Drivers'!I10) -> 12387.035 | I7: =('Revenue Drivers'!K10) -> 2561.831 | J7: =('Revenue Drivers'!L10) -> 2457.235 | K7: =('Revenue Drivers'!M10) -> 2375.814 | L7: =('Revenue Drivers'!N10) -> 2350.135 | M7: =('Revenue Drivers'!O10) -> 2517.641 | N7: =('Revenue Drivers'!P10) -> 2562.17 | O7: =('Revenue Drivers'!Q10) -> 2693.146 | P7: =('Revenue Drivers'!R10) -> 2783.53 | ... W7: =('Revenue Drivers'!Y10) -> 3699.052 | AG7: =SUM(P7:S7) -> 11882.961 | AH7: =SUM(Q7:T7) -> 12387.035 | AI7: =SUM(R7:U7) -> 12833.518 | AJ7: =SUM(S7:V7) -> 13363.921 | AK7: =SUM(T7:W7) -> 13929.507 | AM7: =SUM(AK7/AG7)-1 -> 0.17222526
B8: ='Revenue Drivers'!B11 -> LATAM Revenue | C8: =('Revenue Drivers'!E11) -> 3156.727 | D8: =('Revenue Drivers'!F11) -> 3576.976 | E8: =('Revenue Drivers'!G11) -> 4069.973 | F8: =('Revenue Drivers'!H11) -> 4446.461 | G8: =('Revenue Drivers'!I11) -> 4839.816 | I8: =('Revenue Drivers'!K11) -> 998.948 | J8: =('Revenue Drivers'!L11) -> 1030.234 | K8: =('Revenue Drivers'!M11) -> 1023.945 | L8: =('Revenue Drivers'!N11) -> 1016.846 | M8: =('Revenue Drivers'!O11) -> 1070.192 | N8: =('Revenue Drivers'!P11) -> 1077.435 | O8: =('Revenue Drivers'!Q11) -> 1142.811 | P8: =('Revenue Drivers'!R11) -> 1156.023 | ... W8: =('Revenue Drivers'!Y11) -> 1370.913 | AG8: =SUM(P8:S8) -> 4766.068 | AH8: =SUM(Q8:T8) -> 4839.816 | AI8: =SUM(R8:U8) -> 4936.742 | AJ8: =SUM(S8:V8) -> 5039.332 | AK8: =SUM(T8:W8) -> 5169.353 | AM8: =SUM(AK8/AG8)-1 -> 0.084615872
B9: ='Revenue Drivers'!B12 -> APAC Revenue | C9: =('Revenue Drivers'!E12) -> 2372.3 | D9: =('Revenue Drivers'!F12) -> 3266.601 | E9: =('Revenue Drivers'!G12) -> 3570.221 | F9: =('Revenue Drivers'!H12) -> 3763.727 | G9: =('Revenue Drivers'!I12) -> 4414.746 | I9: =('Revenue Drivers'!K12) -> 916.754 | J9: =('Revenue Drivers'!L12) -> 907.719 | K9: =('Revenue Drivers'!M12) -> 889.037 | L9: =('Revenue Drivers'!N12) -> 856.711 | M9: =('Revenue Drivers'!O12) -> 933.523 | N9: =('Revenue Drivers'!P12) -> 919.273 | O9: =('Revenue Drivers'!Q12) -> 948.216 | P9: =('Revenue Drivers'!R12) -> 962.715 | ... W9: =('Revenue Drivers'!Y12) -> 1368.561 | AG9: =SUM(P9:S9) -> 4165.341 | AH9: =SUM(Q9:T9) -> 4414.746 | AI9: =SUM(R9:U9) -> 4650.915 | AJ9: =SUM(S9:V9) -> 4904.335 | AK9: =SUM(T9:W9) -> 5145.027 | AM9: =SUM(AK9/AG9)-1 -> 0.23519947
B10: ='Revenue Drivers'!B13 -> Domestic DVD Revenue | C10: =('Revenue Drivers'!E13) -> 239.381 | D10: =('Revenue Drivers'!F13) -> 182.348 | E10: =('Revenue Drivers'!G13) -> 145.698 | F10: =('Revenue Drivers'!H13) -> 82.839 | G10: =('Revenue Drivers'!I13) -> 0 | I10: =('Revenue Drivers'!K13) -> 39.81 | J10: =('Revenue Drivers'!L13) -> 37.09 | K10: =('Revenue Drivers'!M13) -> 35.228 | L10: =('Revenue Drivers'!N13) -> 33.57 | M10: =('Revenue Drivers'!O13) -> 31.502 | N10: =('Revenue Drivers'!P13) -> 28.975 | O10: =('Revenue Drivers'!Q13) -> 22.362 | P10: =('Revenue Drivers'!R13) -> 0 | ... W10: =('Revenue Drivers'!Y13) -> 0 | AG10: =SUM(P10:S10) -> 0 | AH10: =SUM(Q10:T10) -> 0 | AI10: =SUM(R10:U10) -> 0 | AJ10: =SUM(S10:V10) -> 0 | AK10: =SUM(T10:W10) -> 0 | AM10: =SUM(AK10/AG10)-1 -> #DIV/0!
B11: Total Revenue | C11: =SUM(C6:C10) -> 24996.056 | D11: =SUM(D6:D10) -> 29697.844 | E11: =SUM(E6:E10) -> 31615.55 | F11: =SUM(F6:F10) -> 33723.297 | G11: =SUM(G6:G10) -> 39000.966 | I11: =SUM(I6:I10) -> 7867.767 | J11: =SUM(J6:J10) -> 7970.141 | K11: =SUM(K6:K10) -> 7925.589 | L11: =SUM(L6:L10) -> 7852.053 | M11: =SUM(M6:M10) -> 8161.503 | N11: =SUM(N6:N10) -> 8187.301 | O11: =SUM(O6:O10) -> 8541.668 | P11: =SUM(P6:P10) -> 8832.825 | ... W11: =SUM(W6:W10) -> 11510.307 | Y11: =SUM(Y6:Y10) -> 10489.852 | Z11: =SUM(Z6:Z10) -> 14084.643 | AA11: =SUM(AA6:AA10) -> 14342.864 | AB11: =SUM(AB6:AB10) -> 14404.449 | AC11: =SUM(AC6:AC10) -> 14538.017 | AD11: =SUM(AD6:AD10) -> 14873.783 | AE11: =SUM(AE6:AE10) -> 15489.453 | AF11: =SUM(AF6:AF10) -> 16185.565 | ... AK11: =SUM(AK6:AK10) -> 43378.787 | AM11: =SUM(AK11/AG11)-1 -> 0.15408163
B12: Y/Y Growth (%) | D12: =SUM(D11/C11)-1 -> 0.18810119 | E12: =SUM(E11/D11)-1 -> 0.064573913 | F12: =SUM(F11/E11)-1 -> 0.066668048 | G12: =SUM(G11/F11)-1 -> 0.1564992 | M12: =SUM(M11/I11)-1 -> 0.0373341 | N12: =SUM(N11/J11)-1 -> 0.027246695 | O12: =SUM(O11/K11)-1 -> 0.077732898 | P12: =SUM(P11/L11)-1 -> 0.12490644 | Q12: =SUM(Q11/M11)-1 -> 0.14812676 | R12: =SUM(R11/N11)-1 -> 0.16757769 | S12: =SUM(S11/O11)-1 -> 0.15020895 | T12: =SUM(T11/P11)-1 -> 0.16004936 | ... W12: =SUM(W11/S11)-1 -> 0.17156793 | AC12: =SUM(AC11/Y11)-1 -> 0.3859125 | AD12: =SUM(AD11/Z11)-1 -> 0.056028399 | AE12: =SUM(AE11/AA11)-1 -> 0.079941426 | AF12: =SUM(AF11/AB11)-1 -> 0.12365041 | AG12: =SUM(AG11/AC11)-1 -> 1.5854474 | AH12: =SUM(AH11/AD11)-1 -> 1.6221282 | AI12: =SUM(AI11/AE11)-1 -> 1.5935924 | AJ12: =SUM(AJ11/AF11)-1 -> 1.5759486 | AK12: =SUM(AK11/AG11)-1 -> 0.15408163 | AM12: =SUM(AK12-AG12)*10000 -> -14313.658
B13: Q/Q Growth (%) | C13: N/A | D13: N/A | E13: N/A | F13: N/A | G13: N/A | J13: =SUM(J11/I11)-1 -> 0.013011824 | K13: =SUM(K11/J11)-1 -> -0.0055898635 | L13: =SUM(L11/K11)-1 -> -0.009278301 | M13: =SUM(M11/L11)-1 -> 0.039410075 | N13: =SUM(N11/M11)-1 -> 0.0031609374 | O13: =SUM(O11/N11)-1 -> 0.043282518 | P13: =SUM(P11/O11)-1 -> 0.034086668 | Q13: =SUM(Q11/P11)-1 -> 0.060865578 | ... W13: =SUM(W11/V11)-1 -> 0.038914572 | Y13: N/A | Z13: N/A | AA13: N/A | AB13: N/A | AC13: N/A | AD13: N/A | AE13: N/A | AF13: N/A | AG13: N/A | AH13: N/A | AI13: N/A | AJ13: N/A | AK13: N/A
B15: (-) Amortization of content assets | C15: =('Historical Financials'!E13) -> -10806.912 | D15: =('Historical Financials'!F13) -> -12230.367 | E15: =('Historical Financials'!G13) -> -14026.132 | F15: =('Historical Financials'!H13) -> -14197.437 | G15: =('Historical Financials'!I13) -> -15301.517 | I15: =('Historical Financials'!O13) -> -3166.365 | J15: =('Historical Financials'!P13) -> -3261.348 | K15: =('Historical Financials'!Q13) -> -3653.592 | L15: =('Historical Financials'!R13) -> -3944.827 | M15: =('Historical Financials'!S13) -> -3459.984 | N15: =('Historical Financials'!T13) -> -3410.021 | O15: =('Historical Financials'!U13) -> -3573.353 | P15: =('Historical Financials'!V13) -> -3754.079 | ... W15: =('Historical Financials'!AC13) -> -4002.744 | Y15: =SUM(H15:K15) -> -10081.305 | Z15: =SUM(I15:L15) -> -14026.132 | AA15: =SUM(J15:M15) -> -14319.751 | AB15: =SUM(K15:N15) -> -14468.424 | AC15: =SUM(L15:O15) -> -14388.185 | AD15: =SUM(M15:P15) -> -14197.437 | AE15: =SUM(N15:Q15) -> -14408.258 | AF15: =SUM(O15:R15) -> -14767.927 | ... AK15: =SUM(T15:W15) -> -15819.431 | AM15: =SUM(AK15/AG15)-1 -> 0.062127709
B16: (-) Other Cost of Revenues | C16: =('Historical Financials'!E14) -> -4469.407 | D16: =('Historical Financials'!F14) -> -5102.316 | E16: =('Historical Financials'!G14) -> -5142.153 | F16: =('Historical Financials'!H14) -> -5517.931 | G16: =('Historical Financials'!I14) -> -5736.947 | I16: =('Historical Financials'!O14) -> -1118.34 | J16: =('Historical Financials'!P14) -> -1429.407 | K16: =('Historical Financials'!Q14) -> -1135.073 | L16: =('Historical Financials'!R14) -> -1459.333 | M16: =('Historical Financials'!S14) -> -1343.641 | N16: =('Historical Financials'!T14) -> -1263.449 | O16: =('Historical Financials'!U14) -> -1357.435 | P16: =('Historical Financials'!V14) -> -1553.406 | ... W16: =('Historical Financials'!AC14) -> -2161.506 | AG16: =SUM(P16:S16) -> -5684.49 | AH16: =SUM(Q16:T16) -> -5736.947 | AI16: =SUM(R16:U16) -> -5870.714 | AJ16: =SUM(S16:V16) -> -5959.498 | AK16: =SUM(T16:W16) -> -6700.641
B17: Gross Profit | C17: =SUM(C11+SUM(C15:C16)) -> 9719.737 | D17: =SUM(D11+SUM(D15:D16)) -> 12365.161 | E17: =SUM(E11+SUM(E15:E16)) -> 12447.265 | F17: =SUM(F11+SUM(F15:F16)) -> 14007.929 | G17: =SUM(G11+SUM(G15:G16)) -> 17962.502 | I17: =SUM(I11+SUM(I15:I16)) -> 3583.062 | J17: =SUM(J11+SUM(J15:J16)) -> 3279.386 | K17: =SUM(K11+SUM(K15:K16)) -> 3136.924 | L17: =SUM(L11+SUM(L15:L16)) -> 2447.893 | M17: =SUM(M11+SUM(M15:M16)) -> 3357.878 | N17: =SUM(N11+SUM(N15:N16)) -> 3513.831 | O17: =SUM(O11+SUM(O15:O16)) -> 3610.88 | P17: =SUM(P11+SUM(P15:P16)) -> 3525.34 | ... W17: =SUM(W11+SUM(W15:W16)) -> 5346.057 | Y17: =SUM(Y11+SUM(Y15:Y16)) -> 408.547 | Z17: =SUM(Z11+SUM(Z15:Z16)) -> 58.511 | AA17: =SUM(AA11+SUM(AA15:AA16)) -> 23.113 | AB17: =SUM(AB11+SUM(AB15:AB16)) -> -63.975 | AC17: =SUM(AC11+SUM(AC15:AC16)) -> 149.832 | AD17: =SUM(AD11+SUM(AD15:AD16)) -> 676.346 | AE17: =SUM(AE11+SUM(AE15:AE16)) -> 1081.195 | AF17: =SUM(AF11+SUM(AF15:AF16)) -> 1417.638 | ... AK17: =SUM(AK11+SUM(AK15:AK16)) -> 20858.715 | AM17: =SUM(AK17/AG17)-1 -> 0.22635613
B18: Gross Margin (%) | C18: =C17/C11 -> 0.38885083 | D18: =D17/D11 -> 0.41636561 | E18: =E17/E11 -> 0.39370705 | F18: =F17/F11 -> 0.4153784 | G18: =G17/G11 -> 0.46056557 | I18: =I17/I11 -> 0.45541028 | J18: =J17/J11 -> 0.41145897 | K18: =K17/K11 -> 0.39579696 | L18: =L17/L11 -> 0.31175197 | M18: =M17/M11 -> 0.41142888 | N18: =N17/N11 -> 0.42918063 | O18: =O17/O11 -> 0.4227371 | P18: =P17/P11 -> 0.39911806 | ... W18: =W17/W11 -> 0.46445825 | Y18: =Y17/Y11 -> 0.038946879 | Z18: =Z17/Z11 -> 0.0041542409 | AA18: =AA17/AA11 -> 0.0016114634 | AB18: =AB17/AB11 -> -0.0044413361 | AC18: =AC17/AC11 -> 0.01030622 | AD18: =AD17/AD11 -> 0.045472359 | AE18: =AE17/AE11 -> 0.069802013 | AF18: =AF17/AF11 -> 0.087586562 | ... AK18: =AK17/AK11 -> 0.48085058 | AM18: =SUM(AK18-AG18)*10000 -> 283.38618
B20: (-) Marketing | C20: =('Historical Financials'!E19) -> -2228.362 | D20: =('Historical Financials'!F19) -> -2545.146 | E20: =('Historical Financials'!G19) -> -2530.502 | F20: =('Historical Financials'!H19) -> -2657.883 | G20: =('Historical Financials'!I19) -> -2917.554 | I20: =('Historical Financials'!O19) -> -555.978 | J20: =('Historical Financials'!P19) -> -574.96 | K20: =('Historical Financials'!Q19) -> -567.954 | L20: =('Historical Financials'!R19) -> -831.61 | M20: =('Historical Financials'!S19) -> -555.362 | N20: =('Historical Financials'!T19) -> -627.168 | O20: =('Historical Financials'!U19) -> -558.736 | P20: =('Historical Financials'!V19) -> -916.617 | ... W20: =('Historical Financials'!AC19) -> -786.295 | Y20: =SUM(H20:K20) -> -1698.892 | Z20: =SUM(I20:L20) -> -2530.502 | AA20: =SUM(J20:M20) -> -2529.886 | AB20: =SUM(K20:N20) -> -2582.094 | AC20: =SUM(L20:O20) -> -2572.876 | AD20: =SUM(M20:P20) -> -2657.883 | AE20: =SUM(N20:Q20) -> -2756.861 | AF20: =SUM(O20:R20) -> -2773.777 | ... AK20: =SUM(T20:W20) -> -3164.134 | AM20: =SUM(AK20/AG20)-1 -> 0.10712755
