Workbook

Sheet Historical Financials
B2: Qualcomm (NASDAQ: QCOM)
B3: Historical Financials
B4: $ in thousands except per share
A6: X | B6: Income Statement | E6: FYE | I6: Quarterly | M6: Quarterly | S6: Quarterly | AH6: LTM | AI6: LTM | AO6: Variance
B7: Fiscal Period | C7: 2020 | D7: 2021 | E7: 2022 | F7: 2023 | G7: 2024 | I7: 1Q22 | J7: 2Q22 | K7: 3Q22 | L7: 4Q22 | M7: 1Q23 | N7: 2Q23 | O7: 3Q23 | P7: 4Q23 | Q7: 1Q24 | R7: 2Q24 | S7: 3Q24 | T7: 4Q24 | U7: 1Q25 | V7: 2Q25 | W7: 3Q25 | Y7: =I7 -> 1Q22 | Z7: =J7 -> 2Q22 | AA7: =K7 -> 3Q22 | AB7: =L7 -> 4Q22 | AC7: =M7 -> 1Q23 | AD7: =N7 -> 2Q23 | AE7: =O7 -> 3Q23 | AF7: =P7 -> 4Q23 | ... AM7: =W7 -> 3Q25
B8: Fiscal Period End Date | C8: 44196 | D8: 44561 | E8: 44926 | F8: 45291 | G8: 45657 | I8: 44651 | J8: 44742 | K8: 44834 | L8: =E8 -> 44926 | M8: 45016 | N8: 45107 | O8: 45199 | P8: =F8 -> 45291 | Q8: 45382 | R8: 45473 | S8: 45565 | T8: =G8 -> 45657 | U8: 45747 | V8: 45838 | W8: 45930 | Y8: =I8 -> 44651 | Z8: =J8 -> 44742 | AA8: =K8 -> 44834 | AB8: =L8 -> 44926 | AC8: =M8 -> 45016 | AD8: =N8 -> 45107 | AE8: =O8 -> 45199 | AF8: =P8 -> 45291 | ... AM8: =W8 -> 45930
B10: Consolidated Revenue | C10: 23531 | D10: 33566 | E10: 44200 | F10: 35820 | G10: 38962 | I10: 10705 | J10: 11164 | K10: 10936 | L10: =SUM(E10-SUM(I10:K10)) -> 11395 | M10: 9463 | N10: 9275 | O10: 8451 | P10: =SUM(F10-SUM(M10:O10)) -> 8631 | Q10: 9935 | R10: 9389 | S10: 9393 | T10: =SUM(G10-SUM(Q10:S10)) -> 10245 | Y10: =SUM(I10:I10) -> 10705 | Z10: =SUM(I10:J10) -> 21869 | AA10: =SUM(I10:K10) -> 32805 | AB10: =SUM(I10:L10) -> 44200 | AC10: =SUM(J10:M10) -> 42958 | AD10: =SUM(K10:N10) -> 41069 | AE10: =SUM(L10:O10) -> 38584 | AF10: =SUM(M10:P10) -> 35820 | AG10: =SUM(N10:Q10) -> 36292 | AH10: =SUM(O10:R10) -> 36406 | AI10: =SUM(P10:S10) -> 37348 | ... AM10: =SUM(T10:W10) -> 10245 | AO10: =SUM(AM10/AI10)-1 -> -0.72568812
B11: Total Revenue | C11: =+SUM(C10:C10) -> 23531 | D11: =+SUM(D10:D10) -> 33566 | E11: =+SUM(E10:E10) -> 44200 | F11: =+SUM(F10:F10) -> 35820 | G11: =+SUM(G10:G10) -> 38962 | I11: =+SUM(I10:I10) -> 10705 | J11: =+SUM(J10:J10) -> 11164 | K11: =+SUM(K10:K10) -> 10936 | L11: =+SUM(L10:L10) -> 11395 | M11: =+SUM(M10:M10) -> 9463 | N11: =+SUM(N10:N10) -> 9275 | O11: =+SUM(O10:O10) -> 8451 | P11: =+SUM(P10:P10) -> 8631 | ... W11: =+SUM(W10:W10) -> 0 | Y11: =+SUM(Y10:Y10) -> 10705 | Z11: =+SUM(Z10:Z10) -> 21869 | AA11: =+SUM(AA10:AA10) -> 32805 | AB11: =+SUM(AB10:AB10) -> 44200 | AC11: =+SUM(AC10:AC10) -> 42958 | AD11: =+SUM(AD10:AD10) -> 41069 | AE11: =+SUM(AE10:AE10) -> 38584 | AF11: =+SUM(AF10:AF10) -> 35820 | ... AM11: =+SUM(AM10:AM10) -> 10245 | AO11: =SUM(AM11/AI11)-1 -> -0.72568812
B13: Cost of revenue | C13: -9255 | D13: -14262 | E13: -18635 | F13: -15869 | G13: -17060 | I13: -4303 | J13: -4648 | K13: -4816 | L13: =SUM(E13-SUM(I13:K13)) -> -4868 | M13: -4044 | N13: -4153 | O13: -3792 | P13: =SUM(F13-SUM(M13:O13)) -> -3880 | Q13: -4312 | R13: -4106 | S13: -4174 | T13: =SUM(G13-SUM(Q13:S13)) -> -4468 | Y13: =SUM(I13:I13) -> -4303 | Z13: =SUM(I13:J13) -> -8951 | AA13: =SUM(I13:K13) -> -13767 | AB13: =SUM(I13:L13) -> -18635 | AC13: =SUM(J13:M13) -> -18376 | AD13: =SUM(K13:N13) -> -17881 | AE13: =SUM(L13:O13) -> -16857 | AF13: =SUM(M13:P13) -> -15869 | AG13: =SUM(N13:Q13) -> -16137 | AH13: =SUM(O13:R13) -> -16090 | AI13: =SUM(P13:S13) -> -16472 | ... AM13: =SUM(T13:W13) -> -4468 | AO13: =SUM(AM13/AI13)-1 -> -0.72875182
B14: Gross Profit | C14: =+SUM(C11+SUM(C13:C13)) -> 14276 | D14: =+SUM(D11+SUM(D13:D13)) -> 19304 | E14: =+SUM(E11+SUM(E13:E13)) -> 25565 | F14: =+SUM(F11+SUM(F13:F13)) -> 19951 | G14: =+SUM(G11+SUM(G13:G13)) -> 21902 | I14: =+SUM(I11+SUM(I13:I13)) -> 6402 | J14: =+SUM(J11+SUM(J13:J13)) -> 6516 | K14: =+SUM(K11+SUM(K13:K13)) -> 6120 | L14: =+SUM(L11+SUM(L13:L13)) -> 6527 | M14: =+SUM(M11+SUM(M13:M13)) -> 5419 | N14: =+SUM(N11+SUM(N13:N13)) -> 5122 | O14: =+SUM(O11+SUM(O13:O13)) -> 4659 | P14: =+SUM(P11+SUM(P13:P13)) -> 4751 | ... W14: =+SUM(W11+SUM(W13:W13)) -> 0 | Y14: =+SUM(Y11+SUM(Y13:Y13)) -> 6402 | Z14: =+SUM(Z11+SUM(Z13:Z13)) -> 12918 | AA14: =+SUM(AA11+SUM(AA13:AA13)) -> 19038 | AB14: =+SUM(AB11+SUM(AB13:AB13)) -> 25565 | AC14: =+SUM(AC11+SUM(AC13:AC13)) -> 24582 | AD14: =+SUM(AD11+SUM(AD13:AD13)) -> 23188 | AE14: =+SUM(AE11+SUM(AE13:AE13)) -> 21727 | AF14: =+SUM(AF11+SUM(AF13:AF13)) -> 19951 | ... AM14: =+SUM(AM11+SUM(AM13:AM13)) -> 5777 | AO14: =SUM(AM14/AI14)-1 -> -0.72327074
B15: Gross Margin (%) | C15: =C14/C11 -> 0.60668905 | D15: =D14/D11 -> 0.57510576 | E15: =E14/E11 -> 0.57839367 | F15: =F14/F11 -> 0.55697934 | G15: =G14/G11 -> 0.56213747 | I15: =I14/I11 -> 0.5980383 | J15: =J14/J11 -> 0.58366177 | K15: =K14/K11 -> 0.5596196 | L15: =L14/L11 -> 0.57279509 | M15: =M14/M11 -> 0.57265138 | N15: =N14/N11 -> 0.5522372 | O15: =O14/O11 -> 0.5512957 | P15: =P14/P11 -> 0.55045765 | ... W15: =W14/W11 -> #DIV/0! | Y15: =Y14/Y11 -> 0.5980383 | Z15: =Z14/Z11 -> 0.59069916 | AA15: =AA14/AA11 -> 0.58033836 | AB15: =AB14/AB11 -> 0.57839367 | AC15: =AC14/AC11 -> 0.57223334 | AD15: =AD14/AD11 -> 0.56461078 | AE15: =AE14/AE11 -> 0.56310906 | AF15: =AF14/AF11 -> 0.55697934 | ... AM15: =AM14/AM11 -> 0.56388482 | AO15: =SUM(AM15-AI15)*1000 -> 4.9258415
B17: Research and development | C17: -5975 | D17: -7176 | E17: -8194 | F17: -8818 | G17: -8893 | I17: -1930 | J17: -2034 | K17: -2052 | L17: =SUM(E17-SUM(I17:K17)) -> -2178 | M17: -2251 | N17: -2210 | O17: -2222 | P17: =SUM(F17-SUM(M17:O17)) -> -2135 | Q17: -2096 | R17: -2236 | S17: -2259 | T17: =SUM(G17-SUM(Q17:S17)) -> -2302 | Y17: =SUM(I17:I17) -> -1930 | Z17: =SUM(I17:J17) -> -3964 | AA17: =SUM(I17:K17) -> -6016 | AB17: =SUM(I17:L17) -> -8194 | AC17: =SUM(J17:M17) -> -8515 | AD17: =SUM(K17:N17) -> -8691 | AE17: =SUM(L17:O17) -> -8861 | AF17: =SUM(M17:P17) -> -8818 | AG17: =SUM(N17:Q17) -> -8663 | AH17: =SUM(O17:R17) -> -8689 | AI17: =SUM(P17:S17) -> -8726 | ... AM17: =SUM(T17:W17) -> -2302 | AO17: =SUM(AM17/AI17)-1 -> -0.73619069
B18: Selling, general and administrative | C18: -2074 | D18: -2339 | E18: -2570 | F18: -2483 | G18: -2759 | I18: -608 | J18: -624 | K18: -655 | L18: =SUM(E18-SUM(I18:K18)) -> -683 | M18: -623 | N18: -614 | O18: -618 | P18: =SUM(F18-SUM(M18:O18)) -> -628 | Q18: -627 | R18: -707 | S18: -664 | T18: =SUM(G18-SUM(Q18:S18)) -> -761 | Y18: =SUM(I18:I18) -> -608 | Z18: =SUM(I18:J18) -> -1232 | AA18: =SUM(I18:K18) -> -1887 | AB18: =SUM(I18:L18) -> -2570 | AC18: =SUM(J18:M18) -> -2585 | AD18: =SUM(K18:N18) -> -2575 | AE18: =SUM(L18:O18) -> -2538 | AF18: =SUM(M18:P18) -> -2483 | AG18: =SUM(N18:Q18) -> -2487 | AH18: =SUM(O18:R18) -> -2580 | AI18: =SUM(P18:S18) -> -2626 | ... AM18: =SUM(T18:W18) -> -761 | AO18: =SUM(AM18/AI18)-1 -> -0.71020564
B19: Other Expenses | C19: 28 | D19: 0 | E19: 1059 | F19: -862 | G19: -179 | I19: 0 | J19: 0 | K19: 1059 | L19: =SUM(E19-SUM(I19:K19)) -> 0 | M19: -80 | N19: -208 | O19: 4 | P19: =SUM(F19-SUM(M19:O19)) -> -578 | Q19: 28 | R19: 0 | S19: -75 | T19: =SUM(G19-SUM(Q19:S19)) -> -132 | Y19: =SUM(I19:I19) -> 0 | Z19: =SUM(I19:J19) -> 0 | AA19: =SUM(I19:K19) -> 1059 | AB19: =SUM(I19:L19) -> 1059 | AC19: =SUM(J19:M19) -> 979 | AD19: =SUM(K19:N19) -> 771 | AE19: =SUM(L19:O19) -> -284 | AF19: =SUM(M19:P19) -> -862 | AG19: =SUM(N19:Q19) -> -754 | AH19: =SUM(O19:R19) -> -546 | AI19: =SUM(P19:S19) -> -625 | ... AM19: =SUM(T19:W19) -> -132 | AO19: =SUM(AM19/AI19)-1 -> -0.7888
B20: Operating Profit | C20: =+SUM(C14+SUM(C17:C19)) -> 6255 | D20: =+SUM(D14+SUM(D17:D19)) -> 9789 | E20: =+SUM(E14+SUM(E17:E19)) -> 15860 | F20: =+SUM(F14+SUM(F17:F19)) -> 7788 | G20: =+SUM(G14+SUM(G17:G19)) -> 10071 | I20: =+SUM(I14+SUM(I17:I19)) -> 3864 | J20: =+SUM(J14+SUM(J17:J19)) -> 3858 | K20: =+SUM(K14+SUM(K17:K19)) -> 4472 | L20: =+SUM(L14+SUM(L17:L19)) -> 3666 | M20: =+SUM(M14+SUM(M17:M19)) -> 2465 | N20: =+SUM(N14+SUM(N17:N19)) -> 2090 | O20: =+SUM(O14+SUM(O17:O19)) -> 1823 | P20: =+SUM(P14+SUM(P17:P19)) -> 1410 | ... W20: =+SUM(W14+SUM(W17:W19)) -> 0 | Y20: =+SUM(Y14+SUM(Y17:Y19)) -> 3864 | Z20: =+SUM(Z14+SUM(Z17:Z19)) -> 7722 | AA20: =+SUM(AA14+SUM(AA17:AA19)) -> 12194 | AB20: =+SUM(AB14+SUM(AB17:AB19)) -> 15860 | AC20: =+SUM(AC14+SUM(AC17:AC19)) -> 14461 | AD20: =+SUM(AD14+SUM(AD17:AD19)) -> 12693 | AE20: =+SUM(AE14+SUM(AE17:AE19)) -> 10044 | AF20: =+SUM(AF14+SUM(AF17:AF19)) -> 7788 | ... AM20: =+SUM(AM14+SUM(AM17:AM19)) -> 2582 | AO20: =SUM(AM20/AI20)-1 -> -0.70985504
B21: Operating Margin (%) | C21: =C20/C11 -> 0.26581956 | D21: =D20/D11 -> 0.29163439 | E21: =E20/E11 -> 0.35882353 | F21: =F20/F11 -> 0.21742044 | G21: =G20/G11 -> 0.25848262 | I21: =I20/I11 -> 0.36095283 | J21: =J20/J11 -> 0.34557506 | K21: =K20/K11 -> 0.40892465 | L21: =L20/L11 -> 0.32172005 | M21: =M20/M11 -> 0.26048822 | N21: =N20/N11 -> 0.22533693 | O21: =O20/O11 -> 0.21571412 | P21: =P20/P11 -> 0.16336462 | ... W21: =W20/W11 -> #DIV/0! | Y21: =Y20/Y11 -> 0.36095283 | Z21: =Z20/Z11 -> 0.35310257 | AA21: =AA20/AA11 -> 0.37171163 | AB21: =AB20/AB11 -> 0.35882353 | AC21: =AC20/AC11 -> 0.33663113 | AD21: =AD20/AD11 -> 0.30906523 | AE21: =AE20/AE11 -> 0.26031516 | AF21: =AF20/AF11 -> 0.21742044 | ... AM21: =AM20/AM11 -> 0.25202538 | AO21: =SUM(AM21-AI21)*1000 -> 13.752914
B23: Interest expense | C23: -602 | D23: -559 | E23: -490 | F23: -694 | G23: -697 | I23: -139 | J23: -137 | K23: -70 | L23: =SUM(E23-SUM(I23:K23)) -> -144 | M23: -170 | N23: -179 | O23: -172 | P23: =SUM(F23-SUM(M23:O23)) -> -173 | Q23: -178 | R23: -172 | S23: -168 | T23: =SUM(G23-SUM(Q23:S23)) -> -179 | Y23: =SUM(I23:I23) -> -139 | Z23: =SUM(I23:J23) -> -276 | AA23: =SUM(I23:K23) -> -346 | AB23: =SUM(I23:L23) -> -490 | AC23: =SUM(J23:M23) -> -521 | AD23: =SUM(K23:N23) -> -563 | AE23: =SUM(L23:O23) -> -665 | AF23: =SUM(M23:P23) -> -694 | AG23: =SUM(N23:Q23) -> -702 | AH23: =SUM(O23:R23) -> -695 | AI23: =SUM(P23:S23) -> -691 | ... AM23: =SUM(T23:W23) -> -179 | AO23: =SUM(AM23/AI23)-1 -> -0.74095514
B24: Interest and dividend income | C24: 156 | D24: 83 | E24: 91 | F24: 313 | G24: 675 | I24: 17 | J24: 20 | K24: 22 | L24: =SUM(E24-SUM(I24:K24)) -> 32 | M24: 55 | N24: 59 | O24: 79 | P24: =SUM(F24-SUM(M24:O24)) -> 120 | Q24: 149 | R24: 160 | S24: 182 | T24: =SUM(G24-SUM(Q24:S24)) -> 184 | Y24: =SUM(I24:I24) -> 17 | Z24: =SUM(I24:J24) -> 37 | AA24: =SUM(I24:K24) -> 59 | AB24: =SUM(I24:L24) -> 91 | AC24: =SUM(J24:M24) -> 129 | AD24: =SUM(K24:N24) -> 168 | AE24: =SUM(L24:O24) -> 225 | AF24: =SUM(M24:P24) -> 313 | AG24: =SUM(N24:Q24) -> 407 | AH24: =SUM(O24:R24) -> 508 | AI24: =SUM(P24:S24) -> 611 | ... AM24: =SUM(T24:W24) -> 184 | AO24: =SUM(AM24/AI24)-1 -> -0.69885434
B25: Investment and other income (expense), net | C25: -90 | D25: 961 | E25: -463 | F25: 36 | G25: 287 | I25: 123 | J25: -318 | K25: -185 | L25: =SUM(E25-SUM(I25:K25)) -> -83 | M25: 21 | N25: -75 | O25: 27 | P25: =SUM(F25-SUM(M25:O25)) -> 63 | Q25: 63 | R25: 170 | S25: 44 | T25: =SUM(G25-SUM(Q25:S25)) -> 10 | Y25: =SUM(I25:I25) -> 123 | Z25: =SUM(I25:J25) -> -195 | AA25: =SUM(I25:K25) -> -380 | AB25: =SUM(I25:L25) -> -463 | AC25: =SUM(J25:M25) -> -565 | AD25: =SUM(K25:N25) -> -322 | AE25: =SUM(L25:O25) -> -110 | AF25: =SUM(M25:P25) -> 36 | AG25: =SUM(N25:Q25) -> 78 | AH25: =SUM(O25:R25) -> 323 | AI25: =SUM(P25:S25) -> 340 | ... AM25: =SUM(T25:W25) -> 10 | AO25: =SUM(AM25/AI25)-1 -> -0.97058824
B26: Earning Before Taxes | C26: =SUM(C20+SUM(C23:C25)) -> 5719 | D26: =SUM(D20+SUM(D23:D25)) -> 10274 | E26: =SUM(E20+SUM(E23:E25)) -> 14998 | F26: =SUM(F20+SUM(F23:F25)) -> 7443 | G26: =SUM(G20+SUM(G23:G25)) -> 10336 | I26: =SUM(I20+SUM(I23:I25)) -> 3865 | J26: =SUM(J20+SUM(J23:J25)) -> 3423 | K26: =SUM(K20+SUM(K23:K25)) -> 4239 | L26: =SUM(L20+SUM(L23:L25)) -> 3471 | M26: =SUM(M20+SUM(M23:M25)) -> 2371 | N26: =SUM(N20+SUM(N23:N25)) -> 1895 | O26: =SUM(O20+SUM(O23:O25)) -> 1757 | P26: =SUM(P20+SUM(P23:P25)) -> 1420 | ... W26: =SUM(W20+SUM(W23:W25)) -> 0 | Y26: =SUM(Y20+SUM(Y23:Y25)) -> 3865 | Z26: =SUM(Z20+SUM(Z23:Z25)) -> 7288 | AA26: =SUM(AA20+SUM(AA23:AA25)) -> 11527 | AB26: =SUM(AB20+SUM(AB23:AB25)) -> 14998 | AC26: =SUM(AC20+SUM(AC23:AC25)) -> 13504 | AD26: =SUM(AD20+SUM(AD23:AD25)) -> 11976 | AE26: =SUM(AE20+SUM(AE23:AE25)) -> 9494 | AF26: =SUM(AF20+SUM(AF23:AF25)) -> 7443 | ... AM26: =SUM(AM20+SUM(AM23:AM25)) -> 2597 | AO26: =SUM(AM26/AI26)-1 -> -0.71645376
B27: EBT Margin (%) | C27: =C26/C11 -> 0.24304109 | D27: =D26/D11 -> 0.30608354 | E27: =E26/E11 -> 0.33932127 | F27: =F26/F11 -> 0.20778894 | G27: =G26/G11 -> 0.26528412 | I27: =I26/I11 -> 0.36104624 | J27: =J26/J11 -> 0.30661053 | K27: =K26/K11 -> 0.38761887 | L27: =L26/L11 -> 0.30460728 | M27: =M26/M11 -> 0.25055479 | N27: =N26/N11 -> 0.20431267 | O27: =O26/O11 -> 0.20790439 | P27: =P26/P11 -> 0.16452323 | ... W27: =W26/W11 -> #DIV/0! | Y27: =Y26/Y11 -> 0.36104624 | Z27: =Z26/Z11 -> 0.33325712 | AA27: =AA26/AA11 -> 0.35137936 | AB27: =AB26/AB11 -> 0.33932127 | AC27: =AC26/AC11 -> 0.31435355 | AD27: =AD26/AD11 -> 0.29160681 | AE27: =AE26/AE11 -> 0.24606054 | AF27: =AF26/AF11 -> 0.20778894 | ... AM27: =AM26/AM11 -> 0.25348951 | AO27: =SUM(AM27-AI27)*1000 -> 8.2554919
B29: Provision for taxes | C29: -521 | D29: -1231 | E29: -2012 | F29: -104 | G29: -226 | I29: -466 | J29: -489 | K29: -509 | L29: =SUM(E29-SUM(I29:K29)) -> -548 | M29: -98 | N29: -193 | O29: -22 | P29: =SUM(F29-SUM(M29:O29)) -> 209 | Q29: -151 | R29: -223 | S29: -171 | T29: =SUM(G29-SUM(Q29:S29)) -> 319 | Y29: =SUM(I29:I29) -> -466 | Z29: =SUM(I29:J29) -> -955 | AA29: =SUM(I29:K29) -> -1464 | AB29: =SUM(I29:L29) -> -2012 | AC29: =SUM(J29:M29) -> -1644 | AD29: =SUM(K29:N29) -> -1348 | AE29: =SUM(L29:O29) -> -861 | AF29: =SUM(M29:P29) -> -104 | AG29: =SUM(N29:Q29) -> -157 | AH29: =SUM(O29:R29) -> -187 | AI29: =SUM(P29:S29) -> -336 | ... AM29: =SUM(T29:W29) -> 319 | AO29: =SUM(AM29/AI29)-1 -> -1.9494048
B30: Income from continuing operations | C30: =SUM(C26+SUM(C29:C29)) -> 5198 | D30: =SUM(D26+SUM(D29:D29)) -> 9043 | E30: =SUM(E26+SUM(E29:E29)) -> 12986 | F30: =SUM(F26+SUM(F29:F29)) -> 7339 | G30: =SUM(G26+SUM(G29:G29)) -> 10110 | I30: =SUM(I26+SUM(I29:I29)) -> 3399 | J30: =SUM(J26+SUM(J29:J29)) -> 2934 | K30: =SUM(K26+SUM(K29:K29)) -> 3730 | L30: =SUM(L26+SUM(L29:L29)) -> 2923 | M30: =SUM(M26+SUM(M29:M29)) -> 2273 | N30: =SUM(N26+SUM(N29:N29)) -> 1702 | O30: =SUM(O26+SUM(O29:O29)) -> 1735 | P30: =SUM(P26+SUM(P29:P29)) -> 1629 | ... W30: =SUM(W26+SUM(W29:W29)) -> 0 | Y30: =SUM(Y26+SUM(Y29:Y29)) -> 3399 | Z30: =SUM(Z26+SUM(Z29:Z29)) -> 6333 | AA30: =SUM(AA26+SUM(AA29:AA29)) -> 10063 | AB30: =SUM(AB26+SUM(AB29:AB29)) -> 12986 | AC30: =SUM(AC26+SUM(AC29:AC29)) -> 11860 | AD30: =SUM(AD26+SUM(AD29:AD29)) -> 10628 | AE30: =SUM(AE26+SUM(AE29:AE29)) -> 8633 | AF30: =SUM(AF26+SUM(AF29:AF29)) -> 7339 | ... AM30: =SUM(AM26+SUM(AM29:AM29)) -> 2916 | AO30: =SUM(AM30/AI30)-1 -> -0.66950017
B31: Net Margin (%) | C31: =C30/C11 -> 0.22090009 | D31: =D30/D11 -> 0.26940952 | E31: =E30/E11 -> 0.2938009 | F31: =F30/F11 -> 0.20488554 | G31: =G30/G11 -> 0.2594836 | I31: =I30/I11 -> 0.31751518 | J31: =J30/J11 -> 0.26280903 | K31: =K30/K11 -> 0.34107535 | L31: =L30/L11 -> 0.25651602 | M31: =M30/M11 -> 0.24019867 | N31: =N30/N11 -> 0.18350404 | O31: =O30/O11 -> 0.20530115 | P31: =P30/P11 -> 0.18873827 | ... W31: =W30/W11 -> #DIV/0! | Y31: =Y30/Y11 -> 0.31751518 | Z31: =Z30/Z11 -> 0.289588 | AA31: =AA30/AA11 -> 0.30675202 | AB31: =AB30/AB11 -> 0.2938009 | AC31: =AC30/AC11 -> 0.27608362 | AD31: =AD30/AD11 -> 0.258784 | AE31: =AE30/AE11 -> 0.22374559 | AF31: =AF30/AF11 -> 0.20488554 | ... AM31: =AM30/AM11 -> 0.28462665 | AO31: =SUM(AM31-AI31)*1000 -> 48.389098
B33: Discontinued operations, net of income taxes | C33: 0 | D33: 0 | E33: -50 | F33: -107 | G33: 32 | I33: 0 | J33: 0 | K33: 0 | L33: =SUM(E33-SUM(I33:K33)) -> -50 | M33: -38 | N33: 2 | O33: 68 | P33: =SUM(F33-SUM(M33:O33)) -> -139 | Q33: -44 | R33: 51 | S33: 21 | T33: =SUM(G33-SUM(Q33:S33)) -> 4
B34: Net Income | C34: =SUM(C30+SUM(C33:C33)) -> 5198 | D34: =SUM(D30+SUM(D33:D33)) -> 9043 | E34: =SUM(E30+SUM(E33:E33)) -> 12936 | F34: =SUM(F30+SUM(F33:F33)) -> 7232 | G34: =SUM(G30+SUM(G33:G33)) -> 10142 | I34: =SUM(I30+SUM(I33:I33)) -> 3399 | J34: =SUM(J30+SUM(J33:J33)) -> 2934 | K34: =SUM(K30+SUM(K33:K33)) -> 3730 | L34: =SUM(L30+SUM(L33:L33)) -> 2873 | M34: =SUM(M30+SUM(M33:M33)) -> 2235 | N34: =SUM(N30+SUM(N33:N33)) -> 1704 | O34: =SUM(O30+SUM(O33:O33)) -> 1803 | P34: =SUM(P30+SUM(P33:P33)) -> 1490 | ... W34: =SUM(W30+SUM(W33:W33)) -> 0 | Y34: =SUM(Y29+SUM(Y33:Y33)) -> -466 | Z34: =SUM(Z29+SUM(Z33:Z33)) -> -955 | AA34: =SUM(AA29+SUM(AA33:AA33)) -> -1464 | AB34: =SUM(AB29+SUM(AB33:AB33)) -> -2012 | AC34: =SUM(AC29+SUM(AC33:AC33)) -> -1644 | AD34: =SUM(AD29+SUM(AD33:AD33)) -> -1348 | AE34: =SUM(AE29+SUM(AE33:AE33)) -> -861 | AF34: =SUM(AF29+SUM(AF33:AF33)) -> -104 | ... AM34: =SUM(AM29+SUM(AM33:AM33)) -> 319 | AO34: =SUM(AM34/AI34)-1 -> -1.9494048
B35: Net Margin (%) | C35: =C34/C11 -> 0.22090009 | D35: =D34/D11 -> 0.26940952 | E35: =E34/E11 -> 0.29266968 | F35: =F34/F11 -> 0.20189838 | G35: =G34/G11 -> 0.26030491 | I35: =I34/I11 -> 0.31751518 | J35: =J34/J11 -> 0.26280903 | K35: =K34/K11 -> 0.34107535 | L35: =L34/L11 -> 0.25212813 | M35: =M34/M11 -> 0.23618303 | N35: =N34/N11 -> 0.18371968 | O35: =O34/O11 -> 0.21334753 | P35: =P34/P11 -> 0.17263353 | ... W35: =W34/W11 -> #DIV/0! | Y35: =Y34/Y14 -> -0.072789753 | Z35: =Z34/Z14 -> -0.073927853 | AA35: =AA34/AA14 -> -0.076898834 | AB35: =AB34/AB14 -> -0.07870135 | AC35: =AC34/AC14 -> -0.066878204 | AD35: =AD34/AD14 -> -0.058133517 | AE35: =AE34/AE14 -> -0.039628112 | AF35: =AF34/AF14 -> -0.0052127713 | ... AM35: =AM34/AM14 -> 0.055218972 | AO35: =SUM(AM35-AI35)*1000 -> 71.314009
B37: Basic Shares | L37: =E37 -> 0 | P37: =F37 -> 0 | T37: =G37 -> 0 | Y37: =I37 -> 0 | Z37: =J37 -> 0 | AA37: =K37 -> 0 | AB37: =L37 -> 0 | AC37: =M37 -> 0 | AD37: =N37 -> 0 | AE37: =O37 -> 0 | AF37: =P37 -> 0 | ... AM37: =W37 -> 0 | AO37: =SUM(AM37/AI37)-1 -> #DIV/0!
B38: Basic EPS | C38: =C30/C37 -> #DIV/0! | D38: =D30/D37 -> #DIV/0! | E38: =E30/E37 -> #DIV/0! | F38: =F30/F37 -> #DIV/0! | G38: =G30/G37 -> #DIV/0! | I38: =I30/I37 -> #DIV/0! | J38: =J30/J37 -> #DIV/0! | K38: =K30/K37 -> #DIV/0! | L38: =L30/L37 -> #DIV/0! | M38: =M30/M37 -> #DIV/0! | N38: =N30/N37 -> #DIV/0! | O38: =O30/O37 -> #DIV/0! | P38: =P30/P37 -> #DIV/0! | ... W38: =W30/W37 -> #DIV/0! | Y38: =Y30/Y37 -> #DIV/0! | Z38: =Z30/Z37 -> #DIV/0! | AA38: =AA30/AA37 -> #DIV/0! | AB38: =AB30/AB37 -> #DIV/0! | AC38: =AC30/AC37 -> #DIV/0! | AD38: =AD30/AD37 -> #DIV/0! | AE38: =AE30/AE37 -> #DIV/0! | AF38: =AF30/AF37 -> #DIV/0! | ... AM38: =AM30/AM37 -> #DIV/0! | AO38: =SUM(AM38/AI38)-1 -> #DIV/0!
B40: Fully Diluted Shares | C40: 1149 | D40: 1149 | E40: 1137 | F40: 1126 | G40: 1130 | I40: 1142 | J40: 1140 | K40: 1134 | L40: =E40 -> 1137 | M40: 1131 | N40: 1123 | O40: 1124 | P40: =F40 -> 1126 | Q40: 1127 | R40: 1130 | S40: 1134 | T40: =G40 -> 1130 | Y40: =I40 -> 1142 | Z40: =J40 -> 1140 | AA40: =K40 -> 1134 | AB40: =L40 -> 1137 | AC40: =M40 -> 1131 | AD40: =N40 -> 1123 | AE40: =O40 -> 1124 | AF40: =P40 -> 1126 | ... AM40: =W40 -> 0 | AO40: =SUM(AM40/AI40)-1 -> -1
B41: Fully Diluted EPS | C41: =C34/C40 -> 4.5239339 | D41: =D34/D40 -> 7.870322 | E41: =E34/E40 -> 11.377309 | F41: =F34/F40 -> 6.4227353 | G41: =G34/G40 -> 8.9752212 | I41: =I30/I40 -> 2.9763573 | J41: =J30/J40 -> 2.5736842 | K41: =K30/K40 -> 3.2892416 | L41: =L30/L40 -> 2.5708004 | M41: =M30/M40 -> 2.0097259 | N41: =N30/N40 -> 1.5155833 | O41: =O30/O40 -> 1.5435943 | P41: =P30/P40 -> 1.446714 | ... W41: =W30/W40 -> #DIV/0! | Y41: =Y30/Y40 -> 2.9763573 | Z41: =Z30/Z40 -> 5.5552632 | AA41: =AA30/AA40 -> 8.8738977 | AB41: =AB30/AB40 -> 11.421284 | AC41: =AC30/AC40 -> 10.486295 | AD41: =AD30/AD40 -> 9.4639359 | AE41: =AE30/AE40 -> 7.680605 | AF41: =AF30/AF40 -> 6.517762 | ... AM41: =AM30/AM40 -> #DIV/0! | AO41: =SUM(AM41/AI41)-1 -> #DIV/0!
A43: X | B43: Balance Sheet | AH43: LTM | AO43: Variance
B44: =B7 -> Fiscal Period | C44: =C7 -> 2020 | D44: =D7 -> 2021 | E44: =E7 -> 2022 | F44: =F7 -> 2023 | G44: =G7 -> 2024 | I44: =I7 -> 1Q22 | J44: =J7 -> 2Q22 | K44: =K7 -> 3Q22 | L44: =L7 -> 4Q22 | M44: =M7 -> 1Q23 | N44: =N7 -> 2Q23 | O44: =O7 -> 3Q23 | P44: =P7 -> 4Q23 | ... W44: =W7 -> 3Q25 | Y44: =Y7 -> 1Q22 | Z44: =Z7 -> 2Q22 | AA44: =AA7 -> 3Q22 | AB44: =AB7 -> 4Q22 | AC44: =AC7 -> 1Q23 | AD44: =AD7 -> 2Q23 | AE44: =AE7 -> 3Q23 | AF44: =AF7 -> 4Q23 | ... AM44: =AM7 -> 3Q25
B45: =B8 -> Fiscal Period End Date | C45: =C8 -> 44196 | D45: =D8 -> 44561 | E45: =E8 -> 44926 | F45: =F8 -> 45291 | G45: =G8 -> 45657 | I45: =I8 -> 44651 | J45: =J8 -> 44742 | K45: =K8 -> 44834 | L45: =L8 -> 44926 | M45: =M8 -> 45016 | N45: =N8 -> 45107 | O45: =O8 -> 45199 | P45: =P8 -> 45291 | ... W45: =W8 -> 45930 | Y45: =Y8 -> 44651 | Z45: =Z8 -> 44742 | AA45: =AA8 -> 44834 | AB45: =AB8 -> 44926 | AC45: =AC8 -> 45016 | AD45: =AD8 -> 45107 | AE45: =AE8 -> 45199 | AF45: =AF8 -> 45291 | ... AM45: =AM8 -> 45930
B47: Current Assets
B48: Cash and cash equivalents | C48: 6707 | D48: 7116 | E48: 2773 | F48: 8450 | G48: 7849 | I48: 6607 | J48: 7173 | K48: 2676 | L48: =E48 -> 2773 | M48: 4808 | N48: 3488 | O48: 6087 | P48: =F48 -> 8450 | Q48: 8133 | R48: 9219 | S48: 7770 | T48: =G48 -> 7849 | Y48: =I48 -> 6607 | Z48: =J48 -> 7173 | AA48: =K48 -> 2676 | AB48: =L48 -> 2773 | AC48: =M48 -> 4808 | AD48: =N48 -> 3488 | AE48: =O48 -> 6087 | AF48: =P48 -> 8450 | ... AM48: =W48 -> 0 | AO48: =SUM(AM48/AI48)-1 -> -1
B49: Marketable securities | C49: 4507 | D49: 5298 | E49: 3609 | F49: 2874 | G49: 5451 | I49: 4703 | J49: 4373 | K49: 4172 | L49: =E49 -> 3609 | M49: 3430 | N49: 3188 | O49: 2544 | P49: =F49 -> 2874 | Q49: 3921 | R49: 4632 | S49: 5262 | T49: =G49 -> 5451
B50: Accounts receivable, net | C50: 4003 | D50: 3579 | E50: 5643 | F50: 3183 | G50: 3929 | I50: 4032 | J50: 4084 | K50: 3804 | L50: =E50 -> 5643 | M50: 3960 | N50: 3691 | O50: 3850 | P50: =F50 -> 3183 | Q50: 3513 | R50: 3054 | S50: 2948 | T50: =G50 -> 3929
B51: Inventories | C51: 2598 | D51: 3228 | E51: 6341 | F51: 6422 | G51: 6423 | I51: 3861 | J51: 4555 | K51: 5418 | L51: =E51 -> 6341 | M51: 6932 | N51: 6858 | O51: 6628 | P51: =F51 -> 6422 | Q51: 6247 | R51: 6087 | S51: 6020 | T51: =G51 -> 6423
B52: Held for sale assets | C52: 0 | D52: 0 | E52: 733 | F52: 341 | G52: 0 | I52: 0 | J52: 0 | K52: 950 | L52: =E52 -> 733 | M52: 721 | N52: 816 | O52: 317 | P52: =F52 -> 341 | Q52: 337 | R52: 0 | S52: 0 | T52: =G52 -> 0
...

Sheet Revenue Drivers
B2: ='Historical Financials'!B2 -> Qualcomm (NASDAQ: QCOM) | E2: FYE | I2: Quarterly | Q2: Quarterly | R2: Quarterly | Y2: LTM | AC2: LTM | AE2: LTM | AK2: Variance
B3: Segment Anaysis | C3: ='Historical Financials'!C7 -> 2020 | D3: ='Historical Financials'!D7 -> 2021 | E3: ='Historical Financials'!E7 -> 2022 | F3: ='Historical Financials'!F7 -> 2023 | G3: ='Historical Financials'!G7 -> 2024 | I3: ='Historical Financials'!I7 -> 1Q22 | J3: ='Historical Financials'!J7 -> 2Q22 | K3: ='Historical Financials'!K7 -> 3Q22 | L3: ='Historical Financials'!L7 -> 4Q22 | M3: ='Historical Financials'!M7 -> 1Q23 | N3: ='Historical Financials'!N7 -> 2Q23 | O3: ='Historical Financials'!O7 -> 3Q23 | P3: ='Historical Financials'!P7 -> 4Q23 | ... W3: ='Historical Financials'!W7 -> 3Q25 | Y3: =M3 -> 1Q23 | Z3: =N3 -> 2Q23 | AA3: =O3 -> 3Q23 | AB3: =P3 -> 4Q23 | AC3: =Q3 -> 1Q24 | AD3: =R3 -> 2Q24 | AE3: =S3 -> 3Q24 | AF3: =T3 -> 4Q24 | ... AI3: =W3 -> 3Q25
B4: $ in thousands except per share | C4: ='Historical Financials'!C8 -> 44196 | D4: ='Historical Financials'!D8 -> 44561 | E4: ='Historical Financials'!E8 -> 44926 | F4: ='Historical Financials'!F8 -> 45291 | G4: ='Historical Financials'!G8 -> 45657 | I4: ='Historical Financials'!I8 -> 44651 | J4: ='Historical Financials'!J8 -> 44742 | K4: ='Historical Financials'!K8 -> 44834 | L4: ='Historical Financials'!L8 -> 44926 | M4: ='Historical Financials'!M8 -> 45016 | N4: ='Historical Financials'!N8 -> 45107 | O4: ='Historical Financials'!O8 -> 45199 | P4: ='Historical Financials'!P8 -> 45291 | ... W4: ='Historical Financials'!W8 -> 45930 | Y4: =M4 -> 45016 | Z4: =N4 -> 45107 | AA4: =O4 -> 45199 | AB4: =P4 -> 45291 | AC4: =Q4 -> 45382 | AD4: =R4 -> 45473 | AE4: =S4 -> 45565 | AF4: =T4 -> 45657 | ... AI4: =W4 -> 45930
A6: X | B6: Offerings Drivers
Y9: =SUM(J9:M9) -> 0 | Z9: =SUM(K9:N9) -> 0 | AA9: =SUM(L9:O9) -> 0 | AB9: =SUM(M9:P9) -> 0 | AC9: =SUM(N9:Q9) -> 0 | AD9: =SUM(O9:R9) -> 0 | AE9: =SUM(P9:S9) -> 0 | AF9: =SUM(Q9:T9) -> 0 | ... AI9: =SUM(T9:W9) -> 0 | AK9: =SUM(AI9/AE9)-1 -> #DIV/0!
AE10: =SUM(P10:S10) -> 0 | AF10: =SUM(Q10:T10) -> 0 | AG10: =SUM(R10:U10) -> 0 | AH10: =SUM(S10:V10) -> 0 | AI10: =SUM(T10:W10) -> 0 | AK10: =SUM(AI10/AE10)-1 -> #DIV/0!
B11: Total Net Revenue | C11: =SUM(C9:C10) -> 0 | D11: =SUM(D9:D10) -> 0 | E11: =SUM(E9:E10) -> 0 | F11: =SUM(F9:F10) -> 0 | G11: =SUM(G9:G10) -> 0 | I11: =SUM(I9:I10) -> 0 | J11: =SUM(J9:J10) -> 0 | K11: =SUM(K9:K10) -> 0 | L11: =SUM(L9:L10) -> 0 | M11: =SUM(M9:M10) -> 0 | N11: =SUM(N9:N10) -> 0 | O11: =SUM(O9:O10) -> 0 | P11: =SUM(P9:P10) -> 0 | ... W11: =SUM(W9:W10) -> 0 | Y11: =SUM(Y9:Y10) -> 0 | Z11: =SUM(Z9:Z10) -> 0 | AA11: =SUM(AA9:AA10) -> 0 | AB11: =SUM(AB9:AB10) -> 0 | AC11: =SUM(AC9:AC10) -> 0 | AD11: =SUM(AD9:AD10) -> 0 | AE11: =SUM(AE9:AE10) -> 0 | AF11: =SUM(AF9:AF10) -> 0 | ... AI11: =SUM(AI9:AI10) -> 0 | AK11: =SUM(AI11/AE11)-1 -> #DIV/0!
B12: Variance Check | C12: =+C11-'Historical Financials'!C11 -> -23531 | D12: =+D11-'Historical Financials'!D11 -> -33566 | E12: =+E11-'Historical Financials'!E11 -> -44200 | F12: =+F11-'Historical Financials'!F11 -> -35820 | G12: =+G11-'Historical Financials'!G11 -> -38962 | I12: =I11-'Historical Financials'!I11 -> -10705 | J12: =J11-'Historical Financials'!J11 -> -11164 | K12: =K11-'Historical Financials'!K11 -> -10936 | L12: =L11-'Historical Financials'!L11 -> -11395 | M12: =M11-'Historical Financials'!M11 -> -9463 | N12: =N11-'Historical Financials'!N11 -> -9275 | O12: =O11-'Historical Financials'!O11 -> -8451 | P12: =P11-'Historical Financials'!P11 -> -8631 | ... W12: =W11-'Historical Financials'!W11 -> 0 | Y12: =+Y11-'Historical Financials'!AC11 -> -42958 | Z12: =+Z11-'Historical Financials'!AD11 -> -41069 | AA12: =+AA11-'Historical Financials'!AE11 -> -38584 | AB12: =+AB11-'Historical Financials'!AF11 -> -35820 | AC12: =+AC11-'Historical Financials'!AG11 -> -36292 | AD12: =+AD11-'Historical Financials'!AH11 -> -36406 | AE12: =+AE11-'Historical Financials'!AI11 -> -37348 | AF12: =+AF11-'Historical Financials'!AJ11 -> -38962 | ... AH12: =+AH11-'Historical Financials'!AL11 -> -19638 | AI12: =AI11-'Historical Financials'!AM11 -> -10245

Sheet FCF
B2: ='Historical Financials'!B2 -> Qualcomm (NASDAQ: QCOM) | C2: FYE | E2: FYE | I2: Quarterly | M2: Quarterly | S2: Quarterly | Y2: LTM | AF2: LTM | AG2: LTM | AM2: Variance
B3: FCF Analysis | C3: ='Historical Financials'!C7 -> 2020 | D3: ='Historical Financials'!D7 -> 2021 | E3: ='Historical Financials'!E7 -> 2022 | F3: ='Historical Financials'!F7 -> 2023 | G3: ='Historical Financials'!G7 -> 2024 | I3: ='Historical Financials'!I7 -> 1Q22 | J3: ='Historical Financials'!J7 -> 2Q22 | K3: ='Historical Financials'!K7 -> 3Q22 | L3: ='Historical Financials'!L7 -> 4Q22 | M3: ='Historical Financials'!M7 -> 1Q23 | N3: ='Historical Financials'!N7 -> 2Q23 | O3: ='Historical Financials'!O7 -> 3Q23 | P3: ='Historical Financials'!P7 -> 4Q23 | ... W3: ='Historical Financials'!W7 -> 3Q25 | Y3: =K3 -> 3Q22 | Z3: =L3 -> 4Q22 | AA3: =M3 -> 1Q23 | AB3: =N3 -> 2Q23 | AC3: =O3 -> 3Q23 | AD3: =P3 -> 4Q23 | AE3: =Q3 -> 1Q24 | AF3: =R3 -> 2Q24 | ... AK3: =W3 -> 3Q25
B4: $ mm except per share | C4: ='Historical Financials'!C8 -> 44196 | D4: ='Historical Financials'!D8 -> 44561 | E4: ='Historical Financials'!E8 -> 44926 | F4: ='Historical Financials'!F8 -> 45291 | G4: ='Historical Financials'!G8 -> 45657 | I4: ='Historical Financials'!I8 -> 44651 | J4: ='Historical Financials'!J8 -> 44742 | K4: ='Historical Financials'!K8 -> 44834 | L4: ='Historical Financials'!L8 -> 44926 | M4: ='Historical Financials'!M8 -> 45016 | N4: ='Historical Financials'!N8 -> 45107 | O4: ='Historical Financials'!O8 -> 45199 | P4: ='Historical Financials'!P8 -> 45291 | ... W4: ='Historical Financials'!W8 -> 45930 | Y4: =K4 -> 44834 | Z4: =L4 -> 44926 | AA4: =M4 -> 45016 | AB4: =N4 -> 45107 | AC4: =O4 -> 45199 | AD4: =P4 -> 45291 | AE4: =Q4 -> 45382 | AF4: =R4 -> 45473 | ... AK4: =W4 -> 45930
B6: ='Revenue Drivers'!B9 -> 0 | C6: =('Revenue Drivers'!C9)/1000 -> 0 | D6: =('Revenue Drivers'!D9)/1000 -> 0 | E6: =('Revenue Drivers'!E9)/1000 -> 0 | F6: =('Revenue Drivers'!F9)/1000 -> 0 | G6: =('Revenue Drivers'!G9)/1000 -> 0 | I6: =('Revenue Drivers'!I9)/1000 -> 0 | J6: =('Revenue Drivers'!J9)/1000 -> 0 | K6: =('Revenue Drivers'!K9)/1000 -> 0 | L6: =('Revenue Drivers'!L9)/1000 -> 0 | M6: =('Revenue Drivers'!M9)/1000 -> 0 | N6: =('Revenue Drivers'!N9)/1000 -> 0 | O6: =('Revenue Drivers'!O9)/1000 -> 0 | P6: =('Revenue Drivers'!P9)/1000 -> 0 | ... W6: =('Revenue Drivers'!W9)/1000 -> 0 | Y6: =SUM(H6:K6) -> 0 | Z6: =SUM(I6:L6) -> 0 | AA6: =SUM(J6:M6) -> 0 | AB6: =SUM(K6:N6) -> 0 | AC6: =SUM(L6:O6) -> 0 | AD6: =SUM(M6:P6) -> 0 | AE6: =SUM(N6:Q6) -> 0 | AF6: =SUM(O6:R6) -> 0 | ... AK6: =SUM(T6:W6) -> 0 | AM6: =SUM(AK6/AG6)-1 -> #DIV/0!
B7: ='Revenue Drivers'!B10 -> 0 | C7: =('Revenue Drivers'!C10)/1000 -> 0 | D7: =('Revenue Drivers'!D10)/1000 -> 0 | E7: =('Revenue Drivers'!E10)/1000 -> 0 | F7: =('Revenue Drivers'!F10)/1000 -> 0 | G7: =('Revenue Drivers'!G10)/1000 -> 0 | I7: =('Revenue Drivers'!I10)/1000 -> 0 | J7: =('Revenue Drivers'!J10)/1000 -> 0 | K7: =('Revenue Drivers'!K10)/1000 -> 0 | L7: =('Revenue Drivers'!L10)/1000 -> 0 | M7: =('Revenue Drivers'!M10)/1000 -> 0 | N7: =('Revenue Drivers'!N10)/1000 -> 0 | O7: =('Revenue Drivers'!O10)/1000 -> 0 | P7: =('Revenue Drivers'!P10)/1000 -> 0 | ... W7: =('Revenue Drivers'!W10)/1000 -> 0 | AG7: =SUM(P7:S7) -> 0 | AH7: =SUM(Q7:T7) -> 0 | AI7: =SUM(R7:U7) -> 0 | AJ7: =SUM(S7:V7) -> 0 | AK7: =SUM(T7:W7) -> 0 | AM7: =SUM(AK7/AG7)-1 -> #DIV/0!
B8: ='Revenue Drivers'!#REF! -> #REF! | C8: =('Revenue Drivers'!#REF!)/1000 -> #REF! | D8: =('Revenue Drivers'!#REF!)/1000 -> #REF! | E8: =('Revenue Drivers'!#REF!)/1000 -> #REF! | F8: =('Revenue Drivers'!#REF!)/1000 -> #REF! | G8: =('Revenue Drivers'!#REF!)/1000 -> #REF! | I8: =('Revenue Drivers'!#REF!)/1000 -> #REF! | J8: =('Revenue Drivers'!#REF!)/1000 -> #REF! | K8: =('Revenue Drivers'!#REF!)/1000 -> #REF! | L8: =('Revenue Drivers'!#REF!)/1000 -> #REF! | M8: =('Revenue Drivers'!#REF!)/1000 -> #REF! | N8: =('Revenue Drivers'!#REF!)/1000 -> #REF! | O8: =('Revenue Drivers'!#REF!)/1000 -> #REF! | P8: =('Revenue Drivers'!#REF!)/1000 -> #REF! | ... W8: =('Revenue Drivers'!#REF!)/1000 -> #REF! | AG8: =SUM(P8:S8) -> #REF! | AH8: =SUM(Q8:T8) -> #REF! | AI8: =SUM(R8:U8) -> #REF! | AJ8: =SUM(S8:V8) -> #REF! | AK8: =SUM(T8:W8) -> #REF! | AM8: =SUM(AK8/AG8)-1 -> #REF!
B9: ='Revenue Drivers'!#REF! -> #REF! | C9: =('Revenue Drivers'!#REF!)/1000 -> #REF! | D9: =('Revenue Drivers'!#REF!)/1000 -> #REF! | E9: =('Revenue Drivers'!#REF!)/1000 -> #REF! | F9: =('Revenue Drivers'!#REF!)/1000 -> #REF! | G9: =('Revenue Drivers'!#REF!)/1000 -> #REF! | I9: =('Revenue Drivers'!#REF!)/1000 -> #REF! | J9: =('Revenue Drivers'!#REF!)/1000 -> #REF! | K9: =('Revenue Drivers'!#REF!)/1000 -> #REF! | L9: =('Revenue Drivers'!#REF!)/1000 -> #REF! | M9: =('Revenue Drivers'!#REF!)/1000 -> #REF! | N9: =('Revenue Drivers'!#REF!)/1000 -> #REF! | O9: =('Revenue Drivers'!#REF!)/1000 -> #REF! | P9: =('Revenue Drivers'!#REF!)/1000 -> #REF! | ... W9: =('Revenue Drivers'!#REF!)/1000 -> #REF! | AG9: =SUM(P9:S9) -> #REF! | AH9: =SUM(Q9:T9) -> #REF! | AI9: =SUM(R9:U9) -> #REF! | AJ9: =SUM(S9:V9) -> #REF! | AK9: =SUM(T9:W9) -> #REF! | AM9: =SUM(AK9/AG9)-1 -> #REF!
B10: ='Revenue Drivers'!#REF! -> #REF! | C10: =('Revenue Drivers'!#REF!)/1000 -> #REF! | D10: =('Revenue Drivers'!#REF!)/1000 -> #REF! | E10: =('Revenue Drivers'!#REF!)/1000 -> #REF! | F10: =('Revenue Drivers'!#REF!)/1000 -> #REF! | G10: =('Revenue Drivers'!#REF!)/1000 -> #REF! | I10: =('Revenue Drivers'!#REF!)/1000 -> #REF! | J10: =('Revenue Drivers'!#REF!)/1000 -> #REF! | K10: =('Revenue Drivers'!#REF!)/1000 -> #REF! | L10: =('Revenue Drivers'!#REF!)/1000 -> #REF! | M10: =('Revenue Drivers'!#REF!)/1000 -> #REF! | N10: =('Revenue Drivers'!#REF!)/1000 -> #REF! | O10: =('Revenue Drivers'!#REF!)/1000 -> #REF! | P10: =('Revenue Drivers'!#REF!)/1000 -> #REF! | ... W10: =('Revenue Drivers'!#REF!)/1000 -> #REF! | AG10: =SUM(P10:S10) -> #REF! | AH10: =SUM(Q10:T10) -> #REF! | AI10: =SUM(R10:U10) -> #REF! | AJ10: =SUM(S10:V10) -> #REF! | AK10: =SUM(T10:W10) -> #REF! | AM10: =SUM(AK10/AG10)-1 -> #REF!
B11: Total Revenue | C11: =SUM(C6:C10) -> #REF! | D11: =SUM(D6:D10) -> #REF! | E11: =SUM(E6:E10) -> #REF! | F11: =SUM(F6:F10) -> #REF! | G11: =SUM(G6:G10) -> #REF! | I11: =SUM(I6:I10) -> #REF! | J11: =SUM(J6:J10) -> #REF! | K11: =SUM(K6:K10) -> #REF! | L11: =SUM(L6:L10) -> #REF! | M11: =SUM(M6:M10) -> #REF! | N11: =SUM(N6:N10) -> #REF! | O11: =SUM(O6:O10) -> #REF! | P11: =SUM(P6:P10) -> #REF! | ... W11: =SUM(W6:W10) -> #REF! | Y11: =SUM(Y6:Y10) -> 0 | Z11: =SUM(Z6:Z10) -> 0 | AA11: =SUM(AA6:AA10) -> 0 | AB11: =SUM(AB6:AB10) -> 0 | AC11: =SUM(AC6:AC10) -> 0 | AD11: =SUM(AD6:AD10) -> 0 | AE11: =SUM(AE6:AE10) -> 0 | AF11: =SUM(AF6:AF10) -> 0 | ... AK11: =SUM(AK6:AK10) -> #REF! | AM11: =SUM(AK11/AG11)-1 -> #REF!
B12: Y/Y Growth (%) | D12: =SUM(D11/C11)-1 -> #REF! | E12: =SUM(E11/D11)-1 -> #REF! | F12: =SUM(F11/E11)-1 -> #REF! | G12: =SUM(G11/F11)-1 -> #REF! | M12: =SUM(M11/I11)-1 -> #REF! | N12: =SUM(N11/J11)-1 -> #REF! | O12: =SUM(O11/K11)-1 -> #REF! | P12: =SUM(P11/L11)-1 -> #REF! | Q12: =SUM(Q11/M11)-1 -> #REF! | R12: =SUM(R11/N11)-1 -> #REF! | S12: =SUM(S11/O11)-1 -> #REF! | T12: =SUM(T11/P11)-1 -> #REF! | ... W12: =SUM(W11/S11)-1 -> #REF! | AC12: =SUM(AC11/Y11)-1 -> #DIV/0! | AD12: =SUM(AD11/Z11)-1 -> #DIV/0! | AE12: =SUM(AE11/AA11)-1 -> #DIV/0! | AF12: =SUM(AF11/AB11)-1 -> #DIV/0! | AG12: =SUM(AG11/AC11)-1 -> #REF! | AH12: =SUM(AH11/AD11)-1 -> #REF! | AI12: =SUM(AI11/AE11)-1 -> #REF! | AJ12: =SUM(AJ11/AF11)-1 -> #REF! | AK12: =SUM(AK11/AG11)-1 -> #REF! | AM12: =SUM(AK12-AG12)*10000 -> #REF!
B13: Q/Q Growth (%) | C13: N/A | D13: N/A | E13: N/A | F13: N/A | G13: N/A | J13: =SUM(J11/I11)-1 -> #REF! | K13: =SUM(K11/J11)-1 -> #REF! | L13: =SUM(L11/K11)-1 -> #REF! | M13: =SUM(M11/L11)-1 -> #REF! | N13: =SUM(N11/M11)-1 -> #REF! | O13: =SUM(O11/N11)-1 -> #REF! | P13: =SUM(P11/O11)-1 -> #REF! | Q13: =SUM(Q11/P11)-1 -> #REF! | ... W13: =SUM(W11/V11)-1 -> #REF! | Y13: N/A | Z13: N/A | AA13: N/A | AB13: N/A | AC13: N/A | AD13: N/A | AE13: N/A | AF13: N/A | AG13: N/A | AH13: N/A | AI13: N/A | AJ13: N/A | AK13: N/A
B15: (-) Amortization of content assets | C15: =('Historical Financials'!C13)/1000 -> -9.255 | D15: =('Historical Financials'!D13)/1000 -> -14.262 | E15: =('Historical Financials'!E13)/1000 -> -18.635 | F15: =('Historical Financials'!F13)/1000 -> -15.869 | G15: =('Historical Financials'!G13)/1000 -> -17.06 | I15: =('Historical Financials'!I13)/1000 -> -4.303 | J15: =('Historical Financials'!J13)/1000 -> -4.648 | K15: =('Historical Financials'!K13)/1000 -> -4.816 | L15: =('Historical Financials'!L13)/1000 -> -4.868 | M15: =('Historical Financials'!M13)/1000 -> -4.044 | N15: =('Historical Financials'!N13)/1000 -> -4.153 | O15: =('Historical Financials'!O13)/1000 -> -3.792 | P15: =('Historical Financials'!P13)/1000 -> -3.88 | ... W15: =('Historical Financials'!W13)/1000 -> 0 | Y15: =SUM(H15:K15) -> -13.767 | Z15: =SUM(I15:L15) -> -18.635 | AA15: =SUM(J15:M15) -> -18.376 | AB15: =SUM(K15:N15) -> -17.881 | AC15: =SUM(L15:O15) -> -16.857 | AD15: =SUM(M15:P15) -> -15.869 | AE15: =SUM(N15:Q15) -> -16.137 | AF15: =SUM(O15:R15) -> -16.09 | ... AK15: =SUM(T15:W15) -> -4.468 | AM15: =SUM(AK15/AG15)-1 -> -0.72875182
B16: (-) Other Cost of Revenues | C16: =('Historical Financials'!#REF!)/1000 -> #REF! | D16: =('Historical Financials'!#REF!)/1000 -> #REF! | E16: =('Historical Financials'!#REF!)/1000 -> #REF! | F16: =('Historical Financials'!#REF!)/1000 -> #REF! | G16: =('Historical Financials'!#REF!)/1000 -> #REF! | I16: =('Historical Financials'!#REF!)/1000 -> #REF! | J16: =('Historical Financials'!#REF!)/1000 -> #REF! | K16: =('Historical Financials'!#REF!)/1000 -> #REF! | L16: =('Historical Financials'!#REF!)/1000 -> #REF! | M16: =('Historical Financials'!#REF!)/1000 -> #REF! | N16: =('Historical Financials'!#REF!)/1000 -> #REF! | O16: =('Historical Financials'!#REF!)/1000 -> #REF! | P16: =('Historical Financials'!#REF!)/1000 -> #REF! | ... W16: =('Historical Financials'!#REF!)/1000 -> #REF! | AG16: =SUM(P16:S16) -> #REF! | AH16: =SUM(Q16:T16) -> #REF! | AI16: =SUM(R16:U16) -> #REF! | AJ16: =SUM(S16:V16) -> #REF! | AK16: =SUM(T16:W16) -> #REF!
B17: Gross Profit | C17: =SUM(C11+SUM(C15:C16)) -> #REF! | D17: =SUM(D11+SUM(D15:D16)) -> #REF! | E17: =SUM(E11+SUM(E15:E16)) -> #REF! | F17: =SUM(F11+SUM(F15:F16)) -> #REF! | G17: =SUM(G11+SUM(G15:G16)) -> #REF! | I17: =SUM(I11+SUM(I15:I16)) -> #REF! | J17: =SUM(J11+SUM(J15:J16)) -> #REF! | K17: =SUM(K11+SUM(K15:K16)) -> #REF! | L17: =SUM(L11+SUM(L15:L16)) -> #REF! | M17: =SUM(M11+SUM(M15:M16)) -> #REF! | N17: =SUM(N11+SUM(N15:N16)) -> #REF! | O17: =SUM(O11+SUM(O15:O16)) -> #REF! | P17: =SUM(P11+SUM(P15:P16)) -> #REF! | ... W17: =SUM(W11+SUM(W15:W16)) -> #REF! | Y17: =SUM(Y11+SUM(Y15:Y16)) -> -13.767 | Z17: =SUM(Z11+SUM(Z15:Z16)) -> -18.635 | AA17: =SUM(AA11+SUM(AA15:AA16)) -> -18.376 | AB17: =SUM(AB11+SUM(AB15:AB16)) -> -17.881 | AC17: =SUM(AC11+SUM(AC15:AC16)) -> -16.857 | AD17: =SUM(AD11+SUM(AD15:AD16)) -> -15.869 | AE17: =SUM(AE11+SUM(AE15:AE16)) -> -16.137 | AF17: =SUM(AF11+SUM(AF15:AF16)) -> -16.09 | ... AK17: =SUM(AK11+SUM(AK15:AK16)) -> #REF! | AM17: =SUM(AK17/AG17)-1 -> #REF!
B18: Gross Margin (%) | C18: =C17/C11 -> #REF! | D18: =D17/D11 -> #REF! | E18: =E17/E11 -> #REF! | F18: =F17/F11 -> #REF! | G18: =G17/G11 -> #REF! | I18: =I17/I11 -> #REF! | J18: =J17/J11 -> #REF! | K18: =K17/K11 -> #REF! | L18: =L17/L11 -> #REF! | M18: =M17/M11 -> #REF! | N18: =N17/N11 -> #REF! | O18: =O17/O11 -> #REF! | P18: =P17/P11 -> #REF! | ... W18: =W17/W11 -> #REF! | Y18: =Y17/Y11 -> #DIV/0! | Z18: =Z17/Z11 -> #DIV/0! | AA18: =AA17/AA11 -> #DIV/0! | AB18: =AB17/AB11 -> #DIV/0! | AC18: =AC17/AC11 -> #DIV/0! | AD18: =AD17/AD11 -> #DIV/0! | AE18: =AE17/AE11 -> #DIV/0! | AF18: =AF17/AF11 -> #DIV/0! | ... AK18: =AK17/AK11 -> #REF! | AM18: =SUM(AK18-AG18)*10000 -> #REF!
B20: (-) Marketing | C20: =('Historical Financials'!C17)/1000 -> -5.975 | D20: =('Historical Financials'!D17)/1000 -> -7.176 | E20: =('Historical Financials'!E17)/1000 -> -8.194 | F20: =('Historical Financials'!F17)/1000 -> -8.818 | G20: =('Historical Financials'!G17)/1000 -> -8.893 | I20: =('Historical Financials'!I17)/1000 -> -1.93 | J20: =('Historical Financials'!J17)/1000 -> -2.034 | K20: =('Historical Financials'!K17)/1000 -> -2.052 | L20: =('Historical Financials'!L17)/1000 -> -2.178 | M20: =('Historical Financials'!M17)/1000 -> -2.251 | N20: =('Historical Financials'!N17)/1000 -> -2.21 | O20: =('Historical Financials'!O17)/1000 -> -2.222 | P20: =('Historical Financials'!P17)/1000 -> -2.135 | ... W20: =('Historical Financials'!W17)/1000 -> 0 | Y20: =SUM(H20:K20) -> -6.016 | Z20: =SUM(I20:L20) -> -8.194 | AA20: =SUM(J20:M20) -> -8.515 | AB20: =SUM(K20:N20) -> -8.691 | AC20: =SUM(L20:O20) -> -8.861 | AD20: =SUM(M20:P20) -> -8.818 | AE20: =SUM(N20:Q20) -> -8.663 | AF20: =SUM(O20:R20) -> -8.689 | ... AK20: =SUM(T20:W20) -> -2.302 | AM20: =SUM(AK20/AG20)-1 -> -0.73619069
B21: (-) Technology and Development (T&D) | C21: =('Historical Financials'!C18)/1000 -> -2.074 | D21: =('Historical Financials'!D18)/1000 -> -2.339 | E21: =('Historical Financials'!E18)/1000 -> -2.57 | F21: =('Historical Financials'!F18)/1000 -> -2.483 | G21: =('Historical Financials'!G18)/1000 -> -2.759 | I21: =('Historical Financials'!I18)/1000 -> -0.608 | J21: =('Historical Financials'!J18)/1000 -> -0.624 | K21: =('Historical Financials'!K18)/1000 -> -0.655 | L21: =('Historical Financials'!L18)/1000 -> -0.683 | M21: =('Historical Financials'!M18)/1000 -> -0.623 | N21: =('Historical Financials'!N18)/1000 -> -0.614 | O21: =('Historical Financials'!O18)/1000 -> -0.618 | P21: =('Historical Financials'!P18)/1000 -> -0.628 | ... W21: =('Historical Financials'!W18)/1000 -> 0 | Y21: =SUM(H21:K21) -> -1.887 | Z21: =SUM(I21:L21) -> -2.57 | AA21: =SUM(J21:M21) -> -2.585 | AB21: =SUM(K21:N21) -> -2.575 | AC21: =SUM(L21:O21) -> -2.538 | AD21: =SUM(M21:P21) -> -2.483 | AE21: =SUM(N21:Q21) -> -2.487 | AF21: =SUM(O21:R21) -> -2.58 | ... AK21: =SUM(T21:W21) -> -0.761 | AM21: =SUM(AK21/AG21)-1 -> -0.71020564
B22: (-) General and Administrative (G&A) | C22: =('Historical Financials'!C19)/1000 -> 0.028 | D22: =('Historical Financials'!D19)/1000 -> 0 | E22: =('Historical Financials'!E19)/1000 -> 1.059 | F22: =('Historical Financials'!F19)/1000 -> -0.862 | G22: =('Historical Financials'!G19)/1000 -> -0.179 | I22: =('Historical Financials'!I19)/1000 -> 0 | J22: =('Historical Financials'!J19)/1000 -> 0 | K22: =('Historical Financials'!K19)/1000 -> 1.059 | L22: =('Historical Financials'!L19)/1000 -> 0 | M22: =('Historical Financials'!M19)/1000 -> -0.08 | N22: =('Historical Financials'!N19)/1000 -> -0.208 | O22: =('Historical Financials'!O19)/1000 -> 0.004 | P22: =('Historical Financials'!P19)/1000 -> -0.578 | ... W22: =('Historical Financials'!W19)/1000 -> 0 | Y22: =SUM(H22:K22) -> 1.059 | Z22: =SUM(I22:L22) -> 1.059 | AA22: =SUM(J22:M22) -> 0.979 | AB22: =SUM(K22:N22) -> 0.771 | AC22: =SUM(L22:O22) -> -0.284 | AD22: =SUM(M22:P22) -> -0.862 | AE22: =SUM(N22:Q22) -> -0.754 | AF22: =SUM(O22:R22) -> -0.546 | ... AK22: =SUM(T22:W22) -> -0.132 | AM22: =SUM(AK22/AG22)-1 -> -0.7888
B23: Earning before Interest & Taxes (EBIT) | C23: =SUM(C17+SUM(C20:C22)) -> #REF! | D23: =SUM(D17+SUM(D20:D22)) -> #REF! | E23: =SUM(E17+SUM(E20:E22)) -> #REF! | F23: =SUM(F17+SUM(F20:F22)) -> #REF! | G23: =SUM(G17+SUM(G20:G22)) -> #REF! | I23: =SUM(I17+SUM(I20:I22)) -> #REF! | J23: =SUM(J17+SUM(J20:J22)) -> #REF! | K23: =SUM(K17+SUM(K20:K22)) -> #REF! | L23: =SUM(L17+SUM(L20:L22)) -> #REF! | M23: =SUM(M17+SUM(M20:M22)) -> #REF! | N23: =SUM(N17+SUM(N20:N22)) -> #REF! | O23: =SUM(O17+SUM(O20:O22)) -> #REF! | P23: =SUM(P17+SUM(P20:P22)) -> #REF! | ... W23: =SUM(W17+SUM(W20:W22)) -> #REF! | Y23: =SUM(Y17+SUM(Y20:Y22)) -> -20.611 | Z23: =SUM(Z17+SUM(Z20:Z22)) -> -28.34 | AA23: =SUM(AA17+SUM(AA20:AA22)) -> -28.497 | AB23: =SUM(AB17+SUM(AB20:AB22)) -> -28.376 | AC23: =SUM(AC17+SUM(AC20:AC22)) -> -28.54 | AD23: =SUM(AD17+SUM(AD20:AD22)) -> -28.032 | AE23: =SUM(AE17+SUM(AE20:AE22)) -> -28.041 | AF23: =SUM(AF17+SUM(AF20:AF22)) -> -27.905 | ... AK23: =SUM(AK17+SUM(AK20:AK22)) -> #REF! | AM23: =SUM(AK23/AG23)-1 -> #REF!
B24: Operating Margin (%) | C24: =C23/C11 -> #REF! | D24: =D23/D11 -> #REF! | E24: =E23/E11 -> #REF! | F24: =F23/F11 -> #REF! | G24: =G23/G11 -> #REF! | I24: =I23/I11 -> #REF! | J24: =J23/J11 -> #REF! | K24: =K23/K11 -> #REF! | L24: =L23/L11 -> #REF! | M24: =M23/M11 -> #REF! | N24: =N23/N11 -> #REF! | O24: =O23/O11 -> #REF! | P24: =P23/P11 -> #REF! | ... W24: =W23/W11 -> #REF! | Y24: =Y23/Y11 -> #DIV/0! | Z24: =Z23/Z11 -> #DIV/0! | AA24: =AA23/AA11 -> #DIV/0! | AB24: =AB23/AB11 -> #DIV/0! | AC24: =AC23/AC11 -> #DIV/0! | AD24: =AD23/AD11 -> #DIV/0! | AE24: =AE23/AE11 -> #DIV/0! | AF24: =AF23/AF11 -> #DIV/0! | ... AK24: =AK23/AK11 -> #REF! | AM24: =SUM(AK24-AG24)*10000 -> #REF!
B26: (+) Depreciation and amortization of PP&E and intangibles | C26: =('Historical Financials'!C103)/1000 -> 1.212 | D26: =('Historical Financials'!D103)/1000 -> 1.663 | E26: =('Historical Financials'!E103)/1000 -> 2.031 | F26: =('Historical Financials'!F103)/1000 -> 2.484 | G26: =('Historical Financials'!G103)/1000 -> 2.648 | I26: =('Historical Financials'!I103)/1000 -> 0.496 | J26: =('Historical Financials'!J103)/1000 -> 0.498 | K26: =('Historical Financials'!K103)/1000 -> 1.51 | L26: =('Historical Financials'!L103)/1000 -> -0.473 | M26: =('Historical Financials'!M103)/1000 -> 0.634 | N26: =('Historical Financials'!N103)/1000 -> 0.628 | O26: =('Historical Financials'!O103)/1000 -> 0.614 | P26: =('Historical Financials'!P103)/1000 -> 0.608 | ... W26: =('Historical Financials'!W103)/1000 -> 0 | Y26: =SUM(H26:K26) -> 2.504 | Z26: =SUM(I26:L26) -> 2.031 | AA26: =SUM(J26:M26) -> 2.169 | AB26: =SUM(K26:N26) -> 2.299 | AC26: =SUM(L26:O26) -> 1.403 | AD26: =SUM(M26:P26) -> 2.484 | AE26: =SUM(N26:Q26) -> 2.452 | AF26: =SUM(O26:R26) -> 2.529 | ... AK26: =SUM(T26:W26) -> 0.697 | AM26: =SUM(AK26/AG26)-1 -> -0.72762798
B27: (+) Amortization of content assets | C27: =-C15 -> 9.255 | D27: =-D15 -> 14.262 | E27: =-E15 -> 18.635 | F27: =-F15 -> 15.869 | G27: =-G15 -> 17.06 | I27: =-I15 -> 4.303 | J27: =-J15 -> 4.648 | K27: =-K15 -> 4.816 | L27: =-L15 -> 4.868 | M27: =-M15 -> 4.044 | N27: =-N15 -> 4.153 | O27: =-O15 -> 3.792 | P27: =-P15 -> 3.88 | ... W27: =-W15 -> 0 | Y27: =-Y15 -> 13.767 | Z27: =-Z15 -> 18.635 | AA27: =-AA15 -> 18.376 | AB27: =-AB15 -> 17.881 | AC27: =-AC15 -> 16.857 | AD27: =-AD15 -> 15.869 | AE27: =-AE15 -> 16.137 | AF27: =-AF15 -> 16.09 | ... AK27: =-AK15 -> 4.468
B28: EBITDA | C28: =SUM(C23+SUM(C26:C27)) -> #REF! | D28: =SUM(D23+SUM(D26:D27)) -> #REF! | E28: =SUM(E23+SUM(E26:E27)) -> #REF! | F28: =SUM(F23+SUM(F26:F27)) -> #REF! | G28: =SUM(G23+SUM(G26:G27)) -> #REF! | I28: =SUM(I23+SUM(I26:I27)) -> #REF! | J28: =SUM(J23+SUM(J26:J27)) -> #REF! | K28: =SUM(K23+SUM(K26:K27)) -> #REF! | L28: =SUM(L23+SUM(L26:L27)) -> #REF! | M28: =SUM(M23+SUM(M26:M27)) -> #REF! | N28: =SUM(N23+SUM(N26:N27)) -> #REF! | O28: =SUM(O23+SUM(O26:O27)) -> #REF! | P28: =SUM(P23+SUM(P26:P27)) -> #REF! | ... W28: =SUM(W23+SUM(W26:W27)) -> #REF! | Y28: =SUM(Y23+SUM(Y26:Y27)) -> -4.34 | Z28: =SUM(Z23+SUM(Z26:Z27)) -> -7.674 | AA28: =SUM(AA23+SUM(AA26:AA27)) -> -7.952 | AB28: =SUM(AB23+SUM(AB26:AB27)) -> -8.196 | AC28: =SUM(AC23+SUM(AC26:AC27)) -> -10.28 | AD28: =SUM(AD23+SUM(AD26:AD27)) -> -9.679 | AE28: =SUM(AE23+SUM(AE26:AE27)) -> -9.452 | AF28: =SUM(AF23+SUM(AF26:AF27)) -> -9.286 | ... AK28: =SUM(AK23+SUM(AK26:AK27)) -> #REF! | AM28: =SUM(AK28/AG28)-1 -> #REF!
B29: EBITDA Margin (%) | C29: =C28/C11 -> #REF! | D29: =D28/D11 -> #REF! | E29: =E28/E11 -> #REF! | F29: =F28/F11 -> #REF! | G29: =G28/G11 -> #REF! | I29: =I28/I11 -> #REF! | J29: =J28/J11 -> #REF! | K29: =K28/K11 -> #REF! | L29: =L28/L11 -> #REF! | M29: =M28/M11 -> #REF! | N29: =N28/N11 -> #REF! | O29: =O28/O11 -> #REF! | P29: =P28/P11 -> #REF! | ... W29: =W28/W11 -> #REF! | Y29: =Y28/Y11 -> #DIV/0! | Z29: =Z28/Z11 -> #DIV/0! | AA29: =AA28/AA11 -> #DIV/0! | AB29: =AB28/AB11 -> #DIV/0! | AC29: =AC28/AC11 -> #DIV/0! | AD29: =AD28/AD11 -> #DIV/0! | AE29: =AE28/AE11 -> #DIV/0! | AF29: =AF28/AF11 -> #DIV/0! | ... AK29: =AK28/AK11 -> #REF! | AM29: =SUM(AK29-AG29)*10000 -> #REF!
B31: (+) Share-based Compensation | C31: =('Historical Financials'!C104)/1000 -> -0.336 | D31: =('Historical Financials'!D104)/1000 -> -1.002 | E31: =('Historical Financials'!E104)/1000 -> 0.432 | F31: =('Historical Financials'!F104)/1000 -> -0.152 | G31: =('Historical Financials'!G104)/1000 -> -0.349 | I31: =('Historical Financials'!I104)/1000 -> -0.103 | J31: =('Historical Financials'!J104)/1000 -> 0.316 | K31: =('Historical Financials'!K104)/1000 -> 0.374 | L31: =('Historical Financials'!L104)/1000 -> -0.155 | M31: =('Historical Financials'!M104)/1000 -> -0.025 | N31: =('Historical Financials'!N104)/1000 -> -0.02 | O31: =('Historical Financials'!O104)/1000 -> -0.039 | P31: =('Historical Financials'!P104)/1000 -> -0.068 | ... W31: =('Historical Financials'!W104)/1000 -> 0 | Y31: =SUM(H31:K31) -> 0.587 | Z31: =SUM(I31:L31) -> 0.432 | AA31: =SUM(J31:M31) -> 0.51 | AB31: =SUM(K31:N31) -> 0.174 | AC31: =SUM(L31:O31) -> -0.239 | AD31: =SUM(M31:P31) -> -0.152 | AE31: =SUM(N31:Q31) -> -0.198 | AF31: =SUM(O31:R31) -> -0.38 | ... AK31: =SUM(T31:W31) -> -0.035 | AM31: =SUM(AK31/AG31)-1 -> -0.90837696
B32: Adj. EBITDA | C32: =+SUM(C28+SUM(C31:C31)) -> #REF! | D32: =+SUM(D28+SUM(D31:D31)) -> #REF! | E32: =+SUM(E28+SUM(E31:E31)) -> #REF! | F32: =+SUM(F28+SUM(F31:F31)) -> #REF! | G32: =+SUM(G28+SUM(G31:G31)) -> #REF! | I32: =+SUM(I28+SUM(I31:I31)) -> #REF! | J32: =+SUM(J28+SUM(J31:J31)) -> #REF! | K32: =+SUM(K28+SUM(K31:K31)) -> #REF! | L32: =+SUM(L28+SUM(L31:L31)) -> #REF! | M32: =+SUM(M28+SUM(M31:M31)) -> #REF! | N32: =+SUM(N28+SUM(N31:N31)) -> #REF! | O32: =+SUM(O28+SUM(O31:O31)) -> #REF! | P32: =+SUM(P28+SUM(P31:P31)) -> #REF! | ... W32: =+SUM(W28+SUM(W31:W31)) -> #REF! | Y32: =+SUM(Y28+SUM(Y31:Y31)) -> -3.753 | Z32: =+SUM(Z28+SUM(Z31:Z31)) -> -7.242 | AA32: =+SUM(AA28+SUM(AA31:AA31)) -> -7.442 | AB32: =+SUM(AB28+SUM(AB31:AB31)) -> -8.022 | AC32: =+SUM(AC28+SUM(AC31:AC31)) -> -10.519 | AD32: =+SUM(AD28+SUM(AD31:AD31)) -> -9.831 | AE32: =+SUM(AE28+SUM(AE31:AE31)) -> -9.65 | AF32: =+SUM(AF28+SUM(AF31:AF31)) -> -9.666 | ... AK32: =+SUM(AK28+SUM(AK31:AK31)) -> #REF! | AM32: =SUM(AK32/AG32)-1 -> #REF!
B33: Adj. EBITDA Margin (%) | C33: =C32/C11 -> #REF! | D33: =D32/D11 -> #REF! | E33: =E32/E11 -> #REF! | F33: =F32/F11 -> #REF! | G33: =G32/G11 -> #REF! | I33: =I32/I11 -> #REF! | J33: =J32/J11 -> #REF! | K33: =K32/K11 -> #REF! | L33: =L32/L11 -> #REF! | M33: =M32/M11 -> #REF! | N33: =N32/N11 -> #REF! | O33: =O32/O11 -> #REF! | P33: =P32/P11 -> #REF! | ... W33: =W32/W11 -> #REF! | Y33: =Y32/Y11 -> #DIV/0! | Z33: =Z32/Z11 -> #DIV/0! | AA33: =AA32/AA11 -> #DIV/0! | AB33: =AB32/AB11 -> #DIV/0! | AC33: =AC32/AC11 -> #DIV/0! | AD33: =AD32/AD11 -> #DIV/0! | AE33: =AE32/AE11 -> #DIV/0! | AF33: =AF32/AF11 -> #DIV/0! | ... AK33: =AK32/AK11 -> #REF! | AM33: =SUM(AK33-AG33)*10000 -> #REF!
B35: (-) Capital Expenditures | C35: =('Historical Financials'!C118)/1000 -> -1.407 | D35: =('Historical Financials'!D118)/1000 -> -1.888 | E35: =('Historical Financials'!E118)/1000 -> -2.262 | F35: =('Historical Financials'!F118)/1000 -> -1.45 | G35: =('Historical Financials'!G118)/1000 -> -1.041 | I35: =('Historical Financials'!I118)/1000 -> -0.583 | J35: =('Historical Financials'!J118)/1000 -> -0.491 | K35: =('Historical Financials'!K118)/1000 -> -1.628 | L35: =('Historical Financials'!L118)/1000 -> 0.44 | M35: =('Historical Financials'!M118)/1000 -> -0.398 | N35: =('Historical Financials'!N118)/1000 -> -0.453 | O35: =('Historical Financials'!O118)/1000 -> -0.306 | P35: =('Historical Financials'!P118)/1000 -> -0.293 | ... W35: =('Historical Financials'!W118)/1000 -> 0 | Y35: =SUM(H35:K35) -> -2.702 | Z35: =SUM(I35:L35) -> -2.262 | AA35: =SUM(J35:M35) -> -2.077 | AB35: =SUM(K35:N35) -> -2.039 | AC35: =SUM(L35:O35) -> -0.717 | AD35: =SUM(M35:P35) -> -1.45 | AE35: =SUM(N35:Q35) -> -1.266 | AF35: =SUM(O35:R35) -> -1.211 | ... AK35: =SUM(T35:W35) -> -0.256 | AM35: =SUM(AK35/AG35)-1 -> -0.76252319
B36: (-) Cash Taxes | C36: =-('Historical Financials'!C155)/1000 -> 0 | D36: =-('Historical Financials'!D155)/1000 -> 0 | E36: =-('Historical Financials'!E155)/1000 -> 0 | F36: =-('Historical Financials'!F155)/1000 -> 0 | G36: =-('Historical Financials'!G155)/1000 -> 0 | I36: =('Historical Financials'!I29)/1000 -> -0.466 | J36: =('Historical Financials'!J29)/1000 -> -0.489 | K36: =('Historical Financials'!K29)/1000 -> -0.509 | L36: =('Historical Financials'!L29)/1000 -> -0.548 | M36: =('Historical Financials'!M29)/1000 -> -0.098 | N36: =('Historical Financials'!N29)/1000 -> -0.193 | O36: =('Historical Financials'!O29)/1000 -> -0.022 | P36: =('Historical Financials'!P29)/1000 -> 0.209 | ... W36: =('Historical Financials'!W29)/1000 -> 0 | Y36: =SUM(H36:K36) -> -1.464 | Z36: =SUM(I36:L36) -> -2.012 | AA36: =SUM(J36:M36) -> -1.644 | AB36: =SUM(K36:N36) -> -1.348 | AC36: =SUM(L36:O36) -> -0.861 | AD36: =SUM(M36:P36) -> -0.104 | AE36: =SUM(N36:Q36) -> -0.157 | AF36: =SUM(O36:R36) -> -0.187 | ... AK36: =SUM(T36:W36) -> 0.319 | AM36: =SUM(AK36/AG36)-1 -> -1.9494048
B37: (-) Cash Interest | C37: =-('Historical Financials'!C156)/1000 -> 0 | D37: =-('Historical Financials'!D156)/1000 -> 0 | E37: =-('Historical Financials'!E156)/1000 -> 0 | F37: =-('Historical Financials'!F156)/1000 -> 0 | G37: =-('Historical Financials'!G156)/1000 -> 0 | I37: =('Historical Financials'!I24)/1000 -> 0.017 | J37: =('Historical Financials'!J24)/1000 -> 0.02 | K37: =('Historical Financials'!K24)/1000 -> 0.022 | L37: =('Historical Financials'!L24)/1000 -> 0.032 | M37: =('Historical Financials'!M24)/1000 -> 0.055 | N37: =('Historical Financials'!N24)/1000 -> 0.059 | O37: =('Historical Financials'!O24)/1000 -> 0.079 | P37: =('Historical Financials'!P24)/1000 -> 0.12 | ... W37: =('Historical Financials'!W24)/1000 -> 0 | Y37: =SUM(H37:K37) -> 0.059 | Z37: =SUM(I37:L37) -> 0.091 | AA37: =SUM(J37:M37) -> 0.129 | AB37: =SUM(K37:N37) -> 0.168 | AC37: =SUM(L37:O37) -> 0.225 | AD37: =SUM(M37:P37) -> 0.313 | AE37: =SUM(N37:Q37) -> 0.407 | AF37: =SUM(O37:R37) -> 0.508 | ... AK37: =SUM(T37:W37) -> 0.184 | AM37: =SUM(AK37/AG37)-1 -> -0.69885434
B38: (+/-) Changes in NWC | C38: =SUM('Historical Financials'!C109:C114)/1000 -> -1.607 | D38: =SUM('Historical Financials'!D109:D114)/1000 -> -0.461 | E38: =SUM('Historical Financials'!E109:E114)/1000 -> -7.8 | F38: =SUM('Historical Financials'!F109:F114)/1000 -> 1.148 | G38: =SUM('Historical Financials'!G109:G114)/1000 -> 1.223 | I38: =SUM('Historical Financials'!I109:I114)/1000 -> -2.388 | J38: =SUM('Historical Financials'!J109:J114)/1000 -> -0.793 | K38: =SUM('Historical Financials'!K109:K114)/1000 -> -5.335 | L38: =SUM('Historical Financials'!L109:L114)/1000 -> 0.716 | M38: =SUM('Historical Financials'!M109:M114)/1000 -> -0.004 | N38: =SUM('Historical Financials'!N109:N114)/1000 -> -0.929 | O38: =SUM('Historical Financials'!O109:O114)/1000 -> 0.38 | P38: =SUM('Historical Financials'!P109:P114)/1000 -> 1.701 | ... W38: =SUM('Historical Financials'!W109:W114)/1000 -> 0 | Y38: =SUM(H38:K38) -> -8.516 | Z38: =SUM(I38:L38) -> -7.8 | AA38: =SUM(J38:M38) -> -5.416 | AB38: =SUM(K38:N38) -> -5.552 | AC38: =SUM(L38:O38) -> 0.163 | AD38: =SUM(M38:P38) -> 1.148 | AE38: =SUM(N38:Q38) -> 1.341 | AF38: =SUM(O38:R38) -> 3.438 | ... AK38: =SUM(T38:W38) -> -0.859 | AM38: =SUM(AK38/AG38)-1 -> -1.2270685
B39: Discretionary Cash-Flows | C39: =SUM(C32+SUM(C35:C38)) -> #REF! | D39: =SUM(D32+SUM(D35:D38)) -> #REF! | E39: =SUM(E32+SUM(E35:E38)) -> #REF! | F39: =SUM(F32+SUM(F35:F38)) -> #REF! | G39: =SUM(G32+SUM(G35:G38)) -> #REF! | I39: =SUM(I32+SUM(I35:I38)) -> #REF! | J39: =SUM(J32+SUM(J35:J38)) -> #REF! | K39: =SUM(K32+SUM(K35:K38)) -> #REF! | L39: =SUM(L32+SUM(L35:L38)) -> #REF! | M39: =SUM(M32+SUM(M35:M38)) -> #REF! | N39: =SUM(N32+SUM(N35:N38)) -> #REF! | O39: =SUM(O32+SUM(O35:O38)) -> #REF! | P39: =SUM(P32+SUM(P35:P38)) -> #REF! | ... W39: =SUM(W32+SUM(W35:W38)) -> #REF! | Y39: =SUM(Y32+SUM(Y35:Y38)) -> -16.376 | Z39: =SUM(Z32+SUM(Z35:Z38)) -> -19.225 | AA39: =SUM(AA32+SUM(AA35:AA38)) -> -16.45 | AB39: =SUM(AB32+SUM(AB35:AB38)) -> -16.793 | AC39: =SUM(AC32+SUM(AC35:AC38)) -> -11.709 | AD39: =SUM(AD32+SUM(AD35:AD38)) -> -9.924 | AE39: =SUM(AE32+SUM(AE35:AE38)) -> -9.325 | AF39: =SUM(AF32+SUM(AF35:AF38)) -> -7.118 | ... AK39: =SUM(AK32+SUM(AK35:AK38)) -> #REF! | AM39: =SUM(AK39/AG39)-1 -> #REF!
B41: (+/-) Proceeds / (Purchases) of ST Investments | C41: =SUM('Historical Financials'!C125:C125)/1000 -> 0 | D41: =SUM('Historical Financials'!D125:D125)/1000 -> 0 | E41: =SUM('Historical Financials'!E125:E125)/1000 -> -0.016 | F41: =SUM('Historical Financials'!F125:F125)/1000 -> 1.383 | G41: =SUM('Historical Financials'!G125:G125)/1000 -> 0.002 | I41: =SUM('Historical Financials'!I125:I125)/1000 -> 0 | J41: =SUM('Historical Financials'!J125:J125)/1000 -> 0 | K41: =SUM('Historical Financials'!K125:K125)/1000 -> 0 | L41: =SUM('Historical Financials'!L125:L125)/1000 -> -0.016 | M41: =SUM('Historical Financials'!M125:M125)/1000 -> 0 | N41: =SUM('Historical Financials'!N125:N125)/1000 -> -0.042 | O41: =SUM('Historical Financials'!O125:O125)/1000 -> 1.437 | P41: =SUM('Historical Financials'!P125:P125)/1000 -> -0.012 | ... W41: =SUM('Historical Financials'!W125:W125)/1000 -> 0 | Y41: =SUM(H41:K41) -> 0 | Z41: =SUM(I41:L41) -> -0.016 | AA41: =SUM(J41:M41) -> -0.016 | AB41: =SUM(K41:N41) -> -0.058 | AC41: =SUM(L41:O41) -> 1.379 | AD41: =SUM(M41:P41) -> 1.383 | AE41: =SUM(N41:Q41) -> 1.383 | AF41: =SUM(O41:R41) -> 1.425 | ... AK41: =SUM(T41:W41) -> 0.004
B42: (+/-) Divestiture / Acquisitions | C42: =('Historical Financials'!C124)/1000 -> 0.043 | D42: =('Historical Financials'!D124)/1000 -> -0.059 | E42: =('Historical Financials'!E124)/1000 -> 0.041 | F42: =('Historical Financials'!F124)/1000 -> 0.019 | G42: =('Historical Financials'!G124)/1000 -> -0.036 | I42: =('Historical Financials'!I124)/1000 -> 0 | J42: =('Historical Financials'!J124)/1000 -> 0 | K42: =('Historical Financials'!K124)/1000 -> 0.041 | L42: =('Historical Financials'!L124)/1000 -> 0 | M42: =('Historical Financials'!M124)/1000 -> -0.018 | N42: =('Historical Financials'!N124)/1000 -> 0.014 | O42: =('Historical Financials'!O124)/1000 -> 0.022 | P42: =('Historical Financials'!P124)/1000 -> 0.001 | ... W42: =('Historical Financials'!W124)/1000 -> 0 | Y42: =SUM(H42:K42) -> 0.041 | Z42: =SUM(I42:L42) -> 0.041 | AA42: =SUM(J42:M42) -> 0.023 | AB42: =SUM(K42:N42) -> 0.037 | AC42: =SUM(L42:O42) -> 0.018 | AD42: =SUM(M42:P42) -> 0.019 | AE42: =SUM(N42:Q42) -> 0.039 | AF42: =SUM(O42:R42) -> -0.013 | ... AK42: =SUM(T42:W42) -> 0
B43: (-) Proceeds From Equity Issuances / (Share Repurchases) | C43: =SUM('Historical Financials'!#REF!)/1000 -> #REF! | D43: =SUM('Historical Financials'!#REF!)/1000 -> #REF! | E43: =SUM('Historical Financials'!#REF!)/1000 -> #REF! | F43: =SUM('Historical Financials'!#REF!)/1000 -> #REF! | G43: =SUM('Historical Financials'!#REF!)/1000 -> #REF! | I43: =SUM('Historical Financials'!#REF!)/1000 -> #REF! | J43: =SUM('Historical Financials'!#REF!)/1000 -> #REF! | K43: =SUM('Historical Financials'!#REF!)/1000 -> #REF! | L43: =SUM('Historical Financials'!#REF!)/1000 -> #REF! | M43: =SUM('Historical Financials'!#REF!)/1000 -> #REF! | N43: =SUM('Historical Financials'!#REF!)/1000 -> #REF! | O43: =SUM('Historical Financials'!#REF!)/1000 -> #REF! | P43: =SUM('Historical Financials'!#REF!)/1000 -> #REF! | ... W43: =SUM('Historical Financials'!#REF!)/1000 -> #REF! | AG43: =SUM(P43:S43) -> #REF! | AH43: =SUM(Q43:T43) -> #REF! | AI43: =SUM(R43:U43) -> #REF! | AJ43: =SUM(S43:V43) -> #REF! | AK43: =SUM(T43:W43) -> #REF!
B44: (-) 'Proceeds from issuance of Debt / (Repayment), net | C44: =SUM('Historical Financials'!C129:C131)/1000 -> 0.002 | D44: =SUM('Historical Financials'!D129:D131)/1000 -> 0.001 | E44: =SUM('Historical Financials'!E129:E131)/1000 -> -0.352 | F44: =SUM('Historical Financials'!F129:F131)/1000 -> -0.498 | G44: =SUM('Historical Financials'!G129:G131)/1000 -> 0 | I44: =SUM('Historical Financials'!I129:I131)/1000 -> 0 | J44: =SUM('Historical Financials'!J129:J131)/1000 -> 0 | K44: =SUM('Historical Financials'!K129:K131)/1000 -> -0.35 | L44: =SUM('Historical Financials'!L129:L131)/1000 -> -0.002 | M44: =SUM('Historical Financials'!M129:M131)/1000 -> -0.497 | N44: =SUM('Historical Financials'!N129:N131)/1000 -> 0.497 | O44: =SUM('Historical Financials'!O129:O131)/1000 -> -0.498 | P44: =SUM('Historical Financials'!P129:P131)/1000 -> 0 | ... W44: =SUM('Historical Financials'!W129:W131)/1000 -> 0 | AG44: =SUM(P44:S44) -> 0 | AH44: =SUM(Q44:T44) -> 0 | AI44: =SUM(R44:U44) -> 0 | AJ44: =SUM(S44:V44) -> 0 | AK44: =SUM(T44:W44) -> 0
