Workbook

Sheet Historical Financials
B2: Beyond Meat, Inc. (NASDAQ: BYND)
B3: Historical Financials
B4: $ mm except per share
A6: X | B6: Income Statement | G6: FYE | K6: Quarterly | AV6: LTM | BB6: Variance
B7: Fiscal Period | C7: 2018 | D7: 2019 | E7: 2020 | F7: 2021 | G7: 2022 | H7: 2023 | I7: 2024 | K7: 1Q18 | L7: 2Q18 | M7: 3Q18 | N7: 4Q18 | O7: 1Q19 | P7: 2Q19 | Q7: 3Q19 | R7: 4Q19 | S7: 1Q20 | T7: 2Q20 | U7: 3Q20 | V7: 4Q20 | W7: 1Q21 | X7: 2Q21 | Y7: 3Q21 | Z7: 4Q21 | AA7: 1Q22 | AB7: 2Q22 | AC7: 3Q22 | AD7: 4Q22 | AE7: 1Q23 | AF7: 2Q23 | AG7: 3Q23 | AH7: 4Q23 | AI7: 1Q24 | AJ7: 2Q24 | AK7: 3Q24 | AL7: 4Q24 | AM7: 1Q25 | AN7: 2Q25 | AP7: =AD7 -> 4Q22 | AQ7: =AE7 -> 1Q23 | AR7: =AF7 -> 2Q23 | AS7: =AG7 -> 3Q23 | AT7: =AH7 -> 4Q23 | AU7: =AI7 -> 1Q24 | AV7: =AJ7 -> 2Q24 | AW7: =AK7 -> 3Q24 | ... AZ7: =AN7 -> 2Q25
B8: Fiscal Period End Date | C8: 43465 | D8: 43830 | E8: 44196 | F8: 44561 | G8: 44926 | H8: 45291 | I8: 45657 | K8: 43190 | L8: 43281 | M8: 43372 | N8: 43465 | O8: 43554 | P8: 43645 | Q8: 43736 | R8: 43830 | S8: 43918 | T8: 44009 | U8: 44100 | V8: 44196 | W8: 44289 | X8: 44380 | Y8: 44471 | Z8: 44561 | AA8: 44653 | AB8: 44744 | AC8: 44835 | AD8: 44926 | AE8: 45017 | AF8: 45108 | AG8: 45199 | AH8: 45291 | AI8: 45381 | AJ8: 45472 | AK8: 45563 | AL8: 45657 | AM8: 45745 | AN8: 45836 | AP8: =AD8 -> 44926 | AQ8: =AE8 -> 45017 | AR8: =AF8 -> 45108 | AS8: =AG8 -> 45199 | AT8: =AH8 -> 45291 | AU8: =AI8 -> 45381 | AV8: =AJ8 -> 45472 | AW8: =AK8 -> 45563 | ... AZ8: =AN8 -> 45836
B10: Consolidated Revenue | C10: 87934 | D10: 297897 | E10: 406785 | F10: 464700 | G10: 418933 | H10: 343376 | I10: 326452 | K10: 12776 | L10: 17367 | M10: 26277 | N10: =SUM(C10-SUM(K10:M10)) -> 31514 | O10: 40206 | P10: 67251 | Q10: 91961 | R10: =SUM(D10-SUM(O10:Q10)) -> 98479 | S10: 97074 | T10: 113338 | U10: 94436 | V10: =SUM(E10-SUM(S10:U10)) -> 101937 | W10: 108164 | X10: 149426 | Y10: 106432 | Z10: =SUM(F10-SUM(W10:Y10)) -> 100678 | AA10: 109455 | AB10: 147040 | AC10: 82500 | AD10: =SUM(G10-SUM(AA10:AC10)) -> 79938 | AE10: 92236 | AF10: 102149 | AG10: 75312 | AH10: =SUM(H10-SUM(AE10:AG10)) -> 73679 | AI10: 75603 | AJ10: 93185 | AK10: 81006 | AL10: =SUM(I10-SUM(AI10:AK10)) -> 76658 | AM10: 68731 | AN10: 74958 | AP10: =SUM(AA10:AD10) -> 418933 | AQ10: =SUM(AB10:AE10) -> 401714 | AR10: =SUM(AC10:AF10) -> 356823 | AS10: =SUM(AD10:AG10) -> 349635 | AT10: =SUM(AE10:AH10) -> 343376 | AU10: =SUM(AF10:AI10) -> 326743 | AV10: =SUM(AG10:AJ10) -> 317779 | AW10: =SUM(AH10:AK10) -> 323473 | ... AZ10: =SUM(AK10:AN10) -> 301353 | BB10: =SUM(AZ10/AV10)-1 -> -0.051690011
B11: Total Revenue | C11: =+SUM(C10:C10) -> 87934 | D11: =+SUM(D10:D10) -> 297897 | E11: =+SUM(E10:E10) -> 406785 | F11: =+SUM(F10:F10) -> 464700 | G11: =+SUM(G10:G10) -> 418933 | H11: =+SUM(H10:H10) -> 343376 | I11: =+SUM(I10:I10) -> 326452 | K11: =+SUM(K10:K10) -> 12776 | L11: =+SUM(L10:L10) -> 17367 | M11: =+SUM(M10:M10) -> 26277 | N11: =+SUM(N10:N10) -> 31514 | O11: =+SUM(O10:O10) -> 40206 | P11: =+SUM(P10:P10) -> 67251 | Q11: =+SUM(Q10:Q10) -> 91961 | R11: =+SUM(R10:R10) -> 98479 | ... AN11: =+SUM(AN10:AN10) -> 74958 | AP11: =+SUM(AP10:AP10) -> 418933 | AQ11: =+SUM(AQ10:AQ10) -> 401714 | AR11: =+SUM(AR10:AR10) -> 356823 | AS11: =+SUM(AS10:AS10) -> 349635 | AT11: =+SUM(AT10:AT10) -> 343376 | AU11: =+SUM(AU10:AU10) -> 326743 | AV11: =+SUM(AV10:AV10) -> 317779 | AW11: =+SUM(AW10:AW10) -> 323473 | ... AZ11: =+SUM(AZ10:AZ10) -> 301353 | BB11: =SUM(AZ11/AV11)-1 -> -0.051690011
B13: Cost of Sales | C13: -70360 | D13: -198141 | E13: -284510 | F13: -347419 | G13: -442676 | H13: -426031 | I13: -284753 | K13: -10719 | L13: -14755 | M13: -21235 | N13: =SUM(C13-SUM(K13:M13)) -> -23651 | O13: -29435 | P13: -44510 | Q13: -59178 | R13: =SUM(D13-SUM(O13:Q13)) -> -65018 | S13: -59383 | T13: -79687 | U13: -68908 | V13: =SUM(E13-SUM(S13:U13)) -> -76532 | W13: -75456 | X13: -102074 | Y13: -83456 | Z13: =SUM(F13-SUM(W13:Y13)) -> -86433 | AA13: -109265 | AB13: -153202 | AC13: -97340 | AD13: =SUM(G13-SUM(AA13:AC13)) -> -82869 | AE13: -86051 | AF13: -99876 | AG13: -82566 | AH13: =SUM(H13-SUM(AE13:AG13)) -> -157538 | AI13: -71935 | AJ13: -79468 | AK13: -66698 | AL13: =SUM(I13-SUM(AI13:AK13)) -> -66652 | AM13: -69796 | AN13: -66367 | AP13: =SUM(AA13:AD13) -> -442676 | AQ13: =SUM(AB13:AE13) -> -419462 | AR13: =SUM(AC13:AF13) -> -366136 | AS13: =SUM(AD13:AG13) -> -351362 | AT13: =SUM(AE13:AH13) -> -426031 | AU13: =SUM(AF13:AI13) -> -411915 | AV13: =SUM(AG13:AJ13) -> -391507 | AW13: =SUM(AH13:AK13) -> -375639 | ... AZ13: =SUM(AK13:AN13) -> -269513 | BB13: =SUM(AZ13/AV13)-1 -> -0.31160107
B14: Gross Profit | C14: =+SUM(C11+SUM(C13:C13)) -> 17574 | D14: =+SUM(D11+SUM(D13:D13)) -> 99756 | E14: =+SUM(E11+SUM(E13:E13)) -> 122275 | F14: =+SUM(F11+SUM(F13:F13)) -> 117281 | G14: =+SUM(G11+SUM(G13:G13)) -> -23743 | H14: =+SUM(H11+SUM(H13:H13)) -> -82655 | I14: =+SUM(I11+SUM(I13:I13)) -> 41699 | K14: =+SUM(K11+SUM(K13:K13)) -> 2057 | L14: =+SUM(L11+SUM(L13:L13)) -> 2612 | M14: =+SUM(M11+SUM(M13:M13)) -> 5042 | N14: =+SUM(N11+SUM(N13:N13)) -> 7863 | O14: =+SUM(O11+SUM(O13:O13)) -> 10771 | P14: =+SUM(P11+SUM(P13:P13)) -> 22741 | Q14: =+SUM(Q11+SUM(Q13:Q13)) -> 32783 | R14: =+SUM(R11+SUM(R13:R13)) -> 33461 | ... AN14: =+SUM(AN11+SUM(AN13:AN13)) -> 8591 | AP14: =+SUM(AP11+SUM(AP13:AP13)) -> -23743 | AQ14: =+SUM(AQ11+SUM(AQ13:AQ13)) -> -17748 | AR14: =+SUM(AR11+SUM(AR13:AR13)) -> -9313 | AS14: =+SUM(AS11+SUM(AS13:AS13)) -> -1727 | AT14: =+SUM(AT11+SUM(AT13:AT13)) -> -82655 | AU14: =+SUM(AU11+SUM(AU13:AU13)) -> -85172 | AV14: =+SUM(AV11+SUM(AV13:AV13)) -> -73728 | AW14: =+SUM(AW11+SUM(AW13:AW13)) -> -52166 | ... AZ14: =+SUM(AZ11+SUM(AZ13:AZ13)) -> 31840 | BB14: =SUM(AZ14/AV14)-1 -> -1.4318576
B15: Gross Margin (%) | C15: =C14/C11 -> 0.19985444 | D15: =D14/D11 -> 0.33486742 | E15: =E14/E11 -> 0.30058876 | F15: =F14/F11 -> 0.25238003 | G15: =G14/G11 -> -0.056674934 | H15: =H14/H11 -> -0.2407128 | I15: =I14/I11 -> 0.12773394 | K15: =K14/K11 -> 0.16100501 | L15: =L14/L11 -> 0.15040018 | M15: =M14/M11 -> 0.19187883 | N15: =N14/N11 -> 0.24950816 | O15: =O14/O11 -> 0.26789534 | P15: =P14/P11 -> 0.33815111 | Q15: =Q14/Q11 -> 0.35648808 | R15: =R14/R11 -> 0.33977802 | ... AN15: =AN14/AN11 -> 0.11461085 | AP15: =AP14/AP11 -> -0.056674934 | AQ15: =AQ14/AQ11 -> -0.044180686 | AR15: =AR14/AR11 -> -0.026099775 | AS15: =AS14/AS11 -> -0.0049394368 | AT15: =AT14/AT11 -> -0.2407128 | AU15: =AU14/AU11 -> -0.2606697 | AV15: =AV14/AV11 -> -0.2320103 | AW15: =AW14/AW11 -> -0.16126848 | ... AZ15: =AZ14/AZ11 -> 0.10565682 | BB15: =SUM(AZ15-AV15)*1000 -> 337.66712
B17: Selling, General & Administrative | C17: -34461 | D17: -74726 | E17: -133655 | F17: -209474 | G17: -239505 | H17: -220344 | I17: -169674 | K17: -5737 | L17: -7043 | M17: -10353 | N17: =SUM(C17-SUM(K17:M17)) -> -11328 | O17: -11177 | P17: -15515 | Q17: -20944 | R17: =SUM(D17-SUM(O17:Q17)) -> -27090 | S17: -27315 | T17: -34292 | U17: -33560 | V17: =SUM(E17-SUM(S17:U17)) -> -38488 | W17: -38954 | X17: -48286 | Y17: -56362 | Z17: =SUM(F17-SUM(W17:Y17)) -> -65872 | AA17: -75114 | AB17: -63015 | AC17: -54495 | AD17: =SUM(G17-SUM(AA17:AC17)) -> -46881 | AE17: -51900 | AF17: -47455 | AG17: -53252 | AH17: =SUM(H17-SUM(AE17:AG17)) -> -67737 | AI17: -47282 | AJ17: -42163 | AK17: -39084 | AL17: =SUM(I17-SUM(AI17:AK17)) -> -41145 | AM17: -47672 | AN17: -37696 | AP17: =SUM(AA17:AD17) -> -239505 | AQ17: =SUM(AB17:AE17) -> -216291 | AR17: =SUM(AC17:AF17) -> -200731 | AS17: =SUM(AD17:AG17) -> -199488 | AT17: =SUM(AE17:AH17) -> -220344 | AU17: =SUM(AF17:AI17) -> -215726 | AV17: =SUM(AG17:AJ17) -> -210434 | AW17: =SUM(AH17:AK17) -> -196266 | ... AZ17: =SUM(AK17:AN17) -> -165597 | BB17: =SUM(AZ17/AV17)-1 -> -0.21306918
B18: Research & Development | C18: -9587 | D18: -20650 | E18: -31535 | F18: -66946 | G18: -62264 | H18: -39530 | I18: -28149 | K18: -1605 | L18: -2497 | M18: -2165 | N18: =SUM(C18-SUM(K18:M18)) -> -3320 | O18: -4498 | P18: -4212 | Q18: -5951 | R18: =SUM(D18-SUM(O18:Q18)) -> -5989 | S18: -6194 | T18: -6016 | U18: -8278 | V18: =SUM(E18-SUM(S18:U18)) -> -11047 | W18: -15925 | X18: -13823 | Y18: -14862 | Z18: =SUM(F18-SUM(W18:Y18)) -> -22336 | AA18: -19678 | AB18: -16202 | AC18: -13413 | AD18: =SUM(G18-SUM(AA18:AC18)) -> -12971 | AE18: -12432 | AF18: -8773 | AG18: -9118 | AH18: =SUM(H18-SUM(AE18:AG18)) -> -9207 | AI18: -9860 | AJ18: -5485 | AK18: -6133 | AL18: =SUM(I18-SUM(AI18:AK18)) -> -6671 | AM18: -7462 | AN18: -5807 | AP18: =SUM(AA18:AD18) -> -62264 | AQ18: =SUM(AB18:AE18) -> -55018 | AR18: =SUM(AC18:AF18) -> -47589 | AS18: =SUM(AD18:AG18) -> -43294 | AT18: =SUM(AE18:AH18) -> -39530 | AU18: =SUM(AF18:AI18) -> -36958 | AV18: =SUM(AG18:AJ18) -> -33670 | AW18: =SUM(AH18:AK18) -> -30685 | ... AZ18: =SUM(AK18:AN18) -> -26073 | BB18: =SUM(AZ18/AV18)-1 -> -0.22563113
B19: Operating Profit | C19: =+SUM(C14+SUM(C17:C18)) -> -26474 | D19: =+SUM(D14+SUM(D17:D18)) -> 4380 | E19: =+SUM(E14+SUM(E17:E18)) -> -42915 | F19: =+SUM(F14+SUM(F17:F18)) -> -159139 | G19: =+SUM(G14+SUM(G17:G18)) -> -325512 | H19: =+SUM(H14+SUM(H17:H18)) -> -342529 | I19: =+SUM(I14+SUM(I17:I18)) -> -156124 | K19: =+SUM(K14+SUM(K17:K18)) -> -5285 | L19: =+SUM(L14+SUM(L17:L18)) -> -6928 | M19: =+SUM(M14+SUM(M17:M18)) -> -7476 | N19: =+SUM(N14+SUM(N17:N18)) -> -6785 | O19: =+SUM(O14+SUM(O17:O18)) -> -4904 | P19: =+SUM(P14+SUM(P17:P18)) -> 3014 | Q19: =+SUM(Q14+SUM(Q17:Q18)) -> 5888 | R19: =+SUM(R14+SUM(R17:R18)) -> 382 | ... AN19: =+SUM(AN14+SUM(AN17:AN18)) -> -34912 | AP19: =+SUM(AP14+SUM(AP17:AP18)) -> -325512 | AQ19: =+SUM(AQ14+SUM(AQ17:AQ18)) -> -289057 | AR19: =+SUM(AR14+SUM(AR17:AR18)) -> -257633 | AS19: =+SUM(AS14+SUM(AS17:AS18)) -> -244509 | AT19: =+SUM(AT14+SUM(AT17:AT18)) -> -342529 | AU19: =+SUM(AU14+SUM(AU17:AU18)) -> -337856 | AV19: =+SUM(AV14+SUM(AV17:AV18)) -> -317832 | AW19: =+SUM(AW14+SUM(AW17:AW18)) -> -279117 | ... AZ19: =+SUM(AZ14+SUM(AZ17:AZ18)) -> -159830 | BB19: =SUM(AZ19/AV19)-1 -> -0.49712427
B20: Operating Margin (%) | C20: =C19/C11 -> -0.30106671 | D20: =D19/D11 -> 0.014703069 | E20: =E19/E11 -> -0.10549799 | F20: =F19/F11 -> -0.34245535 | G20: =G19/G11 -> -0.77700253 | H20: =H19/H11 -> -0.99753332 | I20: =I19/I11 -> -0.47824489 | K20: =K19/K11 -> -0.41366625 | L20: =L19/L11 -> -0.39891749 | M20: =M19/M11 -> -0.28450736 | N20: =N19/N11 -> -0.21530114 | O20: =O19/O11 -> -0.12197184 | P20: =P19/P11 -> 0.044817177 | Q20: =Q19/Q11 -> 0.064027142 | R20: =R19/R11 -> 0.0038789996 | ... AN20: =AN19/AN11 -> -0.46575416 | AP20: =AP19/AP11 -> -0.77700253 | AQ20: =AQ19/AQ11 -> -0.71955919 | AR20: =AR19/AR11 -> -0.72201904 | AS20: =AS19/AS11 -> -0.69932644 | AT20: =AT19/AT11 -> -0.99753332 | AU20: =AU19/AU11 -> -1.0340114 | AV20: =AV19/AV11 -> -1.0001668 | AW20: =AW19/AW11 -> -0.86287573 | ... AZ20: =AZ19/AZ11 -> -0.53037468
B22: Restructuring Expenses | C22: -1515 | D22: -4869 | E22: -6430 | F22: 0 | G22: 0 | H22: 0 | I22: 0 | K22: -294 | L22: -348 | M22: -528 | N22: =SUM(C22-SUM(K22:M22)) -> -345 | O22: -394 | P22: -847 | Q22: -2319 | R22: =SUM(D22-SUM(O22:Q22)) -> -1309 | S22: -2373 | T22: -1509 | U22: -2146 | V22: =SUM(E22-SUM(S22:U22)) -> -402 | W22: -2474 | X22: -3844 | Y22: -5750 | Z22: =SUM(F22-SUM(W22:Y22)) -> 12068 | AA22: -3026 | AB22: -4302 | AC22: -6993 | AD22: =SUM(G22-SUM(AA22:AC22)) -> 14321 | AE22: 426 | AF22: 201 | AG22: 4 | AH22: =SUM(H22-SUM(AE22:AG22)) -> -631 | AI22: 0 | AJ22: 0 | AK22: 0 | AL22: =SUM(I22-SUM(AI22:AK22)) -> 0 | AM22: 0 | AN22: 0 | AP22: =SUM(AA22:AD22) -> 0 | AQ22: =SUM(AB22:AE22) -> 3452 | AR22: =SUM(AC22:AF22) -> 7955 | AS22: =SUM(AD22:AG22) -> 14952 | AT22: =SUM(AE22:AH22) -> 0 | AU22: =SUM(AF22:AI22) -> -426 | AV22: =SUM(AG22:AJ22) -> -627 | AW22: =SUM(AH22:AK22) -> -631 | ... AZ22: =SUM(AK22:AN22) -> 0 | BB22: =SUM(AZ22/AV22)-1 -> -1
B23: Restructuring Income/expense | C23: -1128 | D23: 0 | E23: 0 | F23: -15794 | G23: -17259 | H23: 631 | I23: 0 | K23: -47 | L23: -28 | M23: -313 | N23: =SUM(C23-SUM(K23:M23)) -> -740 | O23: -733 | P23: -741 | Q23: -855 | R23: =SUM(D23-SUM(O23:Q23)) -> 2329 | S23: 0 | T23: 0 | U23: 0 | V23: =SUM(E23-SUM(S23:U23)) -> 0 | W23: 0 | X23: 0 | Y23: 0 | Z23: =SUM(F23-SUM(W23:Y23)) -> -15794 | AA23: 0 | AB23: 0 | AC23: 0 | AD23: =SUM(G23-SUM(AA23:AC23)) -> -17259 | AE23: 0 | AF23: 0 | AG23: 0 | AH23: =SUM(H23-SUM(AE23:AG23)) -> 631 | AI23: 0 | AJ23: 0 | AK23: 0 | AL23: =SUM(I23-SUM(AI23:AK23)) -> 0 | AM23: 0 | AN23: 0 | AP23: =SUM(AA23:AD23) -> -17259 | AQ23: =SUM(AB23:AE23) -> -17259 | AR23: =SUM(AC23:AF23) -> -17259 | AS23: =SUM(AD23:AG23) -> -17259 | AT23: =SUM(AE23:AH23) -> 631 | AU23: =SUM(AF23:AI23) -> 631 | AV23: =SUM(AG23:AJ23) -> 631 | AW23: =SUM(AH23:AK23) -> 631 | ... AZ23: =SUM(AK23:AN23) -> 0 | BB23: =SUM(AZ23/AV23)-1 -> -1
B24: Interest Expense | C24: 352 | D24: -3071 | E24: -2576 | F24: -3648 | G24: -3966 | H24: -3955 | I24: -4097 | K24: -70 | L24: 38 | M24: -31 | N24: =SUM(C24-SUM(K24:M24)) -> 415 | O24: 141 | P24: 898 | Q24: 0 | R24: =SUM(D24-SUM(O24:Q24)) -> -4110 | S24: -705 | T24: -569 | U24: -689 | V24: =SUM(E24-SUM(S24:U24)) -> -613 | W24: -629 | X24: -1022 | Y24: -1005 | Z24: =SUM(F24-SUM(W24:Y24)) -> -992 | AA24: -1025 | AB24: -1108 | AC24: -1040 | AD24: =SUM(G24-SUM(AA24:AC24)) -> -793 | AE24: -989 | AF24: -989 | AG24: -989 | AH24: =SUM(H24-SUM(AE24:AG24)) -> -988 | AI24: -1015 | AJ24: -1029 | AK24: -1028 | AL24: =SUM(I24-SUM(AI24:AK24)) -> -1025 | AM24: -1024 | AN24: -2002 | AP24: =SUM(AA24:AD24) -> -3966 | AQ24: =SUM(AB24:AE24) -> -3930 | AR24: =SUM(AC24:AF24) -> -3811 | AS24: =SUM(AD24:AG24) -> -3760 | AT24: =SUM(AE24:AH24) -> -3955 | AU24: =SUM(AF24:AI24) -> -3981 | AV24: =SUM(AG24:AJ24) -> -4021 | AW24: =SUM(AH24:AK24) -> -4060 | ... AZ24: =SUM(AK24:AN24) -> -5079 | BB24: =SUM(AZ24/AV24)-1 -> 0.26311863
B25: Other, Net | C25: -1120 | D25: 3629 | E25: -759 | F25: -487 | G25: -420 | H25: 11616 | I25: -10 | K25: 0 | L25: 0 | M25: 0 | N25: =SUM(C25-SUM(K25:M25)) -> -1120 | O25: 0 | P25: 0 | Q25: 1385 | R25: =SUM(D25-SUM(O25:Q25)) -> 2244 | S25: 0 | T25: 0 | U25: 0 | V25: =SUM(E25-SUM(S25:U25)) -> -759 | W25: 0 | X25: 0 | Y25: 0 | Z25: =SUM(F25-SUM(W25:Y25)) -> -487 | AA25: 0 | AB25: 0 | AC25: 0 | AD25: =SUM(G25-SUM(AA25:AC25)) -> -420 | AE25: 0 | AF25: 0 | AG25: 0 | AH25: =SUM(H25-SUM(AE25:AG25)) -> 11616 | AI25: 0 | AJ25: 0 | AK25: 0 | AL25: =SUM(I25-SUM(AI25:AK25)) -> -10 | AM25: 0 | AN25: 0 | AP25: =SUM(AA25:AD25) -> -420 | AQ25: =SUM(AB25:AE25) -> -420 | AR25: =SUM(AC25:AF25) -> -420 | AS25: =SUM(AD25:AG25) -> -420 | AT25: =SUM(AE25:AH25) -> 11616 | AU25: =SUM(AF25:AI25) -> 11616 | AV25: =SUM(AG25:AJ25) -> 11616 | AW25: =SUM(AH25:AK25) -> 11616 | ... AZ25: =SUM(AK25:AN25) -> -10 | BB25: =SUM(AZ25/AV25)-1 -> -1.0008609
B26: Remeasurement of Warrant Liability | C26: 0 | D26: -12503 | E26: 0 | F26: 0 | G26: 0 | H26: 0 | I26: 0 | K26: 0 | L26: -130 | M26: -994 | N26: =SUM(C26-SUM(K26:M26)) -> 1124 | O26: -759 | P26: -11744 | Q26: 0 | R26: =SUM(D26-SUM(O26:Q26)) -> 0 | S26: 710 | T26: -1454 | U26: -85 | V26: =SUM(E26-SUM(S26:U26)) -> 829 | W26: -1570 | X26: 180 | Y26: 759 | Z26: =SUM(F26-SUM(W26:Y26)) -> 631 | AA26: -1124 | AB26: -4902 | AC26: -2151 | AD26: =SUM(G26-SUM(AA26:AC26)) -> 8177 | AE26: 2908 | AF26: 1746 | AG26: 243 | AH26: =SUM(H26-SUM(AE26:AG26)) -> -4897 | AI26: 123 | AJ26: 477 | AK26: 5405 | AL26: =SUM(I26-SUM(AI26:AK26)) -> -6005 | AM26: 4318 | AN26: 7731 | AP26: =SUM(AA26:AD26) -> 0 | AQ26: =SUM(AB26:AE26) -> 4032 | AR26: =SUM(AC26:AF26) -> 10680 | AS26: =SUM(AD26:AG26) -> 13074 | AT26: =SUM(AE26:AH26) -> 0 | AU26: =SUM(AF26:AI26) -> -2785 | AV26: =SUM(AG26:AJ26) -> -4054 | AW26: =SUM(AH26:AK26) -> 1108 | ... AZ26: =SUM(AK26:AN26) -> 11449 | BB26: =SUM(AZ26/AV26)-1 -> -3.8241243
B27: Equity in Losses of Unconsolidated Joint Venture | C27: 0 | D27: 0 | E27: 0 | F27: -2977 | G27: -18948 | H27: -3902 | I27: -73 | K27: 0 | L27: 0 | M27: 0 | N27: NA | O27: 0 | P27: 0 | Q27: 0 | R27: NA | S27: 0 | T27: 0 | U27: 0 | V27: NA | W27: -374 | X27: -207 | Y27: -595 | Z27: -1801 | AA27: -671 | AB27: -1432 | AC27: -8746 | AD27: -8099 | AE27: -3235 | AF27: -503 | AG27: -126 | AH27: -38 | AI27: 7 | AJ27: -30 | AK27: -38 | AL27: -12 | AM27: 0 | AN27: -59 | AP27: =SUM(AA27:AD27) -> -18948 | AQ27: =SUM(AB27:AE27) -> -21512 | AR27: =SUM(AC27:AF27) -> -20583 | AS27: =SUM(AD27:AG27) -> -11963 | AT27: =SUM(AE27:AH27) -> -3902 | AU27: =SUM(AF27:AI27) -> -660 | AV27: =SUM(AG27:AJ27) -> -187 | AW27: =SUM(AH27:AK27) -> -99 | ... AZ27: =SUM(AK27:AN27) -> -109
B28: Earning Before Taxes | C28: =SUM(C19+SUM(C22:C27)) -> -29885 | D28: =SUM(D19+SUM(D22:D27)) -> -12434 | E28: =SUM(E19+SUM(E22:E27)) -> -52680 | F28: =SUM(F19+SUM(F22:F27)) -> -182045 | G28: =SUM(G19+SUM(G22:G27)) -> -366105 | H28: =SUM(H19+SUM(H22:H27)) -> -338139 | I28: =SUM(I19+SUM(I22:I27)) -> -160304 | K28: =SUM(K19+SUM(K22:K27)) -> -5696 | L28: =SUM(L19+SUM(L22:L27)) -> -7396 | M28: =SUM(M19+SUM(M22:M27)) -> -9342 | N28: =SUM(N19+SUM(N22:N27)) -> -7451 | O28: =SUM(O19+SUM(O22:O27)) -> -6649 | P28: =SUM(P19+SUM(P22:P27)) -> -9420 | Q28: =SUM(Q19+SUM(Q22:Q27)) -> 4099 | R28: =SUM(R19+SUM(R22:R27)) -> -464 | ... AN28: =SUM(AN19+SUM(AN22:AN27)) -> -29242 | AP28: =SUM(AP19+SUM(AP22:AP27)) -> -366105 | AQ28: =SUM(AQ19+SUM(AQ22:AQ27)) -> -324694 | AR28: =SUM(AR19+SUM(AR22:AR27)) -> -281071 | AS28: =SUM(AS19+SUM(AS22:AS27)) -> -249885 | AT28: =SUM(AT19+SUM(AT22:AT27)) -> -338139 | AU28: =SUM(AU19+SUM(AU22:AU27)) -> -333461 | AV28: =SUM(AV19+SUM(AV22:AV27)) -> -314474 | AW28: =SUM(AW19+SUM(AW22:AW27)) -> -270552 | ... AZ28: =SUM(AZ19+SUM(AZ22:AZ27)) -> -153579 | BB28: =SUM(AZ28/AV28)-1 -> -0.51163212
B29: EBT Margin (%) | C29: =C28/C11 -> -0.33985717 | D29: =D28/D11 -> -0.041739259 | E29: =E28/E11 -> -0.1295033 | F29: =F28/F11 -> -0.39174736 | G29: =G28/G11 -> -0.87389869 | H29: =H28/H11 -> -0.9847485 | I29: =I28/I11 -> -0.49104922 | K29: =K28/K11 -> -0.44583594 | L29: =L28/L11 -> -0.42586515 | M29: =M28/M11 -> -0.35552004 | N29: =N28/N11 -> -0.2364346 | O29: =O28/O11 -> -0.16537333 | P29: =P28/P11 -> -0.14007227 | Q29: =Q28/Q11 -> 0.044573243 | R29: =R28/R11 -> -0.0047116644 | ... AN29: =AN28/AN11 -> -0.3901118 | AP29: =AP28/AP11 -> -0.87389869 | AQ29: =AQ28/AQ11 -> -0.80827156 | AR29: =AR28/AR11 -> -0.78770427 | AS29: =AS28/AS11 -> -0.71470248 | AT29: =AT28/AT11 -> -0.9847485 | AU29: =AU28/AU11 -> -1.0205605 | AV29: =AV28/AV11 -> -0.98959969 | AW29: =AW28/AW11 -> -0.83639747 | ... AZ29: =AZ28/AZ11 -> -0.50963156 | BB29: =SUM(AZ29-AV29)*1000 -> 479.96813
B31: Provision for taxes | C31: -1 | D31: -9 | E31: -72 | F31: -60 | G31: -32 | H31: -5 | I31: 26 | K31: 0 | L31: 0 | M31: 0 | N31: =SUM(C31-SUM(K31:M31)) -> -1 | O31: 0 | P31: -21 | Q31: 0 | R31: =SUM(D31-SUM(O31:Q31)) -> 12 | S31: 1 | T31: -16 | U31: -55 | V31: =SUM(E31-SUM(S31:U31)) -> -2 | W31: -48 | X31: -2 | Y31: 23 | Z31: =SUM(F31-SUM(W31:Y31)) -> -33 | AA31: -10 | AB31: -11 | AC31: 0 | AD31: =SUM(G31-SUM(AA31:AC31)) -> -11 | AE31: 0 | AF31: -5 | AG31: 0 | AH31: =SUM(H31-SUM(AE31:AG31)) -> 0 | AI31: -2 | AJ31: 34 | AK31: -6 | AL31: =SUM(I31-SUM(AI31:AK31)) -> 0 | AM31: 0 | AN31: 0 | AP31: =SUM(AA31:AD31) -> -32 | AQ31: =SUM(AB31:AE31) -> -22 | AR31: =SUM(AC31:AF31) -> -16 | AS31: =SUM(AD31:AG31) -> -16 | AT31: =SUM(AE31:AH31) -> -5 | AU31: =SUM(AF31:AI31) -> -7 | AV31: =SUM(AG31:AJ31) -> 32 | AW31: =SUM(AH31:AK31) -> 26 | ... AZ31: =SUM(AK31:AN31) -> -6 | BB31: =SUM(AZ31/AV31)-1 -> -1.1875
B32: Net loss | C32: =SUM(C28+C31) -> -29886 | D32: =SUM(D28+D31) -> -12443 | E32: =SUM(E28+E31) -> -52752 | F32: =SUM(F28+F31) -> -182105 | G32: =SUM(G28+G31) -> -366137 | H32: =SUM(H28+H31) -> -338144 | I32: =SUM(I28+I31) -> -160278 | K32: =SUM(K28+K31) -> -5696 | L32: =SUM(L28+L31) -> -7396 | M32: =SUM(M28+M31) -> -9342 | N32: =SUM(N28+N31) -> -7452 | O32: =SUM(O28+O31) -> -6649 | P32: =SUM(P28+P31) -> -9441 | Q32: =SUM(Q28+Q31) -> 4099 | R32: =SUM(R28+R31) -> -452 | ... AN32: =SUM(AN28+AN31) -> -29242 | AP32: =SUM(AP28+AP31) -> -366137 | AQ32: =SUM(AQ28+AQ31) -> -324716 | AR32: =SUM(AR28+AR31) -> -281087 | AS32: =SUM(AS28+AS31) -> -249901 | AT32: =SUM(AT28+AT31) -> -338144 | AU32: =SUM(AU28+AU31) -> -333468 | AV32: =SUM(AV28+AV31) -> -314442 | AW32: =SUM(AW28+AW31) -> -270526 | ... AZ32: =SUM(AZ28+AZ31) -> -153585 | BB32: =SUM(AZ32/AV32)-1 -> -0.51156334
B33: Net Margin (%) | C33: =C32/C11 -> -0.33986854 | D33: =D32/D11 -> -0.041769471 | E33: =E32/E11 -> -0.1296803 | F33: =F32/F11 -> -0.39187648 | G33: =G32/G11 -> -0.87397507 | H33: =H32/H11 -> -0.98476306 | I33: =I32/I11 -> -0.49096958 | K33: =K32/K11 -> -0.44583594 | L33: =L32/L11 -> -0.42586515 | M33: =M32/M11 -> -0.35552004 | N33: =N32/N11 -> -0.23646633 | O33: =O32/O11 -> -0.16537333 | P33: =P32/P11 -> -0.14038453 | Q33: =Q32/Q11 -> 0.044573243 | R33: =R32/R11 -> -0.004589811 | ... AN33: =AN32/AN11 -> -0.3901118 | AP33: =AP32/AP11 -> -0.87397507 | AQ33: =AQ32/AQ11 -> -0.80832632 | AR33: =AR32/AR11 -> -0.78774911 | AS33: =AS32/AS11 -> -0.71474824 | AT33: =AT32/AT11 -> -0.98476306 | AU33: =AU32/AU11 -> -1.0205819 | AV33: =AV32/AV11 -> -0.98949899 | AW33: =AW32/AW11 -> -0.8363171 | ... AZ33: =AZ32/AZ11 -> -0.50965147 | BB33: =SUM(AZ33-AV33)*1000 -> 479.84752
B35: Basic shares | N35: =D35 -> 0 | R35: =H35 -> 0 | V35: =L35 -> 0 | Z35: =P35 -> 0 | AD35: =T35 -> 0 | AH35: =X35 -> 0 | AL35: =AB35 -> 0 | AP35: =AD35 -> 0 | AQ35: =AE35 -> 0 | AR35: =AF35 -> 0 | AS35: =AG35 -> 0 | AT35: =AH35 -> 0 | AU35: =AI35 -> 0 | AV35: =AJ35 -> 0 | AW35: =AK35 -> 0 | ... AZ35: =AN35 -> 0
B36: Basic EPS | C36: =C32/C35 -> #DIV/0! | D36: =D32/D35 -> #DIV/0! | E36: =E32/E35 -> #DIV/0! | F36: =F32/F35 -> #DIV/0! | G36: =G32/G35 -> #DIV/0! | H36: =H32/H35 -> #DIV/0! | I36: =I32/I35 -> #DIV/0! | K36: =K32/K35 -> #DIV/0! | L36: =L32/L35 -> #DIV/0! | M36: =M32/M35 -> #DIV/0! | N36: =N32/N35 -> #DIV/0! | O36: =O32/O35 -> #DIV/0! | P36: =P32/P35 -> #DIV/0! | Q36: =Q32/Q35 -> #DIV/0! | R36: =R32/R35 -> #DIV/0! | ... AN36: =AN32/AN35 -> #DIV/0! | AP36: =AP32/AP35 -> #DIV/0! | AQ36: =AQ32/AQ35 -> #DIV/0! | AR36: =AR32/AR35 -> #DIV/0! | AS36: =AS32/AS35 -> #DIV/0! | AT36: =AT32/AT35 -> #DIV/0! | AU36: =AU32/AU35 -> #DIV/0! | AV36: =AV32/AV35 -> #DIV/0! | AW36: =AW32/AW35 -> #DIV/0! | ... AZ36: =AZ32/AZ35 -> #DIV/0! | BB36: =SUM(AZ36/AV36)-1 -> #DIV/0!
B38: Fully Diluted Shares | C38: 6287.172 | D38: 42274.777 | N38: =D38 -> 42274.777 | R38: =H38 -> 0 | V38: =L38 -> 0 | Z38: =P38 -> 0 | AD38: =T38 -> 0 | AH38: =X38 -> 0 | AL38: =AB38 -> 0 | AP38: =AD38 -> 0 | AQ38: =AE38 -> 0 | AR38: =AF38 -> 0 | AS38: =AG38 -> 0 | AT38: =AH38 -> 0 | AU38: =AI38 -> 0 | AV38: =AJ38 -> 0 | AW38: =AK38 -> 0 | ... AZ38: =AN38 -> 0
B39: Diluted EPS | C39: =C32/C38 -> -4.7534885 | D39: =D32/D38 -> -0.29433627 | E39: =E32/E38 -> #DIV/0! | F39: =F32/F38 -> #DIV/0! | G39: =G32/G38 -> #DIV/0! | H39: =H32/H38 -> #DIV/0! | I39: =I32/I38 -> #DIV/0! | K39: =K32/K38 -> #DIV/0! | L39: =L32/L38 -> #DIV/0! | M39: =M32/M38 -> #DIV/0! | N39: =N32/N38 -> -0.17627532 | O39: =O32/O38 -> #DIV/0! | P39: =P32/P38 -> #DIV/0! | Q39: =Q32/Q38 -> #DIV/0! | R39: =R32/R38 -> #DIV/0! | ... AN39: =AN32/AN38 -> #DIV/0! | AP39: =AP32/AP38 -> #DIV/0! | AQ39: =AQ32/AQ38 -> #DIV/0! | AR39: =AR32/AR38 -> #DIV/0! | AS39: =AS32/AS38 -> #DIV/0! | AT39: =AT32/AT38 -> #DIV/0! | AU39: =AU32/AU38 -> #DIV/0! | AV39: =AV32/AV38 -> #DIV/0! | AW39: =AW32/AW38 -> #DIV/0! | ... AZ39: =AZ32/AZ38 -> #DIV/0! | BB39: =SUM(AZ39/AV39)-1 -> #DIV/0!
A41: X | B41: Balance Sheet | K41: Quarterly | AV41: LTM | BB41: Variance
B42: =B7 -> Fiscal Period | C42: =C7 -> 2018 | D42: =D7 -> 2019 | E42: =E7 -> 2020 | F42: =F7 -> 2021 | G42: =G7 -> 2022 | H42: =H7 -> 2023 | I42: =I7 -> 2024 | K42: =K7 -> 1Q18 | L42: =L7 -> 2Q18 | M42: =M7 -> 3Q18 | N42: =N7 -> 4Q18 | O42: =O7 -> 1Q19 | P42: =P7 -> 2Q19 | Q42: =Q7 -> 3Q19 | R42: =R7 -> 4Q19 | ... AN42: =AN7 -> 2Q25 | AP42: =AP7 -> 4Q22 | AQ42: =AQ7 -> 1Q23 | AR42: =AR7 -> 2Q23 | AS42: =AS7 -> 3Q23 | AT42: =AT7 -> 4Q23 | AU42: =AU7 -> 1Q24 | AV42: =AV7 -> 2Q24 | AW42: =AW7 -> 3Q24 | ... AZ42: =AZ7 -> 2Q25
B43: =B8 -> Fiscal Period End Date | C43: =C8 -> 43465 | D43: =D8 -> 43830 | E43: =E8 -> 44196 | F43: =F8 -> 44561 | G43: =G8 -> 44926 | H43: =H8 -> 45291 | I43: =I8 -> 45657 | K43: =K8 -> 43190 | L43: =L8 -> 43281 | M43: =M8 -> 43372 | N43: =N8 -> 43465 | O43: =O8 -> 43554 | P43: =P8 -> 43645 | Q43: =Q8 -> 43736 | R43: =R8 -> 43830 | ... AN43: =AN8 -> 45836 | AP43: =AP8 -> 44926 | AQ43: =AQ8 -> 45017 | AR43: =AR8 -> 45108 | AS43: =AS8 -> 45199 | AT43: =AT8 -> 45291 | AU43: =AU8 -> 45381 | AV43: =AV8 -> 45472 | AW43: =AW8 -> 45563 | ... AZ43: =AZ8 -> 45836
B45: Current Assets
B46: Cash and Cash Equivalents | C46: 54271 | D46: 275988 | E46: 159127 | F46: 733294 | G46: 309922 | H46: 190505 | I46: 131913 | K46: 29047 | L46: 23489 | M46: 49780 | N46: =C46 -> 54271 | O46: 35409 | P46: 276987 | Q46: 312451 | R46: =D46 -> 275988 | S46: 246410 | T46: 222334 | U46: 214615 | V46: =E46 -> 159127 | W46: 1125017 | X46: 1009337 | Y46: 886442 | Z46: =F46 -> 733294 | AA46: 547858 | AB46: 454674 | AC46: 390176 | AD46: =G46 -> 309922 | AE46: 258566 | AF46: 210781 | AG46: 217545 | AH46: =H46 -> 190505 | AI46: 157913 | AJ46: 144873 | AK46: 121732 | AL46: =I46 -> 131913 | AM46: 102143 | AN46: 103497 | AP46: =AD46 -> 309922 | AQ46: =AE46 -> 258566 | AR46: =AF46 -> 210781 | AS46: =AG46 -> 217545 | AT46: =AH46 -> 190505 | AU46: =AI46 -> 157913 | AV46: =AJ46 -> 144873 | AW46: =AK46 -> 121732 | ... AZ46: =AN46 -> 103497 | BB46: =SUM(AZ46/AV46)-1 -> -0.28560187
B47: Restricted Cash | C47: 0 | D47: 0 | E47: 0 | F47: 0 | G47: 0 | H47: 2830 | I47: 1041 | N47: =C47 -> 0 | O47: 0 | P47: 0 | Q47: 0 | R47: =D47 -> 0 | S47: 0 | T47: 0 | U47: 0 | V47: =E47 -> 0 | W47: 0 | X47: 0 | Y47: 0 | Z47: =F47 -> 0 | AA47: 0 | AB47: 0 | AC47: 0 | AD47: =G47 -> 0 | AE47: 2426 | AF47: 2552 | AG47: 2689 | AH47: =H47 -> 2830 | AI47: 2971 | AJ47: 536 | AK47: 558 | AL47: =I47 -> 1041 | AM47: 1083 | AN47: 1172 | AP47: =AD47 -> 0 | AQ47: =AE47 -> 2426 | AR47: =AF47 -> 2552 | AS47: =AG47 -> 2689 | AT47: =AH47 -> 2830 | AU47: =AI47 -> 2971 | AV47: =AJ47 -> 536 | AW47: =AK47 -> 558 | ... AZ47: =AN47 -> 1172
B48: Accounts Receivables | C48: 12626 | D48: 40080 | E48: 35975 | F48: 43806 | G48: 34198 | H48: 31730 | I48: 26862 | N48: =C48 -> 12626 | O48: 16194 | P48: 34388 | Q48: 34482 | R48: =D48 -> 40080 | S48: 36333 | T48: 45986 | U48: 29760 | V48: =E48 -> 35975 | W48: 36653 | X48: 63369 | Y48: 48849 | Z48: =F48 -> 43806 | AA48: 52675 | AB48: 77154 | AC48: 34949 | AD48: =G48 -> 34198 | AE48: 42395 | AF48: 50821 | AG48: 35763 | AH48: =H48 -> 31730 | AI48: 35648 | AJ48: 34463 | AK48: 34674 | AL48: =I48 -> 26862 | AM48: 33267 | AN48: 37338 | AP48: =AD48 -> 34198 | AQ48: =AE48 -> 42395 | AR48: =AF48 -> 50821 | AS48: =AG48 -> 35763 | AT48: =AH48 -> 31730 | AU48: =AI48 -> 35648 | AV48: =AJ48 -> 34463 | AW48: =AK48 -> 34674 | ... AZ48: =AN48 -> 37338 | BB48: =SUM(AZ48/AV48)-1 -> 0.083422801
B49: Inventory | C49: 30257 | D49: 81596 | E49: 121717 | F49: 241870 | G49: 235696 | H49: 130336 | I49: 113444 | N49: =C49 -> 30257 | O49: 34281 | P49: 42695 | Q49: 60270 | R49: =D49 -> 81596 | S49: 120702 | T49: 143033 | U49: 132359 | V49: =E49 -> 121717 | W49: 145524 | X49: 165746 | Y49: 193490 | Z49: =F49 -> 241870 | AA49: 283754 | AB49: 254653 | AC49: 246987 | AD49: =G49 -> 235696 | AE49: 222370 | AF49: 207138 | AG49: 194570 | AH49: =H49 -> 130336 | AI49: 122538 | AJ49: 119532 | AK49: 125158 | AL49: =I49 -> 113444 | AM49: 100068 | AN49: 110868 | AP49: =AD49 -> 235696 | AQ49: =AE49 -> 222370 | AR49: =AF49 -> 207138 | AS49: =AG49 -> 194570 | AT49: =AH49 -> 130336 | AU49: =AI49 -> 122538 | AV49: =AJ49 -> 119532 | AW49: =AK49 -> 125158 | ... AZ49: =AN49 -> 110868
B50: Prepaid Expenses and Other Current Assets (1) | C50: 5672 | D50: 5930 | E50: 15407 | F50: 33078 | G50: =20700+5943 -> 26643 | H50: =12904+4539 -> 17443 | I50: =11332+1864 -> 13196 | N50: =C50 -> 5672 | O50: 6525 | P50: 7726 | Q50: 11742 | R50: =D50 -> 5930 | S50: 12498 | T50: 17990 | U50: 14195 | V50: =E50 -> 15407 | W50: 17788 | X50: 25630 | Y50: 24341 | Z50: =F50 -> 33078 | AA50: 33010 | AB50: 33029 | AC50: 23868 | AD50: =G50 -> 26643 | AE50: =16561+4737 -> 21298 | AF50: =26051+98 -> 26149 | AG50: =20938+118 -> 21056 | AH50: =H50 -> 17443 | AI50: =15032+2401 -> 17433 | AJ50: =15538+2323 -> 17861 | AK50: =13016+2275 -> 15291 | AL50: =I50 -> 13196 | AM50: =19135+1576 -> 20711 | AN50: =42596+1664 -> 44260 | AP50: =AD50 -> 26643 | AQ50: =AE50 -> 21298 | AR50: =AF50 -> 26149 | AS50: =AG50 -> 21056 | AT50: =AH50 -> 17443 | AU50: =AI50 -> 17433 | AV50: =AJ50 -> 17861 | AW50: =AK50 -> 15291 | ... AZ50: =AN50 -> 44260
B51: Total Current Assets | C51: =SUM(C46:C50) -> 102826 | D51: =SUM(D46:D50) -> 403594 | E51: =SUM(E46:E50) -> 332226 | F51: =SUM(F46:F50) -> 1052048 | G51: =SUM(G46:G50) -> 606459 | H51: =SUM(H46:H50) -> 372844 | I51: =SUM(I46:I50) -> 286456 | K51: =SUM(K46:K50) -> 29047 | L51: =SUM(L46:L50) -> 23489 | M51: =SUM(M46:M50) -> 49780 | N51: =SUM(N46:N50) -> 102826 | O51: =SUM(O46:O50) -> 92409 | P51: =SUM(P46:P50) -> 361796 | Q51: =SUM(Q46:Q50) -> 418945 | R51: =SUM(R46:R50) -> 403594 | ... AN51: =SUM(AN46:AN50) -> 297135 | AP51: =SUM(AP46:AP50) -> 606459 | AQ51: =SUM(AQ46:AQ50) -> 547055 | AR51: =SUM(AR46:AR50) -> 497441 | AS51: =SUM(AS46:AS50) -> 471623 | AT51: =SUM(AT46:AT50) -> 372844 | AU51: =SUM(AU46:AU50) -> 336503 | AV51: =SUM(AV46:AV50) -> 317265 | AW51: =SUM(AW46:AW50) -> 297413 | ... AZ51: =SUM(AZ46:AZ50) -> 297135 | BB51: =SUM(AZ51/AV51)-1 -> -0.063448537
...

Sheet Revenue Drivers
B2: Beyond Meat, Inc. (NASDAQ: BYND) | C2: FYE | K2: Quarterly | S2: Quarterly | T2: Quarterly | Z2: LTM | AD2: LTM | AL2: Variance
B3: Segment Anaysis | C3: ='Historical Financials'!C7 -> 2018 | D3: ='Historical Financials'!D7 -> 2019 | E3: ='Historical Financials'!E7 -> 2020 | F3: ='Historical Financials'!F7 -> 2021 | G3: ='Historical Financials'!G7 -> 2022 | H3: ='Historical Financials'!H7 -> 2023 | I3: ='Historical Financials'!I7 -> 2024 | K3: 1Q22 | L3: 2Q22 | M3: 3Q22 | N3: 4Q22 | O3: 1Q23 | P3: 2Q23 | Q3: 3Q23 | R3: 4Q23 | S3: 1Q24 | T3: 2Q24 | U3: 3Q24 | V3: 4Q24 | W3: 1Q25 | X3: 2Q25 | Z3: 1Q23 | AA3: 2Q23 | AB3: 3Q23 | AC3: 4Q23 | AD3: 1Q24 | AE3: 2Q24 | AF3: 3Q24 | AG3: 4Q24 | AH3: 1Q25 | AI3: 2Q25 | AJ3: 3Q25
B4: $ mm except per share | C4: ='Historical Financials'!C8 -> 43465 | D4: ='Historical Financials'!D8 -> 43830 | E4: ='Historical Financials'!E8 -> 44196 | F4: ='Historical Financials'!F8 -> 44561 | G4: ='Historical Financials'!G8 -> 44926 | H4: ='Historical Financials'!H8 -> 45291 | I4: ='Historical Financials'!I8 -> 45657 | K4: 44653 | L4: 44744 | M4: 44835 | N4: 44926 | O4: 45017 | P4: 45108 | Q4: 45199 | R4: 45291 | S4: 45381 | T4: 45472 | U4: 45563 | V4: 45657 | W4: 45745 | X4: 45836 | Z4: 44917 | AA4: 45008 | AB4: 45100 | AC4: 45192 | AD4: 45283 | AE4: 45375 | AF4: 45467 | AG4: 45559 | AH4: 45650 | AI4: 45741 | AJ4: 45833
A6: X | B6: Net Revenues by Channel
B7: Retail | C7: =+C13+C18 -> 50779 | D7: =+D13+D18 -> 144809 | E7: =+E13+E18 -> 300583 | F7: =+F13+F18 -> 324843 | G7: =+G13+G18 -> 295651 | H7: =+H13+H18 -> 216963 | I7: =+I13+I18 -> 210595 | K7: =+K13+K18 -> 84397 | L7: =+L13+L18 -> 102553 | M7: =+M13+M18 -> 56372 | N7: =+N13+N18 -> 52329 | O7: =+O13+O18 -> 58448 | P7: =+P13+P18 -> 68485 | Q7: =+Q13+Q18 -> 44671 | R7: =+R13+R18 -> 45359 | ... X7: =+X13+X18 -> 48776 | Z7: =SUM(L7:O7) -> 269702 | AA7: =SUM(M7:P7) -> 235634 | AB7: =SUM(N7:Q7) -> 223933 | AC7: =SUM(O7:R7) -> 216963 | AD7: =SUM(P7:S7) -> 208181 | AE7: =SUM(Q7:T7) -> 202150 | AF7: =SUM(R7:U7) -> 209013 | AG7: =SUM(S7:V7) -> 210595 | ... AI7: =SUM(U7:X7) -> 191293 | AJ7: =SUM(V7:X7) -> 139759 | AL7: =SUM(AJ7/AF7)-1 -> -0.33133824
B8: Foodservice | C8: =+C14+C19 -> 37155 | D8: =+D14+D19 -> 153088 | E8: =+E14+E19 -> 106202 | F8: =+F14+F19 -> 139857 | G8: =+G14+G19 -> 123282 | H8: =+H14+H19 -> 126413 | I8: =+I14+I19 -> 115857 | K8: =+K14+K19 -> 25058 | L8: =+L14+L19 -> 44487 | M8: =+M14+M19 -> 26128 | N8: =+N14+N19 -> 27609 | O8: =+O14+O19 -> 33788 | P8: =+P14+P19 -> 33664 | Q8: =+Q14+Q19 -> 30641 | R8: =+R14+R19 -> 28320 | ... X8: =+X14+X19 -> 26182 | Z8: =SUM(L8:O8) -> 132012 | AA8: =SUM(M8:P8) -> 121189 | AB8: =SUM(N8:Q8) -> 125702 | AC8: =SUM(O8:R8) -> 126413 | AD8: =SUM(P8:S8) -> 118562 | AE8: =SUM(Q8:T8) -> 115629 | AF8: =SUM(R8:U8) -> 114460 | AG8: =SUM(S8:V8) -> 115857 | ... AI8: =SUM(U8:X8) -> 110060 | AJ8: =SUM(V8:X8) -> 80588 | AL8: =SUM(AJ8/AF8)-1 -> -0.29592871
B9: Total Net Revenue | C9: =SUM(C7:C8) -> 87934 | D9: =SUM(D7:D8) -> 297897 | E9: =SUM(E7:E8) -> 406785 | F9: =SUM(F7:F8) -> 464700 | G9: =SUM(G7:G8) -> 418933 | H9: =SUM(H7:H8) -> 343376 | I9: =SUM(I7:I8) -> 326452 | K9: =SUM(K7:K8) -> 109455 | L9: =SUM(L7:L8) -> 147040 | M9: =SUM(M7:M8) -> 82500 | N9: =SUM(N7:N8) -> 79938 | O9: =SUM(O7:O8) -> 92236 | P9: =SUM(P7:P8) -> 102149 | Q9: =SUM(Q7:Q8) -> 75312 | R9: =SUM(R7:R8) -> 73679 | ... X9: =SUM(X7:X8) -> 74958 | Z9: =SUM(Z7:Z8) -> 401714 | AA9: =SUM(AA7:AA8) -> 356823 | AB9: =SUM(AB7:AB8) -> 349635 | AC9: =SUM(AC7:AC8) -> 343376 | AD9: =SUM(AD7:AD8) -> 326743 | AE9: =SUM(AE7:AE8) -> 317779 | AF9: =SUM(AF7:AF8) -> 323473 | AG9: =SUM(AG7:AG8) -> 326452 | ... AJ9: =SUM(AJ7:AJ8) -> 220347 | AL9: =SUM(AJ9/AF9)-1 -> -0.31880868
B10: Balance Check | C10: =+C9-'Historical Financials'!C11 -> 0 | D10: =+D9-'Historical Financials'!D11 -> 0 | E10: =+E9-'Historical Financials'!E11 -> 0 | F10: =+F9-'Historical Financials'!F11 -> 0 | G10: =+G9-'Historical Financials'!G11 -> 0 | H10: =+H9-'Historical Financials'!H11 -> 0 | I10: =+I9-'Historical Financials'!I11 -> 0 | K10: =K9-'Historical Financials'!AA11 -> 0 | L10: =L9-'Historical Financials'!AB11 -> 0 | M10: =M9-'Historical Financials'!AC11 -> 0 | N10: =N9-'Historical Financials'!AD11 -> 0 | O10: =O9-'Historical Financials'!AE11 -> 0 | P10: =P9-'Historical Financials'!AF11 -> 0 | Q10: =Q9-'Historical Financials'!AG11 -> 0 | R10: =R9-'Historical Financials'!AH11 -> 0 | ... X10: =X9-'Historical Financials'!AN11 -> 0 | Z10: =Z9-'Historical Financials'!AP11 -> -17219 | AA10: =AA9-'Historical Financials'!AQ11 -> -44891 | AB10: =AB9-'Historical Financials'!AR11 -> -7188 | AC10: =AC9-'Historical Financials'!AS11 -> -6259 | AD10: =AD9-'Historical Financials'!AT11 -> -16633 | AE10: =AE9-'Historical Financials'!AU11 -> -8964 | AF10: =AF9-'Historical Financials'!AV11 -> 5694 | AG10: =AG9-'Historical Financials'!AW11 -> 2979 | ... AJ10: =AJ9-'Historical Financials'!AZ11 -> -81006
A12: X | B12: Revenue by Channel: U.S
B13: Retail | C13: 49772 | D13: 129383 | E13: 264111 | F13: 243360 | G13: 234744 | H13: 155240 | I13: 150812 | K13: 68260 | L13: 78861 | M13: 46177 | N13: =SUM(G13-SUM(K13:M13)) -> 41446 | O13: 44159 | P13: 48490 | Q13: 30518 | R13: =SUM(H13-SUM(O13:Q13)) -> 32073 | S13: 37088 | T13: 44869 | U13: 34969 | V13: =SUM(I13-SUM(S13:U13)) -> 33886 | W13: 31360 | X13: 32909 | Z13: =SUM(L13:O13) -> 210643 | AA13: =SUM(M13:P13) -> 180272 | AB13: =SUM(N13:Q13) -> 164613 | AC13: =SUM(O13:R13) -> 155240 | AD13: =SUM(P13:S13) -> 148169 | AE13: =SUM(Q13:T13) -> 144548 | AF13: =SUM(R13:U13) -> 148999 | AG13: =SUM(S13:V13) -> 150812 | ... AI13: =SUM(U13:X13) -> 133124 | AJ13: =SUM(V13:X13) -> 98155 | AL13: =SUM(AJ13/AF13)-1 -> -0.34123719
B14: Foodservice | C14: 20717 | D14: 70372 | E14: 60763 | F14: 76475 | G14: 69289 | H14: 50647 | I14: 47584 | K14: 15493 | L14: 23389 | M14: 15994 | N14: =SUM(G14-SUM(K14:M14)) -> 14413 | O14: 14675 | P14: 12764 | Q14: 12535 | R14: =SUM(H14-SUM(O14:Q14)) -> 10673 | S14: 12304 | T14: 10350 | U14: 14478 | V14: =SUM(I14-SUM(S14:U14)) -> 10452 | W14: 9413 | X14: 11055 | Z14: =SUM(L14:O14) -> 68471 | AA14: =SUM(M14:P14) -> 57846 | AB14: =SUM(N14:Q14) -> 54387 | AC14: =SUM(O14:R14) -> 50647 | AD14: =SUM(P14:S14) -> 48276 | AE14: =SUM(Q14:T14) -> 45862 | AF14: =SUM(R14:U14) -> 47805 | AG14: =SUM(S14:V14) -> 47584 | ... AI14: =SUM(U14:X14) -> 45398 | AJ14: =SUM(V14:X14) -> 30920 | AL14: =SUM(AJ14/AF14)-1 -> -0.35320573
B15: Total Net U.S Revenue | C15: =SUM(C13:C14) -> 70489 | D15: =SUM(D13:D14) -> 199755 | E15: =SUM(E13:E14) -> 324874 | F15: =SUM(F13:F14) -> 319835 | G15: =SUM(G13:G14) -> 304033 | H15: =SUM(H13:H14) -> 205887 | I15: =SUM(I13:I14) -> 198396 | K15: =SUM(K13:K14) -> 83753 | L15: =SUM(L13:L14) -> 102250 | M15: =SUM(M13:M14) -> 62171 | N15: =SUM(N13:N14) -> 55859 | O15: =SUM(O13:O14) -> 58834 | P15: =SUM(P13:P14) -> 61254 | Q15: =SUM(Q13:Q14) -> 43053 | R15: =SUM(R13:R14) -> 42746 | ... X15: =SUM(X13:X14) -> 43964 | Z15: =SUM(Z13:Z14) -> 279114 | AA15: =SUM(AA13:AA14) -> 238118 | AB15: =SUM(AB13:AB14) -> 219000 | AC15: =SUM(AC13:AC14) -> 205887 | AD15: =SUM(AD13:AD14) -> 196445 | AE15: =SUM(AE13:AE14) -> 190410 | AF15: =SUM(AF13:AF14) -> 196804 | AG15: =SUM(AG13:AG14) -> 198396 | ... AJ15: =SUM(AJ13:AJ14) -> 129075 | AL15: =SUM(AJ15/AF15)-1 -> -0.34414443
A17: X | B17: Revenue by Channel: International
B18: Retail | C18: 1007 | D18: 15426 | E18: 36472 | F18: 81483 | G18: 60907 | H18: 61723 | I18: 59783 | K18: 16137 | L18: 23692 | M18: 10195 | N18: =SUM(G18-SUM(K18:M18)) -> 10883 | O18: 14289 | P18: 19995 | Q18: 14153 | R18: =SUM(H18-SUM(O18:Q18)) -> 13286 | S18: 12578 | T18: 17585 | U18: 16565 | V18: =SUM(I18-SUM(S18:U18)) -> 13055 | W18: 12682 | X18: 15867 | Z18: =SUM(L18:O18) -> 59059 | AA18: =SUM(M18:P18) -> 55362 | AB18: =SUM(N18:Q18) -> 59320 | AC18: =SUM(O18:R18) -> 61723 | AD18: =SUM(P18:S18) -> 60012 | AE18: =SUM(Q18:T18) -> 57602 | AF18: =SUM(R18:U18) -> 60014 | AG18: =SUM(S18:V18) -> 59783 | ... AI18: =SUM(U18:X18) -> 58169 | AJ18: =SUM(V18:X18) -> 41604 | AL18: =SUM(AJ18/AF18)-1 -> -0.30676176
B19: Foodservice | C19: 16438 | D19: 82716 | E19: 45439 | F19: 63382 | G19: 53993 | H19: 75766 | I19: 68273 | K19: 9565 | L19: 21098 | M19: 10134 | N19: =SUM(G19-SUM(K19:M19)) -> 13196 | O19: 19113 | P19: 20900 | Q19: 18106 | R19: =SUM(H19-SUM(O19:Q19)) -> 17647 | S19: 13633 | T19: 20381 | U19: 14994 | V19: =SUM(I19-SUM(S19:U19)) -> 19265 | W19: 15276 | X19: 15127 | Z19: =SUM(L19:O19) -> 63541 | AA19: =SUM(M19:P19) -> 63343 | AB19: =SUM(N19:Q19) -> 71315 | AC19: =SUM(O19:R19) -> 75766 | AD19: =SUM(P19:S19) -> 70286 | AE19: =SUM(Q19:T19) -> 69767 | AF19: =SUM(R19:U19) -> 66655 | AG19: =SUM(S19:V19) -> 68273 | ... AI19: =SUM(U19:X19) -> 64662 | AJ19: =SUM(V19:X19) -> 49668 | AL19: =SUM(AJ19/AF19)-1 -> -0.2548496
B20: Total Net International Revenue | C20: =SUM(C18:C19) -> 17445 | D20: =SUM(D18:D19) -> 98142 | E20: =SUM(E18:E19) -> 81911 | F20: =SUM(F18:F19) -> 144865 | G20: =SUM(G18:G19) -> 114900 | H20: =SUM(H18:H19) -> 137489 | I20: =SUM(I18:I19) -> 128056 | K20: =SUM(K18:K19) -> 25702 | L20: =SUM(L18:L19) -> 44790 | M20: =SUM(M18:M19) -> 20329 | N20: =SUM(N18:N19) -> 24079 | O20: =SUM(O18:O19) -> 33402 | P20: =SUM(P18:P19) -> 40895 | Q20: =SUM(Q18:Q19) -> 32259 | R20: =SUM(R18:R19) -> 30933 | ... X20: =SUM(X18:X19) -> 30994 | Z20: =SUM(Z18:Z19) -> 122600 | AA20: =SUM(AA18:AA19) -> 118705 | AB20: =SUM(AB18:AB19) -> 130635 | AC20: =SUM(AC18:AC19) -> 137489 | AD20: =SUM(AD18:AD19) -> 130298 | AE20: =SUM(AE18:AE19) -> 127369 | AF20: =SUM(AF18:AF19) -> 126669 | AG20: =SUM(AG18:AG19) -> 128056 | ... AJ20: =SUM(AJ18:AJ19) -> 91272 | AL20: =SUM(AJ20/AF20)-1 -> -0.27944485

Sheet FCF
B2: Beyond Meat, Inc. (NASDAQ: BYND) | C2: FYE | E2: FYE | I2: Quarterly | Q2: Quarterly | R2: Quarterly | X2: LTM | AE2: LTM | AK2: Variance
B3: FCF Analysis | C3: ='Historical Financials'!E7 -> 2020 | D3: ='Historical Financials'!F7 -> 2021 | E3: ='Historical Financials'!G7 -> 2022 | F3: ='Historical Financials'!H7 -> 2023 | G3: ='Historical Financials'!I7 -> 2024 | I3: ='Historical Financials'!AA7 -> 1Q22 | J3: ='Historical Financials'!AB7 -> 2Q22 | K3: ='Historical Financials'!AC7 -> 3Q22 | L3: ='Historical Financials'!AD7 -> 4Q22 | M3: ='Historical Financials'!AE7 -> 1Q23 | N3: ='Historical Financials'!AF7 -> 2Q23 | O3: ='Historical Financials'!AG7 -> 3Q23 | P3: ='Historical Financials'!AH7 -> 4Q23 | ... V3: ='Historical Financials'!AN7 -> 2Q25 | X3: =K3 -> 3Q22 | Y3: =L3 -> 4Q22 | Z3: =M3 -> 1Q23 | AA3: =N3 -> 2Q23 | AB3: =O3 -> 3Q23 | AC3: =P3 -> 4Q23 | AD3: =Q3 -> 1Q24 | AE3: =R3 -> 2Q24 | ... AI3: =V3 -> 2Q25
B4: $ mm except per share | C4: ='Historical Financials'!E8 -> 44196 | D4: ='Historical Financials'!F8 -> 44561 | E4: ='Historical Financials'!G8 -> 44926 | F4: ='Historical Financials'!H8 -> 45291 | G4: ='Historical Financials'!I8 -> 45657 | I4: ='Historical Financials'!AA8 -> 44653 | J4: ='Historical Financials'!AB8 -> 44744 | K4: ='Historical Financials'!AC8 -> 44835 | L4: ='Historical Financials'!AD8 -> 44926 | M4: ='Historical Financials'!AE8 -> 45017 | N4: ='Historical Financials'!AF8 -> 45108 | O4: ='Historical Financials'!AG8 -> 45199 | P4: ='Historical Financials'!AH8 -> 45291 | ... V4: ='Historical Financials'!AN8 -> 45836 | X4: =K4 -> 44835 | Y4: =L4 -> 44926 | Z4: =M4 -> 45017 | AA4: =N4 -> 45108 | AB4: =O4 -> 45199 | AC4: =P4 -> 45291 | AD4: =Q4 -> 45381 | AE4: =R4 -> 45472 | ... AI4: =V4 -> 45836
B6: ='Revenue Drivers'!B7 -> Retail | C6: ='Revenue Drivers'!E7 -> 300583 | D6: ='Revenue Drivers'!F7 -> 324843 | E6: ='Revenue Drivers'!G7 -> 295651 | F6: ='Revenue Drivers'!H7 -> 216963 | G6: ='Revenue Drivers'!I7 -> 210595 | I6: ='Revenue Drivers'!K7 -> 84397 | J6: ='Revenue Drivers'!L7 -> 102553 | K6: ='Revenue Drivers'!M7 -> 56372 | L6: ='Revenue Drivers'!N7 -> 52329 | M6: ='Revenue Drivers'!O7 -> 58448 | N6: ='Revenue Drivers'!P7 -> 68485 | O6: ='Revenue Drivers'!Q7 -> 44671 | P6: ='Revenue Drivers'!R7 -> 45359 | ... V6: ='Revenue Drivers'!X7 -> 48776 | X6: =SUM(H6:K6) -> 243322 | Y6: =SUM(I6:L6) -> 295651 | Z6: =SUM(J6:M6) -> 269702 | AA6: =SUM(K6:N6) -> 235634 | AB6: =SUM(L6:O6) -> 223933 | AC6: =SUM(M6:P6) -> 216963 | AD6: =SUM(N6:Q6) -> 208181 | AE6: =SUM(O6:R6) -> 202150 | ... AI6: =SUM(S6:V6) -> 191293 | AK6: =SUM(AI6/AE6)-1 -> -0.053707643
B7: ='Revenue Drivers'!B8 -> Foodservice | C7: ='Revenue Drivers'!E8 -> 106202 | D7: ='Revenue Drivers'!F8 -> 139857 | E7: ='Revenue Drivers'!G8 -> 123282 | F7: ='Revenue Drivers'!H8 -> 126413 | G7: ='Revenue Drivers'!I8 -> 115857 | I7: ='Revenue Drivers'!K8 -> 25058 | J7: ='Revenue Drivers'!L8 -> 44487 | K7: ='Revenue Drivers'!M8 -> 26128 | L7: ='Revenue Drivers'!N8 -> 27609 | M7: ='Revenue Drivers'!O8 -> 33788 | N7: ='Revenue Drivers'!P8 -> 33664 | O7: ='Revenue Drivers'!Q8 -> 30641 | P7: ='Revenue Drivers'!R8 -> 28320 | ... V7: ='Revenue Drivers'!X8 -> 26182 | X7: =SUM(H7:K7) -> 95673 | Y7: =SUM(I7:L7) -> 123282 | Z7: =SUM(J7:M7) -> 132012 | AA7: =SUM(K7:N7) -> 121189 | AB7: =SUM(L7:O7) -> 125702 | AC7: =SUM(M7:P7) -> 126413 | AD7: =SUM(N7:Q7) -> 118562 | AE7: =SUM(O7:R7) -> 115629 | ... AI7: =SUM(S7:V7) -> 110060 | AK7: =SUM(AI7/AE7)-1 -> -0.048162658
B8: Total Revenue | C8: =SUM(C6:C7) -> 406785 | D8: =SUM(D6:D7) -> 464700 | E8: =SUM(E6:E7) -> 418933 | F8: =SUM(F6:F7) -> 343376 | G8: =SUM(G6:G7) -> 326452 | I8: =SUM(I6:I7) -> 109455 | J8: =SUM(J6:J7) -> 147040 | K8: =SUM(K6:K7) -> 82500 | L8: =SUM(L6:L7) -> 79938 | M8: =SUM(M6:M7) -> 92236 | N8: =SUM(N6:N7) -> 102149 | O8: =SUM(O6:O7) -> 75312 | P8: =SUM(P6:P7) -> 73679 | ... V8: =SUM(V6:V7) -> 74958 | X8: =SUM(X6:X7) -> 338995 | Y8: =SUM(Y6:Y7) -> 418933 | Z8: =SUM(Z6:Z7) -> 401714 | AA8: =SUM(AA6:AA7) -> 356823 | AB8: =SUM(AB6:AB7) -> 349635 | AC8: =SUM(AC6:AC7) -> 343376 | AD8: =SUM(AD6:AD7) -> 326743 | AE8: =SUM(AE6:AE7) -> 317779 | ... AI8: =SUM(AI6:AI7) -> 301353 | AK8: =SUM(AI8/AE8)-1 -> -0.051690011
B9: Y/Y Growth (%) | D9: =SUM(D8/C8)-1 -> 0.14237251 | E9: =SUM(E8/D8)-1 -> -0.098487196 | F9: =SUM(F8/E8)-1 -> -0.18035581 | G9: =SUM(G8/F8)-1 -> -0.049287079 | M9: =SUM(M8/I8)-1 -> -0.15731579 | N9: =SUM(N8/J8)-1 -> -0.30529788 | O9: =SUM(O8/K8)-1 -> -0.087127273 | P9: =SUM(P8/L8)-1 -> -0.078298181 | Q9: =SUM(Q8/M8)-1 -> -0.18033089 | R9: =SUM(R8/N8)-1 -> -0.087754163 | S9: =SUM(S8/O8)-1 -> 0.075605481 | T9: =SUM(T8/P8)-1 -> 0.040432145 | ... V9: =SUM(V8/R8)-1 -> -0.19560015 | AB9: =SUM(AB8/X8)-1 -> 0.031386894 | AC9: =SUM(AC8/Y8)-1 -> -0.18035581 | AD9: =SUM(AD8/Z8)-1 -> -0.1866278 | AE9: =SUM(AE8/AA8)-1 -> -0.1094212 | AF9: =SUM(AF8/AB8)-1 -> -0.074826605 | AG9: =SUM(AG8/AC8)-1 -> -0.049287079 | AH9: =SUM(AH8/AD8)-1 -> -0.021922428 | AI9: =SUM(AI8/AE8)-1 -> -0.051690011 | AK9: =SUM(AI9-AE9)*10000 -> 577.31187
B10: Q/Q Growth (%) | C10: N/A | D10: N/A | E10: N/A | F10: N/A | G10: N/A | J10: =SUM(J8/I8)-1 -> 0.34338313 | K10: =SUM(K8/J8)-1 -> -0.43892818 | L10: =SUM(L8/K8)-1 -> -0.031054545 | M10: =SUM(M8/L8)-1 -> 0.15384423 | N10: =SUM(N8/M8)-1 -> 0.10747431 | O10: =SUM(O8/N8)-1 -> -0.26272406 | P10: =SUM(P8/O8)-1 -> -0.021683132 | Q10: =SUM(Q8/P8)-1 -> 0.026113275 | ... V10: =SUM(V8/U8)-1 -> 0.090599584 | X10: N/A | Y10: N/A | Z10: N/A | AA10: N/A | AB10: N/A | AC10: N/A | AD10: N/A | AE10: N/A | AF10: N/A | AG10: N/A | AH10: N/A | AI10: N/A
B12: (-) Cost of Sales | C12: ='Historical Financials'!E13 -> -284510 | D12: ='Historical Financials'!F13 -> -347419 | E12: ='Historical Financials'!G13 -> -442676 | F12: ='Historical Financials'!H13 -> -426031 | G12: ='Historical Financials'!I13 -> -284753 | I12: ='Historical Financials'!AA13 -> -109265 | J12: ='Historical Financials'!AB13 -> -153202 | K12: ='Historical Financials'!AC13 -> -97340 | L12: ='Historical Financials'!AD13 -> -82869 | M12: ='Historical Financials'!AE13 -> -86051 | N12: ='Historical Financials'!AF13 -> -99876 | O12: ='Historical Financials'!AG13 -> -82566 | P12: ='Historical Financials'!AH13 -> -157538 | ... V12: ='Historical Financials'!AN13 -> -66367 | X12: =SUM(H12:K12) -> -359807 | Y12: =SUM(I12:L12) -> -442676 | Z12: =SUM(J12:M12) -> -419462 | AA12: =SUM(K12:N12) -> -366136 | AB12: =SUM(L12:O12) -> -351362 | AC12: =SUM(M12:P12) -> -426031 | AD12: =SUM(N12:Q12) -> -411915 | AE12: =SUM(O12:R12) -> -391507 | ... AI12: =SUM(S12:V12) -> -269513 | AK12: =SUM(AI12/AE12)-1 -> -0.31160107
B13: Gross Profit | C13: =+C8+C12 -> 122275 | D13: =+D8+D12 -> 117281 | E13: =+E8+E12 -> -23743 | F13: =+F8+F12 -> -82655 | G13: =+G8+G12 -> 41699 | I13: =+I8+I12 -> 190 | J13: =+J8+J12 -> -6162 | K13: =+K8+K12 -> -14840 | L13: =+L8+L12 -> -2931 | M13: =+M8+M12 -> 6185 | N13: =+N8+N12 -> 2273 | O13: =+O8+O12 -> -7254 | P13: =+P8+P12 -> -83859 | ... V13: =+V8+V12 -> 8591 | X13: =+X8+X12 -> -20812 | Y13: =+Y8+Y12 -> -23743 | Z13: =+Z8+Z12 -> -17748 | AA13: =+AA8+AA12 -> -9313 | AB13: =+AB8+AB12 -> -1727 | AC13: =+AC8+AC12 -> -82655 | AD13: =+AD8+AD12 -> -85172 | AE13: =+AE8+AE12 -> -73728 | ... AI13: =+AI8+AI12 -> 31840 | AK13: =SUM(AI13/AE13)-1 -> -1.4318576
B14: Gross Margin (%) | C14: =C13/C8 -> 0.30058876 | D14: =D13/D8 -> 0.25238003 | E14: =E13/E8 -> -0.056674934 | F14: =F13/F8 -> -0.2407128 | G14: =G13/G8 -> 0.12773394 | I14: =I13/I8 -> 0.0017358732 | J14: =J13/J8 -> -0.041906964 | K14: =K13/K8 -> -0.17987879 | L14: =L13/L8 -> -0.036665916 | M14: =M13/M8 -> 0.067056247 | N14: =N13/N8 -> 0.022251809 | O14: =O13/O8 -> -0.096319312 | P14: =P13/P8 -> -1.1381669 | ... V14: =V13/V8 -> 0.11461085 | X14: =X13/X8 -> -0.061393236 | Y14: =Y13/Y8 -> -0.056674934 | Z14: =Z13/Z8 -> -0.044180686 | AA14: =AA13/AA8 -> -0.026099775 | AB14: =AB13/AB8 -> -0.0049394368 | AC14: =AC13/AC8 -> -0.2407128 | AD14: =AD13/AD8 -> -0.2606697 | AE14: =AE13/AE8 -> -0.2320103 | ... AI14: =AI13/AI8 -> 0.10565682 | AK14: =SUM(AI14-AE14)*10000 -> 3376.6712
B16: (-) Selling, General & Administrative (SG&A) | C16: ='Historical Financials'!E17 -> -133655 | D16: ='Historical Financials'!F17 -> -209474 | E16: ='Historical Financials'!G17 -> -239505 | F16: ='Historical Financials'!H17 -> -220344 | G16: ='Historical Financials'!I17 -> -169674 | I16: ='Historical Financials'!AA17 -> -75114 | J16: ='Historical Financials'!AB17 -> -63015 | K16: ='Historical Financials'!AC17 -> -54495 | L16: ='Historical Financials'!AD17 -> -46881 | M16: ='Historical Financials'!AE17 -> -51900 | N16: ='Historical Financials'!AF17 -> -47455 | O16: ='Historical Financials'!AG17 -> -53252 | P16: ='Historical Financials'!AH17 -> -67737 | ... V16: ='Historical Financials'!AN17 -> -37696 | X16: =SUM(H16:K16) -> -192624 | Y16: =SUM(I16:L16) -> -239505 | Z16: =SUM(J16:M16) -> -216291 | AA16: =SUM(K16:N16) -> -200731 | AB16: =SUM(L16:O16) -> -199488 | AC16: =SUM(M16:P16) -> -220344 | AD16: =SUM(N16:Q16) -> -215726 | AE16: =SUM(O16:R16) -> -210434 | ... AI16: =SUM(S16:V16) -> -165597 | AK16: =SUM(AI16/AE16)-1 -> -0.21306918
B17: (-) Research and Development (R&D) | C17: ='Historical Financials'!E18 -> -31535 | D17: ='Historical Financials'!F18 -> -66946 | E17: ='Historical Financials'!G18 -> -62264 | F17: ='Historical Financials'!H18 -> -39530 | G17: ='Historical Financials'!I18 -> -28149 | I17: ='Historical Financials'!AA18 -> -19678 | J17: ='Historical Financials'!AB18 -> -16202 | K17: ='Historical Financials'!AC18 -> -13413 | L17: ='Historical Financials'!AD18 -> -12971 | M17: ='Historical Financials'!AE18 -> -12432 | N17: ='Historical Financials'!AF18 -> -8773 | O17: ='Historical Financials'!AG18 -> -9118 | P17: ='Historical Financials'!AH18 -> -9207 | ... V17: ='Historical Financials'!AN18 -> -5807 | X17: =SUM(H17:K17) -> -49293 | Y17: =SUM(I17:L17) -> -62264 | Z17: =SUM(J17:M17) -> -55018 | AA17: =SUM(K17:N17) -> -47589 | AB17: =SUM(L17:O17) -> -43294 | AC17: =SUM(M17:P17) -> -39530 | AD17: =SUM(N17:Q17) -> -36958 | AE17: =SUM(O17:R17) -> -33670 | ... AI17: =SUM(S17:V17) -> -26073 | AK17: =SUM(AI17/AE17)-1 -> -0.22563113
B18: Earning before Interest & Taxes (EBIT) | C18: =SUM(C13+SUM(C16:C17)) -> -42915 | D18: =SUM(D13+SUM(D16:D17)) -> -159139 | E18: =SUM(E13+SUM(E16:E17)) -> -325512 | F18: =SUM(F13+SUM(F16:F17)) -> -342529 | G18: =SUM(G13+SUM(G16:G17)) -> -156124 | I18: =SUM(I13+SUM(I16:I17)) -> -94602 | J18: =SUM(J13+SUM(J16:J17)) -> -85379 | K18: =SUM(K13+SUM(K16:K17)) -> -82748 | L18: =SUM(L13+SUM(L16:L17)) -> -62783 | M18: =SUM(M13+SUM(M16:M17)) -> -58147 | N18: =SUM(N13+SUM(N16:N17)) -> -53955 | O18: =SUM(O13+SUM(O16:O17)) -> -69624 | P18: =SUM(P13+SUM(P16:P17)) -> -160803 | ... V18: =SUM(V13+SUM(V16:V17)) -> -34912 | X18: =SUM(X13+SUM(X16:X17)) -> -262729 | Y18: =SUM(Y13+SUM(Y16:Y17)) -> -325512 | Z18: =SUM(Z13+SUM(Z16:Z17)) -> -289057 | AA18: =SUM(AA13+SUM(AA16:AA17)) -> -257633 | AB18: =SUM(AB13+SUM(AB16:AB17)) -> -244509 | AC18: =SUM(AC13+SUM(AC16:AC17)) -> -342529 | AD18: =SUM(AD13+SUM(AD16:AD17)) -> -337856 | AE18: =SUM(AE13+SUM(AE16:AE17)) -> -317832 | ... AI18: =SUM(AI13+SUM(AI16:AI17)) -> -159830 | AK18: =SUM(AI18/AE18)-1 -> -0.49712427
B19: Operating Margin (%) | C19: =C18/C8 -> -0.10549799 | D19: =D18/D8 -> -0.34245535 | E19: =E18/E8 -> -0.77700253 | F19: =F18/F8 -> -0.99753332 | G19: =G18/G8 -> -0.47824489 | I19: =I18/I8 -> -0.8643004 | J19: =J18/J8 -> -0.58065152 | K19: =K18/K8 -> -1.0030061 | L19: =L18/L8 -> -0.78539618 | M19: =M18/M8 -> -0.63041546 | N19: =N18/N8 -> -0.528199 | O19: =O18/O8 -> -0.92447419 | P19: =P18/P8 -> -2.1824808 | ... V19: =V18/V8 -> -0.46575416 | X19: =X18/X8 -> -0.77502323 | Y19: =Y18/Y8 -> -0.77700253 | Z19: =Z18/Z8 -> -0.71955919 | AA19: =AA18/AA8 -> -0.72201904 | AB19: =AB18/AB8 -> -0.69932644 | AC19: =AC18/AC8 -> -0.99753332 | AD19: =AD18/AD8 -> -1.0340114 | AE19: =AE18/AE8 -> -1.0001668 | ... AI19: =AI18/AI8 -> -0.53037468 | AK19: =SUM(AI19-AE19)*10000 -> 4697.9211
B21: (+) Depreciation and Amortization | C21: ='Historical Financials'!E100 -> 13299 | D21: ='Historical Financials'!F100 -> 21663 | E21: ='Historical Financials'!G100 -> 32582 | F21: ='Historical Financials'!H100 -> 48094 | G21: ='Historical Financials'!I100 -> 23121 | I21: ='Historical Financials'!AA100 -> 7091 | J21: ='Historical Financials'!AB100 -> 7729 | K21: ='Historical Financials'!AC100 -> 8435 | L21: ='Historical Financials'!AD100 -> 9327 | M21: ='Historical Financials'!AE100 -> 6049 | N21: ='Historical Financials'!AF100 -> 5879 | O21: ='Historical Financials'!AG100 -> 5779 | P21: ='Historical Financials'!AH100 -> 30387 | ... V21: ='Historical Financials'!AN100 -> 8266 | X21: =SUM(H21:K21) -> 23255 | Y21: =SUM(I21:L21) -> 32582 | Z21: =SUM(J21:M21) -> 31540 | AA21: =SUM(K21:N21) -> 29690 | AB21: =SUM(L21:O21) -> 27034 | AC21: =SUM(M21:P21) -> 48094 | AD21: =SUM(N21:Q21) -> 49014 | AE21: =SUM(O21:R21) -> 48348 | ... AI21: =SUM(S21:V21) -> 26621 | AK21: =SUM(AI21/AE21)-1 -> -0.44938777
B22: EBITDA | C22: =SUM(C18+C21) -> -29616 | D22: =SUM(D18+D21) -> -137476 | E22: =SUM(E18+E21) -> -292930 | F22: =SUM(F18+F21) -> -294435 | G22: =SUM(G18+G21) -> -133003 | I22: =SUM(I18+I21) -> -87511 | J22: =SUM(J18+J21) -> -77650 | K22: =SUM(K18+K21) -> -74313 | L22: =SUM(L18+L21) -> -53456 | M22: =SUM(M18+M21) -> -52098 | N22: =SUM(N18+N21) -> -48076 | O22: =SUM(O18+O21) -> -63845 | P22: =SUM(P18+P21) -> -130416 | ... V22: =SUM(V18+V21) -> -26646 | X22: =SUM(X18+X21) -> -239474 | Y22: =SUM(Y18+Y21) -> -292930 | Z22: =SUM(Z18+Z21) -> -257517 | AA22: =SUM(AA18+AA21) -> -227943 | AB22: =SUM(AB18+AB21) -> -217475 | AC22: =SUM(AC18+AC21) -> -294435 | AD22: =SUM(AD18+AD21) -> -288842 | AE22: =SUM(AE18+AE21) -> -269484 | ... AI22: =SUM(AI18+AI21) -> -133209 | AK22: =SUM(AI22/AE22)-1 -> -0.50568865
B23: EBITDA Margin (%) | C23: =C22/C8 -> -0.072805044 | D23: =D22/D8 -> -0.29583818 | E23: =E22/E8 -> -0.69922875 | F23: =F22/F8 -> -0.85747111 | G23: =G22/G8 -> -0.40741977 | I23: =I22/I8 -> -0.79951578 | J23: =J22/J8 -> -0.5280876 | K23: =K22/K8 -> -0.90076364 | L23: =L22/L8 -> -0.66871826 | M23: =M22/M8 -> -0.56483369 | N23: =N22/N8 -> -0.47064582 | O23: =O22/O8 -> -0.84774007 | P23: =P22/P8 -> -1.7700566 | ... V23: =V22/V8 -> -0.35547907 | X23: =X22/X8 -> -0.7064234 | Y23: =Y22/Y8 -> -0.69922875 | Z23: =Z22/Z8 -> -0.64104562 | AA23: =AA22/AA8 -> -0.63881252 | AB23: =AB22/AB8 -> -0.62200581 | AC23: =AC22/AC8 -> -0.85747111 | AD23: =AD22/AD8 -> -0.88400364 | AE23: =AE22/AE8 -> -0.84802331 | ... AI23: =AI22/AI8 -> -0.44203642 | AK23: =SUM(AI23-AE23)*10000 -> 4059.869
B25: (+) Share-based Compensation | C25: ='Historical Financials'!E101 -> 27279 | D25: ='Historical Financials'!F101 -> 27698 | E25: ='Historical Financials'!G101 -> 33857 | F25: ='Historical Financials'!H101 -> 29098 | G25: ='Historical Financials'!I101 -> 23923 | I25: ='Historical Financials'!AA101 -> 9292 | J25: ='Historical Financials'!AB101 -> 10306 | K25: ='Historical Financials'!AC101 -> 9250 | L25: ='Historical Financials'!AD101 -> 5009 | M25: ='Historical Financials'!AE101 -> 9565 | N25: ='Historical Financials'!AF101 -> 7748 | O25: ='Historical Financials'!AG101 -> 6478 | P25: ='Historical Financials'!AH101 -> 5307 | ... V25: ='Historical Financials'!AN101 -> 4304 | X25: =SUM(H25:K25) -> 28848 | Y25: =SUM(I25:L25) -> 33857 | Z25: =SUM(J25:M25) -> 34130 | AA25: =SUM(K25:N25) -> 31572 | AB25: =SUM(L25:O25) -> 28800 | AC25: =SUM(M25:P25) -> 29098 | AD25: =SUM(N25:Q25) -> 25608 | AE25: =SUM(O25:R25) -> 23633 | ... AI25: =SUM(S25:V25) -> 22232 | AK25: =SUM(AI25/AE25)-1 -> -0.059281513
B26: (+) Restructuring Expenses | C26: 6430 | D26: 21663 | E26: 17259 | F26: -631 | G26: 0 | I26: 3026 | J26: 4302 | K26: 6993 | L26: =SUM(E26-SUM(I26:K26)) -> 2938 | M26: 426 | N26: -201 | O26: -4 | P26: =SUM(F26-SUM(M26:O26)) -> -852 | Q26: 0 | R26: 0 | S26: 0 | T26: =SUM(G26-SUM(Q26:S26)) -> 0 | U26: 0 | V26: 0 | AE26: =SUM(O26:R26) -> -856 | AF26: =SUM(P26:S26) -> -852 | AG26: =SUM(Q26:T26) -> 0 | AH26: =SUM(R26:U26) -> 0 | AI26: =SUM(S26:V26) -> 0
B27: (+) Accrued litigation settlement costs | C27: 0 | D27: 0 | E27: 0 | F27: 0 | G27: 7500 | I27: 0 | J27: 0 | K27: 0 | L27: =SUM(E27-SUM(I27:K27)) -> 0 | M27: 0 | N27: 0 | O27: 0 | P27: =SUM(F27-SUM(M27:O27)) -> 0 | Q27: 7500 | R27: 0 | S27: 0 | T27: =SUM(G27-SUM(Q27:S27)) -> 0 | U27: 0 | V27: 0 | AE27: =SUM(O27:R27) -> 7500 | AF27: =SUM(P27:S27) -> 7500 | AG27: =SUM(Q27:T27) -> 7500 | AH27: =SUM(R27:U27) -> 0 | AI27: =SUM(S27:V27) -> 0
B28: (+) Other | C28: 0 | D28: 0 | E28: 0 | F28: 0 | G28: 0 | I28: 0 | J28: 0 | K28: 0 | L28: =SUM(E28-SUM(I28:K28)) -> 0 | M28: 0 | N28: 0 | O28: 0 | P28: =SUM(F28-SUM(M28:O28)) -> 0 | Q28: 0 | R28: 0 | S28: 0 | T28: =SUM(G28-SUM(Q28:S28)) -> 0 | U28: 2083 | V28: 1739 | AE28: =SUM(O28:R28) -> 0 | AF28: =SUM(P28:S28) -> 0 | AG28: =SUM(Q28:T28) -> 0 | AH28: =SUM(R28:U28) -> 2083 | AI28: =SUM(S28:V28) -> 3822
B29: Adj. EBITDA | C29: =+SUM(C22+SUM(C25:C28)) -> 4093 | D29: =+SUM(D22+SUM(D25:D28)) -> -88115 | E29: =+SUM(E22+SUM(E25:E28)) -> -241814 | F29: =+SUM(F22+SUM(F25:F28)) -> -265968 | G29: =+SUM(G22+SUM(G25:G28)) -> -101580 | I29: =+SUM(I22+SUM(I25:I28)) -> -75193 | J29: =+SUM(J22+SUM(J25:J28)) -> -63042 | K29: =+SUM(K22+SUM(K25:K28)) -> -58070 | L29: =+SUM(L22+SUM(L25:L28)) -> -45509 | M29: =+SUM(M22+SUM(M25:M28)) -> -42107 | N29: =+SUM(N22+SUM(N25:N28)) -> -40529 | O29: =+SUM(O22+SUM(O25:O28)) -> -57371 | P29: =+SUM(P22+SUM(P25:P28)) -> -125961 | ... V29: =+SUM(V22+SUM(V25:V28)) -> -20603 | X29: =+SUM(X22+SUM(X25:X28)) -> -210626 | Y29: =+SUM(Y22+SUM(Y25:Y28)) -> -259073 | Z29: =+SUM(Z22+SUM(Z25:Z28)) -> -223387 | AA29: =+SUM(AA22+SUM(AA25:AA28)) -> -196371 | AB29: =+SUM(AB22+SUM(AB25:AB28)) -> -188675 | AC29: =+SUM(AC22+SUM(AC25:AC28)) -> -265337 | AD29: =+SUM(AD22+SUM(AD25:AD28)) -> -263234 | AE29: =+SUM(AE22+SUM(AE25:AE28)) -> -239207 | ... AI29: =+SUM(AI22+SUM(AI25:AI28)) -> -107155 | AK29: =SUM(AI29/AE29)-1 -> -0.5520407
B30: Adj. EBITDA Margin (%) | C30: =C29/C8 -> 0.010061826 | D30: =D29/D8 -> -0.18961696 | E30: =E29/E8 -> -0.57721402 | F30: =F29/F8 -> -0.77456782 | G30: =G29/G8 -> -0.31116366 | I30: =I29/I8 -> -0.68697638 | J30: =J29/J8 -> -0.42874048 | K30: =K29/K8 -> -0.70387879 | L30: =L29/L8 -> -0.56930371 | M30: =M29/M8 -> -0.45651373 | N30: =N29/N8 -> -0.39676355 | O30: =O29/O8 -> -0.76177767 | P30: =P29/P8 -> -1.7095916 | ... V30: =V29/V8 -> -0.27486059 | X30: =X29/X8 -> -0.6213248 | Y30: =Y29/Y8 -> -0.61841154 | Z30: =Z29/Z8 -> -0.55608468 | AA30: =AA29/AA8 -> -0.55033168 | AB30: =AB29/AB8 -> -0.53963419 | AC30: =AC29/AC8 -> -0.77273018 | AD30: =AD29/AD8 -> -0.80563011 | AE30: =AE29/AE8 -> -0.75274641 | ... AI30: =AI29/AI8 -> -0.35557967 | AK30: =SUM(AI30-AE30)*10000 -> 3971.6674
B32: (-) Capital Expenditures | C32: ='Historical Financials'!E125 -> -57696 | D32: ='Historical Financials'!F125 -> -135961 | E32: ='Historical Financials'!G125 -> -70475 | F32: ='Historical Financials'!H125 -> -10564 | G32: ='Historical Financials'!I125 -> -11015 | I32: ='Historical Financials'!AA125 -> -21548 | J32: ='Historical Financials'!AB125 -> -20417 | K32: ='Historical Financials'!AC125 -> -17987 | L32: ='Historical Financials'!AD125 -> -10523 | M32: ='Historical Financials'!AE125 -> -5302 | N32: ='Historical Financials'!AF125 -> -1837 | O32: ='Historical Financials'!AG125 -> -1428 | P32: ='Historical Financials'!AH125 -> -1997 | ... V32: ='Historical Financials'!AN125 -> -1938 | X32: =SUM(H32:K32) -> -59952 | Y32: =SUM(I32:L32) -> -70475 | Z32: =SUM(J32:M32) -> -54229 | AA32: =SUM(K32:N32) -> -35649 | AB32: =SUM(L32:O32) -> -19090 | AC32: =SUM(M32:P32) -> -10564 | AD32: =SUM(N32:Q32) -> -6459 | AE32: =SUM(O32:R32) -> -5945 | ... AI32: =SUM(S32:V32) -> -14918 | AK32: =SUM(AI32/AE32)-1 -> 1.5093356
B33: (-) Cash Taxes | C33: =-'Historical Financials'!E160 -> -18 | D33: =-'Historical Financials'!F160 -> 10 | E33: =-'Historical Financials'!G160 -> -38 | F33: =-'Historical Financials'!H160 -> 1 | G33: =-'Historical Financials'!I160 -> -6 | I33: =-'Historical Financials'!AA160 -> -52 | J33: =-'Historical Financials'!AB160 -> 31 | K33: =-'Historical Financials'!AC160 -> 0 | L33: =-'Historical Financials'!AD160 -> -17 | M33: =-'Historical Financials'!AE160 -> 0 | N33: =-'Historical Financials'!AF160 -> -9 | O33: =-'Historical Financials'!AG160 -> 0 | P33: =-'Historical Financials'!AH160 -> 10 | ... V33: =-'Historical Financials'!AN160 -> -2 | X33: =SUM(H33:K33) -> -21 | Y33: =SUM(I33:L33) -> -38 | Z33: =SUM(J33:M33) -> 14 | AA33: =SUM(K33:N33) -> -26 | AB33: =SUM(L33:O33) -> -26 | AC33: =SUM(M33:P33) -> 1 | AD33: =SUM(N33:Q33) -> -1 | AE33: =SUM(O33:R33) -> -6 | ... AI33: =SUM(S33:V33) -> 8 | AK33: =SUM(AI33/AE33)-1 -> -2.3333333
