Workbook

Sheet Historical Financials
B2: Netflix, Inc. (NASDAQ: NFLX)
B3: Historical Financials
B4: $ in thousands except per share
A6: X | B6: Income Statement | G6: FYE | O6: Quarterly | Y6: Quarterly | AN6: LTM | AO6: LTM | AU6: Variance
B7: Fiscal Period | C7: 2018 | D7: 2019 | E7: 2020 | F7: 2021 | G7: 2022 | H7: 2023 | I7: 2024 | K7: 1Q21 | L7: 2Q21 | M7: 3Q21 | N7: 4Q21 | O7: 1Q22 | P7: 2Q22 | Q7: 3Q22 | R7: 4Q22 | S7: 1Q23 | T7: 2Q23 | U7: 3Q23 | V7: 4Q23 | W7: 1Q24 | X7: 2Q24 | Y7: 3Q24 | Z7: 4Q24 | AA7: 1Q25 | AB7: 2Q25 | AC7: 3Q25 | AE7: =O7 -> 1Q22 | AF7: =P7 -> 2Q22 | AG7: =Q7 -> 3Q22 | AH7: =R7 -> 4Q22 | AI7: =S7 -> 1Q23 | AJ7: =T7 -> 2Q23 | AK7: =U7 -> 3Q23 | AL7: =V7 -> 4Q23 | ... AS7: =AC7 -> 3Q25
B8: Fiscal Period End Date | C8: 43465 | D8: 43830 | E8: 44196 | F8: 44561 | G8: 44926 | H8: 45291 | I8: 45657 | K8: 44286 | L8: 44377 | M8: 44469 | N8: =F8 -> 44561 | O8: 44651 | P8: 44742 | Q8: 44834 | R8: =G8 -> 44926 | S8: 45016 | T8: 45107 | U8: 45199 | V8: =H8 -> 45291 | W8: 45382 | X8: 45473 | Y8: 45565 | Z8: =I8 -> 45657 | AA8: 45747 | AB8: 45838 | AC8: 45930 | AE8: =O8 -> 44651 | AF8: =P8 -> 44742 | AG8: =Q8 -> 44834 | AH8: =R8 -> 44926 | AI8: =S8 -> 45016 | AJ8: =T8 -> 45107 | AK8: =U8 -> 45199 | AL8: =V8 -> 45291 | ... AS8: =AC8 -> 45930
B10: Consolidated Revenue | C10: 15794341 | D10: 20156447 | E10: 24996056 | F10: 29697844 | G10: 31615550 | H10: 33723297 | I10: 39000966 | K10: 7163282 | L10: 7341777 | M10: 7483467 | N10: =SUM(F10-SUM(K10:M10)) -> 7709318 | O10: 7867767 | P10: 7970141 | Q10: 7925589 | R10: =SUM(G10-SUM(O10:Q10)) -> 7852053 | S10: 8161503 | T10: 8187301 | U10: 8541668 | V10: =SUM(H10-SUM(S10:U10)) -> 8832825 | W10: 9370440 | X10: 9559310 | Y10: 9824703 | Z10: =SUM(I10-SUM(W10:Y10)) -> 10246513 | AA10: 10542801 | AB10: 11079166 | AC10: 11510307 | AE10: =SUM(L10:O10) -> 30402329 | AF10: =SUM(M10:P10) -> 31030693 | AG10: =SUM(N10:Q10) -> 31472815 | AH10: =SUM(O10:R10) -> 31615550 | AI10: =SUM(P10:S10) -> 31909286 | AJ10: =SUM(Q10:T10) -> 32126446 | AK10: =SUM(R10:U10) -> 32742525 | AL10: =SUM(S10:V10) -> 33723297 | ... AS10: =SUM(Z10:AC10) -> 43378787 | AU10: =SUM(AS10/AO10)-1 -> 0.15408163
B11: Total Revenue | C11: =+SUM(C10:C10) -> 15794341 | D11: =+SUM(D10:D10) -> 20156447 | E11: =+SUM(E10:E10) -> 24996056 | F11: =+SUM(F10:F10) -> 29697844 | G11: =+SUM(G10:G10) -> 31615550 | H11: =+SUM(H10:H10) -> 33723297 | I11: =+SUM(I10:I10) -> 39000966 | K11: =+SUM(K10:K10) -> 7163282 | L11: =+SUM(L10:L10) -> 7341777 | M11: =+SUM(M10:M10) -> 7483467 | N11: =+SUM(N10:N10) -> 7709318 | O11: =+SUM(O10:O10) -> 7867767 | P11: =+SUM(P10:P10) -> 7970141 | Q11: =+SUM(Q10:Q10) -> 7925589 | R11: =+SUM(R10:R10) -> 7852053 | ... AC11: =+SUM(AC10:AC10) -> 11510307 | AE11: =+SUM(AE10:AE10) -> 30402329 | AF11: =+SUM(AF10:AF10) -> 31030693 | AG11: =+SUM(AG10:AG10) -> 31472815 | AH11: =+SUM(AH10:AH10) -> 31615550 | AI11: =+SUM(AI10:AI10) -> 31909286 | AJ11: =+SUM(AJ10:AJ10) -> 32126446 | AK11: =+SUM(AK10:AK10) -> 32742525 | AL11: =+SUM(AL10:AL10) -> 33723297 | ... AS11: =+SUM(AS10:AS10) -> 43378787 | AU11: =SUM(AS11/AO11)-1 -> 0.15408163
B13: Amortization of content assets | C13: -7532088 | D13: -9216247 | E13: -10806912 | F13: -12230367 | G13: -14026132 | H13: -14197437 | I13: -15301517 | K13: -2719196 | L13: -2806803 | M13: -2963051 | N13: =SUM(F13-SUM(K13:M13)) -> -3741317 | O13: -3166365 | P13: -3261348 | Q13: -3653592 | R13: =SUM(G13-SUM(O13:Q13)) -> -3944827 | S13: -3459984 | T13: -3410021 | U13: -3573353 | V13: =SUM(H13-SUM(S13:U13)) -> -3754079 | W13: -3670805 | X13: -3769690 | Y13: -3699521 | Z13: =SUM(I13-SUM(W13:Y13)) -> -4161501 | AA13: -3823112 | AB13: -3832074 | AC13: -4002744 | AE13: =SUM(L13:O13) -> -12677536 | AF13: =SUM(M13:P13) -> -13132081 | AG13: =SUM(N13:Q13) -> -13822622 | AH13: =SUM(O13:R13) -> -14026132 | AI13: =SUM(P13:S13) -> -14319751 | AJ13: =SUM(Q13:T13) -> -14468424 | AK13: =SUM(R13:U13) -> -14388185 | AL13: =SUM(S13:V13) -> -14197437 | ... AS13: =SUM(Z13:AC13) -> -15819431
B14: Other Cost of Revenues | C14: =+C15-C13 -> -2435450 | D14: =+D15-D13 -> -3223966 | E14: =+E15-E13 -> -4469407 | F14: =+F15-F13 -> -5102316 | G14: =+G15-G13 -> -5142153 | H14: =+H15-H13 -> -5517931 | I14: =+I15-I13 -> -5736947 | K14: =+K15-K13 -> -1149315 | L14: =+L15-L13 -> -1211205 | M14: =+M15-M13 -> -1243538 | N14: =+N15-N13 -> -1498258 | O14: =+O15-O13 -> -1118340 | P14: =+P15-P13 -> -1429407 | Q14: =+Q15-Q13 -> -1135073 | R14: =+R15-R13 -> -1459333 | ... AC14: =+AC15-AC13 -> -2161506 | AE14: =SUM(L14:O14) -> -5071341 | AF14: =SUM(M14:P14) -> -5289543 | AG14: =SUM(N14:Q14) -> -5181078 | AH14: =SUM(O14:R14) -> -5142153 | AI14: =SUM(P14:S14) -> -5367454 | AJ14: =SUM(Q14:T14) -> -5201496 | AK14: =SUM(R14:U14) -> -5423858 | AL14: =SUM(S14:V14) -> -5517931 | ... AS14: =SUM(Z14:AC14) -> -6700641
B15: Total Cost of Revenue | C15: -9967538 | D15: -12440213 | E15: -15276319 | F15: -17332683 | G15: -19168285 | H15: -19715368 | I15: -21038464 | K15: -3868511 | L15: -4018008 | M15: -4206589 | N15: =SUM(F15-SUM(K15:M15)) -> -5239575 | O15: -4284705 | P15: -4690755 | Q15: -4788665 | R15: =SUM(G15-SUM(O15:Q15)) -> -5404160 | S15: -4803625 | T15: -4673470 | U15: -4930788 | V15: =SUM(H15-SUM(S15:U15)) -> -5307485 | W15: -4977073 | X15: -5174143 | Y15: -5119884 | Z15: =SUM(I15-SUM(W15:Y15)) -> -5767364 | AA15: -5263147 | AB15: -5325311 | AC15: -6164250 | AE15: =SUM(L15:O15) -> -17748877 | AF15: =SUM(M15:P15) -> -18421624 | AG15: =SUM(N15:Q15) -> -19003700 | AH15: =SUM(O15:R15) -> -19168285 | AI15: =SUM(P15:S15) -> -19687205 | AJ15: =SUM(Q15:T15) -> -19669920 | AK15: =SUM(R15:U15) -> -19812043 | AL15: =SUM(S15:V15) -> -19715368 | ... AS15: =SUM(Z15:AC15) -> -22520072
B16: Gross Profit | C16: =+SUM(C11+SUM(C13:C14)) -> 5826803 | D16: =+SUM(D11+SUM(D13:D14)) -> 7716234 | E16: =+SUM(E11+SUM(E13:E14)) -> 9719737 | F16: =+SUM(F11+SUM(F13:F14)) -> 12365161 | G16: =+SUM(G11+SUM(G13:G14)) -> 12447265 | H16: =+SUM(H11+SUM(H13:H14)) -> 14007929 | I16: =+SUM(I11+SUM(I13:I14)) -> 17962502 | K16: =+SUM(K11+SUM(K13:K14)) -> 3294771 | L16: =+SUM(L11+SUM(L13:L14)) -> 3323769 | M16: =+SUM(M11+SUM(M13:M14)) -> 3276878 | N16: =+SUM(N11+SUM(N13:N14)) -> 2469743 | O16: =+SUM(O11+SUM(O13:O14)) -> 3583062 | P16: =+SUM(P11+SUM(P13:P14)) -> 3279386 | Q16: =+SUM(Q11+SUM(Q13:Q14)) -> 3136924 | R16: =+SUM(R11+SUM(R13:R14)) -> 2447893 | ... AC16: =+SUM(AC11+SUM(AC13:AC14)) -> 5346057 | AE16: =+SUM(AE11+SUM(AE13:AE14)) -> 12653452 | AF16: =+SUM(AF11+SUM(AF13:AF14)) -> 12609069 | AG16: =+SUM(AG11+SUM(AG13:AG14)) -> 12469115 | AH16: =+SUM(AH11+SUM(AH13:AH14)) -> 12447265 | AI16: =+SUM(AI11+SUM(AI13:AI14)) -> 12222081 | AJ16: =+SUM(AJ11+SUM(AJ13:AJ14)) -> 12456526 | AK16: =+SUM(AK11+SUM(AK13:AK14)) -> 12930482 | AL16: =+SUM(AL11+SUM(AL13:AL14)) -> 14007929 | ... AS16: =+SUM(AS11+SUM(AS13:AS14)) -> 20858715 | AU16: =SUM(AS16/AO16)-1 -> 0.22635613
B17: Gross Margin (%) | C17: =C16/C11 -> 0.36891713 | D17: =D16/D11 -> 0.38281717 | E17: =E16/E11 -> 0.38885083 | F17: =F16/F11 -> 0.41636561 | G17: =G16/G11 -> 0.39370705 | H17: =H16/H11 -> 0.4153784 | I17: =I16/I11 -> 0.46056557 | K17: =K16/K11 -> 0.45995271 | L17: =L16/L11 -> 0.45271996 | M17: =M16/M11 -> 0.43788233 | N17: =N16/N11 -> 0.32035817 | O17: =O16/O11 -> 0.45541028 | P17: =P16/P11 -> 0.41145897 | Q17: =Q16/Q11 -> 0.39579696 | R17: =R16/R11 -> 0.31175197 | ... AC17: =AC16/AC11 -> 0.46445825 | AE17: =AE16/AE11 -> 0.41620009 | AF17: =AF16/AF11 -> 0.40634184 | AG17: =AG16/AG11 -> 0.39618684 | AH17: =AH16/AH11 -> 0.39370705 | AI17: =AI16/AI11 -> 0.38302584 | AJ17: =AJ16/AJ11 -> 0.38773433 | AK17: =AK16/AK11 -> 0.39491401 | AL17: =AL16/AL11 -> 0.4153784 | ... AS17: =AS16/AS11 -> 0.48085058 | AU17: =SUM(AS17-AO17)*1000 -> 28.338618
B19: Marketing | C19: -2369469 | D19: -2652462 | E19: -2228362 | F19: -2545146 | G19: -2530502 | H19: -2657883 | I19: -2917554 | K19: -512512 | L19: -603973 | M19: -635948 | N19: =SUM(F19-SUM(K19:M19)) -> -792713 | O19: -555978 | P19: -574960 | Q19: -567954 | R19: =SUM(G19-SUM(O19:Q19)) -> -831610 | S19: -555362 | T19: -627168 | U19: -558736 | V19: =SUM(H19-SUM(S19:U19)) -> -916617 | W19: -654340 | X19: -644084 | Y19: -642926 | Z19: =SUM(I19-SUM(W19:Y19)) -> -976204 | AA19: -688370 | AB19: -713265 | AC19: -786295 | AE19: =SUM(L19:O19) -> -2588612 | AF19: =SUM(M19:P19) -> -2559599 | AG19: =SUM(N19:Q19) -> -2491605 | AH19: =SUM(O19:R19) -> -2530502 | AI19: =SUM(P19:S19) -> -2529886 | AJ19: =SUM(Q19:T19) -> -2582094 | AK19: =SUM(R19:U19) -> -2572876 | AL19: =SUM(S19:V19) -> -2657883 | ... AS19: =SUM(Z19:AC19) -> -3164134 | AU19: =SUM(AS19/AO19)-1 -> 0.10712755
B20: Technology and Development (T&D) | C20: -1221814 | D20: -1545149 | E20: -1829600 | F20: -2273885 | G20: -2711041 | H20: -2675758 | I20: -2925295 | K20: -525207 | L20: -537321 | M20: -563887 | N20: =SUM(F20-SUM(K20:M20)) -> -647470 | O20: -657530 | P20: -716846 | Q20: -662739 | R20: =SUM(G20-SUM(O20:Q20)) -> -673926 | S20: -687275 | T20: -657983 | U20: -657159 | V20: =SUM(H20-SUM(S20:U20)) -> -673341 | W20: -702473 | X20: -711254 | Y20: -735063 | Z20: =SUM(I20-SUM(W20:Y20)) -> -776505 | AA20: -822823 | AB20: -824683 | AC20: -853584 | AE20: =SUM(L20:O20) -> -2406208 | AF20: =SUM(M20:P20) -> -2585733 | AG20: =SUM(N20:Q20) -> -2684585 | AH20: =SUM(O20:R20) -> -2711041 | AI20: =SUM(P20:S20) -> -2740786 | AJ20: =SUM(Q20:T20) -> -2681923 | AK20: =SUM(R20:U20) -> -2676343 | AL20: =SUM(S20:V20) -> -2675758 | ... AS20: =SUM(Z20:AC20) -> -3277595 | AU20: =SUM(AS20/AO20)-1 -> 0.1613901
B21: General and Administrative (G&A) | C21: -630294 | D21: -914369 | E21: -1076486 | F21: -1351621 | G21: -1572891 | H21: -1720285 | I21: -1702039 | K21: -297196 | L21: -334845 | M21: -321790 | N21: =SUM(F21-SUM(K21:M21)) -> -397790 | O21: -397928 | P21: -409297 | Q21: -373213 | R21: =SUM(G21-SUM(O21:Q21)) -> -392453 | S21: -400924 | T21: -401497 | U21: -478591 | V21: =SUM(H21-SUM(S21:U21)) -> -439273 | W21: -404020 | X21: -426992 | Y21: -417353 | Z21: =SUM(I21-SUM(W21:Y21)) -> -453674 | AA21: -421462 | AB21: -441213 | AC21: -457931 | AE21: =SUM(L21:O21) -> -1452353 | AF21: =SUM(M21:P21) -> -1526805 | AG21: =SUM(N21:Q21) -> -1578228 | AH21: =SUM(O21:R21) -> -1572891 | AI21: =SUM(P21:S21) -> -1575887 | AJ21: =SUM(Q21:T21) -> -1568087 | AK21: =SUM(R21:U21) -> -1673465 | AL21: =SUM(S21:V21) -> -1720285 | ... AS21: =SUM(Z21:AC21) -> -1774280 | AU21: =SUM(AS21/AO21)-1 -> 0.051339209
B22: Operating Profit | C22: =+SUM(C16+SUM(C19:C21)) -> 1605226 | D22: =+SUM(D16+SUM(D19:D21)) -> 2604254 | E22: =+SUM(E16+SUM(E19:E21)) -> 4585289 | F22: =+SUM(F16+SUM(F19:F21)) -> 6194509 | G22: =+SUM(G16+SUM(G19:G21)) -> 5632831 | H22: =+SUM(H16+SUM(H19:H21)) -> 6954003 | I22: =+SUM(I16+SUM(I19:I21)) -> 10417614 | K22: =+SUM(K16+SUM(K19:K21)) -> 1959856 | L22: =+SUM(L16+SUM(L19:L21)) -> 1847630 | M22: =+SUM(M16+SUM(M19:M21)) -> 1755253 | N22: =+SUM(N16+SUM(N19:N21)) -> 631770 | O22: =+SUM(O16+SUM(O19:O21)) -> 1971626 | P22: =+SUM(P16+SUM(P19:P21)) -> 1578283 | Q22: =+SUM(Q16+SUM(Q19:Q21)) -> 1533018 | R22: =+SUM(R16+SUM(R19:R21)) -> 549904 | ... AC22: =+SUM(AC16+SUM(AC19:AC21)) -> 3248247 | AE22: =+SUM(AE16+SUM(AE19:AE21)) -> 6206279 | AF22: =+SUM(AF16+SUM(AF19:AF21)) -> 5936932 | AG22: =+SUM(AG16+SUM(AG19:AG21)) -> 5714697 | AH22: =+SUM(AH16+SUM(AH19:AH21)) -> 5632831 | AI22: =+SUM(AI16+SUM(AI19:AI21)) -> 5375522 | AJ22: =+SUM(AJ16+SUM(AJ19:AJ21)) -> 5624422 | AK22: =+SUM(AK16+SUM(AK19:AK21)) -> 6007798 | AL22: =+SUM(AL16+SUM(AL19:AL21)) -> 6954003 | ... AS22: =+SUM(AS16+SUM(AS19:AS21)) -> 12642706 | AU22: =SUM(AS22/AO22)-1 -> 0.31135384
B23: Operating Margin (%) | C23: =C22/C11 -> 0.10163298 | D23: =D22/D11 -> 0.12920204 | E23: =E22/E11 -> 0.1834405 | F23: =F22/F11 -> 0.20858447 | G23: =G22/G11 -> 0.17816647 | H23: =H22/H11 -> 0.20620768 | I23: =I22/I11 -> 0.26711169 | K23: =K22/K11 -> 0.27359749 | L23: =L22/L11 -> 0.25165978 | M23: =M22/M11 -> 0.23455078 | N23: =N22/N11 -> 0.081948883 | O23: =O22/O11 -> 0.25059537 | P23: =P22/P11 -> 0.19802448 | Q23: =Q22/Q11 -> 0.19342638 | R23: =R22/R11 -> 0.070033149 | ... AC23: =AC22/AC11 -> 0.28220333 | AE23: =AE22/AE11 -> 0.20413828 | AF23: =AF22/AF11 -> 0.19132451 | AG23: =AG22/AG11 -> 0.18157566 | AH23: =AH22/AH11 -> 0.17816647 | AI23: =AI22/AI11 -> 0.16846262 | AJ23: =AJ22/AJ11 -> 0.1750714 | AK23: =AK22/AK11 -> 0.18348609 | AL23: =AL22/AL11 -> 0.20620768 | ... AS23: =AS22/AS11 -> 0.29144904 | AU23: =SUM(AS23-AO23)*1000 -> 34.953828
B25: Interest Income | C25: 0 | D25: 0 | E25: 0 | F25: 0 | G25: 60000 | H25: 281000 | I25: 294000 | K25: 0 | L25: 0 | M25: 0 | N25: =SUM(F25-SUM(K25:M25)) -> 0 | O25: 0 | P25: 0 | Q25: 0 | R25: =SUM(G25-SUM(O25:Q25)) -> 60000 | S25: 0 | T25: 0 | U25: 0 | V25: =SUM(H25-SUM(S25:U25)) -> 281000 | W25: 67000 | X25: 63000 | Y25: 76000 | Z25: =SUM(I25-SUM(W25:Y25)) -> 88000 | AA25: 82000 | AB25: 72000 | AC25: 67000 | AE25: =SUM(L25:O25) -> 0 | AF25: =SUM(M25:P25) -> 0 | AG25: =SUM(N25:Q25) -> 0 | AH25: =SUM(O25:R25) -> 60000 | AI25: =SUM(P25:S25) -> 60000 | AJ25: =SUM(Q25:T25) -> 60000 | AK25: =SUM(R25:U25) -> 60000 | AL25: =SUM(S25:V25) -> 281000 | ... AS25: =SUM(Z25:AC25) -> 309000 | AU25: =SUM(AS25/AO25)-1 -> -0.36550308
B26: Interest Expense | C26: -420493 | D26: -626023 | E26: -767499 | F26: -765620 | G26: -706212 | H26: -699826 | I26: -718733 | K26: -194440 | L26: -191322 | M26: -190429 | N26: =SUM(F26-SUM(K26:M26)) -> -189429 | O26: -187579 | P26: -175455 | Q26: -172575 | R26: =SUM(G26-SUM(O26:Q26)) -> -170603 | S26: -174239 | T26: -174812 | U26: -175563 | V26: =SUM(H26-SUM(S26:U26)) -> -175212 | W26: -173314 | X26: -167986 | Y26: -184830 | Z26: =SUM(I26-SUM(W26:Y26)) -> -192603 | AA26: -184172 | AB26: -182649 | AC26: -175294 | AE26: =SUM(L26:O26) -> -758759 | AF26: =SUM(M26:P26) -> -742892 | AG26: =SUM(N26:Q26) -> -725038 | AH26: =SUM(O26:R26) -> -706212 | AI26: =SUM(P26:S26) -> -692872 | AJ26: =SUM(Q26:T26) -> -692229 | AK26: =SUM(R26:U26) -> -695217 | AL26: =SUM(S26:V26) -> -699826 | ... AS26: =SUM(Z26:AC26) -> -734718 | AU26: =SUM(AS26/AO26)-1 -> 0.047588766
B27: Other Income & Expenses | C27: 41725 | D27: 84000 | E27: -618441 | F27: 411214 | G27: =337310-G25 -> 277310 | H27: =-48772-H25 -> -329772 | I27: =266776-I25 -> -27224 | K27: 269086 | L27: -62519 | M27: 96135 | N27: =SUM(F27-SUM(K27:M27)) -> 108512 | O27: 195645 | P27: 220226 | Q27: 261404 | R27: =SUM(G27-SUM(O27:Q27)) -> -399965 | S27: -71204 | T27: 26961 | U27: 168218 | V27: =SUM(H27-SUM(S27:U27)) -> -453747 | W27: =155359-W25 -> 88359 | X27: =79005-X25 -> 16005 | Y27: =-21693-Y25 -> -97693 | Z27: =SUM(I27-SUM(W27:Y27)) -> -33895 | AA27: =50899-AA25 -> -31101 | AB27: =39630-AB25 -> -32370 | AC27: =36457-AC25 -> -30543 | AE27: =SUM(L27:O27) -> 337773 | AF27: =SUM(M27:P27) -> 620518 | AG27: =SUM(N27:Q27) -> 785787 | AH27: =SUM(O27:R27) -> 277310 | AI27: =SUM(P27:S27) -> 10461 | AJ27: =SUM(Q27:T27) -> -182804 | AK27: =SUM(R27:U27) -> -275990 | AL27: =SUM(S27:V27) -> -329772 | ... AS27: =SUM(Z27:AC27) -> -127909 | AU27: =SUM(AS27/AO27)-1 -> -0.71389876
B28: Earning Before Taxes | C28: =SUM(C22+SUM(C25:C27)) -> 1226458 | D28: =SUM(D22+SUM(D25:D27)) -> 2062231 | E28: =SUM(E22+SUM(E25:E27)) -> 3199349 | F28: =SUM(F22+SUM(F25:F27)) -> 5840103 | G28: =SUM(G22+SUM(G25:G27)) -> 5263929 | H28: =SUM(H22+SUM(H25:H27)) -> 6205405 | I28: =SUM(I22+SUM(I25:I27)) -> 9965657 | K28: =SUM(K22+SUM(K25:K27)) -> 2034502 | L28: =SUM(L22+SUM(L25:L27)) -> 1593789 | M28: =SUM(M22+SUM(M25:M27)) -> 1660959 | N28: =SUM(N22+SUM(N25:N27)) -> 550853 | O28: =SUM(O22+SUM(O25:O27)) -> 1979692 | P28: =SUM(P22+SUM(P25:P27)) -> 1623054 | Q28: =SUM(Q22+SUM(Q25:Q27)) -> 1621847 | R28: =SUM(R22+SUM(R25:R27)) -> 39336 | ... AC28: =SUM(AC22+SUM(AC25:AC27)) -> 3109410 | AE28: =SUM(AE22+SUM(AE25:AE27)) -> 5785293 | AF28: =SUM(AF22+SUM(AF25:AF27)) -> 5814558 | AG28: =SUM(AG22+SUM(AG25:AG27)) -> 5775446 | AH28: =SUM(AH22+SUM(AH25:AH27)) -> 5263929 | AI28: =SUM(AI22+SUM(AI25:AI27)) -> 4753111 | AJ28: =SUM(AJ22+SUM(AJ25:AJ27)) -> 4809389 | AK28: =SUM(AK22+SUM(AK25:AK27)) -> 5096591 | AL28: =SUM(AL22+SUM(AL25:AL27)) -> 6205405 | ... AS28: =SUM(AS22+SUM(AS25:AS27)) -> 12089079 | AU28: =SUM(AS28/AO28)-1 -> 0.34629172
B29: EBT Margin (%) | C29: =C28/C11 -> 0.077651736 | D29: =D28/D11 -> 0.10231124 | E29: =E28/E11 -> 0.12799415 | F29: =F28/F11 -> 0.19665074 | G29: =G28/G11 -> 0.1664981 | H29: =H28/H11 -> 0.18400944 | I29: =I28/I11 -> 0.25552334 | K29: =K28/K11 -> 0.28401814 | L29: =L28/L11 -> 0.21708491 | M29: =M28/M11 -> 0.22195047 | N29: =N28/N11 -> 0.071452883 | O29: =O28/O11 -> 0.25162057 | P29: =P28/P11 -> 0.20364182 | Q29: =Q28/Q11 -> 0.20463425 | R29: =R28/R11 -> 0.0050096452 | ... AC29: =AC28/AC11 -> 0.27014136 | AE29: =AE28/AE11 -> 0.19029111 | AF29: =AF28/AF11 -> 0.18738086 | AG29: =AG28/AG11 -> 0.18350586 | AH29: =AH28/AH11 -> 0.1664981 | AI29: =AI28/AI11 -> 0.14895698 | AJ29: =AJ28/AJ11 -> 0.14970187 | AK29: =AK28/AK11 -> 0.15565663 | AL29: =AL28/AL11 -> 0.18400944 | ... AS29: =AS28/AS11 -> 0.27868642 | AU29: =SUM(AS29-AO29)*1000 -> 39.788065
B31: Provision for taxes | C31: -15216 | D31: -195315 | E31: -437954 | F31: -723875 | G31: -772005 | H31: -797415 | I31: -1254026 | K31: -327787 | L31: -240776 | M31: -211888 | N31: =SUM(F31-SUM(K31:M31)) -> 56576 | O31: -382245 | P31: -182103 | Q31: -223605 | R31: =SUM(G31-SUM(O31:Q31)) -> 15948 | S31: -163754 | T31: -191722 | U31: -231627 | V31: =SUM(H31-SUM(S31:U31)) -> -210312 | W31: -282370 | X31: -366550 | Y31: -339445 | Z31: =SUM(I31-SUM(W31:Y31)) -> -265661 | AA31: -323375 | AB31: -506262 | AC31: -562494 | AE31: =SUM(L31:O31) -> -778333 | AF31: =SUM(M31:P31) -> -719660 | AG31: =SUM(N31:Q31) -> -731377 | AH31: =SUM(O31:R31) -> -772005 | AI31: =SUM(P31:S31) -> -553514 | AJ31: =SUM(Q31:T31) -> -563133 | AK31: =SUM(R31:U31) -> -571155 | AL31: =SUM(S31:V31) -> -797415 | ... AS31: =SUM(Z31:AC31) -> -1657792 | AU31: =SUM(AS31/AO31)-1 -> 0.38301811
B32: Net loss | C32: =SUM(C28+SUM(C31:C31)) -> 1211242 | D32: =SUM(D28+SUM(D31:D31)) -> 1866916 | E32: =SUM(E28+SUM(E31:E31)) -> 2761395 | F32: =SUM(F28+SUM(F31:F31)) -> 5116228 | G32: =SUM(G28+SUM(G31:G31)) -> 4491924 | H32: =SUM(H28+SUM(H31:H31)) -> 5407990 | I32: =SUM(I28+SUM(I31:I31)) -> 8711631 | K32: =SUM(K28+SUM(K31:K31)) -> 1706715 | L32: =SUM(L28+SUM(L31:L31)) -> 1353013 | M32: =SUM(M28+SUM(M31:M31)) -> 1449071 | N32: =SUM(N28+SUM(N31:N31)) -> 607429 | O32: =SUM(O28+SUM(O31:O31)) -> 1597447 | P32: =SUM(P28+SUM(P31:P31)) -> 1440951 | Q32: =SUM(Q28+SUM(Q31:Q31)) -> 1398242 | R32: =SUM(R28+SUM(R31:R31)) -> 55284 | ... AC32: =SUM(AC28+SUM(AC31:AC31)) -> 2546916 | AE32: =SUM(AE28+SUM(AE31:AE31)) -> 5006960 | AF32: =SUM(AF28+SUM(AF31:AF31)) -> 5094898 | AG32: =SUM(AG28+SUM(AG31:AG31)) -> 5044069 | AH32: =SUM(AH28+SUM(AH31:AH31)) -> 4491924 | AI32: =SUM(AI28+SUM(AI31:AI31)) -> 4199597 | AJ32: =SUM(AJ28+SUM(AJ31:AJ31)) -> 4246256 | AK32: =SUM(AK28+SUM(AK31:AK31)) -> 4525436 | AL32: =SUM(AL28+SUM(AL31:AL31)) -> 5407990 | ... AS32: =SUM(AS28+SUM(AS31:AS31)) -> 10431287 | AU32: =SUM(AS32/AO32)-1 -> 0.34063385
B33: Net Margin (%) | C33: =C32/C11 -> 0.076688353 | D33: =D32/D11 -> 0.092621284 | E33: =E32/E11 -> 0.11047323 | F33: =F32/F11 -> 0.17227607 | G33: =G32/G11 -> 0.14207958 | H33: =H32/H11 -> 0.16036362 | I33: =I32/I11 -> 0.22336962 | K33: =K32/K11 -> 0.2382588 | L33: =L32/L11 -> 0.18428958 | M33: =M32/M11 -> 0.19363632 | N33: =N32/N11 -> 0.078791535 | O33: =O32/O11 -> 0.2030369 | P33: =P32/P11 -> 0.18079366 | Q33: =Q32/Q11 -> 0.17642121 | R33: =R32/R11 -> 0.0070407064 | ... AC33: =AC32/AC11 -> 0.22127264 | AE33: =AE32/AE11 -> 0.16469001 | AF33: =AF32/AF11 -> 0.16418899 | AG33: =AG32/AG11 -> 0.16026749 | AH33: =AH32/AH11 -> 0.14207958 | AI33: =AI32/AI11 -> 0.1316105 | AJ33: =AJ32/AJ11 -> 0.13217323 | AK33: =AK32/AK11 -> 0.1382128 | AL33: =AL32/AL11 -> 0.16036362 | ... AS33: =AS32/AS11 -> 0.24046977 | AU33: =SUM(AS33-AO33)*1000 -> 33.461911
B35: Basic EPS | AU35: =SUM(AS35/AO35)-1 -> #DIV/0!
B36: Fully Diluted EPS | AU36: =SUM(AS36/AO36)-1 -> #DIV/0!
A38: X | B38: Balance Sheet | AN38: LTM | AU38: Variance
B39: =B7 -> Fiscal Period | C39: =C7 -> 2018 | D39: =D7 -> 2019 | E39: =E7 -> 2020 | F39: =F7 -> 2021 | G39: =G7 -> 2022 | H39: =H7 -> 2023 | I39: =I7 -> 2024 | K39: =K7 -> 1Q21 | L39: =L7 -> 2Q21 | M39: =M7 -> 3Q21 | N39: =N7 -> 4Q21 | O39: =O7 -> 1Q22 | P39: =P7 -> 2Q22 | Q39: =Q7 -> 3Q22 | R39: =R7 -> 4Q22 | ... AC39: =AC7 -> 3Q25 | AE39: =AE7 -> 1Q22 | AF39: =AF7 -> 2Q22 | AG39: =AG7 -> 3Q22 | AH39: =AH7 -> 4Q22 | AI39: =AI7 -> 1Q23 | AJ39: =AJ7 -> 2Q23 | AK39: =AK7 -> 3Q23 | AL39: =AL7 -> 4Q23 | ... AS39: =AS7 -> 3Q25
B40: =B8 -> Fiscal Period End Date | C40: =C8 -> 43465 | D40: =D8 -> 43830 | E40: =E8 -> 44196 | F40: =F8 -> 44561 | G40: =G8 -> 44926 | H40: =H8 -> 45291 | I40: =I8 -> 45657 | K40: =K8 -> 44286 | L40: =L8 -> 44377 | M40: =M8 -> 44469 | N40: =N8 -> 44561 | O40: =O8 -> 44651 | P40: =P8 -> 44742 | Q40: =Q8 -> 44834 | R40: =R8 -> 44926 | ... AC40: =AC8 -> 45930 | AE40: =AE8 -> 44651 | AF40: =AF8 -> 44742 | AG40: =AG8 -> 44834 | AH40: =AH8 -> 44926 | AI40: =AI8 -> 45016 | AJ40: =AJ8 -> 45107 | AK40: =AK8 -> 45199 | AL40: =AL8 -> 45291 | ... AS40: =AS8 -> 45930
B42: Current Assets
B43: Cash and cash equivalents | C43: 3794483 | D43: 5018437 | E43: 8205550 | F43: 6027804 | G43: 5147176 | H43: 7116913 | I43: 7804733 | K43: 8403705 | L43: 7777530 | M43: 7526681 | N43: =F43 -> 6027804 | O43: 6008946 | P43: 5819449 | Q43: 6113733 | R43: =G43 -> 5147176 | S43: 6714594 | T43: 7662788 | U43: 7353245 | V43: =H43 -> 7116913 | W43: 7024766 | X43: 6624939 | Y43: 7457025 | Z43: =I43 -> 7804733 | AA43: 7199848 | AB43: 8177405 | AC43: 9287287 | AE43: =O43 -> 6008946 | AF43: =P43 -> 5819449 | AG43: =Q43 -> 6113733 | AH43: =R43 -> 5147176 | AI43: =S43 -> 6714594 | AJ43: =T43 -> 7662788 | AK43: =U43 -> 7353245 | AL43: =V43 -> 7116913 | ... AS43: =AC43 -> 9287287 | AU43: =SUM(AS43/AO43)-1 -> 0.24544131
B44: Other current assets | C44: 748466 | D44: 1160067 | E44: 1556030 | F44: 2042021 | G44: 3208021 | H44: 2780247 | I44: 3516640 | K44: 1703803 | L44: 1826746 | M44: 1889106 | N44: =F44 -> 2042021 | O44: 2089069 | P44: 2021329 | Q44: 2703170 | R44: =G44 -> 3208021 | S44: 2655119 | T44: 2929347 | U44: 2912028 | V44: =H44 -> 2780247 | W44: 2875574 | X44: 2959641 | Y44: 2905172 | Z44: =I44 -> 3516640 | AA44: 3326642 | AB44: 3602586 | AC44: 3638543 | AE44: =O44 -> 2089069 | AF44: =P44 -> 2021329 | AG44: =Q44 -> 2703170 | AH44: =R44 -> 3208021 | AI44: =S44 -> 2655119 | AJ44: =T44 -> 2929347 | AK44: =U44 -> 2912028 | AL44: =V44 -> 2780247 | ... AS44: =AC44 -> 3638543 | AU44: =SUM(AS44/AO44)-1 -> 0.25243634
B45: Short-term investments | C45: 0 | D45: 0 | E45: 0 | F45: 0 | G45: 911276 | H45: 20973 | I45: 1779006 | K45: 0 | L45: 0 | M45: 0 | N45: =F45 -> 0 | O45: 0 | P45: 0 | Q45: 0 | R45: =G45 -> 911276 | S45: 1112910 | T45: 914201 | U45: 514201 | V45: =H45 -> 20973 | W45: 20973 | X45: 30973 | Y45: 1766902 | Z45: =I45 -> 1779006 | AA45: 1171142 | AB45: 213115 | AC45: 37105 | AE45: =O45 -> 0 | AF45: =P45 -> 0 | AG45: =Q45 -> 0 | AH45: =R45 -> 911276 | AI45: =S45 -> 1112910 | AJ45: =T45 -> 914201 | AK45: =U45 -> 514201 | AL45: =V45 -> 20973 | ... AS45: =AC45 -> 37105 | AU45: =SUM(AS45/AO45)-1 -> -0.97899997
B46: Total Current Assets | C46: =SUM(C43:C45) -> 4542949 | D46: =SUM(D43:D45) -> 6178504 | E46: =SUM(E43:E45) -> 9761580 | F46: =SUM(F43:F45) -> 8069825 | G46: =SUM(G43:G45) -> 9266473 | H46: =SUM(H43:H45) -> 9918133 | I46: =SUM(I43:I45) -> 13100379 | K46: =SUM(K43:K45) -> 10107508 | L46: =SUM(L43:L45) -> 9604276 | M46: =SUM(M43:M45) -> 9415787 | N46: =SUM(N43:N45) -> 8069825 | O46: =SUM(O43:O45) -> 8098015 | P46: =SUM(P43:P45) -> 7840778 | Q46: =SUM(Q43:Q45) -> 8816903 | R46: =SUM(R43:R45) -> 9266473 | ... AC46: =SUM(AC43:AC45) -> 12962935 | AE46: =SUM(AE43:AE45) -> 8098015 | AF46: =SUM(AF43:AF45) -> 7840778 | AG46: =SUM(AG43:AG45) -> 8816903 | AH46: =SUM(AH43:AH45) -> 9266473 | AI46: =SUM(AI43:AI45) -> 10482623 | AJ46: =SUM(AJ43:AJ45) -> 11506336 | AK46: =SUM(AK43:AK45) -> 10779474 | AL46: =SUM(AL43:AL45) -> 9918133 | ... AS46: =SUM(AS43:AS45) -> 12962935 | AU46: =SUM(AS46/AO46)-1 -> 0.068746739
B48: Non-Current Assets
B49: Content assets, net | C49: 20102327 | D49: 24504567 | E49: 25383950 | F49: 30919539 | G49: 32736713 | H49: 31658056 | I49: 32452462 | K49: 26043991 | L49: 27291640 | M49: 28974045 | N49: =F49 -> 30919539 | O49: 31191920 | P49: 32533199 | Q49: 32777340 | R49: =G49 -> 32736713 | S49: 32349184 | T49: 32520774 | U49: 31749861 | V49: =H49 -> 31658056 | W49: 31662100 | X49: 31927355 | Y49: 32175382 | Z49: =I49 -> 32452462 | AA49: 32040839 | AB49: 32089394 | AC49: 32639879 | AE49: =O49 -> 31191920 | AF49: =P49 -> 32533199 | AG49: =Q49 -> 32777340 | AH49: =R49 -> 32736713 | AI49: =S49 -> 32349184 | AJ49: =T49 -> 32520774 | AK49: =U49 -> 31749861 | AL49: =V49 -> 31658056 | ... AS49: =AC49 -> 32639879 | AU49: =SUM(AS49/AO49)-1 -> 0.01443641
B50: Property and equipment, net | C50: 418281 | D50: 565221 | E50: 960183 | F50: 1323453 | G50: 1398257 | H50: 1491444 | I50: 1593756 | K50: 1015419 | L50: 1107437 | M50: 1220114 | N50: =F50 -> 1323453 | O50: 1383763 | P50: 1361920 | Q50: 1372754 | R50: =G50 -> 1398257 | S50: 1413094 | T50: 1471968 | U50: 1498391 | V50: =H50 -> 1491444 | W50: 1501168 | X50: 1510958 | Y50: 1568212 | Z50: =I50 -> 1593756 | AA50: 1644346 | AB50: 1743566 | AC50: 1837889 | AE50: =O50 -> 1383763 | AF50: =P50 -> 1361920 | AG50: =Q50 -> 1372754 | AH50: =R50 -> 1398257 | AI50: =S50 -> 1413094 | AJ50: =T50 -> 1471968 | AK50: =U50 -> 1498391 | AL50: =V50 -> 1491444 | ... AS50: =AC50 -> 1837889 | AU50: =SUM(AS50/AO50)-1 -> 0.17196463
B51: Other non-current assets | C51: 910843 | D51: 2727420 | E51: 3174646 | F51: 4271846 | G51: 5193325 | H51: 5664359 | I51: 6483777 | K51: 2956096 | L51: 2967616 | M51: 3129911 | N51: =F51 -> 4271846 | O51: 4657206 | P51: 4615038 | Q51: 4595190 | R51: =G51 -> 5193325 | S51: 5245444 | T51: 5318395 | U51: 5474060 | V51: =H51 -> 5664359 | W51: 5743140 | X51: 6045029 | Y51: 6409151 | Z51: =I51 -> 6483777 | AA51: 6704827 | AB51: 7273598 | AC51: 7494132 | AE51: =O51 -> 4657206 | AF51: =P51 -> 4615038 | AG51: =Q51 -> 4595190 | AH51: =R51 -> 5193325 | AI51: =S51 -> 5245444 | AJ51: =T51 -> 5318395 | AK51: =U51 -> 5474060 | AL51: =V51 -> 5664359 | ... AS51: =AC51 -> 7494132 | AU51: =SUM(AS51/AO51)-1 -> 0.16928623
...

Sheet EPS
B2: ='Historical Financials'!B2 -> Netflix, Inc. (NASDAQ: NFLX)
B3: EPS Build-Up
B4: ($ in Bns, Including Shares)
B6: Stock Split Converter | C6: 1
B7: Stock Split Amount | C7: 20
B8: Stock Split End Period | C8: 2Q22
B10: Net Income Per Share | G10: FYE | O10: Quarterly | Y10: Quarterly | AO10: LTM | AP10: LTM
B11: Fiscal Period | C11: 2018 | D11: 2019 | E11: 2020 | F11: 2021 | G11: 2022 | H11: 2023 | I11: 2024 | K11: 1Q21 | L11: 2Q21 | M11: 3Q21 | N11: 4Q21 | O11: 1Q22 | P11: 2Q22 | Q11: 3Q22 | R11: 4Q22 | S11: 1Q23 | T11: 2Q23 | U11: 3Q23 | V11: 4Q23 | W11: 1Q24 | X11: 2Q24 | Y11: 3Q24 | Z11: 4Q24 | AA11: 1Q25 | AB11: 2Q25 | AC11: 3Q25 | AE11: =N11 -> 4Q21 | AF11: =O11 -> 1Q22 | AG11: =P11 -> 2Q22 | AH11: =Q11 -> 3Q22 | AI11: =R11 -> 4Q22 | AJ11: =S11 -> 1Q23 | AK11: =T11 -> 2Q23 | AL11: =U11 -> 3Q23 | ... AT11: =AC11 -> 3Q25
B12: Fiscal Period End Date | C12: 43465 | D12: 43830 | E12: 44196 | F12: 44561 | G12: 44926 | H12: 45291 | I12: 45657 | K12: 44289 | L12: 44380 | M12: 44471 | N12: 44561 | O12: 44653 | P12: 44744 | Q12: 44835 | R12: 44926 | S12: 45017 | T12: 45108 | U12: 45199 | V12: 45291 | W12: 45381 | X12: 45472 | Y12: 45563 | Z12: 45657 | AA12: 45745 | AB12: 45836 | AC12: 45927 | AE12: =N12 -> 44561 | AF12: =O12 -> 44653 | AG12: =P12 -> 44744 | AH12: =Q12 -> 44835 | AI12: =R12 -> 44926 | AJ12: =S12 -> 45017 | AK12: =T12 -> 45108 | AL12: =U12 -> 45199 | ... AT12: =AC12 -> 45927
A14: X | B14: Consolidated Basic EPS
B16: Consolidated Allocation of undistributed earnings | C16: =C29+C35+C41 -> 0 | D16: =D29+D35+D41 -> 0 | E16: =E29+E35+E41 -> 0 | F16: =F29+F35+F41 -> 0 | G16: =G29+G35+G41 -> 0 | H16: =H29+H35+H41 -> 0 | I16: =I29+I35+I41 -> 0 | K16: =K29+K35+K41 -> 17930 | L16: =L29+L35+L41 -> 18525 | M16: =M29+M35+M41 -> 18936 | N16: =N29+N35+N41 -> -55391 | O16: =O29+O35+O41 -> 16436 | P16: =P29+P35+P41 -> 16002 | Q16: =Q29+Q35+Q41 -> 13910 | R16: =R29+R35+R41 -> -46348 | ... AC16: =AC29+AC35+AC41 -> 34979 | AE16: =AE29+AE35+AE41 -> 0 | AF16: =AF29+AF35+AF41 -> -1494 | AG16: =AG29+AG35+AG41 -> -4017 | AH16: =AH29+AH35+AH41 -> -9043 | AI16: =AI29+AI35+AI41 -> 0 | AJ16: =AJ29+AJ35+AJ41 -> -1385 | AK16: =AK29+AK35+AK41 -> 981 | AL16: =AL29+AL35+AL41 -> 6760 | ... AT16: =AT29+AT35+AT41 -> 24133
B17: Consolidated Basic Shares | C17: =IF($C$6=1,C30+C35+C41,C31+C37+C43) -> 0 | D17: =IF($C$6=1,D30+D35+D41,D31+D37+D43) -> 0 | E17: =IF($C$6=1,E30+E35+E41,E31+E37+E43) -> 0 | F17: =IF($C$6=1,F30+F36+F42,F31+F37+F43) -> 0 | G17: =IF($C$6=1,G30+G36+G42,G31+G37+G43) -> 0 | H17: =IF($C$6=1,H30+H36+H42,H31+H37+H43) -> 0 | I17: =IF($C$6=1,I30+I36+I42,I31+I37+I43) -> 0 | K17: =IF($C$6=1,K30+K36+K42,K31+K37+K43) -> 13464.4 | L17: =IF($C$6=1,L30+L36+L42,L31+L37+L43) -> 13379.16 | M17: =IF($C$6=1,M30+M36+M42,M31+M37+M43) -> 13315.16 | N17: =IF($C$6=1,N30+N36+N42,N31+N37+N43) -> 0 | O17: =IF($C$6=1,O30+O36+O42,O31+O37+O43) -> 13203.42 | P17: =IF($C$6=1,P30+P36+P42,P31+P37+P43) -> 13133 | Q17: =IF($C$6=1,Q30+Q36+Q42,Q31+Q37+Q43) -> 13018 | R17: =IF($C$6=1,R30+R36+R42,R31+R37+R43) -> 0 | ... AC17: =IF($C$6=1,AC30+AC36+AC42,AC31+AC37+AC43) -> 12086 | AE17: =IF($C$6=1,AE30+AE36+AE42,AE31+AE37+AE43) -> 0 | AF17: =IF($C$6=1,AF30+AF36+AF42,AF31+AF37+AF43) -> 13203.42 | AG17: =IF($C$6=1,AG30+AG36+AG42,AG31+AG37+AG43) -> 13133 | AH17: =IF($C$6=1,AH30+AH36+AH42,AH31+AH37+AH43) -> 13018 | AI17: =IF($C$6=1,AI30+AI36+AI42,AI31+AI37+AI43) -> 0 | AJ17: =IF($C$6=1,AJ30+AJ36+AJ42,AJ31+AJ37+AJ43) -> 12781 | AK17: =IF($C$6=1,AK30+AK36+AK42,AK31+AK37+AK43) -> 12668 | AL17: =IF($C$6=1,AL30+AL36+AL42,AL31+AL37+AL43) -> 12581 | ... AT17: =IF($C$6=1,AT30+AT36+AT42,AT31+AT37+AT43) -> 12086
B18: Consolidated Basic EPS | C18: =C16/C17 -> #DIV/0! | D18: =D16/D17 -> #DIV/0! | E18: =E16/E17 -> #DIV/0! | F18: =F16/F17 -> #DIV/0! | G18: =G16/G17 -> #DIV/0! | H18: =H16/H17 -> #DIV/0! | I18: =I16/I17 -> #DIV/0! | K18: =K16/K17 -> 1.3316598 | L18: =L16/L17 -> 1.3846161 | M18: =M16/M17 -> 1.4221384 | N18: =N16/N17 -> #DIV/0! | O18: =O16/O17 -> 1.244829 | P18: =P16/P17 -> 1.2184573 | Q18: =Q16/Q17 -> 1.0685205 | R18: =R16/R17 -> #DIV/0! | ... AC18: =AC16/AC17 -> 2.8941751 | AE18: =AE16/AE17 -> #DIV/0! | AF18: =AF16/AF17 -> -0.1131525 | AG18: =AG16/AG17 -> -0.30587071 | AH18: =AH16/AH17 -> -0.69465356 | AI18: =AI16/AI17 -> #DIV/0! | AJ18: =AJ16/AJ17 -> -0.10836398 | AK18: =AK16/AK17 -> 0.077439217 | AL18: =AL16/AL17 -> 0.53731818 | ... AT18: =AT16/AT17 -> 1.9967731
A20: X | B20: Consolidated Fully Diluted EPS
B22: Consolidated Allocation of undistributed earnings | C22: =+C49+C58+C64 -> 0 | D22: =+D49+D58+D64 -> 0 | E22: =+E49+E58+E64 -> 0 | F22: =+F49+F58+F64 -> 0 | G22: =+G49+G58+G64 -> 0 | H22: =+H49+H58+H64 -> 0 | I22: =+I49+I58+I64 -> 0 | K22: =+K49+K58+K64 -> 19135 | L22: =+L49+L58+L64 -> 19771 | M22: =+M49+M58+M64 -> 20207 | N22: =+N49+N58+N64 -> -59113 | O22: =+O49+O58+O64 -> 17533 | P22: =+P49+P58+P64 -> 17074 | Q22: =+Q49+Q58+Q64 -> 14850 | R22: =+R49+R58+R64 -> -49457 | ... AC22: =+AC49+AC58+AC64 -> 37402 | AE22: =+AE49+AE58+AE64 -> 0 | AF22: =+AF49+AF58+AF64 -> -1602 | AG22: =+AG49+AG58+AG64 -> -4299 | AH22: =+AH49+AH58+AH64 -> -9656 | AI22: =+AI49+AI58+AI64 -> 0 | AJ22: =+AJ49+AJ58+AJ64 -> -1446 | AK22: =+AK49+AK58+AK64 -> 1113 | AL22: =+AL49+AL58+AL64 -> 7309 | ... AT22: =+AT49+AT58+AT64 -> 25827
B23: Consolidated Fully Diluted Shares | C23: =+C50+C59+C65 -> 0 | D23: =+D50+D59+D65 -> 0 | E23: =+E50+E59+E65 -> 0 | F23: =+F50+F59+F65 -> 0 | G23: =+G50+G59+G65 -> 0 | H23: =+H50+H59+H65 -> 0 | I23: =+I50+I59+I65 -> 0 | K23: =+K50+K59+K65 -> 14558.22 | L23: =+L50+L59+L65 -> 14506.08 | M23: =+M50+M59+M65 -> 14438.46 | N23: =+N50+N59+N65 -> -605.32 | O23: =+O50+O59+O65 -> 14241.72 | P23: =+P50+P59+P65 -> 14126 | Q23: =+Q50+Q59+Q65 -> 13982 | R23: =+R50+R59+R65 -> 0 | ... AC23: =+AC50+AC59+AC65 -> 13048 | AE23: =+AE50+AE59+AE65 -> -604.427 | AF23: =+AF50+AF59+AF65 -> 14241.625 | AG23: =+AG50+AG59+AG65 -> 14126 | AH23: =+AH50+AH59+AH65 -> 13982 | AI23: =+AI50+AI59+AI65 -> 0 | AJ23: =+AJ50+AJ59+AJ65 -> 13706 | AK23: =+AK50+AK59+AK65 -> 13616 | AL23: =+AL50+AL59+AL65 -> 13571 | ... AT23: =+AT50+AT59+AT65 -> 13048
B24: Consolidated Basic EPS | C24: =C22/C23 -> #DIV/0! | D24: =D22/D23 -> #DIV/0! | E24: =E22/E23 -> #DIV/0! | F24: =F22/F23 -> #DIV/0! | G24: =G22/G23 -> #DIV/0! | H24: =H22/H23 -> #DIV/0! | I24: =I22/I23 -> #DIV/0! | K24: =K22/K23 -> 1.3143777 | L24: =L22/L23 -> 1.3629457 | M24: =M22/M23 -> 1.399526 | N24: =N22/N23 -> 97.655785 | O24: =O22/O23 -> 1.2311013 | P24: =P22/P23 -> 1.2086932 | Q24: =Q22/Q23 -> 1.0620798 | R24: =R22/R23 -> #DIV/0! | ... AC24: =AC22/AC23 -> 2.8664929 | AE24: =AE22/AE23 -> 0 | AF24: =AF22/AF23 -> -0.11248716 | AG24: =AG22/AG23 -> -0.30433244 | AH24: =AH22/AH23 -> -0.6906022 | AI24: =AI22/AI23 -> #DIV/0! | AJ24: =AJ22/AJ23 -> -0.10550124 | AK24: =AK22/AK23 -> 0.081742068 | AL24: =AL22/AL23 -> 0.5385749 | ... AT24: =AT22/AT23 -> 1.9793838
A26: X | B26: Basic EPS Per Share Class
B28: Class A
B29: Allocation of undistributed earnings | K29: 8011 | L29: 8321 | M29: 8548 | N29: =SUM(F29-SUM(K29:M29)) -> -24880 | O29: 7481 | P29: 7329 | Q29: 6393 | R29: =SUM(G29-SUM(O29:Q29)) -> -21203 | S29: 7006 | T29: 8600 | U29: 9271 | V29: =SUM(H29-SUM(S29:U29)) -> -24877 | W29: 11213 | X29: 11219 | Y29: 12521 | Z29: =SUM(I29-SUM(W29:Y29)) -> -34953 | AA29: 16534 | AB29: 13536 | AC29: 16839 | AE29: =SUM(K29:N29) -> 0 | AF29: =SUM(L29:O29) -> -530 | AG29: =SUM(M29:P29) -> -1522 | AH29: =SUM(N29:Q29) -> -3677 | AI29: =SUM(O29:R29) -> 0 | AJ29: =SUM(P29:S29) -> -475 | AK29: =SUM(Q29:T29) -> 796 | AL29: =SUM(R29:U29) -> 3674 | ... AT29: =SUM(Z29:AC29) -> 11956
B30: Stock Split Adjusted Basic Shares | C30: =IF($C$6=1,C31*20,C31) -> 0 | D30: =IF($C$6=1,D31*20,D31) -> 0 | E30: =IF($C$6=1,E31*20,E31) -> 0 | F30: =IF($C$6=1,F31*20,F31) -> 0 | G30: =G31 -> 0 | H30: =H31 -> 0 | I30: =I31 -> 0 | K30: =IF($C$6=1,K31*20,K31) -> 6016 | L30: =IF($C$6=1,L31*20,L31) -> 6009.7 | M30: =IF($C$6=1,M31*20,M31) -> 6010.38 | N30: =IF($C$6=1,N31*20,N31) -> 0 | O30: =IF($C$6=1,O31*20,O31) -> 6009.56 | P30: =P31 -> 6015 | Q30: =Q31 -> 5983 | R30: =R31 -> 0 | S30: =S31 -> 5949 | T30: =T31 -> 5931 | U30: =U31 -> 5924 | V30: =V31 -> 0 | W30: =W31 -> 5883 | ... AC30: =AC31 -> 5818 | AE30: =N30 -> 0 | AF30: =O30 -> 6009.56 | AG30: =P30 -> 6015 | AH30: =Q30 -> 5983 | AI30: =R30 -> 0 | AJ30: =S30 -> 5949 | AK30: =T30 -> 5931 | AL30: =U30 -> 5924 | ... AT30: =AC30 -> 5818
B31: Unadjusted Basic Shares | K31: 300.8 | L31: 300.485 | M31: 300.519 | N31: =F31 -> 0 | O31: 300.478 | P31: 6015 | Q31: 5983 | R31: =G31 -> 0 | S31: 5949 | T31: 5931 | U31: 5924 | V31: =H31 -> 0 | W31: 5883 | X31: 5862 | Y31: 5850 | Z31: =I31 -> 0 | AA31: 5831 | AB31: 5819 | AC31: 5818 | AE31: =N31 -> 0 | AF31: =O31 -> 300.478 | AG31: =P31 -> 6015 | AH31: =Q31 -> 5983 | AI31: =R31 -> 0 | AJ31: =S31 -> 5949 | AK31: =T31 -> 5931 | AL31: =U31 -> 5924 | ... AT31: =AC31 -> 5818
B32: Class A Basic EPS | C32: =IF($C$6=1, C29/C30,C29/C31) -> #DIV/0! | D32: =IF($C$6=1, D29/D30,D29/D31) -> #DIV/0! | E32: =IF($C$6=1, E29/E30,E29/E31) -> #DIV/0! | F32: =IF($C$6=1, F29/F30,F29/F31) -> #DIV/0! | G32: =IF($C$6=1, G29/G30,G29/G31) -> #DIV/0! | H32: =IF($C$6=1, H29/H30,H29/H31) -> #DIV/0! | I32: =IF($C$6=1, I29/I30,I29/I31) -> #DIV/0! | K32: =IF($C$6=1, K29/K30,K29/K31) -> 1.3316157 | L32: =IF($C$6=1, L29/L30,L29/L31) -> 1.3845949 | M32: =IF($C$6=1, M29/M30,M29/M31) -> 1.4222062 | N32: =IF($C$6=1, N29/N30,N29/N31) -> #DIV/0! | O32: =IF($C$6=1, O29/O30,O29/O31) -> 1.2448499 | P32: =IF($C$6=1, P29/P30,P29/P31) -> 1.2184539 | Q32: =IF($C$6=1, Q29/Q30,Q29/Q31) -> 1.0685275 | R32: =IF($C$6=1, R29/R30,R29/R31) -> #DIV/0! | ... AC32: =IF($C$6=1, AC29/AC30,AC29/AC31) -> 2.8942936 | AE32: =IF($C$6=1, AE29/AE30,AE29/AE31) -> #DIV/0! | AF32: =IF($C$6=1, AF29/AF30,AF29/AF31) -> -0.088192813 | AG32: =IF($C$6=1, AG29/AG30,AG29/AG31) -> -0.25303408 | AH32: =IF($C$6=1, AH29/AH30,AH29/AH31) -> -0.61457463 | AI32: =IF($C$6=1, AI29/AI30,AI29/AI31) -> #DIV/0! | AJ32: =IF($C$6=1, AJ29/AJ30,AJ29/AJ31) -> -0.079845352 | AK32: =IF($C$6=1, AK29/AK30,AK29/AK31) -> 0.13421008 | AL32: =IF($C$6=1, AL29/AL30,AL29/AL31) -> 0.62018906 | ... AT32: =IF($C$6=1, AT29/AT30,AT29/AT31) -> 2.0550017
B34: Class B
B35: Allocation of undistributed earnings | K35: 1221 | L35: 1265 | M35: 1291 | N35: =SUM(F35-SUM(K35:M35)) -> -3777 | O35: 1109 | P35: 1081 | Q35: 946 | R35: =SUM(G35-SUM(O35:Q35)) -> -3136 | S35: 1040 | T35: 1275 | U35: 1369 | V35: =SUM(H35-SUM(S35:U35)) -> -3684 | W35: 1656 | X35: 1657 | Y35: 1851 | Z35: =SUM(I35-SUM(W35:Y35)) -> -5164 | AA35: 2435 | AB35: 1981 | AC35: 2445 | AE35: =SUM(K35:N35) -> 0 | AF35: =SUM(L35:O35) -> -112 | AG35: =SUM(M35:P35) -> -296 | AH35: =SUM(N35:Q35) -> -641 | AI35: =SUM(O35:R35) -> 0 | AJ35: =SUM(P35:S35) -> -69 | AK35: =SUM(Q35:T35) -> 125 | AL35: =SUM(R35:U35) -> 548 | ... AT35: =SUM(Z35:AC35) -> 1697
B36: Stock Split Adjusted Basic Shares | C36: =IF($C$6=1,C37*20,C37) -> 0 | D36: =IF($C$6=1,D37*20,D37) -> 0 | E36: =IF($C$6=1,E37*20,E37) -> 0 | F36: =IF($C$6=1,F37*20,F37) -> 0 | G36: =G37 -> 0 | H36: =H37 -> 0 | I36: =I37 -> 0 | K36: =IF($C$6=1,K37*20,K37) -> 916.8 | L36: =IF($C$6=1,L37*20,L37) -> 913.84 | M36: =IF($C$6=1,M37*20,M37) -> 908.08 | N36: =IF($C$6=1,N37*20,N37) -> 0 | O36: =IF($C$6=1,O37*20,O37) -> 890.7 | P36: =P37 -> 887 | Q36: =Q37 -> 885 | R36: =R37 -> 0 | S36: =S37 -> 883 | T36: =T37 -> 879 | U36: =U37 -> 875 | V36: =V37 -> 0 | W36: =W37 -> 869 | ... AC36: =AC37 -> 845 | AE36: =N36 -> 0 | AF36: =O36 -> 890.7 | AG36: =P36 -> 887 | AH36: =Q36 -> 885 | AI36: =R36 -> 0 | AJ36: =S36 -> 883 | AK36: =T36 -> 879 | AL36: =U36 -> 875 | ... AT36: =AC36 -> 845
B37: Unadjusted Basic Shares | K37: 45.84 | L37: 45.692 | M37: 45.404 | N37: =F37 -> 0 | O37: 44.535 | P37: 887 | Q37: 885 | R37: =G37 -> 0 | S37: 883 | T37: 879 | U37: 875 | V37: =H37 -> 0 | W37: 869 | X37: 866 | Y37: 865 | Z37: =I37 -> 0 | AA37: 859 | AB37: 852 | AC37: 845 | AE37: =N37 -> 0 | AF37: =O37 -> 44.535 | AG37: =P37 -> 887 | AH37: =Q37 -> 885 | AI37: =R37 -> 0 | AJ37: =S37 -> 883 | AK37: =T37 -> 879 | AL37: =U37 -> 875 | ... AT37: =AC37 -> 845
B38: Class B Basic EPS | C38: =IF($C$6=1, C35/C36,C35/C37) -> #DIV/0! | D38: =IF($C$6=1, D35/D36,D35/D37) -> #DIV/0! | E38: =IF($C$6=1, E35/E36,E35/E37) -> #DIV/0! | F38: =IF($C$6=1, F35/F36,F35/F37) -> #DIV/0! | G38: =IF($C$6=1, G35/G36,G35/G37) -> #DIV/0! | H38: =IF($C$6=1, H35/H36,H35/H37) -> #DIV/0! | I38: =IF($C$6=1, I35/I36,I35/I37) -> #DIV/0! | K38: =IF($C$6=1, K35/K36,K35/K37) -> 1.3318063 | L38: =IF($C$6=1, L35/L36,L35/L37) -> 1.3842686 | M38: =IF($C$6=1, M35/M36,M35/M37) -> 1.4216809 | N38: =IF($C$6=1, N35/N36,N35/N37) -> #DIV/0! | O38: =IF($C$6=1, O35/O36,O35/O37) -> 1.2450881 | P38: =IF($C$6=1, P35/P36,P35/P37) -> 1.2187148 | Q38: =IF($C$6=1, Q35/Q36,Q35/Q37) -> 1.0689266 | R38: =IF($C$6=1, R35/R36,R35/R37) -> #DIV/0! | ... AC38: =IF($C$6=1, AC35/AC36,AC35/AC37) -> 2.8934911 | AE38: =IF($C$6=1, AE35/AE36,AE35/AE37) -> #DIV/0! | AF38: =IF($C$6=1, AF35/AF36,AF35/AF37) -> -0.1257438 | AG38: =IF($C$6=1, AG35/AG36,AG35/AG37) -> -0.33370913 | AH38: =IF($C$6=1, AH35/AH36,AH35/AH37) -> -0.72429379 | AI38: =IF($C$6=1, AI35/AI36,AI35/AI37) -> #DIV/0! | AJ38: =IF($C$6=1, AJ35/AJ36,AJ35/AJ37) -> -0.078142695 | AK38: =IF($C$6=1, AK35/AK36,AK35/AK37) -> 0.14220705 | AL38: =IF($C$6=1, AL35/AL36,AL35/AL37) -> 0.62628571 | ... AT38: =IF($C$6=1, AT35/AT36,AT35/AT37) -> 2.008284
B40: Class C
B41: Allocation of undistributed earnings | K41: 8698 | L41: 8939 | M41: 9097 | N41: =SUM(F41-SUM(K41:M41)) -> -26734 | O41: 7846 | P41: 7592 | Q41: 6571 | R41: =SUM(G41-SUM(O41:Q41)) -> -22009 | S41: 7005 | T41: 8493 | U41: 9049 | V41: =SUM(H41-SUM(S41:U41)) -> -24547 | W41: 10793 | X41: 10743 | Y41: 11929 | Z41: =SUM(I41-SUM(W41:Y41)) -> -33465 | AA41: 15571 | AB41: 12679 | AC41: 15695 | AE41: =SUM(K41:N41) -> 0 | AF41: =SUM(L41:O41) -> -852 | AG41: =SUM(M41:P41) -> -2199 | AH41: =SUM(N41:Q41) -> -4725 | AI41: =SUM(O41:R41) -> 0 | AJ41: =SUM(P41:S41) -> -841 | AK41: =SUM(Q41:T41) -> 60 | AL41: =SUM(R41:U41) -> 2538 | ... AT41: =SUM(Z41:AC41) -> 10480
B42: Stock Split Adjusted Basic Shares | C42: =IF($C$6=1,C43*20,C43) -> 0 | D42: =IF($C$6=1,D43*20,D43) -> 0 | E42: =IF($C$6=1,E43*20,E43) -> 0 | F42: =IF($C$6=1,F43*20,F43) -> 0 | G42: =G43 -> 0 | H42: =H43 -> 0 | I42: =I43 -> 0 | K42: =IF($C$6=1,K43*20,K43) -> 6531.6 | L42: =IF($C$6=1,L43*20,L43) -> 6455.62 | M42: =IF($C$6=1,M43*20,M43) -> 6396.7 | N42: =IF($C$6=1,N43*20,N43) -> 0 | O42: =IF($C$6=1,O43*20,O43) -> 6303.16 | P42: =P43 -> 6231 | Q42: =Q43 -> 6150 | R42: =R43 -> 0 | S42: =S43 -> 5949 | T42: =T43 -> 5858 | U42: =U43 -> 5782 | V42: =V43 -> 0 | W42: =W43 -> 5663 | ... AC42: =AC43 -> 5423 | AE42: =N42 -> 0 | AF42: =O42 -> 6303.16 | AG42: =P42 -> 6231 | AH42: =Q42 -> 6150 | AI42: =R42 -> 0 | AJ42: =S42 -> 5949 | AK42: =T42 -> 5858 | AL42: =U42 -> 5782 | ... AT42: =AC42 -> 5423
B43: Unadjusted Basic Shares | K43: 326.58 | L43: 322.781 | M43: 319.835 | N43: =F43 -> 0 | O43: 315.158 | P43: 6231 | Q43: 6150 | R43: =G43 -> 0 | S43: 5949 | T43: 5858 | U43: 5782 | V43: =H43 -> 0 | W43: 5663 | X43: 5615 | Y43: 5575 | Z43: =I43 -> 0 | AA43: 5493 | AB43: 5451 | AC43: 5423 | AE43: =N43 -> 0 | AF43: =O43 -> 315.158 | AG43: =P43 -> 6231 | AH43: =Q43 -> 6150 | AI43: =R43 -> 0 | AJ43: =S43 -> 5949 | AK43: =T43 -> 5858 | AL43: =U43 -> 5782 | ... AT43: =AC43 -> 5423
B44: Class C Basic EPS | C44: =IF($C$6=1, C41/C42,C41/C43) -> #DIV/0! | D44: =IF($C$6=1, D41/D42,D41/D43) -> #DIV/0! | E44: =IF($C$6=1, E41/E42,E41/E43) -> #DIV/0! | F44: =IF($C$6=1, F41/F42,F41/F43) -> #DIV/0! | G44: =IF($C$6=1, G41/G42,G41/G43) -> #DIV/0! | H44: =IF($C$6=1, H41/H42,H41/H43) -> #DIV/0! | I44: =IF($C$6=1, I41/I42,I41/I43) -> #DIV/0! | K44: =IF($C$6=1, K41/K42,K41/K43) -> 1.3316798 | L44: =IF($C$6=1, L41/L42,L41/L43) -> 1.384685 | M44: =IF($C$6=1, M41/M42,M41/M43) -> 1.4221395 | N44: =IF($C$6=1, N41/N42,N41/N43) -> #DIV/0! | O44: =IF($C$6=1, O41/O42,O41/O43) -> 1.2447725 | P44: =IF($C$6=1, P41/P42,P41/P43) -> 1.218424 | Q44: =IF($C$6=1, Q41/Q42,Q41/Q43) -> 1.0684553 | R44: =IF($C$6=1, R41/R42,R41/R43) -> #DIV/0! | ... AC44: =IF($C$6=1, AC41/AC42,AC41/AC43) -> 2.8941545 | AE44: =IF($C$6=1, AE41/AE42,AE41/AE43) -> #DIV/0! | AF44: =IF($C$6=1, AF41/AF42,AF41/AF43) -> -0.1351703 | AG44: =IF($C$6=1, AG41/AG42,AG41/AG43) -> -0.35291286 | AH44: =IF($C$6=1, AH41/AH42,AH41/AH43) -> -0.76829268 | AI44: =IF($C$6=1, AI41/AI42,AI41/AI43) -> #DIV/0! | AJ44: =IF($C$6=1, AJ41/AJ42,AJ41/AJ43) -> -0.1413683 | AK44: =IF($C$6=1, AK41/AK42,AK41/AK43) -> 0.010242404 | AL44: =IF($C$6=1, AL41/AL42,AL41/AL43) -> 0.43894846 | ... AT44: =IF($C$6=1, AT41/AT42,AT41/AT43) -> 1.9325097
A46: X | B46: Fully Diluted EPS Per Share Class
B48: Class A
B49: Allocation of undistributed earnings | K49: 9113 | L49: 9437 | M49: 9683 | N49: =SUM(F49-SUM(K49:M49)) -> -28233 | O49: 8495 | P49: 8342 | Q49: 7294 | R49: =SUM(G49-SUM(O49:Q49)) -> -24131 | S49: 8019 | T49: 9800 | U49: 10544 | V49: =SUM(H49-SUM(S49:U49)) -> -28363 | W49: 12754 | X49: 12736 | Y49: 14237 | Z49: =SUM(I49-SUM(W49:Y49)) -> -39727 | AA49: 18813 | AB49: 15429 | AC49: 19113 | AE49: =SUM(K49:N49) -> 0 | AF49: =SUM(L49:O49) -> -618 | AG49: =SUM(M49:P49) -> -1713 | AH49: =SUM(N49:Q49) -> -4102 | AI49: =SUM(O49:R49) -> 0 | AJ49: =SUM(P49:S49) -> -476 | AK49: =SUM(Q49:T49) -> 982 | AL49: =SUM(R49:U49) -> 4232 | ... AT49: =SUM(Z49:AC49) -> 13628
B50: Fully Diluted Shares | C50: =SUM(C51:C53) -> 0 | D50: =SUM(D51:D53) -> 0 | E50: =SUM(E51:E53) -> 0 | F50: =SUM(F51:F53) -> 0 | G50: =SUM(G51:G53) -> 0 | H50: =SUM(H51:H53) -> 0 | I50: =SUM(I51:I53) -> 0 | K50: =SUM(K51:K53) -> 6933.16 | L50: =SUM(L51:L53) -> 6923.84 | M50: =SUM(M51:M53) -> 6918.74 | N50: =SUM(N51:N53) -> -0.94 | O50: =SUM(O51:O53) -> 6900.36 | P50: =SUM(P51:P53) -> 6902 | Q50: =SUM(Q51:Q53) -> 6868 | R50: =SUM(R51:R53) -> 0 | ... AC50: =SUM(AC51:AC53) -> 6663 | AE50: =SUM(AE51:AE53) -> -0.047 | AF50: =SUM(AF51:AF53) -> 6900.265 | AG50: =SUM(AG51:AG53) -> 6902 | AH50: =SUM(AH51:AH53) -> 6868 | AI50: =SUM(AI51:AI53) -> 0 | AJ50: =SUM(AJ51:AJ53) -> 6832 | AK50: =SUM(AK51:AK53) -> 6810 | AL50: =SUM(AL51:AL53) -> 6799 | ... AT50: =SUM(AT51:AT53) -> 6663
B51: Number of shares used in basic computation | C51: =IF($C$6=1,C30,C31) -> 0 | D51: =IF($C$6=1,D30,D31) -> 0 | E51: =IF($C$6=1,E30,E31) -> 0 | F51: =IF($C$6=1,F30,F31) -> 0 | G51: =IF($C$6=1,G30,G31) -> 0 | H51: =IF($C$6=1,H30,H31) -> 0 | I51: =IF($C$6=1,I30,I31) -> 0 | K51: =IF($C$6=1,K30,K31) -> 6016 | L51: =IF($C$6=1,L30,L31) -> 6009.7 | M51: =IF($C$6=1,M30,M31) -> 6010.38 | N51: =IF($C$6=1,N30,N31) -> 0 | O51: =IF($C$6=1,O30,O31) -> 6009.56 | P51: =IF($C$6=1,P30,P31) -> 6015 | Q51: =IF($C$6=1,Q30,Q31) -> 5983 | R51: =IF($C$6=1,R30,R31) -> 0 | ... AC51: =IF($C$6=1,AC30,AC31) -> 5818 | AE51: =IF($C$6=1,AE30,AE31) -> 0 | AF51: =IF($C$6=1,AF30,AF31) -> 6009.56 | AG51: =IF($C$6=1,AG30,AG31) -> 6015 | AH51: =IF($C$6=1,AH30,AH31) -> 5983 | AI51: =IF($C$6=1,AI30,AI31) -> 0 | AJ51: =IF($C$6=1,AJ30,AJ31) -> 5949 | AK51: =IF($C$6=1,AK30,AK31) -> 5931 | AL51: =IF($C$6=1,AL30,AL31) -> 5924 | ... AT51: =IF($C$6=1,AT30,AT31) -> 5818
B52: Conversion of Class B to Class A common shares outstanding | C52: =IF($C$6=1,C36,C37) -> 0 | D52: =IF($C$6=1,D36,D37) -> 0 | E52: =IF($C$6=1,E36,E37) -> 0 | F52: =IF($C$6=1,F36,F37) -> 0 | G52: =IF($C$6=1,G36,G37) -> 0 | H52: =IF($C$6=1,H36,H37) -> 0 | I52: =IF($C$6=1,I36,I37) -> 0 | K52: =IF($C$6=1,K36,K37) -> 916.8 | L52: =IF($C$6=1,L36,L37) -> 913.84 | M52: =IF($C$6=1,M36,M37) -> 908.08 | N52: =IF($C$6=1,N36,N37) -> 0 | O52: =IF($C$6=1,O36,O37) -> 890.7 | P52: =IF($C$6=1,P36,P37) -> 887 | Q52: =IF($C$6=1,Q36,Q37) -> 885 | R52: =IF($C$6=1,R36,R37) -> 0 | ... AC52: =IF($C$6=1,AC36,AC37) -> 845 | AE52: =IF($C$6=1,AE36,AE37) -> 0 | AF52: =IF($C$6=1,AF36,AF37) -> 890.7 | AG52: =IF($C$6=1,AG36,AG37) -> 887 | AH52: =IF($C$6=1,AH36,AH37) -> 885 | AI52: =IF($C$6=1,AI36,AI37) -> 0 | AJ52: =IF($C$6=1,AJ36,AJ37) -> 883 | AK52: =IF($C$6=1,AK36,AK37) -> 879 | AL52: =IF($C$6=1,AL36,AL37) -> 875 | ... AT52: =IF($C$6=1,AT36,AT37) -> 845
B53: Adjusted RSUs and other contingently issuable shares | C53: =IF($C$6=1,C54*20,C54) -> 0 | D53: =IF($C$6=1,D54*20,D54) -> 0 | E53: =IF($C$6=1,E54*20,E54) -> 0 | F53: =IF($C$6=1,F54*20,F54) -> 0 | G53: =IF($C$6=1,G54*20,G54) -> 0 | H53: =IF($C$6=1,H54*20,H54) -> 0 | I53: =IF($C$6=1,I54*20,I54) -> 0 | K53: =IF($C$6=1,K54*20,K54) -> 0.36 | L53: =IF($C$6=1,L54*20,L54) -> 0.3 | M53: =IF($C$6=1,M54*20,M54) -> 0.28 | N53: =IF($C$6=1,N54*20,N54) -> -0.94 | O53: =IF($C$6=1,O54*20,O54) -> 0.1 | P53: =IF($C$6=1,P54*20,P54) -> 0 | Q53: =Q54 -> 0 | R53: =R54 -> 0 | S53: =S54 -> 0 | T53: =T54 -> 0 | U53: =U54 -> 0 | V53: =V54 -> 0 | W53: =W54 -> 0 | X53: =X54 -> 0 | ... AC53: =AC54 -> 0 | AE53: =AE54 -> -0.047 | AF53: =AF54 -> 0.005 | AG53: =AG54 -> 0 | AH53: =AH54 -> 0 | AI53: =AI54 -> 0 | AJ53: =AJ54 -> 0 | AK53: =AK54 -> 0 | AL53: =AL54 -> 0 | ... AT53: =AT54 -> 0
...

Sheet Revenue Drivers
B2: Netflix, Inc. (NASDAQ: NFLX) | C2: FYE | G2: FYE | K2: Quarterly | S2: Quarterly | T2: Quarterly | AA2: LTM | AE2: LTM | AG2: LTM | AM2: Variance
B3: Segment Anaysis | C3: ='Historical Financials'!C7 -> 2018 | D3: ='Historical Financials'!D7 -> 2019 | E3: ='Historical Financials'!E7 -> 2020 | F3: ='Historical Financials'!F7 -> 2021 | G3: ='Historical Financials'!G7 -> 2022 | H3: ='Historical Financials'!H7 -> 2023 | I3: ='Historical Financials'!I7 -> 2024 | K3: ='Historical Financials'!O7 -> 1Q22 | L3: ='Historical Financials'!P7 -> 2Q22 | M3: ='Historical Financials'!Q7 -> 3Q22 | N3: ='Historical Financials'!R7 -> 4Q22 | O3: ='Historical Financials'!S7 -> 1Q23 | P3: ='Historical Financials'!T7 -> 2Q23 | Q3: ='Historical Financials'!U7 -> 3Q23 | R3: ='Historical Financials'!V7 -> 4Q23 | ... Y3: ='Historical Financials'!AC7 -> 3Q25 | AA3: =O3 -> 1Q23 | AB3: =P3 -> 2Q23 | AC3: =Q3 -> 3Q23 | AD3: =R3 -> 4Q23 | AE3: =S3 -> 1Q24 | AF3: =T3 -> 2Q24 | AG3: =U3 -> 3Q24 | AH3: =V3 -> 4Q24 | ... AK3: =Y3 -> 3Q25
B4: $ in thousands except per share | C4: ='Historical Financials'!C8 -> 43465 | D4: ='Historical Financials'!D8 -> 43830 | E4: ='Historical Financials'!E8 -> 44196 | F4: ='Historical Financials'!F8 -> 44561 | G4: ='Historical Financials'!G8 -> 44926 | H4: ='Historical Financials'!H8 -> 45291 | I4: ='Historical Financials'!I8 -> 45657 | K4: ='Historical Financials'!O8 -> 44651 | L4: ='Historical Financials'!P8 -> 44742 | M4: ='Historical Financials'!Q8 -> 44834 | N4: ='Historical Financials'!R8 -> 44926 | O4: ='Historical Financials'!S8 -> 45016 | P4: ='Historical Financials'!T8 -> 45107 | Q4: ='Historical Financials'!U8 -> 45199 | R4: ='Historical Financials'!V8 -> 45291 | ... Y4: ='Historical Financials'!AC8 -> 45930 | AA4: =O4 -> 45016 | AB4: =P4 -> 45107 | AC4: =Q4 -> 45199 | AD4: =R4 -> 45291 | AE4: =S4 -> 45382 | AF4: =T4 -> 45473 | AG4: =U4 -> 45565 | AH4: =V4 -> 45657 | ... AK4: =Y4 -> 45930
A6: X | B6: Offerings Drivers
B8: Disaggregated Revenues
B9: UCAN Revenue | C9: 8281532 | D9: 10051208 | E9: 11455396 | F9: 12972100 | G9: 14084643 | H9: 14873783 | I9: 17359369 | K9: 3350424 | L9: 3537863 | M9: 3601565 | N9: =SUM(G9-SUM(K9:M9)) -> 3594791 | O9: 3608645 | P9: 3599448 | Q9: 3735133 | R9: =SUM(H9-SUM(O9:Q9)) -> 3930557 | S9: 4224315 | T9: 4295560 | U9: 4322476 | V9: =SUM(I9-SUM(S9:U9)) -> 4517018 | W9: 4617098 | X9: 4929003 | Y9: 5071781 | AA9: =SUM(L9:O9) -> 14342864 | AB9: =SUM(M9:P9) -> 14404449 | AC9: =SUM(N9:Q9) -> 14538017 | AD9: =SUM(O9:R9) -> 14873783 | AE9: =SUM(P9:S9) -> 15489453 | AF9: =SUM(Q9:T9) -> 16185565 | AG9: =SUM(R9:U9) -> 16772908 | AH9: =SUM(S9:V9) -> 17359369 | ... AK9: =SUM(V9:Y9) -> 19134900 | AM9: =SUM(AK9/AG9)-1 -> 0.14082185
B10: EMEA Revenue | C10: 3963707 | D10: 5543067 | E10: 7772252 | F10: 9699819 | G10: 9745015 | H10: 10556487 | I10: 12387035 | K10: 2561831 | L10: 2457235 | M10: 2375814 | N10: =SUM(G10-SUM(K10:M10)) -> 2350135 | O10: 2517641 | P10: 2562170 | Q10: 2693146 | R10: =SUM(H10-SUM(O10:Q10)) -> 2783530 | S10: 2958193 | T10: 3007772 | U10: 3133466 | V10: =SUM(I10-SUM(S10:U10)) -> 3287604 | W10: 3404676 | X10: 3538175 | Y10: 3699052 | AG10: =SUM(R10:U10) -> 11882961 | AH10: =SUM(S10:V10) -> 12387035 | AI10: =SUM(T10:W10) -> 12833518 | AJ10: =SUM(U10:X10) -> 13363921 | AK10: =SUM(V10:Y10) -> 13929507 | AM10: =SUM(AK10/AG10)-1 -> 0.17222526
B11: LATAM Revenue | C11: 2237697 | D11: 2795434 | E11: 3156727 | F11: 3576976 | G11: 4069973 | H11: 4446461 | I11: 4839816 | K11: 998948 | L11: 1030234 | M11: 1023945 | N11: =SUM(G11-SUM(K11:M11)) -> 1016846 | O11: 1070192 | P11: 1077435 | Q11: 1142811 | R11: =SUM(H11-SUM(O11:Q11)) -> 1156023 | S11: 1165008 | T11: 1204145 | U11: 1240892 | V11: =SUM(I11-SUM(S11:U11)) -> 1229771 | W11: 1261934 | X11: 1306735 | Y11: 1370913 | AG11: =SUM(R11:U11) -> 4766068 | AH11: =SUM(S11:V11) -> 4839816 | AI11: =SUM(T11:W11) -> 4936742 | AJ11: =SUM(U11:X11) -> 5039332 | AK11: =SUM(V11:Y11) -> 5169353 | AM11: =SUM(AK11/AG11)-1 -> 0.084615872
B12: APAC Revenue | C12: 945816 | D12: 1469521 | E12: 2372300 | F12: 3266601 | G12: 3570221 | H12: 3763727 | I12: 4414746 | K12: 916754 | L12: 907719 | M12: 889037 | N12: =SUM(G12-SUM(K12:M12)) -> 856711 | O12: 933523 | P12: 919273 | Q12: 948216 | R12: =SUM(H12-SUM(O12:Q12)) -> 962715 | S12: 1022924 | T12: 1051833 | U12: 1127869 | V12: =SUM(I12-SUM(S12:U12)) -> 1212120 | W12: 1259093 | X12: 1305253 | Y12: 1368561 | AG12: =SUM(R12:U12) -> 4165341 | AH12: =SUM(S12:V12) -> 4414746 | AI12: =SUM(T12:W12) -> 4650915 | AJ12: =SUM(U12:X12) -> 4904335 | AK12: =SUM(V12:Y12) -> 5145027 | AM12: =SUM(AK12/AG12)-1 -> 0.23519947
B13: Domestic DVD Revenue | C13: 365589 | D13: 297217 | E13: 239381 | F13: 182348 | G13: 145698 | H13: 82839 | I13: 0 | K13: 39810 | L13: 37090 | M13: 35228 | N13: =SUM(G13-SUM(K13:M13)) -> 33570 | O13: 31502 | P13: 28975 | Q13: 22362 | R13: =SUM(H13-SUM(O13:Q13)) -> 0 | S13: 0 | T13: 0 | U13: 0 | V13: =SUM(I13-SUM(S13:U13)) -> 0 | W13: 0 | X13: 0 | Y13: 0 | AG13: =SUM(R13:U13) -> 0 | AH13: =SUM(S13:V13) -> 0 | AI13: =SUM(T13:W13) -> 0 | AJ13: =SUM(U13:X13) -> 0 | AK13: =SUM(V13:Y13) -> 0 | AM13: =SUM(AK13/AG13)-1 -> #DIV/0!
B14: Total Net Revenue | C14: =SUM(C9:C13) -> 15794341 | D14: =SUM(D9:D13) -> 20156447 | E14: =SUM(E9:E13) -> 24996056 | F14: =SUM(F9:F13) -> 29697844 | G14: =SUM(G9:G13) -> 31615550 | H14: =SUM(H9:H13) -> 33723297 | I14: =SUM(I9:I13) -> 39000966 | K14: =SUM(K9:K13) -> 7867767 | L14: =SUM(L9:L13) -> 7970141 | M14: =SUM(M9:M13) -> 7925589 | N14: =SUM(N9:N13) -> 7852053 | O14: =SUM(O9:O13) -> 8161503 | P14: =SUM(P9:P13) -> 8187301 | Q14: =SUM(Q9:Q13) -> 8541668 | R14: =SUM(R9:R13) -> 8832825 | ... Y14: =SUM(Y9:Y13) -> 11510307 | AA14: =SUM(AA9:AA13) -> 14342864 | AB14: =SUM(AB9:AB13) -> 14404449 | AC14: =SUM(AC9:AC13) -> 14538017 | AD14: =SUM(AD9:AD13) -> 14873783 | AE14: =SUM(AE9:AE13) -> 15489453 | AF14: =SUM(AF9:AF13) -> 16185565 | AG14: =SUM(AG9:AG13) -> 37587278 | AH14: =SUM(AH9:AH13) -> 39000966 | ... AK14: =SUM(AK9:AK13) -> 43378787 | AM14: =SUM(AK14/AG14)-1 -> 0.15408163
B15: Variance Check | C15: =+C14-'Historical Financials'!C11 -> 0 | D15: =+D14-'Historical Financials'!D11 -> 0 | E15: =+E14-'Historical Financials'!E11 -> 0 | F15: =+F14-'Historical Financials'!F11 -> 0 | G15: =+G14-'Historical Financials'!G11 -> 0 | H15: =+H14-'Historical Financials'!H11 -> 0 | I15: =+I14-'Historical Financials'!I11 -> 0 | K15: =K14-'Historical Financials'!O11 -> 0 | L15: =L14-'Historical Financials'!P11 -> 0 | M15: =M14-'Historical Financials'!Q11 -> 0 | N15: =N14-'Historical Financials'!R11 -> 0 | O15: =O14-'Historical Financials'!S11 -> 0 | P15: =P14-'Historical Financials'!T11 -> 0 | Q15: =Q14-'Historical Financials'!U11 -> 0 | R15: =R14-'Historical Financials'!V11 -> 0 | ... Y15: =Y14-'Historical Financials'!AC11 -> 0 | AA15: =+AA14-'Historical Financials'!AI11 -> -17566422 | AB15: =+AB14-'Historical Financials'!AJ11 -> -17721997 | AC15: =+AC14-'Historical Financials'!AK11 -> -18204508 | AD15: =+AD14-'Historical Financials'!AL11 -> -18849514 | AE15: =+AE14-'Historical Financials'!AM11 -> -19442781 | AF15: =+AF14-'Historical Financials'!AN11 -> -20118678 | AG15: =+AG14-'Historical Financials'!AO11 -> 0 | AH15: =+AH14-'Historical Financials'!AP11 -> 0 | ... AJ15: =+AJ14-'Historical Financials'!AR11 -> 0 | AK15: =AK14-'Historical Financials'!AS11 -> 0

Sheet FCF
B2: ='Historical Financials'!B2 -> Netflix, Inc. (NASDAQ: NFLX) | C2: FYE | E2: FYE | I2: Quarterly | S2: Quarterly | Y2: LTM | AF2: LTM | AG2: LTM | AM2: Variance
B3: FCF Analysis | C3: ='Historical Financials'!E7 -> 2020 | D3: ='Historical Financials'!F7 -> 2021 | E3: ='Historical Financials'!G7 -> 2022 | F3: ='Historical Financials'!H7 -> 2023 | G3: ='Historical Financials'!I7 -> 2024 | I3: ='Historical Financials'!O7 -> 1Q22 | J3: ='Historical Financials'!P7 -> 2Q22 | K3: ='Historical Financials'!Q7 -> 3Q22 | L3: ='Historical Financials'!R7 -> 4Q22 | M3: ='Historical Financials'!S7 -> 1Q23 | N3: ='Historical Financials'!T7 -> 2Q23 | O3: ='Historical Financials'!U7 -> 3Q23 | P3: ='Historical Financials'!V7 -> 4Q23 | ... W3: ='Historical Financials'!AC7 -> 3Q25 | Y3: =K3 -> 3Q22 | Z3: =L3 -> 4Q22 | AA3: =M3 -> 1Q23 | AB3: =N3 -> 2Q23 | AC3: =O3 -> 3Q23 | AD3: =P3 -> 4Q23 | AE3: =Q3 -> 1Q24 | AF3: =R3 -> 2Q24 | ... AK3: =W3 -> 3Q25
B4: $ mm except per share | C4: ='Historical Financials'!E8 -> 44196 | D4: ='Historical Financials'!F8 -> 44561 | E4: ='Historical Financials'!G8 -> 44926 | F4: ='Historical Financials'!H8 -> 45291 | G4: ='Historical Financials'!I8 -> 45657 | I4: ='Historical Financials'!O8 -> 44651 | J4: ='Historical Financials'!P8 -> 44742 | K4: ='Historical Financials'!Q8 -> 44834 | L4: ='Historical Financials'!R8 -> 44926 | M4: ='Historical Financials'!S8 -> 45016 | N4: ='Historical Financials'!T8 -> 45107 | O4: ='Historical Financials'!U8 -> 45199 | P4: ='Historical Financials'!V8 -> 45291 | ... W4: ='Historical Financials'!AC8 -> 45930 | Y4: =K4 -> 44834 | Z4: =L4 -> 44926 | AA4: =M4 -> 45016 | AB4: =N4 -> 45107 | AC4: =O4 -> 45199 | AD4: =P4 -> 45291 | AE4: =Q4 -> 45382 | AF4: =R4 -> 45473 | ... AK4: =W4 -> 45930
B6: ='Revenue Drivers'!B9 -> UCAN Revenue | C6: =('Revenue Drivers'!E9)/1000 -> 11455.396 | D6: =('Revenue Drivers'!F9)/1000 -> 12972.1 | E6: =('Revenue Drivers'!G9)/1000 -> 14084.643 | F6: =('Revenue Drivers'!H9)/1000 -> 14873.783 | G6: =('Revenue Drivers'!I9)/1000 -> 17359.369 | I6: =('Revenue Drivers'!K9)/1000 -> 3350.424 | J6: =('Revenue Drivers'!L9)/1000 -> 3537.863 | K6: =('Revenue Drivers'!M9)/1000 -> 3601.565 | L6: =('Revenue Drivers'!N9)/1000 -> 3594.791 | M6: =('Revenue Drivers'!O9)/1000 -> 3608.645 | N6: =('Revenue Drivers'!P9)/1000 -> 3599.448 | O6: =('Revenue Drivers'!Q9)/1000 -> 3735.133 | P6: =('Revenue Drivers'!R9)/1000 -> 3930.557 | ... W6: =('Revenue Drivers'!Y9)/1000 -> 5071.781 | Y6: =SUM(H6:K6) -> 10489.852 | Z6: =SUM(I6:L6) -> 14084.643 | AA6: =SUM(J6:M6) -> 14342.864 | AB6: =SUM(K6:N6) -> 14404.449 | AC6: =SUM(L6:O6) -> 14538.017 | AD6: =SUM(M6:P6) -> 14873.783 | AE6: =SUM(N6:Q6) -> 15489.453 | AF6: =SUM(O6:R6) -> 16185.565 | ... AK6: =SUM(T6:W6) -> 19134.9 | AM6: =SUM(AK6/AG6)-1 -> 0.14082185
B7: ='Revenue Drivers'!B10 -> EMEA Revenue | C7: =('Revenue Drivers'!E10)/1000 -> 7772.252 | D7: =('Revenue Drivers'!F10)/1000 -> 9699.819 | E7: =('Revenue Drivers'!G10)/1000 -> 9745.015 | F7: =('Revenue Drivers'!H10)/1000 -> 10556.487 | G7: =('Revenue Drivers'!I10)/1000 -> 12387.035 | I7: =('Revenue Drivers'!K10)/1000 -> 2561.831 | J7: =('Revenue Drivers'!L10)/1000 -> 2457.235 | K7: =('Revenue Drivers'!M10)/1000 -> 2375.814 | L7: =('Revenue Drivers'!N10)/1000 -> 2350.135 | M7: =('Revenue Drivers'!O10)/1000 -> 2517.641 | N7: =('Revenue Drivers'!P10)/1000 -> 2562.17 | O7: =('Revenue Drivers'!Q10)/1000 -> 2693.146 | P7: =('Revenue Drivers'!R10)/1000 -> 2783.53 | ... W7: =('Revenue Drivers'!Y10)/1000 -> 3699.052 | AG7: =SUM(P7:S7) -> 11882.961 | AH7: =SUM(Q7:T7) -> 12387.035 | AI7: =SUM(R7:U7) -> 12833.518 | AJ7: =SUM(S7:V7) -> 13363.921 | AK7: =SUM(T7:W7) -> 13929.507 | AM7: =SUM(AK7/AG7)-1 -> 0.17222526
B8: ='Revenue Drivers'!B11 -> LATAM Revenue | C8: =('Revenue Drivers'!E11)/1000 -> 3156.727 | D8: =('Revenue Drivers'!F11)/1000 -> 3576.976 | E8: =('Revenue Drivers'!G11)/1000 -> 4069.973 | F8: =('Revenue Drivers'!H11)/1000 -> 4446.461 | G8: =('Revenue Drivers'!I11)/1000 -> 4839.816 | I8: =('Revenue Drivers'!K11)/1000 -> 998.948 | J8: =('Revenue Drivers'!L11)/1000 -> 1030.234 | K8: =('Revenue Drivers'!M11)/1000 -> 1023.945 | L8: =('Revenue Drivers'!N11)/1000 -> 1016.846 | M8: =('Revenue Drivers'!O11)/1000 -> 1070.192 | N8: =('Revenue Drivers'!P11)/1000 -> 1077.435 | O8: =('Revenue Drivers'!Q11)/1000 -> 1142.811 | P8: =('Revenue Drivers'!R11)/1000 -> 1156.023 | ... W8: =('Revenue Drivers'!Y11)/1000 -> 1370.913 | AG8: =SUM(P8:S8) -> 4766.068 | AH8: =SUM(Q8:T8) -> 4839.816 | AI8: =SUM(R8:U8) -> 4936.742 | AJ8: =SUM(S8:V8) -> 5039.332 | AK8: =SUM(T8:W8) -> 5169.353 | AM8: =SUM(AK8/AG8)-1 -> 0.084615872
B9: ='Revenue Drivers'!B12 -> APAC Revenue | C9: =('Revenue Drivers'!E12)/1000 -> 2372.3 | D9: =('Revenue Drivers'!F12)/1000 -> 3266.601 | E9: =('Revenue Drivers'!G12)/1000 -> 3570.221 | F9: =('Revenue Drivers'!H12)/1000 -> 3763.727 | G9: =('Revenue Drivers'!I12)/1000 -> 4414.746 | I9: =('Revenue Drivers'!K12)/1000 -> 916.754 | J9: =('Revenue Drivers'!L12)/1000 -> 907.719 | K9: =('Revenue Drivers'!M12)/1000 -> 889.037 | L9: =('Revenue Drivers'!N12)/1000 -> 856.711 | M9: =('Revenue Drivers'!O12)/1000 -> 933.523 | N9: =('Revenue Drivers'!P12)/1000 -> 919.273 | O9: =('Revenue Drivers'!Q12)/1000 -> 948.216 | P9: =('Revenue Drivers'!R12)/1000 -> 962.715 | ... W9: =('Revenue Drivers'!Y12)/1000 -> 1368.561 | AG9: =SUM(P9:S9) -> 4165.341 | AH9: =SUM(Q9:T9) -> 4414.746 | AI9: =SUM(R9:U9) -> 4650.915 | AJ9: =SUM(S9:V9) -> 4904.335 | AK9: =SUM(T9:W9) -> 5145.027 | AM9: =SUM(AK9/AG9)-1 -> 0.23519947
