Workbook

Sheet Historical Financials
B2: Cassava Sciences (NASDAQ: SAVA)
B3: Historical Financials
B4: $ in thousands except per share
A6: X | B6: Income Statement | C6: FYE | G6: Quarterly | M6: Quarterly | V6: LTM | AB6: Variance
B7: Fiscal Period | C7: 2021 | D7: 2022 | E7: 2023 | G7: 1Q22 | H7: 2Q22 | I7: 3Q22 | J7: 4Q22 | K7: 1Q23 | L7: 2Q23 | M7: 3Q23 | N7: 4Q23 | O7: 1Q24 | P7: 2Q24 | Q7: 3Q24 | S7: =J7 -> 4Q22 | T7: =K7 -> 1Q23 | U7: =L7 -> 2Q23 | V7: =M7 -> 3Q23 | W7: =N7 -> 4Q23 | X7: =O7 -> 1Q24 | Y7: =P7 -> 2Q24 | Z7: =Q7 -> 3Q24
B8: Fiscal Period End Date | C8: 44561 | D8: 44926 | E8: 45291 | G8: 44651 | H8: 44742 | I8: 44834 | J8: 44926 | K8: 45016 | L8: 45107 | M8: 45199 | N8: 45291 | O8: 45382 | P8: 45473 | Q8: 45565 | S8: =J8 -> 44926 | T8: =K8 -> 45016 | U8: =L8 -> 45107 | V8: =M8 -> 45199 | W8: =N8 -> 45291 | X8: =O8 -> 45382 | Y8: =P8 -> 45473 | Z8: =Q8 -> 45565
B10: Consolidated Revenue | C10: 0 | D10: 0 | E10: 0 | G10: 0 | H10: 0 | I10: 0 | J10: =SUM(D10-SUM(G10:I10)) -> 0 | K10: 0 | L10: 0 | M10: 0 | N10: =SUM(E10-SUM(K10:M10)) -> 0 | O10: 0 | P10: 0 | Q10: 0 | S10: =SUM(G10:J10) -> 0 | T10: =SUM(H10:K10) -> 0 | U10: =SUM(I10:L10) -> 0 | V10: =SUM(J10:M10) -> 0 | W10: =SUM(K10:N10) -> 0 | X10: =SUM(L10:O10) -> 0 | Y10: =SUM(M10:P10) -> 0 | Z10: =SUM(N10:Q10) -> 0 | AB10: =SUM(Z10/V10)-1 -> #DIV/0!
B11: Total Revenue | C11: =+SUM(C10:C10) -> 0 | D11: =+SUM(D10:D10) -> 0 | E11: =+SUM(E10:E10) -> 0 | G11: =+SUM(G10:G10) -> 0 | H11: =+SUM(H10:H10) -> 0 | I11: =+SUM(I10:I10) -> 0 | J11: =+SUM(J10:J10) -> 0 | K11: =+SUM(K10:K10) -> 0 | L11: =+SUM(L10:L10) -> 0 | M11: =+SUM(M10:M10) -> 0 | N11: =+SUM(N10:N10) -> 0 | ... Q11: =+SUM(Q10:Q10) -> 0 | S11: =+SUM(S10:S10) -> 0 | T11: =+SUM(T10:T10) -> 0 | U11: =+SUM(U10:U10) -> 0 | V11: =+SUM(V10:V10) -> 0 | W11: =+SUM(W10:W10) -> 0 | X11: =+SUM(X10:X10) -> 0 | Y11: =+SUM(Y10:Y10) -> 0 | Z11: =+SUM(Z10:Z10) -> 0 | AB11: =SUM(Z11/V11)-1 -> #DIV/0!
B13: Cost of Sales | C13: 0 | D13: 0 | E13: 0 | G13: 0 | H13: 0 | I13: 0 | J13: =SUM(D13-SUM(G13:I13)) -> 0 | K13: 0 | L13: 0 | M13: 0 | N13: =SUM(E13-SUM(K13:M13)) -> 0 | O13: 0 | P13: 0 | Q13: 0 | S13: =SUM(G13:J13) -> 0 | T13: =SUM(H13:K13) -> 0 | U13: =SUM(I13:L13) -> 0 | V13: =SUM(J13:M13) -> 0 | W13: =SUM(K13:N13) -> 0 | X13: =SUM(L13:O13) -> 0 | Y13: =SUM(M13:P13) -> 0 | Z13: =SUM(N13:Q13) -> 0 | AB13: =SUM(Z13/V13)-1 -> #DIV/0!
B14: Gross Profit | C14: =+SUM(C11+SUM(C13:C13)) -> 0 | D14: =+SUM(D11+SUM(D13:D13)) -> 0 | E14: =+SUM(E11+SUM(E13:E13)) -> 0 | G14: =+SUM(G11+SUM(G13:G13)) -> 0 | H14: =+SUM(H11+SUM(H13:H13)) -> 0 | I14: =+SUM(I11+SUM(I13:I13)) -> 0 | J14: =+SUM(J11+SUM(J13:J13)) -> 0 | K14: =+SUM(K11+SUM(K13:K13)) -> 0 | L14: =+SUM(L11+SUM(L13:L13)) -> 0 | M14: =+SUM(M11+SUM(M13:M13)) -> 0 | N14: =+SUM(N11+SUM(N13:N13)) -> 0 | ... Q14: =+SUM(Q11+SUM(Q13:Q13)) -> 0 | S14: =+SUM(S11+SUM(S13:S13)) -> 0 | T14: =+SUM(T11+SUM(T13:T13)) -> 0 | U14: =+SUM(U11+SUM(U13:U13)) -> 0 | V14: =+SUM(V11+SUM(V13:V13)) -> 0 | W14: =+SUM(W11+SUM(W13:W13)) -> 0 | X14: =+SUM(X11+SUM(X13:X13)) -> 0 | Y14: =+SUM(Y11+SUM(Y13:Y13)) -> 0 | Z14: =+SUM(Z11+SUM(Z13:Z13)) -> 0 | AB14: =SUM(Z14/V14)-1 -> #DIV/0!
B15: Gross Margin (%) | C15: =C14/C11 -> #DIV/0! | D15: =D14/D11 -> #DIV/0! | E15: =E14/E11 -> #DIV/0! | G15: =G14/G11 -> #DIV/0! | H15: =H14/H11 -> #DIV/0! | I15: =I14/I11 -> #DIV/0! | J15: =J14/J11 -> #DIV/0! | K15: =K14/K11 -> #DIV/0! | L15: =L14/L11 -> #DIV/0! | M15: =M14/M11 -> #DIV/0! | N15: =N14/N11 -> #DIV/0! | ... Q15: =Q14/Q11 -> #DIV/0! | S15: =S14/S11 -> #DIV/0! | T15: =T14/T11 -> #DIV/0! | U15: =U14/U11 -> #DIV/0! | V15: =V14/V11 -> #DIV/0! | W15: =W14/W11 -> #DIV/0! | X15: =X14/X11 -> #DIV/0! | Y15: =Y14/Y11 -> #DIV/0! | Z15: =Z14/Z11 -> #DIV/0! | AB15: =SUM(Z15-V15)*1000 -> #DIV/0!
B17: Research and development, net of grant reimbursement | C17: -24813 | D17: -68032 | E17: -89423 | G17: -14906 | H17: -16948 | I17: -18526 | J17: =SUM(D17-SUM(G17:I17)) -> -17652 | K17: -22120 | L17: -24969 | M17: -23603 | N17: =SUM(E17-SUM(K17:M17)) -> -18731 | O17: -16233 | P17: -15198 | Q17: -17676 | S17: =SUM(G17:J17) -> -68032 | T17: =SUM(H17:K17) -> -75246 | U17: =SUM(I17:L17) -> -83267 | V17: =SUM(J17:M17) -> -88344 | W17: =SUM(K17:N17) -> -89423 | X17: =SUM(L17:O17) -> -83536 | Y17: =SUM(M17:P17) -> -73765 | Z17: =SUM(N17:Q17) -> -67838 | AB17: =SUM(Z17/V17)-1 -> -0.23211537
B18: General and administrative | C18: -8055 | D18: -11988 | E18: -16534 | G18: -2915 | H18: -2969 | I18: -2819 | J18: =SUM(D18-SUM(G18:I18)) -> -3285 | K18: -4392 | L18: -3808 | M18: -4276 | N18: =SUM(E18-SUM(K18:M18)) -> -4058 | O18: -3701 | P18: -46204 | Q18: -12947 | S18: =SUM(G18:J18) -> -11988 | T18: =SUM(H18:K18) -> -13465 | U18: =SUM(I18:L18) -> -14304 | V18: =SUM(J18:M18) -> -15761 | W18: =SUM(K18:N18) -> -16534 | X18: =SUM(L18:O18) -> -15843 | Y18: =SUM(M18:P18) -> -58239 | Z18: =SUM(N18:Q18) -> -66910 | AB18: =SUM(Z18/V18)-1 -> 3.245289
B19: Operating Profit | C19: =+SUM(C14+SUM(C17:C18)) -> -32868 | D19: =+SUM(D14+SUM(D17:D18)) -> -80020 | E19: =+SUM(E14+SUM(E17:E18)) -> -105957 | G19: =+SUM(G14+SUM(G17:G18)) -> -17821 | H19: =+SUM(H14+SUM(H17:H18)) -> -19917 | I19: =+SUM(I14+SUM(I17:I18)) -> -21345 | J19: =+SUM(J14+SUM(J17:J18)) -> -20937 | K19: =+SUM(K14+SUM(K17:K18)) -> -26512 | L19: =+SUM(L14+SUM(L17:L18)) -> -28777 | M19: =+SUM(M14+SUM(M17:M18)) -> -27879 | N19: =+SUM(N14+SUM(N17:N18)) -> -22789 | ... Q19: =+SUM(Q14+SUM(Q17:Q18)) -> -30623 | S19: =+SUM(S14+SUM(S17:S18)) -> -80020 | T19: =+SUM(T14+SUM(T17:T18)) -> -88711 | U19: =+SUM(U14+SUM(U17:U18)) -> -97571 | V19: =+SUM(V14+SUM(V17:V18)) -> -104105 | W19: =+SUM(W14+SUM(W17:W18)) -> -105957 | X19: =+SUM(X14+SUM(X17:X18)) -> -99379 | Y19: =+SUM(Y14+SUM(Y17:Y18)) -> -132004 | Z19: =+SUM(Z14+SUM(Z17:Z18)) -> -134748 | AB19: =SUM(Z19/V19)-1 -> 0.29434705
B20: Operating Margin (%) | C20: =C19/C11 -> #DIV/0! | D20: =D19/D11 -> #DIV/0! | E20: =E19/E11 -> #DIV/0! | G20: =G19/G11 -> #DIV/0! | H20: =H19/H11 -> #DIV/0! | I20: =I19/I11 -> #DIV/0! | J20: =J19/J11 -> #DIV/0! | K20: =K19/K11 -> #DIV/0! | L20: =L19/L11 -> #DIV/0! | M20: =M19/M11 -> #DIV/0! | N20: =N19/N11 -> #DIV/0! | ... Q20: =Q19/Q11 -> #DIV/0! | S20: =S19/S11 -> #DIV/0! | T20: =T19/T11 -> #DIV/0! | U20: =U19/U11 -> #DIV/0! | V20: =V19/V11 -> #DIV/0! | W20: =W19/W11 -> #DIV/0! | X20: =X19/X11 -> #DIV/0! | Y20: =Y19/Y11 -> #DIV/0! | Z20: =Z19/Z11 -> #DIV/0! | AB20: =SUM(Z20-V20)*1000 -> #DIV/0!
B22: Interest income | C22: 49 | D22: 2777 | E22: 7833 | G22: 31 | H22: 314 | I22: 878 | J22: =SUM(D22-SUM(G22:I22)) -> 1554 | K22: 2051 | L22: 2198 | M22: 2005 | N22: =SUM(E22-SUM(K22:M22)) -> 1579 | O22: 1776 | P22: 2316 | Q22: 2618 | S22: =SUM(G22:J22) -> 2777 | T22: =SUM(H22:K22) -> 4797 | U22: =SUM(I22:L22) -> 6681 | V22: =SUM(J22:M22) -> 7808 | W22: =SUM(K22:N22) -> 7833 | X22: =SUM(L22:O22) -> 7558 | Y22: =SUM(M22:P22) -> 7676 | Z22: =SUM(N22:Q22) -> 8289 | AB22: =SUM(Z22/V22)-1 -> 0.061603484
B23: Other income, net | C23: 434 | D23: 997 | E23: 907 | G23: 263 | H23: 275 | I23: 210 | J23: =SUM(D23-SUM(G23:I23)) -> 249 | K23: 190 | L23: 203 | M23: 223 | N23: =SUM(E23-SUM(K23:M23)) -> 291 | O23: 160 | P23: 99 | Q23: 62 | S23: =SUM(G23:J23) -> 997 | T23: =SUM(H23:K23) -> 924 | U23: =SUM(I23:L23) -> 852 | V23: =SUM(J23:M23) -> 865 | W23: =SUM(K23:N23) -> 907 | X23: =SUM(L23:O23) -> 877 | Y23: =SUM(M23:P23) -> 773 | Z23: =SUM(N23:Q23) -> 612 | AB23: =SUM(Z23/V23)-1 -> -0.29248555
B24: Gain from change in fair value of warrant liabilities | C24: 0 | D24: 0 | E24: 0 | G24: 0 | H24: 0 | I24: 0 | J24: =SUM(D24-SUM(G24:I24)) -> 0 | K24: 0 | L24: 0 | M24: 0 | N24: =SUM(E24-SUM(K24:M24)) -> 0 | O24: 43041 | P24: 65142 | Q24: 0 | S24: =SUM(G24:J24) -> 0 | T24: =SUM(H24:K24) -> 0 | U24: =SUM(I24:L24) -> 0 | V24: =SUM(J24:M24) -> 0 | W24: =SUM(K24:N24) -> 0 | X24: =SUM(L24:O24) -> 43041 | Y24: =SUM(M24:P24) -> 108183 | Z24: =SUM(N24:Q24) -> 108183 | AB24: =SUM(Z24/V24)-1 -> #DIV/0!
B25: Earning Before Taxes | C25: =SUM(C19+SUM(C22:C24)) -> -32385 | D25: =SUM(D19+SUM(D22:D24)) -> -76246 | E25: =SUM(E19+SUM(E22:E24)) -> -97217 | G25: =SUM(G19+SUM(G22:G24)) -> -17527 | H25: =SUM(H19+SUM(H22:H24)) -> -19328 | I25: =SUM(I19+SUM(I22:I24)) -> -20257 | J25: =SUM(J19+SUM(J22:J24)) -> -19134 | K25: =SUM(K19+SUM(K22:K24)) -> -24271 | L25: =SUM(L19+SUM(L22:L24)) -> -26376 | M25: =SUM(M19+SUM(M22:M24)) -> -25651 | N25: =SUM(N19+SUM(N22:N24)) -> -20919 | ... Q25: =SUM(Q19+SUM(Q22:Q24)) -> -27943 | S25: =SUM(S19+SUM(S22:S24)) -> -76246 | T25: =SUM(T19+SUM(T22:T24)) -> -82990 | U25: =SUM(U19+SUM(U22:U24)) -> -90038 | V25: =SUM(V19+SUM(V22:V24)) -> -95432 | W25: =SUM(W19+SUM(W22:W24)) -> -97217 | X25: =SUM(X19+SUM(X22:X24)) -> -47903 | Y25: =SUM(Y19+SUM(Y22:Y24)) -> -15372 | Z25: =SUM(Z19+SUM(Z22:Z24)) -> -17664 | AB25: =SUM(Z25/V25)-1 -> -0.81490485
B26: EBT Margin (%) | C26: =C25/C11 -> #DIV/0! | D26: =D25/D11 -> #DIV/0! | E26: =E25/E11 -> #DIV/0! | G26: =G25/G11 -> #DIV/0! | H26: =H25/H11 -> #DIV/0! | I26: =I25/I11 -> #DIV/0! | J26: =J25/J11 -> #DIV/0! | K26: =K25/K11 -> #DIV/0! | L26: =L25/L11 -> #DIV/0! | M26: =M25/M11 -> #DIV/0! | N26: =N25/N11 -> #DIV/0! | ... Q26: =Q25/Q11 -> #DIV/0! | S26: =S25/S11 -> #DIV/0! | T26: =T25/T11 -> #DIV/0! | U26: =U25/U11 -> #DIV/0! | V26: =V25/V11 -> #DIV/0! | W26: =W25/W11 -> #DIV/0! | X26: =X25/X11 -> #DIV/0! | Y26: =Y25/Y11 -> #DIV/0! | Z26: =Z25/Z11 -> #DIV/0! | AB26: =SUM(Z26-V26)*1000 -> #DIV/0!
B28: Provision for taxes | C28: 0 | D28: 0 | E28: 0 | G28: 0 | H28: 0 | I28: 0 | J28: =SUM(C28-SUM(G28:I28)) -> 0 | K28: 0 | L28: 0 | M28: 0 | N28: =SUM(D28-SUM(K28:M28)) -> 0 | O28: 0 | P28: 0 | Q28: 0 | S28: =SUM(G28:J28) -> 0 | T28: =SUM(H28:K28) -> 0 | U28: =SUM(I28:L28) -> 0 | V28: =SUM(J28:M28) -> 0 | W28: =SUM(K28:N28) -> 0 | X28: =SUM(L28:O28) -> 0 | Y28: =SUM(M28:P28) -> 0 | Z28: =SUM(N28:Q28) -> 0 | AB28: =SUM(Z28/V28)-1 -> #DIV/0!
B29: Net loss | C29: =SUM(C25+C28) -> -32385 | D29: =SUM(D25+D28) -> -76246 | E29: =SUM(E25+E28) -> -97217 | G29: =SUM(G25+G28) -> -17527 | H29: =SUM(H25+H28) -> -19328 | I29: =SUM(I25+I28) -> -20257 | J29: =SUM(J25+J28) -> -19134 | K29: =SUM(K25+K28) -> -24271 | L29: =SUM(L25+L28) -> -26376 | M29: =SUM(M25+M28) -> -25651 | N29: =SUM(N25+N28) -> -20919 | ... Q29: =SUM(Q25+Q28) -> -27943 | S29: =SUM(S25+S28) -> -76246 | T29: =SUM(T25+T28) -> -82990 | U29: =SUM(U25+U28) -> -90038 | V29: =SUM(V25+V28) -> -95432 | W29: =SUM(W25+W28) -> -97217 | X29: =SUM(X25+X28) -> -47903 | Y29: =SUM(Y25+Y28) -> -15372 | Z29: =SUM(Z25+Z28) -> -17664 | AB29: =SUM(Z29/V29)-1 -> -0.81490485
B30: Net Margin (%) | C30: =C29/C11 -> #DIV/0! | D30: =D29/D11 -> #DIV/0! | E30: =E29/E11 -> #DIV/0! | G30: =G29/G11 -> #DIV/0! | H30: =H29/H11 -> #DIV/0! | I30: =I29/I11 -> #DIV/0! | J30: =J29/J11 -> #DIV/0! | K30: =K29/K11 -> #DIV/0! | L30: =L29/L11 -> #DIV/0! | M30: =M29/M11 -> #DIV/0! | N30: =N29/N11 -> #DIV/0! | ... Q30: =Q29/Q11 -> #DIV/0! | S30: =S29/S11 -> #DIV/0! | T30: =T29/T11 -> #DIV/0! | U30: =U29/U11 -> #DIV/0! | V30: =V29/V11 -> #DIV/0! | W30: =W29/W11 -> #DIV/0! | X30: =X29/X11 -> #DIV/0! | Y30: =Y29/Y11 -> #DIV/0! | Z30: =Z29/Z11 -> #DIV/0! | AB30: =SUM(Z30-V30)*1000 -> #DIV/0!
A32: X | B32: Balance Sheet | C32: FYE | G32: Quarterly | Q32: Quarterly | V32: LTM | AB32: Variance
B33: =B7 -> Fiscal Period | C33: =C7 -> 2021 | D33: =D7 -> 2022 | E33: =E7 -> 2023 | G33: =G7 -> 1Q22 | H33: =H7 -> 2Q22 | I33: =I7 -> 3Q22 | J33: =J7 -> 4Q22 | K33: =K7 -> 1Q23 | L33: =L7 -> 2Q23 | M33: =M7 -> 3Q23 | N33: =N7 -> 4Q23 | ... Q33: =Q7 -> 3Q24 | S33: =S7 -> 4Q22 | T33: =T7 -> 1Q23 | U33: =U7 -> 2Q23 | V33: =V7 -> 3Q23 | W33: =W7 -> 4Q23 | X33: =X7 -> 1Q24 | Y33: =Y7 -> 2Q24 | Z33: =Z7 -> 3Q24
B34: =B8 -> Fiscal Period End Date | C34: =C8 -> 44561 | D34: =D8 -> 44926 | E34: =E8 -> 45291 | G34: =G8 -> 44651 | H34: =H8 -> 44742 | I34: =I8 -> 44834 | J34: =J8 -> 44926 | K34: =K8 -> 45016 | L34: =L8 -> 45107 | M34: =M8 -> 45199 | N34: =N8 -> 45291 | ... Q34: =Q8 -> 45565 | S34: =S8 -> 44926 | T34: =T8 -> 45016 | U34: =U8 -> 45107 | V34: =V8 -> 45199 | W34: =W8 -> 45291 | X34: =X8 -> 45382 | Y34: =Y8 -> 45473 | Z34: =Z8 -> 45565
B36: Current Assets
B37: Cash and cash equivalents | C37: 233437 | D37: 201015 | E37: 121136 | G37: 209693 | H37: 197232 | I37: 174662 | J37: =D37 -> 201015 | K37: 187467 | L37: 168438 | M37: 142350 | N37: =E37 -> 121136 | O37: 124169 | P37: 207291 | Q37: 148978 | S37: =J37 -> 201015 | T37: =K37 -> 187467 | U37: =L37 -> 168438 | V37: =M37 -> 142350 | W37: =N37 -> 121136 | X37: =O37 -> 124169 | Y37: =P37 -> 207291 | Z37: =Q37 -> 148978 | AB37: =SUM(Z37/V37)-1 -> 0.046561293
B38: Prepaid expenses and other current assets | C38: 11045 | D38: 10211 | E38: 8497 | G38: 12507 | H38: 6969 | I38: 8610 | J38: =D38 -> 10211 | K38: 7532 | L38: 6095 | M38: 7834 | N38: =E38 -> 8497 | O38: 9830 | P38: 14831 | Q38: 13571 | S38: =J38 -> 10211 | T38: =K38 -> 7532 | U38: =L38 -> 6095 | V38: =M38 -> 7834 | W38: =N38 -> 8497 | X38: =O38 -> 9830 | Y38: =P38 -> 14831 | Z38: =Q38 -> 13571 | AB38: =SUM(Z38/V38)-1 -> 0.73232065
B39: Restricted cash | C39: 0 | D39: 0 | E39: 0 | G39: 0 | H39: 0 | I39: 0 | J39: =D39 -> 0 | K39: 0 | L39: 0 | M39: 0 | N39: =E39 -> 0 | O39: 0 | P39: 0 | Q39: 40000 | S39: =J39 -> 0 | T39: =K39 -> 0 | U39: =L39 -> 0 | V39: =M39 -> 0 | W39: =N39 -> 0 | X39: =O39 -> 0 | Y39: =P39 -> 0 | Z39: =Q39 -> 40000 | AB39: =SUM(Z39/V39)-1 -> #DIV/0!
B40: Total Current Assets | C40: =SUM(C37:C39) -> 244482 | D40: =SUM(D37:D39) -> 211226 | E40: =SUM(E37:E39) -> 129633 | G40: =SUM(G37:G39) -> 222200 | H40: =SUM(H37:H39) -> 204201 | I40: =SUM(I37:I39) -> 183272 | J40: =SUM(J37:J39) -> 211226 | K40: =SUM(K37:K39) -> 194999 | L40: =SUM(L37:L39) -> 174533 | M40: =SUM(M37:M39) -> 150184 | N40: =SUM(N37:N39) -> 129633 | ... Q40: =SUM(Q37:Q39) -> 202549 | S40: =SUM(S37:S39) -> 211226 | T40: =SUM(T37:T39) -> 194999 | U40: =SUM(U37:U39) -> 174533 | V40: =SUM(V37:V39) -> 150184 | W40: =SUM(W37:W39) -> 129633 | X40: =SUM(X37:X39) -> 133999 | Y40: =SUM(Y37:Y39) -> 222122 | Z40: =SUM(Z37:Z39) -> 202549 | AB40: =SUM(Z40/V40)-1 -> 0.3486723
B42: Non-Current Assets
B43: Operating lease right-of-use assets | C43: 210 | D43: 122 | E43: 0 | G43: 188 | H43: 166 | I43: 144 | J43: =D43 -> 122 | K43: - | L43: - | M43: - | N43: =E43 -> 0 | O43: - | P43: - | Q43: - | S43: =J43 -> 122 | T43: =K43 -> - | U43: =L43 -> - | V43: =M43 -> - | W43: =N43 -> 0 | X43: =O43 -> - | Y43: =P43 -> - | Z43: =Q43 -> - | AB43: =SUM(Z43/V43)-1 -> #VALUE!
B44: Property and equipment, net | C44: 20616 | D44: 22864 | E44: 21854 | G44: 20863 | H44: 22155 | I44: 23130 | J44: =D44 -> 22864 | K44: 22609 | L44: 22328 | M44: 22077 | N44: =E44 -> 21854 | O44: 21604 | P44: 21364 | Q44: 21135 | S44: =J44 -> 22864 | T44: =K44 -> 22609 | U44: =L44 -> 22328 | V44: =M44 -> 22077 | W44: =N44 -> 21854 | X44: =O44 -> 21604 | Y44: =P44 -> 21364 | Z44: =Q44 -> 21135 | AB44: =SUM(Z44/V44)-1 -> -0.042668841
B45: Intangible assets, net | C45: 1075 | D45: 622 | E45: 176 | G45: 940 | H45: 859 | I45: 740 | J45: =D45 -> 622 | K45: 503 | L45: 387 | M45: 268 | N45: =E45 -> 176 | O45: 115 | P45: 82 | Q45: 69 | S45: =J45 -> 622 | T45: =K45 -> 503 | U45: =L45 -> 387 | V45: =M45 -> 268 | W45: =N45 -> 176 | X45: =O45 -> 115 | Y45: =P45 -> 82 | Z45: =Q45 -> 69 | AB45: =SUM(Z45/V45)-1 -> -0.74253731
B46: Other assets | C46: 399 | D46: 0 | E46: 0 | G46: 0 | H46: 0 | I46: 0 | J46: =D46 -> 0 | L46: - | M46: - | N46: =E46 -> 0 | O46: 0 | P46: 0 | Q46: 0 | S46: =J46 -> 0 | T46: =K46 -> 0 | U46: =L46 -> - | V46: =M46 -> - | W46: =N46 -> 0 | X46: =O46 -> 0 | Y46: =P46 -> 0 | Z46: =Q46 -> 0 | AB46: =SUM(Z46/V46)-1 -> #VALUE!
B47: Total Assets | C47: =SUM(C43:C46)+C40 -> 266782 | D47: =SUM(D43:D46)+D40 -> 234834 | E47: =SUM(E43:E46)+E40 -> 151663 | G47: =SUM(G43:G46)+G40 -> 244191 | H47: =SUM(H43:H46)+H40 -> 227381 | I47: =SUM(I43:I46)+I40 -> 207286 | J47: =SUM(J43:J46)+J40 -> 234834 | K47: =SUM(K43:K46)+K40 -> 218111 | L47: =SUM(L43:L46)+L40 -> 197248 | M47: =SUM(M43:M46)+M40 -> 172529 | N47: =SUM(N43:N46)+N40 -> 151663 | ... Q47: =SUM(Q43:Q46)+Q40 -> 223753 | S47: =SUM(S43:S46)+S40 -> 234834 | T47: =SUM(T43:T46)+T40 -> 218111 | U47: =SUM(U43:U46)+U40 -> 197248 | V47: =SUM(V43:V46)+V40 -> 172529 | W47: =SUM(W43:W46)+W40 -> 151663 | X47: =SUM(X43:X46)+X40 -> 155718 | Y47: =SUM(Y43:Y46)+Y40 -> 243568 | Z47: =SUM(Z43:Z46)+Z40 -> 223753 | AB47: =SUM(Z47/V47)-1 -> 0.29690081
B49: Current Liabilities
B50: Accounts payable and other accrued expenses | C50: 7126 | D50: 4017 | E50: 10573 | G50: 3332 | H50: 4758 | I50: 3534 | J50: =D50 -> 4017 | K50: 8242 | L50: 10338 | M50: 9492 | N50: =E50 -> 10573 | O50: 9603 | P50: 52552 | Q50: 52244 | S50: =J50 -> 4017 | T50: =K50 -> 8242 | U50: =L50 -> 10338 | V50: =M50 -> 9492 | W50: =N50 -> 10573 | X50: =O50 -> 9603 | Y50: =P50 -> 52552 | Z50: =Q50 -> 52244 | AB50: =SUM(Z50/V50)-1 -> 4.5040034
B51: Accrued development expense | C51: 2803 | D51: 2280 | E51: 3037 | G51: 2925 | H51: 3318 | I51: 4096 | J51: =D51 -> 2280 | K51: 5276 | L51: 7044 | M51: 7344 | N51: =E51 -> 3037 | O51: 1797 | P51: 1596 | Q51: 2543 | S51: =J51 -> 2280 | T51: =K51 -> 5276 | U51: =L51 -> 7044 | V51: =M51 -> 7344 | W51: =N51 -> 3037 | X51: =O51 -> 1797 | Y51: =P51 -> 1596 | Z51: =Q51 -> 2543 | AB51: =SUM(Z51/V51)-1 -> -0.65373094
...

Sheet FCF
B2: Cassava Sciences (NASDAQ: SAVA) | C2: FYE | G2: Quarterly | M2: Quarterly | V2: LTM | AB2: Variance
B3: FCF Analysis | C3: ='Historical Financials'!C7 -> 2021 | D3: ='Historical Financials'!D7 -> 2022 | E3: ='Historical Financials'!E7 -> 2023 | F3: ='Historical Financials'!F7 -> 0 | G3: ='Historical Financials'!G7 -> 1Q22 | H3: ='Historical Financials'!H7 -> 2Q22 | I3: ='Historical Financials'!I7 -> 3Q22 | J3: ='Historical Financials'!J7 -> 4Q22 | ... Q3: ='Historical Financials'!Q7 -> 3Q24 | S3: =N3 -> 4Q23 | T3: =O3 -> 1Q24 | U3: =P3 -> 2Q24 | V3: =M3 -> 3Q23 | W3: =N3 -> 4Q23 | X3: =O3 -> 1Q24 | Y3: =P3 -> 2Q24 | Z3: =Q3 -> 3Q24
B4: $ in thousands except per share | C4: ='Historical Financials'!C8 -> 44561 | D4: ='Historical Financials'!D8 -> 44926 | E4: ='Historical Financials'!E8 -> 45291 | F4: ='Historical Financials'!F8 -> 0 | G4: ='Historical Financials'!G8 -> 44651 | H4: ='Historical Financials'!H8 -> 44742 | I4: ='Historical Financials'!I8 -> 44834 | J4: ='Historical Financials'!J8 -> 44926 | ... Q4: ='Historical Financials'!Q8 -> 45565 | S4: =N4 -> 45291 | T4: =O4 -> 45382 | U4: =P4 -> 45473 | V4: =M4 -> 45199 | W4: =N4 -> 45291 | X4: =O4 -> 45382 | Y4: =P4 -> 45473 | Z4: =Q4 -> 45565
B6: Total Revenue | C6: ='Historical Financials'!C10 -> 0 | D6: ='Historical Financials'!D10 -> 0 | E6: ='Historical Financials'!E10 -> 0 | G6: ='Historical Financials'!G10 -> 0 | H6: ='Historical Financials'!H10 -> 0 | I6: ='Historical Financials'!I10 -> 0 | J6: ='Historical Financials'!J10 -> 0 | K6: ='Historical Financials'!K10 -> 0 | L6: ='Historical Financials'!L10 -> 0 | M6: ='Historical Financials'!M10 -> 0 | N6: ='Historical Financials'!N10 -> 0 | ... Q6: ='Historical Financials'!Q10 -> 0 | S6: =SUM(G6:J6) -> 0 | T6: =SUM(H6:K6) -> 0 | U6: =SUM(I6:L6) -> 0 | V6: =SUM(J6:M6) -> 0 | W6: =SUM(K6:N6) -> 0 | X6: =SUM(L6:O6) -> 0 | Y6: =SUM(M6:P6) -> 0 | Z6: =SUM(N6:Q6) -> 0 | AB6: =SUM(Z6/V6)-1 -> #DIV/0!
B7: Total Revenue | C7: =SUM(C6:C6) -> 0 | D7: =SUM(D6:D6) -> 0 | E7: =SUM(E6:E6) -> 0 | G7: ='Historical Financials'!G11 -> 0 | H7: ='Historical Financials'!H11 -> 0 | I7: ='Historical Financials'!I11 -> 0 | J7: ='Historical Financials'!J11 -> 0 | K7: ='Historical Financials'!K11 -> 0 | L7: ='Historical Financials'!L11 -> 0 | M7: ='Historical Financials'!M11 -> 0 | N7: ='Historical Financials'!N11 -> 0 | O7: =SUM(O6:O6) -> 0 | P7: =SUM(P6:P6) -> 0 | Q7: =SUM(Q6:Q6) -> 0 | S7: =SUM(K7:N7) -> 0 | T7: =SUM(T6:T6) -> 0 | U7: =SUM(U6:U6) -> 0 | V7: =SUM(V6:V6) -> 0 | W7: =SUM(W6:W6) -> 0 | X7: =SUM(X6:X6) -> 0 | Y7: =SUM(Y6:Y6) -> 0 | Z7: =SUM(Z6:Z6) -> 0 | AB7: =SUM(Z7/V7)-1 -> #DIV/0!
B8: Y/Y Growth (%) | D8: =SUM(D7/C7)-1 -> #DIV/0! | E8: =SUM(E7/D7)-1 -> #DIV/0! | L8: =SUM(L7/H7)-1 -> #DIV/0! | M8: =SUM(M7/I7)-1 -> #DIV/0! | N8: =SUM(N7/J7)-1 -> #DIV/0! | O8: =SUM(O7/K7)-1 -> #DIV/0! | P8: =SUM(P7/L7)-1 -> #DIV/0! | Q8: =SUM(Q7/M7)-1 -> #DIV/0! | W8: =SUM(W7/S7)-1 -> #DIV/0! | X8: =SUM(X7/T7)-1 -> #DIV/0! | Y8: =SUM(Y7/U7)-1 -> #DIV/0! | Z8: =SUM(Z7/V7)-1 -> #DIV/0! | AB8: =SUM(Z8-V8)*10000 -> #DIV/0!
B9: Q/Q Growth (%) | C9: N/A | D9: N/A | E9: N/A | I9: =SUM(I7/H7)-1 -> #DIV/0! | J9: =SUM(J7/I7)-1 -> #DIV/0! | K9: =SUM(K7/J7)-1 -> #DIV/0! | L9: =SUM(L7/K7)-1 -> #DIV/0! | M9: =SUM(M7/L7)-1 -> #DIV/0! | N9: =SUM(N7/M7)-1 -> #DIV/0! | O9: =SUM(O7/N7)-1 -> #DIV/0! | P9: =SUM(P7/O7)-1 -> #DIV/0! | Q9: =SUM(Q7/P7)-1 -> #DIV/0! | S9: N/A | T9: N/A | U9: N/A | V9: N/A | W9: N/A | X9: N/A | Y9: N/A | Z9: N/A
B11: (-) Cost of Sales | C11: ='Historical Financials'!C13 -> 0 | D11: ='Historical Financials'!D13 -> 0 | E11: ='Historical Financials'!E13 -> 0 | G11: ='Historical Financials'!G13 -> 0 | H11: ='Historical Financials'!H13 -> 0 | I11: ='Historical Financials'!I13 -> 0 | J11: ='Historical Financials'!J13 -> 0 | K11: ='Historical Financials'!K13 -> 0 | L11: ='Historical Financials'!L13 -> 0 | M11: ='Historical Financials'!M13 -> 0 | N11: ='Historical Financials'!N13 -> 0 | ... Q11: ='Historical Financials'!Q13 -> 0 | S11: =SUM(G11:J11) -> 0 | T11: =SUM(H11:K11) -> 0 | U11: =SUM(I11:L11) -> 0 | V11: =SUM(J11:M11) -> 0 | W11: =SUM(K11:N11) -> 0 | X11: =SUM(L11:O11) -> 0 | Y11: =SUM(M11:P11) -> 0 | Z11: =SUM(N11:Q11) -> 0 | AB11: =SUM(Z11/V11)-1 -> #DIV/0!
B12: Gross Profit | C12: =+C7+C11 -> 0 | D12: =+D7+D11 -> 0 | E12: =+E7+E11 -> 0 | G12: =+G7+G11 -> 0 | H12: =+H7+H11 -> 0 | I12: =+I7+I11 -> 0 | J12: =+J7+J11 -> 0 | K12: =+K7+K11 -> 0 | L12: =+L7+L11 -> 0 | M12: =+M7+M11 -> 0 | N12: =+N7+N11 -> 0 | ... Q12: =+Q7+Q11 -> 0 | S12: =+S7+S11 -> 0 | T12: =+T7+T11 -> 0 | U12: =+U7+U11 -> 0 | V12: =+V7+V11 -> 0 | W12: =+W7+W11 -> 0 | X12: =+X7+X11 -> 0 | Y12: =+Y7+Y11 -> 0 | Z12: =+Z7+Z11 -> 0 | AB12: =SUM(Z12/V12)-1 -> #DIV/0!
B13: Gross Margin (%) | C13: =C12/C7 -> #DIV/0! | D13: =D12/D7 -> #DIV/0! | E13: =E12/E7 -> #DIV/0! | G13: =G12/G7 -> #DIV/0! | H13: =H12/H7 -> #DIV/0! | I13: =I12/I7 -> #DIV/0! | J13: =J12/J7 -> #DIV/0! | K13: =K12/K7 -> #DIV/0! | L13: =L12/L7 -> #DIV/0! | M13: =M12/M7 -> #DIV/0! | N13: =N12/N7 -> #DIV/0! | ... Q13: =Q12/Q7 -> #DIV/0! | S13: =S12/S7 -> #DIV/0! | T13: =T12/T7 -> #DIV/0! | U13: =U12/U7 -> #DIV/0! | V13: =V12/V7 -> #DIV/0! | W13: =W12/W7 -> #DIV/0! | X13: =X12/X7 -> #DIV/0! | Y13: =Y12/Y7 -> #DIV/0! | Z13: =Z12/Z7 -> #DIV/0! | AB13: =SUM(Z13-V13)*10000 -> #DIV/0!
B15: (-) Research and development, net of grant reimbursement | C15: ='Historical Financials'!C17 -> -24813 | D15: ='Historical Financials'!D17 -> -68032 | E15: ='Historical Financials'!E17 -> -89423 | G15: ='Historical Financials'!G17 -> -14906 | H15: ='Historical Financials'!H17 -> -16948 | I15: ='Historical Financials'!I17 -> -18526 | J15: ='Historical Financials'!J17 -> -17652 | K15: ='Historical Financials'!K17 -> -22120 | L15: ='Historical Financials'!L17 -> -24969 | M15: ='Historical Financials'!M17 -> -23603 | N15: ='Historical Financials'!N17 -> -18731 | ... Q15: ='Historical Financials'!Q17 -> -17676 | S15: =SUM(G15:J15) -> -68032 | T15: =SUM(H15:K15) -> -75246 | U15: =SUM(I15:L15) -> -83267 | V15: =SUM(J15:M15) -> -88344 | W15: =SUM(K15:N15) -> -89423 | X15: =SUM(L15:O15) -> -83536 | Y15: =SUM(M15:P15) -> -73765 | Z15: =SUM(N15:Q15) -> -67838 | AB15: =SUM(Z15/V15)-1 -> -0.23211537
B16: (-) General and administrative | C16: ='Historical Financials'!C18 -> -8055 | D16: ='Historical Financials'!D18 -> -11988 | E16: ='Historical Financials'!E18 -> -16534 | G16: ='Historical Financials'!G18 -> -2915 | H16: ='Historical Financials'!H18 -> -2969 | I16: ='Historical Financials'!I18 -> -2819 | J16: ='Historical Financials'!J18 -> -3285 | K16: ='Historical Financials'!K18 -> -4392 | L16: ='Historical Financials'!L18 -> -3808 | M16: ='Historical Financials'!M18 -> -4276 | N16: ='Historical Financials'!N18 -> -4058 | ... Q16: ='Historical Financials'!Q18 -> -12947 | S16: =SUM(G16:J16) -> -11988 | T16: =SUM(H16:K16) -> -13465 | U16: =SUM(I16:L16) -> -14304 | V16: =SUM(J16:M16) -> -15761 | W16: =SUM(K16:N16) -> -16534 | X16: =SUM(L16:O16) -> -15843 | Y16: =SUM(M16:P16) -> -58239 | Z16: =SUM(N16:Q16) -> -66910 | AB16: =SUM(Z16/V16)-1 -> 3.245289
B17: Earning before Interest & Taxes (EBIT) | C17: =SUM(C12+SUM(C15:C16)) -> -32868 | D17: =SUM(D12+SUM(D15:D16)) -> -80020 | E17: =SUM(E12+SUM(E15:E16)) -> -105957 | G17: =SUM(G12+SUM(G15:G16)) -> -17821 | H17: =SUM(H12+SUM(H15:H16)) -> -19917 | I17: =SUM(I12+SUM(I15:I16)) -> -21345 | J17: =SUM(J12+SUM(J15:J16)) -> -20937 | K17: =SUM(K12+SUM(K15:K16)) -> -26512 | L17: =SUM(L12+SUM(L15:L16)) -> -28777 | M17: =SUM(M12+SUM(M15:M16)) -> -27879 | N17: =SUM(N12+SUM(N15:N16)) -> -22789 | ... Q17: =SUM(Q12+SUM(Q15:Q16)) -> -30623 | S17: =SUM(S12+SUM(S15:S16)) -> -80020 | T17: =SUM(T12+SUM(T15:T16)) -> -88711 | U17: =SUM(U12+SUM(U15:U16)) -> -97571 | V17: =SUM(V12+SUM(V15:V16)) -> -104105 | W17: =SUM(W12+SUM(W15:W16)) -> -105957 | X17: =SUM(X12+SUM(X15:X16)) -> -99379 | Y17: =SUM(Y12+SUM(Y15:Y16)) -> -132004 | Z17: =SUM(Z12+SUM(Z15:Z16)) -> -134748 | AB17: =SUM(Z17/V17)-1 -> 0.29434705
B18: Operating Margin (%) | C18: =C17/C7 -> #DIV/0! | D18: =D17/D7 -> #DIV/0! | E18: =E17/E7 -> #DIV/0! | G18: =G17/G7 -> #DIV/0! | H18: =H17/H7 -> #DIV/0! | I18: =I17/I7 -> #DIV/0! | J18: =J17/J7 -> #DIV/0! | K18: =K17/K7 -> #DIV/0! | L18: =L17/L7 -> #DIV/0! | M18: =M17/M7 -> #DIV/0! | N18: =N17/N7 -> #DIV/0! | ... Q18: =Q17/Q7 -> #DIV/0! | S18: =S17/S7 -> #DIV/0! | T18: =T17/T7 -> #DIV/0! | U18: =U17/U7 -> #DIV/0! | V18: =V17/V7 -> #DIV/0! | W18: =W17/W7 -> #DIV/0! | X18: =X17/X7 -> #DIV/0! | Y18: =Y17/Y7 -> #DIV/0! | Z18: =Z17/Z7 -> #DIV/0! | AB18: =SUM(Z18-V18)*10000 -> #DIV/0!
B20: (+) Depreciation and Amortization | C20: ='Historical Financials'!C83+'Historical Financials'!C84 -> 534 | D20: ='Historical Financials'!D83+'Historical Financials'!D84 -> 1301 | E20: ='Historical Financials'!E83+'Historical Financials'!E84 -> 1530 | G20: ='Historical Financials'!G83+'Historical Financials'!G84 -> 313 | H20: ='Historical Financials'!H83+'Historical Financials'!H84 -> 299 | I20: ='Historical Financials'!I83+'Historical Financials'!I84 -> 300 | J20: ='Historical Financials'!J83+'Historical Financials'!J84 -> 389 | K20: ='Historical Financials'!K83+'Historical Financials'!K84 -> 391 | L20: ='Historical Financials'!L83+'Historical Financials'!L84 -> 391 | M20: ='Historical Financials'!M83+'Historical Financials'!M84 -> 392 | N20: ='Historical Financials'!N83+'Historical Financials'!N84 -> 356 | ... Q20: ='Historical Financials'!Q83+'Historical Financials'!Q84 -> 259 | S20: =SUM(G20:J20) -> 1301 | T20: =SUM(H20:K20) -> 1379 | U20: =SUM(I20:L20) -> 1471 | V20: =SUM(J20:M20) -> 1563 | W20: =SUM(K20:N20) -> 1530 | X20: =SUM(L20:O20) -> 1450 | Y20: =SUM(M20:P20) -> 1361 | Z20: =SUM(N20:Q20) -> 1228 | AB20: =SUM(Z20/V20)-1 -> -0.21433141
B21: EBITDA | C21: =SUM(C17+C20) -> -32334 | D21: =SUM(D17+D20) -> -78719 | E21: =SUM(E17+E20) -> -104427 | G21: =SUM(G17+G20) -> -17508 | H21: =SUM(H17+H20) -> -19618 | I21: =SUM(I17+I20) -> -21045 | J21: =SUM(J17+J20) -> -20548 | K21: =SUM(K17+K20) -> -26121 | L21: =SUM(L17+L20) -> -28386 | M21: =SUM(M17+M20) -> -27487 | N21: =SUM(N17+N20) -> -22433 | ... Q21: =SUM(Q17+Q20) -> -30364 | S21: =SUM(S17+S20) -> -78719 | T21: =SUM(T17+T20) -> -87332 | U21: =SUM(U17+U20) -> -96100 | V21: =SUM(V17+V20) -> -102542 | W21: =SUM(W17+W20) -> -104427 | X21: =SUM(X17+X20) -> -97929 | Y21: =SUM(Y17+Y20) -> -130643 | Z21: =SUM(Z17+Z20) -> -133520 | AB21: =SUM(Z21/V21)-1 -> 0.3021006
B22: EBITDA Margin (%) | C22: =C21/C7 -> #DIV/0! | D22: =D21/D7 -> #DIV/0! | E22: =E21/E7 -> #DIV/0! | G22: =G21/G7 -> #DIV/0! | H22: =H21/H7 -> #DIV/0! | I22: =I21/I7 -> #DIV/0! | J22: =J21/J7 -> #DIV/0! | K22: =K21/K7 -> #DIV/0! | L22: =L21/L7 -> #DIV/0! | M22: =M21/M7 -> #DIV/0! | N22: =N21/N7 -> #DIV/0! | ... Q22: =Q21/Q7 -> #DIV/0! | S22: =S21/S7 -> #DIV/0! | T22: =T21/T7 -> #DIV/0! | U22: =U21/U7 -> #DIV/0! | V22: =V21/V7 -> #DIV/0! | W22: =W21/W7 -> #DIV/0! | X22: =X21/X7 -> #DIV/0! | Y22: =Y21/Y7 -> #DIV/0! | Z22: =Z21/Z7 -> #DIV/0! | AB22: =SUM(Z22-V22)*10000 -> #DIV/0!
B24: (+) Share-based Compensation | C24: ='Historical Financials'!C81 -> 1759 | D24: ='Historical Financials'!D81 -> 2066 | E24: ='Historical Financials'!E81 -> 4586 | G24: ='Historical Financials'!G81 -> 495 | H24: ='Historical Financials'!H81 -> 485 | I24: ='Historical Financials'!I81 -> 470 | J24: ='Historical Financials'!J81 -> 616 | K24: ='Historical Financials'!K81 -> 673 | L24: ='Historical Financials'!L81 -> 835 | M24: ='Historical Financials'!M81 -> 949 | N24: ='Historical Financials'!N81 -> 2129 | ... Q24: ='Historical Financials'!Q81 -> 5608 | S24: =SUM(G24:J24) -> 2066 | T24: =SUM(H24:K24) -> 2244 | U24: =SUM(I24:L24) -> 2594 | V24: =SUM(J24:M24) -> 3073 | W24: =SUM(K24:N24) -> 4586 | X24: =SUM(L24:O24) -> 6248 | Y24: =SUM(M24:P24) -> 8017 | Z24: =SUM(N24:Q24) -> 12676 | AB24: =SUM(Z24/V24)-1 -> 3.1249593
B25: Adj. EBITDA | C25: =+SUM(C21+SUM(C24:C24)) -> -30575 | D25: =+SUM(D21+SUM(D24:D24)) -> -76653 | E25: =+SUM(E21+SUM(E24:E24)) -> -99841 | G25: =+SUM(G21+SUM(G24:G24)) -> -17013 | H25: =+SUM(H21+SUM(H24:H24)) -> -19133 | I25: =+SUM(I21+SUM(I24:I24)) -> -20575 | J25: =+SUM(J21+SUM(J24:J24)) -> -19932 | K25: =+SUM(K21+SUM(K24:K24)) -> -25448 | L25: =+SUM(L21+SUM(L24:L24)) -> -27551 | M25: =+SUM(M21+SUM(M24:M24)) -> -26538 | N25: =+SUM(N21+SUM(N24:N24)) -> -20304 | ... Q25: =+SUM(Q21+SUM(Q24:Q24)) -> -24756 | S25: =+SUM(S21+SUM(S24:S24)) -> -76653 | T25: =+SUM(T21+SUM(T24:T24)) -> -85088 | U25: =+SUM(U21+SUM(U24:U24)) -> -93506 | V25: =+SUM(V21+SUM(V24:V24)) -> -99469 | W25: =+SUM(W21+SUM(W24:W24)) -> -99841 | X25: =+SUM(X21+SUM(X24:X24)) -> -91681 | Y25: =+SUM(Y21+SUM(Y24:Y24)) -> -122626 | Z25: =+SUM(Z21+SUM(Z24:Z24)) -> -120844 | AB25: =SUM(Z25/V25)-1 -> 0.21489107
B26: Adj. EBITDA Margin (%) | C26: =C25/C7 -> #DIV/0! | D26: =D25/D7 -> #DIV/0! | E26: =E25/E7 -> #DIV/0! | G26: =G25/G7 -> #DIV/0! | H26: =H25/H7 -> #DIV/0! | I26: =I25/I7 -> #DIV/0! | J26: =J25/J7 -> #DIV/0! | K26: =K25/K7 -> #DIV/0! | L26: =L25/L7 -> #DIV/0! | M26: =M25/M7 -> #DIV/0! | N26: =N25/N7 -> #DIV/0! | ... Q26: =Q25/Q7 -> #DIV/0! | S26: =S25/S7 -> #DIV/0! | T26: =T25/T7 -> #DIV/0! | U26: =U25/U7 -> #DIV/0! | V26: =V25/V7 -> #DIV/0! | W26: =W25/W7 -> #DIV/0! | X26: =X25/X7 -> #DIV/0! | Y26: =Y25/Y7 -> #DIV/0! | Z26: =Z25/Z7 -> #DIV/0! | AB26: =SUM(Z26-V26)*10000 -> #DIV/0!
B28: (-) Capital Expenditures | C28: ='Historical Financials'!C96 -> -22214 | D28: ='Historical Financials'!D96 -> -2712 | E28: ='Historical Financials'!E96 -> -414 | G28: ='Historical Financials'!G96 -> -425 | H28: ='Historical Financials'!H96 -> -1466 | I28: ='Historical Financials'!I96 -> -1156 | J28: ='Historical Financials'!J96 -> 335 | K28: ='Historical Financials'!K96 -> -357 | L28: ='Historical Financials'!L96 -> 6 | M28: ='Historical Financials'!M96 -> -22 | N28: ='Historical Financials'!N96 -> -41 | ... Q28: ='Historical Financials'!Q96 -> -17 | S28: =SUM(G28:J28) -> -2712 | T28: =SUM(H28:K28) -> -2644 | U28: =SUM(I28:L28) -> -1172 | V28: =SUM(J28:M28) -> -38 | W28: =SUM(K28:N28) -> -414 | X28: =SUM(L28:O28) -> -57 | Y28: =SUM(M28:P28) -> -92 | Z28: =SUM(N28:Q28) -> -87 | AB28: =SUM(Z28/V28)-1 -> 1.2894737
B29: (-) Cash Taxes | C29: 0 | D29: 0 | E29: 0 | G29: 0 | H29: 0 | I29: 0 | J29: 0 | K29: 0 | L29: 0 | M29: 0 | N29: 0 | O29: 0 | P29: 0 | Q29: 0 | S29: =SUM(G29:J29) -> 0 | T29: =SUM(H29:K29) -> 0 | U29: =SUM(I29:L29) -> 0 | V29: =SUM(J29:M29) -> 0 | W29: =SUM(K29:N29) -> 0 | X29: =SUM(L29:O29) -> 0 | Y29: =SUM(M29:P29) -> 0 | Z29: =SUM(N29:Q29) -> 0 | AB29: =SUM(Z29/V29)-1 -> #DIV/0!
B30: (-) Cash Interest | C30: 0 | D30: 0 | E30: 0 | G30: 0 | H30: 0 | I30: 0 | J30: 0 | K30: 0 | L30: 0 | M30: 0 | N30: 0 | O30: 0 | P30: 0 | Q30: 0 | S30: =SUM(G30:J30) -> 0 | T30: =SUM(H30:K30) -> 0 | U30: =SUM(I30:L30) -> 0 | V30: =SUM(J30:M30) -> 0 | W30: =SUM(K30:N30) -> 0 | X30: =SUM(L30:O30) -> 0 | Y30: =SUM(M30:P30) -> 0 | Z30: =SUM(N30:Q30) -> 0 | AB30: =SUM(Z30/V30)-1 -> #DIV/0!
B31: (+/-) Changes in NWC | C31: =SUM('Historical Financials'!C87:C92) -> -104 | D31: =SUM('Historical Financials'!D87:D92) -> -4635 | E31: =SUM('Historical Financials'!E87:E92) -> 9076 | G31: =SUM('Historical Financials'!G87:G92) -> -6811 | H31: =SUM('Historical Financials'!H87:H92) -> 7430 | I31: =SUM('Historical Financials'!I87:I92) -> -2063 | J31: =SUM('Historical Financials'!J87:J92) -> -3191 | K31: =SUM('Historical Financials'!K87:K92) -> 9952 | L31: =SUM('Historical Financials'!L87:L92) -> 5226 | M31: =SUM('Historical Financials'!M87:M92) -> -2220 | N31: =SUM('Historical Financials'!N87:N92) -> -3882 | ... Q31: =SUM('Historical Financials'!Q87:Q92) -> 3780 | S31: =SUM(G31:J31) -> -4635 | T31: =SUM(H31:K31) -> 12128 | U31: =SUM(I31:L31) -> 9924 | V31: =SUM(J31:M31) -> 9767 | W31: =SUM(K31:N31) -> 9076 | X31: =SUM(L31:O31) -> -4651 | Y31: =SUM(M31:P31) -> 27963 | Z31: =SUM(N31:Q31) -> 33963 | AB31: =SUM(Z31/V31)-1 -> 2.4773216
B32: Discretionary Cash-Flows | C32: =SUM(C25+SUM(C28:C31)) -> -52893 | D32: =SUM(D25+SUM(D28:D31)) -> -84000 | E32: =SUM(E25+SUM(E28:E31)) -> -91179 | G32: =SUM(G25+SUM(G28:G31)) -> -24249 | H32: =SUM(H25+SUM(H28:H31)) -> -13169 | I32: =SUM(I25+SUM(I28:I31)) -> -23794 | J32: =SUM(J25+SUM(J28:J31)) -> -22788 | K32: =SUM(K25+SUM(K28:K31)) -> -15853 | L32: =SUM(L25+SUM(L28:L31)) -> -22319 | M32: =SUM(M25+SUM(M28:M31)) -> -28780 | N32: =SUM(N25+SUM(N28:N31)) -> -24227 | ... Q32: =SUM(Q25+SUM(Q28:Q31)) -> -20993 | S32: =SUM(S25+SUM(S28:S31)) -> -84000 | T32: =SUM(T25+SUM(T28:T31)) -> -75604 | U32: =SUM(U25+SUM(U28:U31)) -> -84754 | V32: =SUM(V25+SUM(V28:V31)) -> -89740 | W32: =SUM(W25+SUM(W28:W31)) -> -91179 | X32: =SUM(X25+SUM(X28:X31)) -> -96389 | Y32: =SUM(Y25+SUM(Y28:Y31)) -> -94755 | Z32: =SUM(Z25+SUM(Z28:Z31)) -> -86968 | AB32: =SUM(Z32/V32)-1 -> -0.030889236
B34: (+/-) Proceeds from issuance of common stock upon exercise of stock options | C34: ='Historical Financials'!C100 -> 1824 | D34: ='Historical Financials'!D100 -> 475 | E34: ='Historical Financials'!E100 -> 2560 | G34: ='Historical Financials'!G100 -> 211 | H34: ='Historical Financials'!H100 -> 119 | I34: ='Historical Financials'!I100 -> 136 | J34: ='Historical Financials'!J100 -> 9 | K34: ='Historical Financials'!K100 -> 64 | L34: ='Historical Financials'!L100 -> 889 | M34: ='Historical Financials'!M100 -> 464 | N34: ='Historical Financials'!N100 -> 1143 | ... Q34: ='Historical Financials'!Q100 -> 0 | S34: =SUM(G34:J34) -> 475 | T34: =SUM(H34:K34) -> 328 | U34: =SUM(I34:L34) -> 1098 | V34: =SUM(J34:M34) -> 1426 | W34: =SUM(K34:N34) -> 2560 | X34: =SUM(L34:O34) -> 2496 | Y34: =SUM(M34:P34) -> 1607 | Z34: =SUM(N34:Q34) -> 1143
B35: (+/-) Proceeds from issuance of common stock upon exercise of 2018 warrants | C35: ='Historical Financials'!C101 -> 692 | D35: ='Historical Financials'!D101 -> 0 | E35: ='Historical Financials'!E101 -> 0 | G35: ='Historical Financials'!G101 -> 0 | H35: ='Historical Financials'!H101 -> 0 | I35: ='Historical Financials'!I101 -> 0 | J35: ='Historical Financials'!J101 -> 0 | K35: ='Historical Financials'!K101 -> 0 | L35: ='Historical Financials'!L101 -> 0 | M35: ='Historical Financials'!M101 -> 0 | N35: ='Historical Financials'!N101 -> 0 | ... Q35: ='Historical Financials'!Q101 -> 0 | S35: =SUM(G35:J35) -> 0 | T35: =SUM(H35:K35) -> 0 | U35: =SUM(I35:L35) -> 0 | V35: =SUM(J35:M35) -> 0 | W35: =SUM(K35:N35) -> 0 | X35: =SUM(L35:O35) -> 0 | Y35: =SUM(M35:P35) -> 0 | Z35: =SUM(N35:Q35) -> 0
B36: (+/-) Proceeds from exercise of common stock warrants, net of exercise costs | C36: ='Historical Financials'!C102 -> 0 | D36: ='Historical Financials'!D102 -> 0 | E36: ='Historical Financials'!E102 -> 0 | G36: ='Historical Financials'!G102 -> 0 | H36: ='Historical Financials'!H102 -> 0 | I36: ='Historical Financials'!I102 -> 0 | J36: ='Historical Financials'!J102 -> 0 | K36: ='Historical Financials'!K102 -> 0 | L36: ='Historical Financials'!L102 -> 0 | M36: ='Historical Financials'!M102 -> 0 | N36: ='Historical Financials'!N102 -> 0 | ... Q36: ='Historical Financials'!Q102 -> 0 | S36: =SUM(G36:J36) -> 0 | T36: =SUM(H36:K36) -> 0 | U36: =SUM(I36:L36) -> 0 | V36: =SUM(J36:M36) -> 0 | W36: =SUM(K36:N36) -> 0 | X36: =SUM(L36:O36) -> 22160 | Y36: =SUM(M36:P36) -> 123552 | Z36: =SUM(N36:Q36) -> 123552
B37: (+/-) Proceeds from common stock offering, net of issuance costs | C37: ='Historical Financials'!C103 -> 189825 | D37: ='Historical Financials'!D103 -> 47329 | E37: ='Historical Financials'!E103 -> 0 | G37: ='Historical Financials'!G103 -> 0 | H37: ='Historical Financials'!H103 -> 0 | I37: ='Historical Financials'!I103 -> 0 | J37: ='Historical Financials'!J103 -> 47329 | K37: ='Historical Financials'!K103 -> 0 | L37: ='Historical Financials'!L103 -> 0 | M37: ='Historical Financials'!M103 -> 0 | N37: ='Historical Financials'!N103 -> 0 | ... Q37: ='Historical Financials'!Q103 -> 0 | S37: =SUM(G37:J37) -> 47329 | T37: =SUM(H37:K37) -> 47329 | U37: =SUM(I37:L37) -> 47329 | V37: =SUM(J37:M37) -> 47329 | W37: =SUM(K37:N37) -> 0 | X37: =SUM(L37:O37) -> 0 | Y37: =SUM(M37:P37) -> 0 | Z37: =SUM(N37:Q37) -> 0
B38: (+/-) Other | D38: =SUM(D43:D44)-SUM(C43:C44)-SUM(D32:D37) -> 3774 | E38: =SUM(E43:E44)-SUM(D43:D44)-SUM(E32:E37) -> 8740 | H38: =SUM(H43:H44)-SUM(G43:G44)-SUM(H32:H37) -> 589 | I38: =SUM(I43:I44)-SUM(H43:H44)-SUM(I32:I37) -> 1088 | J38: =SUM(J43:J44)-SUM(I43:I44)-SUM(J32:J37) -> 1803 | K38: =SUM(K43:K44)-SUM(J43:J44)-SUM(K32:K37) -> 2241 | L38: =SUM(L43:L44)-SUM(K43:K44)-SUM(L32:L37) -> 2401 | M38: =SUM(M43:M44)-SUM(L43:L44)-SUM(M32:M37) -> 2228 | N38: =SUM(N43:N44)-SUM(M43:M44)-SUM(N32:N37) -> 1870 | O38: =SUM(O43:O44)-SUM(N43:N44)-SUM(O32:O37) -> 1936 | ... Q38: =SUM(Q43:Q44)-SUM(P43:P44)-SUM(Q32:Q37) -> 2680 | S38: =SUM(G38:J38) -> 3480 | T38: =SUM(H38:K38) -> 5721 | U38: =SUM(I38:L38) -> 7533 | V38: =SUM(J38:M38) -> 8673 | W38: =SUM(K38:N38) -> 8740 | X38: =SUM(L38:O38) -> 8435 | Y38: =SUM(M38:P38) -> 8449 | Z38: =SUM(N38:Q38) -> 8901
B39: Free-Cash Flows | C39: =SUM(C32+SUM(C34:C38)) -> 139448 | D39: =SUM(D32+SUM(D34:D38)) -> -32422 | E39: =SUM(E32+SUM(E34:E38)) -> -79879 | G39: =SUM(G32+SUM(G34:G38)) -> -24038 | H39: =SUM(H32+SUM(H34:H38)) -> -12461 | I39: =SUM(I32+SUM(I34:I38)) -> -22570 | J39: =SUM(J32+SUM(J34:J38)) -> 26353 | K39: =SUM(K32+SUM(K34:K38)) -> -13548 | L39: =SUM(L32+SUM(L34:L38)) -> -19029 | M39: =SUM(M32+SUM(M34:M38)) -> -26088 | N39: =SUM(N32+SUM(N34:N38)) -> -21214 | ... Q39: =SUM(Q32+SUM(Q34:Q38)) -> -18313 | S39: =SUM(S32+SUM(S34:S38)) -> -32716 | T39: =SUM(T32+SUM(T34:T38)) -> -22226 | U39: =SUM(U32+SUM(U34:U38)) -> -28794 | V39: =SUM(V32+SUM(V34:V38)) -> -32312 | W39: =SUM(W32+SUM(W34:W38)) -> -79879 | X39: =SUM(X32+SUM(X34:X38)) -> -63298 | Y39: =SUM(Y32+SUM(Y34:Y38)) -> 38853 | Z39: =SUM(Z32+SUM(Z34:Z38)) -> 46628
B41: Capitalization
B43: Cash & Cash Equivelants | C43: ='Historical Financials'!C37 -> 233437 | D43: ='Historical Financials'!D37 -> 201015 | E43: ='Historical Financials'!E37 -> 121136 | G43: ='Historical Financials'!G37 -> 209693 | H43: ='Historical Financials'!H37 -> 197232 | I43: ='Historical Financials'!I37 -> 174662 | J43: ='Historical Financials'!J37 -> 201015 | K43: ='Historical Financials'!K37 -> 187467 | L43: ='Historical Financials'!L37 -> 168438 | M43: ='Historical Financials'!M37 -> 142350 | N43: ='Historical Financials'!N37 -> 121136 | ... Q43: ='Historical Financials'!Q37 -> 148978 | S43: =J43 -> 201015 | T43: =K43 -> 187467 | U43: =L43 -> 168438 | V43: =M43 -> 142350 | W43: =N43 -> 121136 | X43: =O43 -> 124169 | Y43: =P43 -> 207291 | Z43: =Q43 -> 148978
B44: Restricted Cash | C44: ='Historical Financials'!C39 -> 0 | D44: ='Historical Financials'!D39 -> 0 | E44: ='Historical Financials'!E39 -> 0 | G44: ='Historical Financials'!G39 -> 0 | H44: ='Historical Financials'!H39 -> 0 | I44: ='Historical Financials'!I39 -> 0 | J44: ='Historical Financials'!J39 -> 0 | K44: ='Historical Financials'!K39 -> 0 | L44: ='Historical Financials'!L39 -> 0 | M44: ='Historical Financials'!M39 -> 0 | N44: ='Historical Financials'!N39 -> 0 | ... Q44: ='Historical Financials'!Q39 -> 40000 | S44: =J44 -> 0 | T44: =K44 -> 0 | U44: =L44 -> 0 | V44: =M44 -> 0 | W44: =N44 -> 0 | X44: =O44 -> 0 | Y44: =P44 -> 0 | Z44: =Q44 -> 40000
B45: Total Liquidity | C45: =SUM(C43:C44) -> 233437 | D45: =SUM(D43:D44) -> 201015 | E45: =SUM(E43:E44) -> 121136 | G45: =SUM(G43:G44) -> 209693 | H45: =SUM(H43:H44) -> 197232 | I45: =SUM(I43:I44) -> 174662 | J45: =SUM(J43:J44) -> 201015 | K45: =SUM(K43:K44) -> 187467 | L45: =SUM(L43:L44) -> 168438 | M45: =SUM(M43:M44) -> 142350 | N45: =SUM(N43:N44) -> 121136 | ... Q45: =SUM(Q43:Q44) -> 188978 | S45: =SUM(S43:S44) -> 201015 | T45: =SUM(T43:T44) -> 187467 | U45: =SUM(U43:U44) -> 168438 | V45: =SUM(V43:V44) -> 142350 | W45: =SUM(W43:W44) -> 121136 | X45: =SUM(X43:X44) -> 124169 | Y45: =SUM(Y43:Y44) -> 207291 | Z45: =SUM(Z43:Z44) -> 188978
B47: Balance Sheet Metrics:
B48: Property Plant, and Equiptment | C48: ='Historical Financials'!C44 -> 20616 | D48: ='Historical Financials'!D44 -> 22864 | E48: ='Historical Financials'!E44 -> 21854 | G48: ='Historical Financials'!G44 -> 20863 | H48: ='Historical Financials'!H44 -> 22155 | I48: ='Historical Financials'!I44 -> 23130 | J48: ='Historical Financials'!J44 -> 22864 | K48: ='Historical Financials'!K44 -> 22609 | L48: ='Historical Financials'!L44 -> 22328 | M48: ='Historical Financials'!M44 -> 22077 | N48: ='Historical Financials'!N44 -> 21854 | ... Q48: ='Historical Financials'!Q44 -> 21135 | S48: =J48 -> 22864 | T48: =K48 -> 22609 | U48: =L48 -> 22328 | V48: =M48 -> 22077 | W48: =N48 -> 21854 | X48: =O48 -> 21604 | Y48: =P48 -> 21364 | Z48: =Q48 -> 21135
B49: Accounts payable and other accrued expenses | C49: ='Historical Financials'!C50 -> 7126 | D49: ='Historical Financials'!D50 -> 4017 | E49: ='Historical Financials'!E50 -> 10573 | G49: ='Historical Financials'!G50 -> 3332 | H49: ='Historical Financials'!H50 -> 4758 | I49: ='Historical Financials'!I50 -> 3534 | J49: ='Historical Financials'!J50 -> 4017 | K49: ='Historical Financials'!K50 -> 8242 | L49: ='Historical Financials'!L50 -> 10338 | M49: ='Historical Financials'!M50 -> 9492 | N49: ='Historical Financials'!N50 -> 10573 | ... Q49: ='Historical Financials'!Q50 -> 52244 | S49: =J49 -> 4017 | T49: =K49 -> 8242 | U49: =L49 -> 10338 | V49: =M49 -> 9492 | W49: =N49 -> 10573 | X49: =O49 -> 9603 | Y49: =P49 -> 52552 | Z49: =Q49 -> 52244
B50: Accrued development expense | C50: ='Historical Financials'!C51 -> 2803 | D50: ='Historical Financials'!D51 -> 2280 | E50: ='Historical Financials'!E51 -> 3037 | G50: ='Historical Financials'!G51 -> 2925 | H50: ='Historical Financials'!H51 -> 3318 | I50: ='Historical Financials'!I51 -> 4096 | J50: ='Historical Financials'!J51 -> 2280 | K50: ='Historical Financials'!K51 -> 5276 | L50: ='Historical Financials'!L51 -> 7044 | M50: ='Historical Financials'!M51 -> 7344 | N50: ='Historical Financials'!N51 -> 3037 | ... Q50: ='Historical Financials'!Q51 -> 2543 | S50: =J50 -> 2280 | T50: =K50 -> 5276 | U50: =L50 -> 7044 | V50: =M50 -> 7344 | W50: =N50 -> 3037 | X50: =O50 -> 1797 | Y50: =P50 -> 1596 | Z50: =Q50 -> 2543
B51: Current Liabilities | C51: ='Historical Financials'!C56 -> 12534 | D51: ='Historical Financials'!D56 -> 7063 | E51: ='Historical Financials'!E56 -> 14195 | G51: ='Historical Financials'!G56 -> 6789 | H51: ='Historical Financials'!H56 -> 8722 | I51: ='Historical Financials'!I56 -> 8308 | J51: ='Historical Financials'!J56 -> 7063 | K51: ='Historical Financials'!K56 -> 13909 | L51: ='Historical Financials'!L56 -> 17895 | M51: ='Historical Financials'!M56 -> 17414 | N51: ='Historical Financials'!N56 -> 14195 | ... Q51: ='Historical Financials'!Q56 -> 57034 | S51: =J51 -> 7063 | T51: =K51 -> 13909 | U51: =L51 -> 17895 | V51: =M51 -> 17414 | W51: =N51 -> 14195 | X51: =O51 -> 77121 | Y51: =P51 -> 54594 | Z51: =Q51 -> 57034
...
