Workbook

Sheet Historical Financials
B2: Spirit Airlines, Inc. (NASDAQ: FLYYQ)
B3: Historical Financials
B4: $ in thousands except per share
A6: X | B6: Income Statement | F6: FYE | J6: Quarterly | P6: Quarterly | W6: LTM | X6: LTM | AD6: Variance
B7: Fiscal Period | C7: 2019 | D7: 2020 | E7: 2021 | F7: 2022 | G7: 2023 | H7: 2024 | J7: 1Q23 | K7: 2Q23 | L7: 3Q23 | M7: 4Q23 | N7: 1Q24 | O7: 2Q24 | P7: 3Q24 | Q7: 4Q24 | R7: 1Q25 | S7: 2Q25 | T7: 3Q25 | V7: =N7 -> 1Q24 | W7: =O7 -> 2Q24 | X7: =P7 -> 3Q24 | Y7: =Q7 -> 4Q24 | Z7: =R7 -> 1Q25 | AA7: =S7 -> 2Q25 | AB7: =T7 -> 3Q25
B8: Fiscal Period End Date | C8: 43830 | D8: 44196 | E8: 44561 | F8: 44926 | G8: 45291 | H8: 45657 | J8: 45016 | K8: 45107 | L8: 45199 | M8: =G8 -> 45291 | N8: 45382 | O8: 45473 | P8: 45565 | Q8: =H8 -> 45657 | R8: 45747 | S8: 45838 | T8: 45930 | V8: =N8 -> 45382 | W8: =O8 -> 45473 | X8: =P8 -> 45565 | Y8: =Q8 -> 45657 | Z8: =R8 -> 45747 | AA8: =S8 -> 45838 | AB8: =T8 -> 45930
B10: Consolidated Revenue | C10: 3830536 | D10: 1810022 | E10: 3230775 | F10: 5068447 | G10: 5362549 | H10: 4913421 | J10: 1349774 | K10: 1432472 | L10: 1258543 | M10: =SUM(G10-SUM(J10:L10)) -> 1321760 | N10: 1265537 | O10: 1280889 | P10: 1197104 | Q10: =SUM(H10-SUM(N10:P10)) -> 1169891 | R10: =755354+257045 -> 1012399 | S10: 1019833 | T10: 958524 | V10: =SUM(K10:N10) -> 5278312 | W10: =SUM(L10:O10) -> 5126729 | X10: =SUM(M10:P10) -> 5065290 | Y10: =SUM(N10:Q10) -> 4913421 | Z10: =SUM(O10:R10) -> 4660283 | AA10: =SUM(P10:S10) -> 4399227 | AB10: =SUM(Q10:T10) -> 4160647 | AD10: =SUM(AB10/X10)-1 -> -0.17859649
B11: Total Revenue | C11: =+SUM(C10:C10) -> 3830536 | D11: =+SUM(D10:D10) -> 1810022 | E11: =+SUM(E10:E10) -> 3230775 | F11: =+SUM(F10:F10) -> 5068447 | G11: =+SUM(G10:G10) -> 5362549 | H11: =+SUM(H10:H10) -> 4913421 | J11: =+SUM(J10:J10) -> 1349774 | K11: =+SUM(K10:K10) -> 1432472 | L11: =+SUM(L10:L10) -> 1258543 | M11: =+SUM(M10:M10) -> 1321760 | N11: =+SUM(N10:N10) -> 1265537 | O11: =+SUM(O10:O10) -> 1280889 | P11: =+SUM(P10:P10) -> 1197104 | Q11: =+SUM(Q10:Q10) -> 1169891 | ... T11: =+SUM(T10:T10) -> 958524 | V11: =+SUM(V10:V10) -> 5278312 | W11: =+SUM(W10:W10) -> 5126729 | X11: =+SUM(X10:X10) -> 5065290 | Y11: =+SUM(Y10:Y10) -> 4913421 | Z11: =+SUM(Z10:Z10) -> 4660283 | AA11: =+SUM(AA10:AA10) -> 4399227 | AB11: =+SUM(AB10:AB10) -> 4160647 | AD11: =SUM(AB11/X11)-1 -> -0.17859649
B13: Salaries, wages and benefits | C13: -865019 | D13: -909834 | E13: -1065461 | F13: -1251225 | G13: -1616803 | H13: -1689083 | J13: -389185 | K13: -407705 | L13: -404177 | M13: =SUM(G13-SUM(J13:L13)) -> -415736 | N13: -431483 | O13: -418378 | P13: -427125 | Q13: =SUM(H13-SUM(N13:P13)) -> -412097 | R13: =-76212-308585 -> -384797 | S13: -367361 | T13: -367356 | V13: =SUM(K13:N13) -> -1659101 | W13: =SUM(L13:O13) -> -1669774 | X13: =SUM(M13:P13) -> -1692722 | Y13: =SUM(N13:Q13) -> -1689083 | Z13: =SUM(O13:R13) -> -1642397 | AA13: =SUM(P13:S13) -> -1591380 | AB13: =SUM(Q13:T13) -> -1531611 | AD13: =SUM(AB13/X13)-1 -> -0.095178653
B14: Aircraft fuel | C14: -993478 | D14: -431000 | E14: -913945 | F14: -1929969 | G14: -1821165 | H14: -1479203 | J14: -487711 | K14: -391032 | L14: -455241 | M14: =SUM(G14-SUM(J14:L14)) -> -487181 | N14: -406351 | O14: -407296 | P14: -373399 | Q14: =SUM(H14-SUM(N14:P14)) -> -292157 | R14: =-60797-219922 -> -280719 | S14: -260486 | T14: -253308 | V14: =SUM(K14:N14) -> -1739805 | W14: =SUM(L14:O14) -> -1756069 | X14: =SUM(M14:P14) -> -1674227 | Y14: =SUM(N14:Q14) -> -1479203 | Z14: =SUM(O14:R14) -> -1353571 | AA14: =SUM(P14:S14) -> -1206761 | AB14: =SUM(Q14:T14) -> -1086670 | AD14: =SUM(AB14/X14)-1 -> -0.35094226
B15: Aircraft rent | C15: -182609 | D15: -196359 | E15: -246601 | F15: -282428 | G15: -381239 | H15: -541909 | J15: -85267 | K15: -92101 | L15: -97393 | M15: =SUM(G15-SUM(J15:L15)) -> -106478 | N15: -115206 | O15: -125339 | P15: -148511 | Q15: =SUM(H15-SUM(N15:P15)) -> -152853 | R15: =-30884-120183 -> -151067 | S15: -140693 | T15: -154064 | V15: =SUM(K15:N15) -> -411178 | W15: =SUM(L15:O15) -> -444416 | X15: =SUM(M15:P15) -> -495534 | Y15: =SUM(N15:Q15) -> -541909 | Z15: =SUM(O15:R15) -> -577770 | AA15: =SUM(P15:S15) -> -593124 | AB15: =SUM(Q15:T15) -> -598677 | AD15: =SUM(AB15/X15)-1 -> 0.20814515
B16: Landing fees and other rents | C16: -256275 | D16: -251028 | E16: -315999 | F16: -347268 | G16: -408262 | H16: -451008 | J16: -97345 | K16: -106487 | L16: -107525 | M16: =SUM(G16-SUM(J16:L16)) -> -96905 | N16: -106718 | O16: -116064 | P16: -130044 | Q16: =SUM(H16-SUM(N16:P16)) -> -98182 | R16: =-20944-87001 -> -107945 | S16: -101457 | T16: -104900 | V16: =SUM(K16:N16) -> -417635 | W16: =SUM(L16:O16) -> -427212 | X16: =SUM(M16:P16) -> -449731 | Y16: =SUM(N16:Q16) -> -451008 | Z16: =SUM(O16:R16) -> -452235 | AA16: =SUM(P16:S16) -> -437628 | AB16: =SUM(Q16:T16) -> -412484 | AD16: =SUM(AB16/X16)-1 -> -0.082820619
B17: Depreciation and amortization | C17: -225264 | D17: -278588 | E17: -297211 | F17: -313090 | G17: -320872 | H17: -325273 | J17: -77991 | K17: -80542 | L17: -82802 | M17: =SUM(G17-SUM(J17:L17)) -> -79537 | N17: -81346 | O17: -84486 | P17: -84028 | Q17: =SUM(H17-SUM(N17:P17)) -> -75413 | R17: =-11597-54853 -> -66450 | S17: -62886 | T17: -58032 | V17: =SUM(K17:N17) -> -324227 | W17: =SUM(L17:O17) -> -328171 | X17: =SUM(M17:P17) -> -329397 | Y17: =SUM(N17:Q17) -> -325273 | Z17: =SUM(O17:R17) -> -310377 | AA17: =SUM(P17:S17) -> -288777 | AB17: =SUM(Q17:T17) -> -262781 | AD17: =SUM(AB17/X17)-1 -> -0.20223621
B18: Maintenance, materials and repairs | C18: -143575 | D18: -111227 | E18: -159502 | F18: -187820 | G18: -223339 | H18: -217738 | J18: -54414 | K18: -56825 | L18: -56465 | M18: =SUM(G18-SUM(J18:L18)) -> -55635 | N18: -54915 | O18: -52453 | P18: -57368 | Q18: =SUM(H18-SUM(N18:P18)) -> -53002 | R18: =-11209-47498 -> -58707 | S18: -48747 | T18: -54849 | V18: =SUM(K18:N18) -> -223840 | W18: =SUM(L18:O18) -> -219468 | X18: =SUM(M18:P18) -> -220371 | Y18: =SUM(N18:Q18) -> -217738 | Z18: =SUM(O18:R18) -> -221530 | AA18: =SUM(P18:S18) -> -217824 | AB18: =SUM(Q18:T18) -> -215305 | AD18: =SUM(AB18/X18)-1 -> -0.022988506
B19: Distribution | C19: -153770 | D19: -85059 | E19: -132499 | F19: -177557 | G19: -190891 | H19: -197197 | J19: -48017 | K19: -50701 | L19: -46323 | M19: =SUM(G19-SUM(J19:L19)) -> -45850 | N19: -45176 | O19: -45923 | P19: -55687 | Q19: =SUM(H19-SUM(N19:P19)) -> -50411 | R19: =-10432-39461 -> -49893 | S19: -47139 | T19: -45833 | V19: =SUM(K19:N19) -> -188050 | W19: =SUM(L19:O19) -> -183272 | X19: =SUM(M19:P19) -> -192636 | Y19: =SUM(N19:Q19) -> -197197 | Z19: =SUM(O19:R19) -> -201914 | AA19: =SUM(P19:S19) -> -203130 | AB19: =SUM(Q19:T19) -> -193276 | AD19: =SUM(AB19/X19)-1 -> 0.0033223281
B20: Special Credits (Charges) | C20: -717 | D20: 302761 | E20: 377715 | F20: -420172 | G20: -69537 | H20: -36029 | J20: -13983 | K20: -19972 | L20: -12378 | M20: =SUM(G20-SUM(J20:L20)) -> -23204 | N20: -36258 | O20: 381 | P20: -151 | Q20: =SUM(H20-SUM(N20:P20)) -> -1 | R20: 4 | S20: 0 | T20: 0 | V20: =SUM(K20:N20) -> -91812 | W20: =SUM(L20:O20) -> -71459 | X20: =SUM(M20:P20) -> -59232 | Y20: =SUM(N20:Q20) -> -36029 | Z20: =SUM(O20:R20) -> 233 | AA20: =SUM(P20:S20) -> -148 | AB20: =SUM(Q20:T20) -> 3 | AD20: =SUM(AB20/X20)-1 -> -1.0000506
B21: Gains (Losses) on disposal of assets | C21: -17350 | D21: -2264 | E21: -3320 | F21: -46624 | G21: -33966 | H21: -273871 | J21: -7100 | K21: -802 | L21: 2250 | M21: =SUM(G21-SUM(J21:L21)) -> -28314 | N21: 3029 | O21: 14047 | P21: -3191 | Q21: =SUM(H21-SUM(N21:P21)) -> -287756 | R21: =-11655+19 -> -11636 | S21: 309 | T21: 113713 | V21: =SUM(K21:N21) -> -23837 | W21: =SUM(L21:O21) -> -8988 | X21: =SUM(M21:P21) -> -14429 | Y21: =SUM(N21:Q21) -> -273871 | Z21: =SUM(O21:R21) -> -288536 | AA21: =SUM(P21:S21) -> -302274 | AB21: =SUM(Q21:T21) -> -185370 | AD21: =SUM(AB21/X21)-1 -> 11.847044
B22: Other Operating Expenses | C22: -491432 | D22: -355186 | E22: -530826 | F22: -711211 | G22: -792232 | H22: -807488 | J22: -201156 | K22: -206094 | L22: -187249 | M22: =SUM(G22-SUM(J22:L22)) -> -197733 | N22: -198450 | O22: -197890 | P22: -214039 | Q22: =SUM(H22-SUM(N22:P22)) -> -197109 | R22: =-153395-36950 -> -190345 | S22: -175496 | T22: -168810 | V22: =SUM(K22:N22) -> -789526 | W22: =SUM(L22:O22) -> -781322 | X22: =SUM(M22:P22) -> -808112 | Y22: =SUM(N22:Q22) -> -807488 | Z22: =SUM(O22:R22) -> -799383 | AA22: =SUM(P22:S22) -> -776989 | AB22: =SUM(Q22:T22) -> -731760 | AD22: =SUM(AB22/X22)-1 -> -0.094481953
B23: Operating Profit | C23: =SUM(C11+SUM(C13:C22)) -> 501047 | D23: =SUM(D11+SUM(D13:D22)) -> -507762 | E23: =SUM(E11+SUM(E13:E22)) -> -56874 | F23: =SUM(F11+SUM(F13:F22)) -> -598917 | G23: =SUM(G11+SUM(G13:G22)) -> -495757 | H23: =SUM(H11+SUM(H13:H22)) -> -1105378 | J23: =SUM(J11+SUM(J13:J22)) -> -112395 | K23: =SUM(K11+SUM(K13:K22)) -> 20211 | L23: =SUM(L11+SUM(L13:L22)) -> -188760 | M23: =SUM(M11+SUM(M13:M22)) -> -214813 | N23: =SUM(N11+SUM(N13:N22)) -> -207337 | O23: =SUM(O11+SUM(O13:O22)) -> -152512 | P23: =SUM(P11+SUM(P13:P22)) -> -296439 | Q23: =SUM(Q11+SUM(Q13:Q22)) -> -449090 | ... T23: =SUM(T11+SUM(T13:T22)) -> -134915 | V23: {=SUM(V11+V14:V22)} -> 43294898 | W23: {=SUM(W11+W14:W22)} -> 41920184 | X23: =SUM(X11+SUM(X13:X22)) -> -871101 | Y23: =SUM(Y11+SUM(Y13:Y22)) -> -1105378 | Z23: =SUM(Z11+SUM(Z13:Z22)) -> -1187197 | AA23: =SUM(AA11+SUM(AA13:AA22)) -> -1218808 | AB23: =SUM(AB11+SUM(AB13:AB22)) -> -1057284 | AD23: =SUM(AB23/X23)-1 -> 0.21373297
B24: Operating Margin (%) | C24: =C23/C11 -> 0.13080337 | D24: =D23/D11 -> -0.28052808 | E24: =E23/E11 -> -0.017603826 | F24: =F23/F11 -> -0.11816578 | G24: =G23/G11 -> -0.092448013 | H24: =H23/H11 -> -0.22497116 | J24: =J23/J11 -> -0.083269495 | K24: =K23/K11 -> 0.014109176 | L24: =L23/L11 -> -0.14998296 | M24: =M23/M11 -> -0.16252043 | N24: =N23/N11 -> -0.16383322 | O24: =O23/O11 -> -0.1190673 | P24: =P23/P11 -> -0.24763011 | Q24: =Q23/Q11 -> -0.38387337 | ... T24: =T23/T11 -> -0.14075287 | V24: =V23/V11 -> 8.2024136 | W24: =W23/W11 -> 8.1767895 | X24: =X23/X11 -> -0.17197456 | Y24: =Y23/Y11 -> -0.22497116 | Z24: =Z23/Z11 -> -0.25474783 | AA24: =AA23/AA11 -> -0.27705049 | AB24: =AB23/AB11 -> -0.25411529 | AD24: =SUM(AB24-X24)*1000 -> -82.140729
B26: Interest Expense | C26: -101350 | D26: -134520 | E26: -155611 | F26: -139905 | G26: -169191 | H26: -219094 | J26: -51793 | K26: -28880 | L26: -41260 | M26: =SUM(G26-SUM(J26:L26)) -> -47258 | N26: -54809 | O26: -54307 | P26: -54135 | Q26: =SUM(H26-SUM(N26:P26)) -> -55843 | R26: =-47682-9777 -> -57459 | S26: -62103 | T26: -46261 | V26: =SUM(K26:N26) -> -172207 | W26: =SUM(L26:O26) -> -197634 | X26: =SUM(M26:P26) -> -210509 | Y26: =SUM(N26:Q26) -> -219094 | Z26: =SUM(O26:R26) -> -221744 | AA26: =SUM(P26:S26) -> -229540 | AB26: =SUM(Q26:T26) -> -221666 | AD26: =SUM(AB26/X26)-1 -> 0.053000109
B27: Interest Income | C27: 25133 | D27: 6314 | E27: 5374 | F27: 20083 | G27: 61647 | H27: 48324 | J27: 15434 | K27: 15962 | L27: 18442 | M27: =SUM(G27-SUM(J27:L27)) -> 11809 | N27: 13590 | O27: 12169 | P27: 11341 | Q27: =SUM(H27-SUM(N27:P27)) -> 11224 | R27: =8873+2003 -> 10876 | S27: 7142 | T27: 7001 | V27: =SUM(K27:N27) -> 59803 | W27: =SUM(L27:O27) -> 56010 | X27: =SUM(M27:P27) -> 48909 | Y27: =SUM(N27:Q27) -> 48324 | Z27: =SUM(O27:R27) -> 45610 | AA27: =SUM(P27:S27) -> 40583 | AB27: =SUM(Q27:T27) -> 36243 | AD27: =SUM(AB27/X27)-1 -> -0.25897074
B28: Capitalized Interest | C28: 12471 | D28: 15995 | E28: 18998 | F28: 22818 | G28: 33360 | H28: 18087 | J28: 7648 | K28: 8445 | L28: 8582 | M28: =SUM(G28-SUM(J28:L28)) -> 8685 | N28: 10003 | O28: 5689 | P28: 1173 | Q28: =SUM(H28-SUM(N28:P28)) -> 1222 | R28: =956+118 -> 1074 | S28: 557 | T28: 393 | V28: =SUM(K28:N28) -> 35715 | W28: =SUM(L28:O28) -> 32959 | X28: =SUM(M28:P28) -> 25550 | Y28: =SUM(N28:Q28) -> 18087 | Z28: =SUM(O28:R28) -> 9158 | AA28: =SUM(P28:S28) -> 4026 | AB28: =SUM(Q28:T28) -> 3246 | AD28: =SUM(AB28/X28)-1 -> -0.87295499
B29: Other Income / (Expenses) | C29: -875 | D29: -211 | E29: =-577-331630 -> -332207 | F29: -4818 | G29: =-4065+15411 -> 11346 | H29: =65694+14937 -> 80631 | J29: -542 | K29: -766 | L29: -649 | M29: =SUM(G29-SUM(J29:L29)) -> 13303 | N29: =14996+66490 -> 81486 | O29: -665 | P29: 23 | Q29: =SUM(H29-SUM(N29:P29)) -> -213 | R29: =87-902-50 -> -865 | S29: -262 | T29: =-2728-337 -> -3065 | V29: =SUM(K29:N29) -> 93374 | W29: =SUM(L29:O29) -> 93475 | X29: =SUM(M29:P29) -> 94147 | Y29: =SUM(N29:Q29) -> 80631 | Z29: =SUM(O29:R29) -> -1720 | AA29: =SUM(P29:S29) -> -1317 | AB29: =SUM(Q29:T29) -> -4405 | AD29: =SUM(AB29/X29)-1 -> -1.0467885
B30: Restructuring & Other Special Charges | C30: 0 | D30: 0 | E30: 0 | F30: 0 | G30: 0 | H30: =-15493-96780 -> -112273 | J30: 0 | K30: 0 | L30: 0 | M30: =SUM(G30-SUM(J30:L30)) -> 0 | N30: 0 | O30: 0 | P30: 0 | Q30: =SUM(H30-SUM(N30:P30)) -> -112273 | R30: =-5511-1376+421464 -> 414577 | S30: -11039 | T30: =-13026-125983 -> -139009 | V30: =SUM(K30:N30) -> 0 | W30: =SUM(L30:O30) -> 0 | X30: =SUM(M30:P30) -> 0 | Y30: =SUM(N30:Q30) -> -112273 | Z30: =SUM(O30:R30) -> 302304 | AA30: =SUM(P30:S30) -> 291265 | AB30: =SUM(Q30:T30) -> 152256 | AD30: =SUM(AB30/X30)-1 -> #DIV/0!
B31: Earning Before Taxes | C31: =SUM(C23+SUM(C26:C30)) -> 436426 | D31: =SUM(D23+SUM(D26:D30)) -> -620184 | E31: =SUM(E23+SUM(E26:E30)) -> -520320 | F31: =SUM(F23+SUM(F26:F30)) -> -700739 | G31: =SUM(G23+SUM(G26:G30)) -> -558595 | H31: =SUM(H23+SUM(H26:H30)) -> -1289703 | J31: =SUM(J23+SUM(J26:J30)) -> -141648 | K31: =SUM(K23+SUM(K26:K30)) -> 14972 | L31: =SUM(L23+SUM(L26:L30)) -> -203645 | M31: =SUM(M23+SUM(M26:M30)) -> -228274 | N31: =SUM(N23+SUM(N26:N30)) -> -157067 | O31: =SUM(O23+SUM(O26:O30)) -> -189626 | P31: =SUM(P23+SUM(P26:P30)) -> -338037 | Q31: =SUM(Q23+SUM(Q26:Q30)) -> -604973 | ... T31: =SUM(T23+SUM(T26:T30)) -> -315856 | V31: =SUM(V23+SUM(V26:V30)) -> 43311583 | W31: =SUM(W23+SUM(W26:W30)) -> 41904994 | X31: =SUM(X23+SUM(X26:X30)) -> -913004 | Y31: =SUM(Y23+SUM(Y26:Y30)) -> -1289703 | Z31: =SUM(Z23+SUM(Z26:Z30)) -> -1053589 | AA31: =SUM(AA23+SUM(AA26:AA30)) -> -1113791 | AB31: =SUM(AB23+SUM(AB26:AB30)) -> -1091610 | AD31: =SUM(AB31/X31)-1 -> 0.19562455
B32: EBT Margin (%) | C32: =C31/C11 -> 0.1139334 | D32: =D31/D11 -> -0.34263893 | E32: =E31/E11 -> -0.16105114 | F32: =F31/F11 -> -0.13825517 | G32: =G31/G11 -> -0.10416595 | H32: =H31/H11 -> -0.26248575 | J32: =J31/J11 -> -0.10494201 | K32: =K31/K11 -> 0.010451862 | L32: =L31/L11 -> -0.16181012 | M32: =M31/M11 -> -0.17270458 | N32: =N31/N11 -> -0.12411095 | O32: =O31/O11 -> -0.14804249 | P32: =P31/P11 -> -0.28237897 | Q32: =Q31/Q11 -> -0.51711912 | ... T32: =T31/T11 -> -0.32952331 | V32: =V31/V11 -> 8.2055746 | W32: =W31/W11 -> 8.1738266 | X32: =X31/X11 -> -0.18024713 | Y32: =Y31/Y11 -> -0.26248575 | Z32: =Z31/Z11 -> -0.22607833 | AA32: =AA31/AA11 -> -0.2531788 | AB32: =AB31/AB11 -> -0.26236544 | AD32: =SUM(AB32-X32)*1000 -> -82.118312
B34: Benefit (Provision) for Income Taxes | C34: -101171 | D34: 191484 | E34: 47751 | F34: 146589 | G34: 111131 | H34: 60208 | J34: 37737 | K34: -17321 | L34: 46093 | M34: =SUM(G34-SUM(J34:L34)) -> 44622 | N34: 14432 | O34: -3301 | P34: 29794 | Q34: =SUM(H34-SUM(N34:P34)) -> 19283 | R34: =-17870+103 -> -17767 | S34: 3997 | T34: -1620 | V34: =SUM(K34:N34) -> 87826 | W34: =SUM(L34:O34) -> 101846 | X34: =SUM(M34:P34) -> 85547 | Y34: =SUM(N34:Q34) -> 60208 | Z34: =SUM(O34:R34) -> 28009 | AA34: =SUM(P34:S34) -> 35307 | AB34: =SUM(Q34:T34) -> 3893 | AD34: =SUM(AB34/X34)-1 -> -0.95449285
B35: Net loss | C35: =SUM(C31+SUM(C34:C34)) -> 335255 | D35: =SUM(D31+SUM(D34:D34)) -> -428700 | E35: =SUM(E31+SUM(E34:E34)) -> -472569 | F35: =SUM(F31+SUM(F34:F34)) -> -554150 | G35: =SUM(G31+SUM(G34:G34)) -> -447464 | H35: =SUM(H31+SUM(H34:H34)) -> -1229495 | J35: =SUM(J31+SUM(J34:J34)) -> -103911 | K35: =SUM(K31+SUM(K34:K34)) -> -2349 | L35: =SUM(L31+SUM(L34:L34)) -> -157552 | M35: =SUM(M31+SUM(M34:M34)) -> -183652 | N35: =SUM(N31+SUM(N34:N34)) -> -142635 | O35: =SUM(O31+SUM(O34:O34)) -> -192927 | P35: =SUM(P31+SUM(P34:P34)) -> -308243 | Q35: =SUM(Q31+SUM(Q34:Q34)) -> -585690 | ... T35: =SUM(T31+SUM(T34:T34)) -> -317476 | V35: =SUM(V31+SUM(V34:V34)) -> 43399409 | W35: =SUM(W31+SUM(W34:W34)) -> 42006840 | X35: =SUM(X31+SUM(X34:X34)) -> -827457 | Y35: =SUM(Y31+SUM(Y34:Y34)) -> -1229495 | Z35: =SUM(Z31+SUM(Z34:Z34)) -> -1025580 | AA35: =SUM(AA31+SUM(AA34:AA34)) -> -1078484 | AB35: =SUM(AB31+SUM(AB34:AB34)) -> -1087717 | AD35: =SUM(AB35/X35)-1 -> 0.31452994
B36: Net Margin (%) | C36: =C35/C11 -> 0.087521694 | D36: =D35/D11 -> -0.23684795 | E36: =E35/E11 -> -0.1462711 | F36: =F35/F11 -> -0.10933329 | G36: =G35/G11 -> -0.083442408 | H36: =H35/H11 -> -0.25023197 | J36: =J35/J11 -> -0.076983999 | K36: =K35/K11 -> -0.0016398226 | L36: =L35/L11 -> -0.12518603 | M36: =M35/M11 -> -0.13894504 | N36: =N35/N11 -> -0.1127071 | O36: =O35/O11 -> -0.15061961 | P36: =P35/P11 -> -0.25749058 | Q36: =Q35/Q11 -> -0.50063638 | ... T36: =T35/T11 -> -0.33121341 | V36: =V35/V11 -> 8.2222137 | W36: =W35/W11 -> 8.1936923 | X36: =X35/X11 -> -0.16335827 | Y36: =Y35/Y11 -> -0.25023197 | Z36: =Z35/Z11 -> -0.22006818 | AA36: =AA35/AA11 -> -0.24515307 | AB36: =AB35/AB11 -> -0.26142977 | AD36: =SUM(AB36-X36)*1000 -> -98.071505
B38: Basic Shares | C38: 84692 | D38: 84692 | E38: 105000 | F38: 108751 | G38: 109152 | H38: 109495 | J38: 109110 | K38: 109161 | L38: 109164 | M38: =G38 -> 109152 | N38: 109430 | O38: 109506 | P38: 109521 | Q38: =H38 -> 109495 | R38: =19685+109525 -> 129210 | S38: 33972 | T38: 40322 | V38: =N38 -> 109430 | W38: =O38 -> 109506 | X38: =P38 -> 109521 | Y38: =Q38 -> 109495 | Z38: =R38 -> 129210 | AA38: =S38 -> 33972 | AB38: =T38 -> 40322 | AD38: =SUM(AB38/X38)-1 -> -0.63183316
B39: Basic EPS | C39: =C35/C38 -> 3.9585203 | D39: =D35/D38 -> -5.0618713 | E39: =E35/E38 -> -4.5006571 | F39: =F35/F38 -> -5.0955853 | G39: =G35/G38 -> -4.0994576 | H39: =H35/H38 -> -11.228778 | J39: =J35/J38 -> -0.95235084 | K39: =K35/K38 -> -0.021518674 | L39: =L35/L38 -> -1.4432597 | M39: =M35/M38 -> -1.6825344 | N39: =N35/N38 -> -1.303436 | O39: =O35/O38 -> -1.7617939 | P39: =P35/P38 -> -2.8144648 | Q39: =Q35/Q38 -> -5.3490114 | ... T39: =T35/T38 -> -7.8735182 | V39: =V35/V38 -> 396.59517 | W39: =W35/W38 -> 383.60309 | X39: =X35/X38 -> -7.555236 | Y39: =Y35/Y38 -> -11.228778 | Z39: =Z35/Z38 -> -7.9373114 | AA39: =AA35/AA38 -> -31.746262 | AB39: =AB35/AB38 -> -26.97577 | AD39: =SUM(AB39/X39)-1 -> 2.5704735
B41: Fully Diluted Shares | C41: 68559 | D41: 84692 | E41: 105000 | F41: 108751 | G41: 109152 | H41: 109495 | J41: 109110 | K41: 109161 | L41: 109164 | M41: =G41 -> 109152 | N41: 109430 | O41: 109506 | P41: 109521 | Q41: =H41 -> 109495 | R41: =19685+109525 -> 129210 | S41: 33972 | T41: 40322 | V41: =N41 -> 109430 | W41: =O41 -> 109506 | X41: =P41 -> 109521 | Y41: =Q41 -> 109495 | Z41: =R41 -> 129210 | AA41: =S41 -> 33972 | AB41: =T41 -> 40322 | AD41: =SUM(AB41/X41)-1 -> -0.63183316
B42: Fully Diluted EPS | C42: =C35/C41 -> 4.8900217 | D42: =D35/D41 -> -5.0618713 | E42: =E35/E41 -> -4.5006571 | F42: =F35/F41 -> -5.0955853 | G42: =G35/G41 -> -4.0994576 | H42: =H35/H41 -> -11.228778 | J42: =J35/J41 -> -0.95235084 | K42: =K35/K41 -> -0.021518674 | L42: =L35/L41 -> -1.4432597 | M42: =M35/M41 -> -1.6825344 | N42: =N35/N41 -> -1.303436 | O42: =O35/O41 -> -1.7617939 | P42: =P35/P41 -> -2.8144648 | Q42: =Q35/Q41 -> -5.3490114 | ... T42: =T35/T41 -> -7.8735182 | V42: =V35/V41 -> 396.59517 | W42: =W35/W41 -> 383.60309 | X42: =X35/X41 -> -7.555236 | Y42: =Y35/Y41 -> -11.228778 | Z42: =Z35/Z41 -> -7.9373114 | AA42: =AA35/AA41 -> -31.746262 | AB42: =AB35/AB41 -> -26.97577 | AD42: =SUM(AB42/X42)-1 -> 2.5704735
A44: X | B44: Balance Sheet | W44: LTM | AD44: Variance
B45: =B7 -> Fiscal Period | C45: =C7 -> 2019 | D45: =D7 -> 2020 | E45: =E7 -> 2021 | F45: =F7 -> 2022 | G45: =G7 -> 2023 | H45: =H7 -> 2024 | J45: =J7 -> 1Q23 | K45: =K7 -> 2Q23 | L45: =L7 -> 3Q23 | M45: =M7 -> 4Q23 | N45: =N7 -> 1Q24 | O45: =O7 -> 2Q24 | P45: =P7 -> 3Q24 | Q45: =Q7 -> 4Q24 | ... T45: =T7 -> 3Q25 | V45: =V7 -> 1Q24 | W45: =W7 -> 2Q24 | X45: =X7 -> 3Q24 | Y45: =Y7 -> 4Q24 | Z45: =Z7 -> 1Q25 | AA45: =AA7 -> 2Q25 | AB45: =AB7 -> 3Q25
B46: =B8 -> Fiscal Period End Date | C46: =C8 -> 43830 | D46: =D8 -> 44196 | E46: =E8 -> 44561 | F46: =F8 -> 44926 | G46: =G8 -> 45291 | H46: =H8 -> 45657 | J46: =J8 -> 45016 | K46: =K8 -> 45107 | L46: =L8 -> 45199 | M46: =M8 -> 45291 | N46: =N8 -> 45382 | O46: =O8 -> 45473 | P46: =P8 -> 45565 | Q46: =Q8 -> 45657 | ... T46: =T8 -> 45930 | V46: =V8 -> 45382 | W46: =W8 -> 45473 | X46: =X8 -> 45565 | Y46: =Y8 -> 45657 | Z46: =Z8 -> 45747 | AA46: =AA8 -> 45838 | AB46: =AB8 -> 45930
B48: Current Assets
B49: Cash and cash equivalents | C49: 978957 | D49: 1789723 | E49: 1333507 | F49: 1346350 | G49: 865211 | H49: 902057 | J49: 1287711 | K49: 1110688 | L49: 818323 | M49: =G49 -> 865211 | N49: 764788 | O49: 724794 | P49: 423547 | Q49: =H49 -> 902057 | R49: 487535 | S49: 407511 | T49: 250494 | V49: =N49 -> 764788 | W49: =O49 -> 724794 | X49: =P49 -> 423547 | Y49: =Q49 -> 902057 | Z49: =R49 -> 487535 | AA49: =S49 -> 407511 | AB49: =T49 -> 250494 | AD49: =SUM(AB49/X49)-1 -> -0.40858039
B50: Restricted cash | C50: 0 | D50: 71401 | E50: 95400 | F50: 119392 | G50: 119400 | H50: 168390 | J50: 119400 | K50: 119400 | L50: 119400 | M50: =G50 -> 119400 | N50: 133585 | O50: 120579 | P50: 170086 | Q50: =H50 -> 168390 | R50: 270522 | S50: 152088 | T50: 396103 | V50: =N50 -> 133585 | W50: =O50 -> 120579 | X50: =P50 -> 170086 | Y50: =Q50 -> 168390 | Z50: =R50 -> 270522 | AA50: =S50 -> 152088 | AB50: =T50 -> 396103 | AD50: =SUM(AB50/X50)-1 -> 1.3288395
...

Sheet Revenue Drivers
B2: Netflix, Inc. (NASDAQ: NFLX) | F2: FYE | N2: Quarterly | O2: Quarterly | V2: LTM | Z2: LTM | AB2: LTM | AH2: Variance
B3: Segment Anaysis | C3: ='Historical Financials'!C7 -> 2019 | D3: ='Historical Financials'!D7 -> 2020 | E3: ='Historical Financials'!E7 -> 2021 | F3: ='Historical Financials'!F7 -> 2022 | G3: ='Historical Financials'!G7 -> 2023 | H3: ='Historical Financials'!H7 -> 2024 | J3: ='Historical Financials'!J7 -> 1Q23 | K3: ='Historical Financials'!K7 -> 2Q23 | L3: ='Historical Financials'!L7 -> 3Q23 | M3: ='Historical Financials'!M7 -> 4Q23 | N3: ='Historical Financials'!N7 -> 1Q24 | O3: ='Historical Financials'!O7 -> 2Q24 | P3: ='Historical Financials'!P7 -> 3Q24 | Q3: ='Historical Financials'!Q7 -> 4Q24 | ... T3: ='Historical Financials'!T7 -> 3Q25 | V3: =J3 -> 1Q23 | W3: =K3 -> 2Q23 | X3: =L3 -> 3Q23 | Y3: =M3 -> 4Q23 | Z3: =N3 -> 1Q24 | AA3: =O3 -> 2Q24 | AB3: =P3 -> 3Q24 | AC3: =Q3 -> 4Q24 | ... AF3: =T3 -> 3Q25
B4: $ in thousands except per share | C4: ='Historical Financials'!C8 -> 43830 | D4: ='Historical Financials'!D8 -> 44196 | E4: ='Historical Financials'!E8 -> 44561 | F4: ='Historical Financials'!F8 -> 44926 | G4: ='Historical Financials'!G8 -> 45291 | H4: ='Historical Financials'!H8 -> 45657 | J4: ='Historical Financials'!J8 -> 45016 | K4: ='Historical Financials'!K8 -> 45107 | L4: ='Historical Financials'!L8 -> 45199 | M4: ='Historical Financials'!M8 -> 45291 | N4: ='Historical Financials'!N8 -> 45382 | O4: ='Historical Financials'!O8 -> 45473 | P4: ='Historical Financials'!P8 -> 45565 | Q4: ='Historical Financials'!Q8 -> 45657 | ... T4: ='Historical Financials'!T8 -> 45930 | V4: =J4 -> 45016 | W4: =K4 -> 45107 | X4: =L4 -> 45199 | Y4: =M4 -> 45291 | Z4: =N4 -> 45382 | AA4: =O4 -> 45473 | AB4: =P4 -> 45565 | AC4: =Q4 -> 45657 | ... AF4: =T4 -> 45930
A6: X | B6: Offerings Drivers
B8: Disaggregated Revenues
B9: Passenger | C9: 3757605 | D9: 1765533 | E9: 3175802 | F9: 4989365 | G9: 5268161 | H9: 4811752 | J9: 1327473 | K9: 1410061 | L9: 1233912 | M9: =SUM(G9-SUM(J9:L9)) -> 1296715 | N9: 1239310 | O9: 1253803 | P9: 1171405 | Q9: =SUM(H9-SUM(N9:P9)) -> 1147234 | R9: =740610+252959 -> 993569 | S9: 1000806 | T9: =937126 -> 937126 | V9: =SUM(J9:J9) -> 1327473 | W9: =SUM(J9:K9) -> 2737534 | X9: =SUM(J9:L9) -> 3971446 | Y9: =SUM(J9:M9) -> 5268161 | Z9: =SUM(K9:N9) -> 5179998 | AA9: =SUM(L9:O9) -> 5023740 | AB9: =SUM(M9:P9) -> 4961233 | AC9: =SUM(N9:Q9) -> 4811752 | AD9: =SUM(O9:R9) -> 4566011 | AE9: =SUM(P9:S9) -> 4313014 | AF9: =SUM(Q9:T9) -> 4078735 | AH9: =SUM(AF9/AB9)-1 -> -0.17787877
B10: Other | C10: 72931 | D10: 44489 | E10: 54973 | F10: 79082 | G10: 94388 | H10: 101669 | J10: 22301 | K10: 22411 | L10: 24631 | M10: =SUM(G10-SUM(J10:L10)) -> 25045 | N10: 26227 | O10: 27086 | P10: 25699 | Q10: =SUM(H10-SUM(N10:P10)) -> 22657 | R10: =14744+4086 -> 18830 | S10: 19027 | T10: 21398 | AB10: =SUM(M10:P10) -> 104057 | AC10: =SUM(N10:Q10) -> 101669 | AD10: =SUM(O10:R10) -> 94272 | AE10: =SUM(P10:S10) -> 86213 | AF10: =SUM(Q10:T10) -> 81912 | AH10: =SUM(AF10/AB10)-1 -> -0.21281605
B11: Total Net Revenue | C11: =SUM(C9:C10) -> 3830536 | D11: =SUM(D9:D10) -> 1810022 | E11: =SUM(E9:E10) -> 3230775 | F11: =SUM(F9:F10) -> 5068447 | G11: =SUM(G9:G10) -> 5362549 | H11: =SUM(H9:H10) -> 4913421 | J11: =SUM(J9:J10) -> 1349774 | K11: =SUM(K9:K10) -> 1432472 | L11: =SUM(L9:L10) -> 1258543 | M11: =SUM(M9:M10) -> 1321760 | N11: =SUM(N9:N10) -> 1265537 | O11: =SUM(O9:O10) -> 1280889 | P11: =SUM(P9:P10) -> 1197104 | Q11: =SUM(Q9:Q10) -> 1169891 | ... T11: =SUM(T9:T10) -> 958524 | V11: =SUM(V9:V10) -> 1327473 | W11: =SUM(W9:W10) -> 2737534 | X11: =SUM(X9:X10) -> 3971446 | Y11: =SUM(Y9:Y10) -> 5268161 | Z11: =SUM(Z9:Z10) -> 5179998 | AA11: =SUM(AA9:AA10) -> 5023740 | AB11: =SUM(AB9:AB10) -> 5065290 | AC11: =SUM(AC9:AC10) -> 4913421 | ... AF11: =SUM(AF9:AF10) -> 4160647 | AH11: =SUM(AF11/AB11)-1 -> -0.17859649
B12: Variance Check | C12: =+C11-'Historical Financials'!C11 -> 0 | D12: =+D11-'Historical Financials'!D11 -> 0 | E12: =+E11-'Historical Financials'!E11 -> 0 | F12: =+F11-'Historical Financials'!F11 -> 0 | G12: =+G11-'Historical Financials'!G11 -> 0 | H12: ='Historical Financials'!H11-'Revenue Drivers'!H11 -> 0 | J12: =J11-'Historical Financials'!J11 -> 0 | K12: =K11-'Historical Financials'!K11 -> 0 | L12: =L11-'Historical Financials'!L11 -> 0 | M12: =M11-'Historical Financials'!M11 -> 0 | N12: =N11-'Historical Financials'!N11 -> 0 | O12: =O11-'Historical Financials'!O11 -> 0 | P12: =P11-'Historical Financials'!P11 -> 0 | Q12: =Q11-'Historical Financials'!Q11 -> 0 | ... T12: =T11-'Historical Financials'!T11 -> 0 | V12: =+V11-'Historical Financials'!#REF! -> #REF! | W12: =+W11-'Historical Financials'!#REF! -> #REF! | X12: =+X11-'Historical Financials'!#REF! -> #REF! | Y12: =+Y11-'Historical Financials'!#REF! -> #REF! | Z12: =+Z11-'Historical Financials'!V11 -> -98314 | AA12: =+AA11-'Historical Financials'!W11 -> -102989 | AB12: =+AB11-'Historical Financials'!X11 -> 0 | AC12: =+AC11-'Historical Financials'!Y11 -> 0 | AD12: =+AD11-'Historical Financials'!Z11 -> 0 | AE12: =+AE11-'Historical Financials'!AA11 -> 0 | AF12: =AF11-'Historical Financials'!AB11 -> 0

Sheet FCF
B2: ='Historical Financials'!B2 -> Spirit Airlines, Inc. (NASDAQ: FLYYQ) | C2: FYE | E2: FYE | I2: Quarterly | O2: Quarterly | Z2: LTM | AA2: LTM | AG2: Variance
B3: FCF Analysis | C3: ='Historical Financials'!D7 -> 2020 | D3: ='Historical Financials'!E7 -> 2021 | E3: ='Historical Financials'!F7 -> 2022 | F3: ='Historical Financials'!G7 -> 2023 | G3: ='Historical Financials'!H7 -> 2024 | I3: ='Historical Financials'!J7 -> 1Q23 | J3: ='Historical Financials'!K7 -> 2Q23 | K3: ='Historical Financials'!L7 -> 3Q23 | L3: ='Historical Financials'!M7 -> 4Q23 | M3: ='Historical Financials'!N7 -> 1Q24 | N3: ='Historical Financials'!O7 -> 2Q24 | O3: ='Historical Financials'!P7 -> 3Q24 | P3: ='Historical Financials'!Q7 -> 4Q24 | ... S3: ='Historical Financials'!T7 -> 3Q25 | U3: =I3 -> 1Q23 | V3: =J3 -> 2Q23 | W3: =K3 -> 3Q23 | X3: =L3 -> 4Q23 | Y3: =M3 -> 1Q24 | Z3: =N3 -> 2Q24 | AA3: =O3 -> 3Q24 | AB3: =P3 -> 4Q24 | ... AE3: =S3 -> 3Q25
B4: $ mm except per share | C4: ='Historical Financials'!D8 -> 44196 | D4: ='Historical Financials'!E8 -> 44561 | E4: ='Historical Financials'!F8 -> 44926 | F4: ='Historical Financials'!G8 -> 45291 | G4: ='Historical Financials'!H8 -> 45657 | I4: ='Historical Financials'!J8 -> 45016 | J4: ='Historical Financials'!K8 -> 45107 | K4: ='Historical Financials'!L8 -> 45199 | L4: ='Historical Financials'!M8 -> 45291 | M4: ='Historical Financials'!N8 -> 45382 | N4: ='Historical Financials'!O8 -> 45473 | O4: ='Historical Financials'!P8 -> 45565 | P4: ='Historical Financials'!Q8 -> 45657 | ... S4: ='Historical Financials'!T8 -> 45930 | U4: =I4 -> 45016 | V4: =J4 -> 45107 | W4: =K4 -> 45199 | X4: =L4 -> 45291 | Y4: =M4 -> 45382 | Z4: =N4 -> 45473 | AA4: =O4 -> 45565 | AB4: =P4 -> 45657 | ... AE4: =S4 -> 45930
B6: ='Revenue Drivers'!B9 -> Passenger | C6: ='Revenue Drivers'!D9/1000 -> 1765.533 | D6: ='Revenue Drivers'!E9/1000 -> 3175.802 | E6: ='Revenue Drivers'!F9/1000 -> 4989.365 | F6: ='Revenue Drivers'!G9/1000 -> 5268.161 | G6: ='Revenue Drivers'!H9/1000 -> 4811.752 | I6: ='Revenue Drivers'!J9/1000 -> 1327.473 | J6: ='Revenue Drivers'!K9/1000 -> 1410.061 | K6: ='Revenue Drivers'!L9/1000 -> 1233.912 | L6: ='Revenue Drivers'!M9/1000 -> 1296.715 | M6: ='Revenue Drivers'!N9/1000 -> 1239.31 | N6: ='Revenue Drivers'!O9/1000 -> 1253.803 | O6: ='Revenue Drivers'!P9/1000 -> 1171.405 | P6: ='Revenue Drivers'!Q9/1000 -> 1147.234 | ... S6: ='Revenue Drivers'!T9/1000 -> 937.126 | U6: =SUM(F6:I6) -> 11407.386 | V6: =SUM(G6:J6) -> 7549.286 | W6: =SUM(H6:K6) -> 3971.446 | X6: =SUM(I6:L6) -> 5268.161 | Y6: =SUM(J6:M6) -> 5179.998 | Z6: =SUM(K6:N6) -> 5023.74 | AA6: =SUM(L6:O6) -> 4961.233 | AB6: =SUM(M6:P6) -> 4811.752 | ... AE6: =SUM(P6:S6) -> 4078.735 | AG6: =SUM(AE6/AA6)-1 -> -0.17787877
B7: ='Revenue Drivers'!B10 -> Other | C7: ='Revenue Drivers'!D10/1000 -> 44.489 | D7: ='Revenue Drivers'!E10/1000 -> 54.973 | E7: ='Revenue Drivers'!F10/1000 -> 79.082 | F7: ='Revenue Drivers'!G10/1000 -> 94.388 | G7: ='Revenue Drivers'!H10/1000 -> 101.669 | I7: ='Revenue Drivers'!J10/1000 -> 22.301 | J7: ='Revenue Drivers'!K10/1000 -> 22.411 | K7: ='Revenue Drivers'!L10/1000 -> 24.631 | L7: ='Revenue Drivers'!M10/1000 -> 25.045 | M7: ='Revenue Drivers'!N10/1000 -> 26.227 | N7: ='Revenue Drivers'!O10/1000 -> 27.086 | O7: ='Revenue Drivers'!P10/1000 -> 25.699 | P7: ='Revenue Drivers'!Q10/1000 -> 22.657 | ... S7: ='Revenue Drivers'!T10/1000 -> 21.398 | U7: =SUM(F7:I7) -> 218.358 | V7: =SUM(G7:J7) -> 146.381 | W7: =SUM(H7:K7) -> 69.343 | X7: =SUM(I7:L7) -> 94.388 | Y7: =SUM(J7:M7) -> 98.314 | Z7: =SUM(K7:N7) -> 102.989 | AA7: =SUM(L7:O7) -> 104.057 | AB7: =SUM(M7:P7) -> 101.669 | ... AE7: =SUM(P7:S7) -> 81.912 | AG7: =SUM(AE7/AA7)-1 -> -0.21281605
B8: Total Revenue | C8: =SUM(C6:C7) -> 1810.022 | D8: =SUM(D6:D7) -> 3230.775 | E8: =SUM(E6:E7) -> 5068.447 | F8: =SUM(F6:F7) -> 5362.549 | G8: =SUM(G6:G7) -> 4913.421 | I8: =SUM(I6:I7) -> 1349.774 | J8: =SUM(J6:J7) -> 1432.472 | K8: =SUM(K6:K7) -> 1258.543 | L8: =SUM(L6:L7) -> 1321.76 | M8: =SUM(M6:M7) -> 1265.537 | N8: =SUM(N6:N7) -> 1280.889 | O8: =SUM(O6:O7) -> 1197.104 | P8: =SUM(P6:P7) -> 1169.891 | ... S8: =SUM(S6:S7) -> 958.524 | U8: =SUM(U6:U7) -> 11625.744 | V8: =SUM(V6:V7) -> 7695.667 | W8: =SUM(W6:W7) -> 4040.789 | X8: =SUM(X6:X7) -> 5362.549 | Y8: =SUM(Y6:Y7) -> 5278.312 | Z8: =SUM(Z6:Z7) -> 5126.729 | AA8: =SUM(AA6:AA7) -> 5065.29 | AB8: =SUM(AB6:AB7) -> 4913.421 | ... AE8: =SUM(AE6:AE7) -> 4160.647 | AG8: =SUM(AE8/AA8)-1 -> -0.17859649
B9: Y/Y Growth (%) | D9: =SUM(D8/C8)-1 -> 0.78493687 | E9: =SUM(E8/D8)-1 -> 0.56880222 | F9: =SUM(F8/E8)-1 -> 0.058026058 | G9: =SUM(G8/F8)-1 -> -0.083752708 | M9: =SUM(M8/I8)-1 -> -0.062408225 | N9: =SUM(N8/J8)-1 -> -0.10581917 | O9: =SUM(O8/K8)-1 -> -0.048817561 | P9: =SUM(P8/L8)-1 -> -0.11489907 | Q9: =SUM(Q8/M8)-1 -> -0.20002418 | R9: =SUM(R8/N8)-1 -> -0.20380845 | S9: =SUM(S8/O8)-1 -> -0.19929764 | W9: =SUM(W8/#REF!)-1 -> #REF! | X9: =SUM(X8/#REF!)-1 -> #REF! | Y9: =SUM(Y8/U8)-1 -> -0.54598071 | Z9: =SUM(Z8/V8)-1 -> -0.33381616 | AA9: =SUM(AA8/W8)-1 -> 0.25353984 | AB9: =SUM(AB8/X8)-1 -> -0.083752708 | AC9: =SUM(AC8/Y8)-1 -> -0.11708838 | AD9: =SUM(AD8/Z8)-1 -> -0.14190374 | AE9: =SUM(AE8/AA8)-1 -> -0.17859649 | AG9: =SUM(AE9-AA9)*10000 -> -4321.3633
B10: Q/Q Growth (%) | C10: N/A | D10: N/A | E10: N/A | F10: N/A | G10: N/A | J10: =SUM(J8/I8)-1 -> 0.061268035 | K10: =SUM(K8/J8)-1 -> -0.12141878 | L10: =SUM(L8/K8)-1 -> 0.050230306 | M10: =SUM(M8/L8)-1 -> -0.042536467 | N10: =SUM(N8/M8)-1 -> 0.012130819 | O10: =SUM(O8/N8)-1 -> -0.065411601 | P10: =SUM(P8/O8)-1 -> -0.022732361 | Q10: =SUM(Q8/P8)-1 -> -0.13462109 | ... S10: =SUM(S8/R8)-1 -> -0.060116705 | U10: N/A | V10: N/A | W10: N/A | X10: N/A | Y10: N/A | Z10: N/A | AA10: N/A | AB10: N/A | AC10: N/A | AD10: N/A | AE10: N/A
B13: (-) Salaries, wages and benefits | C13: ='Historical Financials'!D13/1000 -> -909.834 | D13: ='Historical Financials'!E13/1000 -> -1065.461 | E13: ='Historical Financials'!F13/1000 -> -1251.225 | F13: ='Historical Financials'!G13/1000 -> -1616.803 | G13: ='Historical Financials'!H13/1000 -> -1689.083 | I13: ='Historical Financials'!J13/1000 -> -389.185 | J13: ='Historical Financials'!K13/1000 -> -407.705 | K13: ='Historical Financials'!L13/1000 -> -404.177 | L13: ='Historical Financials'!M13/1000 -> -415.736 | M13: ='Historical Financials'!N13/1000 -> -431.483 | N13: ='Historical Financials'!O13/1000 -> -418.378 | O13: ='Historical Financials'!P13/1000 -> -427.125 | P13: ='Historical Financials'!Q13/1000 -> -412.097 | ... S13: ='Historical Financials'!T13/1000 -> -367.356 | U13: =SUM(F13:I13) -> -3695.071 | V13: =SUM(G13:J13) -> -2485.973 | W13: =SUM(H13:K13) -> -1201.067 | X13: =SUM(I13:L13) -> -1616.803 | Y13: =SUM(J13:M13) -> -1659.101 | Z13: =SUM(K13:N13) -> -1669.774 | AA13: =SUM(L13:O13) -> -1692.722 | AB13: =SUM(M13:P13) -> -1689.083 | ... AE13: =SUM(P13:S13) -> -1531.611 | AG13: =SUM(AE13/AA13)-1 -> -0.095178653
B14: (-) Aircraft fuel | C14: ='Historical Financials'!D14/1000 -> -431 | D14: ='Historical Financials'!E14/1000 -> -913.945 | E14: ='Historical Financials'!F14/1000 -> -1929.969 | F14: ='Historical Financials'!G14/1000 -> -1821.165 | G14: ='Historical Financials'!H14/1000 -> -1479.203 | I14: ='Historical Financials'!J14/1000 -> -487.711 | J14: ='Historical Financials'!K14/1000 -> -391.032 | K14: ='Historical Financials'!L14/1000 -> -455.241 | L14: ='Historical Financials'!M14/1000 -> -487.181 | M14: ='Historical Financials'!N14/1000 -> -406.351 | N14: ='Historical Financials'!O14/1000 -> -407.296 | O14: ='Historical Financials'!P14/1000 -> -373.399 | P14: ='Historical Financials'!Q14/1000 -> -292.157 | ... S14: ='Historical Financials'!T14/1000 -> -253.308 | U14: =SUM(F14:I14) -> -3788.079 | V14: =SUM(G14:J14) -> -2357.946 | W14: =SUM(H14:K14) -> -1333.984 | X14: =SUM(I14:L14) -> -1821.165 | Y14: =SUM(J14:M14) -> -1739.805 | Z14: =SUM(K14:N14) -> -1756.069 | AA14: =SUM(L14:O14) -> -1674.227 | AB14: =SUM(M14:P14) -> -1479.203 | ... AE14: =SUM(P14:S14) -> -1086.67 | AG14: =SUM(AE14/AA14)-1 -> -0.35094226
B15: (-) Aircraft rent | C15: ='Historical Financials'!D15/1000 -> -196.359 | D15: ='Historical Financials'!E15/1000 -> -246.601 | E15: ='Historical Financials'!F15/1000 -> -282.428 | F15: ='Historical Financials'!G15/1000 -> -381.239 | G15: ='Historical Financials'!H15/1000 -> -541.909 | I15: ='Historical Financials'!J15/1000 -> -85.267 | J15: ='Historical Financials'!K15/1000 -> -92.101 | K15: ='Historical Financials'!L15/1000 -> -97.393 | L15: ='Historical Financials'!M15/1000 -> -106.478 | M15: ='Historical Financials'!N15/1000 -> -115.206 | N15: ='Historical Financials'!O15/1000 -> -125.339 | O15: ='Historical Financials'!P15/1000 -> -148.511 | P15: ='Historical Financials'!Q15/1000 -> -152.853 | ... S15: ='Historical Financials'!T15/1000 -> -154.064 | U15: =SUM(F15:I15) -> -1008.415 | V15: =SUM(G15:J15) -> -719.277 | W15: =SUM(H15:K15) -> -274.761 | X15: =SUM(I15:L15) -> -381.239 | Y15: =SUM(J15:M15) -> -411.178 | Z15: =SUM(K15:N15) -> -444.416 | AA15: =SUM(L15:O15) -> -495.534 | AB15: =SUM(M15:P15) -> -541.909 | ... AE15: =SUM(P15:S15) -> -598.677 | AG15: =SUM(AE15/AA15)-1 -> 0.20814515
B16: (-) Landing fees and other rents | C16: ='Historical Financials'!D16/1000 -> -251.028 | D16: ='Historical Financials'!E16/1000 -> -315.999 | E16: ='Historical Financials'!F16/1000 -> -347.268 | F16: ='Historical Financials'!G16/1000 -> -408.262 | G16: ='Historical Financials'!H16/1000 -> -451.008 | I16: ='Historical Financials'!J16/1000 -> -97.345 | J16: ='Historical Financials'!K16/1000 -> -106.487 | K16: ='Historical Financials'!L16/1000 -> -107.525 | L16: ='Historical Financials'!M16/1000 -> -96.905 | M16: ='Historical Financials'!N16/1000 -> -106.718 | N16: ='Historical Financials'!O16/1000 -> -116.064 | O16: ='Historical Financials'!P16/1000 -> -130.044 | P16: ='Historical Financials'!Q16/1000 -> -98.182 | ... S16: ='Historical Financials'!T16/1000 -> -104.9 | U16: =SUM(F16:I16) -> -956.615 | V16: =SUM(G16:J16) -> -654.84 | W16: =SUM(H16:K16) -> -311.357 | X16: =SUM(I16:L16) -> -408.262 | Y16: =SUM(J16:M16) -> -417.635 | Z16: =SUM(K16:N16) -> -427.212 | AA16: =SUM(L16:O16) -> -449.731 | AB16: =SUM(M16:P16) -> -451.008 | ... AE16: =SUM(P16:S16) -> -412.484 | AG16: =SUM(AE16/AA16)-1 -> -0.082820619
B17: (-) Depreciation and amortization | C17: ='Historical Financials'!D17/1000 -> -278.588 | D17: ='Historical Financials'!E17/1000 -> -297.211 | E17: ='Historical Financials'!F17/1000 -> -313.09 | F17: ='Historical Financials'!G17/1000 -> -320.872 | G17: ='Historical Financials'!H17/1000 -> -325.273 | I17: ='Historical Financials'!J17/1000 -> -77.991 | J17: ='Historical Financials'!K17/1000 -> -80.542 | K17: ='Historical Financials'!L17/1000 -> -82.802 | L17: ='Historical Financials'!M17/1000 -> -79.537 | M17: ='Historical Financials'!N17/1000 -> -81.346 | N17: ='Historical Financials'!O17/1000 -> -84.486 | O17: ='Historical Financials'!P17/1000 -> -84.028 | P17: ='Historical Financials'!Q17/1000 -> -75.413 | ... S17: ='Historical Financials'!T17/1000 -> -58.032 | U17: =SUM(F17:I17) -> -724.136 | V17: =SUM(G17:J17) -> -483.806 | W17: =SUM(H17:K17) -> -241.335 | X17: =SUM(I17:L17) -> -320.872 | Y17: =SUM(J17:M17) -> -324.227 | Z17: =SUM(K17:N17) -> -328.171 | AA17: =SUM(L17:O17) -> -329.397 | AB17: =SUM(M17:P17) -> -325.273 | ... AE17: =SUM(P17:S17) -> -262.781 | AG17: =SUM(AE17/AA17)-1 -> -0.20223621
B18: (-) Maintenance, materials and repairs | C18: ='Historical Financials'!D18/1000 -> -111.227 | D18: ='Historical Financials'!E18/1000 -> -159.502 | E18: ='Historical Financials'!F18/1000 -> -187.82 | F18: ='Historical Financials'!G18/1000 -> -223.339 | G18: ='Historical Financials'!H18/1000 -> -217.738 | I18: ='Historical Financials'!J18/1000 -> -54.414 | J18: ='Historical Financials'!K18/1000 -> -56.825 | K18: ='Historical Financials'!L18/1000 -> -56.465 | L18: ='Historical Financials'!M18/1000 -> -55.635 | M18: ='Historical Financials'!N18/1000 -> -54.915 | N18: ='Historical Financials'!O18/1000 -> -52.453 | O18: ='Historical Financials'!P18/1000 -> -57.368 | P18: ='Historical Financials'!Q18/1000 -> -53.002 | ... S18: ='Historical Financials'!T18/1000 -> -54.849 | U18: =SUM(F18:I18) -> -495.491 | V18: =SUM(G18:J18) -> -328.977 | W18: =SUM(H18:K18) -> -167.704 | X18: =SUM(I18:L18) -> -223.339 | Y18: =SUM(J18:M18) -> -223.84 | Z18: =SUM(K18:N18) -> -219.468 | AA18: =SUM(L18:O18) -> -220.371 | AB18: =SUM(M18:P18) -> -217.738 | ... AE18: =SUM(P18:S18) -> -215.305 | AG18: =SUM(AE18/AA18)-1 -> -0.022988506
B19: (-) Distribution | C19: ='Historical Financials'!D19/1000 -> -85.059 | D19: ='Historical Financials'!E19/1000 -> -132.499 | E19: ='Historical Financials'!F19/1000 -> -177.557 | F19: ='Historical Financials'!G19/1000 -> -190.891 | G19: ='Historical Financials'!H19/1000 -> -197.197 | I19: ='Historical Financials'!J19/1000 -> -48.017 | J19: ='Historical Financials'!K19/1000 -> -50.701 | K19: ='Historical Financials'!L19/1000 -> -46.323 | L19: ='Historical Financials'!M19/1000 -> -45.85 | M19: ='Historical Financials'!N19/1000 -> -45.176 | N19: ='Historical Financials'!O19/1000 -> -45.923 | O19: ='Historical Financials'!P19/1000 -> -55.687 | P19: ='Historical Financials'!Q19/1000 -> -50.411 | ... S19: ='Historical Financials'!T19/1000 -> -45.833 | U19: =SUM(F19:I19) -> -436.105 | V19: =SUM(G19:J19) -> -295.915 | W19: =SUM(H19:K19) -> -145.041 | X19: =SUM(I19:L19) -> -190.891 | Y19: =SUM(J19:M19) -> -188.05 | Z19: =SUM(K19:N19) -> -183.272 | AA19: =SUM(L19:O19) -> -192.636 | AB19: =SUM(M19:P19) -> -197.197 | ... AE19: =SUM(P19:S19) -> -193.276 | AG19: =SUM(AE19/AA19)-1 -> 0.0033223281
B20: (-) Special Credits (Charges) | C20: ='Historical Financials'!D20/1000 -> 302.761 | D20: ='Historical Financials'!E20/1000 -> 377.715 | E20: ='Historical Financials'!F20/1000 -> -420.172 | F20: ='Historical Financials'!G20/1000 -> -69.537 | G20: ='Historical Financials'!H20/1000 -> -36.029 | I20: ='Historical Financials'!J20/1000 -> -13.983 | J20: ='Historical Financials'!K20/1000 -> -19.972 | K20: ='Historical Financials'!L20/1000 -> -12.378 | L20: ='Historical Financials'!M20/1000 -> -23.204 | M20: ='Historical Financials'!N20/1000 -> -36.258 | N20: ='Historical Financials'!O20/1000 -> 0.381 | O20: ='Historical Financials'!P20/1000 -> -0.151 | P20: ='Historical Financials'!Q20/1000 -> -0.001 | ... S20: ='Historical Financials'!T20/1000 -> 0 | U20: =SUM(F20:I20) -> -119.549 | V20: =SUM(G20:J20) -> -69.984 | W20: =SUM(H20:K20) -> -46.333 | X20: =SUM(I20:L20) -> -69.537 | Y20: =SUM(J20:M20) -> -91.812 | Z20: =SUM(K20:N20) -> -71.459 | AA20: =SUM(L20:O20) -> -59.232 | AB20: =SUM(M20:P20) -> -36.029 | ... AE20: =SUM(P20:S20) -> 0.003 | AG20: =SUM(AE20/AA20)-1 -> -1.0000506
B21: (-) Gains (Losses) on disposal of assets | C21: ='Historical Financials'!D21/1000 -> -2.264 | D21: ='Historical Financials'!E21/1000 -> -3.32 | E21: ='Historical Financials'!F21/1000 -> -46.624 | F21: ='Historical Financials'!G21/1000 -> -33.966 | G21: ='Historical Financials'!H21/1000 -> -273.871 | I21: ='Historical Financials'!J21/1000 -> -7.1 | J21: ='Historical Financials'!K21/1000 -> -0.802 | K21: ='Historical Financials'!L21/1000 -> 2.25 | L21: ='Historical Financials'!M21/1000 -> -28.314 | M21: ='Historical Financials'!N21/1000 -> 3.029 | N21: ='Historical Financials'!O21/1000 -> 14.047 | O21: ='Historical Financials'!P21/1000 -> -3.191 | P21: ='Historical Financials'!Q21/1000 -> -287.756 | ... S21: ='Historical Financials'!T21/1000 -> 113.713 | U21: =SUM(F21:I21) -> -314.937 | V21: =SUM(G21:J21) -> -281.773 | W21: =SUM(H21:K21) -> -5.652 | X21: =SUM(I21:L21) -> -33.966 | Y21: =SUM(J21:M21) -> -23.837 | Z21: =SUM(K21:N21) -> -8.988 | AA21: =SUM(L21:O21) -> -14.429 | AB21: =SUM(M21:P21) -> -273.871 | ... AE21: =SUM(P21:S21) -> -185.37 | AG21: =SUM(AE21/AA21)-1 -> 11.847044
B22: (-) Other Operating Expenses | C22: ='Historical Financials'!D22/1000 -> -355.186 | D22: ='Historical Financials'!E22/1000 -> -530.826 | E22: ='Historical Financials'!F22/1000 -> -711.211 | F22: ='Historical Financials'!G22/1000 -> -792.232 | G22: ='Historical Financials'!H22/1000 -> -807.488 | I22: ='Historical Financials'!J22/1000 -> -201.156 | J22: ='Historical Financials'!K22/1000 -> -206.094 | K22: ='Historical Financials'!L22/1000 -> -187.249 | L22: ='Historical Financials'!M22/1000 -> -197.733 | M22: ='Historical Financials'!N22/1000 -> -198.45 | N22: ='Historical Financials'!O22/1000 -> -197.89 | O22: ='Historical Financials'!P22/1000 -> -214.039 | P22: ='Historical Financials'!Q22/1000 -> -197.109 | ... S22: ='Historical Financials'!T22/1000 -> -168.81 | U22: =SUM(F22:I22) -> -1800.876 | V22: =SUM(G22:J22) -> -1214.738 | W22: =SUM(H22:K22) -> -594.499 | X22: =SUM(I22:L22) -> -792.232 | Y22: =SUM(J22:M22) -> -789.526 | Z22: =SUM(K22:N22) -> -781.322 | AA22: =SUM(L22:O22) -> -808.112 | AB22: =SUM(M22:P22) -> -807.488 | ... AE22: =SUM(P22:S22) -> -731.76 | AG22: =SUM(AE22/AA22)-1 -> -0.094481953
B23: Earning before Interest & Taxes (EBIT) | C23: =SUM(C8+SUM(C13:C22)) -> -507.762 | D23: =SUM(D8+SUM(D13:D22)) -> -56.874 | E23: =SUM(E8+SUM(E13:E22)) -> -598.917 | F23: =SUM(F8+SUM(F13:F22)) -> -495.757 | G23: =SUM(G8+SUM(G13:G22)) -> -1105.378 | I23: =SUM(I8+SUM(I13:I22)) -> -112.395 | J23: =SUM(J8+SUM(J13:J22)) -> 20.211 | K23: =SUM(K8+SUM(K13:K22)) -> -188.76 | L23: =SUM(L8+SUM(L13:L22)) -> -214.813 | M23: =SUM(M8+SUM(M13:M22)) -> -207.337 | N23: =SUM(N8+SUM(N13:N22)) -> -152.512 | O23: =SUM(O8+SUM(O13:O22)) -> -296.439 | P23: =SUM(P8+SUM(P13:P22)) -> -449.09 | ... S23: =SUM(S8+SUM(S13:S22)) -> -134.915 | U23: =SUM(U8+SUM(U13:U22)) -> -1713.53 | V23: =SUM(V8+SUM(V13:V22)) -> -1197.562 | W23: =SUM(W8+SUM(W13:W22)) -> -280.944 | X23: =SUM(X8+SUM(X13:X22)) -> -495.757 | Y23: =SUM(Y8+SUM(Y13:Y22)) -> -590.699 | Z23: =SUM(Z8+SUM(Z13:Z22)) -> -763.422 | AA23: =SUM(AA8+SUM(AA13:AA22)) -> -871.101 | AB23: =SUM(AB8+SUM(AB13:AB22)) -> -1105.378 | ... AE23: =SUM(AE8+SUM(AE13:AE22)) -> -1057.284 | AG23: =SUM(AE23/AA23)-1 -> 0.21373297
B24: Operating Margin (%) | C24: =C23/C8 -> -0.28052808 | D24: =D23/D8 -> -0.017603826 | E24: =E23/E8 -> -0.11816578 | F24: =F23/F8 -> -0.092448013 | G24: =G23/G8 -> -0.22497116 | I24: =I23/I8 -> -0.083269495 | J24: =J23/J8 -> 0.014109176 | K24: =K23/K8 -> -0.14998296 | L24: =L23/L8 -> -0.16252043 | M24: =M23/M8 -> -0.16383322 | N24: =N23/N8 -> -0.1190673 | O24: =O23/O8 -> -0.24763011 | P24: =P23/P8 -> -0.38387337 | ... S24: =S23/S8 -> -0.14075287 | U24: =U23/U8 -> -0.147391 | V24: =V23/V8 -> -0.1556151 | W24: =W23/W8 -> -0.069527016 | X24: =X23/X8 -> -0.092448013 | Y24: =Y23/Y8 -> -0.11191059 | Z24: =Z23/Z8 -> -0.14891015 | AA24: =AA23/AA8 -> -0.17197456 | AB24: =AB23/AB8 -> -0.22497116 | ... AE24: =AE23/AE8 -> -0.25411529 | AG24: =SUM(AE24-AA24)*10000 -> -821.40729
B26: (+) Depreciation and Amortization (D&A) | C26: =-C17 -> 278.588 | D26: =-D17 -> 297.211 | E26: =-E17 -> 313.09 | F26: =-F17 -> 320.872 | G26: =-G17 -> 325.273 | I26: =-I17 -> 77.991 | J26: =-J17 -> 80.542 | K26: =-K17 -> 82.802 | L26: =-L17 -> 79.537 | M26: =-M17 -> 81.346 | N26: =-N17 -> 84.486 | O26: =-O17 -> 84.028 | P26: =-P17 -> 75.413 | ... S26: =-S17 -> 58.032 | U26: =SUM(I26:I26) -> 77.991 | V26: =SUM(I26:J26) -> 158.533 | W26: =SUM(I26:K26) -> 241.335 | X26: =SUM(I26:L26) -> 320.872 | Y26: =SUM(J26:M26) -> 324.227 | Z26: =SUM(K26:N26) -> 328.171 | AA26: =SUM(L26:O26) -> 329.397 | AB26: =SUM(M26:P26) -> 325.273 | AC26: =SUM(N26:Q26) -> 310.377 | AD26: =SUM(O26:R26) -> 288.777 | AE26: =SUM(P26:S26) -> 262.781 | AG26: =SUM(AE26/AA26)-1 -> -0.20223621
B27: EBITDA | C27: =SUM(C23+SUM(C26:C26)) -> -229.174 | D27: =SUM(D23+SUM(D26:D26)) -> 240.337 | E27: =SUM(E23+SUM(E26:E26)) -> -285.827 | F27: =SUM(F23+SUM(F26:F26)) -> -174.885 | G27: =SUM(G23+SUM(G26:G26)) -> -780.105 | I27: =SUM(I23+SUM(I26:I26)) -> -34.404 | J27: =SUM(J23+SUM(J26:J26)) -> 100.753 | K27: =SUM(K23+SUM(K26:K26)) -> -105.958 | L27: =SUM(L23+SUM(L26:L26)) -> -135.276 | M27: =SUM(M23+SUM(M26:M26)) -> -125.991 | N27: =SUM(N23+SUM(N26:N26)) -> -68.026 | O27: =SUM(O23+SUM(O26:O26)) -> -212.411 | P27: =SUM(P23+SUM(P26:P26)) -> -373.677 | ... S27: =SUM(S23+SUM(S26:S26)) -> -76.883 | U27: =SUM(U23+SUM(U26:U26)) -> -1635.539 | V27: =SUM(V23+SUM(V26:V26)) -> -1039.029 | W27: =SUM(W23+SUM(W26:W26)) -> -39.609 | X27: =SUM(X23+SUM(X26:X26)) -> -174.885 | Y27: =SUM(Y23+SUM(Y26:Y26)) -> -266.472 | Z27: =SUM(Z23+SUM(Z26:Z26)) -> -435.251 | AA27: =SUM(AA23+SUM(AA26:AA26)) -> -541.704 | AB27: =SUM(AB23+SUM(AB26:AB26)) -> -780.105 | ... AE27: =SUM(AE23+SUM(AE26:AE26)) -> -794.503 | AG27: =SUM(AE27/AA27)-1 -> 0.46667368
B28: EBITDA Margin (%) | C28: =C27/C8 -> -0.12661393 | D28: =D27/D8 -> 0.074389891 | E28: =E27/E8 -> -0.056393408 | F28: =F27/F8 -> -0.032612289 | G28: =G27/G8 -> -0.15877023 | I28: =I27/I8 -> -0.025488711 | J28: =J27/J8 -> 0.070335057 | K28: =K27/K8 -> -0.084191005 | L28: =L27/L8 -> -0.10234536 | M28: =M27/M8 -> -0.099555367 | N28: =N27/N8 -> -0.053108427 | O28: =O27/O8 -> -0.17743738 | P28: =P27/P8 -> -0.31941181 | ... S28: =S27/S8 -> -0.080209781 | U28: =U27/U8 -> -0.14068252 | V28: =V27/V8 -> -0.13501481 | W28: =W27/W8 -> -0.0098022936 | X28: =X27/X8 -> -0.032612289 | Y28: =Y27/Y8 -> -0.050484322 | Z28: =Z27/Z8 -> -0.084898383 | AA28: =AA27/AA8 -> -0.10694432 | AB28: =AB27/AB8 -> -0.15877023 | ... AE28: =AE27/AE8 -> -0.1909566 | AG28: =SUM(AE28-AA28)*10000 -> -840.12278
B30: (+) Share-based Compensation | C30: ='Historical Financials'!D100/1000 -> 11.575 | D30: ='Historical Financials'!E100/1000 -> 12.536 | E30: ='Historical Financials'!F100/1000 -> 11.483 | F30: ='Historical Financials'!G100/1000 -> 11.963 | G30: ='Historical Financials'!H100/1000 -> 7.21 | I30: ='Historical Financials'!J100/1000 -> 3.273 | J30: ='Historical Financials'!K100/1000 -> 3.48 | K30: ='Historical Financials'!L100/1000 -> 2.569 | L30: ='Historical Financials'!M100/1000 -> 2.641 | M30: ='Historical Financials'!N100/1000 -> 3.08 | N30: ='Historical Financials'!O100/1000 -> 0.342 | O30: ='Historical Financials'!P100/1000 -> 1.952 | P30: ='Historical Financials'!Q100/1000 -> 1.836 | ... S30: ='Historical Financials'!T100/1000 -> 2.522 | U30: =SUM(F30:I30) -> 22.446 | V30: =SUM(G30:J30) -> 13.963 | W30: =SUM(H30:K30) -> 9.322 | X30: =SUM(I30:L30) -> 11.963 | Y30: =SUM(J30:M30) -> 11.77 | Z30: =SUM(K30:N30) -> 8.632 | AA30: =SUM(L30:O30) -> 8.015 | AB30: =SUM(M30:P30) -> 7.21 | ... AE30: =SUM(P30:S30) -> 7.435 | AG30: =SUM(AE30/AA30)-1 -> -0.072364317
B31: (+) Special Charges / (Credits) | C31: =-C20 -> -302.761 | D31: =-D20 -> -377.715 | E31: =-E20 -> 420.172 | F31: =-F20 -> 69.537 | G31: =-G20 -> 36.029 | I31: =-I20 -> 13.983 | J31: =-J20 -> 19.972 | K31: =-K20 -> 12.378 | L31: =-L20 -> 23.204 | M31: =-M20 -> 36.258 | N31: =-N20 -> -0.381 | O31: =-O20 -> 0.151 | P31: =-P20 -> 0.001 | ... S31: =-S20 -> 0 | U31: =SUM(F31:I31) -> 119.549 | V31: =SUM(G31:J31) -> 69.984 | W31: =SUM(H31:K31) -> 46.333 | X31: =SUM(I31:L31) -> 69.537 | Y31: =SUM(J31:M31) -> 91.812 | Z31: =SUM(K31:N31) -> 71.459 | AA31: =SUM(L31:O31) -> 59.232 | AB31: =SUM(M31:P31) -> 36.029 | ... AE31: =SUM(P31:S31) -> -0.003 | AG31: =SUM(AE31/AA31)-1 -> -1.0000506
B32: (+) Gains (Losses) on Disposal of Assets | C32: =-C21 -> 2.264 | D32: =-D21 -> 3.32 | E32: =-E21 -> 46.624 | F32: =-F21 -> 33.966 | G32: =-G21 -> 273.871 | I32: =-I21 -> 7.1 | J32: =-J21 -> 0.802 | K32: =-K21 -> -2.25 | L32: =-L21 -> 28.314 | M32: =-M21 -> -3.029 | N32: =-N21 -> -14.047 | O32: =-O21 -> 3.191 | P32: =-P21 -> 287.756 | ... S32: =-S21 -> -113.713 | U32: =SUM(F32:I32) -> 314.937 | V32: =SUM(G32:J32) -> 281.773 | W32: =SUM(H32:K32) -> 5.652 | X32: =SUM(I32:L32) -> 33.966 | Y32: =SUM(J32:M32) -> 23.837 | Z32: =SUM(K32:N32) -> 8.988 | AA32: =SUM(L32:O32) -> 14.429 | AB32: =SUM(M32:P32) -> 273.871 | ... AE32: =SUM(P32:S32) -> 185.37 | AG32: =SUM(AE32/AA32)-1 -> 11.847044
B33: Adj. EBITDA | C33: =+SUM(C27+SUM(C30:C32)) -> -518.096 | D33: =+SUM(D27+SUM(D30:D32)) -> -121.522 | E33: =+SUM(E27+SUM(E30:E32)) -> 192.452 | F33: =+SUM(F27+SUM(F30:F32)) -> -59.419 | G33: =+SUM(G27+SUM(G30:G32)) -> -462.995 | I33: =+SUM(I27+SUM(I30:I32)) -> -10.048 | J33: =+SUM(J27+SUM(J30:J32)) -> 125.007 | K33: =+SUM(K27+SUM(K30:K32)) -> -93.261 | L33: =+SUM(L27+SUM(L30:L32)) -> -81.117 | M33: =+SUM(M27+SUM(M30:M32)) -> -89.682 | N33: =+SUM(N27+SUM(N30:N32)) -> -82.112 | O33: =+SUM(O27+SUM(O30:O32)) -> -207.117 | P33: =+SUM(P27+SUM(P30:P32)) -> -84.084 | ... S33: =+SUM(S27+SUM(S30:S32)) -> -188.074 | U33: =+SUM(U27+SUM(U30:U30)) -> -1613.093 | V33: =+SUM(V27+SUM(V30:V30)) -> -1025.066 | W33: =+SUM(W27+SUM(W30:W30)) -> -30.287 | X33: =+SUM(X27+SUM(X30:X30)) -> -162.922 | Y33: =+SUM(Y27+SUM(Y30:Y30)) -> -254.702 | Z33: =+SUM(Z27+SUM(Z30:Z30)) -> -426.619 | AA33: =+SUM(AA27+SUM(AA30:AA32)) -> -460.028 | AB33: =+SUM(AB27+SUM(AB30:AB32)) -> -462.995 | AC33: =+SUM(AC27+SUM(AC30:AC32)) -> -583.154 | AD33: =+SUM(AD27+SUM(AD30:AD32)) -> -620.744 | AE33: =+SUM(AE27+SUM(AE30:AE32)) -> -601.701 | AG33: =SUM(AE33/AA33)-1 -> 0.30796604
B34: Adj. EBITDA Margin (%) | C34: =C33/C8 -> -0.2862374 | D34: =D33/D8 -> -0.037613885 | E34: =E33/E8 -> 0.037970605 | F34: =F33/F8 -> -0.011080365 | G34: =G33/G8 -> -0.09423068 | I34: =I33/I8 -> -0.0074442092 | J34: =J33/J8 -> 0.087266627 | K34: =K33/K8 -> -0.074102355 | L34: =L33/L8 -> -0.061370445 | M34: =M33/M8 -> -0.070864779 | N34: =N33/N8 -> -0.064105477 | O34: =O33/O8 -> -0.17301504 | P34: =P33/P8 -> -0.071873363 | ... S34: =S33/S8 -> -0.19621209 | U34: =U33/U8 -> -0.13875181 | V34: =V33/V8 -> -0.13320041 | W34: =W33/W8 -> -0.0074953184 | X34: =X33/X8 -> -0.030381447 | Y34: =Y33/Y8 -> -0.048254442 | Z34: =Z33/Z8 -> -0.083214658 | AA34: =AA33/AA8 -> -0.090819677 | AB34: =AB33/AB8 -> -0.09423068 | ... AE34: =AE33/AE8 -> -0.14461717 | AG34: =SUM(AE34-AA34)*10000 -> -537.97495
B36: (-) Capital Expenditures | C36: ='Historical Financials'!D119/1000 -> -393.375 | D36: ='Historical Financials'!E119/1000 -> -213.767 | E36: ='Historical Financials'!F119/1000 -> -237.584 | F36: ='Historical Financials'!G119/1000 -> -255.563 | G36: ='Historical Financials'!H119/1000 -> -110.955 | I36: ='Historical Financials'!J119/1000 -> -60.513 | J36: ='Historical Financials'!K119/1000 -> -70.466 | K36: ='Historical Financials'!L119/1000 -> -80.104 | L36: ='Historical Financials'!M119/1000 -> -44.48 | M36: ='Historical Financials'!N119/1000 -> -64.338 | N36: ='Historical Financials'!O119/1000 -> 3.787 | O36: ='Historical Financials'!P119/1000 -> -31.203 | P36: ='Historical Financials'!Q119/1000 -> -19.201 | ... S36: ='Historical Financials'!T119/1000 -> -11.926 | U36: =SUM(I36:I36) -> -60.513 | V36: =SUM(I36:J36) -> -130.979 | W36: =SUM(I36:K36) -> -211.083 | X36: =SUM(I36:L36) -> -255.563 | Y36: =SUM(J36:M36) -> -259.388 | Z36: =SUM(K36:N36) -> -185.135 | AA36: =SUM(L36:O36) -> -136.234 | AB36: =SUM(M36:P36) -> -110.955 | AC36: =SUM(N36:Q36) -> -57.975 | AD36: =SUM(O36:R36) -> -71.689 | AE36: =SUM(P36:S36) -> -52.412 | AG36: =SUM(AE36/AA36)-1 -> -0.61527959
B37: (-) Cash Taxes | C37: =-'Historical Financials'!D149/1000 -> 17.79 | D37: =-'Historical Financials'!E149/1000 -> 112.461 | E37: =-'Historical Financials'!F149/1000 -> 0.082 | F37: =-'Historical Financials'!G149/1000 -> 32.854 | G37: =-'Historical Financials'!H149/1000 -> -3.548 | I37: =-'Historical Financials'!J149/1000 -> -0.466 | J37: =-'Historical Financials'!K149/1000 -> -0.731 | K37: =-'Historical Financials'!L149/1000 -> 33.921 | L37: =-'Historical Financials'!M149/1000 -> 0.13 | M37: =-'Historical Financials'!N149/1000 -> -0.007 | N37: =-'Historical Financials'!O149/1000 -> -7.043 | O37: =-'Historical Financials'!P149/1000 -> -0.334 | P37: =-'Historical Financials'!Q149/1000 -> 3.836 | ... S37: =-'Historical Financials'!T149/1000 -> 0.092 | U37: =SUM(I37:I37) -> -0.466 | V37: =SUM(I37:J37) -> -1.197 | W37: =SUM(I37:K37) -> 32.724 | X37: =SUM(I37:L37) -> 32.854 | Y37: =SUM(J37:M37) -> 33.313 | Z37: =SUM(K37:N37) -> 27.001 | AA37: =SUM(L37:O37) -> -7.254 | AB37: =SUM(M37:P37) -> -3.548 | AC37: =SUM(N37:Q37) -> -3.809 | AD37: =SUM(O37:R37) -> 1.938 | AE37: =SUM(P37:S37) -> 2.364 | AG37: =SUM(AE37/AA37)-1 -> -1.3258892
B38: (-) Cash Interest | C38: =-'Historical Financials'!D148/1000 -> -80.837 | D38: =-'Historical Financials'!E148/1000 -> -135.5 | E38: =-'Historical Financials'!F148/1000 -> -107.443 | F38: =-'Historical Financials'!G148/1000 -> -138.38 | G38: =-'Historical Financials'!H148/1000 -> -176.187 | I38: =-'Historical Financials'!J148/1000 -> -31.999 | J38: =-'Historical Financials'!K148/1000 -> -37.467 | K38: =-'Historical Financials'!L148/1000 -> -32.263 | L38: =-'Historical Financials'!M148/1000 -> -36.651 | M38: =-'Historical Financials'!N148/1000 -> -39.897 | N38: =-'Historical Financials'!O148/1000 -> -43.774 | O38: =-'Historical Financials'!P148/1000 -> -42.456 | P38: =-'Historical Financials'!Q148/1000 -> -50.06 | ... S38: =-'Historical Financials'!T148/1000 -> -39.059 | U38: =SUM(I38:I38) -> -31.999 | V38: =SUM(I38:J38) -> -69.466 | W38: =SUM(I38:K38) -> -101.729 | X38: =SUM(I38:L38) -> -138.38 | Y38: =SUM(J38:M38) -> -146.278 | Z38: =SUM(K38:N38) -> -152.585 | AA38: =SUM(L38:O38) -> -162.778 | AB38: =SUM(M38:P38) -> -176.187 | AC38: =SUM(N38:Q38) -> -205.934 | AD38: =SUM(O38:R38) -> -179.154 | AE38: =SUM(P38:S38) -> -175.757 | AG38: =SUM(AE38/AA38)-1 -> 0.079734362
B39: (+/-) Changes in NWC | C39: =SUM('Historical Financials'!D110:D115)/1000 -> -63.926 | D39: =SUM('Historical Financials'!E110:E115)/1000 -> 71.209 | E39: =SUM('Historical Financials'!F110:F115)/1000 -> -120.159 | F39: =SUM('Historical Financials'!G110:G115)/1000 -> -74.279 | G39: =SUM('Historical Financials'!H110:H115)/1000 -> -187.205 | I39: =SUM('Historical Financials'!J110:J115)/1000 -> 185.718 | J39: =SUM('Historical Financials'!K110:K115)/1000 -> -112.314 | K39: =SUM('Historical Financials'!L110:L115)/1000 -> -81.402 | L39: =SUM('Historical Financials'!M110:M115)/1000 -> -66.281 | M39: =SUM('Historical Financials'!N110:N115)/1000 -> -69.37 | N39: =SUM('Historical Financials'!O110:O115)/1000 -> -20.584 | O39: =SUM('Historical Financials'!P110:P115)/1000 -> -126.78 | P39: =SUM('Historical Financials'!Q110:Q115)/1000 -> 29.529 | ... S39: =SUM('Historical Financials'!T110:T115)/1000 -> -170.842 | U39: =SUM(I39:I39) -> 185.718 | V39: =SUM(I39:J39) -> 73.404 | W39: =SUM(I39:K39) -> -7.998 | X39: =SUM(I39:L39) -> -74.279 | Y39: =SUM(J39:M39) -> -329.367 | Z39: =SUM(K39:N39) -> -237.637 | AA39: =SUM(L39:O39) -> -283.015 | AB39: =SUM(M39:P39) -> -187.205 | AC39: =SUM(N39:Q39) -> -89.086 | AD39: =SUM(O39:R39) -> -133.768 | AE39: =SUM(P39:S39) -> -177.83 | AG39: =SUM(AE39/AA39)-1 -> -0.37165875
B40: Discretionary Cash-Flows | C40: =SUM(C33+SUM(C36:C39)) -> -1038.444 | D40: =SUM(D33+SUM(D36:D39)) -> -287.119 | E40: =SUM(E33+SUM(E36:E39)) -> -272.652 | F40: =SUM(F33+SUM(F36:F39)) -> -494.787 | G40: =SUM(G33+SUM(G36:G39)) -> -940.89 | I40: =SUM(I33+SUM(I36:I39)) -> 82.692 | J40: =SUM(J33+SUM(J36:J39)) -> -95.971 | K40: =SUM(K33+SUM(K36:K39)) -> -253.109 | L40: =SUM(L33+SUM(L36:L39)) -> -228.399 | M40: =SUM(M33+SUM(M36:M39)) -> -263.294 | N40: =SUM(N33+SUM(N36:N39)) -> -149.726 | O40: =SUM(O33+SUM(O36:O39)) -> -407.89 | P40: =SUM(P33+SUM(P36:P39)) -> -119.98 | ... S40: =SUM(S33+SUM(S36:S39)) -> -409.809 | U40: =SUM(U33+SUM(U36:U39)) -> -1520.353 | V40: =SUM(V33+SUM(V36:V39)) -> -1153.304 | W40: =SUM(W33+SUM(W36:W39)) -> -318.373 | X40: =SUM(X33+SUM(X36:X39)) -> -598.29 | Y40: =SUM(Y33+SUM(Y36:Y39)) -> -956.422 | Z40: =SUM(Z33+SUM(Z36:Z39)) -> -974.975 | AA40: =SUM(AA33+SUM(AA36:AA39)) -> -1049.309 | AB40: =SUM(AB33+SUM(AB36:AB39)) -> -940.89 | ... AE40: =SUM(AE33+SUM(AE36:AE39)) -> -1005.336 | AG40: =SUM(AE40/AA40)-1 -> -0.041906626
B42: (+/-) Proceeds / (Purchase) of available-for-sale investment securities | C42: ='Historical Financials'!D121/1000 -> -1.228 | D42: ='Historical Financials'!E121/1000 -> -0.861 | E42: ='Historical Financials'!F121/1000 -> -1.19 | F42: ='Historical Financials'!G121/1000 -> -2.057 | G42: ='Historical Financials'!H121/1000 -> -1.395 | I42: ='Historical Financials'!J121/1000 -> -0.593 | J42: ='Historical Financials'!K121/1000 -> -0.607 | K42: ='Historical Financials'!L121/1000 -> -0.503 | L42: ='Historical Financials'!M121/1000 -> -0.354 | M42: ='Historical Financials'!N121/1000 -> -0.326 | N42: ='Historical Financials'!O121/1000 -> -0.298 | O42: ='Historical Financials'!P121/1000 -> -0.316 | P42: ='Historical Financials'!Q121/1000 -> -0.455 | ... S42: ='Historical Financials'!T121/1000 -> 0 | U42: =SUM(F42:I42) -> -4.045 | V42: =SUM(G42:J42) -> -2.595 | W42: =SUM(H42:K42) -> -1.703 | X42: =SUM(I42:L42) -> -2.057 | Y42: =SUM(J42:M42) -> -1.79 | Z42: =SUM(K42:N42) -> -1.481 | AA42: =SUM(L42:O42) -> -1.294 | AB42: =SUM(M42:P42) -> -1.395 | ... AE42: =SUM(P42:S42) -> 119.413
