Workbook

Sheet Historical Financials
B2: Best Buy Co Inc (NASDAQ: BBY)
B3: Historical Financials
B4: ($ In Millions, except EPS)
A6: X | B6: Income Statement | C6: FYE | F6: FYE | J6: Quarterly | P6: Quarterly | AF6: LTM | AL6: Variance
B7: Fiscal Period | C7: 2020 | D7: 2021 | E7: 2022 | F7: 2023 | G7: 2024 | H7: 2025 | J7: 1Q23 | K7: 2Q23 | L7: 3Q23 | M7: 4Q23 | N7: 1Q24 | O7: 2Q24 | P7: 3Q24 | Q7: 4Q24 | R7: 1Q25 | S7: 2Q25 | T7: 3Q25 | U7: 4Q25 | V7: 1Q26 | W7: 2Q26 | X7: 3Q26 | Z7: =N7 -> 1Q24 | AA7: =O7 -> 2Q24 | AB7: =P7 -> 3Q24 | AC7: =Q7 -> 4Q24 | AD7: =R7 -> 1Q25 | AE7: =S7 -> 2Q25 | AF7: =T7 -> 3Q25 | AG7: =U7 -> 4Q25 | ... AJ7: =X7 -> 3Q26
B8: Fiscal Period End Date | C8: 43862 | D8: 44226 | E8: 44590 | F8: 44954 | G8: 45325 | H8: 45689 | J8: 44681 | K8: 44772 | L8: 44863 | M8: =F8 -> 44954 | N8: 45045 | O8: 45136 | P8: 45227 | Q8: =G8 -> 45325 | R8: 45416 | S8: 45507 | T8: 45598 | U8: =H8 -> 45689 | V8: 45780 | W8: 45871 | X8: 45962 | Z8: =N8 -> 45045 | AA8: =O8 -> 45136 | AB8: =P8 -> 45227 | AC8: =Q8 -> 45325 | AD8: =R8 -> 45416 | AE8: =S8 -> 45507 | AF8: =T8 -> 45598 | AG8: =U8 -> 45689 | ... AJ8: =X8 -> 45962
B10: Consolidated Revenue | C10: 43638 | D10: 47262 | E10: 51761 | F10: 46298 | G10: 43452 | H10: 41528 | J10: 10647 | K10: 10329 | L10: 10587 | M10: =SUM(F10-SUM(J10:L10)) -> 14735 | N10: 9467 | O10: 9583 | P10: 9756 | Q10: =SUM(G10-SUM(N10:P10)) -> 14646 | R10: 8847 | S10: 9288 | T10: 9445 | U10: =SUM(H10-SUM(R10:T10)) -> 13948 | V10: 8767 | W10: 9438 | X10: 9672 | Z10: =SUM(K10:N10) -> 45118 | AA10: =SUM(L10:O10) -> 44372 | AB10: =SUM(M10:P10) -> 43541 | AC10: =SUM(N10:Q10) -> 43452 | AD10: =SUM(O10:R10) -> 42832 | AE10: =SUM(P10:S10) -> 42537 | AF10: =SUM(Q10:T10) -> 42226 | AG10: =SUM(R10:U10) -> 41528 | ... AJ10: =SUM(U10:X10) -> 41825 | AL10: =SUM(AJ10/AF10)-1 -> -0.0094965187
B11: Total Revenue | C11: =+SUM(C10:C10) -> 43638 | D11: =+SUM(D10:D10) -> 47262 | E11: =+SUM(E10:E10) -> 51761 | F11: =+SUM(F10:F10) -> 46298 | G11: =+SUM(G10:G10) -> 43452 | H11: =+SUM(H10:H10) -> 41528 | J11: =+SUM(J10:J10) -> 10647 | K11: =+SUM(K10:K10) -> 10329 | L11: =+SUM(L10:L10) -> 10587 | M11: =+SUM(M10:M10) -> 14735 | N11: =+SUM(N10:N10) -> 9467 | O11: =+SUM(O10:O10) -> 9583 | P11: =+SUM(P10:P10) -> 9756 | Q11: =+SUM(Q10:Q10) -> 14646 | ... X11: =+SUM(X10:X10) -> 9672 | Z11: =+SUM(Z10:Z10) -> 45118 | AA11: =+SUM(AA10:AA10) -> 44372 | AB11: =+SUM(AB10:AB10) -> 43541 | AC11: =+SUM(AC10:AC10) -> 43452 | AD11: =+SUM(AD10:AD10) -> 42832 | AE11: =+SUM(AE10:AE10) -> 42537 | AF11: =+SUM(AF10:AF10) -> 42226 | AG11: =+SUM(AG10:AG10) -> 41528 | ... AJ11: =+SUM(AJ10:AJ10) -> 41825 | AL11: =SUM(AJ11/AF11)-1 -> -0.0094965187
B13: Cost of Sales | C13: -33590 | D13: -36689 | E13: -40121 | F13: -36386 | G13: -33849 | H13: -32143 | J13: -8294 | K13: -8042 | L13: -8255 | M13: =SUM(F13-SUM(J13:L13)) -> -11795 | N13: -7317 | O13: -7363 | P13: -7524 | Q13: =SUM(G13-SUM(N13:P13)) -> -11645 | R13: -6783 | S13: -7102 | T13: -7228 | U13: =SUM(H13-SUM(R13:T13)) -> -11030 | V13: -6718 | W13: -7244 | X13: -7424 | Z13: =SUM(K13:N13) -> -35409 | AA13: =SUM(L13:O13) -> -34730 | AB13: =SUM(M13:P13) -> -33999 | AC13: =SUM(N13:Q13) -> -33849 | AD13: =SUM(O13:R13) -> -33315 | AE13: =SUM(P13:S13) -> -33054 | AF13: =SUM(Q13:T13) -> -32758 | AG13: =SUM(R13:U13) -> -32143 | ... AJ13: =SUM(U13:X13) -> -32416 | AL13: =SUM(AJ13/AF13)-1 -> -0.010440198
B14: Gross Profit | C14: =+SUM(C11+SUM(C13:C13)) -> 10048 | D14: =+SUM(D11+SUM(D13:D13)) -> 10573 | E14: =+SUM(E11+SUM(E13:E13)) -> 11640 | F14: =+SUM(F11+SUM(F13:F13)) -> 9912 | G14: =+SUM(G11+SUM(G13:G13)) -> 9603 | H14: =+SUM(H11+SUM(H13:H13)) -> 9385 | J14: =+SUM(J11+SUM(J13:J13)) -> 2353 | K14: =+SUM(K11+SUM(K13:K13)) -> 2287 | L14: =+SUM(L11+SUM(L13:L13)) -> 2332 | M14: =+SUM(M11+SUM(M13:M13)) -> 2940 | N14: =+SUM(N11+SUM(N13:N13)) -> 2150 | O14: =+SUM(O11+SUM(O13:O13)) -> 2220 | P14: =+SUM(P11+SUM(P13:P13)) -> 2232 | Q14: =+SUM(Q11+SUM(Q13:Q13)) -> 3001 | ... X14: =+SUM(X11+SUM(X13:X13)) -> 2248 | Z14: =+SUM(Z11+SUM(Z13:Z13)) -> 9709 | AA14: =+SUM(AA11+SUM(AA13:AA13)) -> 9642 | AB14: =+SUM(AB11+SUM(AB13:AB13)) -> 9542 | AC14: =+SUM(AC11+SUM(AC13:AC13)) -> 9603 | AD14: =+SUM(AD11+SUM(AD13:AD13)) -> 9517 | AE14: =+SUM(AE11+SUM(AE13:AE13)) -> 9483 | AF14: =+SUM(AF11+SUM(AF13:AF13)) -> 9468 | AG14: =+SUM(AG11+SUM(AG13:AG13)) -> 9385 | ... AJ14: =+SUM(AJ11+SUM(AJ13:AJ13)) -> 9409 | AL14: =SUM(AJ14/AF14)-1 -> -0.0062315167
B15: Gross Margin (%) | C15: =C14/C11 -> 0.23025803 | D15: =D14/D11 -> 0.22371038 | E15: =E14/E11 -> 0.22487974 | F15: =F14/F11 -> 0.21409132 | G15: =G14/G11 -> 0.22100249 | H15: =H14/H11 -> 0.2259921 | J15: =J14/J11 -> 0.22100122 | K15: =K14/K11 -> 0.22141543 | L15: =L14/L11 -> 0.22027014 | M15: =M14/M11 -> 0.19952494 | N15: =N14/N11 -> 0.22710468 | O15: =O14/O11 -> 0.23166023 | P15: =P14/P11 -> 0.22878229 | Q15: =Q14/Q11 -> 0.20490236 | ... X15: =X14/X11 -> 0.23242349 | Z15: =Z14/Z11 -> 0.21519128 | AA15: =AA14/AA11 -> 0.2172992 | AB15: =AB14/AB11 -> 0.21914977 | AC15: =AC14/AC11 -> 0.22100249 | AD15: =AD14/AD11 -> 0.22219369 | AE15: =AE14/AE11 -> 0.22293533 | AF15: =AF14/AF11 -> 0.22422204 | AG15: =AG14/AG11 -> 0.2259921 | ... AJ15: =AJ14/AJ11 -> 0.22496115 | AL15: =SUM(AJ15-AF15)*1000 -> 0.73910435
B17: Selling, general and administrative expenses | C17: -7998 | D17: -7928 | E17: -8635 | F17: -7970 | G17: -7876 | H17: -7651 | J17: -1890 | K17: -1882 | L17: -1941 | M17: =SUM(F17-SUM(J17:L17)) -> -2257 | N17: -1848 | O17: -1879 | P17: -1878 | Q17: =SUM(G17-SUM(N17:P17)) -> -2271 | R17: -1737 | S17: -1810 | T17: -1871 | U17: =SUM(H17-SUM(R17:T17)) -> -2233 | V17: -1721 | W17: -1829 | X17: -1884 | Z17: =SUM(K17:N17) -> -7928 | AA17: =SUM(L17:O17) -> -7925 | AB17: =SUM(M17:P17) -> -7862 | AC17: =SUM(N17:Q17) -> -7876 | AD17: =SUM(O17:R17) -> -7765 | AE17: =SUM(P17:S17) -> -7696 | AF17: =SUM(Q17:T17) -> -7689 | AG17: =SUM(R17:U17) -> -7651 | ... AJ17: =SUM(U17:X17) -> -7667 | AL17: =SUM(AJ17/AF17)-1 -> -0.0028612303
B18: Restructuring, Impairments, and Other Charges | C18: -41 | D18: -254 | E18: 34 | F18: -147 | G18: -153 | H18: =-475 +3 -> -472 | J18: -1 | K18: -34 | L18: -26 | M18: =SUM(F18-SUM(J18:L18)) -> -86 | N18: 9 | O18: 7 | P18: 0 | Q18: =SUM(G18-SUM(N18:P18)) -> -169 | R18: -15 | S18: 7 | T18: 4 | U18: =SUM(H18-SUM(R18:T18)) -> -468 | V18: -109 | W18: -114 | X18: =-171+5 -> -166 | Z18: =SUM(K18:N18) -> -137 | AA18: =SUM(L18:O18) -> -96 | AB18: =SUM(M18:P18) -> -70 | AC18: =SUM(N18:Q18) -> -153 | AD18: =SUM(O18:R18) -> -177 | AE18: =SUM(P18:S18) -> -177 | AF18: =SUM(Q18:T18) -> -173 | AG18: =SUM(R18:U18) -> -472 | ... AJ18: =SUM(U18:X18) -> -857 | AL18: =SUM(AJ18/AF18)-1 -> 3.9537572
B19: Operating Profit | C19: =+SUM(C14+SUM(C17:C18)) -> 2009 | D19: =+SUM(D14+SUM(D17:D18)) -> 2391 | E19: =+SUM(E14+SUM(E17:E18)) -> 3039 | F19: =+SUM(F14+SUM(F17:F18)) -> 1795 | G19: =+SUM(G14+SUM(G17:G18)) -> 1574 | H19: =+SUM(H14+SUM(H17:H18)) -> 1262 | J19: =+SUM(J14+SUM(J17:J18)) -> 462 | K19: =+SUM(K14+SUM(K17:K18)) -> 371 | L19: =+SUM(L14+SUM(L17:L18)) -> 365 | M19: =+SUM(M14+SUM(M17:M18)) -> 597 | N19: =+SUM(N14+SUM(N17:N18)) -> 311 | O19: =+SUM(O14+SUM(O17:O18)) -> 348 | P19: =+SUM(P14+SUM(P17:P18)) -> 354 | Q19: =+SUM(Q14+SUM(Q17:Q18)) -> 561 | ... X19: =+SUM(X14+SUM(X17:X18)) -> 198 | Z19: =+SUM(Z14+SUM(Z17:Z18)) -> 1644 | AA19: =+SUM(AA14+SUM(AA17:AA18)) -> 1621 | AB19: =+SUM(AB14+SUM(AB17:AB18)) -> 1610 | AC19: =+SUM(AC14+SUM(AC17:AC18)) -> 1574 | AD19: =+SUM(AD14+SUM(AD17:AD18)) -> 1575 | AE19: =+SUM(AE14+SUM(AE17:AE18)) -> 1610 | AF19: =+SUM(AF14+SUM(AF17:AF18)) -> 1606 | AG19: =+SUM(AG14+SUM(AG17:AG18)) -> 1262 | ... AJ19: =+SUM(AJ14+SUM(AJ17:AJ18)) -> 885 | AL19: =SUM(AJ19/AF19)-1 -> -0.44894147
B20: Operating Margin (%) | C20: =C19/C11 -> 0.046037857 | D20: =D19/D11 -> 0.050590326 | E20: =E19/E11 -> 0.058712158 | F20: =F19/F11 -> 0.038770573 | G20: =G19/G11 -> 0.036223879 | H20: =H19/H11 -> 0.030389135 | J20: =J19/J11 -> 0.043392505 | K20: =K19/K11 -> 0.035918288 | L20: =L19/L11 -> 0.034476244 | M20: =M19/M11 -> 0.040515779 | N20: =N19/N11 -> 0.032850956 | O20: =O19/O11 -> 0.036314307 | P20: =P19/P11 -> 0.036285363 | Q20: =Q19/Q11 -> 0.038303974 | ... X20: =X19/X11 -> 0.020471464 | Z20: =Z19/Z11 -> 0.036437785 | AA20: =AA19/AA11 -> 0.036532047 | AB20: =AB19/AB11 -> 0.036976643 | AC20: =AC19/AC11 -> 0.036223879 | AD20: =AD19/AD11 -> 0.036771573 | AE20: =AE19/AE11 -> 0.037849402 | AF20: =AF19/AF11 -> 0.038033439 | AG20: =AG19/AG11 -> 0.030389135 | ... AJ20: =AJ19/AJ11 -> 0.021159594 | AL20: =SUM(AJ20-AF20)*1000 -> -16.873846
B22: Gain (Loss) on sale of subsidiary, net | C22: 1 | D22: 1 | E22: 0 | F22: 0 | G22: 21 | H22: 0 | J22: 0 | K22: 0 | L22: 0 | M22: =SUM(F22-SUM(J22:L22)) -> 0 | N22: 0 | O22: 21 | P22: 0 | Q22: =SUM(G22-SUM(N22:P22)) -> 0 | R22: 0 | S22: 0 | T22: 0 | U22: =SUM(H22-SUM(R22:T22)) -> 0 | V22: 0 | W22: -4 | X22: 0 | Z22: =SUM(K22:N22) -> 0 | AA22: =SUM(L22:O22) -> 21 | AB22: =SUM(M22:P22) -> 21 | AC22: =SUM(N22:Q22) -> 21 | AD22: =SUM(O22:R22) -> 21 | AE22: =SUM(P22:S22) -> 0 | AF22: =SUM(Q22:T22) -> 0 | AG22: =SUM(R22:U22) -> 0 | ... AJ22: =SUM(U22:X22) -> -4 | AL22: =SUM(AJ22/AF22)-1 -> #DIV/0!
B23: Investment income and other | C23: 47 | D23: 37 | E23: 10 | F23: 28 | G23: 78 | H23: 84 | J23: -5 | K23: 3 | L23: 4 | M23: =SUM(F23-SUM(J23:L23)) -> 26 | N23: 21 | O23: 12 | P23: 8 | Q23: =SUM(G23-SUM(N23:P23)) -> 37 | R23: 25 | S23: 21 | T23: 19 | U23: =SUM(H23-SUM(R23:T23)) -> 19 | V23: 15 | W23: 18 | X23: 19 | Z23: =SUM(K23:N23) -> 54 | AA23: =SUM(L23:O23) -> 63 | AB23: =SUM(M23:P23) -> 67 | AC23: =SUM(N23:Q23) -> 78 | AD23: =SUM(O23:R23) -> 82 | AE23: =SUM(P23:S23) -> 91 | AF23: =SUM(Q23:T23) -> 102 | AG23: =SUM(R23:U23) -> 84 | ... AJ23: =SUM(U23:X23) -> 71 | AL23: =SUM(AJ23/AF23)-1 -> -0.30392157
B24: Interest Income (expense) | C24: -64 | D24: -52 | E24: -25 | F24: -35 | G24: -52 | H24: -51 | J24: -6 | K24: -7 | L24: -10 | M24: =SUM(F24-SUM(J24:L24)) -> -12 | N24: -12 | O24: -12 | P24: -14 | Q24: =SUM(G24-SUM(N24:P24)) -> -14 | R24: -12 | S24: -13 | T24: -13 | U24: =SUM(H24-SUM(R24:T24)) -> -13 | V24: -12 | W24: -12 | X24: -12 | Z24: =SUM(K24:N24) -> -41 | AA24: =SUM(L24:O24) -> -46 | AB24: =SUM(M24:P24) -> -50 | AC24: =SUM(N24:Q24) -> -52 | AD24: =SUM(O24:R24) -> -52 | AE24: =SUM(P24:S24) -> -53 | AF24: =SUM(Q24:T24) -> -52 | AG24: =SUM(R24:U24) -> -51 | ... AJ24: =SUM(U24:X24) -> -49 | AL24: =SUM(AJ24/AF24)-1 -> -0.057692308
B25: Earnings before income tax expense and equity in income of affiliates | C25: =SUM(C22:C24)+C19 -> 1993 | D25: =SUM(D22:D24)+D19 -> 2377 | E25: =SUM(E22:E24)+E19 -> 3024 | F25: =SUM(F22:F24)+F19 -> 1788 | G25: =SUM(G22:G24)+G19 -> 1621 | H25: =SUM(H22:H24)+H19 -> 1295 | J25: =SUM(J22:J24)+J19 -> 451 | K25: =SUM(K22:K24)+K19 -> 367 | L25: =SUM(L22:L24)+L19 -> 359 | M25: =SUM(M22:M24)+M19 -> 611 | N25: =SUM(N22:N24)+N19 -> 320 | O25: =SUM(O22:O24)+O19 -> 369 | P25: =SUM(P22:P24)+P19 -> 348 | Q25: =SUM(Q22:Q24)+Q19 -> 584 | ... X25: =SUM(X22:X24)+X19 -> 205 | Z25: =SUM(Z22:Z24)+Z19 -> 1657 | AA25: =SUM(AA22:AA24)+AA19 -> 1659 | AB25: =SUM(AB22:AB24)+AB19 -> 1648 | AC25: =SUM(AC22:AC24)+AC19 -> 1621 | AD25: =SUM(AD22:AD24)+AD19 -> 1626 | AE25: =SUM(AE22:AE24)+AE19 -> 1648 | AF25: =SUM(AF22:AF24)+AF19 -> 1656 | AG25: =SUM(AG22:AG24)+AG19 -> 1295 | ... AJ25: =SUM(AJ22:AJ24)+AJ19 -> 903 | AL25: =SUM(AJ25/AF25)-1 -> -0.45471014
B26: EBT Margin (%) | C26: =C25/C11 -> 0.045671204 | D26: =D25/D11 -> 0.050294105 | E26: =E25/E11 -> 0.058422364 | F26: =F25/F11 -> 0.038619379 | G26: =G25/G11 -> 0.037305533 | H26: =H25/H11 -> 0.03118378 | J26: =J25/J11 -> 0.04235935 | K26: =K25/K11 -> 0.035531029 | L26: =L25/L11 -> 0.033909512 | M26: =M25/M11 -> 0.041465898 | N26: =N25/N11 -> 0.033801627 | O26: =O25/O11 -> 0.038505687 | P26: =P25/P11 -> 0.035670357 | Q26: =Q25/Q11 -> 0.039874368 | ... X26: =X25/X11 -> 0.021195203 | Z26: =Z25/Z11 -> 0.036725919 | AA26: =AA25/AA11 -> 0.037388443 | AB26: =AB25/AB11 -> 0.037849383 | AC26: =AC25/AC11 -> 0.037305533 | AD26: =AD25/AD11 -> 0.037962271 | AE26: =AE25/AE11 -> 0.038742742 | AF26: =AF25/AF11 -> 0.039217544 | AG26: =AG25/AG11 -> 0.03118378 | ... AJ26: =AJ25/AJ11 -> 0.021589958 | AL26: =SUM(AJ26-AF26)*1000 -> -17.627586
B28: Income tax expense | C28: -452 | D28: -579 | E28: -574 | F28: -370 | G28: -381 | H28: -372 | J28: -110 | K28: -58 | L28: -84 | M28: =SUM(F28-SUM(J28:L28)) -> -118 | N28: -75 | O28: -96 | P28: -86 | Q28: =SUM(G28-SUM(N28:P28)) -> -124 | R28: -80 | S28: -101 | T28: -85 | U28: =SUM(H28-SUM(R28:T28)) -> -106 | V28: -19 | W28: -68 | X28: -64 | Z28: =SUM(K28:N28) -> -335 | AA28: =SUM(L28:O28) -> -373 | AB28: =SUM(M28:P28) -> -375 | AC28: =SUM(N28:Q28) -> -381 | AD28: =SUM(O28:R28) -> -386 | AE28: =SUM(P28:S28) -> -391 | AF28: =SUM(Q28:T28) -> -390 | AG28: =SUM(R28:U28) -> -372 | ... AJ28: =SUM(U28:X28) -> -257 | AL28: =SUM(AJ28/AF28)-1 -> -0.34102564
B29: Equity in income of affiliates | C29: 0 | D29: 0 | E29: 4 | F29: 1 | G29: 1 | H29: 4 | J29: 0 | K29: -3 | L29: 2 | M29: =SUM(F29-SUM(J29:L29)) -> 2 | N29: -1 | O29: 1 | P29: 1 | Q29: =SUM(G29-SUM(N29:P29)) -> 0 | R29: 1 | S29: 1 | T29: 2 | U29: =SUM(H29-SUM(R29:T29)) -> 0 | V29: -1 | W29: 1 | X29: -1 | Z29: =SUM(K29:N29) -> 0 | AA29: =SUM(L29:O29) -> 4 | AB29: =SUM(M29:P29) -> 3 | AC29: =SUM(N29:Q29) -> 1 | AD29: =SUM(O29:R29) -> 3 | AE29: =SUM(P29:S29) -> 3 | AF29: =SUM(Q29:T29) -> 4 | AG29: =SUM(R29:U29) -> 4 | ... AJ29: =SUM(U29:X29) -> -1 | AL29: =SUM(AJ29/AF29)-1 -> -1.25
B30: Net loss | C30: =SUM(C25+SUM(C28:C29)) -> 1541 | D30: =SUM(D25+SUM(D28:D29)) -> 1798 | E30: =SUM(E25+SUM(E28:E29)) -> 2454 | F30: =SUM(F25+SUM(F28:F29)) -> 1419 | G30: =SUM(G25+SUM(G28:G29)) -> 1241 | H30: =SUM(H25+SUM(H28:H29)) -> 927 | J30: =SUM(J25+SUM(J28:J29)) -> 341 | K30: =SUM(K25+SUM(K28:K29)) -> 306 | L30: =SUM(L25+SUM(L28:L29)) -> 277 | M30: =SUM(M25+SUM(M28:M29)) -> 495 | N30: =SUM(N25+SUM(N28:N29)) -> 244 | O30: =SUM(O25+SUM(O28:O29)) -> 274 | P30: =SUM(P25+SUM(P28:P29)) -> 263 | Q30: =SUM(Q25+SUM(Q28:Q29)) -> 460 | ... X30: =SUM(X25+SUM(X28:X29)) -> 140 | Z30: =SUM(Z25+SUM(Z28:Z29)) -> 1322 | AA30: =SUM(AA25+SUM(AA28:AA29)) -> 1290 | AB30: =SUM(AB25+SUM(AB28:AB29)) -> 1276 | AC30: =SUM(AC25+SUM(AC28:AC29)) -> 1241 | AD30: =SUM(AD25+SUM(AD28:AD29)) -> 1243 | AE30: =SUM(AE25+SUM(AE28:AE29)) -> 1260 | AF30: =SUM(AF25+SUM(AF28:AF29)) -> 1270 | AG30: =SUM(AG25+SUM(AG28:AG29)) -> 927 | ... AJ30: =SUM(AJ25+SUM(AJ28:AJ29)) -> 645 | AL30: =SUM(AJ30/AF30)-1 -> -0.49212598
B31: Net Margin (%) | C31: =C30/C11 -> 0.035313259 | D31: =D30/D11 -> 0.038043248 | E31: =E30/E11 -> 0.047410212 | F31: =F30/F11 -> 0.030649272 | G31: =G30/G11 -> 0.02856025 | H31: =H30/H11 -> 0.022322289 | J31: =J30/J11 -> 0.032027801 | K31: =K30/K11 -> 0.029625327 | L31: =L30/L11 -> 0.026164164 | M31: =M30/M11 -> 0.033593485 | N31: =N30/N11 -> 0.02577374 | O31: =O30/O11 -> 0.028592299 | P31: =P30/P11 -> 0.02695777 | Q31: =Q30/Q11 -> 0.031407893 | ... X31: =X30/X11 -> 0.014474773 | Z31: =Z30/Z11 -> 0.029300944 | AA31: =AA30/AA11 -> 0.029072388 | AB31: =AB30/AB11 -> 0.029305712 | AC31: =AC30/AC11 -> 0.02856025 | AD31: =AD30/AD11 -> 0.029020359 | AE31: =AE30/AE11 -> 0.029621271 | AF31: =AF30/AF11 -> 0.030076256 | AG31: =AG30/AG11 -> 0.022322289 | ... AJ31: =AJ30/AJ11 -> 0.015421399 | AL31: =SUM(AJ31-AF31)*1000 -> -14.654858
B33: Basic shares | C33: 264.9 | D33: 259.6 | E33: 246.8 | F33: 224.8 | G33: 217.7 | H33: 215.2 | J33: 226.8 | K33: 225.4 | L33: 225.5 | M33: =F33 -> 224.8 | N33: 218.9 | O33: 218.6 | P33: 217.8 | Q33: =G33 -> 217.7 | R33: 216.2 | S33: 216 | T33: 214.8 | U33: =H33 -> 215.2 | V33: 212 | W33: 211.5 | X33: 210.7 | Z33: =N33 -> 218.9 | AA33: =O33 -> 218.6 | AB33: =P33 -> 217.8 | AC33: =Q33 -> 217.7 | AD33: =R33 -> 216.2 | AE33: =S33 -> 216 | AF33: =T33 -> 214.8 | AG33: =U33 -> 215.2 | ... AJ33: =X33 -> 210.7 | AL33: =SUM(AJ33/AF33)-1 -> -0.019087523
B34: Basic EPS | C34: =C30/C33 -> 5.8172895 | D34: =D30/D33 -> 6.9260401 | E34: =E30/E33 -> 9.9432739 | F34: =F30/F33 -> 6.3122776 | G34: =G30/G33 -> 5.7005053 | H34: =H30/H33 -> 4.3076208 | J34: =J30/J33 -> 1.5035273 | K34: =K30/K33 -> 1.3575865 | L34: =L30/L33 -> 1.2283814 | M34: =M30/M33 -> 2.2019573 | N34: =N30/N33 -> 1.1146642 | O34: =O30/O33 -> 1.2534309 | P34: =P30/P33 -> 1.2075298 | Q34: =Q30/Q33 -> 2.1129995 | ... X34: =X30/X33 -> 0.66445183 | Z34: =Z30/Z33 -> 6.0392873 | AA34: =AA30/AA33 -> 5.9011894 | AB34: =AB30/AB33 -> 5.8585859 | AC34: =AC30/AC33 -> 5.7005053 | AD34: =AD30/AD33 -> 5.7493062 | AE34: =AE30/AE33 -> 5.8333333 | AF34: =AF30/AF33 -> 5.9124767 | AG34: =AG30/AG33 -> 4.3076208 | ... AJ34: =AJ30/AJ33 -> 3.0612245 | AL34: =SUM(AJ34/AF34)-1 -> -0.48224329
B36: Fully Diluted Shares | C36: 268.1 | D36: 263 | E36: 249.3 | F36: 225.7 | G36: 218.5 | H36: 216.6 | J36: 228.4 | K36: 226.1 | L36: 226.2 | M36: =F36 -> 225.7 | N36: 219.9 | O36: 219 | P36: 218.3 | Q36: =G36 -> 218.5 | R36: 217.2 | S36: 217.1 | T36: 216.7 | U36: =H36 -> 216.6 | V36: 213 | W36: 212 | X36: 212.1 | Z36: =N36 -> 219.9 | AA36: =O36 -> 219 | AB36: =P36 -> 218.3 | AC36: =Q36 -> 218.5 | AD36: =R36 -> 217.2 | AE36: =S36 -> 217.1 | AF36: =T36 -> 216.7 | AG36: =U36 -> 216.6 | ... AJ36: =X36 -> 212.1 | AL36: =SUM(AJ36/AF36)-1 -> -0.021227503
B37: Diluted EPS | C37: =C30/C36 -> 5.7478553 | D37: =D30/D36 -> 6.8365019 | E37: =E30/E36 -> 9.843562 | F37: =F30/F36 -> 6.2871068 | G37: =G30/G36 -> 5.6796339 | H37: =H30/H36 -> 4.2797784 | J37: =J30/J36 -> 1.4929947 | K37: =K30/K36 -> 1.3533835 | L37: =L30/L36 -> 1.22458 | M37: =M30/M36 -> 2.1931768 | N37: =N30/N36 -> 1.1095953 | O37: =O30/O36 -> 1.2511416 | P37: =P30/P36 -> 1.2047641 | Q37: =Q30/Q36 -> 2.1052632 | ... X37: =X30/X36 -> 0.66006601 | Z37: =Z30/Z36 -> 6.0118236 | AA37: =AA30/AA36 -> 5.890411 | AB37: =AB30/AB36 -> 5.8451672 | AC37: =AC30/AC36 -> 5.6796339 | AD37: =AD30/AD36 -> 5.7228361 | AE37: =AE30/AE36 -> 5.8037771 | AF37: =AF30/AF36 -> 5.8606368 | AG37: =AG30/AG36 -> 4.2797784 | ... AJ37: =AJ30/AJ36 -> 3.0410184 | AL37: =SUM(AJ37/AF37)-1 -> -0.48111127
A39: X | B39: Balance Sheet | C39: FYE | D39: FYE | E39: FYE | P39: Quarterly | AF39: LTM | AL39: Variance
B40: =B7 -> Fiscal Period | C40: =C7 -> 2020 | D40: =D7 -> 2021 | E40: =E7 -> 2022 | F40: =F7 -> 2023 | G40: =G7 -> 2024 | H40: =H7 -> 2025 | J40: =J7 -> 1Q23 | K40: =K7 -> 2Q23 | L40: =L7 -> 3Q23 | M40: =M7 -> 4Q23 | N40: =N7 -> 1Q24 | O40: =O7 -> 2Q24 | P40: =P7 -> 3Q24 | Q40: =Q7 -> 4Q24 | ... X40: =X7 -> 3Q26 | Z40: =Z7 -> 1Q24 | AA40: =AA7 -> 2Q24 | AB40: =AB7 -> 3Q24 | AC40: =AC7 -> 4Q24 | AD40: =AD7 -> 1Q25 | AE40: =AE7 -> 2Q25 | AF40: =AF7 -> 3Q25 | AG40: =AG7 -> 4Q25 | ... AJ40: =AJ7 -> 3Q26
B41: =B8 -> Fiscal Period End Date | C41: =C8 -> 43862 | D41: =D8 -> 44226 | E41: =E8 -> 44590 | F41: =F8 -> 44954 | G41: =G8 -> 45325 | H41: =H8 -> 45689 | J41: =J8 -> 44681 | K41: =K8 -> 44772 | L41: =L8 -> 44863 | M41: =M8 -> 44954 | N41: =N8 -> 45045 | O41: =O8 -> 45136 | P41: =P8 -> 45227 | Q41: =Q8 -> 45325 | ... X41: =X8 -> 45962 | Z41: =Z8 -> 45045 | AA41: =AA8 -> 45136 | AB41: =AB8 -> 45227 | AC41: =AC8 -> 45325 | AD41: =AD8 -> 45416 | AE41: =AE8 -> 45507 | AF41: =AF8 -> 45598 | AG41: =AG8 -> 45689 | ... AJ41: =AJ8 -> 45962
B43: Current Assets
B44: Cash and cash equivalents | C44: 2229 | D44: 5494 | E44: 2936 | F44: 1874 | G44: 1447 | H44: 1578 | J44: 640 | K44: 840 | L44: 932 | M44: =F44 -> 1874 | N44: 1030 | O44: 1093 | P44: 636 | Q44: =G44 -> 1447 | R44: 1214 | S44: 1387 | T44: 643 | U44: =H44 -> 1578 | V44: 1147 | W44: 1456 | X44: 923 | Z44: =N44 -> 1030 | AA44: =O44 -> 1093 | AB44: =P44 -> 636 | AC44: =Q44 -> 1447 | AD44: =R44 -> 1214 | AE44: =S44 -> 1387 | AF44: =T44 -> 643 | AG44: =U44 -> 1578 | ... AJ44: =X44 -> 923 | AL44: =SUM(AJ44/AF44)-1 -> 0.43545879
B45: Restricted Cash | C45: 126 | D45: 131 | E45: 269 | F45: 379 | G45: 346 | H45: 290 | J45: 320 | K45: 312 | L45: 361 | M45: =F45 -> 379 | N45: 402 | O45: 398 | P45: 423 | Q45: =G45 -> 346 | R45: 313 | S45: 311 | T45: 295 | U45: =H45 -> 290 | V45: 288 | W45: 257 | X45: 271 | Z45: =N45 -> 402 | AA45: =O45 -> 398 | AB45: =P45 -> 423 | AC45: =Q45 -> 346 | AD45: =R45 -> 313 | AE45: =S45 -> 311 | AF45: =T45 -> 295 | AG45: =U45 -> 290 | ... AJ45: =X45 -> 271 | AL45: =SUM(AJ45/AF45)-1 -> -0.081355932
B46: Receivables, net | C46: 1149 | D46: 1061 | E46: 1042 | F46: 1141 | G46: 939 | H46: 1044 | J46: 804 | K46: 840 | L46: 1050 | M46: =F46 -> 1141 | N46: 860 | O46: 856 | P46: 901 | Q46: =G46 -> 939 | R46: 770 | S46: 871 | T46: 932 | U46: =H46 -> 1044 | V46: 744 | W46: 917 | X46: 1017 | Z46: =N46 -> 860 | AA46: =O46 -> 856 | AB46: =P46 -> 901 | AC46: =Q46 -> 939 | AD46: =R46 -> 770 | AE46: =S46 -> 871 | AF46: =T46 -> 932 | AG46: =U46 -> 1044 | ... AJ46: =X46 -> 1017 | AL46: =SUM(AJ46/AF46)-1 -> 0.091201717
B47: Merchandise inventories | C47: 5174 | D47: 5612 | E47: 5965 | F47: 5140 | G47: 4958 | H47: 5085 | J47: 6258 | K47: 6043 | L47: 7294 | M47: =F47 -> 5140 | N47: 5219 | O47: 5651 | P47: 7562 | Q47: =G47 -> 4958 | R47: 5225 | S47: 5706 | T47: 7806 | U47: =H47 -> 5085 | V47: 5194 | W47: 5816 | X47: 7993 | Z47: =N47 -> 5219 | AA47: =O47 -> 5651 | AB47: =P47 -> 7562 | AC47: =Q47 -> 4958 | AD47: =R47 -> 5225 | AE47: =S47 -> 5706 | AF47: =T47 -> 7806 | AG47: =U47 -> 5085 | ... AJ47: =X47 -> 7993 | AL47: =SUM(AJ47/AF47)-1 -> 0.023955931
B48: Other current assets | C48: =305-C45 -> 179 | D48: =373-D45 -> 242 | E48: =596-E45 -> 327 | F48: =647-F45 -> 268 | G48: =553-G45 -> 207 | H48: =517-H45 -> 227 | J48: =613-J45 -> 293 | K48: =621-K45 -> 309 | L48: =646-L45 -> 285 | M48: =F48 -> 268 | N48: =653-N45 -> 251 | O48: =704-O45 -> 306 | P48: =766-P45 -> 343 | Q48: =G48 -> 207 | R48: =544-R45 -> 231 | S48: =598-S45 -> 287 | T48: =574-T45 -> 279 | U48: =H48 -> 227 | V48: =500-V45 -> 212 | W48: =688-W45 -> 431 | X48: =640-X45 -> 369 | Z48: =N48 -> 251 | AA48: =O48 -> 306 | AB48: =P48 -> 343 | AC48: =Q48 -> 207 | AD48: =R48 -> 231 | AE48: =S48 -> 287 | AF48: =T48 -> 279 | AG48: =U48 -> 227 | ... AJ48: =X48 -> 369 | AL48: =SUM(AJ48/AF48)-1 -> 0.32258065
B49: Total Current Assets | C49: =SUM(C44:C48) -> 8857 | D49: =SUM(D44:D48) -> 12540 | E49: =SUM(E44:E48) -> 10539 | F49: =SUM(F44:F48) -> 8802 | G49: =SUM(G44:G48) -> 7897 | H49: =SUM(H44:H48) -> 8224 | J49: =SUM(J44:J48) -> 8315 | K49: =SUM(K44:K48) -> 8344 | L49: =SUM(L44:L48) -> 9922 | M49: =SUM(M44:M48) -> 8802 | N49: =SUM(N44:N48) -> 7762 | O49: =SUM(O44:O48) -> 8304 | P49: =SUM(P44:P48) -> 9865 | Q49: =SUM(Q44:Q48) -> 7897 | ... X49: =SUM(X44:X48) -> 10573 | Z49: =SUM(Z44:Z48) -> 7762 | AA49: =SUM(AA44:AA48) -> 8304 | AB49: =SUM(AB44:AB48) -> 9865 | AC49: =SUM(AC44:AC48) -> 7897 | AD49: =SUM(AD44:AD48) -> 7753 | AE49: =SUM(AE44:AE48) -> 8562 | AF49: =SUM(AF44:AF48) -> 9955 | AG49: =SUM(AG44:AG48) -> 8224 | ... AJ49: =SUM(AJ44:AJ48) -> 10573 | AL49: =SUM(AJ49/AF49)-1 -> 0.062079357
B51: Non-Current Assets
B52: Net property and equipment | C52: 2328 | D52: 2260 | E52: 2250 | F52: 2352 | G52: 2260 | H52: 2122 | J52: 2251 | K52: 2319 | L52: 2373 | M52: =F52 -> 2352 | N52: 2321 | O52: 2305 | P52: 2313 | Q52: =G52 -> 2260 | R52: 2196 | S52: 2183 | T52: 2196 | U52: =H52 -> 2122 | V52: 2089 | W52: 2046 | X52: 2037 | Z52: =N52 -> 2321 | AA52: =O52 -> 2305 | AB52: =P52 -> 2313 | AC52: =Q52 -> 2260 | AD52: =R52 -> 2196 | AE52: =S52 -> 2183 | AF52: =T52 -> 2196 | AG52: =U52 -> 2122 | ... AJ52: =X52 -> 2037 | AL52: =SUM(AJ52/AF52)-1 -> -0.072404372
...

Sheet Revenue Drivers
B2: ='Historical Financials'!B2 -> Best Buy Co Inc (NASDAQ: BBY) | E2: FYE | P2: Quarterly | AF2: LTM
B3: Segment Anaysis | C3: ='Historical Financials'!C7 -> 2020 | D3: ='Historical Financials'!D7 -> 2021 | E3: ='Historical Financials'!E7 -> 2022 | F3: ='Historical Financials'!F7 -> 2023 | G3: ='Historical Financials'!G7 -> 2024 | H3: ='Historical Financials'!H7 -> 2025 | J3: ='Historical Financials'!J7 -> 1Q23 | K3: ='Historical Financials'!K7 -> 2Q23 | L3: ='Historical Financials'!L7 -> 3Q23 | M3: ='Historical Financials'!M7 -> 4Q23 | N3: ='Historical Financials'!N7 -> 1Q24 | O3: ='Historical Financials'!O7 -> 2Q24 | P3: ='Historical Financials'!P7 -> 3Q24 | Q3: ='Historical Financials'!Q7 -> 4Q24 | ... X3: ='Historical Financials'!X7 -> 3Q26 | Z3: =N3 -> 1Q24 | AA3: =O3 -> 2Q24 | AB3: =P3 -> 3Q24 | AC3: =Q3 -> 4Q24 | AD3: =R3 -> 1Q25 | AE3: =S3 -> 2Q25 | AF3: =T3 -> 3Q25 | AG3: =U3 -> 4Q25 | ... AJ3: =X3 -> 3Q26
B4: ($ In Millions) | C4: ='Historical Financials'!C8 -> 43862 | D4: ='Historical Financials'!D8 -> 44226 | E4: ='Historical Financials'!E8 -> 44590 | F4: ='Historical Financials'!F8 -> 44954 | G4: ='Historical Financials'!G8 -> 45325 | H4: ='Historical Financials'!H8 -> 45689 | J4: ='Historical Financials'!J8 -> 44681 | K4: ='Historical Financials'!K8 -> 44772 | L4: ='Historical Financials'!L8 -> 44863 | M4: ='Historical Financials'!M8 -> 44954 | N4: ='Historical Financials'!N8 -> 45045 | O4: ='Historical Financials'!O8 -> 45136 | P4: ='Historical Financials'!P8 -> 45227 | Q4: ='Historical Financials'!Q8 -> 45325 | ... X4: ='Historical Financials'!X8 -> 45962 | Z4: =N4 -> 45045 | AA4: =O4 -> 45136 | AB4: =P4 -> 45227 | AC4: =Q4 -> 45325 | AD4: =R4 -> 45416 | AE4: =S4 -> 45507 | AF4: =T4 -> 45598 | AG4: =U4 -> 45689 | ... AJ4: =X4 -> 45962
A6: X | B6: Revenue by reportable segment
A8: X | B8: Revenue Segment Anaysis
B9: Domestic | C9: 40114 | D9: 43293 | E9: 47830 | F9: 42794 | G9: 40097 | H9: 38238 | J9: 9894 | K9: 9569 | L9: 9800 | M9: =SUM(F9-SUM(J9:L9)) -> 13531 | N9: 8801 | O9: 8890 | P9: 8996 | Q9: =SUM(G9-SUM(N9:P9)) -> 13410 | R9: 8203 | S9: 8623 | T9: 8697 | U9: =SUM(H9-SUM(R9:T9)) -> 12715 | V9: 8127 | W9: 8698 | X9: 8878 | Z9: =SUM(K9:N9) -> 41701 | AA9: =SUM(L9:O9) -> 41022 | AB9: =SUM(M9:P9) -> 40218 | AC9: =SUM(N9:Q9) -> 40097 | AD9: =SUM(O9:R9) -> 39499 | AE9: =SUM(P9:S9) -> 39232 | AF9: =SUM(Q9:T9) -> 38933 | AG9: =SUM(R9:U9) -> 38238 | ... AJ9: =SUM(U9:X9) -> 38418
B10: International | C10: 3524 | D10: 3969 | E10: 3931 | F10: 3504 | G10: 3355 | H10: 3290 | J10: 753 | K10: 760 | L10: 787 | M10: =SUM(F10-SUM(J10:L10)) -> 1204 | N10: 666 | O10: 693 | P10: 760 | Q10: =SUM(G10-SUM(N10:P10)) -> 1236 | R10: 644 | S10: 665 | T10: 748 | U10: =SUM(H10-SUM(R10:T10)) -> 1233 | V10: 640 | W10: 740 | X10: 794 | Z10: =SUM(K10:N10) -> 3417 | AA10: =SUM(L10:O10) -> 3350 | AB10: =SUM(M10:P10) -> 3323 | AC10: =SUM(N10:Q10) -> 3355 | AD10: =SUM(O10:R10) -> 3333 | AE10: =SUM(P10:S10) -> 3305 | AF10: =SUM(Q10:T10) -> 3293 | AG10: =SUM(R10:U10) -> 3290 | ... AJ10: =SUM(U10:X10) -> 3407
B11: Total Net Revenue | C11: =SUM(C9:C10) -> 43638 | D11: =SUM(D9:D10) -> 47262 | E11: =SUM(E9:E10) -> 51761 | F11: =SUM(F9:F10) -> 46298 | G11: =SUM(G9:G10) -> 43452 | H11: =SUM(H9:H10) -> 41528 | J11: =SUM(J9:J10) -> 10647 | K11: =SUM(K9:K10) -> 10329 | L11: =SUM(L9:L10) -> 10587 | M11: =SUM(M9:M10) -> 14735 | N11: =SUM(N9:N10) -> 9467 | O11: =SUM(O9:O10) -> 9583 | P11: =SUM(P9:P10) -> 9756 | Q11: =SUM(Q9:Q10) -> 14646 | ... X11: =SUM(X9:X10) -> 9672 | Z11: =SUM(Z9:Z10) -> 45118 | AA11: =SUM(AA9:AA10) -> 44372 | AB11: =SUM(AB9:AB10) -> 43541 | AC11: =SUM(AC9:AC10) -> 43452 | AD11: =SUM(AD9:AD10) -> 42832 | AE11: =SUM(AE9:AE10) -> 42537 | AF11: =SUM(AF9:AF10) -> 42226 | AG11: =SUM(AG9:AG10) -> 41528 | ... AJ11: =SUM(AJ9:AJ10) -> 41825
B12: Balance Check | C12: =+C11-'Historical Financials'!C11 -> 0 | D12: =+D11-'Historical Financials'!D11 -> 0 | E12: =+E11-'Historical Financials'!E11 -> 0 | F12: =+F11-'Historical Financials'!F11 -> 0 | G12: =+G11-'Historical Financials'!G11 -> 0 | H12: =+H11-'Historical Financials'!H11 -> 0 | J12: =+J11-'Historical Financials'!J11 -> 0 | K12: =+K11-'Historical Financials'!K11 -> 0 | L12: =+L11-'Historical Financials'!L11 -> 0 | M12: =+M11-'Historical Financials'!M11 -> 0 | N12: =+N11-'Historical Financials'!N11 -> 0 | O12: =+O11-'Historical Financials'!O11 -> 0 | P12: =+P11-'Historical Financials'!P11 -> 0 | Q12: =+Q11-'Historical Financials'!Q11 -> 0 | ... X12: =+X11-'Historical Financials'!X11 -> 0 | Z12: =+Z11-'Historical Financials'!Z11 -> 0 | AA12: =+AA11-'Historical Financials'!AA11 -> 0 | AB12: =+AB11-'Historical Financials'!AB11 -> 0 | AC12: =+AC11-'Historical Financials'!AC11 -> 0 | AD12: =+AD11-'Historical Financials'!AD11 -> 0 | AE12: =+AE11-'Historical Financials'!AE11 -> 0 | AF12: =+AF11-'Historical Financials'!AF11 -> 0 | AG12: =+AG11-'Historical Financials'!AG11 -> 0 | ... AJ12: =+AJ11-'Historical Financials'!AJ11 -> 0
B14: =B9&"(%)" -> Domestic(%) | C14: =SUM(C9/C$11) -> 0.91924469 | D14: =SUM(D9/D$11) -> 0.91602133 | E14: =SUM(E9/E$11) -> 0.92405479 | F14: =SUM(F9/F$11) -> 0.92431639 | G14: =SUM(G9/G$11) -> 0.92278836 | H14: =SUM(H9/H$11) -> 0.92077634 | J14: =SUM(J9/J$11) -> 0.92927585 | K14: =SUM(K9/K$11) -> 0.92642076 | L14: =SUM(L9/L$11) -> 0.92566355 | M14: =SUM(M9/M$11) -> 0.91828979 | N14: =SUM(N9/N$11) -> 0.92965036 | O14: =SUM(O9/O$11) -> 0.92768444 | P14: =SUM(P9/P$11) -> 0.92209922 | Q14: =SUM(Q9/Q$11) -> 0.91560836 | ... X14: =SUM(X9/X$11) -> 0.91790736 | Z14: =J14 -> 0.92927585 | AA14: =K14 -> 0.92642076 | AB14: =L14 -> 0.92566355 | AC14: =M14 -> 0.91828979 | AD14: =N14 -> 0.92965036 | AE14: =O14 -> 0.92768444 | AF14: =P14 -> 0.92209922 | AG14: =Q14 -> 0.91560836 | ... AJ14: =T14 -> 0.92080466
B15: =B10&"(%)" -> International(%) | C15: =SUM(C10/C$11) -> 0.080755305 | D15: =SUM(D10/D$11) -> 0.083978672 | E15: =SUM(E10/E$11) -> 0.07594521 | F15: =SUM(F10/F$11) -> 0.075683615 | G15: =SUM(G10/G$11) -> 0.077211636 | H15: =SUM(H10/H$11) -> 0.079223656 | J15: =SUM(J10/J$11) -> 0.070724148 | K15: =SUM(K10/K$11) -> 0.073579243 | L15: =SUM(L10/L$11) -> 0.07433645 | M15: =SUM(M10/M$11) -> 0.081710214 | N15: =SUM(N10/N$11) -> 0.070349636 | O15: =SUM(O10/O$11) -> 0.072315559 | P15: =SUM(P10/P$11) -> 0.077900779 | Q15: =SUM(Q10/Q$11) -> 0.084391643 | ... X15: =SUM(X10/X$11) -> 0.082092639 | Z15: =J15 -> 0.070724148 | AA15: =K15 -> 0.073579243 | AB15: =L15 -> 0.07433645 | AC15: =M15 -> 0.081710214 | AD15: =N15 -> 0.070349636 | AE15: =O15 -> 0.072315559 | AF15: =P15 -> 0.077900779 | AG15: =Q15 -> 0.084391643 | ... AJ15: =T15 -> 0.079195341
A17: X | B17: Revenue by product category
A19: X | B19: Revenue by product category: Aggregate
B20: Computing and Mobile Phones | C20: =SUM(C37+C54) -> 19399 | D20: =SUM(D37+D54) -> 21653 | E20: =SUM(E37+E54) -> 22478 | F20: =SUM(F37+F54) -> 19766 | G20: =SUM(G37+G54) -> 18482 | H20: =SUM(H37+H54) -> 18681 | J20: =SUM(J37+J54) -> 4629 | K20: =SUM(K37+K54) -> 4291 | L20: =SUM(L37+L54) -> 4726 | M20: =SUM(M37+M54) -> 6120 | N20: =SUM(N37+N54) -> 4004 | O20: =SUM(O37+O54) -> 3983 | P20: =SUM(P37+P54) -> 4316 | Q20: =SUM(Q37+Q54) -> 6179 | ... X20: =SUM(X37+X54) -> 4788 | Z20: =SUM(K20:N20) -> 19141 | AA20: =SUM(L20:O20) -> 18833 | AB20: =SUM(M20:P20) -> 18423 | AC20: =SUM(N20:Q20) -> 18482 | AD20: =SUM(O20:R20) -> 18384 | AE20: =SUM(P20:S20) -> 18501 | AF20: =SUM(Q20:T20) -> 18636 | AG20: =SUM(R20:U20) -> 18681 | ... AJ20: =SUM(U20:X20) -> 19404
B21: Consumer Electronics | C21: =SUM(C38+C55) -> 14292 | D21: =SUM(D38+D55) -> 14211 | E21: =SUM(E38+E55) -> 16203 | F21: =SUM(F38+F55) -> 14094 | G21: =SUM(G38+G55) -> 12969 | H21: =SUM(H38+H55) -> 12065 | J21: =SUM(J38+J55) -> 3109 | K21: =SUM(K38+K55) -> 3068 | L21: =SUM(L38+L55) -> 3109 | M21: =SUM(M38+M55) -> 4808 | N21: =SUM(N38+N55) -> 2776 | O21: =SUM(O38+O55) -> 2852 | P21: =SUM(P38+P55) -> 2789 | Q21: =SUM(Q38+Q55) -> 4552 | ... X21: =SUM(X38+X55) -> 2553 | Z21: =SUM(K21:N21) -> 13761 | AA21: =SUM(L21:O21) -> 13545 | AB21: =SUM(M21:P21) -> 13225 | AC21: =SUM(N21:Q21) -> 12969 | AD21: =SUM(O21:R21) -> 12730 | AE21: =SUM(P21:S21) -> 12542 | AF21: =SUM(Q21:T21) -> 12372 | AG21: =SUM(R21:U21) -> 12065 | ... AJ21: =SUM(U21:X21) -> 11757
B22: Appliances | C22: =SUM(C39+C56) -> 4810 | D22: =SUM(D39+D56) -> 5873 | E22: =SUM(E39+E56) -> 7167 | F22: =SUM(F39+F56) -> 6736 | G22: =SUM(G39+G56) -> 5804 | H22: =SUM(H39+H56) -> 4910 | J22: =SUM(J39+J56) -> 1661 | K22: =SUM(K39+K56) -> 1761 | L22: =SUM(L39+L56) -> 1543 | M22: =SUM(M39+M56) -> 1771 | N22: =SUM(N39+N56) -> 1398 | O22: =SUM(O39+O56) -> 1476 | P22: =SUM(P39+P56) -> 1312 | Q22: =SUM(Q39+Q56) -> 1618 | ... X22: =SUM(X39+X56) -> 1029 | Z22: =SUM(K22:N22) -> 6473 | AA22: =SUM(L22:O22) -> 6188 | AB22: =SUM(M22:P22) -> 5957 | AC22: =SUM(N22:Q22) -> 5804 | AD22: =SUM(O22:R22) -> 5556 | AE22: =SUM(P22:S22) -> 5343 | AF22: =SUM(Q22:T22) -> 5155 | AG22: =SUM(R22:U22) -> 4910 | ... AJ22: =SUM(U22:X22) -> 4614
B23: Entertainment | C23: =SUM(C40+C57) -> 2597 | D23: =SUM(D40+D57) -> 3079 | E23: =SUM(E40+E57) -> 3275 | F23: =SUM(F40+F57) -> 3053 | G23: =SUM(G40+G57) -> 3363 | H23: =SUM(H40+H57) -> 2908 | J23: =SUM(J40+J57) -> 630 | K23: =SUM(K40+K57) -> 559 | L23: =SUM(L40+L57) -> 546 | M23: =SUM(M40+M57) -> 1318 | N23: =SUM(N40+N57) -> 651 | O23: =SUM(O40+O57) -> 594 | P23: =SUM(P40+P57) -> 648 | Q23: =SUM(Q40+Q57) -> 1470 | ... X23: =SUM(X40+X57) -> 597 | Z23: =SUM(K23:N23) -> 3074 | AA23: =SUM(L23:O23) -> 3109 | AB23: =SUM(M23:P23) -> 3211 | AC23: =SUM(N23:Q23) -> 3363 | AD23: =SUM(O23:R23) -> 3278 | AE23: =SUM(P23:S23) -> 3221 | AF23: =SUM(Q23:T23) -> 3099 | AG23: =SUM(R23:U23) -> 2908 | ... AJ23: =SUM(U23:X23) -> 3116
B24: Services | C24: =SUM(C41+C58) -> 2325 | D24: =SUM(D41+D58) -> 2252 | E24: =SUM(E41+E58) -> 2380 | F24: =SUM(F41+F58) -> 2332 | G24: =SUM(G41+G58) -> 2530 | H24: =SUM(H41+H58) -> 2631 | J24: =SUM(J41+J58) -> 543 | K24: =SUM(K41+K58) -> 553 | L24: =SUM(L41+L58) -> 576 | M24: =SUM(M41+M58) -> 660 | N24: =SUM(N41+N58) -> 573 | O24: =SUM(O41+O58) -> 588 | P24: =SUM(P41+P58) -> 608 | Q24: =SUM(Q41+Q58) -> 761 | ... X24: =SUM(X41+X58) -> 638 | Z24: =SUM(K24:N24) -> 2362 | AA24: =SUM(L24:O24) -> 2397 | AB24: =SUM(M24:P24) -> 2429 | AC24: =SUM(N24:Q24) -> 2530 | AD24: =SUM(O24:R24) -> 2574 | AE24: =SUM(P24:S24) -> 2614 | AF24: =SUM(Q24:T24) -> 2654 | AG24: =SUM(R24:U24) -> 2631 | ... AJ24: =SUM(U24:X24) -> 2612
B25: Other | C25: =SUM(C42+C59) -> 215 | D25: =SUM(D42+D59) -> 194 | E25: =SUM(E42+E59) -> 258 | F25: =SUM(F42+F59) -> 317 | G25: =SUM(G42+G59) -> 304 | H25: =SUM(H42+H59) -> 333 | J25: =SUM(J42+J59) -> 75 | K25: =SUM(K42+K59) -> 97 | L25: =SUM(L42+L59) -> 87 | M25: =SUM(M42+M59) -> 58 | N25: =SUM(N42+N59) -> 65 | O25: =SUM(O42+O59) -> 90 | P25: =SUM(P42+P59) -> 83 | Q25: =SUM(Q42+Q59) -> 66 | ... X25: =SUM(X42+X59) -> 67 | Z25: =SUM(K25:N25) -> 307 | AA25: =SUM(L25:O25) -> 300 | AB25: =SUM(M25:P25) -> 296 | AC25: =SUM(N25:Q25) -> 304 | AD25: =SUM(O25:R25) -> 310 | AE25: =SUM(P25:S25) -> 316 | AF25: =SUM(Q25:T25) -> 310 | AG25: =SUM(R25:U25) -> 333 | ... AJ25: =SUM(U25:X25) -> 322
B26: Total Domestic Revenue | C26: =SUM(C20:C25) -> 43638 | D26: =SUM(D20:D25) -> 47262 | E26: =SUM(E20:E25) -> 51761 | F26: =SUM(F20:F25) -> 46298 | G26: =SUM(G20:G25) -> 43452 | H26: =SUM(H20:H25) -> 41528 | J26: =SUM(J20:J25) -> 10647 | K26: =SUM(K20:K25) -> 10329 | L26: =SUM(L20:L25) -> 10587 | M26: =SUM(M20:M25) -> 14735 | N26: =SUM(N20:N25) -> 9467 | O26: =SUM(O20:O25) -> 9583 | P26: =SUM(P20:P25) -> 9756 | Q26: =SUM(Q20:Q25) -> 14646 | ... X26: =SUM(X20:X25) -> 9672 | Z26: =SUM(Z20:Z25) -> 45118 | AA26: =SUM(AA20:AA25) -> 44372 | AB26: =SUM(AB20:AB25) -> 43541 | AC26: =SUM(AC20:AC25) -> 43452 | AD26: =SUM(AD20:AD25) -> 42832 | AE26: =SUM(AE20:AE25) -> 42537 | AF26: =SUM(AF20:AF25) -> 42226 | AG26: =SUM(AG20:AG25) -> 41528 | ... AJ26: =SUM(AJ20:AJ25) -> 41825
B27: Balance Check | C27: =+C26-C11 -> 0 | D27: =+D26-D11 -> 0 | E27: =+E26-E11 -> 0 | F27: =+F26-F11 -> 0 | G27: =+G26-G11 -> 0 | H27: =+H26-H11 -> 0 | J27: =+J26-J11 -> 0 | K27: =+K26-K11 -> 0 | L27: =+L26-L11 -> 0 | M27: =+M26-M11 -> 0 | N27: =+N26-N11 -> 0 | O27: =+O26-O11 -> 0 | P27: =+P26-P11 -> 0 | Q27: =+Q26-Q11 -> 0 | ... X27: =+X26-X11 -> 0 | Z27: =+Z26-Z11 -> 0 | AA27: =+AA26-AA11 -> 0 | AB27: =+AB26-AB11 -> 0 | AC27: =+AC26-AC11 -> 0 | AD27: =+AD26-AD11 -> 0 | AE27: =+AE26-AE11 -> 0 | AF27: =+AF26-AF11 -> 0 | AG27: =+AG26-AG11 -> 0 | ... AJ27: =+AJ26-AJ11 -> 0
B29: =B20&"(%)" -> Computing and Mobile Phones (%) | C29: =C20/C$26 -> 0.44454375 | D29: =D20/D$26 -> 0.4581482 | E29: =E20/E$26 -> 0.43426518 | F29: =F20/F$26 -> 0.42692989 | G29: =G20/G$26 -> 0.42534291 | H29: =H20/H$26 -> 0.44984107 | J29: =J20/J$26 -> 0.43477036 | K29: =K20/K$26 -> 0.41543228 | L29: =L20/L$26 -> 0.44639652 | M29: =M20/M$26 -> 0.41533763 | N29: =N20/N$26 -> 0.42294285 | O29: =O20/O$26 -> 0.41563185 | P29: =P20/P$26 -> 0.44239442 | Q29: =Q20/Q$26 -> 0.42188994 | ... X29: =X20/X$26 -> 0.49503722 | Z29: =Z20/Z$26 -> 0.4242431 | AA29: =AA20/AA$26 -> 0.42443433 | AB29: =AB20/AB$26 -> 0.42311844 | AC29: =AC20/AC$26 -> 0.42534291 | AD29: =AD20/AD$26 -> 0.4292118 | AE29: =AE20/AE$26 -> 0.43493899 | AF29: =AF20/AF$26 -> 0.44133946 | AG29: =AG20/AG$26 -> 0.44984107 | ... AJ29: =AJ20/AJ$26 -> 0.46393305
B30: =B21&"(%)" -> Consumer Electronics (%) | C30: =C21/C$26 -> 0.32751272 | D30: =D21/D$26 -> 0.30068554 | E30: =E21/E$26 -> 0.31303491 | F30: =F21/F$26 -> 0.3044192 | G30: =G21/G$26 -> 0.29846727 | H30: =H21/H$26 -> 0.29052687 | J30: =J21/J$26 -> 0.29200714 | K30: =K21/K$26 -> 0.29702779 | L30: =L21/L$26 -> 0.29366204 | M30: =M21/M$26 -> 0.32629793 | N30: =N21/N$26 -> 0.29322911 | O30: =O21/O$26 -> 0.29761035 | P30: =P21/P$26 -> 0.28587536 | Q30: =Q21/Q$26 -> 0.31080158 | ... X30: =X21/X$26 -> 0.26395782 | Z30: =Z21/Z$26 -> 0.30500022 | AA30: =AA21/AA$26 -> 0.30526007 | AB30: =AB21/AB$26 -> 0.30373671 | AC30: =AC21/AC$26 -> 0.29846727 | AD30: =AD21/AD$26 -> 0.2972077 | AE30: =AE21/AE$26 -> 0.29484919 | AF30: =AF21/AF$26 -> 0.29299484 | AG30: =AG21/AG$26 -> 0.29052687 | ... AJ30: =AJ21/AJ$26 -> 0.28109982
B31: =B22&"(%)" -> Appliances (%) | C31: =C22/C$26 -> 0.11022503 | D31: =D22/D$26 -> 0.12426474 | E31: =E22/E$26 -> 0.13846332 | F31: =F22/F$26 -> 0.14549225 | G31: =G22/G$26 -> 0.13357268 | H31: =H22/H$26 -> 0.11823348 | J31: =J22/J$26 -> 0.15600639 | K31: =K22/K$26 -> 0.17049085 | L31: =L22/L$26 -> 0.14574478 | M31: =M22/M$26 -> 0.12019002 | N31: =N22/N$26 -> 0.14767086 | O31: =O22/O$26 -> 0.15402275 | P31: =P22/P$26 -> 0.13448134 | Q31: =Q22/Q$26 -> 0.11047385 | ... X31: =X22/X$26 -> 0.10638958 | Z31: =Z22/Z$26 -> 0.14346824 | AA31: =AA22/AA$26 -> 0.13945732 | AB31: =AB22/AB$26 -> 0.13681358 | AC31: =AC22/AC$26 -> 0.13357268 | AD31: =AD22/AD$26 -> 0.1297161 | AE31: =AE22/AE$26 -> 0.12560829 | AF31: =AF22/AF$26 -> 0.12208118 | AG31: =AG22/AG$26 -> 0.11823348 | ... AJ31: =AJ22/AJ$26 -> 0.1103168
B32: =B23&"(%)" -> Entertainment (%) | C32: =C23/C$26 -> 0.059512352 | D32: =D23/D$26 -> 0.065147476 | E32: =E23/E$26 -> 0.063271575 | F32: =F23/F$26 -> 0.065942373 | G32: =G23/G$26 -> 0.077395747 | H32: =H23/H$26 -> 0.070025043 | J32: =J23/J$26 -> 0.059171598 | K32: =K23/K$26 -> 0.054119469 | L32: =L23/L$26 -> 0.051572683 | M32: =M23/M$26 -> 0.089446895 | N32: =N23/N$26 -> 0.068765184 | O32: =O23/O$26 -> 0.061984765 | P32: =P23/P$26 -> 0.066420664 | Q32: =Q23/Q$26 -> 0.1003687 | ... X32: =X23/X$26 -> 0.061724566 | Z32: =Z23/Z$26 -> 0.068132453 | AA32: =AA23/AA$26 -> 0.070066709 | AB32: =AB23/AB$26 -> 0.073746584 | AC32: =AC23/AC$26 -> 0.077395747 | AD32: =AD23/AD$26 -> 0.076531565 | AE32: =AE23/AE$26 -> 0.075722312 | AF32: =AF23/AF$26 -> 0.073390802 | AG32: =AG23/AG$26 -> 0.070025043 | ... AJ32: =AJ23/AJ$26 -> 0.074500897
B33: =B24&"(%)" -> Services (%) | C33: =C24/C$26 -> 0.053279252 | D33: =D24/D$26 -> 0.047649274 | E33: =E24/E$26 -> 0.045980565 | F33: =F24/F$26 -> 0.050369346 | G33: =G24/G$26 -> 0.058225168 | H33: =H24/H$26 -> 0.063354845 | J33: =J24/J$26 -> 0.051000282 | K33: =K24/K$26 -> 0.053538581 | L33: =L24/L$26 -> 0.054406347 | M33: =M24/M$26 -> 0.044791313 | N33: =N24/N$26 -> 0.060526038 | O33: =O24/O$26 -> 0.061358656 | P33: =P24/P$26 -> 0.062320623 | Q33: =Q24/Q$26 -> 0.051959579 | ... X33: =X24/X$26 -> 0.065963606 | Z33: =Z24/Z$26 -> 0.052351611 | AA33: =AA24/AA$26 -> 0.054020554 | AB33: =AB24/AB$26 -> 0.0557865 | AC33: =AC24/AC$26 -> 0.058225168 | AD33: =AD24/AD$26 -> 0.060095256 | AE33: =AE24/AE$26 -> 0.061452383 | AF33: =AF24/AF$26 -> 0.062852271 | AG33: =AG24/AG$26 -> 0.063354845 | ... AJ33: =AJ24/AJ$26 -> 0.062450687
B34: =B25&"(%)" -> Other (%) | C34: =C25/C$26 -> 0.0049268986 | D34: =D25/D$26 -> 0.0041047776 | E34: =E25/E$26 -> 0.0049844478 | F34: =F25/F$26 -> 0.006846948 | G34: =G25/G$26 -> 0.0069962257 | H34: =H25/H$26 -> 0.0080186862 | J34: =J25/J$26 -> 0.0070442378 | K34: =K25/K$26 -> 0.009391035 | L34: =L25/L$26 -> 0.0082176254 | M34: =M25/M$26 -> 0.0039362063 | N34: =N25/N$26 -> 0.0068659554 | O34: =O25/O$26 -> 0.009391631 | P34: =P25/P$26 -> 0.0085075851 | Q34: =Q25/Q$26 -> 0.0045063499 | ... X34: =X25/X$26 -> 0.0069272126 | Z34: =Z25/Z$26 -> 0.0068043796 | AA34: =AA25/AA$26 -> 0.0067610205 | AB34: =AB25/AB$26 -> 0.0067981902 | AC34: =AC25/AC$26 -> 0.0069962257 | AD34: =AD25/AD$26 -> 0.0072375794 | AE34: =AE25/AE$26 -> 0.0074288267 | AF34: =AF25/AF$26 -> 0.0073414484 | AG34: =AG25/AG$26 -> 0.0080186862 | ... AJ34: =AJ25/AJ$26 -> 0.0076987448
A36: X | B36: Revenue by product category: Domestic
B37: Computing and Mobile Phones | C37: 17819 | D37: 19799 | E37: 20693 | F37: 18191 | G37: 16930 | H37: 17103 | J37: 4285 | K37: 3964 | L37: 4337 | M37: =SUM(F37-SUM(J37:L37)) -> 5605 | N37: 3688 | O37: 3674 | P37: 3938 | Q37: =SUM(G37-SUM(N37:P37)) -> 5630 | R37: 3588 | S37: 3792 | T37: 4065 | U37: =SUM(H37-SUM(R37:T37)) -> 5658 | V37: 3792 | W37: 3930 | X37: 4368 | Z37: =SUM(K37:N37) -> 17594 | AA37: =SUM(L37:O37) -> 17304 | AB37: =SUM(M37:P37) -> 16905 | AC37: =SUM(N37:Q37) -> 16930 | AD37: =SUM(O37:R37) -> 16830 | AE37: =SUM(P37:S37) -> 16948 | AF37: =SUM(Q37:T37) -> 17075 | AG37: =SUM(R37:U37) -> 17103 | ... AJ37: =SUM(U37:X37) -> 17748
B38: Consumer Electronics | C38: 13129 | D38: 13022 | E38: 15009 | F38: 13040 | G38: 12014 | H38: 11148 | J38: 2896 | K38: 2845 | L38: 2889 | M38: =SUM(F38-SUM(J38:L38)) -> 4410 | N38: 2592 | O38: 2658 | P38: 2589 | Q38: =SUM(G38-SUM(N38:P38)) -> 4175 | R38: 2364 | S38: 2478 | T38: 2425 | U38: =SUM(H38-SUM(R38:T38)) -> 3881 | V38: 2237 | W38: 2351 | X38: 2351 | Z38: =SUM(K38:N38) -> 12736 | AA38: =SUM(L38:O38) -> 12549 | AB38: =SUM(M38:P38) -> 12249 | AC38: =SUM(N38:Q38) -> 12014 | AD38: =SUM(O38:R38) -> 11786 | AE38: =SUM(P38:S38) -> 11606 | AF38: =SUM(Q38:T38) -> 11442 | AG38: =SUM(R38:U38) -> 11148 | ... AJ38: =SUM(U38:X38) -> 10820
B39: Appliances | C39: 4493 | D39: 5489 | E39: 6784 | F39: 6381 | G39: 5469 | H39: 4589 | J39: 1590 | K39: 1657 | L39: 1469 | M39: =SUM(F39-SUM(J39:L39)) -> 1665 | N39: 1339 | O39: 1384 | P39: 1238 | Q39: =SUM(G39-SUM(N39:P39)) -> 1508 | R39: 1090 | S39: 1177 | T39: 1057 | U39: =SUM(H39-SUM(R39:T39)) -> 1265 | V39: 1001 | W39: 1074 | X39: 965 | Z39: =SUM(K39:N39) -> 6130 | AA39: =SUM(L39:O39) -> 5857 | AB39: =SUM(M39:P39) -> 5626 | AC39: =SUM(N39:Q39) -> 5469 | AD39: =SUM(O39:R39) -> 5220 | AE39: =SUM(P39:S39) -> 5013 | AF39: =SUM(Q39:T39) -> 4832 | AG39: =SUM(R39:U39) -> 4589 | ... AJ39: =SUM(U39:X39) -> 4305
B40: Entertainment | C40: 2388 | D40: 2769 | E40: 2963 | F40: 2786 | G40: 3063 | H40: 2641 | J40: 573 | K40: 508 | L40: 500 | M40: =SUM(F40-SUM(J40:L40)) -> 1205 | N40: 591 | O40: 544 | P40: 594 | Q40: =SUM(G40-SUM(N40:P40)) -> 1334 | R40: 520 | S40: 498 | T40: 479 | U40: =SUM(H40-SUM(R40:T40)) -> 1144 | V40: 449 | W40: 681 | X40: 543 | Z40: =SUM(K40:N40) -> 2804 | AA40: =SUM(L40:O40) -> 2840 | AB40: =SUM(M40:P40) -> 2934 | AC40: =SUM(N40:Q40) -> 3063 | AD40: =SUM(O40:R40) -> 2992 | AE40: =SUM(P40:S40) -> 2946 | AF40: =SUM(Q40:T40) -> 2831 | AG40: =SUM(R40:U40) -> 2641 | ... AJ40: =SUM(U40:X40) -> 2817
B41: Services | C41: 2126 | D41: 2082 | E41: 2190 | F41: 2149 | G41: 2357 | H41: 2456 | J41: 489 | K41: 516 | L41: 533 | M41: =SUM(F41-SUM(J41:L41)) -> 611 | N41: 537 | O41: 550 | P41: 563 | Q41: =SUM(G41-SUM(N41:P41)) -> 707 | R41: 578 | S41: 590 | T41: 601 | U41: =SUM(H41-SUM(R41:T41)) -> 687 | V41: 579 | W41: 581 | X41: 591 | Z41: =SUM(K41:N41) -> 2197 | AA41: =SUM(L41:O41) -> 2231 | AB41: =SUM(M41:P41) -> 2261 | AC41: =SUM(N41:Q41) -> 2357 | AD41: =SUM(O41:R41) -> 2398 | AE41: =SUM(P41:S41) -> 2438 | AF41: =SUM(Q41:T41) -> 2476 | AG41: =SUM(R41:U41) -> 2456 | ... AJ41: =SUM(U41:X41) -> 2438
B42: Other | C42: 159 | D42: 132 | E42: 191 | F42: 247 | G42: 264 | H42: 301 | J42: 61 | K42: 79 | L42: 72 | M42: =SUM(F42-SUM(J42:L42)) -> 35 | N42: 54 | O42: 80 | P42: 74 | Q42: =SUM(G42-SUM(N42:P42)) -> 56 | R42: 63 | S42: 88 | T42: 70 | U42: =SUM(H42-SUM(R42:T42)) -> 80 | V42: 69 | W42: 81 | X42: 60 | Z42: =SUM(K42:N42) -> 240 | AA42: =SUM(L42:O42) -> 241 | AB42: =SUM(M42:P42) -> 243 | AC42: =SUM(N42:Q42) -> 264 | AD42: =SUM(O42:R42) -> 273 | AE42: =SUM(P42:S42) -> 281 | AF42: =SUM(Q42:T42) -> 277 | AG42: =SUM(R42:U42) -> 301 | ... AJ42: =SUM(U42:X42) -> 290
B43: Total Domestic Revenue | C43: =SUM(C37:C42) -> 40114 | D43: =SUM(D37:D42) -> 43293 | E43: =SUM(E37:E42) -> 47830 | F43: =SUM(F37:F42) -> 42794 | G43: =SUM(G37:G42) -> 40097 | H43: =SUM(H37:H42) -> 38238 | J43: =SUM(J37:J42) -> 9894 | K43: =SUM(K37:K42) -> 9569 | L43: =SUM(L37:L42) -> 9800 | M43: =SUM(M37:M42) -> 13531 | N43: =SUM(N37:N42) -> 8801 | O43: =SUM(O37:O42) -> 8890 | P43: =SUM(P37:P42) -> 8996 | Q43: =SUM(Q37:Q42) -> 13410 | ... X43: =SUM(X37:X42) -> 8878 | Z43: =SUM(Z37:Z42) -> 41701 | AA43: =SUM(AA37:AA42) -> 41022 | AB43: =SUM(AB37:AB42) -> 40218 | AC43: =SUM(AC37:AC42) -> 40097 | AD43: =SUM(AD37:AD42) -> 39499 | AE43: =SUM(AE37:AE42) -> 39232 | AF43: =SUM(AF37:AF42) -> 38933 | AG43: =SUM(AG37:AG42) -> 38238 | ... AJ43: =SUM(AJ37:AJ42) -> 38418
B44: Balance Check | C44: =+C43-C9 -> 0 | D44: =+D43-D9 -> 0 | E44: =+E43-E9 -> 0 | F44: =+F43-F9 -> 0 | G44: =+G43-G9 -> 0 | H44: =+H43-H9 -> 0 | J44: =+J43-J9 -> 0 | K44: =+K43-K9 -> 0 | L44: =+L43-L9 -> 0 | M44: =+M43-M9 -> 0 | N44: =+N43-N9 -> 0 | O44: =+O43-O9 -> 0 | P44: =+P43-P9 -> 0 | Q44: =+Q43-Q9 -> 0 | ... X44: =+X43-X9 -> 0 | Z44: =+Z43-Z9 -> 0 | AA44: =+AA43-AA9 -> 0 | AB44: =+AB43-AB9 -> 0 | AC44: =+AC43-AC9 -> 0 | AD44: =+AD43-AD9 -> 0 | AE44: =+AE43-AE9 -> 0 | AF44: =+AF43-AF9 -> 0 | AG44: =+AG43-AG9 -> 0 | ... AJ44: =+AJ43-AJ9 -> 0
B46: =B37&"(%)" -> Computing and Mobile Phones (%) | C46: =C37/C$43 -> 0.444209 | D46: =D37/D$43 -> 0.45732566 | E46: =E37/E$43 -> 0.43263642 | F46: =F37/F$43 -> 0.42508296 | G46: =G37/G$43 -> 0.4222261 | H46: =H37/H$43 -> 0.44727758 | J46: =J37/J$43 -> 0.43309076 | K46: =K37/K$43 -> 0.41425436 | L46: =L37/L$43 -> 0.44255102 | M46: =M37/M$43 -> 0.41423398 | N46: =N37/N$43 -> 0.41904329 | O46: =O37/O$43 -> 0.41327334 | P46: =P37/P$43 -> 0.43775011 | Q46: =Q37/Q$43 -> 0.41983594 | ... X46: =X37/X$43 -> 0.4920027 | Z46: =Z37/Z$43 -> 0.42190835 | AA46: =AA37/AA$43 -> 0.42182244 | AB46: =AB37/AB$43 -> 0.42033418 | AC46: =AC37/AC$43 -> 0.4222261 | AD46: =AD37/AD$43 -> 0.42608674 | AE46: =AE37/AE$43 -> 0.43199429 | AF46: =AF37/AF$43 -> 0.43857396 | AG46: =AG37/AG$43 -> 0.44727758 | ... AJ46: =AJ37/AJ$43 -> 0.46197095
B47: =B38&"(%)" -> Consumer Electronics (%) | C47: =C38/C$43 -> 0.32729222 | D47: =D38/D$43 -> 0.30078766 | E47: =E38/E$43 -> 0.31379887 | F47: =F38/F$43 -> 0.30471561 | G47: =G38/G$43 -> 0.29962341 | H47: =H38/H$43 -> 0.29154244 | J47: =J38/J$43 -> 0.29270265 | K47: =K38/K$43 -> 0.29731424 | L47: =L38/L$43 -> 0.29479592 | M47: =M38/M$43 -> 0.32591826 | N47: =N38/N$43 -> 0.29451199 | O47: =O38/O$43 -> 0.29898763 | P47: =P38/P$43 -> 0.28779458 | Q47: =Q38/Q$43 -> 0.31133482 | ... X47: =X38/X$43 -> 0.26481189 | Z47: =Z38/Z$43 -> 0.30541234 | AA47: =AA38/AA$43 -> 0.30590902 | AB47: =AB38/AB$43 -> 0.30456512 | AC47: =AC38/AC$43 -> 0.29962341 | AD47: =AD38/AD$43 -> 0.2983873 | AE47: =AE38/AE$43 -> 0.29582993 | AF47: =AF38/AF$43 -> 0.2938895 | AG47: =AG38/AG$43 -> 0.29154244 | ... AJ47: =AJ38/AJ$43 -> 0.28163882
B48: =B39&"(%)" -> Appliances (%) | C48: =C39/C$43 -> 0.11200578 | D48: =D39/D$43 -> 0.12678724 | E48: =E39/E$43 -> 0.14183567 | F48: =F39/F$43 -> 0.14910969 | G48: =G39/G$43 -> 0.13639424 | H48: =H39/H$43 -> 0.12001151 | J48: =J39/J$43 -> 0.16070346 | K48: =K39/K$43 -> 0.17316334 | L48: =L39/L$43 -> 0.14989796 | M48: =M39/M$43 -> 0.12305077 | N48: =N39/N$43 -> 0.1521418 | O48: =O39/O$43 -> 0.15568054 | P48: =P39/P$43 -> 0.13761672 | Q48: =Q39/Q$43 -> 0.11245339 | ... X48: =X39/X$43 -> 0.10869565 | Z48: =Z39/Z$43 -> 0.14699887 | AA48: =AA39/AA$43 -> 0.14277705 | AB48: =AB39/AB$43 -> 0.13988761 | AC48: =AC39/AC$43 -> 0.13639424 | AD48: =AD39/AD$43 -> 0.13215524 | AE48: =AE39/AE$43 -> 0.12777834 | AF48: =AF39/AF$43 -> 0.12411065 | AG48: =AG39/AG$43 -> 0.12001151 | ... AJ48: =AJ39/AJ$43 -> 0.11205685
B49: =B40&"(%)" -> Entertainment (%) | C49: =C40/C$43 -> 0.059530339 | D49: =D40/D$43 -> 0.063959532 | E49: =E40/E$43 -> 0.061948568 | F49: =F40/F$43 -> 0.065102584 | G49: =G40/G$43 -> 0.076389755 | H49: =H40/H$43 -> 0.06906742 | J49: =J40/J$43 -> 0.057913887 | K49: =K40/K$43 -> 0.053088097 | L49: =L40/L$43 -> 0.051020408 | M49: =M40/M$43 -> 0.089054763 | N49: =N40/N$43 -> 0.06715146 | O49: =O40/O$43 -> 0.061192351 | P49: =P40/P$43 -> 0.066029346 | Q49: =Q40/Q$43 -> 0.099478001 | ... X49: =X40/X$43 -> 0.061162424 | Z49: =Z40/Z$43 -> 0.067240594 | AA49: =AA40/AA$43 -> 0.069231144 | AB49: =AB40/AB$43 -> 0.072952409 | AC49: =AC40/AC$43 -> 0.076389755 | AD49: =AD40/AD$43 -> 0.075748753 | AE49: =AE40/AE$43 -> 0.075091762 | AF49: =AF40/AF$43 -> 0.072714664 | AG49: =AG40/AG$43 -> 0.06906742 | ... AJ49: =AJ40/AJ$43 -> 0.073325004
...

Sheet FCF
B2: ='Historical Financials'!B2 -> Best Buy Co Inc (NASDAQ: BBY) | F2: FYE | J2: Quarterly | T2: Quarterly | AE2: LTM | AF2: LTM | AL2: Variance
B3: FCF Analysis | C3: ='Historical Financials'!C7 -> 2020 | D3: ='Historical Financials'!D7 -> 2021 | E3: ='Historical Financials'!E7 -> 2022 | F3: ='Historical Financials'!F7 -> 2023 | G3: ='Historical Financials'!G7 -> 2024 | H3: ='Historical Financials'!H7 -> 2025 | J3: ='Historical Financials'!J7 -> 1Q23 | K3: ='Historical Financials'!K7 -> 2Q23 | L3: ='Historical Financials'!L7 -> 3Q23 | M3: ='Historical Financials'!M7 -> 4Q23 | N3: ='Historical Financials'!N7 -> 1Q24 | O3: ='Historical Financials'!O7 -> 2Q24 | P3: ='Historical Financials'!P7 -> 3Q24 | Q3: ='Historical Financials'!Q7 -> 4Q24 | ... X3: ='Historical Financials'!X7 -> 3Q26 | Z3: =N3 -> 1Q24 | AA3: =O3 -> 2Q24 | AB3: =P3 -> 3Q24 | AC3: =Q3 -> 4Q24 | AD3: =R3 -> 1Q25 | AE3: =S3 -> 2Q25 | AF3: =T3 -> 3Q25 | AG3: =U3 -> 4Q25 | ... AJ3: =X3 -> 3Q26
B4: ($ In Millions) | C4: ='Historical Financials'!C8 -> 43862 | D4: ='Historical Financials'!D8 -> 44226 | E4: ='Historical Financials'!E8 -> 44590 | F4: ='Historical Financials'!F8 -> 44954 | G4: ='Historical Financials'!G8 -> 45325 | H4: ='Historical Financials'!H8 -> 45689 | J4: ='Historical Financials'!J8 -> 44681 | K4: ='Historical Financials'!K8 -> 44772 | L4: ='Historical Financials'!L8 -> 44863 | M4: ='Historical Financials'!M8 -> 44954 | N4: ='Historical Financials'!N8 -> 45045 | O4: ='Historical Financials'!O8 -> 45136 | P4: ='Historical Financials'!P8 -> 45227 | Q4: ='Historical Financials'!Q8 -> 45325 | ... X4: ='Historical Financials'!X8 -> 45962 | Z4: =N4 -> 45045 | AA4: =O4 -> 45136 | AB4: =P4 -> 45227 | AC4: =Q4 -> 45325 | AD4: =R4 -> 45416 | AE4: =S4 -> 45507 | AF4: =T4 -> 45598 | AG4: =U4 -> 45689 | ... AJ4: =X4 -> 45962
B6: Computing and Mobile Phones | C6: ='Revenue Drivers'!C20 -> 19399 | D6: ='Revenue Drivers'!D20 -> 21653 | E6: ='Revenue Drivers'!E20 -> 22478 | F6: ='Revenue Drivers'!F20 -> 19766 | G6: ='Revenue Drivers'!G20 -> 18482 | H6: ='Revenue Drivers'!H20 -> 18681 | J6: ='Revenue Drivers'!J20 -> 4629 | K6: ='Revenue Drivers'!K20 -> 4291 | L6: ='Revenue Drivers'!L20 -> 4726 | M6: ='Revenue Drivers'!M20 -> 6120 | N6: ='Revenue Drivers'!N20 -> 4004 | O6: ='Revenue Drivers'!O20 -> 3983 | P6: ='Revenue Drivers'!P20 -> 4316 | Q6: ='Revenue Drivers'!Q20 -> 6179 | ... X6: ='Revenue Drivers'!X20 -> 4788 | Z6: =SUM(K6:N6) -> 19141 | AA6: =SUM(L6:O6) -> 18833 | AB6: =SUM(M6:P6) -> 18423 | AC6: =SUM(N6:Q6) -> 18482 | AD6: =SUM(O6:R6) -> 18384 | AE6: =SUM(P6:S6) -> 18501 | AF6: =SUM(Q6:T6) -> 18636 | AG6: =SUM(R6:U6) -> 18681 | ... AJ6: =SUM(U6:X6) -> 19404 | AL6: =SUM(AJ6/AF6)-1 -> 0.04121056
B7: Consumer Electronics | C7: ='Revenue Drivers'!C21 -> 14292 | D7: ='Revenue Drivers'!D21 -> 14211 | E7: ='Revenue Drivers'!E21 -> 16203 | F7: ='Revenue Drivers'!F21 -> 14094 | G7: ='Revenue Drivers'!G21 -> 12969 | H7: ='Revenue Drivers'!H21 -> 12065 | J7: ='Revenue Drivers'!J21 -> 3109 | K7: ='Revenue Drivers'!K21 -> 3068 | L7: ='Revenue Drivers'!L21 -> 3109 | M7: ='Revenue Drivers'!M21 -> 4808 | N7: ='Revenue Drivers'!N21 -> 2776 | O7: ='Revenue Drivers'!O21 -> 2852 | P7: ='Revenue Drivers'!P21 -> 2789 | Q7: ='Revenue Drivers'!Q21 -> 4552 | ... X7: ='Revenue Drivers'!X21 -> 2553 | Z7: =SUM(K7:N7) -> 13761 | AA7: =SUM(L7:O7) -> 13545 | AB7: =SUM(M7:P7) -> 13225 | AC7: =SUM(N7:Q7) -> 12969 | AD7: =SUM(O7:R7) -> 12730 | AE7: =SUM(P7:S7) -> 12542 | AF7: =SUM(Q7:T7) -> 12372 | AG7: =SUM(R7:U7) -> 12065 | ... AJ7: =SUM(U7:X7) -> 11757 | AL7: =SUM(AJ7/AF7)-1 -> -0.04970902
B8: Appliances | C8: ='Revenue Drivers'!C22 -> 4810 | D8: ='Revenue Drivers'!D22 -> 5873 | E8: ='Revenue Drivers'!E22 -> 7167 | F8: ='Revenue Drivers'!F22 -> 6736 | G8: ='Revenue Drivers'!G22 -> 5804 | H8: ='Revenue Drivers'!H22 -> 4910 | J8: ='Revenue Drivers'!J22 -> 1661 | K8: ='Revenue Drivers'!K22 -> 1761 | L8: ='Revenue Drivers'!L22 -> 1543 | M8: ='Revenue Drivers'!M22 -> 1771 | N8: ='Revenue Drivers'!N22 -> 1398 | O8: ='Revenue Drivers'!O22 -> 1476 | P8: ='Revenue Drivers'!P22 -> 1312 | Q8: ='Revenue Drivers'!Q22 -> 1618 | ... X8: ='Revenue Drivers'!X22 -> 1029 | Z8: =SUM(K8:N8) -> 6473 | AA8: =SUM(L8:O8) -> 6188 | AB8: =SUM(M8:P8) -> 5957 | AC8: =SUM(N8:Q8) -> 5804 | AD8: =SUM(O8:R8) -> 5556 | AE8: =SUM(P8:S8) -> 5343 | AF8: =SUM(Q8:T8) -> 5155 | AG8: =SUM(R8:U8) -> 4910 | ... AJ8: =SUM(U8:X8) -> 4614 | AL8: =SUM(AJ8/AF8)-1 -> -0.10494665
B9: Entertainment | C9: ='Revenue Drivers'!C23 -> 2597 | D9: ='Revenue Drivers'!D23 -> 3079 | E9: ='Revenue Drivers'!E23 -> 3275 | F9: ='Revenue Drivers'!F23 -> 3053 | G9: ='Revenue Drivers'!G23 -> 3363 | H9: ='Revenue Drivers'!H23 -> 2908 | J9: ='Revenue Drivers'!J23 -> 630 | K9: ='Revenue Drivers'!K23 -> 559 | L9: ='Revenue Drivers'!L23 -> 546 | M9: ='Revenue Drivers'!M23 -> 1318 | N9: ='Revenue Drivers'!N23 -> 651 | O9: ='Revenue Drivers'!O23 -> 594 | P9: ='Revenue Drivers'!P23 -> 648 | Q9: ='Revenue Drivers'!Q23 -> 1470 | ... X9: ='Revenue Drivers'!X23 -> 597 | Z9: =SUM(K9:N9) -> 3074 | AA9: =SUM(L9:O9) -> 3109 | AB9: =SUM(M9:P9) -> 3211 | AC9: =SUM(N9:Q9) -> 3363 | AD9: =SUM(O9:R9) -> 3278 | AE9: =SUM(P9:S9) -> 3221 | AF9: =SUM(Q9:T9) -> 3099 | AG9: =SUM(R9:U9) -> 2908 | ... AJ9: =SUM(U9:X9) -> 3116 | AL9: =SUM(AJ9/AF9)-1 -> 0.0054856405
B10: Services | C10: ='Revenue Drivers'!C24 -> 2325 | D10: ='Revenue Drivers'!D24 -> 2252 | E10: ='Revenue Drivers'!E24 -> 2380 | F10: ='Revenue Drivers'!F24 -> 2332 | G10: ='Revenue Drivers'!G24 -> 2530 | H10: ='Revenue Drivers'!H24 -> 2631 | J10: ='Revenue Drivers'!J24 -> 543 | K10: ='Revenue Drivers'!K24 -> 553 | L10: ='Revenue Drivers'!L24 -> 576 | M10: ='Revenue Drivers'!M24 -> 660 | N10: ='Revenue Drivers'!N24 -> 573 | O10: ='Revenue Drivers'!O24 -> 588 | P10: ='Revenue Drivers'!P24 -> 608 | Q10: ='Revenue Drivers'!Q24 -> 761 | ... X10: ='Revenue Drivers'!X24 -> 638 | Z10: =SUM(K10:N10) -> 2362 | AA10: =SUM(L10:O10) -> 2397 | AB10: =SUM(M10:P10) -> 2429 | AC10: =SUM(N10:Q10) -> 2530 | AD10: =SUM(O10:R10) -> 2574 | AE10: =SUM(P10:S10) -> 2614 | AF10: =SUM(Q10:T10) -> 2654 | AG10: =SUM(R10:U10) -> 2631 | ... AJ10: =SUM(U10:X10) -> 2612 | AL10: =SUM(AJ10/AF10)-1 -> -0.01582517
B11: Other | C11: ='Revenue Drivers'!C25 -> 215 | D11: ='Revenue Drivers'!D25 -> 194 | E11: ='Revenue Drivers'!E25 -> 258 | F11: ='Revenue Drivers'!F25 -> 317 | G11: ='Revenue Drivers'!G25 -> 304 | H11: ='Revenue Drivers'!H25 -> 333 | J11: ='Revenue Drivers'!J25 -> 75 | K11: ='Revenue Drivers'!K25 -> 97 | L11: ='Revenue Drivers'!L25 -> 87 | M11: ='Revenue Drivers'!M25 -> 58 | N11: ='Revenue Drivers'!N25 -> 65 | O11: ='Revenue Drivers'!O25 -> 90 | P11: ='Revenue Drivers'!P25 -> 83 | Q11: ='Revenue Drivers'!Q25 -> 66 | ... X11: ='Revenue Drivers'!X25 -> 67 | Z11: =SUM(K11:N11) -> 307 | AA11: =SUM(L11:O11) -> 300 | AB11: =SUM(M11:P11) -> 296 | AC11: =SUM(N11:Q11) -> 304 | AD11: =SUM(O11:R11) -> 310 | AE11: =SUM(P11:S11) -> 316 | AF11: =SUM(Q11:T11) -> 310 | AG11: =SUM(R11:U11) -> 333 | ... AJ11: =SUM(U11:X11) -> 322 | AL11: =SUM(AJ11/AF11)-1 -> 0.038709677
B12: Total Revenue | C12: =SUM(C6:C11) -> 43638 | D12: =SUM(D6:D11) -> 47262 | E12: =SUM(E6:E11) -> 51761 | F12: =SUM(F6:F11) -> 46298 | G12: =SUM(G6:G11) -> 43452 | H12: =SUM(H6:H11) -> 41528 | J12: =SUM(J6:J11) -> 10647 | K12: =SUM(K6:K11) -> 10329 | L12: =SUM(L6:L11) -> 10587 | M12: =SUM(M6:M11) -> 14735 | N12: =SUM(N6:N11) -> 9467 | O12: =SUM(O6:O11) -> 9583 | P12: =SUM(P6:P11) -> 9756 | Q12: =SUM(Q6:Q11) -> 14646 | ... X12: =SUM(X6:X11) -> 9672 | Z12: =SUM(Z6:Z11) -> 45118 | AA12: =SUM(AA6:AA11) -> 44372 | AB12: =SUM(AB6:AB11) -> 43541 | AC12: =SUM(AC6:AC11) -> 43452 | AD12: =SUM(AD6:AD11) -> 42832 | AE12: =SUM(AE6:AE11) -> 42537 | AF12: =SUM(AF6:AF11) -> 42226 | AG12: =SUM(AG6:AG11) -> 41528 | ... AJ12: =SUM(AJ6:AJ11) -> 41825 | AL12: =SUM(AJ12/AF12)-1 -> -0.0094965187
B13: Y/Y Growth (%) | D13: =SUM(D12/C12)-1 -> 0.083046886 | E13: =SUM(E12/D12)-1 -> 0.095192755 | F13: =SUM(F12/E12)-1 -> -0.10554278 | G13: =SUM(G12/F12)-1 -> -0.061471338 | H13: =SUM(H12/G12)-1 -> -0.044278744 | N13: =SUM(N12/J12)-1 -> -0.11082934 | O13: =SUM(O12/K12)-1 -> -0.072223836 | P13: =SUM(P12/L12)-1 -> -0.078492491 | Q13: =SUM(Q12/M12)-1 -> -0.0060400407 | R13: =SUM(R12/N12)-1 -> -0.065490652 | S13: =SUM(S12/O12)-1 -> -0.030783679 | T13: =SUM(T12/P12)-1 -> -0.031877819 | U13: =SUM(U12/Q12)-1 -> -0.047658064 | ... X13: =SUM(X12/T12)-1 -> 0.02403388 | AD13: =SUM(AD12/Z12)-1 -> -0.05066714 | AE13: =SUM(AE12/AA12)-1 -> -0.041354909 | AF13: =SUM(AF12/AB12)-1 -> -0.030201419 | AG13: =SUM(AG12/AC12)-1 -> -0.044278744 | AH13: =SUM(AH12/AD12)-1 -> -0.03231229 | AI13: =SUM(AI12/AE12)-1 -> -0.022074899 | AJ13: =SUM(AJ12/AF12)-1 -> -0.0094965187 | AL13: =SUM(AJ13-AF13)*10000 -> 207.04901
B14: Q/Q Growth (%) | C14: N/A | D14: N/A | E14: N/A | F14: N/A | G14: N/A | H14: N/A | K14: =SUM(K12/J12)-1 -> -0.029867568 | L14: =SUM(L12/K12)-1 -> 0.024978217 | M14: =SUM(M12/L12)-1 -> 0.39180127 | N14: =SUM(N12/M12)-1 -> -0.35751612 | O14: =SUM(O12/N12)-1 -> 0.01225309 | P14: =SUM(P12/O12)-1 -> 0.018052802 | Q14: =SUM(Q12/P12)-1 -> 0.50123001 | R14: =SUM(R12/Q12)-1 -> -0.39594429 | ... X14: =SUM(X12/W12)-1 -> 0.024793388 | Z14: N/A | AA14: N/A | AB14: N/A | AC14: N/A | AD14: N/A | AE14: N/A | AF14: N/A | AG14: N/A | AH14: N/A | AI14: N/A | AJ14: N/A
B16: (-) Cost of Sales | C16: ='Historical Financials'!C13 -> -33590 | D16: ='Historical Financials'!D13 -> -36689 | E16: ='Historical Financials'!E13 -> -40121 | F16: ='Historical Financials'!F13 -> -36386 | G16: ='Historical Financials'!G13 -> -33849 | H16: ='Historical Financials'!H13 -> -32143 | J16: ='Historical Financials'!J13 -> -8294 | K16: ='Historical Financials'!K13 -> -8042 | L16: ='Historical Financials'!L13 -> -8255 | M16: ='Historical Financials'!M13 -> -11795 | N16: ='Historical Financials'!N13 -> -7317 | O16: ='Historical Financials'!O13 -> -7363 | P16: ='Historical Financials'!P13 -> -7524 | Q16: ='Historical Financials'!Q13 -> -11645 | ... X16: ='Historical Financials'!X13 -> -7424 | Z16: =SUM(K16:N16) -> -35409 | AA16: =SUM(L16:O16) -> -34730 | AB16: =SUM(M16:P16) -> -33999 | AC16: =SUM(N16:Q16) -> -33849 | AD16: =SUM(O16:R16) -> -33315 | AE16: =SUM(P16:S16) -> -33054 | AF16: =SUM(Q16:T16) -> -32758 | AG16: =SUM(R16:U16) -> -32143 | ... AJ16: =SUM(U16:X16) -> -32416 | AL16: =SUM(AJ16/AF16)-1 -> -0.010440198
