Workbook

Sheet Base Financials
B2: Apple Inc. (NASDAQ: AAPL) | C2: FYE | D2: FYE | E2: FYE | F2: FYE | G2: FYE | I2: FYE | M2: Quarterly | S2: Quarterly | V2: Quarterly | W2: Quarterly | AI2: LTM | AO2: Variance
B3: Base Financials | C3: 2016 | D3: 2017 | E3: 2018 | F3: 2019 | G3: 2020 | H3: 2021 | I3: 2022 | J3: 2023 | K3: 2024 | M3: 1Q22 | N3: 2Q22 | O3: 3Q22 | P3: 4Q22 | Q3: 1Q23 | R3: 2Q23 | S3: 3Q23 | T3: 4Q23 | U3: 1Q24 | V3: 2Q24 | W3: 3Q24 | X3: 4Q24 | Y3: 1Q25 | Z3: 2Q25 | AA3: 3Q25 | AC3: =Q3 -> 1Q23 | AD3: =R3 -> 2Q23 | AE3: =S3 -> 3Q23 | AF3: =T3 -> 4Q23 | AG3: =U3 -> 1Q24 | AH3: =V3 -> 2Q24 | AI3: =W3 -> 3Q24 | AJ3: =X3 -> 4Q24 | ... AM3: =AA3 -> 3Q25
B4: ($ In Millions) | C4: 42643 | D4: 43008 | E4: 43372 | F4: 43737 | G4: 44104 | H4: 44469 | I4: 44834 | J4: 45192 | K4: 45559 | M4: 44560 | N4: 44650 | O4: 44742 | P4: =I4 -> 44834 | Q4: 44917 | R4: 45008 | S4: 45100 | T4: =J4 -> 45192 | U4: 45283 | V4: 45375 | W4: 45467 | X4: =K4 -> 45559 | Y4: 45650 | Z4: 45741 | AA4: 45833 | AC4: =Q4 -> 44917 | AD4: =R4 -> 45008 | AE4: =S4 -> 45100 | AF4: =T4 -> 45192 | AG4: =U4 -> 45283 | AH4: =V4 -> 45375 | AI4: =W4 -> 45467 | AJ4: =X4 -> 45559 | ... AM4: =AA4 -> 45833
A6: X | B6: Income Statement
B8: Consolidated Revenue | C8: 215639 | D8: 229234 | E8: 265595 | F8: 260174 | G8: 274515 | H8: 365817 | I8: 394328 | J8: 383285 | K8: 391035 | M8: 123945 | N8: 97278 | O8: 82959 | P8: =SUM(I8-SUM(M8:O8)) -> 90146 | Q8: 117154 | R8: 94836 | S8: 81797 | T8: =SUM(J8-SUM(Q8:S8)) -> 89498 | U8: 119575 | V8: 90753 | W8: 85777 | X8: =SUM(K8-SUM(U8:W8)) -> 94930 | Y8: 124300 | Z8: 95359 | AA8: 94036 | AC8: =SUM(N8:Q8) -> 387537 | AD8: =SUM(O8:R8) -> 385095 | AE8: =SUM(P8:S8) -> 383933 | AF8: =SUM(Q8:T8) -> 383285 | AG8: =SUM(R8:U8) -> 385706 | AH8: =SUM(S8:V8) -> 381623 | AI8: =SUM(T8:W8) -> 385603 | AJ8: =SUM(U8:X8) -> 391035 | ... AM8: =SUM(X8:AA8) -> 408625 | AO8: =SUM(AM8/AI8)-1 -> 0.059703892
B9: Total Revenue | C9: =+SUM(C8:C8) -> 215639 | D9: =+SUM(D8:D8) -> 229234 | E9: =+SUM(E8:E8) -> 265595 | F9: =+SUM(F8:F8) -> 260174 | G9: =+SUM(G8:G8) -> 274515 | H9: =+SUM(H8:H8) -> 365817 | I9: =+SUM(I8:I8) -> 394328 | J9: =+SUM(J8:J8) -> 383285 | K9: =+SUM(K8:K8) -> 391035 | M9: =+SUM(M8:M8) -> 123945 | N9: =+SUM(N8:N8) -> 97278 | O9: =+SUM(O8:O8) -> 82959 | P9: =+SUM(P8:P8) -> 90146 | Q9: =+SUM(Q8:Q8) -> 117154 | R9: =+SUM(R8:R8) -> 94836 | S9: =+SUM(S8:S8) -> 81797 | T9: =+SUM(T8:T8) -> 89498 | ... AA9: =+SUM(AA8:AA8) -> 94036 | AC9: =+SUM(AC8:AC8) -> 387537 | AD9: =+SUM(AD8:AD8) -> 385095 | AE9: =+SUM(AE8:AE8) -> 383933 | AF9: =+SUM(AF8:AF8) -> 383285 | AG9: =+SUM(AG8:AG8) -> 385706 | AH9: =+SUM(AH8:AH8) -> 381623 | AI9: =+SUM(AI8:AI8) -> 385603 | AJ9: =+SUM(AJ8:AJ8) -> 391035 | ... AM9: =+SUM(AM8:AM8) -> 408625 | AO9: =SUM(AM9/AI9)-1 -> 0.059703892
B11: Cost of Sales | C11: -131376 | D11: -141048 | E11: -163756 | F11: -161782 | G11: -169559 | H11: -212981 | I11: -223546 | J11: -214137 | K11: -210352 | M11: -69702 | N11: -54719 | O11: -47074 | P11: =SUM(I11-SUM(M11:O11)) -> -52051 | Q11: -66822 | R11: -52860 | S11: -45384 | T11: =SUM(J11-SUM(Q11:S11)) -> -49071 | U11: -64720 | V11: -48482 | W11: -46099 | X11: =SUM(K11-SUM(U11:W11)) -> -51051 | Y11: -66025 | Z11: -50492 | AA11: -50318 | AC11: =SUM(N11:Q11) -> -220666 | AD11: =SUM(O11:R11) -> -218807 | AE11: =SUM(P11:S11) -> -217117 | AF11: =SUM(Q11:T11) -> -214137 | AG11: =SUM(R11:U11) -> -212035 | AH11: =SUM(S11:V11) -> -207657 | AI11: =SUM(T11:W11) -> -208372 | AJ11: =SUM(U11:X11) -> -210352 | ... AM11: =SUM(X11:AA11) -> -217886 | AO11: =SUM(AM11/AI11)-1 -> 0.045658726
B12: Gross Profit | C12: =+SUM(C9+SUM(C11:C11)) -> 84263 | D12: =+SUM(D9+SUM(D11:D11)) -> 88186 | E12: =+SUM(E9+SUM(E11:E11)) -> 101839 | F12: =+SUM(F9+SUM(F11:F11)) -> 98392 | G12: =+SUM(G9+SUM(G11:G11)) -> 104956 | H12: =+SUM(H9+SUM(H11:H11)) -> 152836 | I12: =+SUM(I9+SUM(I11:I11)) -> 170782 | J12: =+SUM(J9+SUM(J11:J11)) -> 169148 | K12: =+SUM(K9+SUM(K11:K11)) -> 180683 | M12: =+SUM(M9+SUM(M11:M11)) -> 54243 | N12: =+SUM(N9+SUM(N11:N11)) -> 42559 | O12: =+SUM(O9+SUM(O11:O11)) -> 35885 | P12: =+SUM(P9+SUM(P11:P11)) -> 38095 | Q12: =+SUM(Q9+SUM(Q11:Q11)) -> 50332 | R12: =+SUM(R9+SUM(R11:R11)) -> 41976 | S12: =+SUM(S9+SUM(S11:S11)) -> 36413 | T12: =+SUM(T9+SUM(T11:T11)) -> 40427 | ... AA12: =+SUM(AA9+SUM(AA11:AA11)) -> 43718 | AC12: =+SUM(AC9+SUM(AC11:AC11)) -> 166871 | AD12: =+SUM(AD9+SUM(AD11:AD11)) -> 166288 | AE12: =+SUM(AE9+SUM(AE11:AE11)) -> 166816 | AF12: =+SUM(AF9+SUM(AF11:AF11)) -> 169148 | AG12: =+SUM(AG9+SUM(AG11:AG11)) -> 173671 | AH12: =+SUM(AH9+SUM(AH11:AH11)) -> 173966 | AI12: =+SUM(AI9+SUM(AI11:AI11)) -> 177231 | AJ12: =+SUM(AJ9+SUM(AJ11:AJ11)) -> 180683 | ... AM12: =+SUM(AM9+SUM(AM11:AM11)) -> 190739 | AO12: =SUM(AM12/AI12)-1 -> 0.076216915
B13: Gross Margin (%) | C13: =C12/C9 -> 0.39075956 | D13: =D12/D9 -> 0.3846986 | E13: =E12/E9 -> 0.38343719 | F13: =F12/F9 -> 0.37817768 | G13: =G12/G9 -> 0.38233248 | H13: =H12/H9 -> 0.4177936 | I13: =I12/I9 -> 0.43309631 | J13: =J12/J9 -> 0.4413113 | K13: =K12/K9 -> 0.4620635 | M13: =M12/M9 -> 0.43763766 | N13: =N12/N9 -> 0.43749872 | O13: =O12/O9 -> 0.43256307 | P13: =P12/P9 -> 0.42259224 | Q13: =Q12/Q9 -> 0.42962255 | R13: =R12/R9 -> 0.44261673 | S13: =S12/S9 -> 0.44516303 | T13: =T12/T9 -> 0.45170842 | ... AA13: =AA12/AA9 -> 0.46490706 | AC13: =AC12/AC9 -> 0.43059372 | AD13: =AD12/AD9 -> 0.43181033 | AE13: =AE12/AE9 -> 0.43449248 | AF13: =AF12/AF9 -> 0.4413113 | AG13: =AG12/AG9 -> 0.45026782 | AH13: =AH12/AH9 -> 0.45585827 | AI13: =AI12/AI9 -> 0.45962039 | AJ13: =AJ12/AJ9 -> 0.4620635 | ... AM13: =AM12/AM9 -> 0.4667825 | AO13: =SUM(AM13-AI13)*1000 -> 7.1621155
B15: Research & Development | C15: -10045 | D15: -11581 | E15: -14236 | F15: -16217 | G15: -18752 | H15: -21914 | I15: -26251 | J15: -29915 | K15: -31370 | M15: -6306 | N15: -6387 | O15: -6797 | P15: =SUM(I15-SUM(M15:O15)) -> -6761 | Q15: -7709 | R15: -7457 | S15: -7442 | T15: =SUM(J15-SUM(Q15:S15)) -> -7307 | U15: -7696 | V15: -7903 | W15: -8006 | X15: =SUM(K15-SUM(U15:W15)) -> -7765 | Y15: -8268 | Z15: -8550 | AA15: -8866 | AC15: =SUM(N15:Q15) -> -27654 | AD15: =SUM(O15:R15) -> -28724 | AE15: =SUM(P15:S15) -> -29369 | AF15: =SUM(Q15:T15) -> -29915 | AG15: =SUM(R15:U15) -> -29902 | AH15: =SUM(S15:V15) -> -30348 | AI15: =SUM(T15:W15) -> -30912 | AJ15: =SUM(U15:X15) -> -31370 | ... AM15: =SUM(X15:AA15) -> -33449 | AO15: =SUM(AM15/AI15)-1 -> 0.082071687
B16: Selling, General & Administrative | C16: -14194 | D16: -15261 | E16: -16705 | F16: -18245 | G16: -19916 | H16: -21973 | I16: -25094 | J16: -24932 | K16: -26097 | M16: -6449 | N16: -6193 | O16: -6012 | P16: =SUM(I16-SUM(M16:O16)) -> -6440 | Q16: -6607 | R16: -6201 | S16: -5973 | T16: =SUM(J16-SUM(Q16:S16)) -> -6151 | U16: -6786 | V16: -6468 | W16: -6320 | X16: =SUM(K16-SUM(U16:W16)) -> -6523 | Y16: -7175 | Z16: -6728 | AA16: -6650 | AC16: =SUM(N16:Q16) -> -25252 | AD16: =SUM(O16:R16) -> -25260 | AE16: =SUM(P16:S16) -> -25221 | AF16: =SUM(Q16:T16) -> -24932 | AG16: =SUM(R16:U16) -> -25111 | AH16: =SUM(S16:V16) -> -25378 | AI16: =SUM(T16:W16) -> -25725 | AJ16: =SUM(U16:X16) -> -26097 | ... AM16: =SUM(X16:AA16) -> -27076 | AO16: =SUM(AM16/AI16)-1 -> 0.052517007
B17: Profit From Operations | C17: =SUM(C12+SUM(C15:C16)) -> 60024 | D17: =SUM(D12+SUM(D15:D16)) -> 61344 | E17: =SUM(E12+SUM(E15:E16)) -> 70898 | F17: =SUM(F12+SUM(F15:F16)) -> 63930 | G17: =SUM(G12+SUM(G15:G16)) -> 66288 | H17: =SUM(H12+SUM(H15:H16)) -> 108949 | I17: =SUM(I12+SUM(I15:I16)) -> 119437 | J17: =SUM(J12+SUM(J15:J16)) -> 114301 | K17: =SUM(K12+SUM(K15:K16)) -> 123216 | M17: =SUM(M12+SUM(M15:M16)) -> 41488 | N17: =SUM(N12+SUM(N15:N16)) -> 29979 | O17: =SUM(O12+SUM(O15:O16)) -> 23076 | P17: =SUM(P12+SUM(P15:P16)) -> 24894 | Q17: =SUM(Q12+SUM(Q15:Q16)) -> 36016 | R17: =SUM(R12+SUM(R15:R16)) -> 28318 | S17: =SUM(S12+SUM(S15:S16)) -> 22998 | T17: =SUM(T12+SUM(T15:T16)) -> 26969 | ... AA17: =SUM(AA12+SUM(AA15:AA16)) -> 28202 | AC17: =SUM(AC12+SUM(AC15:AC16)) -> 113965 | AD17: =SUM(AD12+SUM(AD15:AD16)) -> 112304 | AE17: =SUM(AE12+SUM(AE15:AE16)) -> 112226 | AF17: =SUM(AF12+SUM(AF15:AF16)) -> 114301 | AG17: =SUM(AG12+SUM(AG15:AG16)) -> 118658 | AH17: =SUM(AH12+SUM(AH15:AH16)) -> 118240 | AI17: =SUM(AI12+SUM(AI15:AI16)) -> 120594 | AJ17: =SUM(AJ12+SUM(AJ15:AJ16)) -> 123216 | ... AM17: =SUM(AM12+SUM(AM15:AM16)) -> 130214 | AO17: =SUM(AM17/AI17)-1 -> 0.079771796
B18: Operating Margin (%) | C18: =C17/C9 -> 0.2783541 | D18: =D17/D9 -> 0.26760428 | E18: =E17/E9 -> 0.26694027 | F18: =F17/F9 -> 0.24572017 | G18: =G17/G9 -> 0.24147314 | H18: =H17/H9 -> 0.29782378 | I18: =I17/I9 -> 0.30288744 | J18: =J17/J9 -> 0.29821412 | K18: =K17/K9 -> 0.31510223 | M18: =M17/M9 -> 0.33472911 | N18: =N17/N9 -> 0.30817862 | O18: =O17/O9 -> 0.2781615 | P18: =P17/P9 -> 0.27615202 | Q18: =Q17/Q9 -> 0.30742442 | R18: =R17/R9 -> 0.29859969 | S18: =S17/S9 -> 0.28115946 | T18: =T17/T9 -> 0.30133634 | ... AA18: =AA17/AA9 -> 0.29990642 | AC18: =AC17/AC9 -> 0.29407515 | AD18: =AD17/AD9 -> 0.29162674 | AE18: =AE17/AE9 -> 0.29230621 | AF18: =AF17/AF9 -> 0.29821412 | AG18: =AG17/AG9 -> 0.30763846 | AH18: =AH17/AH9 -> 0.30983457 | AI18: =AI17/AI9 -> 0.31274134 | AJ18: =AJ17/AJ9 -> 0.31510223 | ... AM18: =AM17/AM9 -> 0.31866381 | AO18: =SUM(AM18-AI18)*1000 -> 5.9224688
B20: Other income/(expense), net | C20: 1348 | D20: 2745 | E20: 2005 | F20: 1807 | G20: 803 | H20: 258 | I20: -334 | J20: -565 | K20: 269 | M20: -247 | N20: 160 | O20: -10 | P20: =SUM(I20-SUM(M20:O20)) -> -237 | Q20: -393 | R20: 64 | S20: -265 | T20: =SUM(J20-SUM(Q20:S20)) -> 29 | U20: -50 | V20: 158 | W20: 142 | X20: =SUM(K20-SUM(U20:W20)) -> 19 | Y20: -248 | Z20: -279 | AA20: -171 | AC20: =SUM(N20:Q20) -> -480 | AD20: =SUM(O20:R20) -> -576 | AE20: =SUM(P20:S20) -> -831 | AF20: =SUM(Q20:T20) -> -565 | AG20: =SUM(R20:U20) -> -222 | AH20: =SUM(S20:V20) -> -128 | AI20: =SUM(T20:W20) -> 279 | AJ20: =SUM(U20:X20) -> 269 | ... AM20: =SUM(X20:AA20) -> -679 | AO20: =SUM(AM20/AI20)-1 -> -3.4336918
B21: Net loss before provision for income taxes | C21: =SUM(C20:C20)+C17 -> 61372 | D21: =SUM(D20:D20)+D17 -> 64089 | E21: =SUM(E20:E20)+E17 -> 72903 | F21: =SUM(F20:F20)+F17 -> 65737 | G21: =SUM(G20:G20)+G17 -> 67091 | H21: =SUM(H20:H20)+H17 -> 109207 | I21: =SUM(I20:I20)+I17 -> 119103 | J21: =SUM(J20:J20)+J17 -> 113736 | K21: =SUM(K20:K20)+K17 -> 123485 | M21: =SUM(M20:M20)+M17 -> 41241 | N21: =SUM(N20:N20)+N17 -> 30139 | O21: =SUM(O20:O20)+O17 -> 23066 | P21: =SUM(P20:P20)+P17 -> 24657 | Q21: =SUM(Q20:Q20)+Q17 -> 35623 | R21: =SUM(R20:R20)+R17 -> 28382 | S21: =SUM(S20:S20)+S17 -> 22733 | T21: =SUM(T20:T20)+T17 -> 26998 | ... AA21: =SUM(AA20:AA20)+AA17 -> 28031 | AC21: =SUM(AC20:AC20)+AC17 -> 113485 | AD21: =SUM(AD20:AD20)+AD17 -> 111728 | AE21: =SUM(AE20:AE20)+AE17 -> 111395 | AF21: =SUM(AF20:AF20)+AF17 -> 113736 | AG21: =SUM(AG20:AG20)+AG17 -> 118436 | AH21: =SUM(AH20:AH20)+AH17 -> 118112 | AI21: =SUM(AI20:AI20)+AI17 -> 120873 | AJ21: =SUM(AJ20:AJ20)+AJ17 -> 123485 | ... AM21: =SUM(AM20:AM20)+AM17 -> 129535 | AO21: =SUM(AM21/AI21)-1 -> 0.071661992
B23: Provision for taxes | C23: -15685 | D23: -15738 | E23: -13372 | F23: -10481 | G23: -9680 | H23: -14527 | I23: -19300 | J23: -16741 | K23: -29749 | M23: -6611 | N23: -5129 | O23: -3624 | P23: =SUM(I23-SUM(M23:O23)) -> -3936 | Q23: -5625 | R23: -4222 | S23: -2852 | T23: =SUM(J23-SUM(Q23:S23)) -> -4042 | U23: -6407 | V23: -4422 | W23: -4046 | X23: =SUM(K23-SUM(U23:W23)) -> -14874 | Y23: -6254 | Z23: -4530 | AA23: -4597 | AC23: =SUM(N23:Q23) -> -18314 | AD23: =SUM(O23:R23) -> -17407 | AE23: =SUM(P23:S23) -> -16635 | AF23: =SUM(Q23:T23) -> -16741 | AG23: =SUM(R23:U23) -> -17523 | AH23: =SUM(S23:V23) -> -17723 | AI23: =SUM(T23:W23) -> -18917 | AJ23: =SUM(U23:X23) -> -29749 | ... AM23: =SUM(X23:AA23) -> -30255 | AO23: =SUM(AM23/AI23)-1 -> 0.59935508
B24: Net loss | C24: =SUM(C21+C23) -> 45687 | D24: =SUM(D21+D23) -> 48351 | E24: =SUM(E21+E23) -> 59531 | F24: =SUM(F21+F23) -> 55256 | G24: =SUM(G21+G23) -> 57411 | H24: =SUM(H21+H23) -> 94680 | I24: =SUM(I21+I23) -> 99803 | J24: =SUM(J21+J23) -> 96995 | K24: =SUM(K21+K23) -> 93736 | M24: =SUM(M21+M23) -> 34630 | N24: =SUM(N21+N23) -> 25010 | O24: =SUM(O21+O23) -> 19442 | P24: =SUM(P21+P23) -> 20721 | Q24: =SUM(Q21+Q23) -> 29998 | R24: =SUM(R21+R23) -> 24160 | S24: =SUM(S21+S23) -> 19881 | T24: =SUM(T21+T23) -> 22956 | ... AA24: =SUM(AA21+AA23) -> 23434 | AC24: =SUM(AC21+AC23) -> 95171 | AD24: =SUM(AD21+AD23) -> 94321 | AE24: =SUM(AE21+AE23) -> 94760 | AF24: =SUM(AF21+AF23) -> 96995 | AG24: =SUM(AG21+AG23) -> 100913 | AH24: =SUM(AH21+AH23) -> 100389 | AI24: =SUM(AI21+AI23) -> 101956 | AJ24: =SUM(AJ21+AJ23) -> 93736 | ... AM24: =SUM(AM21+AM23) -> 99280 | AO24: =SUM(AM24/AI24)-1 -> -0.026246616
B25: Net Margin (%) | C25: =C24/C9 -> 0.21186798 | D25: =D24/D9 -> 0.21092421 | E25: =E24/E9 -> 0.22414202 | F25: =F24/F9 -> 0.21238095 | G25: =G24/G9 -> 0.20913611 | H25: =H24/H9 -> 0.25881793 | I25: =I24/I9 -> 0.25309641 | J25: =J24/J9 -> 0.25306234 | K25: =K24/K9 -> 0.23971256 | M25: =M24/M9 -> 0.27939812 | N25: =N24/N9 -> 0.25709821 | O25: =O24/O9 -> 0.23435673 | P25: =P24/P9 -> 0.22986045 | Q25: =Q24/Q9 -> 0.25605613 | R25: =R24/R9 -> 0.25475558 | S25: =S24/S9 -> 0.24305292 | T25: =T24/T9 -> 0.25649735 | ... AA25: =AA24/AA9 -> 0.24920243 | AC25: =AC24/AC9 -> 0.24557913 | AD25: =AD24/AD9 -> 0.24492917 | AE25: =AE24/AE9 -> 0.2468139 | AF25: =AF24/AF9 -> 0.25306234 | AG25: =AG24/AG9 -> 0.26163192 | AH25: =AH24/AH9 -> 0.26305804 | AI25: =AI24/AI9 -> 0.26440666 | AJ25: =AJ24/AJ9 -> 0.23971256 | ... AM25: =AM24/AM9 -> 0.24296115 | AO25: =SUM(AM25-AI25)*1000 -> -21.445506
B27: Basic shares | C27: 21883.281 | D27: 20868.968 | E27: 19821.51 | F27: 18471.336 | G27: 17352.119 | H27: 16701.272 | I27: 16215.963 | J27: 15744.231 | K27: 15343.783 | M27: 16391.724 | N27: 16278.802 | O27: 16162.945 | P27: =I27 -> 16215.963 | Q27: 15892.723 | R27: 15787.154 | S27: 15697.614 | T27: =J27 -> 15744.231 | U27: 15509.763 | V27: 15405.856 | W27: 15287.521 | X27: =K27 -> 15343.783 | Y27: 15081.724 | Z27: 14994.082 | AA27: 14902.886 | AC27: =Q27 -> 15892.723 | AD27: =R27 -> 15787.154 | AE27: =S27 -> 15697.614 | AF27: =T27 -> 15744.231 | AG27: =U27 -> 15509.763 | AH27: =V27 -> 15405.856 | AI27: =W27 -> 15287.521 | AJ27: =X27 -> 15343.783 | ... AM27: =AA27 -> 14902.886
B28: Basic EPS | C28: =C24/C27 -> 2.0877582 | D28: =D24/D27 -> 2.3168851 | E28: =E24/E27 -> 3.0033534 | F28: =F24/F27 -> 2.9914458 | G28: =G24/G27 -> 3.3085873 | H28: =H24/H27 -> 5.6690293 | I28: =I24/I27 -> 6.1546144 | J28: =J24/J27 -> 6.1606693 | K28: =K24/K27 -> 6.1090541 | M28: =M24/M27 -> 2.1126515 | N28: =N24/N27 -> 1.5363538 | O28: =O24/O27 -> 1.2028748 | P28: =P24/P27 -> 1.277815 | Q28: =Q24/Q27 -> 1.8875305 | R28: =R24/R27 -> 1.5303582 | S28: =S24/S27 -> 1.2664982 | T28: =T24/T27 -> 1.4580579 | ... AA28: =AA24/AA27 -> 1.5724471 | AC28: =AC24/AC27 -> 5.9883382 | AD28: =AD24/AD27 -> 5.9745411 | AE28: =AE24/AE27 -> 6.0365862 | AF28: =AF24/AF27 -> 6.1606693 | AG28: =AG24/AG27 -> 6.5064179 | AH28: =AH24/AH27 -> 6.5162884 | AI28: =AI24/AI27 -> 6.6692304 | AJ28: =AJ24/AJ27 -> 6.1090541 | ... AM28: =AM24/AM27 -> 6.6617969 | AO28: =SUM(AM28/AI28)-1 -> -0.0011145959
B30: Fully Diluted Shares | C30: 22001.127 | D30: 21006.767 | E30: 20000.436 | F30: 18595.651 | G30: 17528.214 | H30: 16864.919 | I30: 16325.819 | J30: 15812.547 | K30: 15408.095 | M30: 16519.291 | N30: 16403.316 | O30: 16262.203 | P30: =I30 -> 16325.819 | Q30: 15955.718 | R30: 15847.05 | S30: 15775.021 | T30: =J30 -> 15812.547 | U30: 15576.641 | V30: 15464.709 | W30: 15348.175 | X30: =K30 -> 15408.095 | Y30: 15150.865 | Z30: 15056.133 | AA30: 14948.179 | AC30: =Q30 -> 15955.718 | AD30: =R30 -> 15847.05 | AE30: =S30 -> 15775.021 | AF30: =T30 -> 15812.547 | AG30: =U30 -> 15576.641 | AH30: =V30 -> 15464.709 | AI30: =W30 -> 15348.175 | AJ30: =X30 -> 15408.095 | ... AM30: =AA30 -> 14948.179
B31: Diluted EPS | C31: =C24/C30 -> 2.0765754 | D31: =D24/D30 -> 2.3016869 | E31: =E24/E30 -> 2.9764851 | F31: =F24/F30 -> 2.9714475 | G31: =G24/G30 -> 3.275348 | H31: =H24/H30 -> 5.6140204 | I31: =I24/I30 -> 6.1132002 | J31: =J24/J30 -> 6.1340529 | K31: =K24/K30 -> 6.0835554 | M31: =M24/M30 -> 2.0963369 | N31: =N24/N30 -> 1.5246917 | O31: =O24/O30 -> 1.195533 | P31: =P24/P30 -> 1.2692166 | Q31: =Q24/Q30 -> 1.8800784 | R31: =R24/R30 -> 1.524574 | S31: =S24/S30 -> 1.2602836 | T31: =T24/T30 -> 1.4517585 | ... AA31: =AA24/AA30 -> 1.5676826 | AC31: =AC24/AC30 -> 5.9646955 | AD31: =AD24/AD30 -> 5.9519595 | AE31: =AE24/AE30 -> 6.0069651 | AF31: =AF24/AF30 -> 6.1340529 | AG31: =AG24/AG30 -> 6.4784827 | AH31: =AH24/AH30 -> 6.4914898 | AI31: =AI24/AI30 -> 6.6428745 | AJ31: =AJ24/AJ30 -> 6.0835554 | ... AM31: =AM24/AM30 -> 6.6416117 | AO31: =SUM(AM31/AI31)-1 -> -0.00019010064
A33: X | B33: Balance Sheet Statement
B35: Cash/Equivalents | C35: 20484 | D35: 20289 | E35: 25913 | F35: 48844 | G35: 38016 | H35: 34940 | I35: 23646 | J35: 29965 | K35: 29943 | M35: 37119 | N35: 28098 | O35: 27502 | P35: =I35 -> 23646 | Q35: 20535 | R35: 24687 | S35: 28408 | T35: =J35 -> 29965 | U35: 40760 | V35: 32695 | W35: 25565 | X35: =K35 -> 29943 | Y35: 30299 | Z35: 28162 | AA35: 36269 | AC35: =Q35 -> 20535 | AD35: =R35 -> 24687 | AE35: =S35 -> 28408 | AF35: =T35 -> 29965 | AG35: =U35 -> 40760 | AH35: =V35 -> 32695 | AI35: =W35 -> 25565 | AJ35: =X35 -> 29943 | ... AM35: =AA35 -> 36269 | AO35: =SUM(AM35/AI35)-1 -> 0.41869744
B36: Marketable Securities, Current | C36: 46671 | D36: 53892 | E36: 40388 | F36: 51713 | G36: 52927 | H36: 27699 | I36: 24658 | J36: 31590 | K36: 35228 | M36: 26794 | N36: 23413 | O36: 20729 | P36: =I36 -> 24658 | Q36: 30820 | R36: 31185 | S36: 34074 | T36: =J36 -> 31590 | U36: 32340 | V36: 34455 | W36: 36236 | X36: =K36 -> 35228 | Y36: 23476 | Z36: 20336 | AA36: 19103 | AC36: =Q36 -> 30820 | AD36: =R36 -> 31185 | AE36: =S36 -> 34074 | AF36: =T36 -> 31590 | AG36: =U36 -> 32340 | AH36: =V36 -> 34455 | AI36: =W36 -> 36236 | AJ36: =X36 -> 35228 | ... AM36: =AA36 -> 19103 | AO36: =SUM(AM36/AI36)-1 -> -0.47281709
B37: Accounts Receivable | C37: 15754 | D37: 17874 | E37: 23186 | F37: 22926 | G37: 16120 | H37: 26278 | I37: 28184 | J37: 29508 | K37: 66243 | M37: 30213 | N37: 20815 | O37: 21803 | P37: =I37 -> 28184 | Q37: 23752 | R37: 17936 | S37: 19549 | T37: =J37 -> 29508 | U37: 23194 | V37: 21837 | W37: 22795 | X37: =K37 -> 66243 | Y37: 29639 | Z37: 49798 | AA37: 46835 | AC37: =Q37 -> 23752 | AD37: =R37 -> 17936 | AE37: =S37 -> 19549 | AF37: =T37 -> 29508 | AG37: =U37 -> 23194 | AH37: =V37 -> 21837 | AI37: =W37 -> 22795 | AJ37: =X37 -> 66243 | ... AM37: =AA37 -> 46835 | AO37: =SUM(AM37/AI37)-1 -> 1.0546172
B38: Inventory | C38: 2132 | D38: 4855 | E38: 3956 | F38: 4106 | G38: 4061 | H38: 6580 | I38: 4946 | J38: 6331 | K38: 7286 | M38: 5876 | N38: 5460 | O38: 5433 | P38: =I38 -> 4946 | Q38: 6820 | R38: 7482 | S38: 7351 | T38: =J38 -> 6331 | U38: 6511 | V38: 6232 | W38: 6165 | X38: =K38 -> 7286 | Y38: 6911 | Z38: 6269 | AA38: 5925 | AC38: =Q38 -> 6820 | AD38: =R38 -> 7482 | AE38: =S38 -> 7351 | AF38: =T38 -> 6331 | AG38: =U38 -> 6511 | AH38: =V38 -> 6232 | AI38: =W38 -> 6165 | AJ38: =X38 -> 7286 | ... AM38: =AA38 -> 5925 | AO38: =SUM(AM38/AI38)-1 -> -0.03892944
B39: Other Current Assets | C39: 21828 | D39: =13936+17799 -> 31735 | E39: 37896 | F39: 35230 | G39: 32589 | H39: 39339 | I39: 53971 | J39: 46172 | K39: 14287 | M39: 53152 | N39: 40394 | O39: 36825 | P39: =I39 -> 53971 | Q39: 46850 | R39: 31623 | S39: 33277 | T39: =J39 -> 46172 | U39: 40887 | V39: 33197 | W39: 34674 | X39: =K39 -> 14287 | Y39: 42915 | Z39: 14109 | AA39: 14359 | AC39: =Q39 -> 46850 | AD39: =R39 -> 31623 | AE39: =S39 -> 33277 | AF39: =T39 -> 46172 | AG39: =U39 -> 40887 | AH39: =V39 -> 33197 | AI39: =W39 -> 34674 | AJ39: =X39 -> 14287 | ... AM39: =AA39 -> 14359 | AO39: =SUM(AM39/AI39)-1 -> -0.58588568
B40: Total Current Assets | C40: =SUM(C35:C39) -> 106869 | D40: =SUM(D35:D39) -> 128645 | E40: =SUM(E35:E39) -> 131339 | F40: =SUM(F35:F39) -> 162819 | G40: =SUM(G35:G39) -> 143713 | H40: =SUM(H35:H39) -> 134836 | I40: =SUM(I35:I39) -> 135405 | J40: =SUM(J35:J39) -> 143566 | K40: =SUM(K35:K39) -> 152987 | M40: =SUM(M35:M39) -> 153154 | N40: =SUM(N35:N39) -> 118180 | O40: =SUM(O35:O39) -> 112292 | P40: =SUM(P35:P39) -> 135405 | Q40: =SUM(Q35:Q39) -> 128777 | R40: =SUM(R35:R39) -> 112913 | S40: =SUM(S35:S39) -> 122659 | T40: =SUM(T35:T39) -> 143566 | ... AA40: =SUM(AA35:AA39) -> 122491 | AC40: =SUM(AC35:AC39) -> 128777 | AD40: =SUM(AD35:AD39) -> 112913 | AE40: =SUM(AE35:AE39) -> 122659 | AF40: =SUM(AF35:AF39) -> 143566 | AG40: =SUM(AG35:AG39) -> 143692 | AH40: =SUM(AH35:AH39) -> 128416 | AI40: =SUM(AI35:AI39) -> 125435 | AJ40: =SUM(AJ35:AJ39) -> 152987 | ... AM40: =SUM(AM35:AM39) -> 122491 | AO40: =SUM(AM40/AI40)-1 -> -0.023470323
B42: PP&E | C42: 27010 | D42: 33783 | E42: 41304 | F42: 37378 | G42: 36766 | H42: 39440 | I42: 42117 | J42: 43715 | K42: 45680 | M42: 39245 | N42: 39304 | O42: 40335 | P42: =I42 -> 42117 | Q42: 42951 | R42: 43398 | S42: 43550 | T42: =J42 -> 43715 | U42: 43666 | V42: 43546 | W42: 44502 | X42: =K42 -> 45680 | Y42: 46069 | Z42: 46876 | AA42: 48508 | AC42: =Q42 -> 42951 | AD42: =R42 -> 43398 | AE42: =S42 -> 43550 | AF42: =T42 -> 43715 | AG42: =U42 -> 43666 | AH42: =V42 -> 43546 | AI42: =W42 -> 44502 | AJ42: =X42 -> 45680 | ... AM42: =AA42 -> 48508 | AO42: =SUM(AM42/AI42)-1 -> 0.090018426
B43: Marketable Securities, Net of Current Portion | C43: 170430 | D43: 194714 | E43: 170799 | F43: 105341 | G43: 100887 | H43: 127877 | I43: 120805 | J43: 100544 | K43: 91479 | M43: 138683 | N43: 141219 | O43: 131077 | P43: =I43 -> 120805 | Q43: 114095 | R43: 110461 | S43: 104061 | T43: =J43 -> 100544 | U43: 99475 | V43: 95187 | W43: 91240 | X43: =K43 -> 91479 | Y43: 87593 | Z43: 84424 | AA43: 77614 | AC43: =Q43 -> 114095 | AD43: =R43 -> 110461 | AE43: =S43 -> 104061 | AF43: =T43 -> 100544 | AG43: =U43 -> 99475 | AH43: =V43 -> 95187 | AI43: =W43 -> 91240 | AJ43: =X43 -> 91479 | ... AM43: =AA43 -> 77614 | AO43: =SUM(AM43/AI43)-1 -> -0.14934239
B44: Other Assets | C44: =5414+3206+8757 -> 17377 | D44: 18177 | E44: 22283 | F44: 32978 | G44: 42522 | H44: 48849 | I44: 54428 | J44: 64758 | K44: 74834 | M44: 42071 | N44: 43921 | O44: 44567 | P44: =I44 -> 54428 | Q44: 52886 | R44: 57350 | S44: 56730 | T44: =J44 -> 64758 | U44: 58643 | V44: 62224 | W44: 62397 | X44: =K44 -> 74834 | Y44: 77183 | Z44: 81259 | AA44: 82882 | AC44: =Q44 -> 52886 | AD44: =R44 -> 57350 | AE44: =S44 -> 56730 | AF44: =T44 -> 64758 | AG44: =U44 -> 58643 | AH44: =V44 -> 62224 | AI44: =W44 -> 62397 | AJ44: =X44 -> 74834 | ... AM44: =AA44 -> 82882 | AO44: =SUM(AM44/AI44)-1 -> 0.32830104
B45: Total Assets | C45: =SUM(C42:C44)+C40 -> 321686 | D45: =SUM(D42:D44)+D40 -> 375319 | E45: =SUM(E42:E44)+E40 -> 365725 | F45: =SUM(F42:F44)+F40 -> 338516 | G45: =SUM(G42:G44)+G40 -> 323888 | H45: =SUM(H42:H44)+H40 -> 351002 | I45: =SUM(I42:I44)+I40 -> 352755 | J45: =SUM(J42:J44)+J40 -> 352583 | K45: =SUM(K42:K44)+K40 -> 364980 | M45: =SUM(M42:M44)+M40 -> 373153 | N45: =SUM(N42:N44)+N40 -> 342624 | O45: =SUM(O42:O44)+O40 -> 328271 | P45: =SUM(P42:P44)+P40 -> 352755 | Q45: =SUM(Q42:Q44)+Q40 -> 338709 | R45: =SUM(R42:R44)+R40 -> 324122 | S45: =SUM(S42:S44)+S40 -> 327000 | T45: =SUM(T42:T44)+T40 -> 352583 | ... AA45: =SUM(AA42:AA44)+AA40 -> 331495 | AC45: =SUM(AC42:AC44)+AC40 -> 338709 | AD45: =SUM(AD42:AD44)+AD40 -> 324122 | AE45: =SUM(AE42:AE44)+AE40 -> 327000 | AF45: =SUM(AF42:AF44)+AF40 -> 352583 | AG45: =SUM(AG42:AG44)+AG40 -> 345476 | AH45: =SUM(AH42:AH44)+AH40 -> 329373 | AI45: =SUM(AI42:AI44)+AI40 -> 323574 | AJ45: =SUM(AJ42:AJ44)+AJ40 -> 364980 | ... AM45: =SUM(AM42:AM44)+AM40 -> 331495 | AO45: =SUM(AM45/AI45)-1 -> 0.024479717
B47: Accounts Payable | C47: 37294 | D47: 44242 | E47: 55888 | F47: 46236 | G47: 42296 | H47: 54763 | I47: 64115 | J47: 62611 | K47: 68960 | M47: 74362 | N47: 52682 | O47: 48343 | P47: =I47 -> 64115 | Q47: 57918 | R47: 42945 | S47: 46699 | T47: =J47 -> 62611 | U47: 58146 | V47: 45753 | W47: 47574 | X47: =K47 -> 68960 | Y47: 61910 | Z47: 54126 | AA47: 50374 | AC47: =Q47 -> 57918 | AD47: =R47 -> 42945 | AE47: =S47 -> 46699 | AF47: =T47 -> 62611 | AG47: =U47 -> 58146 | AH47: =V47 -> 45753 | AI47: =W47 -> 47574 | AJ47: =X47 -> 68960 | ... AM47: =AA47 -> 50374 | AO47: =SUM(AM47/AI47)-1 -> 0.058855677
B48: Deferred Revenue - Current | C48: 8080 | D48: 7548 | E48: 7543 | F48: 5522 | G48: 6643 | H48: 7612 | I48: 7912 | J48: 8061 | K48: 8249 | M48: 7876 | N48: 7920 | O48: 7728 | P48: =I48 -> 7912 | Q48: 7992 | R48: 8131 | S48: 8158 | T48: =J48 -> 8061 | U48: 8264 | V48: 8012 | W48: 8053 | X48: =K48 -> 8249 | Y48: 8461 | Z48: 8976 | AA48: 8979 | AC48: =Q48 -> 7992 | AD48: =R48 -> 8131 | AE48: =S48 -> 8158 | AF48: =T48 -> 8061 | AG48: =U48 -> 8264 | AH48: =V48 -> 8012 | AI48: =W48 -> 8053 | AJ48: =X48 -> 8249 | ... AM48: =AA48 -> 8979 | AO48: =SUM(AM48/AI48)-1 -> 0.1149882
B49: Other Current Liabilities (accrued exp) | C49: 22027 | D49: 30551 | E49: 32687 | F49: 37720 | G49: 42684 | H49: 47493 | I49: 60845 | J49: 58829 | K49: 78304 | M49: 49167 | N49: 50248 | O49: 48811 | P49: =I49 -> 60845 | Q49: 59893 | R49: 56425 | S49: 58897 | T49: =J49 -> 58829 | U49: 54611 | V49: 57298 | W49: 60889 | X49: =K49 -> 78304 | Y49: 61151 | Z49: 61849 | AA49: 62499 | AC49: =Q49 -> 59893 | AD49: =R49 -> 56425 | AE49: =S49 -> 58897 | AF49: =T49 -> 58829 | AG49: =U49 -> 54611 | AH49: =V49 -> 57298 | AI49: =W49 -> 60889 | AJ49: =X49 -> 78304 | ... AM49: =AA49 -> 62499 | AO49: =SUM(AM49/AI49)-1 -> 0.026441558
B50: Commerical Paper | C50: 8105 | D50: 11977 | E50: 11964 | F50: 5980 | G50: 4996 | H50: 6000 | I50: 9982 | J50: 5985 | K50: 9967 | M50: 5000 | N50: 6999 | O50: 10982 | P50: 9982 | Q50: 1743 | R50: 1996 | S50: 3993 | T50: 5985 | U50: 1998 | V50: 1997 | W50: 2994 | X50: 9967 | Y50: 1995 | Z50: 5982 | AA50: 9923 | AI50: =W50 -> 2994 | AJ50: =X50 -> 9967 | AK50: =Y50 -> 1995 | AL50: =Z50 -> 5982 | AM50: =AA50 -> 9923
B51: Term Debt, Current Portion | C51: 3500 | D51: 6496 | E51: 8784 | F51: 10260 | G51: 8773 | H51: 9613 | I51: 11128 | J51: 9822 | K51: 10912 | M51: 11169 | N51: 9659 | O51: 14009 | P51: 11128 | Q51: 9740 | R51: 10578 | S51: 7216 | T51: 9822 | U51: 10954 | V51: 10762 | W51: 12114 | X51: 10912 | Y51: 10848 | Z51: 13638 | AA51: 9345 | AC51: =Q51 -> 9740 | AD51: =R51 -> 10578 | AE51: =S51 -> 7216 | AF51: =T51 -> 9822 | AG51: =U51 -> 10954 | AH51: =V51 -> 10762 | AI51: =W51 -> 12114 | AJ51: =X51 -> 10912 | ... AM51: =AA51 -> 9345 | AO51: =SUM(AM51/AI51)-1 -> -0.2285785
B52: Total Current Liabilities | C52: =SUM(C47:C51) -> 79006 | D52: =SUM(D47:D51) -> 100814 | E52: =SUM(E47:E51) -> 116866 | F52: =SUM(F47:F51) -> 105718 | G52: =SUM(G47:G51) -> 105392 | H52: =SUM(H47:H51) -> 125481 | I52: =SUM(I47:I51) -> 153982 | J52: =SUM(J47:J51) -> 145308 | K52: =SUM(K47:K51) -> 176392 | M52: =SUM(M47:M51) -> 147574 | N52: =SUM(N47:N51) -> 127508 | O52: =SUM(O47:O51) -> 129873 | P52: =SUM(P47:P51) -> 153982 | Q52: =SUM(Q47:Q51) -> 137286 | R52: =SUM(R47:R51) -> 120075 | S52: =SUM(S47:S51) -> 124963 | T52: =SUM(T47:T51) -> 145308 | ... AA52: =SUM(AA47:AA51) -> 141120 | AC52: =SUM(AC47:AC51) -> 135543 | AD52: =SUM(AD47:AD51) -> 118079 | AE52: =SUM(AE47:AE51) -> 120970 | AF52: =SUM(AF47:AF51) -> 139323 | AG52: =SUM(AG47:AG51) -> 131975 | AH52: =SUM(AH47:AH51) -> 121825 | AI52: =SUM(AI47:AI51) -> 131624 | AJ52: =SUM(AJ47:AJ51) -> 176392 | ... AM52: =SUM(AM47:AM51) -> 141120 | AO52: =SUM(AM52/AI52)-1 -> 0.072144898
B54: Long-Term Debt | C54: 75427 | D54: 97207 | E54: 93735 | F54: 91807 | G54: 98667 | H54: 109106 | I54: 98959 | J54: 95281 | K54: 85750 | M54: 106629 | N54: 103323 | O54: 94700 | P54: =I54 -> 98959 | Q54: 99627 | R54: 97041 | S54: 98071 | T54: =J54 -> 95281 | U54: 95088 | V54: 91831 | W54: 86196 | X54: =K54 -> 85750 | Y54: 83956 | Z54: 78566 | AA54: 82430 | AC54: =Q54 -> 99627 | AD54: =R54 -> 97041 | AE54: =S54 -> 98071 | AF54: =T54 -> 95281 | AG54: =U54 -> 95088 | AH54: =V54 -> 91831 | AI54: =W54 -> 86196 | AJ54: =X54 -> 85750 | ... AM54: =AA54 -> 82430 | AO54: =SUM(AM54/AI54)-1 -> -0.043691123
...

Sheet Revenue Drivers
B2: Apple Inc. (NASDAQ: AAPL) | C2: FYE | D2: FYE | E2: FYE | I2: Quarterly | Q2: Quarterly | R2: Quarterly | Y2: LTM | AC2: LTM | AK2: Variance
B3: Segment Anaysis | C3: ='Base Financials'!G3 -> 2020 | D3: ='Base Financials'!H3 -> 2021 | E3: ='Base Financials'!I3 -> 2022 | F3: ='Base Financials'!J3 -> 2023 | G3: ='Base Financials'!K3 -> 2024 | I3: ='Base Financials'!M3 -> 1Q22 | J3: ='Base Financials'!N3 -> 2Q22 | K3: ='Base Financials'!O3 -> 3Q22 | L3: ='Base Financials'!P3 -> 4Q22 | M3: ='Base Financials'!Q3 -> 1Q23 | N3: ='Base Financials'!R3 -> 2Q23 | O3: ='Base Financials'!S3 -> 3Q23 | P3: ='Base Financials'!T3 -> 4Q23 | ... W3: ='Base Financials'!AA3 -> 3Q25 | Y3: =M3 -> 1Q23 | Z3: =N3 -> 2Q23 | AA3: =O3 -> 3Q23 | AB3: =P3 -> 4Q23 | AC3: =Q3 -> 1Q24 | AD3: =R3 -> 2Q24 | AE3: =S3 -> 3Q24 | AF3: =T3 -> 4Q24 | ... AI3: =W3 -> 3Q25
B4: ($ In Millions) | C4: ='Base Financials'!G4 -> 44104 | D4: ='Base Financials'!H4 -> 44469 | E4: ='Base Financials'!I4 -> 44834 | F4: ='Base Financials'!J4 -> 45192 | G4: ='Base Financials'!K4 -> 45559 | I4: ='Base Financials'!M4 -> 44560 | J4: ='Base Financials'!N4 -> 44650 | K4: ='Base Financials'!O4 -> 44742 | L4: ='Base Financials'!P4 -> 44834 | M4: ='Base Financials'!Q4 -> 44917 | N4: ='Base Financials'!R4 -> 45008 | O4: ='Base Financials'!S4 -> 45100 | P4: ='Base Financials'!T4 -> 45192 | ... W4: ='Base Financials'!AA4 -> 45833 | Y4: =M4 -> 44917 | Z4: =N4 -> 45008 | AA4: =O4 -> 45100 | AB4: =P4 -> 45192 | AC4: =Q4 -> 45283 | AD4: =R4 -> 45375 | AE4: =S4 -> 45467 | AF4: =T4 -> 45559 | ... AI4: =W4 -> 45833
A6: X | B6: Revenue by End Product
B7: iPhone Revenue | C7: 137781 | D7: 191973 | E7: 205489 | F7: 200583 | G7: 201183 | I7: 71628 | J7: 50570 | K7: 40665 | L7: 42626 | M7: 65775 | N7: 51334 | O7: 39669 | P7: 43805 | Q7: 69702 | R7: 45963 | S7: 39296 | T7: 46222 | U7: 69138 | V7: 46841 | W7: 44582 | Y7: =SUM(J7:M7) -> 199636 | Z7: =SUM(K7:N7) -> 200400 | AA7: =SUM(L7:O7) -> 199404 | AB7: =SUM(M7:P7) -> 200583 | AC7: =SUM(N7:Q7) -> 204510 | AD7: =SUM(O7:R7) -> 199139 | AE7: =SUM(P7:S7) -> 198766 | AF7: =SUM(Q7:T7) -> 201183 | ... AI7: =SUM(T7:W7) -> 206783 | AK7: =SUM(AI7/AE7)-1 -> 0.04033386
B8: Mac Revenue | C8: 28622 | D8: 35190 | E8: 40177 | F8: 29357 | G8: 29984 | I8: 10852 | J8: 10435 | K8: 7382 | L8: 11508 | M8: 7735 | N8: 7168 | O8: 6840 | P8: 7614 | Q8: 7780 | R8: 7451 | S8: 7009 | T8: 7744 | U8: 8987 | V8: 7949 | W8: 8046 | Y8: =SUM(J8:M8) -> 37060 | Z8: =SUM(K8:N8) -> 33793 | AA8: =SUM(L8:O8) -> 33251 | AB8: =SUM(M8:P8) -> 29357 | AC8: =SUM(N8:Q8) -> 29402 | AD8: =SUM(O8:R8) -> 29685 | AE8: =SUM(P8:S8) -> 29854 | AF8: =SUM(Q8:T8) -> 29984 | ... AI8: =SUM(T8:W8) -> 32726 | AK8: =SUM(AI8/AE8)-1 -> 0.096201514
B9: iPad Revenue | C9: 23724 | D9: 31862 | E9: 29292 | F9: 28300 | G9: 26694 | I9: 7248 | J9: 7646 | K9: 7224 | L9: 7174 | M9: 9396 | N9: 6670 | O9: 5791 | P9: 6443 | Q9: 7023 | R9: 5559 | S9: 7162 | T9: 6950 | U9: 8088 | V9: 6402 | W9: 6581 | Y9: =SUM(J9:M9) -> 31440 | Z9: =SUM(K9:N9) -> 30464 | AA9: =SUM(L9:O9) -> 29031 | AB9: =SUM(M9:P9) -> 28300 | AC9: =SUM(N9:Q9) -> 25927 | AD9: =SUM(O9:R9) -> 24816 | AE9: =SUM(P9:S9) -> 26187 | AF9: =SUM(Q9:T9) -> 26694 | ... AI9: =SUM(T9:W9) -> 28021 | AK9: =SUM(AI9/AE9)-1 -> 0.07003475
B10: Services Revenue | C10: 53768 | D10: 68425 | E10: 78129 | F10: 85200 | G10: 96169 | I10: 19516 | J10: 19821 | K10: 19604 | L10: 19188 | M10: 20766 | N10: 20907 | O10: 21213 | P10: 22314 | Q10: 23117 | R10: 23867 | S10: 24213 | T10: 24972 | U10: 26340 | V10: 26645 | W10: 27423 | AE10: =SUM(P10:S10) -> 93511 | AF10: =SUM(Q10:T10) -> 96169 | AG10: =SUM(R10:U10) -> 99392 | AH10: =SUM(S10:V10) -> 102170 | AI10: =SUM(T10:W10) -> 105380
B11: Wearables, Home, and Accessories Revenue | C11: 30620 | D11: 38367 | E11: 41241 | F11: 39845 | G11: 37005 | I11: 14701 | J11: 8806 | K11: 8084 | L11: 9650 | M11: 13482 | N11: 8757 | O11: 8284 | P11: 9322 | Q11: 11953 | R11: 7913 | S11: 8097 | T11: 9042 | U11: 11747 | V11: 7522 | W11: 7404 | AE11: =SUM(P11:S11) -> 37285 | AF11: =SUM(Q11:T11) -> 37005 | AG11: =SUM(R11:U11) -> 36799 | AH11: =SUM(S11:V11) -> 36408 | AI11: =SUM(T11:W11) -> 35715
B12: Total Net Revenue | C12: =SUM(C7:C11) -> 274515 | D12: =SUM(D7:D11) -> 365817 | E12: =SUM(E7:E11) -> 394328 | F12: =SUM(F7:F11) -> 383285 | G12: =SUM(G7:G11) -> 391035 | I12: =SUM(I7:I11) -> 123945 | J12: =SUM(J7:J11) -> 97278 | K12: =SUM(K7:K11) -> 82959 | L12: =SUM(L7:L11) -> 90146 | M12: =SUM(M7:M11) -> 117154 | N12: =SUM(N7:N11) -> 94836 | O12: =SUM(O7:O11) -> 81797 | P12: =SUM(P7:P11) -> 89498 | ... W12: =SUM(W7:W11) -> 94036 | Y12: =SUM(Y7:Y9) -> 268136 | Z12: =SUM(Z7:Z9) -> 264657 | AA12: =SUM(AA7:AA9) -> 261686 | AB12: =SUM(AB7:AB9) -> 258240 | AC12: =SUM(AC7:AC9) -> 259839 | AD12: =SUM(AD7:AD9) -> 253640 | AE12: =SUM(AE7:AE11) -> 385603 | AF12: =SUM(AF7:AF11) -> 391035 | AG12: =SUM(AG7:AG11) -> 395760 | AH12: =SUM(AH7:AH11) -> 400366 | AI12: =SUM(AI7:AI11) -> 408625 | AK12: =SUM(AI12/AE12)-1 -> 0.059703892
B13: Balance Check | C13: =C12-'Base Financials'!G9 -> 0 | D13: =D12-'Base Financials'!H9 -> 0 | E13: =E12-'Base Financials'!I9 -> 0 | F13: =F12-'Base Financials'!J9 -> 0 | G13: =G12-'Base Financials'!K9 -> 0 | I13: =I12-'Base Financials'!M9 -> 0 | J13: =J12-'Base Financials'!N9 -> 0 | K13: =K12-'Base Financials'!O9 -> 0 | L13: =L12-'Base Financials'!P9 -> 0 | M13: =M12-'Base Financials'!Q9 -> 0 | N13: =N12-'Base Financials'!R9 -> 0 | O13: =O12-'Base Financials'!S9 -> 0 | P13: =P12-'Base Financials'!T9 -> 0 | ... W13: =W12-'Base Financials'!AA9 -> 0 | Y13: =Y12-'Base Financials'!AC9 -> -119401 | Z13: =Z12-'Base Financials'!AD9 -> -120438 | AA13: =AA12-'Base Financials'!AE9 -> -122247 | AB13: =AB12-'Base Financials'!AF9 -> -125045 | AC13: =AC12-'Base Financials'!AG9 -> -125867 | AD13: =AD12-'Base Financials'!AH9 -> -127983 | AE13: =AE12-'Base Financials'!AI9 -> 0 | AF13: =AF12-'Base Financials'!AJ9 -> 0 | ... AI13: =AI12-'Base Financials'!AM9 -> 0
A15: X | B15: Revenue by Product Offerings: Wearables, Home, and Accessories
B16: Accessories | C16: 16019.941 | D16: 20596.468 | E16: 21262.875 | F16: 19827.709 | G16: 18865.888 | I16: 5656.6733 | J16: 6070.4168 | K16: 4391.8204 | L16: 5143.9643 | M16: 4250.8013 | N16: 5709.2465 | O16: 4595.9109 | P16: 5271.75 | Q16: 4111.1639 | R16: 5174.0625 | S16: 4782.089 | T16: 4798.5722 | U16: 3839.2947 | V16: 4674.9385 | W16: 4052.9944 | Y16: =SUM(J16:M16) -> 19857.003 | Z16: =SUM(K16:N16) -> 19495.832 | AA16: =SUM(L16:O16) -> 19699.923 | AB16: =SUM(M16:P16) -> 19827.709 | AC16: =SUM(N16:Q16) -> 19688.071 | AD16: =SUM(O16:R16) -> 19152.887 | AE16: =SUM(P16:S16) -> 19339.065 | AF16: =SUM(Q16:T16) -> 18865.888 | ... AI16: =SUM(T16:W16) -> 17365.8 | AK16: =SUM(AI16/AE16)-1 -> -0.10203521
B17: Apple Watch | C17: 14229.125 | D17: 17479.962 | E17: 19750.272 | F17: 19838.618 | G17: 17999.002 | I17: 8954.015 | J17: 2690.982 | K17: 3644.0381 | L17: 4461.2373 | M17: 9160.4076 | N17: 3012.7635 | O17: 3650.3329 | P17: 4015.1136 | Q17: 7786.3465 | R17: 2711.4871 | S17: 3285.2996 | T17: 4215.8692 | U17: 7864.2099 | V17: 2847.0615 | W17: 3351.0056 | Y17: =SUM(J17:M17) -> 19956.665 | Z17: =SUM(K17:N17) -> 20278.447 | AA17: =SUM(L17:O17) -> 20284.741 | AB17: =SUM(M17:P17) -> 19838.618 | AC17: =SUM(N17:Q17) -> 18464.556 | AD17: =SUM(O17:R17) -> 18163.28 | AE17: =SUM(P17:S17) -> 17798.247 | AF17: =SUM(Q17:T17) -> 17999.002 | ... AI17: =SUM(T17:W17) -> 18278.146 | AK17: =SUM(AI17/AE17)-1 -> 0.026963301
B18: Total Intel Products Revenue | C18: =SUM(C16:C17) -> 30249.066 | D18: =SUM(D16:D17) -> 38076.431 | E18: =SUM(E16:E17) -> 41013.147 | F18: =SUM(F16:F17) -> 39666.326 | G18: =SUM(G16:G17) -> 36864.89 | I18: =SUM(I16:I17) -> 14610.688 | J18: =SUM(J16:J17) -> 8761.3988 | K18: =SUM(K16:K17) -> 8035.8585 | L18: =SUM(L16:L17) -> 9605.2016 | M18: =SUM(M16:M17) -> 13411.209 | N18: =SUM(N16:N17) -> 8722.01 | O18: =SUM(O16:O17) -> 8246.2439 | P18: =SUM(P16:P17) -> 9286.8636 | ... W18: =SUM(W16:W17) -> 7404 | Y18: =SUM(Y16:Y17) -> 39813.668 | Z18: =SUM(Z16:Z17) -> 39774.279 | AA18: =SUM(AA16:AA17) -> 39984.664 | AB18: =SUM(AB16:AB17) -> 39666.326 | AC18: =SUM(AC16:AC17) -> 38152.628 | AD18: =SUM(AD16:AD17) -> 37316.167 | AE18: =SUM(AE16:AE17) -> 37137.312 | AF18: =SUM(AF16:AF17) -> 36864.89 | ... AI18: =SUM(AI16:AI17) -> 35643.946 | AK18: =SUM(AI18/AE18)-1 -> -0.040212015
B19: Balance Check | C19: =C11-C18 -> 370.93376 | D19: =D11-D18 -> 290.56925 | E19: =E11-E18 -> 227.85276 | F19: =F11-F18 -> 178.67374 | G19: =G11-G18 -> 140.10996 | I19: =I11-I18 -> 90.311719 | J19: =J11-J18 -> 44.601177 | K19: =K11-K18 -> 48.141511 | L19: =L11-L18 -> 44.798357 | M19: =M11-M18 -> 70.79113 | N19: =N11-N18 -> 34.990036 | O19: =O11-O18 -> 37.756146 | P19: =P11-P18 -> 35.136432 | ... W19: =W11-W18 -> 0 | Y19: =Y7-Y18 -> 159822.33 | Z19: =Z7-Z18 -> 160625.72 | AA19: =AA7-AA18 -> 159419.34 | AB19: =AB7-AB18 -> 160916.67 | AC19: =AC7-AC18 -> 166357.37 | AD19: =AD7-AD18 -> 161822.83 | AE19: =AE7-AE18 -> 161628.69 | AF19: =AF7-AF18 -> 164318.11 | ... AI19: =AI7-AI18 -> 171139.05

Sheet FCF
B2: Apple Inc. (NASDAQ: AAPL) | C2: FYE | I2: Quarterly | Q2: Quarterly | S2: Quarterly | Y2: LTM | AC2: LTM | AF2: LTM | AL2: Variance
B3: FCF Analysis | C3: ='Base Financials'!G3 -> 2020 | D3: ='Base Financials'!H3 -> 2021 | E3: ='Base Financials'!I3 -> 2022 | F3: ='Base Financials'!J3 -> 2023 | G3: ='Base Financials'!K3 -> 2024 | I3: ='Base Financials'!M3 -> 1Q22 | J3: ='Base Financials'!N3 -> 2Q22 | K3: ='Base Financials'!O3 -> 3Q22 | L3: ='Base Financials'!P3 -> 4Q22 | M3: ='Base Financials'!Q3 -> 1Q23 | N3: ='Base Financials'!R3 -> 2Q23 | O3: ='Base Financials'!S3 -> 3Q23 | P3: ='Base Financials'!T3 -> 4Q23 | ... W3: ='Base Financials'!AA3 -> 3Q25 | Y3: =L3 -> 4Q22 | Z3: =M3 -> 1Q23 | AA3: =N3 -> 2Q23 | AB3: =O3 -> 3Q23 | AC3: =P3 -> 4Q23 | AD3: =Q3 -> 1Q24 | AE3: =R3 -> 2Q24 | AF3: =S3 -> 3Q24 | ... AJ3: =W3 -> 3Q25
B4: ($ In Thousands) | C4: ='Base Financials'!G4 -> 44104 | D4: ='Base Financials'!H4 -> 44469 | E4: ='Base Financials'!I4 -> 44834 | F4: ='Base Financials'!J4 -> 45192 | G4: ='Base Financials'!K4 -> 45559 | I4: ='Base Financials'!M4 -> 44560 | J4: ='Base Financials'!N4 -> 44650 | K4: ='Base Financials'!O4 -> 44742 | L4: ='Base Financials'!P4 -> 44834 | M4: ='Base Financials'!Q4 -> 44917 | N4: ='Base Financials'!R4 -> 45008 | O4: ='Base Financials'!S4 -> 45100 | P4: ='Base Financials'!T4 -> 45192 | ... W4: ='Base Financials'!AA4 -> 45833 | Y4: =L4 -> 44834 | Z4: =M4 -> 44917 | AA4: =N4 -> 45008 | AB4: =O4 -> 45100 | AC4: =P4 -> 45192 | AD4: =Q4 -> 45283 | AE4: =R4 -> 45375 | AF4: =S4 -> 45467 | ... AJ4: =W4 -> 45833
B6: ='Revenue Drivers'!B7 -> iPhone Revenue | C6: ='Revenue Drivers'!C7 -> 137781 | D6: ='Revenue Drivers'!D7 -> 191973 | E6: ='Revenue Drivers'!E7 -> 205489 | F6: ='Revenue Drivers'!F7 -> 200583 | G6: ='Revenue Drivers'!G7 -> 201183 | I6: ='Revenue Drivers'!I7 -> 71628 | J6: ='Revenue Drivers'!J7 -> 50570 | K6: ='Revenue Drivers'!K7 -> 40665 | L6: ='Revenue Drivers'!L7 -> 42626 | M6: ='Revenue Drivers'!M7 -> 65775 | N6: ='Revenue Drivers'!N7 -> 51334 | O6: ='Revenue Drivers'!O7 -> 39669 | P6: ='Revenue Drivers'!P7 -> 43805 | ... W6: ='Revenue Drivers'!W7 -> 44582 | Y6: =SUM(I6:L6) -> 205489 | Z6: =SUM(J6:M6) -> 199636 | AA6: =SUM(K6:N6) -> 200400 | AB6: =SUM(L6:O6) -> 199404 | AC6: =SUM(M6:P6) -> 200583 | AD6: =SUM(N6:Q6) -> 204510 | AE6: =SUM(O6:R6) -> 199139 | AF6: =SUM(P6:S6) -> 198766 | ... AJ6: =SUM(T6:W6) -> 206783 | AL6: =SUM(AJ6/AF6)-1 -> 0.04033386
B7: ='Revenue Drivers'!B8 -> Mac Revenue | C7: ='Revenue Drivers'!C8 -> 28622 | D7: ='Revenue Drivers'!D8 -> 35190 | E7: ='Revenue Drivers'!E8 -> 40177 | F7: ='Revenue Drivers'!F8 -> 29357 | G7: ='Revenue Drivers'!G8 -> 29984 | I7: ='Revenue Drivers'!I8 -> 10852 | J7: ='Revenue Drivers'!J8 -> 10435 | K7: ='Revenue Drivers'!K8 -> 7382 | L7: ='Revenue Drivers'!L8 -> 11508 | M7: ='Revenue Drivers'!M8 -> 7735 | N7: ='Revenue Drivers'!N8 -> 7168 | O7: ='Revenue Drivers'!O8 -> 6840 | P7: ='Revenue Drivers'!P8 -> 7614 | ... W7: ='Revenue Drivers'!W8 -> 8046 | Y7: =SUM(I7:L7) -> 40177 | Z7: =SUM(J7:M7) -> 37060 | AA7: =SUM(K7:N7) -> 33793 | AB7: =SUM(L7:O7) -> 33251 | AC7: =SUM(M7:P7) -> 29357 | AD7: =SUM(N7:Q7) -> 29402 | AE7: =SUM(O7:R7) -> 29685 | AF7: =SUM(P7:S7) -> 29854 | ... AJ7: =SUM(T7:W7) -> 32726 | AL7: =SUM(AJ7/AF7)-1 -> 0.096201514
B8: ='Revenue Drivers'!B9 -> iPad Revenue | C8: ='Revenue Drivers'!C9 -> 23724 | D8: ='Revenue Drivers'!D9 -> 31862 | E8: ='Revenue Drivers'!E9 -> 29292 | F8: ='Revenue Drivers'!F9 -> 28300 | G8: ='Revenue Drivers'!G9 -> 26694 | I8: ='Revenue Drivers'!I9 -> 7248 | J8: ='Revenue Drivers'!J9 -> 7646 | K8: ='Revenue Drivers'!K9 -> 7224 | L8: ='Revenue Drivers'!L9 -> 7174 | M8: ='Revenue Drivers'!M9 -> 9396 | N8: ='Revenue Drivers'!N9 -> 6670 | O8: ='Revenue Drivers'!O9 -> 5791 | P8: ='Revenue Drivers'!P9 -> 6443 | ... W8: ='Revenue Drivers'!W9 -> 6581 | Y8: =SUM(I8:L8) -> 29292 | Z8: =SUM(J8:M8) -> 31440 | AA8: =SUM(K8:N8) -> 30464 | AB8: =SUM(L8:O8) -> 29031 | AC8: =SUM(M8:P8) -> 28300 | AD8: =SUM(N8:Q8) -> 25927 | AE8: =SUM(O8:R8) -> 24816 | AF8: =SUM(P8:S8) -> 26187 | ... AJ8: =SUM(T8:W8) -> 28021 | AL8: =SUM(AJ8/AF8)-1 -> 0.07003475
B9: ='Revenue Drivers'!B10 -> Services Revenue | C9: ='Revenue Drivers'!C10 -> 53768 | D9: ='Revenue Drivers'!D10 -> 68425 | E9: ='Revenue Drivers'!E10 -> 78129 | F9: ='Revenue Drivers'!F10 -> 85200 | G9: ='Revenue Drivers'!G10 -> 96169 | I9: ='Revenue Drivers'!I10 -> 19516 | J9: ='Revenue Drivers'!J10 -> 19821 | K9: ='Revenue Drivers'!K10 -> 19604 | L9: ='Revenue Drivers'!L10 -> 19188 | M9: ='Revenue Drivers'!M10 -> 20766 | N9: ='Revenue Drivers'!N10 -> 20907 | O9: ='Revenue Drivers'!O10 -> 21213 | P9: ='Revenue Drivers'!P10 -> 22314 | ... W9: ='Revenue Drivers'!W10 -> 27423 | Y9: =SUM(I9:L9) -> 78129 | Z9: =SUM(J9:M9) -> 79379 | AA9: =SUM(K9:N9) -> 80465 | AB9: =SUM(L9:O9) -> 82074 | AC9: =SUM(M9:P9) -> 85200 | AD9: =SUM(N9:Q9) -> 87551 | AE9: =SUM(O9:R9) -> 90511 | AF9: =SUM(P9:S9) -> 93511 | ... AJ9: =SUM(T9:W9) -> 105380 | AL9: =SUM(AJ9/AF9)-1 -> 0.12692624
B10: ='Revenue Drivers'!B11 -> Wearables, Home, and Accessories Revenue | C10: ='Revenue Drivers'!C11 -> 30620 | D10: ='Revenue Drivers'!D11 -> 38367 | E10: ='Revenue Drivers'!E11 -> 41241 | F10: ='Revenue Drivers'!F11 -> 39845 | G10: ='Revenue Drivers'!G11 -> 37005 | I10: ='Revenue Drivers'!I11 -> 14701 | J10: ='Revenue Drivers'!J11 -> 8806 | K10: ='Revenue Drivers'!K11 -> 8084 | L10: ='Revenue Drivers'!L11 -> 9650 | M10: ='Revenue Drivers'!M11 -> 13482 | N10: ='Revenue Drivers'!N11 -> 8757 | O10: ='Revenue Drivers'!O11 -> 8284 | P10: ='Revenue Drivers'!P11 -> 9322 | ... W10: ='Revenue Drivers'!W11 -> 7404 | Y10: =SUM(I10:L10) -> 41241 | Z10: =SUM(J10:M10) -> 40022 | AA10: =SUM(K10:N10) -> 39973 | AB10: =SUM(L10:O10) -> 40173 | AC10: =SUM(M10:P10) -> 39845 | AD10: =SUM(N10:Q10) -> 38316 | AE10: =SUM(O10:R10) -> 37472 | AF10: =SUM(P10:S10) -> 37285 | ... AJ10: =SUM(T10:W10) -> 35715 | AL10: =SUM(AJ10/AF10)-1 -> -0.042108086
B11: Total Revenue | C11: =SUM(C6:C10) -> 274515 | D11: =SUM(D6:D10) -> 365817 | E11: =SUM(E6:E10) -> 394328 | F11: =SUM(F6:F10) -> 383285 | G11: =SUM(G6:G10) -> 391035 | I11: =SUM(I6:I10) -> 123945 | J11: =SUM(J6:J10) -> 97278 | K11: =SUM(K6:K10) -> 82959 | L11: =SUM(L6:L10) -> 90146 | M11: =SUM(M6:M10) -> 117154 | N11: =SUM(N6:N10) -> 94836 | O11: =SUM(O6:O10) -> 81797 | P11: =SUM(P6:P10) -> 89498 | ... W11: =SUM(W6:W10) -> 94036 | Y11: =SUM(Y6:Y10) -> 394328 | Z11: =SUM(Z6:Z10) -> 387537 | AA11: =SUM(AA6:AA10) -> 385095 | AB11: =SUM(AB6:AB10) -> 383933 | AC11: =SUM(AC6:AC10) -> 383285 | AD11: =SUM(AD6:AD10) -> 385706 | AE11: =SUM(AE6:AE10) -> 381623 | AF11: =SUM(AF6:AF10) -> 385603 | ... AJ11: =SUM(AJ6:AJ10) -> 408625 | AL11: =SUM(AJ11/AF11)-1 -> 0.059703892
B12: Y/Y Growth (%) | D12: =SUM(D11/C11)-1 -> 0.33259385 | E12: =SUM(E11/D11)-1 -> 0.077937876 | F12: =SUM(F11/E11)-1 -> -0.028004605 | G12: =SUM(G11/F11)-1 -> 0.020219941 | M12: =SUM(M11/I11)-1 -> -0.054790431 | N12: =SUM(N11/J11)-1 -> -0.025103312 | O12: =SUM(O11/K11)-1 -> -0.014006919 | P12: =SUM(P11/L11)-1 -> -0.0071883389 | Q12: =SUM(Q11/M11)-1 -> 0.020665107 | R12: =SUM(R11/N11)-1 -> -0.043053271 | S12: =SUM(S11/O11)-1 -> 0.048657041 | T12: =SUM(T11/P11)-1 -> 0.060694094 | ... W12: =SUM(W11/S11)-1 -> 0.096284552 | AC12: =SUM(AC11/Y11)-1 -> -0.028004605 | AD12: =SUM(AD11/Z11)-1 -> -0.0047247102 | AE12: =SUM(AE11/AA11)-1 -> -0.0090159571 | AF12: =SUM(AF11/AB11)-1 -> 0.0043497173 | AG12: =SUM(AG11/AC11)-1 -> 0.020219941 | AH12: =SUM(AH11/AD11)-1 -> 0.026066486 | AI12: =SUM(AI11/AE11)-1 -> 0.049113916 | AJ12: =SUM(AJ11/AF11)-1 -> 0.059703892 | AL12: =SUM(AJ12-AF12)*10000 -> 553.54175
B13: Q/Q Growth (%) | C13: N/A | D13: N/A | E13: N/A | F13: N/A | G13: N/A | J13: =SUM(J11/I11)-1 -> -0.21515188 | K13: =SUM(K11/J11)-1 -> -0.14719669 | L13: =SUM(L11/K11)-1 -> 0.086633156 | M13: =SUM(M11/L11)-1 -> 0.29960287 | N13: =SUM(N11/M11)-1 -> -0.19050139 | O13: =SUM(O11/N11)-1 -> -0.13748998 | P13: =SUM(P11/O11)-1 -> 0.094147707 | Q13: =SUM(Q11/P11)-1 -> 0.33606338 | ... W13: =SUM(W11/V11)-1 -> -0.013873887 | Y13: N/A | Z13: N/A | AA13: N/A | AB13: N/A | AC13: N/A | AD13: N/A | AE13: N/A | AF13: N/A | AG13: N/A | AH13: N/A | AI13: N/A | AJ13: N/A
B15: (-) Cost of Sales | C15: ='Base Financials'!G11 -> -169559 | D15: ='Base Financials'!H11 -> -212981 | E15: ='Base Financials'!I11 -> -223546 | F15: ='Base Financials'!J11 -> -214137 | G15: ='Base Financials'!K11 -> -210352 | I15: ='Base Financials'!M11 -> -69702 | J15: ='Base Financials'!N11 -> -54719 | K15: ='Base Financials'!O11 -> -47074 | L15: ='Base Financials'!P11 -> -52051 | M15: ='Base Financials'!Q11 -> -66822 | N15: ='Base Financials'!R11 -> -52860 | O15: ='Base Financials'!S11 -> -45384 | P15: ='Base Financials'!T11 -> -49071 | ... W15: ='Base Financials'!AA11 -> -50318 | Y15: =SUM(I15:L15) -> -223546 | Z15: =SUM(J15:M15) -> -220666 | AA15: =SUM(K15:N15) -> -218807 | AB15: =SUM(L15:O15) -> -217117 | AC15: =SUM(M15:P15) -> -214137 | AD15: =SUM(N15:Q15) -> -212035 | AE15: =SUM(O15:R15) -> -207657 | AF15: =SUM(P15:S15) -> -208372 | ... AJ15: =SUM(T15:W15) -> -217886 | AL15: =SUM(AJ15/AF15)-1 -> 0.045658726
B16: Gross Profit | C16: =+C11+C15 -> 104956 | D16: =+D11+D15 -> 152836 | E16: =+E11+E15 -> 170782 | F16: =+F11+F15 -> 169148 | G16: =+G11+G15 -> 180683 | I16: =+I11+I15 -> 54243 | J16: =+J11+J15 -> 42559 | K16: =+K11+K15 -> 35885 | L16: =+L11+L15 -> 38095 | M16: =+M11+M15 -> 50332 | N16: =+N11+N15 -> 41976 | O16: =+O11+O15 -> 36413 | P16: =+P11+P15 -> 40427 | ... W16: =+W11+W15 -> 43718 | Y16: =+Y11+Y15 -> 170782 | Z16: =+Z11+Z15 -> 166871 | AA16: =+AA11+AA15 -> 166288 | AB16: =+AB11+AB15 -> 166816 | AC16: =+AC11+AC15 -> 169148 | AD16: =+AD11+AD15 -> 173671 | AE16: =+AE11+AE15 -> 173966 | AF16: =+AF11+AF15 -> 177231 | ... AJ16: =+AJ11+AJ15 -> 190739 | AL16: =SUM(AJ16/AF16)-1 -> 0.076216915
B17: Gross Margin (%) | C17: =C16/C11 -> 0.38233248 | D17: =D16/D11 -> 0.4177936 | E17: =E16/E11 -> 0.43309631 | F17: =F16/F11 -> 0.4413113 | G17: =G16/G11 -> 0.4620635 | I17: =I16/I11 -> 0.43763766 | J17: =J16/J11 -> 0.43749872 | K17: =K16/K11 -> 0.43256307 | L17: =L16/L11 -> 0.42259224 | M17: =M16/M11 -> 0.42962255 | N17: =N16/N11 -> 0.44261673 | O17: =O16/O11 -> 0.44516303 | P17: =P16/P11 -> 0.45170842 | ... W17: =W16/W11 -> 0.46490706 | Y17: =Y16/Y11 -> 0.43309631 | Z17: =Z16/Z11 -> 0.43059372 | AA17: =AA16/AA11 -> 0.43181033 | AB17: =AB16/AB11 -> 0.43449248 | AC17: =AC16/AC11 -> 0.4413113 | AD17: =AD16/AD11 -> 0.45026782 | AE17: =AE16/AE11 -> 0.45585827 | AF17: =AF16/AF11 -> 0.45962039 | ... AJ17: =AJ16/AJ11 -> 0.4667825 | AL17: =SUM(AJ17-AF17)*10000 -> 71.621155
B19: (-) Research and Development (R&D) | C19: ='Base Financials'!G15 -> -18752 | D19: ='Base Financials'!H15 -> -21914 | E19: ='Base Financials'!I15 -> -26251 | F19: ='Base Financials'!J15 -> -29915 | G19: ='Base Financials'!K15 -> -31370 | I19: ='Base Financials'!M15 -> -6306 | J19: ='Base Financials'!N15 -> -6387 | K19: ='Base Financials'!O15 -> -6797 | L19: ='Base Financials'!P15 -> -6761 | M19: ='Base Financials'!Q15 -> -7709 | N19: ='Base Financials'!R15 -> -7457 | O19: ='Base Financials'!S15 -> -7442 | P19: ='Base Financials'!T15 -> -7307 | ... W19: ='Base Financials'!AA15 -> -8866 | Y19: =SUM(I19:L19) -> -26251 | Z19: =SUM(J19:M19) -> -27654 | AA19: =SUM(K19:N19) -> -28724 | AB19: =SUM(L19:O19) -> -29369 | AC19: =SUM(M19:P19) -> -29915 | AD19: =SUM(N19:Q19) -> -29902 | AE19: =SUM(O19:R19) -> -30348 | AF19: =SUM(P19:S19) -> -30912 | ... AJ19: =SUM(T19:W19) -> -33449 | AL19: =SUM(AJ19/AF19)-1 -> 0.082071687
B20: (-) Selling, General & Administrative (SG&A) | C20: ='Base Financials'!G16 -> -19916 | D20: ='Base Financials'!H16 -> -21973 | E20: ='Base Financials'!I16 -> -25094 | F20: ='Base Financials'!J16 -> -24932 | G20: ='Base Financials'!K16 -> -26097 | I20: ='Base Financials'!M16 -> -6449 | J20: ='Base Financials'!N16 -> -6193 | K20: ='Base Financials'!O16 -> -6012 | L20: ='Base Financials'!P16 -> -6440 | M20: ='Base Financials'!Q16 -> -6607 | N20: ='Base Financials'!R16 -> -6201 | O20: ='Base Financials'!S16 -> -5973 | P20: ='Base Financials'!T16 -> -6151 | ... W20: ='Base Financials'!AA16 -> -6650 | Y20: =SUM(I20:L20) -> -25094 | Z20: =SUM(J20:M20) -> -25252 | AA20: =SUM(K20:N20) -> -25260 | AB20: =SUM(L20:O20) -> -25221 | AC20: =SUM(M20:P20) -> -24932 | AD20: =SUM(N20:Q20) -> -25111 | AE20: =SUM(O20:R20) -> -25378 | AF20: =SUM(P20:S20) -> -25725 | ... AJ20: =SUM(T20:W20) -> -27076 | AL20: =SUM(AJ20/AF20)-1 -> 0.052517007
B21: Earning before Interest & Taxes (EBIT) | C21: =SUM(C16+SUM(C19:C20)) -> 66288 | D21: =SUM(D16+SUM(D19:D20)) -> 108949 | E21: =SUM(E16+SUM(E19:E20)) -> 119437 | F21: =SUM(F16+SUM(F19:F20)) -> 114301 | G21: =SUM(G16+SUM(G19:G20)) -> 123216 | I21: =SUM(I16+SUM(I19:I20)) -> 41488 | J21: =SUM(J16+SUM(J19:J20)) -> 29979 | K21: =SUM(K16+SUM(K19:K20)) -> 23076 | L21: =SUM(L16+SUM(L19:L20)) -> 24894 | M21: =SUM(M16+SUM(M19:M20)) -> 36016 | N21: =SUM(N16+SUM(N19:N20)) -> 28318 | O21: =SUM(O16+SUM(O19:O20)) -> 22998 | P21: =SUM(P16+SUM(P19:P20)) -> 26969 | ... W21: =SUM(W16+SUM(W19:W20)) -> 28202 | Y21: =SUM(Y16+SUM(Y19:Y20)) -> 119437 | Z21: =SUM(Z16+SUM(Z19:Z20)) -> 113965 | AA21: =SUM(AA16+SUM(AA19:AA20)) -> 112304 | AB21: =SUM(AB16+SUM(AB19:AB20)) -> 112226 | AC21: =SUM(AC16+SUM(AC19:AC20)) -> 114301 | AD21: =SUM(AD16+SUM(AD19:AD20)) -> 118658 | AE21: =SUM(AE16+SUM(AE19:AE20)) -> 118240 | AF21: =SUM(AF16+SUM(AF19:AF20)) -> 120594 | ... AJ21: =SUM(AJ16+SUM(AJ19:AJ20)) -> 130214 | AL21: =SUM(AJ21/AF21)-1 -> 0.079771796
B22: Operating Margin (%) | C22: =C21/C11 -> 0.24147314 | D22: =D21/D11 -> 0.29782378 | E22: =E21/E11 -> 0.30288744 | F22: =F21/F11 -> 0.29821412 | G22: =G21/G11 -> 0.31510223 | I22: =I21/I11 -> 0.33472911 | J22: =J21/J11 -> 0.30817862 | K22: =K21/K11 -> 0.2781615 | L22: =L21/L11 -> 0.27615202 | M22: =M21/M11 -> 0.30742442 | N22: =N21/N11 -> 0.29859969 | O22: =O21/O11 -> 0.28115946 | P22: =P21/P11 -> 0.30133634 | ... W22: =W21/W11 -> 0.29990642 | Y22: =Y21/Y11 -> 0.30288744 | Z22: =Z21/Z11 -> 0.29407515 | AA22: =AA21/AA11 -> 0.29162674 | AB22: =AB21/AB11 -> 0.29230621 | AC22: =AC21/AC11 -> 0.29821412 | AD22: =AD21/AD11 -> 0.30763846 | AE22: =AE21/AE11 -> 0.30983457 | AF22: =AF21/AF11 -> 0.31274134 | ... AJ22: =AJ21/AJ11 -> 0.31866381 | AL22: =SUM(AJ22-AF22)*10000 -> 59.224688
B24: (+) Depreciation and Amortization | C24: ='Base Financials'!G73 -> 11056 | D24: ='Base Financials'!H73 -> 11284 | E24: ='Base Financials'!I73 -> 11104 | F24: ='Base Financials'!J73 -> 11519 | G24: ='Base Financials'!K73 -> 11445 | I24: ='Base Financials'!M73 -> 2697 | J24: ='Base Financials'!N73 -> 2737 | K24: ='Base Financials'!O73 -> 2805 | L24: ='Base Financials'!P73 -> 2865 | M24: ='Base Financials'!Q73 -> 2916 | N24: ='Base Financials'!R73 -> 2898 | O24: ='Base Financials'!S73 -> 3052 | P24: ='Base Financials'!T73 -> 2653 | ... W24: ='Base Financials'!AA73 -> 2830 | Y24: =SUM(I24:L24) -> 11104 | Z24: =SUM(J24:M24) -> 11323 | AA24: =SUM(K24:N24) -> 11484 | AB24: =SUM(L24:O24) -> 11731 | AC24: =SUM(M24:P24) -> 11519 | AD24: =SUM(N24:Q24) -> 11451 | AE24: =SUM(O24:R24) -> 11389 | AF24: =SUM(P24:S24) -> 11187 | ... AJ24: =SUM(T24:W24) -> 11482 | AL24: =SUM(AJ24/AF24)-1 -> 0.026369894
B25: EBITDA | C25: =SUM(C21+C24) -> 77344 | D25: =SUM(D21+D24) -> 120233 | E25: =SUM(E21+E24) -> 130541 | F25: =SUM(F21+F24) -> 125820 | G25: =SUM(G21+G24) -> 134661 | I25: =SUM(I21+I24) -> 44185 | J25: =SUM(J21+J24) -> 32716 | K25: =SUM(K21+K24) -> 25881 | L25: =SUM(L21+L24) -> 27759 | M25: =SUM(M21+M24) -> 38932 | N25: =SUM(N21+N24) -> 31216 | O25: =SUM(O21+O24) -> 26050 | P25: =SUM(P21+P24) -> 29622 | ... W25: =SUM(W21+W24) -> 31032 | Y25: =SUM(Y21+Y24) -> 130541 | Z25: =SUM(Z21+Z24) -> 125288 | AA25: =SUM(AA21+AA24) -> 123788 | AB25: =SUM(AB21+AB24) -> 123957 | AC25: =SUM(AC21+AC24) -> 125820 | AD25: =SUM(AD21+AD24) -> 130109 | AE25: =SUM(AE21+AE24) -> 129629 | AF25: =SUM(AF21+AF24) -> 131781 | ... AJ25: =SUM(AJ21+AJ24) -> 141696 | AL25: =SUM(AJ25/AF25)-1 -> 0.075238464
B26: EBITDA Margin (%) | C26: =C25/C11 -> 0.28174781 | D26: =D25/D11 -> 0.3286698 | E26: =E25/E11 -> 0.33104674 | F26: =F25/F11 -> 0.32826748 | G26: =G25/G11 -> 0.34437071 | I26: =I25/I11 -> 0.35648877 | J26: =J25/J11 -> 0.33631448 | K26: =K25/K11 -> 0.31197338 | L26: =L25/L11 -> 0.3079338 | M26: =M25/M11 -> 0.33231473 | N26: =N25/N11 -> 0.3291577 | O26: =O25/O11 -> 0.31847134 | P26: =P25/P11 -> 0.33097946 | ... W26: =W25/W11 -> 0.33000128 | Y26: =Y25/Y11 -> 0.33104674 | Z26: =Z25/Z11 -> 0.323293 | AA26: =AA25/AA11 -> 0.32144795 | AB26: =AB25/AB11 -> 0.32286102 | AC26: =AC25/AC11 -> 0.32826748 | AD26: =AD25/AD11 -> 0.33732688 | AE26: =AE25/AE11 -> 0.33967816 | AF26: =AF25/AF11 -> 0.34175305 | ... AJ26: =AJ25/AJ11 -> 0.34676292 | AL26: =SUM(AJ26-AF26)*10000 -> 50.098779
B28: (+) Share-based Compensation | C28: ='Base Financials'!G74 -> 6829 | D28: ='Base Financials'!H74 -> 7906 | E28: ='Base Financials'!I74 -> 9038 | F28: ='Base Financials'!J74 -> 10833 | G28: ='Base Financials'!K74 -> 11688 | I28: ='Base Financials'!M74 -> 2265 | J28: ='Base Financials'!N74 -> 2252 | K28: ='Base Financials'!O74 -> 2243 | L28: ='Base Financials'!P74 -> 2278 | M28: ='Base Financials'!Q74 -> 2905 | N28: ='Base Financials'!R74 -> 2686 | O28: ='Base Financials'!S74 -> 2617 | P28: ='Base Financials'!T74 -> 2625 | ... W28: ='Base Financials'!AA74 -> 3168 | Y28: =SUM(I28:L28) -> 9038 | Z28: =SUM(J28:M28) -> 9678 | AA28: =SUM(K28:N28) -> 10112 | AB28: =SUM(L28:O28) -> 10486 | AC28: =SUM(M28:P28) -> 10833 | AD28: =SUM(N28:Q28) -> 10925 | AE28: =SUM(O28:R28) -> 11206 | AF28: =SUM(P28:S28) -> 11455 | ... AJ28: =SUM(T28:W28) -> 12538 | AL28: =SUM(AJ28/AF28)-1 -> 0.094543867
B29: Adj. EBITDA | C29: =+SUM(C25+SUM(C28:C28)) -> 84173 | D29: =+SUM(D25+SUM(D28:D28)) -> 128139 | E29: =+SUM(E25+SUM(E28:E28)) -> 139579 | F29: =+SUM(F25+SUM(F28:F28)) -> 136653 | G29: =+SUM(G25+SUM(G28:G28)) -> 146349 | I29: =+SUM(I25+SUM(I28:I28)) -> 46450 | J29: =+SUM(J25+SUM(J28:J28)) -> 34968 | K29: =+SUM(K25+SUM(K28:K28)) -> 28124 | L29: =+SUM(L25+SUM(L28:L28)) -> 30037 | M29: =+SUM(M25+SUM(M28:M28)) -> 41837 | N29: =+SUM(N25+SUM(N28:N28)) -> 33902 | O29: =+SUM(O25+SUM(O28:O28)) -> 28667 | P29: =+SUM(P25+SUM(P28:P28)) -> 32247 | ... W29: =+SUM(W25+SUM(W28:W28)) -> 34200 | Y29: =+SUM(Y25+SUM(Y28:Y28)) -> 139579 | Z29: =+SUM(Z25+SUM(Z28:Z28)) -> 134966 | AA29: =+SUM(AA25+SUM(AA28:AA28)) -> 133900 | AB29: =+SUM(AB25+SUM(AB28:AB28)) -> 134443 | AC29: =+SUM(AC25+SUM(AC28:AC28)) -> 136653 | AD29: =+SUM(AD25+SUM(AD28:AD28)) -> 141034 | AE29: =+SUM(AE25+SUM(AE28:AE28)) -> 140835 | AF29: =+SUM(AF25+SUM(AF28:AF28)) -> 143236 | ... AJ29: =+SUM(AJ25+SUM(AJ28:AJ28)) -> 154234 | AL29: =SUM(AJ29/AF29)-1 -> 0.076782373
B30: Adj. EBITDA Margin (%) | C30: =C29/C11 -> 0.30662441 | D30: =D29/D11 -> 0.3502817 | E30: =E29/E11 -> 0.35396675 | F30: =F29/F11 -> 0.35653104 | G30: =G29/G11 -> 0.37426062 | I30: =I29/I11 -> 0.374763 | J30: =J29/J11 -> 0.35946463 | K30: =K29/K11 -> 0.33901084 | L30: =L29/L11 -> 0.33320391 | M30: =M29/M11 -> 0.35711115 | N30: =N29/N11 -> 0.35748028 | O30: =O29/O11 -> 0.35046518 | P30: =P29/P11 -> 0.36030973 | ... W30: =W29/W11 -> 0.3636905 | Y30: =Y29/Y11 -> 0.35396675 | Z30: =Z29/Z11 -> 0.3482661 | AA30: =AA29/AA11 -> 0.34770641 | AB30: =AB29/AB11 -> 0.35017308 | AC30: =AC29/AC11 -> 0.35653104 | AD30: =AD29/AD11 -> 0.36565156 | AE30: =AE29/AE11 -> 0.36904222 | AF30: =AF29/AF11 -> 0.37145977 | ... AJ30: =AJ29/AJ11 -> 0.37744631 | AL30: =SUM(AJ30-AF30)*10000 -> 59.865482
B32: (-) Capital Expenditures | C32: ='Base Financials'!G88 -> -7309 | D32: ='Base Financials'!H88 -> -11085 | E32: ='Base Financials'!I88 -> -10708 | F32: ='Base Financials'!J88 -> -10959 | G32: ='Base Financials'!K88 -> -9447 | I32: ='Base Financials'!M88 -> -2803 | J32: ='Base Financials'!N88 -> -2514 | K32: ='Base Financials'!O88 -> -2102 | L32: ='Base Financials'!P88 -> -3289 | M32: ='Base Financials'!Q88 -> -3787 | N32: ='Base Financials'!R88 -> -2916 | O32: ='Base Financials'!S88 -> -2093 | P32: ='Base Financials'!T88 -> -2163 | ... W32: ='Base Financials'!AA88 -> -3462 | Y32: =SUM(I32:L32) -> -10708 | Z32: =SUM(J32:M32) -> -11692 | AA32: =SUM(K32:N32) -> -12094 | AB32: =SUM(L32:O32) -> -12085 | AC32: =SUM(M32:P32) -> -10959 | AD32: =SUM(N32:Q32) -> -9564 | AE32: =SUM(O32:R32) -> -8644 | AF32: =SUM(P32:S32) -> -8702 | ... AJ32: =SUM(T32:W32) -> -12381 | AL32: =SUM(AJ32/AF32)-1 -> 0.42277637
B33: (-) Cash Taxes | C33: =-'Base Financials'!G118 -> -9501 | D33: =-'Base Financials'!H118 -> -25385 | E33: =-'Base Financials'!I118 -> -19573 | F33: =-'Base Financials'!J118 -> -18679 | G33: =-'Base Financials'!K118 -> -26102 | I33: =-'Base Financials'!M118 -> -5235 | J33: =-'Base Financials'!N118 -> -4066 | K33: =-'Base Financials'!O118 -> -2950 | L33: =-'Base Financials'!P118 -> -7322 | M33: =-'Base Financials'!Q118 -> -828 | N33: =-'Base Financials'!R118 -> -4066 | O33: =-'Base Financials'!S118 -> -2126 | P33: =-'Base Financials'!T118 -> -11659 | ... W33: =-'Base Financials'!AA118 -> -5649 | Y33: =SUM(I33:L33) -> -19573 | Z33: =SUM(J33:M33) -> -15166 | AA33: =SUM(K33:N33) -> -15166 | AB33: =SUM(L33:O33) -> -14342 | AC33: =SUM(M33:P33) -> -18679 | AD33: =SUM(N33:Q33) -> -25106 | AE33: =SUM(O33:R33) -> -28316 | AF33: =SUM(P33:S33) -> -30889 | ... AJ33: =SUM(T33:W33) -> -44204 | AL33: =SUM(AJ33/AF33)-1 -> 0.4310596
B34: (-) Cash Interest | C34: =-'Base Financials'!G119 -> -3002 | D34: =-'Base Financials'!H119 -> -2687 | E34: =-'Base Financials'!I119 -> -2865 | F34: =-'Base Financials'!J119 -> -3803 | G34: =-'Base Financials'!K119 -> 0 | I34: =-'Base Financials'!M119 -> -531 | J34: =-'Base Financials'!N119 -> -875 | K34: =-'Base Financials'!O119 -> -504 | L34: =-'Base Financials'!P119 -> -955 | M34: =-'Base Financials'!Q119 -> -703 | N34: =-'Base Financials'!R119 -> -1170 | O34: =-'Base Financials'!S119 -> -717 | P34: =-'Base Financials'!T119 -> -1213 | ... W34: =-'Base Financials'!AA119 -> 0 | Y34: =SUM(I34:L34) -> -2865 | Z34: =SUM(J34:M34) -> -3037 | AA34: =SUM(K34:N34) -> -3332 | AB34: =SUM(L34:O34) -> -3545 | AC34: =SUM(M34:P34) -> -3803 | AD34: =SUM(N34:Q34) -> -3100 | AE34: =SUM(O34:R34) -> -1930 | AF34: =SUM(P34:S34) -> -1213 | ... AJ34: =SUM(T34:W34) -> 0 | AL34: =SUM(AJ34/AF34)-1 -> -1
