Workbook

Sheet Historical Financials
B2: Beyond Meat, Inc. (NASDAQ: BYND)
B3: Historical Financials
B4: $ mm except per share
A6: X | B6: Income Statement | G6: FYE | K6: Quarterly | AA6: Quarterly | AK6: Quarterly | AQ6: LTM | BE6: LTM | BF6: LTM | BL6: Variance
B7: Fiscal Period | C7: 2018 | D7: 2019 | E7: 2020 | F7: 2021 | G7: 2022 | H7: 2023 | I7: 2024 | K7: 1Q18 | L7: 2Q18 | M7: 3Q18 | N7: 4Q18 | O7: 1Q19 | P7: 2Q19 | Q7: 3Q19 | R7: 4Q19 | S7: 1Q20 | T7: 2Q20 | U7: 3Q20 | V7: 4Q20 | W7: 1Q21 | X7: 2Q21 | Y7: 3Q21 | Z7: 4Q21 | AA7: 1Q22 | AB7: 2Q22 | AC7: 3Q22 | AD7: 4Q22 | AE7: 1Q23 | AF7: 2Q23 | AG7: 3Q23 | AH7: 4Q23 | AI7: 1Q24 | AJ7: 2Q24 | AK7: 3Q24 | AL7: 4Q24 | AM7: 1Q25 | AN7: 2Q25 | AO7: 3Q25 | AQ7: =V7 -> 4Q20 | AR7: =W7 -> 1Q21 | AS7: =X7 -> 2Q21 | AT7: =Y7 -> 3Q21 | AU7: =Z7 -> 4Q21 | AV7: =AA7 -> 1Q22 | AW7: =AB7 -> 2Q22 | AX7: =AC7 -> 3Q22 | ... BJ7: =AO7 -> 3Q25
B8: Fiscal Period End Date | C8: 43465 | D8: 43830 | E8: 44196 | F8: 44561 | G8: 44926 | H8: 45291 | I8: 45657 | K8: 43190 | L8: 43281 | M8: 43372 | N8: 43465 | O8: 43554 | P8: 43645 | Q8: 43736 | R8: 43830 | S8: 43918 | T8: 44009 | U8: 44100 | V8: 44196 | W8: 44289 | X8: 44380 | Y8: 44471 | Z8: 44561 | AA8: 44653 | AB8: 44744 | AC8: 44835 | AD8: 44926 | AE8: 45017 | AF8: 45108 | AG8: 45199 | AH8: 45291 | AI8: 45381 | AJ8: 45472 | AK8: 45563 | AL8: 45657 | AM8: 45745 | AN8: 45836 | AO8: 45927 | AQ8: =V8 -> 44196 | AR8: =W8 -> 44289 | AS8: =X8 -> 44380 | AT8: =Y8 -> 44471 | AU8: =Z8 -> 44561 | AV8: =AA8 -> 44653 | AW8: =AB8 -> 44744 | AX8: =AC8 -> 44835 | ... BJ8: =AO8 -> 45927
B10: Consolidated Revenue | C10: 87934 | D10: 297897 | E10: 406785 | F10: 464700 | G10: 418933 | H10: 343376 | I10: 326452 | K10: 12776 | L10: 17367 | M10: 26277 | N10: =SUM(C10-SUM(K10:M10)) -> 31514 | O10: 40206 | P10: 67251 | Q10: 91961 | R10: =SUM(D10-SUM(O10:Q10)) -> 98479 | S10: 97074 | T10: 113338 | U10: 94436 | V10: =SUM(E10-SUM(S10:U10)) -> 101937 | W10: 108164 | X10: 149426 | Y10: 106432 | Z10: =SUM(F10-SUM(W10:Y10)) -> 100678 | AA10: 109455 | AB10: 147040 | AC10: 82500 | AD10: =SUM(G10-SUM(AA10:AC10)) -> 79938 | AE10: 92236 | AF10: 102149 | AG10: 75312 | AH10: =SUM(H10-SUM(AE10:AG10)) -> 73679 | AI10: 75603 | AJ10: 93185 | AK10: 81006 | AL10: =SUM(I10-SUM(AI10:AK10)) -> 76658 | AM10: 68731 | AN10: 74958 | AO10: 70218 | AQ10: =SUM(S10:V10) -> 406785 | AR10: =SUM(T10:W10) -> 417875 | AS10: =SUM(U10:X10) -> 453963 | AT10: =SUM(V10:Y10) -> 465959 | AU10: =SUM(W10:Z10) -> 464700 | AV10: =SUM(X10:AA10) -> 465991 | AW10: =SUM(Y10:AB10) -> 463605 | AX10: =SUM(Z10:AC10) -> 439673 | ... BJ10: =SUM(AL10:AO10) -> 290565 | BL10: =SUM(BI10/BE10)-1 -> -0.051690011
B11: Total Revenue | C11: =+SUM(C10:C10) -> 87934 | D11: =+SUM(D10:D10) -> 297897 | E11: =+SUM(E10:E10) -> 406785 | F11: =+SUM(F10:F10) -> 464700 | G11: =+SUM(G10:G10) -> 418933 | H11: =+SUM(H10:H10) -> 343376 | I11: =+SUM(I10:I10) -> 326452 | K11: =+SUM(K10:K10) -> 12776 | L11: =+SUM(L10:L10) -> 17367 | M11: =+SUM(M10:M10) -> 26277 | N11: =+SUM(N10:N10) -> 31514 | O11: =+SUM(O10:O10) -> 40206 | P11: =+SUM(P10:P10) -> 67251 | Q11: =+SUM(Q10:Q10) -> 91961 | R11: =+SUM(R10:R10) -> 98479 | ... AO11: =+SUM(AO10:AO10) -> 70218 | AQ11: =+SUM(AQ10:AQ10) -> 406785 | AR11: =+SUM(AR10:AR10) -> 417875 | AS11: =+SUM(AS10:AS10) -> 453963 | AT11: =+SUM(AT10:AT10) -> 465959 | AU11: =+SUM(AU10:AU10) -> 464700 | AV11: =+SUM(AV10:AV10) -> 465991 | AW11: =+SUM(AW10:AW10) -> 463605 | AX11: =+SUM(AX10:AX10) -> 439673 | ... BJ11: =+SUM(BJ10:BJ10) -> 290565 | BL11: =SUM(BI11/BE11)-1 -> -0.051690011
B13: Cost of Sales | C13: -70360 | D13: -198141 | E13: -284510 | F13: -347419 | G13: -442676 | H13: -426031 | I13: -284753 | K13: -10719 | L13: -14755 | M13: -21235 | N13: =SUM(C13-SUM(K13:M13)) -> -23651 | O13: -29435 | P13: -44510 | Q13: -59178 | R13: =SUM(D13-SUM(O13:Q13)) -> -65018 | S13: -59383 | T13: -79687 | U13: -68908 | V13: =SUM(E13-SUM(S13:U13)) -> -76532 | W13: -75456 | X13: -102074 | Y13: -83456 | Z13: =SUM(F13-SUM(W13:Y13)) -> -86433 | AA13: -109265 | AB13: -153202 | AC13: -97340 | AD13: =SUM(G13-SUM(AA13:AC13)) -> -82869 | AE13: -86051 | AF13: -99876 | AG13: -82566 | AH13: =SUM(H13-SUM(AE13:AG13)) -> -157538 | AI13: -71935 | AJ13: -79468 | AK13: -66698 | AL13: =SUM(I13-SUM(AI13:AK13)) -> -66652 | AM13: -69796 | AN13: -66367 | AO13: -62988 | AQ13: =SUM(S13:V13) -> -284510 | AR13: =SUM(T13:W13) -> -300583 | AS13: =SUM(U13:X13) -> -322970 | AT13: =SUM(V13:Y13) -> -337518 | AU13: =SUM(W13:Z13) -> -347419 | AV13: =SUM(X13:AA13) -> -381228 | AW13: =SUM(Y13:AB13) -> -432356 | AX13: =SUM(Z13:AC13) -> -446240 | ... BJ13: =SUM(AL13:AO13) -> -265803 | BL13: =SUM(BI13/BE13)-1 -> -0.31160107
B14: Gross Profit | C14: =+SUM(C11+SUM(C13:C13)) -> 17574 | D14: =+SUM(D11+SUM(D13:D13)) -> 99756 | E14: =+SUM(E11+SUM(E13:E13)) -> 122275 | F14: =+SUM(F11+SUM(F13:F13)) -> 117281 | G14: =+SUM(G11+SUM(G13:G13)) -> -23743 | H14: =+SUM(H11+SUM(H13:H13)) -> -82655 | I14: =+SUM(I11+SUM(I13:I13)) -> 41699 | K14: =+SUM(K11+SUM(K13:K13)) -> 2057 | L14: =+SUM(L11+SUM(L13:L13)) -> 2612 | M14: =+SUM(M11+SUM(M13:M13)) -> 5042 | N14: =+SUM(N11+SUM(N13:N13)) -> 7863 | O14: =+SUM(O11+SUM(O13:O13)) -> 10771 | P14: =+SUM(P11+SUM(P13:P13)) -> 22741 | Q14: =+SUM(Q11+SUM(Q13:Q13)) -> 32783 | R14: =+SUM(R11+SUM(R13:R13)) -> 33461 | ... AO14: =+SUM(AO11+SUM(AO13:AO13)) -> 7230 | AQ14: =+SUM(AQ11+SUM(AQ13:AQ13)) -> 122275 | AR14: =+SUM(AR11+SUM(AR13:AR13)) -> 117292 | AS14: =+SUM(AS11+SUM(AS13:AS13)) -> 130993 | AT14: =+SUM(AT11+SUM(AT13:AT13)) -> 128441 | AU14: =+SUM(AU11+SUM(AU13:AU13)) -> 117281 | AV14: =+SUM(AV11+SUM(AV13:AV13)) -> 84763 | AW14: =+SUM(AW11+SUM(AW13:AW13)) -> 31249 | AX14: =+SUM(AX11+SUM(AX13:AX13)) -> -6567 | ... BJ14: =+SUM(BJ11+SUM(BJ13:BJ13)) -> 24762 | BL14: =SUM(BI14/BE14)-1 -> -1.4318576
B15: Gross Margin (%) | C15: =C14/C11 -> 0.19985444 | D15: =D14/D11 -> 0.33486742 | E15: =E14/E11 -> 0.30058876 | F15: =F14/F11 -> 0.25238003 | G15: =G14/G11 -> -0.056674934 | H15: =H14/H11 -> -0.2407128 | I15: =I14/I11 -> 0.12773394 | K15: =K14/K11 -> 0.16100501 | L15: =L14/L11 -> 0.15040018 | M15: =M14/M11 -> 0.19187883 | N15: =N14/N11 -> 0.24950816 | O15: =O14/O11 -> 0.26789534 | P15: =P14/P11 -> 0.33815111 | Q15: =Q14/Q11 -> 0.35648808 | R15: =R14/R11 -> 0.33977802 | ... AO15: =AO14/AO11 -> 0.10296505 | AQ15: =AQ14/AQ11 -> 0.30058876 | AR15: =AR14/AR11 -> 0.28068681 | AS15: =AS14/AS11 -> 0.28855435 | AT15: =AT14/AT11 -> 0.27564872 | AU15: =AU14/AU11 -> 0.25238003 | AV15: =AV14/AV11 -> 0.18189836 | AW15: =AW14/AW11 -> 0.067404364 | AX15: =AX14/AX11 -> -0.0149361 | ... BJ15: =BJ14/BJ11 -> 0.085220174 | BL15: =SUM(BI15-BE15)*1000 -> 337.66712
B17: Selling, General & Administrative (SG&A) | C17: -34461 | D17: -74726 | E17: -133655 | F17: -209474 | G17: -239505 | H17: -220344 | I17: -169674 | K17: -5737 | L17: -7043 | M17: -10353 | N17: =SUM(C17-SUM(K17:M17)) -> -11328 | O17: -11177 | P17: -15515 | Q17: -20944 | R17: =SUM(D17-SUM(O17:Q17)) -> -27090 | S17: -27315 | T17: -34292 | U17: -33560 | V17: =SUM(E17-SUM(S17:U17)) -> -38488 | W17: -38954 | X17: -48286 | Y17: -56362 | Z17: =SUM(F17-SUM(W17:Y17)) -> -65872 | AA17: -75114 | AB17: -63015 | AC17: -54495 | AD17: =SUM(G17-SUM(AA17:AC17)) -> -46881 | AE17: -51900 | AF17: -47455 | AG17: -53252 | AH17: =SUM(H17-SUM(AE17:AG17)) -> -67737 | AI17: -47282 | AJ17: -42163 | AK17: -39084 | AL17: =SUM(I17-SUM(AI17:AK17)) -> -41145 | AM17: -47672 | AN17: -37696 | AO17: -37230 | AQ17: =SUM(S17:V17) -> -133655 | AR17: =SUM(T17:W17) -> -145294 | AS17: =SUM(U17:X17) -> -159288 | AT17: =SUM(V17:Y17) -> -182090 | AU17: =SUM(W17:Z17) -> -209474 | AV17: =SUM(X17:AA17) -> -245634 | AW17: =SUM(Y17:AB17) -> -260363 | AX17: =SUM(Z17:AC17) -> -258496 | ... BJ17: =SUM(AL17:AO17) -> -163743 | BL17: =SUM(BI17/BE17)-1 -> -0.21306918
B18: Research & Development (R&D) | C18: -9587 | D18: -20650 | E18: -31535 | F18: -66946 | G18: -62264 | H18: -39530 | I18: -28149 | K18: -1605 | L18: -2497 | M18: -2165 | N18: =SUM(C18-SUM(K18:M18)) -> -3320 | O18: -4498 | P18: -4212 | Q18: -5951 | R18: =SUM(D18-SUM(O18:Q18)) -> -5989 | S18: -6194 | T18: -6016 | U18: -8278 | V18: =SUM(E18-SUM(S18:U18)) -> -11047 | W18: -15925 | X18: -13823 | Y18: -14862 | Z18: =SUM(F18-SUM(W18:Y18)) -> -22336 | AA18: -19678 | AB18: -16202 | AC18: -13413 | AD18: =SUM(G18-SUM(AA18:AC18)) -> -12971 | AE18: -12432 | AF18: -8773 | AG18: -9118 | AH18: =SUM(H18-SUM(AE18:AG18)) -> -9207 | AI18: -9860 | AJ18: -5485 | AK18: -6133 | AL18: =SUM(I18-SUM(AI18:AK18)) -> -6671 | AM18: -7462 | AN18: -5807 | AO18: -4917 | AQ18: =SUM(S18:V18) -> -31535 | AR18: =SUM(T18:W18) -> -41266 | AS18: =SUM(U18:X18) -> -49073 | AT18: =SUM(V18:Y18) -> -55657 | AU18: =SUM(W18:Z18) -> -66946 | AV18: =SUM(X18:AA18) -> -70699 | AW18: =SUM(Y18:AB18) -> -73078 | AX18: =SUM(Z18:AC18) -> -71629 | ... BJ18: =SUM(AL18:AO18) -> -24857 | BL18: =SUM(BI18/BE18)-1 -> -0.22563113
B19: Restructuring Charges & Other Impairments | C19: =-1515-1128 -> -2643 | D19: -4869 | E19: -6430 | F19: -15794 | G19: -17259 | H19: 631 | I19: 0 | K19: =-47-294 -> -341 | L19: =-28-348 -> -376 | M19: =-313-528 -> -841 | N19: =SUM(C19-SUM(K19:M19)) -> -1085 | O19: =-733-394 -> -1127 | P19: =-741-847 -> -1588 | Q19: =-855-2319 -> -3174 | R19: =SUM(D19-SUM(O19:Q19)) -> 1020 | S19: -2373 | T19: -1509 | U19: -2146 | V19: =SUM(E19-SUM(S19:U19)) -> -402 | W19: -2474 | X19: -3844 | Y19: -5750 | Z19: =SUM(F19-SUM(W19:Y19)) -> -3726 | AA19: -3026 | AB19: -4302 | AC19: -6993 | AD19: =SUM(G19-SUM(AA19:AC19)) -> -2938 | AE19: 426 | AF19: 201 | AG19: 4 | AH19: =SUM(H19-SUM(AE19:AG19)) -> 0 | AI19: 0 | AJ19: 0 | AK19: 0 | AL19: =SUM(I19-SUM(AI19:AK19)) -> 0 | AM19: 0 | AN19: 0 | AO19: -77414 | AQ19: =SUM(S19:V19) -> -6430 | AR19: =SUM(T19:W19) -> -6531 | AS19: =SUM(U19:X19) -> -8866 | AT19: =SUM(V19:Y19) -> -12470 | AU19: =SUM(W19:Z19) -> -15794 | AV19: =SUM(X19:AA19) -> -16346 | AW19: =SUM(Y19:AB19) -> -16804 | AX19: =SUM(Z19:AC19) -> -18047 | ... BJ19: =SUM(AL19:AO19) -> -77414
B20: Operating Profit | C20: =+SUM(C14+SUM(C17:C19)) -> -29117 | D20: =+SUM(D14+SUM(D17:D19)) -> -489 | E20: =+SUM(E14+SUM(E17:E19)) -> -49345 | F20: =+SUM(F14+SUM(F17:F19)) -> -174933 | G20: =+SUM(G14+SUM(G17:G19)) -> -342771 | H20: =+SUM(H14+SUM(H17:H19)) -> -341898 | I20: =+SUM(I14+SUM(I17:I19)) -> -156124 | K20: =+SUM(K14+SUM(K17:K19)) -> -5626 | L20: =+SUM(L14+SUM(L17:L19)) -> -7304 | M20: =+SUM(M14+SUM(M17:M19)) -> -8317 | N20: =+SUM(N14+SUM(N17:N19)) -> -7870 | O20: =+SUM(O14+SUM(O17:O19)) -> -6031 | P20: =+SUM(P14+SUM(P17:P19)) -> 1426 | Q20: =+SUM(Q14+SUM(Q17:Q19)) -> 2714 | R20: =+SUM(R14+SUM(R17:R19)) -> 1402 | ... AO20: =+SUM(AO14+SUM(AO17:AO19)) -> -112331 | AQ20: =+SUM(AQ14+SUM(AQ17:AQ19)) -> -49345 | AR20: =+SUM(AR14+SUM(AR17:AR19)) -> -75799 | AS20: =+SUM(AS14+SUM(AS17:AS19)) -> -86234 | AT20: =+SUM(AT14+SUM(AT17:AT19)) -> -121776 | AU20: =+SUM(AU14+SUM(AU17:AU19)) -> -174933 | AV20: =+SUM(AV14+SUM(AV17:AV19)) -> -247916 | AW20: =+SUM(AW14+SUM(AW17:AW19)) -> -318996 | AX20: =+SUM(AX14+SUM(AX17:AX19)) -> -354739 | ... BJ20: =+SUM(BJ14+SUM(BJ17:BJ19)) -> -241252 | BL20: =SUM(BI20/BE20)-1 -> -0.49711794
B21: Operating Margin (%) | C21: =C20/C11 -> -0.33112334 | D21: =D20/D11 -> -0.001641507 | E21: =E20/E11 -> -0.12130487 | F21: =F20/F11 -> -0.37644287 | G21: =G20/G11 -> -0.81820005 | H21: =H20/H11 -> -0.99569568 | I21: =I20/I11 -> -0.47824489 | K21: =K20/K11 -> -0.44035692 | L21: =L20/L11 -> -0.42056774 | M21: =M20/M11 -> -0.31651254 | N21: =N20/N11 -> -0.24973028 | O21: =O20/O11 -> -0.15000249 | P21: =P20/P11 -> 0.021204146 | Q21: =Q20/Q11 -> 0.029512511 | R21: =R20/R11 -> 0.014236538 | ... AO21: =AO20/AO11 -> -1.5997465 | AQ21: =AQ20/AQ11 -> -0.12130487 | AR21: =AR20/AR11 -> -0.18139156 | AS21: =AS20/AS11 -> -0.18995821 | AT21: =AT20/AT11 -> -0.26134488 | AU21: =AU20/AU11 -> -0.37644287 | AV21: =AV20/AV11 -> -0.53201886 | AW21: =AW20/AW11 -> -0.68807713 | AX21: =AX20/AX11 -> -0.80682462 | ... BJ21: =BJ20/BJ11 -> -0.83028582
B23: Interest Expense | C23: 352 | D23: -3071 | E23: -2576 | F23: -3648 | G23: -3966 | H23: -3955 | I23: -4097 | K23: -70 | L23: 38 | M23: -31 | N23: =SUM(C23-SUM(K23:M23)) -> 415 | O23: 141 | P23: 898 | Q23: 0 | R23: =SUM(D23-SUM(O23:Q23)) -> -4110 | S23: -705 | T23: -569 | U23: -689 | V23: =SUM(E23-SUM(S23:U23)) -> -613 | W23: -629 | X23: -1022 | Y23: -1005 | Z23: =SUM(F23-SUM(W23:Y23)) -> -992 | AA23: -1025 | AB23: -1108 | AC23: -1040 | AD23: =SUM(G23-SUM(AA23:AC23)) -> -793 | AE23: -989 | AF23: -989 | AG23: -989 | AH23: =SUM(H23-SUM(AE23:AG23)) -> -988 | AI23: -1015 | AJ23: -1029 | AK23: -1028 | AL23: =SUM(I23-SUM(AI23:AK23)) -> -1025 | AM23: -1024 | AN23: -2002 | AO23: -4418 | AQ23: =SUM(S23:V23) -> -2576 | AR23: =SUM(T23:W23) -> -2500 | AS23: =SUM(U23:X23) -> -2953 | AT23: =SUM(V23:Y23) -> -3269 | AU23: =SUM(W23:Z23) -> -3648 | AV23: =SUM(X23:AA23) -> -4044 | AW23: =SUM(Y23:AB23) -> -4130 | AX23: =SUM(Z23:AC23) -> -4165 | ... BJ23: =SUM(AL23:AO23) -> -8469 | BL23: =SUM(BI23/BE23)-1 -> 0.26311863
B24: Other, Net | C24: -1120 | D24: 3629 | E24: -759 | F24: -487 | G24: -420 | H24: 11616 | I24: -10 | K24: 0 | L24: 0 | M24: 0 | N24: =SUM(C24-SUM(K24:M24)) -> -1120 | O24: 0 | P24: 0 | Q24: 1385 | R24: =SUM(D24-SUM(O24:Q24)) -> 2244 | S24: 0 | T24: 0 | U24: 0 | V24: =SUM(E24-SUM(S24:U24)) -> -759 | W24: 0 | X24: 0 | Y24: 0 | Z24: =SUM(F24-SUM(W24:Y24)) -> -487 | AA24: 0 | AB24: 0 | AC24: 0 | AD24: =SUM(G24-SUM(AA24:AC24)) -> -420 | AE24: 0 | AF24: 0 | AG24: 0 | AH24: =SUM(H24-SUM(AE24:AG24)) -> 11616 | AI24: 0 | AJ24: 0 | AK24: 0 | AL24: =SUM(I24-SUM(AI24:AK24)) -> -10 | AM24: 0 | AN24: 0 | AO24: 750 | AQ24: =SUM(S24:V24) -> -759 | AR24: =SUM(T24:W24) -> -759 | AS24: =SUM(U24:X24) -> -759 | AT24: =SUM(V24:Y24) -> -759 | AU24: =SUM(W24:Z24) -> -487 | AV24: =SUM(X24:AA24) -> -487 | AW24: =SUM(Y24:AB24) -> -487 | AX24: =SUM(Z24:AC24) -> -487 | ... BJ24: =SUM(AL24:AO24) -> 740 | BL24: =SUM(BI24/BE24)-1 -> -1.0008609
B25: Remeasurement of Warrant Liability | C25: 0 | D25: -12503 | E25: 0 | F25: 0 | G25: 0 | H25: 0 | I25: 0 | K25: 0 | L25: -130 | M25: -994 | N25: =SUM(C25-SUM(K25:M25)) -> 1124 | O25: -759 | P25: -11744 | Q25: 0 | R25: =SUM(D25-SUM(O25:Q25)) -> 0 | S25: 710 | T25: -1454 | U25: -85 | V25: =SUM(E25-SUM(S25:U25)) -> 829 | W25: -1570 | X25: 180 | Y25: 759 | Z25: =SUM(F25-SUM(W25:Y25)) -> 631 | AA25: -1124 | AB25: -4902 | AC25: -2151 | AD25: =SUM(G25-SUM(AA25:AC25)) -> 8177 | AE25: 2908 | AF25: 1746 | AG25: 243 | AH25: =SUM(H25-SUM(AE25:AG25)) -> -4897 | AI25: 123 | AJ25: 477 | AK25: 5405 | AL25: =SUM(I25-SUM(AI25:AK25)) -> -6005 | AM25: 4318 | AN25: 7731 | AO25: 5318 | AQ25: =SUM(S25:V25) -> 0 | AR25: =SUM(T25:W25) -> -2280 | AS25: =SUM(U25:X25) -> -646 | AT25: =SUM(V25:Y25) -> 198 | AU25: =SUM(W25:Z25) -> 0 | AV25: =SUM(X25:AA25) -> 446 | AW25: =SUM(Y25:AB25) -> -4636 | AX25: =SUM(Z25:AC25) -> -7546 | ... BJ25: =SUM(AL25:AO25) -> 11362 | BL25: =SUM(BI25/BE25)-1 -> -3.8241243
B26: Earning Before Taxes | C26: =SUM(C20+SUM(C23:C25)) -> -29885 | D26: =SUM(D20+SUM(D23:D25)) -> -12434 | E26: =SUM(E20+SUM(E23:E25)) -> -52680 | F26: =SUM(F20+SUM(F23:F25)) -> -179068 | G26: =SUM(G20+SUM(G23:G25)) -> -347157 | H26: =SUM(H20+SUM(H23:H25)) -> -334237 | I26: =SUM(I20+SUM(I23:I25)) -> -160231 | K26: =SUM(K20+SUM(K23:K25)) -> -5696 | L26: =SUM(L20+SUM(L23:L25)) -> -7396 | M26: =SUM(M20+SUM(M23:M25)) -> -9342 | N26: =SUM(N20+SUM(N23:N25)) -> -7451 | O26: =SUM(O20+SUM(O23:O25)) -> -6649 | P26: =SUM(P20+SUM(P23:P25)) -> -9420 | Q26: =SUM(Q20+SUM(Q23:Q25)) -> 4099 | R26: =SUM(R20+SUM(R23:R25)) -> -464 | ... AO26: =SUM(AO20+SUM(AO23:AO25)) -> -110681 | AQ26: =SUM(AQ20+SUM(AQ23:AQ25)) -> -52680 | AR26: =SUM(AR20+SUM(AR23:AR25)) -> -81338 | AS26: =SUM(AS20+SUM(AS23:AS25)) -> -90592 | AT26: =SUM(AT20+SUM(AT23:AT25)) -> -125606 | AU26: =SUM(AU20+SUM(AU23:AU25)) -> -179068 | AV26: =SUM(AV20+SUM(AV23:AV25)) -> -252001 | AW26: =SUM(AW20+SUM(AW23:AW25)) -> -328249 | AX26: =SUM(AX20+SUM(AX23:AX25)) -> -366937 | ... BJ26: =SUM(BJ20+SUM(BJ23:BJ25)) -> -237619 | BL26: =SUM(BI26/BE26)-1 -> -0.51168836
B27: EBT Margin (%) | C27: =C26/C11 -> -0.33985717 | D27: =D26/D11 -> -0.041739259 | E27: =E26/E11 -> -0.1295033 | F27: =F26/F11 -> -0.38534108 | G27: =G26/G11 -> -0.8286695 | H27: =H26/H11 -> -0.97338486 | I27: =I26/I11 -> -0.4908256 | K27: =K26/K11 -> -0.44583594 | L27: =L26/L11 -> -0.42586515 | M27: =M26/M11 -> -0.35552004 | N27: =N26/N11 -> -0.2364346 | O27: =O26/O11 -> -0.16537333 | P27: =P26/P11 -> -0.14007227 | Q27: =Q26/Q11 -> 0.044573243 | R27: =R26/R11 -> -0.0047116644 | ... AO27: =AO26/AO11 -> -1.5762483 | AQ27: =AQ26/AQ11 -> -0.1295033 | AR27: =AR26/AR11 -> -0.19464672 | AS27: =AS26/AS11 -> -0.19955811 | AT27: =AT26/AT11 -> -0.26956449 | AU27: =AU26/AU11 -> -0.38534108 | AV27: =AV26/AV11 -> -0.54078512 | AW27: =AW26/AW11 -> -0.70803594 | AX27: =AX26/AX11 -> -0.83456796 | ... BJ27: =BJ26/BJ11 -> -0.8177826 | BL27: =SUM(BI27-BE27)*1000 -> 479.74137
B29: Provision for taxes | C29: -1 | D29: -9 | E29: -72 | F29: -60 | G29: -32 | H29: -5 | I29: 26 | K29: 0 | L29: 0 | M29: 0 | N29: =SUM(C29-SUM(K29:M29)) -> -1 | O29: 0 | P29: -21 | Q29: 0 | R29: =SUM(D29-SUM(O29:Q29)) -> 12 | S29: 1 | T29: -16 | U29: -55 | V29: =SUM(E29-SUM(S29:U29)) -> -2 | W29: -48 | X29: -2 | Y29: 23 | Z29: =SUM(F29-SUM(W29:Y29)) -> -33 | AA29: -10 | AB29: -11 | AC29: 0 | AD29: =SUM(G29-SUM(AA29:AC29)) -> -11 | AE29: 0 | AF29: -5 | AG29: 0 | AH29: =SUM(H29-SUM(AE29:AG29)) -> 0 | AI29: -2 | AJ29: 34 | AK29: -6 | AL29: =SUM(I29-SUM(AI29:AK29)) -> 0 | AM29: 0 | AN29: 0 | AO29: 0 | AQ29: =SUM(S29:V29) -> -72 | AR29: =SUM(T29:W29) -> -121 | AS29: =SUM(U29:X29) -> -107 | AT29: =SUM(V29:Y29) -> -29 | AU29: =SUM(W29:Z29) -> -60 | AV29: =SUM(X29:AA29) -> -22 | AW29: =SUM(Y29:AB29) -> -31 | AX29: =SUM(Z29:AC29) -> -54 | ... BJ29: =SUM(AL29:AO29) -> 0 | BL29: =SUM(BI29/BE29)-1 -> -1.1875
B30: Equity in Losses of Unconsolidated Joint Venture | C30: 0 | D30: 0 | E30: 0 | F30: -2977 | G30: -18948 | H30: -3902 | I30: -73 | K30: 0 | L30: 0 | M30: 0 | N30: =SUM(C30-SUM(K30:M30)) -> 0 | O30: 0 | P30: 0 | Q30: 0 | R30: =SUM(D30-SUM(O30:Q30)) -> 0 | S30: 0 | T30: 0 | U30: 0 | V30: =SUM(E30-SUM(S30:U30)) -> 0 | W30: -374 | X30: -207 | Y30: -595 | Z30: -1801 | AA30: -671 | AB30: -1432 | AC30: -8746 | AD30: -8099 | AE30: -3235 | AF30: -503 | AG30: -126 | AH30: -38 | AI30: 7 | AJ30: -30 | AK30: -38 | AL30: -12 | AM30: -11 | AN30: -59 | AO30: -7 | AQ30: =SUM(S30:V30) -> 0 | AR30: =SUM(T30:W30) -> -374 | AS30: =SUM(U30:X30) -> -581 | AT30: =SUM(V30:Y30) -> -1176 | AU30: =SUM(W30:Z30) -> -2977 | AV30: =SUM(X30:AA30) -> -3274 | AW30: =SUM(Y30:AB30) -> -4499 | AX30: =SUM(Z30:AC30) -> -12650 | ... BJ30: =SUM(AL30:AO30) -> -89
B31: Net loss | C31: =SUM(C26+SUM(C29:C30)) -> -29886 | D31: =SUM(D26+SUM(D29:D30)) -> -12443 | E31: =SUM(E26+SUM(E29:E30)) -> -52752 | F31: =SUM(F26+SUM(F29:F30)) -> -182105 | G31: =SUM(G26+SUM(G29:G30)) -> -366137 | H31: =SUM(H26+SUM(H29:H30)) -> -338144 | I31: =SUM(I26+SUM(I29:I30)) -> -160278 | K31: =SUM(K26+SUM(K29:K30)) -> -5696 | L31: =SUM(L26+SUM(L29:L30)) -> -7396 | M31: =SUM(M26+SUM(M29:M30)) -> -9342 | N31: =SUM(N26+SUM(N29:N30)) -> -7452 | O31: =SUM(O26+SUM(O29:O30)) -> -6649 | P31: =SUM(P26+SUM(P29:P30)) -> -9441 | Q31: =SUM(Q26+SUM(Q29:Q30)) -> 4099 | R31: =SUM(R26+SUM(R29:R30)) -> -452 | ... AO31: =SUM(AO26+SUM(AO29:AO30)) -> -110688 | AQ31: =SUM(AQ26+SUM(AQ29:AQ30)) -> -52752 | AR31: =SUM(AR26+SUM(AR29:AR30)) -> -81833 | AS31: =SUM(AS26+SUM(AS29:AS30)) -> -91280 | AT31: =SUM(AT26+SUM(AT29:AT30)) -> -126811 | AU31: =SUM(AU26+SUM(AU29:AU30)) -> -182105 | AV31: =SUM(AV26+SUM(AV29:AV30)) -> -255297 | AW31: =SUM(AW26+SUM(AW29:AW30)) -> -332779 | AX31: =SUM(AX26+SUM(AX29:AX30)) -> -379641 | ... BJ31: =SUM(BJ26+SUM(BJ29:BJ30)) -> -237708 | BL31: =SUM(BI31/BE31)-1 -> -0.51152836
B32: Net Margin (%) | C32: =C31/C11 -> -0.33986854 | D32: =D31/D11 -> -0.041769471 | E32: =E31/E11 -> -0.1296803 | F32: =F31/F11 -> -0.39187648 | G32: =G31/G11 -> -0.87397507 | H32: =H31/H11 -> -0.98476306 | I32: =I31/I11 -> -0.49096958 | K32: =K31/K11 -> -0.44583594 | L32: =L31/L11 -> -0.42586515 | M32: =M31/M11 -> -0.35552004 | N32: =N31/N11 -> -0.23646633 | O32: =O31/O11 -> -0.16537333 | P32: =P31/P11 -> -0.14038453 | Q32: =Q31/Q11 -> 0.044573243 | R32: =R31/R11 -> -0.004589811 | ... AO32: =AO31/AO11 -> -1.5763479 | AQ32: =AQ31/AQ11 -> -0.1296803 | AR32: =AR31/AR11 -> -0.19583129 | AS32: =AS31/AS11 -> -0.20107366 | AT32: =AT31/AT11 -> -0.27215055 | AU32: =AU31/AU11 -> -0.39187648 | AV32: =AV31/AV11 -> -0.54785822 | AW32: =AW31/AW11 -> -0.71780718 | AX32: =AX31/AX11 -> -0.86346216 | ... BJ32: =BJ31/BJ11 -> -0.8180889 | BL32: =SUM(BI32-BE32)*1000 -> 479.81102
B34: Basic shares | C34: 0 | D34: 61845.096 | E34: 62940.338 | F34: 63455.45 | G34: 64094.519 | H34: 64677.261 | I34: 76131.339 | M34: 6441.838 | N34: =D34 -> 61845.096 | O34: 60122.797 | P34: 60178.252 | Q34: 60415.866 | R34: =H34 -> 64677.261 | S34: 61679.929 | T34: 62098.861 | U34: 62487.152 | V34: =E34 -> 62940.338 | W34: 62941.748 | X34: 63121.4 | Y34: 63280.122 | Z34: =F34 -> 63455.45 | AA34: 63465.205 | AB34: 63573.658 | AC34: 63694.592 | AD34: =G34 -> 64094.519 | AE34: 64004.894 | AF34: 64246.048 | AG34: 64398.448 | AH34: =H34 -> 64677.261 | AI34: 64702.249 | AJ34: 64901.584 | AK34: 65060.729 | AL34: =I34 -> 76131.339 | AM34: 76194.916 | AN34: 76491.594 | AO34: 76670.868 | AQ34: =V34 -> 62940.338 | AR34: =W34 -> 62941.748 | AS34: =X34 -> 63121.4 | AT34: =Y34 -> 63280.122 | AU34: =Z34 -> 63455.45 | AV34: =AA34 -> 63465.205 | AW34: =AB34 -> 63573.658 | AX34: =AC34 -> 63694.592 | ... BJ34: =AO34 -> 76670.868
B35: Basic EPS | C35: =C31/C34 -> #DIV/0! | D35: =D31/D34 -> -0.20119623 | E35: =E31/E34 -> -0.83812705 | F35: =F31/F34 -> -2.8698087 | G35: =G31/G34 -> -5.7124541 | H35: =H31/H34 -> -5.2281744 | I35: =I31/I34 -> -2.1052828 | K35: =K31/K34 -> #DIV/0! | L35: =L31/L34 -> #DIV/0! | M35: =M31/M34 -> -1.4502072 | N35: =N31/N34 -> -0.1204946 | O35: =O31/O34 -> -0.11059033 | P35: =P31/P34 -> -0.15688392 | Q35: =Q31/Q34 -> 0.067846416 | R35: =R31/R34 -> -0.0069885458 | ... AO35: =AO31/AO34 -> -1.4436774 | AQ35: =AQ31/AQ34 -> -0.83812705 | AR35: =AR31/AR34 -> -1.3001387 | AS35: =AS31/AS34 -> -1.4461023 | AT35: =AT31/AT34 -> -2.0039626 | AU35: =AU31/AU34 -> -2.8698087 | AV35: =AV31/AV34 -> -4.0226294 | AW35: =AW31/AW34 -> -5.2345423 | AX35: =AX31/AX34 -> -5.9603333 | ... BJ35: =BJ31/BJ34 -> -3.1003692 | BL35: =SUM(BI35/BE35)-1 -> -0.5855416
B37: Fully Diluted Shares | C37: 6287.172 | D37: 42274.777 | E37: 62290.445 | F37: 63172.368 | G37: 63622.432 | H37: 64300.099 | I37: 66004.815 | K37: 5793.801 | L37: 6072.319 | M37: 6441.838 | N37: =D37 -> 42274.777 | O37: 6974.301 | P37: 39081.359 | Q37: 66026.49 | R37: =H37 -> 64300.099 | S37: 65927.988 | T37: 62098.861 | U37: 62487.152 | V37: =E37 -> 62290.445 | W37: 62941.748 | X37: 63121.4 | Y37: 63280.122 | Z37: =F37 -> 63172.368 | AA37: 63465.205 | AB37: 63573.658 | AC37: 63694.592 | AD37: =G37 -> 63622.432 | AE37: 64004.894 | AF37: 64246.048 | AG37: 64398.448 | AH37: =H37 -> 64300.099 | AI37: 64702.249 | AJ37: 64901.584 | AK37: 65060.729 | AL37: =I37 -> 66004.815 | AM37: 76194.916 | AN37: 76491.594 | AO37: 76670.868 | AQ37: =V37 -> 62290.445 | AR37: =W37 -> 62941.748 | AS37: =X37 -> 63121.4 | AT37: =Y37 -> 63280.122 | AU37: =Z37 -> 63172.368 | AV37: =AA37 -> 63465.205 | AW37: =AB37 -> 63573.658 | AX37: =AC37 -> 63694.592 | ... BJ37: =AO37 -> 76670.868
B38: Diluted EPS | C38: =C31/C37 -> -4.7534885 | D38: =D31/D37 -> -0.29433627 | E38: =E31/E37 -> -0.84687146 | F38: =F31/F37 -> -2.8826686 | G38: =G31/G37 -> -5.7548413 | H38: =H31/H37 -> -5.258841 | I38: =I31/I37 -> -2.4282774 | K38: =K31/K37 -> -0.98311972 | L38: =L31/L37 -> -1.2179861 | M38: =M31/M37 -> -1.4502072 | N38: =N31/N37 -> -0.17627532 | O38: =O31/O37 -> -0.95335719 | P38: =P31/P37 -> -0.24157297 | Q38: =Q31/Q37 -> 0.062081143 | R38: =R31/R37 -> -0.0070295382 | ... AO38: =AO31/AO37 -> -1.4436774 | AQ38: =AQ31/AQ37 -> -0.84687146 | AR38: =AR31/AR37 -> -1.3001387 | AS38: =AS31/AS37 -> -1.4461023 | AT38: =AT31/AT37 -> -2.0039626 | AU38: =AU31/AU37 -> -2.8826686 | AV38: =AV31/AV37 -> -4.0226294 | AW38: =AW31/AW37 -> -5.2345423 | AX38: =AX31/AX37 -> -5.9603333 | ... BJ38: =BJ31/BJ37 -> -3.1003692 | BL38: =SUM(BI38/BE38)-1 -> -0.5855416
A40: X | B40: Balance Sheet | K40: Quarterly | BE40: LTM | BL40: Variance
B41: =B7 -> Fiscal Period | C41: =C7 -> 2018 | D41: =D7 -> 2019 | E41: =E7 -> 2020 | F41: =F7 -> 2021 | G41: =G7 -> 2022 | H41: =H7 -> 2023 | I41: =I7 -> 2024 | K41: =K7 -> 1Q18 | L41: =L7 -> 2Q18 | M41: =M7 -> 3Q18 | N41: =N7 -> 4Q18 | O41: =O7 -> 1Q19 | P41: =P7 -> 2Q19 | Q41: =Q7 -> 3Q19 | R41: =R7 -> 4Q19 | ... AO41: =AO7 -> 3Q25 | AQ41: =AQ7 -> 4Q20 | AR41: =AR7 -> 1Q21 | AS41: =AS7 -> 2Q21 | AT41: =AT7 -> 3Q21 | AU41: =AU7 -> 4Q21 | AV41: =AV7 -> 1Q22 | AW41: =AW7 -> 2Q22 | AX41: =AX7 -> 3Q22 | ... BJ41: =BJ7 -> 3Q25
B42: =B8 -> Fiscal Period End Date | C42: =C8 -> 43465 | D42: =D8 -> 43830 | E42: =E8 -> 44196 | F42: =F8 -> 44561 | G42: =G8 -> 44926 | H42: =H8 -> 45291 | I42: =I8 -> 45657 | K42: =K8 -> 43190 | L42: =L8 -> 43281 | M42: =M8 -> 43372 | N42: =N8 -> 43465 | O42: =O8 -> 43554 | P42: =P8 -> 43645 | Q42: =Q8 -> 43736 | R42: =R8 -> 43830 | ... AO42: =AO8 -> 45927 | AQ42: =AQ8 -> 44196 | AR42: =AR8 -> 44289 | AS42: =AS8 -> 44380 | AT42: =AT8 -> 44471 | AU42: =AU8 -> 44561 | AV42: =AV8 -> 44653 | AW42: =AW8 -> 44744 | AX42: =AX8 -> 44835 | ... BJ42: =BJ8 -> 45927
B44: Current Assets
B45: Cash and Cash Equivalents | C45: 54271 | D45: 275988 | E45: 159127 | F45: 733294 | G45: 309922 | H45: 190505 | I45: 131913 | K45: 29047 | L45: 23489 | M45: 49780 | N45: =C45 -> 54271 | O45: 35409 | P45: 276987 | Q45: 312451 | R45: =D45 -> 275988 | S45: 246410 | T45: 222334 | U45: 214615 | V45: =E45 -> 159127 | W45: 1125017 | X45: 1009337 | Y45: 886442 | Z45: =F45 -> 733294 | AA45: 547858 | AB45: 454674 | AC45: 390176 | AD45: =G45 -> 309922 | AE45: 258566 | AF45: 210781 | AG45: 217545 | AH45: =H45 -> 190505 | AI45: 157913 | AJ45: 144873 | AK45: 121732 | AL45: =I45 -> 131913 | AM45: 102143 | AN45: 103497 | AO45: 117296 | AQ45: =V45 -> 159127 | AR45: =W45 -> 1125017 | AS45: =X45 -> 1009337 | AT45: =Y45 -> 886442 | AU45: =Z45 -> 733294 | AV45: =AA45 -> 547858 | AW45: =AB45 -> 454674 | AX45: =AC45 -> 390176 | ... BJ45: =AO45 -> 117296 | BL45: =SUM(BI45/BE45)-1 -> -0.28560187
B46: Restricted Cash | C46: 0 | D46: 0 | E46: 0 | F46: 0 | G46: 0 | H46: 2830 | I46: 1041 | N46: =C46 -> 0 | O46: 0 | P46: 0 | Q46: 0 | R46: =D46 -> 0 | S46: 0 | T46: 0 | U46: 0 | V46: =E46 -> 0 | W46: 0 | X46: 0 | Y46: 0 | Z46: =F46 -> 0 | AA46: 0 | AB46: 0 | AC46: 0 | AD46: =G46 -> 0 | AE46: 2426 | AF46: 2552 | AG46: 2689 | AH46: =H46 -> 2830 | AI46: 2971 | AJ46: 536 | AK46: 558 | AL46: =I46 -> 1041 | AM46: 1083 | AN46: 1172 | AO46: 1170 | AQ46: =V46 -> 0 | AR46: =W46 -> 0 | AS46: =X46 -> 0 | AT46: =Y46 -> 0 | AU46: =Z46 -> 0 | AV46: =AA46 -> 0 | AW46: =AB46 -> 0 | AX46: =AC46 -> 0 | ... BJ46: =AO46 -> 1170
B47: Accounts Receivables | C47: 12626 | D47: 40080 | E47: 35975 | F47: 43806 | G47: 34198 | H47: 31730 | I47: 26862 | N47: =C47 -> 12626 | O47: 16194 | P47: 34388 | Q47: 34482 | R47: =D47 -> 40080 | S47: 36333 | T47: 45986 | U47: 29760 | V47: =E47 -> 35975 | W47: 36653 | X47: 63369 | Y47: 48849 | Z47: =F47 -> 43806 | AA47: 52675 | AB47: 77154 | AC47: 34949 | AD47: =G47 -> 34198 | AE47: 42395 | AF47: 50821 | AG47: 35763 | AH47: =H47 -> 31730 | AI47: 35648 | AJ47: 34463 | AK47: 34674 | AL47: =I47 -> 26862 | AM47: 33267 | AN47: 37338 | AO47: 27920 | AQ47: =V47 -> 35975 | AR47: =W47 -> 36653 | AS47: =X47 -> 63369 | AT47: =Y47 -> 48849 | AU47: =Z47 -> 43806 | AV47: =AA47 -> 52675 | AW47: =AB47 -> 77154 | AX47: =AC47 -> 34949 | ... BJ47: =AO47 -> 27920 | BL47: =SUM(BI47/BE47)-1 -> 0.083422801
B48: Inventory | C48: 30257 | D48: 81596 | E48: 121717 | F48: 241870 | G48: 235696 | H48: 130336 | I48: 113444 | N48: =C48 -> 30257 | O48: 34281 | P48: 42695 | Q48: 60270 | R48: =D48 -> 81596 | S48: 120702 | T48: 143033 | U48: 132359 | V48: =E48 -> 121717 | W48: 145524 | X48: 165746 | Y48: 193490 | Z48: =F48 -> 241870 | AA48: 283754 | AB48: 254653 | AC48: 246987 | AD48: =G48 -> 235696 | AE48: 222370 | AF48: 207138 | AG48: 194570 | AH48: =H48 -> 130336 | AI48: 122538 | AJ48: 119532 | AK48: 125158 | AL48: =I48 -> 113444 | AM48: 100068 | AN48: 110868 | AO48: 110294 | AQ48: =V48 -> 121717 | AR48: =W48 -> 145524 | AS48: =X48 -> 165746 | AT48: =Y48 -> 193490 | AU48: =Z48 -> 241870 | AV48: =AA48 -> 283754 | AW48: =AB48 -> 254653 | AX48: =AC48 -> 246987 | ... BJ48: =AO48 -> 110294
B49: Prepaid Expenses and Other Current Assets (1) | C49: 5672 | D49: 5930 | E49: 15407 | F49: 33078 | G49: =20700+5943 -> 26643 | H49: =12904+4539 -> 17443 | I49: =11332+1864 -> 13196 | N49: =C49 -> 5672 | O49: 6525 | P49: 7726 | Q49: 11742 | R49: =D49 -> 5930 | S49: 12498 | T49: 17990 | U49: 14195 | V49: =E49 -> 15407 | W49: 17788 | X49: 25630 | Y49: 24341 | Z49: =F49 -> 33078 | AA49: 33010 | AB49: 33029 | AC49: 23868 | AD49: =G49 -> 26643 | AE49: =16561+4737 -> 21298 | AF49: =26051+98 -> 26149 | AG49: =20938+118 -> 21056 | AH49: =H49 -> 17443 | AI49: =15032+2401 -> 17433 | AJ49: =15538+2323 -> 17861 | AK49: =13016+2275 -> 15291 | AL49: =I49 -> 13196 | AM49: =19135+1576 -> 20711 | AN49: =42596+1664 -> 44260 | AO49: =31048+910 -> 31958 | AQ49: =V49 -> 15407 | AR49: =W49 -> 17788 | AS49: =X49 -> 25630 | AT49: =Y49 -> 24341 | AU49: =Z49 -> 33078 | AV49: =AA49 -> 33010 | AW49: =AB49 -> 33029 | AX49: =AC49 -> 23868 | ... BJ49: =AO49 -> 31958
B50: Total Current Assets | C50: =SUM(C45:C49) -> 102826 | D50: =SUM(D45:D49) -> 403594 | E50: =SUM(E45:E49) -> 332226 | F50: =SUM(F45:F49) -> 1052048 | G50: =SUM(G45:G49) -> 606459 | H50: =SUM(H45:H49) -> 372844 | I50: =SUM(I45:I49) -> 286456 | K50: =SUM(K45:K49) -> 29047 | L50: =SUM(L45:L49) -> 23489 | M50: =SUM(M45:M49) -> 49780 | N50: =SUM(N45:N49) -> 102826 | O50: =SUM(O45:O49) -> 92409 | P50: =SUM(P45:P49) -> 361796 | Q50: =SUM(Q45:Q49) -> 418945 | R50: =SUM(R45:R49) -> 403594 | ... AO50: =SUM(AO45:AO49) -> 288638 | AQ50: =SUM(AQ45:AQ49) -> 332226 | AR50: =SUM(AR45:AR49) -> 1324982 | AS50: =SUM(AS45:AS49) -> 1264082 | AT50: =SUM(AT45:AT49) -> 1153122 | AU50: =SUM(AU45:AU49) -> 1052048 | AV50: =SUM(AV45:AV49) -> 917297 | AW50: =SUM(AW45:AW49) -> 819510 | AX50: =SUM(AX45:AX49) -> 695980 | ... BJ50: =SUM(BJ45:BJ49) -> 288638 | BL50: =SUM(BI50/BE50)-1 -> -0.063448537
B52: Non-Current Assets | BL52: =SUM(BI52/BE52)-1 -> #DIV/0!
...

Sheet Revenue Drivers
B2: Beyond Meat, Inc. (NASDAQ: BYND) | C2: FYE | G2: FYE | K2: Quarterly | S2: Quarterly | T2: Quarterly | AA2: LTM | AE2: LTM | AG2: LTM | AM2: Variance
B3: Segment Anaysis | C3: ='Historical Financials'!C7 -> 2018 | D3: ='Historical Financials'!D7 -> 2019 | E3: ='Historical Financials'!E7 -> 2020 | F3: ='Historical Financials'!F7 -> 2021 | G3: ='Historical Financials'!G7 -> 2022 | H3: ='Historical Financials'!H7 -> 2023 | I3: ='Historical Financials'!I7 -> 2024 | K3: ='Historical Financials'!AA7 -> 1Q22 | L3: ='Historical Financials'!AB7 -> 2Q22 | M3: ='Historical Financials'!AC7 -> 3Q22 | N3: ='Historical Financials'!AD7 -> 4Q22 | O3: ='Historical Financials'!AE7 -> 1Q23 | P3: ='Historical Financials'!AF7 -> 2Q23 | Q3: ='Historical Financials'!AG7 -> 3Q23 | R3: ='Historical Financials'!AH7 -> 4Q23 | ... Y3: ='Historical Financials'!AO7 -> 3Q25 | AA3: =O3 -> 1Q23 | AB3: =P3 -> 2Q23 | AC3: =Q3 -> 3Q23 | AD3: =R3 -> 4Q23 | AE3: =S3 -> 1Q24 | AF3: =T3 -> 2Q24 | AG3: =U3 -> 3Q24 | AH3: =V3 -> 4Q24 | ... AK3: =Y3 -> 3Q25
B4: $ mm except per share | C4: ='Historical Financials'!C8 -> 43465 | D4: ='Historical Financials'!D8 -> 43830 | E4: ='Historical Financials'!E8 -> 44196 | F4: ='Historical Financials'!F8 -> 44561 | G4: ='Historical Financials'!G8 -> 44926 | H4: ='Historical Financials'!H8 -> 45291 | I4: ='Historical Financials'!I8 -> 45657 | K4: ='Historical Financials'!AA8 -> 44653 | L4: ='Historical Financials'!AB8 -> 44744 | M4: ='Historical Financials'!AC8 -> 44835 | N4: ='Historical Financials'!AD8 -> 44926 | O4: ='Historical Financials'!AE8 -> 45017 | P4: ='Historical Financials'!AF8 -> 45108 | Q4: ='Historical Financials'!AG8 -> 45199 | R4: ='Historical Financials'!AH8 -> 45291 | ... Y4: ='Historical Financials'!AO8 -> 45927 | AA4: =O4 -> 45017 | AB4: =P4 -> 45108 | AC4: =Q4 -> 45199 | AD4: =R4 -> 45291 | AE4: =S4 -> 45381 | AF4: =T4 -> 45472 | AG4: =U4 -> 45563 | AH4: =V4 -> 45657 | ... AK4: =Y4 -> 45927
A6: X | B6: Net Revenues by Channel
B7: Retail | C7: =+C13+C18 -> 50779 | D7: =+D13+D18 -> 144809 | E7: =+E13+E18 -> 300583 | F7: =+F13+F18 -> 324843 | G7: =+G13+G18 -> 295651 | H7: =+H13+H18 -> 216963 | I7: =+I13+I18 -> 210595 | K7: =+K13+K18 -> 84397 | L7: =+L13+L18 -> 102553 | M7: =+M13+M18 -> 56372 | N7: =+N13+N18 -> 52329 | O7: =+O13+O18 -> 58448 | P7: =+P13+P18 -> 68485 | Q7: =+Q13+Q18 -> 44671 | R7: =+R13+R18 -> 45359 | ... Y7: =+Y13+Y18 -> 44347 | AA7: =SUM(L7:O7) -> 269702 | AB7: =SUM(M7:P7) -> 235634 | AC7: =SUM(N7:Q7) -> 223933 | AD7: =SUM(O7:R7) -> 216963 | AE7: =SUM(P7:S7) -> 208181 | AF7: =SUM(Q7:T7) -> 202150 | AG7: =SUM(R7:U7) -> 209013 | AH7: =SUM(S7:V7) -> 210595 | ... AK7: =SUM(V7:Y7) -> 184106 | AM7: =SUM(AK7/AG7)-1 -> -0.11916484
B8: Foodservice | C8: =+C14+C19 -> 37155 | D8: =+D14+D19 -> 153088 | E8: =+E14+E19 -> 106202 | F8: =+F14+F19 -> 139857 | G8: =+G14+G19 -> 123282 | H8: =+H14+H19 -> 126413 | I8: =+I14+I19 -> 115857 | K8: =+K14+K19 -> 25058 | L8: =+L14+L19 -> 44487 | M8: =+M14+M19 -> 26128 | N8: =+N14+N19 -> 27609 | O8: =+O14+O19 -> 33788 | P8: =+P14+P19 -> 33664 | Q8: =+Q14+Q19 -> 30641 | R8: =+R14+R19 -> 28320 | ... Y8: =+Y14+Y19 -> 25871 | AA8: =SUM(L8:O8) -> 132012 | AB8: =SUM(M8:P8) -> 121189 | AC8: =SUM(N8:Q8) -> 125702 | AD8: =SUM(O8:R8) -> 126413 | AE8: =SUM(P8:S8) -> 118562 | AF8: =SUM(Q8:T8) -> 115629 | AG8: =SUM(R8:U8) -> 114460 | AH8: =SUM(S8:V8) -> 115857 | ... AK8: =SUM(V8:Y8) -> 106459 | AM8: =SUM(AK8/AG8)-1 -> -0.069902149
B9: Total Net Revenue | C9: =SUM(C7:C8) -> 87934 | D9: =SUM(D7:D8) -> 297897 | E9: =SUM(E7:E8) -> 406785 | F9: =SUM(F7:F8) -> 464700 | G9: =SUM(G7:G8) -> 418933 | H9: =SUM(H7:H8) -> 343376 | I9: =SUM(I7:I8) -> 326452 | K9: =SUM(K7:K8) -> 109455 | L9: =SUM(L7:L8) -> 147040 | M9: =SUM(M7:M8) -> 82500 | N9: =SUM(N7:N8) -> 79938 | O9: =SUM(O7:O8) -> 92236 | P9: =SUM(P7:P8) -> 102149 | Q9: =SUM(Q7:Q8) -> 75312 | R9: =SUM(R7:R8) -> 73679 | ... Y9: =SUM(Y7:Y8) -> 70218 | AA9: =SUM(AA7:AA8) -> 401714 | AB9: =SUM(AB7:AB8) -> 356823 | AC9: =SUM(AC7:AC8) -> 349635 | AD9: =SUM(AD7:AD8) -> 343376 | AE9: =SUM(AE7:AE8) -> 326743 | AF9: =SUM(AF7:AF8) -> 317779 | AG9: =SUM(AG7:AG8) -> 323473 | AH9: =SUM(AH7:AH8) -> 326452 | ... AK9: =SUM(AK7:AK8) -> 290565 | AM9: =SUM(AK9/AG9)-1 -> -0.10173337
B10: Balance Check | C10: =+C9-'Historical Financials'!C11 -> 0 | D10: =+D9-'Historical Financials'!D11 -> 0 | E10: =+E9-'Historical Financials'!E11 -> 0 | F10: =+F9-'Historical Financials'!F11 -> 0 | G10: =+G9-'Historical Financials'!G11 -> 0 | H10: =+H9-'Historical Financials'!H11 -> 0 | I10: =+I9-'Historical Financials'!I11 -> 0 | K10: =K9-'Historical Financials'!AA11 -> 0 | L10: =L9-'Historical Financials'!AB11 -> 0 | M10: =M9-'Historical Financials'!AC11 -> 0 | N10: =N9-'Historical Financials'!AD11 -> 0 | O10: =O9-'Historical Financials'!AE11 -> 0 | P10: =P9-'Historical Financials'!AF11 -> 0 | Q10: =Q9-'Historical Financials'!AG11 -> 0 | R10: =R9-'Historical Financials'!AH11 -> 0 | ... Y10: =Y9-'Historical Financials'!AO11 -> 0 | AA10: =+AA9-'Historical Financials'!AZ11 -> 0 | AB10: =+AB9-'Historical Financials'!BA11 -> 0 | AC10: =+AC9-'Historical Financials'!BB11 -> 0 | AD10: =+AD9-'Historical Financials'!BC11 -> 0 | AE10: =+AE9-'Historical Financials'!BD11 -> 0 | AF10: =+AF9-'Historical Financials'!BE11 -> 0 | AG10: =+AG9-'Historical Financials'!BF11 -> 0 | AH10: =+AH9-'Historical Financials'!BG11 -> 0 | ... AK10: =+AK9-'Historical Financials'!BJ11 -> 0
A12: X | B12: Revenue by Channel: U.S
B13: Retail | C13: 49772 | D13: 129383 | E13: 264111 | F13: 243360 | G13: 234744 | H13: 155240 | I13: 150812 | K13: 68260 | L13: 78861 | M13: 46177 | N13: =SUM(G13-SUM(K13:M13)) -> 41446 | O13: 44159 | P13: 48490 | Q13: 30518 | R13: =SUM(H13-SUM(O13:Q13)) -> 32073 | S13: 37088 | T13: 44869 | U13: 34969 | V13: =SUM(I13-SUM(S13:U13)) -> 33886 | W13: 31360 | X13: 32909 | Y13: 28537 | AA13: =SUM(L13:O13) -> 210643 | AB13: =SUM(M13:P13) -> 180272 | AC13: =SUM(N13:Q13) -> 164613 | AD13: =SUM(O13:R13) -> 155240 | AE13: =SUM(P13:S13) -> 148169 | AF13: =SUM(Q13:T13) -> 144548 | AG13: =SUM(R13:U13) -> 148999 | AH13: =SUM(S13:V13) -> 150812 | ... AK13: =SUM(V13:Y13) -> 126692 | AM13: =SUM(AK13/AG13)-1 -> -0.14971241
B14: Foodservice | C14: 20717 | D14: 70372 | E14: 60763 | F14: 76475 | G14: 69289 | H14: 50647 | I14: 47584 | K14: 15493 | L14: 23389 | M14: 15994 | N14: =SUM(G14-SUM(K14:M14)) -> 14413 | O14: 14675 | P14: 12764 | Q14: 12535 | R14: =SUM(H14-SUM(O14:Q14)) -> 10673 | S14: 12304 | T14: 10350 | U14: 14478 | V14: =SUM(I14-SUM(S14:U14)) -> 10452 | W14: 9413 | X14: 11055 | Y14: 10524 | AA14: =SUM(L14:O14) -> 68471 | AB14: =SUM(M14:P14) -> 57846 | AC14: =SUM(N14:Q14) -> 54387 | AD14: =SUM(O14:R14) -> 50647 | AE14: =SUM(P14:S14) -> 48276 | AF14: =SUM(Q14:T14) -> 45862 | AG14: =SUM(R14:U14) -> 47805 | AH14: =SUM(S14:V14) -> 47584 | ... AK14: =SUM(V14:Y14) -> 41444 | AM14: =SUM(AK14/AG14)-1 -> -0.1330614
B15: Total Net U.S Revenue | C15: =SUM(C13:C14) -> 70489 | D15: =SUM(D13:D14) -> 199755 | E15: =SUM(E13:E14) -> 324874 | F15: =SUM(F13:F14) -> 319835 | G15: =SUM(G13:G14) -> 304033 | H15: =SUM(H13:H14) -> 205887 | I15: =SUM(I13:I14) -> 198396 | K15: =SUM(K13:K14) -> 83753 | L15: =SUM(L13:L14) -> 102250 | M15: =SUM(M13:M14) -> 62171 | N15: =SUM(N13:N14) -> 55859 | O15: =SUM(O13:O14) -> 58834 | P15: =SUM(P13:P14) -> 61254 | Q15: =SUM(Q13:Q14) -> 43053 | R15: =SUM(R13:R14) -> 42746 | ... Y15: =SUM(Y13:Y14) -> 39061 | AA15: =SUM(AA13:AA14) -> 279114 | AB15: =SUM(AB13:AB14) -> 238118 | AC15: =SUM(AC13:AC14) -> 219000 | AD15: =SUM(AD13:AD14) -> 205887 | AE15: =SUM(AE13:AE14) -> 196445 | AF15: =SUM(AF13:AF14) -> 190410 | AG15: =SUM(AG13:AG14) -> 196804 | AH15: =SUM(AH13:AH14) -> 198396 | ... AK15: =SUM(AK13:AK14) -> 168136 | AM15: =SUM(AK15/AG15)-1 -> -0.14566777
A17: X | B17: Revenue by Channel: International
B18: Retail | C18: 1007 | D18: 15426 | E18: 36472 | F18: 81483 | G18: 60907 | H18: 61723 | I18: 59783 | K18: 16137 | L18: 23692 | M18: 10195 | N18: =SUM(G18-SUM(K18:M18)) -> 10883 | O18: 14289 | P18: 19995 | Q18: 14153 | R18: =SUM(H18-SUM(O18:Q18)) -> 13286 | S18: 12578 | T18: 17585 | U18: 16565 | V18: =SUM(I18-SUM(S18:U18)) -> 13055 | W18: 12682 | X18: 15867 | Y18: 15810 | AA18: =SUM(L18:O18) -> 59059 | AB18: =SUM(M18:P18) -> 55362 | AC18: =SUM(N18:Q18) -> 59320 | AD18: =SUM(O18:R18) -> 61723 | AE18: =SUM(P18:S18) -> 60012 | AF18: =SUM(Q18:T18) -> 57602 | AG18: =SUM(R18:U18) -> 60014 | AH18: =SUM(S18:V18) -> 59783 | ... AK18: =SUM(V18:Y18) -> 57414 | AM18: =SUM(AK18/AG18)-1 -> -0.043323225
B19: Foodservice | C19: 16438 | D19: 82716 | E19: 45439 | F19: 63382 | G19: 53993 | H19: 75766 | I19: 68273 | K19: 9565 | L19: 21098 | M19: 10134 | N19: =SUM(G19-SUM(K19:M19)) -> 13196 | O19: 19113 | P19: 20900 | Q19: 18106 | R19: =SUM(H19-SUM(O19:Q19)) -> 17647 | S19: 13633 | T19: 20381 | U19: 14994 | V19: =SUM(I19-SUM(S19:U19)) -> 19265 | W19: 15276 | X19: 15127 | Y19: 15347 | AA19: =SUM(L19:O19) -> 63541 | AB19: =SUM(M19:P19) -> 63343 | AC19: =SUM(N19:Q19) -> 71315 | AD19: =SUM(O19:R19) -> 75766 | AE19: =SUM(P19:S19) -> 70286 | AF19: =SUM(Q19:T19) -> 69767 | AG19: =SUM(R19:U19) -> 66655 | AH19: =SUM(S19:V19) -> 68273 | ... AK19: =SUM(V19:Y19) -> 65015 | AM19: =SUM(AK19/AG19)-1 -> -0.024604306
B20: Total Net International Revenue | C20: =SUM(C18:C19) -> 17445 | D20: =SUM(D18:D19) -> 98142 | E20: =SUM(E18:E19) -> 81911 | F20: =SUM(F18:F19) -> 144865 | G20: =SUM(G18:G19) -> 114900 | H20: =SUM(H18:H19) -> 137489 | I20: =SUM(I18:I19) -> 128056 | K20: =SUM(K18:K19) -> 25702 | L20: =SUM(L18:L19) -> 44790 | M20: =SUM(M18:M19) -> 20329 | N20: =SUM(N18:N19) -> 24079 | O20: =SUM(O18:O19) -> 33402 | P20: =SUM(P18:P19) -> 40895 | Q20: =SUM(Q18:Q19) -> 32259 | R20: =SUM(R18:R19) -> 30933 | ... Y20: =SUM(Y18:Y19) -> 31157 | AA20: =SUM(AA18:AA19) -> 122600 | AB20: =SUM(AB18:AB19) -> 118705 | AC20: =SUM(AC18:AC19) -> 130635 | AD20: =SUM(AD18:AD19) -> 137489 | AE20: =SUM(AE18:AE19) -> 130298 | AF20: =SUM(AF18:AF19) -> 127369 | AG20: =SUM(AG18:AG19) -> 126669 | AH20: =SUM(AH18:AH19) -> 128056 | ... AK20: =SUM(AK18:AK19) -> 122429 | AM20: =SUM(AK20/AG20)-1 -> -0.033473068

Sheet FCF
B2: Beyond Meat, Inc. (NASDAQ: BYND) | C2: FYE | E2: FYE | I2: Quarterly | S2: Quarterly | Y2: LTM | AF2: LTM | AG2: LTM | AM2: Variance
B3: FCF Analysis | C3: ='Historical Financials'!E7 -> 2020 | D3: ='Historical Financials'!F7 -> 2021 | E3: ='Historical Financials'!G7 -> 2022 | F3: ='Historical Financials'!H7 -> 2023 | G3: ='Historical Financials'!I7 -> 2024 | I3: ='Historical Financials'!AA7 -> 1Q22 | J3: ='Historical Financials'!AB7 -> 2Q22 | K3: ='Historical Financials'!AC7 -> 3Q22 | L3: ='Historical Financials'!AD7 -> 4Q22 | M3: ='Historical Financials'!AE7 -> 1Q23 | N3: ='Historical Financials'!AF7 -> 2Q23 | O3: ='Historical Financials'!AG7 -> 3Q23 | P3: ='Historical Financials'!AH7 -> 4Q23 | ... W3: ='Historical Financials'!AO7 -> 3Q25 | Y3: =K3 -> 3Q22 | Z3: =L3 -> 4Q22 | AA3: =M3 -> 1Q23 | AB3: =N3 -> 2Q23 | AC3: =O3 -> 3Q23 | AD3: =P3 -> 4Q23 | AE3: =Q3 -> 1Q24 | AF3: =R3 -> 2Q24 | ... AK3: =W3 -> 3Q25
B4: $ mm except per share | C4: ='Historical Financials'!E8 -> 44196 | D4: ='Historical Financials'!F8 -> 44561 | E4: ='Historical Financials'!G8 -> 44926 | F4: ='Historical Financials'!H8 -> 45291 | G4: ='Historical Financials'!I8 -> 45657 | I4: ='Historical Financials'!AA8 -> 44653 | J4: ='Historical Financials'!AB8 -> 44744 | K4: ='Historical Financials'!AC8 -> 44835 | L4: ='Historical Financials'!AD8 -> 44926 | M4: ='Historical Financials'!AE8 -> 45017 | N4: ='Historical Financials'!AF8 -> 45108 | O4: ='Historical Financials'!AG8 -> 45199 | P4: ='Historical Financials'!AH8 -> 45291 | ... W4: ='Historical Financials'!AO8 -> 45927 | Y4: =K4 -> 44835 | Z4: =L4 -> 44926 | AA4: =M4 -> 45017 | AB4: =N4 -> 45108 | AC4: =O4 -> 45199 | AD4: =P4 -> 45291 | AE4: =Q4 -> 45381 | AF4: =R4 -> 45472 | ... AK4: =W4 -> 45927
B6: ='Revenue Drivers'!B7 -> Retail | C6: ='Revenue Drivers'!E7 -> 300583 | D6: ='Revenue Drivers'!F7 -> 324843 | E6: ='Revenue Drivers'!G7 -> 295651 | F6: ='Revenue Drivers'!H7 -> 216963 | G6: ='Revenue Drivers'!I7 -> 210595 | I6: ='Revenue Drivers'!K7 -> 84397 | J6: ='Revenue Drivers'!L7 -> 102553 | K6: ='Revenue Drivers'!M7 -> 56372 | L6: ='Revenue Drivers'!N7 -> 52329 | M6: ='Revenue Drivers'!O7 -> 58448 | N6: ='Revenue Drivers'!P7 -> 68485 | O6: ='Revenue Drivers'!Q7 -> 44671 | P6: ='Revenue Drivers'!R7 -> 45359 | ... W6: ='Revenue Drivers'!Y7 -> 44347 | Y6: =SUM(H6:K6) -> 243322 | Z6: =SUM(I6:L6) -> 295651 | AA6: =SUM(J6:M6) -> 269702 | AB6: =SUM(K6:N6) -> 235634 | AC6: =SUM(L6:O6) -> 223933 | AD6: =SUM(M6:P6) -> 216963 | AE6: =SUM(N6:Q6) -> 208181 | AF6: =SUM(O6:R6) -> 202150 | ... AK6: =SUM(T6:W6) -> 184106 | AM6: =SUM(AK6/AG6)-1 -> -0.11916484
B7: ='Revenue Drivers'!B8 -> Foodservice | C7: ='Revenue Drivers'!E8 -> 106202 | D7: ='Revenue Drivers'!F8 -> 139857 | E7: ='Revenue Drivers'!G8 -> 123282 | F7: ='Revenue Drivers'!H8 -> 126413 | G7: ='Revenue Drivers'!I8 -> 115857 | I7: ='Revenue Drivers'!K8 -> 25058 | J7: ='Revenue Drivers'!L8 -> 44487 | K7: ='Revenue Drivers'!M8 -> 26128 | L7: ='Revenue Drivers'!N8 -> 27609 | M7: ='Revenue Drivers'!O8 -> 33788 | N7: ='Revenue Drivers'!P8 -> 33664 | O7: ='Revenue Drivers'!Q8 -> 30641 | P7: ='Revenue Drivers'!R8 -> 28320 | ... W7: ='Revenue Drivers'!Y8 -> 25871 | Y7: =SUM(H7:K7) -> 95673 | Z7: =SUM(I7:L7) -> 123282 | AA7: =SUM(J7:M7) -> 132012 | AB7: =SUM(K7:N7) -> 121189 | AC7: =SUM(L7:O7) -> 125702 | AD7: =SUM(M7:P7) -> 126413 | AE7: =SUM(N7:Q7) -> 118562 | AF7: =SUM(O7:R7) -> 115629 | ... AK7: =SUM(T7:W7) -> 106459 | AM7: =SUM(AK7/AG7)-1 -> -0.069902149
B8: Total Revenue | C8: =SUM(C6:C7) -> 406785 | D8: =SUM(D6:D7) -> 464700 | E8: =SUM(E6:E7) -> 418933 | F8: =SUM(F6:F7) -> 343376 | G8: =SUM(G6:G7) -> 326452 | I8: =SUM(I6:I7) -> 109455 | J8: =SUM(J6:J7) -> 147040 | K8: =SUM(K6:K7) -> 82500 | L8: =SUM(L6:L7) -> 79938 | M8: =SUM(M6:M7) -> 92236 | N8: =SUM(N6:N7) -> 102149 | O8: =SUM(O6:O7) -> 75312 | P8: =SUM(P6:P7) -> 73679 | ... W8: =SUM(W6:W7) -> 70218 | Y8: =SUM(Y6:Y7) -> 338995 | Z8: =SUM(Z6:Z7) -> 418933 | AA8: =SUM(AA6:AA7) -> 401714 | AB8: =SUM(AB6:AB7) -> 356823 | AC8: =SUM(AC6:AC7) -> 349635 | AD8: =SUM(AD6:AD7) -> 343376 | AE8: =SUM(AE6:AE7) -> 326743 | AF8: =SUM(AF6:AF7) -> 317779 | ... AK8: =SUM(AK6:AK7) -> 290565 | AM8: =SUM(AK8/AG8)-1 -> -0.10173337
B9: Y/Y Growth (%) | D9: =SUM(D8/C8)-1 -> 0.14237251 | E9: =SUM(E8/D8)-1 -> -0.098487196 | F9: =SUM(F8/E8)-1 -> -0.18035581 | G9: =SUM(G8/F8)-1 -> -0.049287079 | M9: =SUM(M8/I8)-1 -> -0.15731579 | N9: =SUM(N8/J8)-1 -> -0.30529788 | O9: =SUM(O8/K8)-1 -> -0.087127273 | P9: =SUM(P8/L8)-1 -> -0.078298181 | Q9: =SUM(Q8/M8)-1 -> -0.18033089 | R9: =SUM(R8/N8)-1 -> -0.087754163 | S9: =SUM(S8/O8)-1 -> 0.075605481 | T9: =SUM(T8/P8)-1 -> 0.040432145 | ... W9: =SUM(W8/S8)-1 -> -0.13317532 | AC9: =SUM(AC8/Y8)-1 -> 0.031386894 | AD9: =SUM(AD8/Z8)-1 -> -0.18035581 | AE9: =SUM(AE8/AA8)-1 -> -0.1866278 | AF9: =SUM(AF8/AB8)-1 -> -0.1094212 | AG9: =SUM(AG8/AC8)-1 -> -0.074826605 | AH9: =SUM(AH8/AD8)-1 -> -0.049287079 | AI9: =SUM(AI8/AE8)-1 -> -0.021922428 | AJ9: =SUM(AJ8/AF8)-1 -> -0.051690011 | AK9: =SUM(AK8/AG8)-1 -> -0.10173337 | AM9: =SUM(AK9-AG9)*10000 -> -269.0677
B10: Q/Q Growth (%) | C10: N/A | D10: N/A | E10: N/A | F10: N/A | G10: N/A | J10: =SUM(J8/I8)-1 -> 0.34338313 | K10: =SUM(K8/J8)-1 -> -0.43892818 | L10: =SUM(L8/K8)-1 -> -0.031054545 | M10: =SUM(M8/L8)-1 -> 0.15384423 | N10: =SUM(N8/M8)-1 -> 0.10747431 | O10: =SUM(O8/N8)-1 -> -0.26272406 | P10: =SUM(P8/O8)-1 -> -0.021683132 | Q10: =SUM(Q8/P8)-1 -> 0.026113275 | ... W10: =SUM(W8/V8)-1 -> -0.063235412 | Y10: N/A | Z10: N/A | AA10: N/A | AB10: N/A | AC10: N/A | AD10: N/A | AE10: N/A | AF10: N/A | AG10: N/A | AH10: N/A | AI10: N/A | AJ10: N/A | AK10: N/A
B12: (-) Cost of Sales | C12: ='Historical Financials'!E13 -> -284510 | D12: ='Historical Financials'!F13 -> -347419 | E12: ='Historical Financials'!G13 -> -442676 | F12: ='Historical Financials'!H13 -> -426031 | G12: ='Historical Financials'!I13 -> -284753 | I12: ='Historical Financials'!AA13 -> -109265 | J12: ='Historical Financials'!AB13 -> -153202 | K12: ='Historical Financials'!AC13 -> -97340 | L12: ='Historical Financials'!AD13 -> -82869 | M12: ='Historical Financials'!AE13 -> -86051 | N12: ='Historical Financials'!AF13 -> -99876 | O12: ='Historical Financials'!AG13 -> -82566 | P12: ='Historical Financials'!AH13 -> -157538 | ... W12: ='Historical Financials'!AO13 -> -62988 | Y12: =SUM(H12:K12) -> -359807 | Z12: =SUM(I12:L12) -> -442676 | AA12: =SUM(J12:M12) -> -419462 | AB12: =SUM(K12:N12) -> -366136 | AC12: =SUM(L12:O12) -> -351362 | AD12: =SUM(M12:P12) -> -426031 | AE12: =SUM(N12:Q12) -> -411915 | AF12: =SUM(O12:R12) -> -391507 | ... AK12: =SUM(T12:W12) -> -265803 | AM12: =SUM(AK12/AG12)-1 -> -0.29239775
B13: Gross Profit | C13: =+C8+C12 -> 122275 | D13: =+D8+D12 -> 117281 | E13: =+E8+E12 -> -23743 | F13: =+F8+F12 -> -82655 | G13: =+G8+G12 -> 41699 | I13: =+I8+I12 -> 190 | J13: =+J8+J12 -> -6162 | K13: =+K8+K12 -> -14840 | L13: =+L8+L12 -> -2931 | M13: =+M8+M12 -> 6185 | N13: =+N8+N12 -> 2273 | O13: =+O8+O12 -> -7254 | P13: =+P8+P12 -> -83859 | ... W13: =+W8+W12 -> 7230 | Y13: =+Y8+Y12 -> -20812 | Z13: =+Z8+Z12 -> -23743 | AA13: =+AA8+AA12 -> -17748 | AB13: =+AB8+AB12 -> -9313 | AC13: =+AC8+AC12 -> -1727 | AD13: =+AD8+AD12 -> -82655 | AE13: =+AE8+AE12 -> -85172 | AF13: =+AF8+AF12 -> -73728 | ... AK13: =+AK8+AK12 -> 24762 | AM13: =SUM(AK13/AG13)-1 -> -1.474677
B14: Gross Margin (%) | C14: =C13/C8 -> 0.30058876 | D14: =D13/D8 -> 0.25238003 | E14: =E13/E8 -> -0.056674934 | F14: =F13/F8 -> -0.2407128 | G14: =G13/G8 -> 0.12773394 | I14: =I13/I8 -> 0.0017358732 | J14: =J13/J8 -> -0.041906964 | K14: =K13/K8 -> -0.17987879 | L14: =L13/L8 -> -0.036665916 | M14: =M13/M8 -> 0.067056247 | N14: =N13/N8 -> 0.022251809 | O14: =O13/O8 -> -0.096319312 | P14: =P13/P8 -> -1.1381669 | ... W14: =W13/W8 -> 0.10296505 | Y14: =Y13/Y8 -> -0.061393236 | Z14: =Z13/Z8 -> -0.056674934 | AA14: =AA13/AA8 -> -0.044180686 | AB14: =AB13/AB8 -> -0.026099775 | AC14: =AC13/AC8 -> -0.0049394368 | AD14: =AD13/AD8 -> -0.2407128 | AE14: =AE13/AE8 -> -0.2606697 | AF14: =AF13/AF8 -> -0.2320103 | ... AK14: =AK13/AK8 -> 0.085220174 | AM14: =SUM(AK14-AG14)*10000 -> 2464.8866
B16: (-) Selling, General & Administrative (SG&A) | C16: ='Historical Financials'!E17 -> -133655 | D16: ='Historical Financials'!F17 -> -209474 | E16: ='Historical Financials'!G17 -> -239505 | F16: ='Historical Financials'!H17 -> -220344 | G16: ='Historical Financials'!I17 -> -169674 | I16: ='Historical Financials'!AA17 -> -75114 | J16: ='Historical Financials'!AB17 -> -63015 | K16: ='Historical Financials'!AC17 -> -54495 | L16: ='Historical Financials'!AD17 -> -46881 | M16: ='Historical Financials'!AE17 -> -51900 | N16: ='Historical Financials'!AF17 -> -47455 | O16: ='Historical Financials'!AG17 -> -53252 | P16: ='Historical Financials'!AH17 -> -67737 | ... W16: ='Historical Financials'!AO17 -> -37230 | Y16: =SUM(H16:K16) -> -192624 | Z16: =SUM(I16:L16) -> -239505 | AA16: =SUM(J16:M16) -> -216291 | AB16: =SUM(K16:N16) -> -200731 | AC16: =SUM(L16:O16) -> -199488 | AD16: =SUM(M16:P16) -> -220344 | AE16: =SUM(N16:Q16) -> -215726 | AF16: =SUM(O16:R16) -> -210434 | ... AK16: =SUM(T16:W16) -> -163743 | AM16: =SUM(AK16/AG16)-1 -> -0.16570878
B17: (-) Research and Development (R&D) | C17: ='Historical Financials'!E18 -> -31535 | D17: ='Historical Financials'!F18 -> -66946 | E17: ='Historical Financials'!G18 -> -62264 | F17: ='Historical Financials'!H18 -> -39530 | G17: ='Historical Financials'!I18 -> -28149 | I17: ='Historical Financials'!AA18 -> -19678 | J17: ='Historical Financials'!AB18 -> -16202 | K17: ='Historical Financials'!AC18 -> -13413 | L17: ='Historical Financials'!AD18 -> -12971 | M17: ='Historical Financials'!AE18 -> -12432 | N17: ='Historical Financials'!AF18 -> -8773 | O17: ='Historical Financials'!AG18 -> -9118 | P17: ='Historical Financials'!AH18 -> -9207 | ... W17: ='Historical Financials'!AO18 -> -4917 | Y17: =SUM(H17:K17) -> -49293 | Z17: =SUM(I17:L17) -> -62264 | AA17: =SUM(J17:M17) -> -55018 | AB17: =SUM(K17:N17) -> -47589 | AC17: =SUM(L17:O17) -> -43294 | AD17: =SUM(M17:P17) -> -39530 | AE17: =SUM(N17:Q17) -> -36958 | AF17: =SUM(O17:R17) -> -33670 | ... AK17: =SUM(T17:W17) -> -24857 | AM17: =SUM(AK17/AG17)-1 -> -0.18992993
B18: (-) Restructuring Charges & Other Impairments | C18: ='Historical Financials'!E19 -> -6430 | D18: ='Historical Financials'!F19 -> -15794 | E18: ='Historical Financials'!G19 -> -17259 | F18: ='Historical Financials'!H19 -> 631 | G18: ='Historical Financials'!I19 -> 0 | I18: ='Historical Financials'!AA19 -> -3026 | J18: ='Historical Financials'!AB19 -> -4302 | K18: ='Historical Financials'!AC19 -> -6993 | L18: ='Historical Financials'!AD19 -> -2938 | M18: ='Historical Financials'!AE19 -> 426 | N18: ='Historical Financials'!AF19 -> 201 | O18: ='Historical Financials'!AG19 -> 4 | P18: ='Historical Financials'!AH19 -> 0 | ... W18: ='Historical Financials'!AO19 -> -77414 | Y18: =SUM(H18:K18) -> -14321 | Z18: =SUM(I18:L18) -> -17259 | AA18: =SUM(J18:M18) -> -13807 | AB18: =SUM(K18:N18) -> -9304 | AC18: =SUM(L18:O18) -> -2307 | AD18: =SUM(M18:P18) -> 631 | AE18: =SUM(N18:Q18) -> 205 | AF18: =SUM(O18:R18) -> 4 | ... AK18: =SUM(T18:W18) -> -77414 | AM18: =SUM(AK18/AG18)-1 -> #DIV/0!
B19: Earning before Interest & Taxes (EBIT) | C19: =SUM(C13+SUM(C16:C18)) -> -49345 | D19: =SUM(D13+SUM(D16:D18)) -> -174933 | E19: =SUM(E13+SUM(E16:E18)) -> -342771 | F19: =SUM(F13+SUM(F16:F18)) -> -341898 | G19: =SUM(G13+SUM(G16:G18)) -> -156124 | I19: =SUM(I13+SUM(I16:I18)) -> -97628 | J19: =SUM(J13+SUM(J16:J18)) -> -89681 | K19: =SUM(K13+SUM(K16:K18)) -> -89741 | L19: =SUM(L13+SUM(L16:L18)) -> -65721 | M19: =SUM(M13+SUM(M16:M18)) -> -57721 | N19: =SUM(N13+SUM(N16:N18)) -> -53754 | O19: =SUM(O13+SUM(O16:O18)) -> -69620 | P19: =SUM(P13+SUM(P16:P18)) -> -160803 | ... W19: =SUM(W13+SUM(W16:W18)) -> -112331 | Y19: =SUM(Y13+SUM(Y16:Y18)) -> -277050 | Z19: =SUM(Z13+SUM(Z16:Z18)) -> -342771 | AA19: =SUM(AA13+SUM(AA16:AA18)) -> -302864 | AB19: =SUM(AB13+SUM(AB16:AB18)) -> -266937 | AC19: =SUM(AC13+SUM(AC16:AC18)) -> -246816 | AD19: =SUM(AD13+SUM(AD16:AD18)) -> -341898 | AE19: =SUM(AE13+SUM(AE16:AE18)) -> -337651 | AF19: =SUM(AF13+SUM(AF16:AF18)) -> -317828 | ... AK19: =SUM(AK13+SUM(AK16:AK18)) -> -241252 | AM19: =SUM(AK19/AG19)-1 -> -0.13565996
B20: Operating Margin (%) | C20: =C19/C8 -> -0.12130487 | D20: =D19/D8 -> -0.37644287 | E20: =E19/E8 -> -0.81820005 | F20: =F19/F8 -> -0.99569568 | G20: =G19/G8 -> -0.47824489 | I20: =I19/I8 -> -0.89194646 | J20: =J19/J8 -> -0.60990887 | K20: =K19/K8 -> -1.0877697 | L20: =L19/L8 -> -0.82214967 | M20: =M19/M8 -> -0.62579687 | N20: =N19/N8 -> -0.52623129 | O20: =O19/O8 -> -0.92442107 | P20: =P19/P8 -> -2.1824808 | ... W20: =W19/W8 -> -1.5997465 | Y20: =Y19/Y8 -> -0.81726869 | Z20: =Z19/Z8 -> -0.81820005 | AA20: =AA19/AA8 -> -0.75392941 | AB20: =AB19/AB8 -> -0.74809359 | AC20: =AC19/AC8 -> -0.70592475 | AD20: =AD19/AD8 -> -0.99569568 | AE20: =AE19/AE8 -> -1.033384 | AF20: =AF19/AF8 -> -1.0001542 | ... AK20: =AK19/AK8 -> -0.83028582 | AM20: =SUM(AK20-AG20)*10000 -> 325.89904
B22: (+) Depreciation and Amortization | C22: ='Historical Financials'!E101 -> 13299 | D22: ='Historical Financials'!F101 -> 21663 | E22: ='Historical Financials'!G101 -> 32582 | F22: ='Historical Financials'!H101 -> 48094 | G22: ='Historical Financials'!I101 -> 23121 | I22: ='Historical Financials'!AA101 -> 7091 | J22: ='Historical Financials'!AB101 -> 7729 | K22: ='Historical Financials'!AC101 -> 8435 | L22: ='Historical Financials'!AD101 -> 9327 | M22: ='Historical Financials'!AE101 -> 6049 | N22: ='Historical Financials'!AF101 -> 5879 | O22: ='Historical Financials'!AG101 -> 5779 | P22: ='Historical Financials'!AH101 -> 30387 | ... W22: ='Historical Financials'!AO101 -> 9361 | Y22: =SUM(H22:K22) -> 23255 | Z22: =SUM(I22:L22) -> 32582 | AA22: =SUM(J22:M22) -> 31540 | AB22: =SUM(K22:N22) -> 29690 | AC22: =SUM(L22:O22) -> 27034 | AD22: =SUM(M22:P22) -> 48094 | AE22: =SUM(N22:Q22) -> 49014 | AF22: =SUM(O22:R22) -> 48348 | ... AK22: =SUM(T22:W22) -> 30700 | AM22: =SUM(AK22/AG22)-1 -> -0.35842511
B23: EBITDA | C23: =SUM(C19+C22) -> -36046 | D23: =SUM(D19+D22) -> -153270 | E23: =SUM(E19+E22) -> -310189 | F23: =SUM(F19+F22) -> -293804 | G23: =SUM(G19+G22) -> -133003 | I23: =SUM(I19+I22) -> -90537 | J23: =SUM(J19+J22) -> -81952 | K23: =SUM(K19+K22) -> -81306 | L23: =SUM(L19+L22) -> -56394 | M23: =SUM(M19+M22) -> -51672 | N23: =SUM(N19+N22) -> -47875 | O23: =SUM(O19+O22) -> -63841 | P23: =SUM(P19+P22) -> -130416 | ... W23: =SUM(W19+W22) -> -102970 | Y23: =SUM(Y19+Y22) -> -253795 | Z23: =SUM(Z19+Z22) -> -310189 | AA23: =SUM(AA19+AA22) -> -271324 | AB23: =SUM(AB19+AB22) -> -237247 | AC23: =SUM(AC19+AC22) -> -219782 | AD23: =SUM(AD19+AD22) -> -293804 | AE23: =SUM(AE19+AE22) -> -288637 | AF23: =SUM(AF19+AF22) -> -269480 | ... AK23: =SUM(AK19+AK22) -> -210552 | AM23: =SUM(AK23/AG23)-1 -> -0.089567857
B24: EBITDA Margin (%) | C24: =C23/C8 -> -0.08861192 | D24: =D23/D8 -> -0.32982569 | E24: =E23/E8 -> -0.74042627 | F24: =F23/F8 -> -0.85563347 | G24: =G23/G8 -> -0.40741977 | I24: =I23/I8 -> -0.82716185 | J24: =J23/J8 -> -0.55734494 | K24: =K23/K8 -> -0.98552727 | L24: =L23/L8 -> -0.70547174 | M24: =M23/M8 -> -0.5602151 | N24: =N23/N8 -> -0.46867811 | O24: =O23/O8 -> -0.84768696 | P24: =P23/P8 -> -1.7700566 | ... W24: =W23/W8 -> -1.4664331 | Y24: =Y23/Y8 -> -0.74866886 | Z24: =Z23/Z8 -> -0.74042627 | AA24: =AA23/AA8 -> -0.67541584 | AB24: =AB23/AB8 -> -0.66488707 | AC24: =AC23/AC8 -> -0.62860412 | AD24: =AD23/AD8 -> -0.85563347 | AE24: =AE23/AE8 -> -0.88337623 | AF24: =AF23/AF8 -> -0.84801072 | ... AK24: =AK23/AK8 -> -0.7246296 | AM24: =SUM(AK24-AG24)*10000 -> -96.827584
B26: (+) Share-based Compensation | C26: ='Historical Financials'!E102 -> 27279 | D26: ='Historical Financials'!F102 -> 27698 | E26: ='Historical Financials'!G102 -> 33857 | F26: ='Historical Financials'!H102 -> 29098 | G26: ='Historical Financials'!I102 -> 23923 | I26: ='Historical Financials'!AA102 -> 9292 | J26: ='Historical Financials'!AB102 -> 10306 | K26: ='Historical Financials'!AC102 -> 9250 | L26: ='Historical Financials'!AD102 -> 5009 | M26: ='Historical Financials'!AE102 -> 9565 | N26: ='Historical Financials'!AF102 -> 7748 | O26: ='Historical Financials'!AG102 -> 6478 | P26: ='Historical Financials'!AH102 -> 5307 | ... W26: ='Historical Financials'!AO102 -> 3767 | Y26: =SUM(H26:K26) -> 28848 | Z26: =SUM(I26:L26) -> 33857 | AA26: =SUM(J26:M26) -> 34130 | AB26: =SUM(K26:N26) -> 31572 | AC26: =SUM(L26:O26) -> 28800 | AD26: =SUM(M26:P26) -> 29098 | AE26: =SUM(N26:Q26) -> 25608 | AF26: =SUM(O26:R26) -> 23633 | ... AK26: =SUM(T26:W26) -> 20094 | AM26: =SUM(AK26/AG26)-1 -> -0.12862099
B27: (+) Restructuring Expenses | C27: =-C18 -> 6430 | D27: =-D18 -> 15794 | E27: =-E18 -> 17259 | F27: =-F18 -> -631 | G27: =-G18 -> 0 | I27: =-I18 -> 3026 | J27: =-J18 -> 4302 | K27: =-K18 -> 6993 | L27: =-L18 -> 2938 | M27: =-M18 -> -426 | N27: =-N18 -> -201 | O27: =-O18 -> -4 | P27: =-P18 -> 0 | ... W27: =-W18 -> 77414 | AF27: =SUM(O27:R27) -> -4 | AG27: =SUM(P27:S27) -> 0 | AH27: =SUM(Q27:T27) -> 0 | AI27: =SUM(R27:U27) -> 0 | AJ27: =SUM(S27:V27) -> 0 | AK27: =SUM(T27:W27) -> 77414 | AM27: =SUM(AK27/AG27)-1 -> #DIV/0!
B28: (+) Accrued litigation settlement costs & other charges | C28: 0 | D28: 0 | E28: 0 | F28: 0 | G28: 7500 | I28: 0 | J28: 0 | K28: 0 | L28: =SUM(E28-SUM(I28:K28)) -> 0 | M28: 0 | N28: 0 | O28: 0 | P28: =SUM(F28-SUM(M28:O28)) -> 0 | Q28: 7500 | R28: 0 | S28: 0 | T28: =SUM(G28-SUM(Q28:S28)) -> 0 | U28: 2083 | V28: 1739 | W28: =1757-750 -> 1007 | AF28: =SUM(O28:R28) -> 7500 | AG28: =SUM(P28:S28) -> 7500 | AH28: =SUM(Q28:T28) -> 7500 | AI28: =SUM(R28:U28) -> 2083 | AJ28: =SUM(S28:V28) -> 3822 | AK28: =SUM(T28:W28) -> 4829 | AM28: =SUM(AK28/AG28)-1 -> -0.35613333
B29: Adj. EBITDA | C29: =+SUM(C23+SUM(C26:C28)) -> -2337 | D29: =+SUM(D23+SUM(D26:D28)) -> -109778 | E29: =+SUM(E23+SUM(E26:E28)) -> -259073 | F29: =+SUM(F23+SUM(F26:F28)) -> -265337 | G29: =+SUM(G23+SUM(G26:G28)) -> -101580 | I29: =+SUM(I23+SUM(I26:I28)) -> -78219 | J29: =+SUM(J23+SUM(J26:J28)) -> -67344 | K29: =+SUM(K23+SUM(K26:K28)) -> -65063 | L29: =+SUM(L23+SUM(L26:L28)) -> -48447 | M29: =+SUM(M23+SUM(M26:M28)) -> -42533 | N29: =+SUM(N23+SUM(N26:N28)) -> -40328 | O29: =+SUM(O23+SUM(O26:O28)) -> -57367 | P29: =+SUM(P23+SUM(P26:P28)) -> -125109 | ... W29: =+SUM(W23+SUM(W26:W28)) -> -20782 | Y29: =+SUM(Y23+SUM(Y26:Y28)) -> -224947 | Z29: =+SUM(Z23+SUM(Z26:Z28)) -> -276332 | AA29: =+SUM(AA23+SUM(AA26:AA28)) -> -237194 | AB29: =+SUM(AB23+SUM(AB26:AB28)) -> -205675 | AC29: =+SUM(AC23+SUM(AC26:AC28)) -> -190982 | AD29: =+SUM(AD23+SUM(AD26:AD28)) -> -264706 | AE29: =+SUM(AE23+SUM(AE26:AE28)) -> -263029 | AF29: =+SUM(AF23+SUM(AF26:AF28)) -> -238351 | ... AK29: =+SUM(AK23+SUM(AK26:AK28)) -> -108215 | AM29: =SUM(AK29/AG29)-1 -> -0.46082828
B30: Adj. EBITDA Margin (%) | C30: =C29/C8 -> -0.0057450496 | D30: =D29/D8 -> -0.23623413 | E30: =E29/E8 -> -0.61841154 | F30: =F29/F8 -> -0.77273018 | G30: =G29/G8 -> -0.31116366 | I30: =I29/I8 -> -0.71462245 | J30: =J29/J8 -> -0.45799782 | K30: =K29/K8 -> -0.78864242 | L30: =L29/L8 -> -0.60605719 | M30: =M29/M8 -> -0.46113231 | N30: =N29/N8 -> -0.39479584 | O30: =O29/O8 -> -0.76172456 | P30: =P29/P8 -> -1.6980279 | ... W30: =W29/W8 -> -0.295964 | Y30: =Y29/Y8 -> -0.66357026 | Z30: =Z29/Z8 -> -0.65960905 | AA30: =AA29/AA8 -> -0.5904549 | AB30: =AB29/AB8 -> -0.57640623 | AC30: =AC29/AC8 -> -0.5462325 | AD30: =AD29/AD8 -> -0.77089255 | AE30: =AE29/AE8 -> -0.80500271 | AF30: =AF29/AF8 -> -0.75005271 | ... AK30: =AK29/AK8 -> -0.37242958 | AM30: =SUM(AK30-AG30)*10000 -> 2480.4261
