Workbook

Sheet Historical Financials
B2: Galectin Therapeutics Inc (NASDAQ: GALT)
B3: Historical Financials
B4: $ in thousands except per share
A6: X | B6: Income Statement | C6: FYE | G6: Quarterly | Q6: Quarterly | Y6: LTM | AE6: Variance
B7: Fiscal Period | C7: 2021 | D7: 2022 | E7: 2023 | G7: 1Q22 | H7: 2Q22 | I7: 3Q22 | J7: 4Q22 | K7: 1Q23 | L7: 2Q23 | M7: 3Q23 | N7: 4Q23 | O7: 1Q24 | P7: 2Q24 | Q7: 3Q24 | S7: =G7 -> 1Q22 | T7: =H7 -> 2Q22 | U7: =I7 -> 3Q22 | V7: =J7 -> 4Q22 | W7: =K7 -> 1Q23 | X7: =L7 -> 2Q23 | Y7: =M7 -> 3Q23 | Z7: =N7 -> 4Q23 | ... AC7: =Q7 -> 3Q24
B8: Fiscal Period End Date | C8: 44561 | D8: 44926 | E8: 45291 | G8: 44651 | H8: 44742 | I8: 44834 | J8: 44926 | K8: 45016 | L8: 45107 | M8: 45199 | N8: 45291 | O8: 45382 | P8: 45473 | Q8: 45565 | S8: =G8 -> 44651 | T8: =H8 -> 44742 | U8: =I8 -> 44834 | V8: =J8 -> 44926 | W8: =K8 -> 45016 | X8: =L8 -> 45107 | Y8: =M8 -> 45199 | Z8: =N8 -> 45291 | ... AC8: =Q8 -> 45565
B10: Consolidated Revenue | C10: 0 | D10: 0 | E10: 0 | G10: 0 | H10: 0 | I10: 0 | J10: =SUM(C10-SUM(G10:I10)) -> 0 | K10: 0 | L10: 0 | M10: 0 | N10: =SUM(D10-SUM(K10:M10)) -> 0 | O10: 0 | P10: 0 | Q10: 0 | S10: =SUM(D10:G10) -> 0 | T10: =SUM(E10:H10) -> 0 | U10: =SUM(F10:I10) -> 0 | V10: =SUM(G10:J10) -> 0 | W10: =SUM(H10:K10) -> 0 | X10: =SUM(I10:L10) -> 0 | Y10: =SUM(J10:M10) -> 0 | Z10: =SUM(K10:N10) -> 0 | ... AC10: =SUM(N10:Q10) -> 0 | AE10: =SUM(AC10/Y10)-1 -> #DIV/0!
B11: Total Revenue | C11: =+SUM(C10:C10) -> 0 | D11: =+SUM(D10:D10) -> 0 | E11: =+SUM(E10:E10) -> 0 | G11: =+SUM(G10:G10) -> 0 | H11: =+SUM(H10:H10) -> 0 | I11: =+SUM(I10:I10) -> 0 | J11: =+SUM(J10:J10) -> 0 | K11: =+SUM(K10:K10) -> 0 | L11: =+SUM(L10:L10) -> 0 | M11: =+SUM(M10:M10) -> 0 | N11: =+SUM(N10:N10) -> 0 | ... Q11: =+SUM(Q10:Q10) -> 0 | S11: =+SUM(S10:S10) -> 0 | T11: =+SUM(T10:T10) -> 0 | U11: =+SUM(U10:U10) -> 0 | V11: =+SUM(V10:V10) -> 0 | W11: =+SUM(W10:W10) -> 0 | X11: =+SUM(X10:X10) -> 0 | Y11: =+SUM(Y10:Y10) -> 0 | Z11: =+SUM(Z10:Z10) -> 0 | ... AC11: =+SUM(AC10:AC10) -> 0 | AE11: =SUM(AC11/Y11)-1 -> #DIV/0!
B13: Cost of Sales | C13: 0 | D13: 0 | E13: 0 | G13: 0 | H13: 0 | I13: 0 | J13: =SUM(C13-SUM(G13:I13)) -> 0 | K13: 0 | L13: 0 | M13: 0 | N13: =SUM(D13-SUM(K13:M13)) -> 0 | O13: 0 | P13: 0 | Q13: 0 | S13: =SUM(H13:K13) -> 0 | T13: =SUM(I13:L13) -> 0 | U13: =SUM(J13:M13) -> 0 | V13: =SUM(K13:N13) -> 0 | W13: =SUM(L13:O13) -> 0 | X13: =SUM(M13:P13) -> 0 | Y13: =SUM(J13:M13) -> 0 | Z13: =SUM(K13:N13) -> 0 | AA13: =SUM(L13:O13) -> 0 | AB13: =SUM(M13:P13) -> 0 | AC13: =SUM(N13:Q13) -> 0 | AE13: =SUM(AC13/Y13)-1 -> #DIV/0!
B14: Gross Profit | C14: =+SUM(C11+SUM(C13:C13)) -> 0 | D14: =+SUM(D11+SUM(D13:D13)) -> 0 | E14: =+SUM(E11+SUM(E13:E13)) -> 0 | G14: =+SUM(G11+SUM(G13:G13)) -> 0 | H14: =+SUM(H11+SUM(H13:H13)) -> 0 | I14: =+SUM(I11+SUM(I13:I13)) -> 0 | J14: =+SUM(J11+SUM(J13:J13)) -> 0 | K14: =+SUM(K11+SUM(K13:K13)) -> 0 | L14: =+SUM(L11+SUM(L13:L13)) -> 0 | M14: =+SUM(M11+SUM(M13:M13)) -> 0 | N14: =+SUM(N11+SUM(N13:N13)) -> 0 | ... Q14: =+SUM(Q11+SUM(Q13:Q13)) -> 0 | S14: =+SUM(S11+SUM(S13:S13)) -> 0 | T14: =+SUM(T11+SUM(T13:T13)) -> 0 | U14: =+SUM(U11+SUM(U13:U13)) -> 0 | V14: =+SUM(V11+SUM(V13:V13)) -> 0 | W14: =+SUM(W11+SUM(W13:W13)) -> 0 | X14: =+SUM(X11+SUM(X13:X13)) -> 0 | Y14: =+SUM(Y11+SUM(Y13:Y13)) -> 0 | Z14: =+SUM(Z11+SUM(Z13:Z13)) -> 0 | ... AC14: =+SUM(AC11+SUM(AC13:AC13)) -> 0 | AE14: =SUM(AC14/Y14)-1 -> #DIV/0!
B15: Gross Margin (%) | C15: =C14/C11 -> #DIV/0! | D15: =D14/D11 -> #DIV/0! | E15: =E14/E11 -> #DIV/0! | G15: =G14/G11 -> #DIV/0! | H15: =H14/H11 -> #DIV/0! | I15: =I14/I11 -> #DIV/0! | J15: =J14/J11 -> #DIV/0! | K15: =K14/K11 -> #DIV/0! | L15: =L14/L11 -> #DIV/0! | M15: =M14/M11 -> #DIV/0! | N15: =N14/N11 -> #DIV/0! | ... Q15: =Q14/Q11 -> #DIV/0! | S15: =S14/S11 -> #DIV/0! | T15: =T14/T11 -> #DIV/0! | U15: =U14/U11 -> #DIV/0! | V15: =V14/V11 -> #DIV/0! | W15: =W14/W11 -> #DIV/0! | X15: =X14/X11 -> #DIV/0! | Y15: =Y14/Y11 -> #DIV/0! | Z15: =Z14/Z11 -> #DIV/0! | ... AC15: =AC14/AC11 -> #DIV/0! | AE15: =SUM(AC15-Y15)*1000 -> #DIV/0!
B17: Research and development | C17: -23818 | D17: -31737 | E17: -32130 | G17: -8058 | H17: -8074 | I17: -6598 | J17: =SUM(D17-SUM(G17:I17)) -> -9007 | K17: -8799 | L17: -7371 | M17: -7732 | N17: =SUM(E17-SUM(K17:M17)) -> -8228 | O17: -8054 | P17: -9813 | Q17: -7595 | S17: =SUM(H17:K17) -> -32478 | T17: =SUM(I17:L17) -> -31775 | U17: =SUM(J17:M17) -> -32909 | V17: =SUM(K17:N17) -> -32130 | W17: =SUM(L17:O17) -> -31385 | X17: =SUM(M17:P17) -> -33827 | Y17: =SUM(J17:M17) -> -32909 | Z17: =SUM(K17:N17) -> -32130 | AA17: =SUM(L17:O17) -> -31385 | AB17: =SUM(M17:P17) -> -33827 | AC17: =SUM(N17:Q17) -> -33690 | AE17: =SUM(AC17/Y17)-1 -> 0.02373211
B18: General and administrative | C18: -6361 | D18: -6615 | E18: -5942 | G18: -1877 | H18: -1588 | I18: -1524 | J18: =SUM(D18-SUM(G18:I18)) -> -1626 | K18: -1543 | L18: -1632 | M18: -1434 | N18: =SUM(E18-SUM(K18:M18)) -> -1333 | O18: -1594 | P18: -1478 | Q18: -1471 | S18: =SUM(H18:K18) -> -6281 | T18: =SUM(I18:L18) -> -6325 | U18: =SUM(J18:M18) -> -6235 | V18: =SUM(K18:N18) -> -5942 | W18: =SUM(L18:O18) -> -5993 | X18: =SUM(M18:P18) -> -5839 | Y18: =SUM(J18:M18) -> -6235 | Z18: =SUM(K18:N18) -> -5942 | AA18: =SUM(L18:O18) -> -5993 | AB18: =SUM(M18:P18) -> -5839 | AC18: =SUM(N18:Q18) -> -5876 | AE18: =SUM(AC18/Y18)-1 -> -0.057578188
B19: Operating Profit | C19: =+SUM(C14+SUM(C17:C18)) -> -30179 | D19: =+SUM(D14+SUM(D17:D18)) -> -38352 | E19: =+SUM(E14+SUM(E17:E18)) -> -38072 | G19: =+SUM(G14+SUM(G17:G18)) -> -9935 | H19: =+SUM(H14+SUM(H17:H18)) -> -9662 | I19: =+SUM(I14+SUM(I17:I18)) -> -8122 | J19: =+SUM(J14+SUM(J17:J18)) -> -10633 | K19: =+SUM(K14+SUM(K17:K18)) -> -10342 | L19: =+SUM(L14+SUM(L17:L18)) -> -9003 | M19: =+SUM(M14+SUM(M17:M18)) -> -9166 | N19: =+SUM(N14+SUM(N17:N18)) -> -9561 | ... Q19: =+SUM(Q14+SUM(Q17:Q18)) -> -9066 | S19: =+SUM(S14+SUM(S17:S18)) -> -38759 | T19: =+SUM(T14+SUM(T17:T18)) -> -38100 | U19: =+SUM(U14+SUM(U17:U18)) -> -39144 | V19: =+SUM(V14+SUM(V17:V18)) -> -38072 | W19: =+SUM(W14+SUM(W17:W18)) -> -37378 | X19: =+SUM(X14+SUM(X17:X18)) -> -39666 | Y19: =+SUM(Y14+SUM(Y17:Y18)) -> -39144 | Z19: =+SUM(Z14+SUM(Z17:Z18)) -> -38072 | ... AC19: =+SUM(AC14+SUM(AC17:AC18)) -> -39566 | AE19: =SUM(AC19/Y19)-1 -> 0.010780707
B20: Operating Margin (%) | C20: =C19/C11 -> #DIV/0! | D20: =D19/D11 -> #DIV/0! | E20: =E19/E11 -> #DIV/0! | G20: =G19/G11 -> #DIV/0! | H20: =H19/H11 -> #DIV/0! | I20: =I19/I11 -> #DIV/0! | J20: =J19/J11 -> #DIV/0! | K20: =K19/K11 -> #DIV/0! | L20: =L19/L11 -> #DIV/0! | M20: =M19/M11 -> #DIV/0! | N20: =N19/N11 -> #DIV/0! | ... Q20: =Q19/Q11 -> #DIV/0! | S20: =S19/S11 -> #DIV/0! | T20: =T19/T11 -> #DIV/0! | U20: =U19/U11 -> #DIV/0! | V20: =V19/V11 -> #DIV/0! | W20: =W19/W11 -> #DIV/0! | X20: =X19/X11 -> #DIV/0! | Y20: =Y19/Y11 -> #DIV/0! | Z20: =Z19/Z11 -> #DIV/0! | ... AC20: =AC19/AC11 -> #DIV/0! | AE20: =SUM(AC20-Y20)*1000 -> #DIV/0!
B22: Interest income | C22: 3 | D22: 52 | E22: 230 | G22: 1 | H22: 3 | I22: 18 | J22: 30 | K22: 44 | L22: 50 | M22: 62 | N22: 74 | O22: 80 | P22: 80 | Q22: 93 | S22: =SUM(H22:K22) -> 95 | T22: =SUM(I22:L22) -> 142 | U22: =SUM(J22:M22) -> 186 | V22: =SUM(K22:N22) -> 230 | W22: =SUM(L22:O22) -> 266 | X22: =SUM(M22:P22) -> 296 | Y22: =SUM(J22:M22) -> 186 | Z22: =SUM(K22:N22) -> 230 | AA22: =SUM(L22:O22) -> 266 | AB22: =SUM(M22:P22) -> 296 | AC22: =SUM(N22:Q22) -> 327 | AE22: =SUM(AC22/Y22)-1 -> 0.75806452
B23: Interest expense | C23: -489 | D23: -1033 | E23: -2792 | G23: -227 | H23: -229 | I23: -269 | J23: -308 | K23: -460 | L23: -650 | M23: -835 | N23: -847 | O23: -869 | P23: -1269 | Q23: -1494 | Y23: =SUM(J23:M23) -> -2253 | Z23: =SUM(K23:N23) -> -2792 | AA23: =SUM(L23:O23) -> -3201 | AB23: =SUM(M23:P23) -> -3820 | AC23: =SUM(N23:Q23) -> -4479 | AE23: =SUM(AC23/Y23)-1 -> 0.98801598
B24: Change in fair value of derivatives | C24: 138 | D24: 557 | E24: -432 | G24: 229 | H24: 275 | I24: -224 | J24: 277 | K24: -769 | L24: 489 | M24: -489 | N24: 337 | O24: -1052 | P24: 109 | Q24: -753 | Y24: =SUM(J24:M24) -> -492 | Z24: =SUM(K24:N24) -> -432 | AA24: =SUM(L24:O24) -> -715 | AB24: =SUM(M24:P24) -> -1095 | AC24: =SUM(N24:Q24) -> -1359 | AE24: =SUM(AC24/Y24)-1 -> 1.7621951
B25: Earning Before Taxes | C25: =SUM(C19+SUM(C22:C24)) -> -30527 | D25: =SUM(D19+SUM(D22:D24)) -> -38776 | E25: =SUM(E19+SUM(E22:E24)) -> -41066 | G25: =SUM(G19+SUM(G22:G24)) -> -9932 | H25: =SUM(H19+SUM(H22:H24)) -> -9613 | I25: =SUM(I19+SUM(I22:I24)) -> -8597 | J25: =SUM(J19+SUM(J22:J24)) -> -10634 | K25: =SUM(K19+SUM(K22:K24)) -> -11527 | L25: =SUM(L19+SUM(L22:L24)) -> -9114 | M25: =SUM(M19+SUM(M22:M24)) -> -10428 | N25: =SUM(N19+SUM(N22:N24)) -> -9997 | ... Q25: =SUM(Q19+SUM(Q22:Q24)) -> -11220 | S25: =SUM(S19+SUM(S22:S24)) -> -38664 | T25: =SUM(T19+SUM(T22:T24)) -> -37958 | U25: =SUM(U19+SUM(U22:U24)) -> -38958 | V25: =SUM(V19+SUM(V22:V24)) -> -37842 | W25: =SUM(W19+SUM(W22:W24)) -> -37112 | X25: =SUM(X19+SUM(X22:X24)) -> -39370 | Y25: =SUM(Y19+SUM(Y22:Y24)) -> -41703 | Z25: =SUM(Z19+SUM(Z22:Z24)) -> -41066 | ... AC25: =SUM(AC19+SUM(AC22:AC24)) -> -45077 | AE25: =SUM(AC25/Y25)-1 -> 0.08090545
B26: EBT Margin (%) | C26: =C25/C11 -> #DIV/0! | D26: =D25/D11 -> #DIV/0! | E26: =E25/E11 -> #DIV/0! | G26: =G25/G11 -> #DIV/0! | H26: =H25/H11 -> #DIV/0! | I26: =I25/I11 -> #DIV/0! | J26: =J25/J11 -> #DIV/0! | K26: =K25/K11 -> #DIV/0! | L26: =L25/L11 -> #DIV/0! | M26: =M25/M11 -> #DIV/0! | N26: =N25/N11 -> #DIV/0! | ... Q26: =Q25/Q11 -> #DIV/0! | S26: =S25/S11 -> #DIV/0! | T26: =T25/T11 -> #DIV/0! | U26: =U25/U11 -> #DIV/0! | V26: =V25/V11 -> #DIV/0! | W26: =W25/W11 -> #DIV/0! | X26: =X25/X11 -> #DIV/0! | Y26: =Y25/Y11 -> #DIV/0! | Z26: =Z25/Z11 -> #DIV/0! | ... AC26: =AC25/AC11 -> #DIV/0! | AE26: =SUM(AC26-Y26)*1000 -> #DIV/0!
B28: Provision for taxes | C28: 0 | D28: 0 | E28: 0 | G28: 0 | H28: 0 | I28: 0 | J28: =SUM(C28-SUM(G28:I28)) -> 0 | K28: 0 | L28: 0 | M28: 0 | N28: =SUM(D28-SUM(K28:M28)) -> 0 | O28: 0 | P28: 0 | Q28: 0 | S28: =SUM(H28:K28) -> 0 | T28: =SUM(I28:L28) -> 0 | U28: =SUM(J28:M28) -> 0 | V28: =SUM(K28:N28) -> 0 | W28: =SUM(L28:O28) -> 0 | X28: =SUM(M28:P28) -> 0 | Y28: =SUM(J28:M28) -> 0 | Z28: =SUM(K28:N28) -> 0 | AA28: =SUM(L28:O28) -> 0 | AB28: =SUM(M28:P28) -> 0 | AC28: =SUM(N28:Q28) -> 0 | AE28: =SUM(AC28/Y28)-1 -> #DIV/0!
B29: Net loss | C29: =SUM(C25+C28) -> -30527 | D29: =SUM(D25+D28) -> -38776 | E29: =SUM(E25+E28) -> -41066 | G29: =SUM(G25+G28) -> -9932 | H29: =SUM(H25+H28) -> -9613 | I29: =SUM(I25+I28) -> -8597 | J29: =SUM(J25+J28) -> -10634 | K29: =SUM(K25+K28) -> -11527 | L29: =SUM(L25+L28) -> -9114 | M29: =SUM(M25+M28) -> -10428 | N29: =SUM(N25+N28) -> -9997 | ... Q29: =SUM(Q25+Q28) -> -11220 | S29: =SUM(S25+S28) -> -38664 | T29: =SUM(T25+T28) -> -37958 | U29: =SUM(U25+U28) -> -38958 | V29: =SUM(V25+V28) -> -37842 | W29: =SUM(W25+W28) -> -37112 | X29: =SUM(X25+X28) -> -39370 | Y29: =SUM(Y25+Y28) -> -41703 | Z29: =SUM(Z25+Z28) -> -41066 | ... AC29: =SUM(AC25+AC28) -> -45077 | AE29: =SUM(AC29/Y29)-1 -> 0.08090545
B30: Net Margin (%) | C30: =C29/C11 -> #DIV/0! | D30: =D29/D11 -> #DIV/0! | E30: =E29/E11 -> #DIV/0! | G30: =G29/G11 -> #DIV/0! | H30: =H29/H11 -> #DIV/0! | I30: =I29/I11 -> #DIV/0! | J30: =J29/J11 -> #DIV/0! | K30: =K29/K11 -> #DIV/0! | L30: =L29/L11 -> #DIV/0! | M30: =M29/M11 -> #DIV/0! | N30: =N29/N11 -> #DIV/0! | ... Q30: =Q29/Q11 -> #DIV/0! | S30: =S29/S11 -> #DIV/0! | T30: =T29/T11 -> #DIV/0! | U30: =U29/U11 -> #DIV/0! | V30: =V29/V11 -> #DIV/0! | W30: =W29/W11 -> #DIV/0! | X30: =X29/X11 -> #DIV/0! | Y30: =Y29/Y11 -> #DIV/0! | Z30: =Z29/Z11 -> #DIV/0! | ... AC30: =AC29/AC11 -> #DIV/0! | AE30: =SUM(AC30-Y30)*1000 -> #DIV/0!
B32: Basic shares | J32: =D32 -> 0 | N32: =E32 -> 0 | S32: =G32 -> 0 | T32: =H32 -> 0 | U32: =I32 -> 0 | V32: =J32 -> 0 | W32: =K32 -> 0 | X32: =L32 -> 0 | Y32: =M32 -> 0 | Z32: =N32 -> 0 | ... AC32: =Q32 -> 0 | AE32: =SUM(AC32/Y32)-1 -> #DIV/0!
B33: Basic EPS | C33: =C29/C32 -> #DIV/0! | D33: =D29/D32 -> #DIV/0! | E33: =E29/E32 -> #DIV/0! | G33: =G29/G32 -> #DIV/0! | H33: =H29/H32 -> #DIV/0! | I33: =I29/I32 -> #DIV/0! | J33: =J29/J32 -> #DIV/0! | K33: =K29/K32 -> #DIV/0! | L33: =L29/L32 -> #DIV/0! | M33: =M29/M32 -> #DIV/0! | N33: =N29/N32 -> #DIV/0! | ... Q33: =Q29/Q32 -> #DIV/0! | S33: =S29/S32 -> #DIV/0! | T33: =T29/T32 -> #DIV/0! | U33: =U29/U32 -> #DIV/0! | V33: =V29/V32 -> #DIV/0! | W33: =W29/W32 -> #DIV/0! | X33: =X29/X32 -> #DIV/0! | Y33: =Y29/Y32 -> #DIV/0! | Z33: =Z29/Z32 -> #DIV/0! | ... AC33: =AC29/AC32 -> #DIV/0! | AE33: =SUM(AC33/Y33)-1 -> #DIV/0!
B35: Fully Diluted Shares | C35: 58527 | D35: 59391 | E35: 60159 | G35: 59354 | H35: 59389 | I35: 59396 | J35: =D35 -> 59391 | K35: 59480 | L35: 59582 | M35: 59704 | N35: =E35 -> 60159 | O35: 61976 | P35: 62233 | Q35: 62278 | S35: =K35 -> 59480 | T35: =L35 -> 59582 | U35: =M35 -> 59704 | V35: =N35 -> 60159 | W35: =O35 -> 61976 | X35: =P35 -> 62233 | Y35: =M35 -> 59704 | Z35: =N35 -> 60159 | AA35: =O35 -> 61976 | AB35: =P35 -> 62233 | AC35: =Q35 -> 62278 | AE35: =SUM(AC35/Y35)-1 -> 0.043112689
B36: Diluted EPS | C36: =C29/C35 -> -0.52158833 | D36: =D29/D35 -> -0.65289354 | E36: =E29/E35 -> -0.68262438 | G36: =G29/G35 -> -0.16733497 | H36: =H29/H35 -> -0.16186499 | I36: =I29/I35 -> -0.14474039 | J36: =J29/J35 -> -0.1790507 | K36: =K29/K35 -> -0.19379623 | L36: =L29/L35 -> -0.15296566 | M36: =M29/M35 -> -0.17466166 | N36: =N29/N35 -> -0.1661763 | ... Q36: =Q29/Q35 -> -0.18015993 | S36: =S29/S35 -> -0.65003362 | T36: =T29/T35 -> -0.6370716 | U36: =U29/U35 -> -0.65251909 | V36: =V29/V35 -> -0.62903306 | W36: =W29/W35 -> -0.59881244 | X36: =X29/X35 -> -0.63262256 | Y36: =Y29/Y35 -> -0.69849591 | Z36: =Z29/Z35 -> -0.68262438 | ... AC36: =AC29/AC35 -> -0.72380295 | AE36: =SUM(AC36/Y36)-1 -> 0.036230756
A38: X | B38: Balance Sheet | C38: FYE | G38: Quarterly | Q38: Quarterly | Y38: LTM | AE38: Variance
B39: =B7 -> Fiscal Period | C39: =C7 -> 2021 | D39: =D7 -> 2022 | E39: =E7 -> 2023 | G39: =G7 -> 1Q22 | H39: =H7 -> 2Q22 | I39: =I7 -> 3Q22 | J39: =J7 -> 4Q22 | K39: =K7 -> 1Q23 | L39: =L7 -> 2Q23 | M39: =M7 -> 3Q23 | N39: =N7 -> 4Q23 | ... Q39: =Q7 -> 3Q24 | S39: =S7 -> 1Q22 | T39: =T7 -> 2Q22 | U39: =U7 -> 3Q22 | V39: =V7 -> 4Q22 | W39: =W7 -> 1Q23 | X39: =X7 -> 2Q23 | Y39: =Y7 -> 3Q23 | Z39: =Z7 -> 4Q23 | ... AC39: =AC7 -> 3Q24
B40: =B8 -> Fiscal Period End Date | C40: =C8 -> 44561 | D40: =D8 -> 44926 | E40: =E8 -> 45291 | G40: =G8 -> 44651 | H40: =H8 -> 44742 | I40: =I8 -> 44834 | J40: =J8 -> 44926 | K40: =K8 -> 45016 | L40: =L8 -> 45107 | M40: =M8 -> 45199 | N40: =N8 -> 45291 | ... Q40: =Q8 -> 45565 | S40: =S8 -> 44651 | T40: =T8 -> 44742 | U40: =U8 -> 44834 | V40: =V8 -> 44926 | W40: =W8 -> 45016 | X40: =X8 -> 45107 | Y40: =Y8 -> 45199 | Z40: =Z8 -> 45291 | ... AC40: =AC8 -> 45565
B42: Current Assets
B43: Cash and cash equivalents | C43: 39648 | D43: 18592 | E43: 25660 | G43: 31606 | H43: 24178 | I43: 15831 | J43: =D43 -> 18592 | K43: 17799 | L43: 17966 | M43: 20362 | N43: =E43 -> 25660 | O43: 23555 | P43: 25598 | Q43: 27060 | S43: =G43 -> 31606 | T43: =H43 -> 24178 | U43: =I43 -> 15831 | V43: =J43 -> 18592 | W43: =K43 -> 17799 | X43: =L43 -> 17966 | Y43: =M43 -> 20362 | Z43: =N43 -> 25660 | ... AC43: =Q43 -> 27060 | AE43: =SUM(AC43/Y43)-1 -> 0.32894608
B44: Prepaid expenses and other current assets | C44: 2172 | D44: 1960 | E44: 2050 | G44: 1901 | H44: 1607 | I44: 1290 | J44: =D44 -> 1960 | K44: 1753 | L44: 1502 | M44: 1249 | N44: =E44 -> 2050 | O44: 1905 | P44: 1689 | Q44: 1606 | S44: =J44 -> 1960 | T44: =K44 -> 1753 | U44: =L44 -> 1502 | V44: =M44 -> 1249 | W44: =N44 -> 2050 | X44: =O44 -> 1905 | Y44: =M44 -> 1249 | Z44: =N44 -> 2050 | AA44: =O44 -> 1905 | AB44: =P44 -> 1689 | AC44: =Q44 -> 1606 | AE44: =SUM(AC44/Y44)-1 -> 0.28582866
B45: Total Current Assets | C45: =SUM(C43:C44) -> 41820 | D45: =SUM(D43:D44) -> 20552 | E45: =SUM(E43:E44) -> 27710 | G45: =SUM(G43:G44) -> 33507 | H45: =SUM(H43:H44) -> 25785 | I45: =SUM(I43:I44) -> 17121 | J45: =SUM(J43:J44) -> 20552 | K45: =SUM(K43:K44) -> 19552 | L45: =SUM(L43:L44) -> 19468 | M45: =SUM(M43:M44) -> 21611 | N45: =SUM(N43:N44) -> 27710 | ... Q45: =SUM(Q43:Q44) -> 28666 | S45: =SUM(S43:S44) -> 33566 | T45: =SUM(T43:T44) -> 25931 | U45: =SUM(U43:U44) -> 17333 | V45: =SUM(V43:V44) -> 19841 | W45: =SUM(W43:W44) -> 19849 | X45: =SUM(X43:X44) -> 19871 | Y45: =SUM(Y43:Y44) -> 21611 | Z45: =SUM(Z43:Z44) -> 27710 | ... AC45: =SUM(AC43:AC44) -> 28666 | AE45: =SUM(AC45/Y45)-1 -> 0.32645412
B47: Non-Current Assets
B48: Property and equipment, net | C48: 0 | D48: 0 | E48: 0 | H48: 0 | I48: - | J48: =D48 -> 0 | K48: 0 | L48: 0 | M48: 0 | N48: =E48 -> 0 | O48: 0 | P48: 0 | Q48: - | S48: =J48 -> 0 | T48: =K48 -> 0 | U48: =L48 -> 0 | V48: =M48 -> 0 | W48: =N48 -> 0 | X48: =O48 -> 0 | Y48: =M48 -> 0 | Z48: =N48 -> 0 | AA48: =O48 -> 0 | AB48: =P48 -> 0 | AC48: =Q48 -> - | AE48: =SUM(AC48/Y48)-1 -> #VALUE!
B49: Other | C49: 7 | D49: 733 | E49: 490 | G49: 108 | H49: 101 | I49: 793 | J49: =D49 -> 733 | K49: 673 | L49: 613 | M49: 552 | N49: =E49 -> 490 | O49: 430 | P49: 368 | Q49: 306 | S49: =K49 -> 673 | T49: =L49 -> 613 | U49: =M49 -> 552 | V49: =N49 -> 490 | W49: =O49 -> 430 | X49: =P49 -> 368 | Y49: =M49 -> 552 | Z49: =N49 -> 490 | AA49: =O49 -> 430 | AB49: =P49 -> 368 | AC49: =Q49 -> 306 | AE49: =SUM(AC49/Y49)-1 -> -0.44565217
B50: Total Assets | C50: =SUM(C48:C49)+C45 -> 41827 | D50: =SUM(D48:D49)+D45 -> 21285 | E50: =SUM(E48:E49)+E45 -> 28200 | G50: =SUM(G48:G49)+G45 -> 33615 | H50: =SUM(H48:H49)+H45 -> 25886 | I50: =SUM(I48:I49)+I45 -> 17914 | J50: =SUM(J48:J49)+J45 -> 21285 | K50: =SUM(K48:K49)+K45 -> 20225 | L50: =SUM(L48:L49)+L45 -> 20081 | M50: =SUM(M48:M49)+M45 -> 22163 | N50: =SUM(N48:N49)+N45 -> 28200 | ... Q50: =SUM(Q48:Q49)+Q45 -> 28972 | S50: =SUM(S48:S49)+S45 -> 34239 | T50: =SUM(T48:T49)+T45 -> 26544 | U50: =SUM(U48:U49)+U45 -> 17885 | V50: =SUM(V48:V49)+V45 -> 20331 | W50: =SUM(W48:W49)+W45 -> 20279 | X50: =SUM(X48:X49)+X45 -> 20239 | Y50: =SUM(Y48:Y49)+Y45 -> 22163 | Z50: =SUM(Z48:Z49)+Z45 -> 28200 | ... AC50: =SUM(AC48:AC49)+AC45 -> 28972 | AE50: =SUM(AC50/Y50)-1 -> 0.30722375
B52: Current Liabilities
B53: Accounts payable | C53: 1805 | D53: 3890 | E53: 6431 | G53: 1906 | H53: 2964 | I53: 2352 | J53: =D53 -> 3890 | K53: 2553 | L53: 1976 | M53: 2681 | N53: =E53 -> 6431 | O53: 3797 | P53: 3698 | Q53: 2795 | S53: =K53 -> 2553 | T53: =L53 -> 1976 | U53: =M53 -> 2681 | V53: =N53 -> 6431 | W53: =O53 -> 3797 | X53: =P53 -> 3698 | Y53: =M53 -> 2681 | Z53: =N53 -> 6431 | AA53: =O53 -> 3797 | AB53: =P53 -> 3698 | AC53: =Q53 -> 2795 | AE53: =SUM(AC53/Y53)-1 -> 0.042521447
...

Sheet Revenue Drivers
B2: Galectin Therapeutics Inc (NASDAQ: GALT) | H2: Quarterly | P2: Quarterly | Q2: Quarterly | W2: LTM | AA2: LTM | AC2: LTM
B3: Segment Anaysis | C3: ='Historical Financials'!#REF! -> #REF! | D3: ='Historical Financials'!C7 -> 2021 | E3: ='Historical Financials'!D7 -> 2022 | F3: ='Historical Financials'!E7 -> 2023 | H3: ='Historical Financials'!G7 -> 1Q22 | I3: ='Historical Financials'!H7 -> 2Q22 | J3: ='Historical Financials'!I7 -> 3Q22 | K3: ='Historical Financials'!J7 -> 4Q22 | L3: ='Historical Financials'!K7 -> 1Q23 | M3: ='Historical Financials'!L7 -> 2Q23 | N3: ='Historical Financials'!M7 -> 3Q23 | O3: ='Historical Financials'!N7 -> 4Q23 | ... R3: ='Historical Financials'!Q7 -> 3Q24 | S3: ='Historical Financials'!#REF! -> #REF! | T3: ='Historical Financials'!#REF! -> #REF! | U3: ='Historical Financials'!#REF! -> #REF! | W3: =L3 -> 1Q23 | X3: =M3 -> 2Q23 | Y3: =N3 -> 3Q23 | Z3: =O3 -> 4Q23 | AA3: =P3 -> 1Q24 | AB3: =Q3 -> 2Q24 | AC3: =S3 -> #REF! | AD3: =T3 -> #REF! | AE3: =U3 -> #REF! | AF3: =#REF! -> #REF!
B4: $ in thousands except per share | C4: ='Historical Financials'!#REF! -> #REF! | D4: ='Historical Financials'!C8 -> 44561 | E4: ='Historical Financials'!D8 -> 44926 | F4: ='Historical Financials'!E8 -> 45291 | H4: ='Historical Financials'!G8 -> 44651 | I4: ='Historical Financials'!H8 -> 44742 | J4: ='Historical Financials'!I8 -> 44834 | K4: ='Historical Financials'!J8 -> 44926 | L4: ='Historical Financials'!K8 -> 45016 | M4: ='Historical Financials'!L8 -> 45107 | N4: ='Historical Financials'!M8 -> 45199 | O4: ='Historical Financials'!N8 -> 45291 | ... R4: ='Historical Financials'!Q8 -> 45565 | S4: ='Historical Financials'!#REF! -> #REF! | T4: ='Historical Financials'!#REF! -> #REF! | U4: ='Historical Financials'!#REF! -> #REF! | W4: =L4 -> 45016 | X4: =M4 -> 45107 | Y4: =N4 -> 45199 | Z4: =O4 -> 45291 | AA4: =P4 -> 45382 | AB4: =Q4 -> 45473 | AC4: =S4 -> #REF! | AD4: =T4 -> #REF! | AE4: =U4 -> #REF! | AF4: =#REF! -> #REF!
A6: X | B6: Net Revenues by Channel
W7: =SUM(I7:L7) -> 0 | X7: =SUM(J7:M7) -> 0 | Y7: =SUM(K7:N7) -> 0 | Z7: =SUM(L7:O7) -> 0 | AA7: =SUM(M7:P7) -> 0 | AB7: =SUM(N7:Q7) -> 0 | AC7: =SUM(P7:S7) -> 0 | AD7: =SUM(Q7:T7) -> 0 | AE7: =SUM(R7:U7) -> 0 | AF7: =SUM(S7:U7) -> 0
W8: =SUM(I8:L8) -> 0 | X8: =SUM(J8:M8) -> 0 | Y8: =SUM(K8:N8) -> 0 | Z8: =SUM(L8:O8) -> 0 | AA8: =SUM(M8:P8) -> 0 | AB8: =SUM(N8:Q8) -> 0 | AC8: =SUM(P8:S8) -> 0 | AD8: =SUM(Q8:T8) -> 0 | AE8: =SUM(R8:U8) -> 0 | AF8: =SUM(S8:U8) -> 0
B9: Total Net Revenue | D9: =SUM(D7:D8) -> 0 | E9: =SUM(E7:E8) -> 0 | F9: =SUM(F7:F8) -> 0 | P9: =SUM(P7:P8) -> 0 | Q9: =SUM(Q7:Q8) -> 0 | R9: =SUM(R7:R8) -> 0 | S9: =SUM(S7:S8) -> 0 | T9: =SUM(T7:T8) -> 0 | U9: =SUM(U7:U8) -> 0 | W9: =SUM(W7:W8) -> 0 | X9: =SUM(X7:X8) -> 0 | Y9: =SUM(Y7:Y8) -> 0 | Z9: =SUM(Z7:Z8) -> 0 | AA9: =SUM(AA7:AA8) -> 0 | AB9: =SUM(AB7:AB8) -> 0 | AC9: =SUM(AC7:AC8) -> 0 | AD9: =SUM(AD7:AD8) -> 0 | ... AF9: =SUM(AF7:AF8) -> 0
B10: Balance Check | D10: =+D9-'Historical Financials'!C11 -> 0 | E10: =+E9-'Historical Financials'!D11 -> 0 | F10: =+F9-'Historical Financials'!E11 -> 0 | P10: =+P9-'Historical Financials'!O11 -> 0 | Q10: =+Q9-'Historical Financials'!P11 -> 0 | R10: =+R9-'Historical Financials'!Q11 -> 0 | S10: =+S9-'Historical Financials'!#REF! -> #REF! | T10: =+T9-'Historical Financials'!#REF! -> #REF! | U10: =+U9-'Historical Financials'!#REF! -> #REF! | W10: =W9-'Historical Financials'!S11 -> 0 | X10: =X9-'Historical Financials'!T11 -> 0 | Y10: =Y9-'Historical Financials'!U11 -> 0 | Z10: =Z9-'Historical Financials'!V11 -> 0 | AA10: =AA9-'Historical Financials'!W11 -> 0 | AB10: =AB9-'Historical Financials'!X11 -> 0 | AC10: =AC9-'Historical Financials'!Z11 -> 0 | AD10: =AD9-'Historical Financials'!AA11 -> 0 | AE10: =AE9-'Historical Financials'!AB11 -> 0 | AF10: =AF9-'Historical Financials'!AC11 -> 0
A12: X | B12: Revenue by Channel
W13: =SUM(I13:L13) -> 0 | X13: =SUM(J13:M13) -> 0 | Y13: =SUM(K13:N13) -> 0 | Z13: =SUM(L13:O13) -> 0 | AA13: =SUM(M13:P13) -> 0 | AB13: =SUM(N13:Q13) -> 0 | AC13: =SUM(P13:S13) -> 0 | AD13: =SUM(Q13:T13) -> 0 | AE13: =SUM(R13:U13) -> 0 | AF13: =SUM(S13:U13) -> 0
W14: =SUM(I14:L14) -> 0 | X14: =SUM(J14:M14) -> 0 | Y14: =SUM(K14:N14) -> 0 | Z14: =SUM(L14:O14) -> 0 | AA14: =SUM(M14:P14) -> 0 | AB14: =SUM(N14:Q14) -> 0 | AC14: =SUM(P14:S14) -> 0 | AD14: =SUM(Q14:T14) -> 0 | AE14: =SUM(R14:U14) -> 0 | AF14: =SUM(S14:U14) -> 0
B15: Total Net U.S Revenue | D15: =SUM(D13:D14) -> 0 | E15: =SUM(E13:E14) -> 0 | F15: =SUM(F13:F14) -> 0 | P15: =SUM(P13:P14) -> 0 | Q15: =SUM(Q13:Q14) -> 0 | R15: =SUM(R13:R14) -> 0 | S15: =SUM(S13:S14) -> 0 | T15: =SUM(T13:T14) -> 0 | U15: =SUM(U13:U14) -> 0 | W15: =SUM(W13:W14) -> 0 | X15: =SUM(X13:X14) -> 0 | Y15: =SUM(Y13:Y14) -> 0 | Z15: =SUM(Z13:Z14) -> 0 | AA15: =SUM(AA13:AA14) -> 0 | AB15: =SUM(AB13:AB14) -> 0 | AC15: =SUM(AC13:AC14) -> 0 | AD15: =SUM(AD13:AD14) -> 0 | ... AF15: =SUM(AF13:AF14) -> 0
B16: Balance Check | D16: =+D15-D9 -> 0 | E16: =+E15-E9 -> 0 | F16: =+F15-F9 -> 0 | P16: =+P15-P9 -> 0 | Q16: =+Q15-Q9 -> 0 | R16: =+R15-R9 -> 0 | S16: =+S15-S9 -> 0 | T16: =+T15-T9 -> 0 | U16: =+U15-U9 -> 0 | W16: =W15-'Historical Financials'!S17 -> 32478 | X16: =X15-'Historical Financials'!T17 -> 31775 | Y16: =Y15-'Historical Financials'!U17 -> 32909 | Z16: =Z15-'Historical Financials'!V17 -> 32130 | AA16: =AA15-'Historical Financials'!W17 -> 31385 | AB16: =AB15-'Historical Financials'!X17 -> 33827 | AC16: =+AC15-AC9 -> 0 | AD16: =+AD15-AD9 -> 0 | AE16: =+AE15-AE9 -> 0 | AF16: =+AF15-AF9 -> 0

Sheet FCF
B2: Galectin Therapeutics Inc (NASDAQ: GALT) | D2: FYE | H2: Quarterly | Q2: Quarterly | R2: Quarterly | X2: LTM | AE2: LTM | AK2: Variance
B3: FCF Analysis | C3: ='Historical Financials'!#REF! -> #REF! | D3: ='Historical Financials'!C7 -> 2021 | E3: ='Historical Financials'!D7 -> 2022 | F3: ='Historical Financials'!E7 -> 2023 | H3: ='Historical Financials'!G7 -> 1Q22 | I3: ='Historical Financials'!H7 -> 2Q22 | J3: ='Historical Financials'!I7 -> 3Q22 | K3: ='Historical Financials'!J7 -> 4Q22 | L3: ='Historical Financials'!K7 -> 1Q23 | M3: ='Historical Financials'!L7 -> 2Q23 | N3: ='Historical Financials'!M7 -> 3Q23 | O3: ='Historical Financials'!N7 -> 4Q23 | ... R3: ='Historical Financials'!Q7 -> 3Q24 | S3: ='Historical Financials'!#REF! -> #REF! | T3: ='Historical Financials'!#REF! -> #REF! | U3: ='Historical Financials'!#REF! -> #REF! | V3: ='Historical Financials'!#REF! -> #REF! | X3: =K3 -> 4Q22 | Y3: =L3 -> 1Q23 | Z3: =M3 -> 2Q23 | AA3: =N3 -> 3Q23 | AB3: =O3 -> 4Q23 | AC3: =P3 -> 1Q24 | AD3: =Q3 -> 2Q24 | AE3: =R3 -> 3Q24 | ... AI3: =V3 -> #REF!
B4: $ in thousands except per share | C4: ='Historical Financials'!#REF! -> #REF! | D4: ='Historical Financials'!C8 -> 44561 | E4: ='Historical Financials'!D8 -> 44926 | F4: ='Historical Financials'!E8 -> 45291 | H4: ='Historical Financials'!G8 -> 44651 | I4: ='Historical Financials'!H8 -> 44742 | J4: ='Historical Financials'!I8 -> 44834 | K4: ='Historical Financials'!J8 -> 44926 | L4: ='Historical Financials'!K8 -> 45016 | M4: ='Historical Financials'!L8 -> 45107 | N4: ='Historical Financials'!M8 -> 45199 | O4: ='Historical Financials'!N8 -> 45291 | ... R4: ='Historical Financials'!Q8 -> 45565 | S4: ='Historical Financials'!#REF! -> #REF! | T4: ='Historical Financials'!#REF! -> #REF! | U4: ='Historical Financials'!#REF! -> #REF! | V4: ='Historical Financials'!#REF! -> #REF! | X4: =K4 -> 44926 | Y4: =L4 -> 45016 | Z4: =M4 -> 45107 | AA4: =N4 -> 45199 | AB4: =O4 -> 45291 | AC4: =P4 -> 45382 | AD4: =Q4 -> 45473 | AE4: =R4 -> 45565 | ... AI4: =V4 -> #REF!
P6: ='Revenue Drivers'!P7 -> 0 | Q6: ='Revenue Drivers'!Q7 -> 0 | AC6: =SUM(M6:P6) -> 0 | AD6: =SUM(N6:Q6) -> 0 | AE6: =SUM(O6:R6) -> 0 | AF6: =SUM(P6:S6) -> 0 | AG6: =SUM(Q6:T6) -> 0 | AH6: =SUM(R6:U6) -> 0 | AI6: =SUM(S6:V6) -> 0 | AK6: =SUM(AI6/AE6)-1 -> #DIV/0!
P7: ='Revenue Drivers'!P8 -> 0 | Q7: ='Revenue Drivers'!Q8 -> 0 | AC7: =SUM(M7:P7) -> 0 | AD7: =SUM(N7:Q7) -> 0 | AE7: =SUM(O7:R7) -> 0 | AF7: =SUM(P7:S7) -> 0 | AG7: =SUM(Q7:T7) -> 0 | AH7: =SUM(R7:U7) -> 0 | AI7: =SUM(S7:V7) -> 0 | AK7: =SUM(AI7/AE7)-1 -> #DIV/0!
B8: Total Revenue | C8: ='Historical Financials'!#REF! -> #REF! | D8: =SUM(D6:D7) -> 0 | E8: =SUM(E6:E7) -> 0 | F8: =SUM(F6:F7) -> 0 | H8: ='Historical Financials'!G11 -> 0 | I8: ='Historical Financials'!H11 -> 0 | J8: ='Historical Financials'!I11 -> 0 | K8: ='Historical Financials'!J11 -> 0 | L8: ='Historical Financials'!K11 -> 0 | M8: ='Historical Financials'!L11 -> 0 | N8: ='Historical Financials'!M11 -> 0 | O8: ='Historical Financials'!N11 -> 0 | P8: =SUM(P6:P7) -> 0 | Q8: =SUM(Q6:Q7) -> 0 | R8: =SUM(R6:R7) -> 0 | S8: =SUM(S6:S7) -> 0 | T8: =SUM(T6:T7) -> 0 | U8: =SUM(U6:U7) -> 0 | V8: =SUM(V6:V7) -> 0 | X8: =SUM(H8:K8) -> 0 | Y8: =SUM(I8:L8) -> 0 | Z8: =SUM(J8:M8) -> 0 | AA8: =SUM(K8:N8) -> 0 | AB8: =SUM(L8:O8) -> 0 | AC8: =SUM(AC6:AC7) -> 0 | AD8: =SUM(AD6:AD7) -> 0 | AE8: =SUM(AE6:AE7) -> 0 | AF8: =SUM(AF6:AF7) -> 0 | AG8: =SUM(AG6:AG7) -> 0 | AH8: =SUM(AH6:AH7) -> 0 | AI8: =SUM(AI6:AI7) -> 0 | AK8: =SUM(AI8/AE8)-1 -> #DIV/0!
B9: Y/Y Growth (%) | D9: =SUM(D8/C8)-1 -> #REF! | E9: =SUM(E8/D8)-1 -> #DIV/0! | F9: =SUM(F8/E8)-1 -> #DIV/0! | M9: =SUM(M8/I8)-1 -> #DIV/0! | N9: =SUM(N8/J8)-1 -> #DIV/0! | O9: =SUM(O8/K8)-1 -> #DIV/0! | P9: =SUM(P8/L8)-1 -> #DIV/0! | Q9: =SUM(Q8/M8)-1 -> #DIV/0! | R9: =SUM(R8/N8)-1 -> #DIV/0! | S9: =SUM(S8/O8)-1 -> #DIV/0! | T9: =SUM(T8/P8)-1 -> #DIV/0! | ... V9: =SUM(V8/R8)-1 -> #DIV/0! | AB9: =SUM(AB8/X8)-1 -> #DIV/0! | AC9: =SUM(AC8/Y8)-1 -> #DIV/0! | AD9: =SUM(AD8/Z8)-1 -> #DIV/0! | AE9: =SUM(AE8/AA8)-1 -> #DIV/0! | AF9: =SUM(AF8/AB8)-1 -> #DIV/0! | AG9: =SUM(AG8/AC8)-1 -> #DIV/0! | AH9: =SUM(AH8/AD8)-1 -> #DIV/0! | AI9: =SUM(AI8/AE8)-1 -> #DIV/0! | AK9: =SUM(AI9-AE9)*10000 -> #DIV/0!
B10: Q/Q Growth (%) | C10: N/A | D10: N/A | E10: N/A | F10: N/A | J10: =SUM(J8/I8)-1 -> #DIV/0! | K10: =SUM(K8/J8)-1 -> #DIV/0! | L10: =SUM(L8/K8)-1 -> #DIV/0! | M10: =SUM(M8/L8)-1 -> #DIV/0! | N10: =SUM(N8/M8)-1 -> #DIV/0! | O10: =SUM(O8/N8)-1 -> #DIV/0! | P10: =SUM(P8/O8)-1 -> #DIV/0! | Q10: =SUM(Q8/P8)-1 -> #DIV/0! | ... V10: =SUM(V8/U8)-1 -> #DIV/0! | X10: N/A | Y10: N/A | Z10: N/A | AA10: N/A | AB10: N/A | AC10: N/A | AD10: N/A | AE10: N/A | AF10: N/A | AG10: N/A | AH10: N/A | AI10: N/A
B12: (-) Cost of Sales | C12: ='Historical Financials'!#REF! -> #REF! | H12: ='Historical Financials'!G13 -> 0 | I12: ='Historical Financials'!H13 -> 0 | J12: ='Historical Financials'!I13 -> 0 | K12: ='Historical Financials'!J13 -> 0 | L12: ='Historical Financials'!K13 -> 0 | M12: ='Historical Financials'!L13 -> 0 | N12: ='Historical Financials'!M13 -> 0 | O12: ='Historical Financials'!N13 -> 0 | ... Q12: ='Historical Financials'!P13 -> 0 | X12: =SUM(G12:K12) -> 0 | Y12: =SUM(I12:L12) -> 0 | Z12: =SUM(J12:M12) -> 0 | AA12: =SUM(K12:N12) -> 0 | AB12: =SUM(L12:O12) -> 0 | AC12: =SUM(M12:P12) -> 0 | AD12: =SUM(N12:Q12) -> 0 | AE12: =SUM(O12:R12) -> 0 | AF12: =SUM(P12:S12) -> 0 | ... AI12: =SUM(S12:V12) -> 0 | AK12: =SUM(AI12/AE12)-1 -> #DIV/0!
B13: Gross Profit | C13: =+C8+C12 -> #REF! | D13: =+D8+D12 -> 0 | E13: =+E8+E12 -> 0 | F13: =+F8+F12 -> 0 | H13: =+H8+H12 -> 0 | I13: =+I8+I12 -> 0 | J13: =+J8+J12 -> 0 | K13: =+K8+K12 -> 0 | L13: =+L8+L12 -> 0 | M13: =+M8+M12 -> 0 | N13: =+N8+N12 -> 0 | O13: =+O8+O12 -> 0 | ... V13: =+V8+V12 -> 0 | X13: =+X8+X12 -> 0 | Y13: =+Y8+Y12 -> 0 | Z13: =+Z8+Z12 -> 0 | AA13: =+AA8+AA12 -> 0 | AB13: =+AB8+AB12 -> 0 | AC13: =+AC8+AC12 -> 0 | AD13: =+AD8+AD12 -> 0 | AE13: =+AE8+AE12 -> 0 | ... AI13: =+AI8+AI12 -> 0 | AK13: =SUM(AI13/AE13)-1 -> #DIV/0!
B14: Gross Margin (%) | C14: =C13/C8 -> #REF! | D14: =D13/D8 -> #DIV/0! | E14: =E13/E8 -> #DIV/0! | F14: =F13/F8 -> #DIV/0! | H14: =H13/H8 -> #DIV/0! | I14: =I13/I8 -> #DIV/0! | J14: =J13/J8 -> #DIV/0! | K14: =K13/K8 -> #DIV/0! | L14: =L13/L8 -> #DIV/0! | M14: =M13/M8 -> #DIV/0! | N14: =N13/N8 -> #DIV/0! | O14: =O13/O8 -> #DIV/0! | ... V14: =V13/V8 -> #DIV/0! | X14: =X13/X8 -> #DIV/0! | Y14: =Y13/Y8 -> #DIV/0! | Z14: =Z13/Z8 -> #DIV/0! | AA14: =AA13/AA8 -> #DIV/0! | AB14: =AB13/AB8 -> #DIV/0! | AC14: =AC13/AC8 -> #DIV/0! | AD14: =AD13/AD8 -> #DIV/0! | AE14: =AE13/AE8 -> #DIV/0! | ... AI14: =AI13/AI8 -> #DIV/0! | AK14: =SUM(AI14-AE14)*10000 -> #DIV/0!
B16: (-) Research and development | C16: ='Historical Financials'!#REF! -> #REF! | H16: ='Historical Financials'!G17 -> -8058 | I16: ='Historical Financials'!H17 -> -8074 | J16: ='Historical Financials'!I17 -> -6598 | K16: ='Historical Financials'!J17 -> -9007 | L16: ='Historical Financials'!K17 -> -8799 | M16: ='Historical Financials'!L17 -> -7371 | N16: ='Historical Financials'!M17 -> -7732 | O16: ='Historical Financials'!N17 -> -8228 | ... Q16: ='Historical Financials'!P17 -> -9813 | X16: =SUM(G16:K16) -> -31737 | Y16: =SUM(I16:L16) -> -32478 | Z16: =SUM(J16:M16) -> -31775 | AA16: =SUM(K16:N16) -> -32909 | AB16: =SUM(L16:O16) -> -32130 | AC16: =SUM(M16:P16) -> -31385 | AD16: =SUM(N16:Q16) -> -33827 | AE16: =SUM(O16:R16) -> -26095 | AF16: =SUM(P16:S16) -> -17867 | ... AI16: =SUM(S16:V16) -> 0 | AK16: =SUM(AI16/AE16)-1 -> -1
B17: (-) Sales and marketing | C17: ='Historical Financials'!#REF! -> #REF! | H17: ='Historical Financials'!G18 -> -1877 | I17: ='Historical Financials'!H18 -> -1588 | J17: ='Historical Financials'!I18 -> -1524 | K17: ='Historical Financials'!J18 -> -1626 | L17: ='Historical Financials'!K18 -> -1543 | M17: ='Historical Financials'!L18 -> -1632 | N17: ='Historical Financials'!M18 -> -1434 | O17: ='Historical Financials'!N18 -> -1333 | ... Q17: ='Historical Financials'!P18 -> -1478 | X17: =SUM(G17:K17) -> -6615 | Y17: =SUM(I17:L17) -> -6281 | Z17: =SUM(J17:M17) -> -6325 | AA17: =SUM(K17:N17) -> -6235 | AB17: =SUM(L17:O17) -> -5942 | AC17: =SUM(M17:P17) -> -5993 | AD17: =SUM(N17:Q17) -> -5839 | AE17: =SUM(O17:R17) -> -4405 | AF17: =SUM(P17:S17) -> -3072 | ... AI17: =SUM(S17:V17) -> 0 | AK17: =SUM(AI17/AE17)-1 -> -1
B18: (-) General and administrative | C18: ='Historical Financials'!#REF! -> #REF! | H18: ='Historical Financials'!#REF! -> #REF! | I18: ='Historical Financials'!#REF! -> #REF! | J18: ='Historical Financials'!#REF! -> #REF! | K18: ='Historical Financials'!#REF! -> #REF! | L18: ='Historical Financials'!#REF! -> #REF! | M18: ='Historical Financials'!#REF! -> #REF! | N18: ='Historical Financials'!#REF! -> #REF! | O18: ='Historical Financials'!#REF! -> #REF! | ... Q18: ='Historical Financials'!#REF! -> #REF! | X18: =SUM(G18:K18) -> #REF! | Y18: =SUM(I18:L18) -> #REF! | Z18: =SUM(J18:M18) -> #REF! | AA18: =SUM(K18:N18) -> #REF! | AB18: =SUM(L18:O18) -> #REF! | AC18: =SUM(M18:P18) -> #REF! | AD18: =SUM(N18:Q18) -> #REF! | AE18: =SUM(O18:R18) -> #REF! | AF18: =SUM(P18:S18) -> #REF! | ... AI18: =SUM(S18:V18) -> 0 | AK18: =SUM(AI18/AE18)-1 -> #REF!
B19: (-) Depreciation and amortization | C19: ='Historical Financials'!#REF! -> #REF! | H19: ='Historical Financials'!#REF! -> #REF! | I19: ='Historical Financials'!#REF! -> #REF! | J19: ='Historical Financials'!#REF! -> #REF! | K19: ='Historical Financials'!#REF! -> #REF! | L19: ='Historical Financials'!#REF! -> #REF! | M19: ='Historical Financials'!#REF! -> #REF! | N19: ='Historical Financials'!#REF! -> #REF! | O19: ='Historical Financials'!#REF! -> #REF! | ... Q19: ='Historical Financials'!#REF! -> #REF! | X19: =SUM(G19:K19) -> #REF! | Y19: =SUM(I19:L19) -> #REF! | Z19: =SUM(J19:M19) -> #REF! | AA19: =SUM(K19:N19) -> #REF! | AB19: =SUM(L19:O19) -> #REF! | AC19: =SUM(M19:P19) -> #REF! | AD19: =SUM(N19:Q19) -> #REF! | AE19: =SUM(O19:R19) -> #REF! | AF19: =SUM(P19:S19) -> #REF! | ... AI19: =SUM(S19:V19) -> 0 | AK19: =SUM(AI19/AE19)-1 -> #REF!
B20: Earning before Interest & Taxes (EBIT) | C20: =SUM(C13+SUM(C16:C19)) -> #REF! | D20: =SUM(D13+SUM(D16:D19)) -> 0 | E20: =SUM(E13+SUM(E16:E19)) -> 0 | F20: =SUM(F13+SUM(F16:F19)) -> 0 | H20: =SUM(H13+SUM(H16:H19)) -> #REF! | I20: =SUM(I13+SUM(I16:I19)) -> #REF! | J20: =SUM(J13+SUM(J16:J19)) -> #REF! | K20: =SUM(K13+SUM(K16:K19)) -> #REF! | L20: =SUM(L13+SUM(L16:L19)) -> #REF! | M20: =SUM(M13+SUM(M16:M19)) -> #REF! | N20: =SUM(N13+SUM(N16:N19)) -> #REF! | O20: =SUM(O13+SUM(O16:O19)) -> #REF! | ... V20: =SUM(V13+SUM(V16:V19)) -> 0 | X20: =SUM(X13+SUM(X16:X19)) -> #REF! | Y20: =SUM(Y13+SUM(Y16:Y19)) -> #REF! | Z20: =SUM(Z13+SUM(Z16:Z19)) -> #REF! | AA20: =SUM(AA13+SUM(AA16:AA19)) -> #REF! | AB20: =SUM(AB13+SUM(AB16:AB19)) -> #REF! | AC20: =SUM(AC13+SUM(AC16:AC19)) -> #REF! | AD20: =SUM(AD13+SUM(AD16:AD19)) -> #REF! | AE20: =SUM(AE13+SUM(AE16:AE19)) -> #REF! | ... AI20: =SUM(AI13+SUM(AI16:AI19)) -> 0 | AK20: =SUM(AI20/AE20)-1 -> #REF!
B21: Operating Margin (%) | C21: =C20/C8 -> #REF! | D21: =D20/D8 -> #DIV/0! | E21: =E20/E8 -> #DIV/0! | F21: =F20/F8 -> #DIV/0! | H21: =H20/H8 -> #REF! | I21: =I20/I8 -> #REF! | J21: =J20/J8 -> #REF! | K21: =K20/K8 -> #REF! | L21: =L20/L8 -> #REF! | M21: =M20/M8 -> #REF! | N21: =N20/N8 -> #REF! | O21: =O20/O8 -> #REF! | ... V21: =V20/V8 -> #DIV/0! | X21: =X20/X8 -> #REF! | Y21: =Y20/Y8 -> #REF! | Z21: =Z20/Z8 -> #REF! | AA21: =AA20/AA8 -> #REF! | AB21: =AB20/AB8 -> #REF! | AC21: =AC20/AC8 -> #REF! | AD21: =AD20/AD8 -> #REF! | AE21: =AE20/AE8 -> #REF! | ... AI21: =AI20/AI8 -> #DIV/0! | AK21: =SUM(AI21-AE21)*10000 -> #DIV/0!
B23: (+) Depreciation and Amortization | C23: =-C19 -> #REF! | H23: =-H19 -> #REF! | I23: =-I19 -> #REF! | J23: =-J19 -> #REF! | K23: =-K19 -> #REF! | L23: =-L19 -> #REF! | M23: =-M19 -> #REF! | N23: =-N19 -> #REF! | O23: =-O19 -> #REF! | ... Q23: =-Q19 -> #REF! | X23: =SUM(G23:K23) -> #REF! | Y23: =SUM(I23:L23) -> #REF! | Z23: =SUM(J23:M23) -> #REF! | AA23: =SUM(K23:N23) -> #REF! | AB23: =SUM(L23:O23) -> #REF! | AC23: =SUM(M23:P23) -> #REF! | AD23: =SUM(N23:Q23) -> #REF! | AE23: =SUM(O23:R23) -> #REF! | AF23: =SUM(P23:S23) -> #REF! | ... AI23: =SUM(S23:V23) -> 0 | AK23: =SUM(AI23/AE23)-1 -> #REF!
B24: EBITDA | C24: =SUM(C20+C23) -> #REF! | D24: =SUM(D20+D23) -> 0 | E24: =SUM(E20+E23) -> 0 | F24: =SUM(F20+F23) -> 0 | H24: =SUM(H20+H23) -> #REF! | I24: =SUM(I20+I23) -> #REF! | J24: =SUM(J20+J23) -> #REF! | K24: =SUM(K20+K23) -> #REF! | L24: =SUM(L20+L23) -> #REF! | M24: =SUM(M20+M23) -> #REF! | N24: =SUM(N20+N23) -> #REF! | O24: =SUM(O20+O23) -> #REF! | ... V24: =SUM(V20+V23) -> 0 | X24: =SUM(X20+X23) -> #REF! | Y24: =SUM(Y20+Y23) -> #REF! | Z24: =SUM(Z20+Z23) -> #REF! | AA24: =SUM(AA20+AA23) -> #REF! | AB24: =SUM(AB20+AB23) -> #REF! | AC24: =SUM(AC20+AC23) -> #REF! | AD24: =SUM(AD20+AD23) -> #REF! | AE24: =SUM(AE20+AE23) -> #REF! | ... AI24: =SUM(AI20+AI23) -> 0 | AK24: =SUM(AI24/AE24)-1 -> #REF!
B25: EBITDA Margin (%) | C25: =C24/C8 -> #REF! | D25: =D24/D8 -> #DIV/0! | E25: =E24/E8 -> #DIV/0! | F25: =F24/F8 -> #DIV/0! | H25: =H24/H8 -> #REF! | I25: =I24/I8 -> #REF! | J25: =J24/J8 -> #REF! | K25: =K24/K8 -> #REF! | L25: =L24/L8 -> #REF! | M25: =M24/M8 -> #REF! | N25: =N24/N8 -> #REF! | O25: =O24/O8 -> #REF! | ... V25: =V24/V8 -> #DIV/0! | X25: =X24/X8 -> #REF! | Y25: =Y24/Y8 -> #REF! | Z25: =Z24/Z8 -> #REF! | AA25: =AA24/AA8 -> #REF! | AB25: =AB24/AB8 -> #REF! | AC25: =AC24/AC8 -> #REF! | AD25: =AD24/AD8 -> #REF! | AE25: =AE24/AE8 -> #REF! | ... AI25: =AI24/AI8 -> #DIV/0! | AK25: =SUM(AI25-AE25)*10000 -> #DIV/0!
B27: (+) Share-based Compensation | C27: ='Historical Financials'!#REF! -> #REF! | H27: ='Historical Financials'!G89 -> 10 | I27: ='Historical Financials'!H89 -> 7 | J27: ='Historical Financials'!I89 -> 7 | K27: ='Historical Financials'!J89 -> 8 | L27: ='Historical Financials'!K89 -> 32 | M27: ='Historical Financials'!L89 -> -16 | N27: ='Historical Financials'!M89 -> 8 | O27: ='Historical Financials'!N89 -> 9 | ... Q27: ='Historical Financials'!P89 -> 18 | X27: =SUM(G27:K27) -> 32 | Y27: =SUM(I27:L27) -> 54 | Z27: =SUM(J27:M27) -> 31 | AA27: =SUM(K27:N27) -> 32 | AB27: =SUM(L27:O27) -> 33 | AC27: =SUM(M27:P27) -> 10 | AD27: =SUM(N27:Q27) -> 44 | AE27: =SUM(O27:R27) -> 36 | AF27: =SUM(P27:S27) -> 27 | ... AI27: =SUM(S27:V27) -> 0 | AK27: =SUM(AI27/AE27)-1 -> -1
B28: Adj. EBITDA | C28: =+SUM(C24+SUM(C27:C27)) -> #REF! | D28: =+SUM(D24+SUM(D27:D27)) -> 0 | E28: =+SUM(E24+SUM(E27:E27)) -> 0 | F28: =+SUM(F24+SUM(F27:F27)) -> 0 | H28: =+SUM(H24+SUM(H27:H27)) -> #REF! | I28: =+SUM(I24+SUM(I27:I27)) -> #REF! | J28: =+SUM(J24+SUM(J27:J27)) -> #REF! | K28: =+SUM(K24+SUM(K27:K27)) -> #REF! | L28: =+SUM(L24+SUM(L27:L27)) -> #REF! | M28: =+SUM(M24+SUM(M27:M27)) -> #REF! | N28: =+SUM(N24+SUM(N27:N27)) -> #REF! | O28: =+SUM(O24+SUM(O27:O27)) -> #REF! | ... V28: =+SUM(V24+SUM(V27:V27)) -> 0 | X28: =+SUM(X24+SUM(X27:X27)) -> #REF! | Y28: =+SUM(Y24+SUM(Y27:Y27)) -> #REF! | Z28: =+SUM(Z24+SUM(Z27:Z27)) -> #REF! | AA28: =+SUM(AA24+SUM(AA27:AA27)) -> #REF! | AB28: =+SUM(AB24+SUM(AB27:AB27)) -> #REF! | AC28: =+SUM(AC24+SUM(AC27:AC27)) -> #REF! | AD28: =+SUM(AD24+SUM(AD27:AD27)) -> #REF! | AE28: =+SUM(AE24+SUM(AE27:AE27)) -> #REF! | ... AI28: =+SUM(AI24+SUM(AI27:AI27)) -> 0 | AK28: =SUM(AI28/AE28)-1 -> #REF!
B29: Adj. EBITDA Margin (%) | C29: =C28/C8 -> #REF! | D29: =D28/D8 -> #DIV/0! | E29: =E28/E8 -> #DIV/0! | F29: =F28/F8 -> #DIV/0! | H29: =H28/H8 -> #REF! | I29: =I28/I8 -> #REF! | J29: =J28/J8 -> #REF! | K29: =K28/K8 -> #REF! | L29: =L28/L8 -> #REF! | M29: =M28/M8 -> #REF! | N29: =N28/N8 -> #REF! | O29: =O28/O8 -> #REF! | ... V29: =V28/V8 -> #DIV/0! | X29: =X28/X8 -> #REF! | Y29: =Y28/Y8 -> #REF! | Z29: =Z28/Z8 -> #REF! | AA29: =AA28/AA8 -> #REF! | AB29: =AB28/AB8 -> #REF! | AC29: =AC28/AC8 -> #REF! | AD29: =AD28/AD8 -> #REF! | AE29: =AE28/AE8 -> #REF! | ... AI29: =AI28/AI8 -> #DIV/0! | AK29: =SUM(AI29-AE29)*10000 -> #DIV/0!
B31: (-) Capital Expenditures | C31: =SUM('Historical Financials'!#REF!+'Historical Financials'!#REF!) -> #REF! | H31: =SUM('Historical Financials'!#REF!+'Historical Financials'!#REF!) -> #REF! | I31: =SUM('Historical Financials'!#REF!+'Historical Financials'!#REF!) -> #REF! | J31: =SUM('Historical Financials'!#REF!+'Historical Financials'!#REF!) -> #REF! | K31: =SUM('Historical Financials'!#REF!+'Historical Financials'!#REF!) -> #REF! | L31: =SUM('Historical Financials'!#REF!+'Historical Financials'!#REF!) -> #REF! | M31: =SUM('Historical Financials'!#REF!+'Historical Financials'!#REF!) -> #REF! | N31: =SUM('Historical Financials'!#REF!+'Historical Financials'!#REF!) -> #REF! | O31: =SUM('Historical Financials'!#REF!+'Historical Financials'!#REF!) -> #REF! | ... Q31: =SUM('Historical Financials'!#REF!+'Historical Financials'!#REF!) -> #REF! | X31: =SUM(G31:K31) -> #REF! | Y31: =SUM(I31:L31) -> #REF! | Z31: =SUM(J31:M31) -> #REF! | AA31: =SUM(K31:N31) -> #REF! | AB31: =SUM(L31:O31) -> #REF! | AC31: =SUM(M31:P31) -> #REF! | AD31: =SUM(N31:Q31) -> #REF! | AE31: =SUM(O31:R31) -> #REF! | AF31: =SUM(P31:S31) -> #REF! | ... AI31: =SUM(S31:V31) -> 0 | AK31: =SUM(AI31/AE31)-1 -> #REF!
B32: (-) Cash Taxes | C32: ='Historical Financials'!#REF! -> #REF! | H32: ='Historical Financials'!G28 -> 0 | I32: ='Historical Financials'!H28 -> 0 | J32: ='Historical Financials'!I28 -> 0 | K32: ='Historical Financials'!J28 -> 0 | L32: ='Historical Financials'!K28 -> 0 | M32: ='Historical Financials'!L28 -> 0 | N32: ='Historical Financials'!M28 -> 0 | O32: ='Historical Financials'!N28 -> 0 | ... Q32: ='Historical Financials'!P28 -> 0 | X32: =SUM(G32:K32) -> 0 | Y32: =SUM(I32:L32) -> 0 | Z32: =SUM(J32:M32) -> 0 | AA32: =SUM(K32:N32) -> 0 | AB32: =SUM(L32:O32) -> 0 | AC32: =SUM(M32:P32) -> 0 | AD32: =SUM(N32:Q32) -> 0 | AE32: =SUM(O32:R32) -> 0 | AF32: =SUM(P32:S32) -> 0 | ... AI32: =SUM(S32:V32) -> 0 | AK32: =SUM(AI32/AE32)-1 -> #DIV/0!
B33: (-) Cash Interest | C33: 0 | H33: 0 | I33: 0 | J33: 0 | K33: =D33 -> 0 | L33: 0 | M33: 0 | N33: 0 | O33: =E33 -> 0 | P33: 0 | Q33: 0 | X33: =SUM(G33:K33) -> 0 | Y33: =SUM(I33:L33) -> 0 | Z33: =SUM(J33:M33) -> 0 | AA33: =SUM(K33:N33) -> 0 | AB33: =SUM(L33:O33) -> 0 | AC33: =SUM(M33:P33) -> 0 | AD33: =SUM(N33:Q33) -> 0 | AE33: =SUM(O33:R33) -> 0 | AF33: =SUM(P33:S33) -> 0 | ... AI33: =SUM(S33:V33) -> 0 | AK33: =SUM(AI33/AE33)-1 -> #DIV/0!
B34: (+/-) Changes in NWC | C34: =SUM('Historical Financials'!#REF!) -> #REF! | H34: =SUM('Historical Financials'!G94:G96) -> 1171 | I34: =SUM('Historical Financials'!H94:H96) -> 1728 | J34: =SUM('Historical Financials'!I94:I96) -> -780 | K34: =SUM('Historical Financials'!J94:J96) -> 2849 | L34: =SUM('Historical Financials'!K94:K96) -> -873 | M34: =SUM('Historical Financials'!L94:L96) -> -898 | N34: =SUM('Historical Financials'!M94:M96) -> 1515 | O34: =SUM('Historical Financials'!N94:N96) -> 4934 | ... Q34: =SUM('Historical Financials'!P94:P96) -> 3150 | X34: =SUM(G34:K34) -> 4968 | Y34: =SUM(I34:L34) -> 2924 | Z34: =SUM(J34:M34) -> 298 | AA34: =SUM(K34:N34) -> 2593 | AB34: =SUM(L34:O34) -> 4678 | AC34: =SUM(M34:P34) -> 3246 | AD34: =SUM(N34:Q34) -> 7294 | AE34: =SUM(O34:R34) -> 5779 | AF34: =SUM(P34:S34) -> 845 | ... AI34: =SUM(S34:V34) -> 0 | AK34: =SUM(AI34/AE34)-1 -> -1
B35: Discretionary Cash-Flows | C35: =SUM(C28+SUM(C31:C34)) -> #REF! | D35: =SUM(D28+SUM(D31:D34)) -> 0 | E35: =SUM(E28+SUM(E31:E34)) -> 0 | F35: =SUM(F28+SUM(F31:F34)) -> 0 | H35: =SUM(H28+SUM(H31:H34)) -> #REF! | I35: =SUM(I28+SUM(I31:I34)) -> #REF! | J35: =SUM(J28+SUM(J31:J34)) -> #REF! | K35: =SUM(K28+SUM(K31:K34)) -> #REF! | L35: =SUM(L28+SUM(L31:L34)) -> #REF! | M35: =SUM(M28+SUM(M31:M34)) -> #REF! | N35: =SUM(N28+SUM(N31:N34)) -> #REF! | O35: =SUM(O28+SUM(O31:O34)) -> #REF! | ... V35: =SUM(V28+SUM(V31:V34)) -> 0 | X35: =SUM(X28+SUM(X31:X34)) -> #REF! | Y35: =SUM(Y28+SUM(Y31:Y34)) -> #REF! | Z35: =SUM(Z28+SUM(Z31:Z34)) -> #REF! | AA35: =SUM(AA28+SUM(AA31:AA34)) -> #REF! | AB35: =SUM(AB28+SUM(AB31:AB34)) -> #REF! | AC35: =SUM(AC28+SUM(AC31:AC34)) -> #REF! | AD35: =SUM(AD28+SUM(AD31:AD34)) -> #REF! | AE35: =SUM(AE28+SUM(AE31:AE34)) -> #REF! | ... AI35: =SUM(AI28+SUM(AI31:AI34)) -> 0 | AK35: =SUM(AI35/AE35)-1 -> #REF!
B37: (+/-) Proceeds / (Purchases) of Equity, net | C37: ='Historical Financials'!#REF! -> #REF! | H37: ='Historical Financials'!#REF! -> #REF! | I37: ='Historical Financials'!#REF! -> #REF! | J37: ='Historical Financials'!#REF! -> #REF! | K37: ='Historical Financials'!#REF! -> #REF! | L37: ='Historical Financials'!#REF! -> #REF! | M37: ='Historical Financials'!#REF! -> #REF! | N37: ='Historical Financials'!#REF! -> #REF! | O37: ='Historical Financials'!#REF! -> #REF! | ... Q37: ='Historical Financials'!#REF! -> #REF! | X37: =SUM(G37:K37) -> #REF! | Y37: =SUM(I37:L37) -> #REF! | Z37: =SUM(J37:M37) -> #REF! | AA37: =SUM(K37:N37) -> #REF! | AB37: =SUM(L37:O37) -> #REF! | AC37: =SUM(M37:P37) -> #REF! | AD37: =SUM(N37:Q37) -> #REF! | AE37: =SUM(O37:R37) -> #REF! | AF37: =SUM(P37:S37) -> #REF! | ... AI37: =SUM(S37:V37) -> 0
B38: (+/-) Maturities / (Purchases) of available-for-sale securities | C38: =SUM('Historical Financials'!#REF!) -> #REF! | H38: =SUM('Historical Financials'!#REF!) -> #REF! | I38: =SUM('Historical Financials'!#REF!) -> #REF! | J38: =SUM('Historical Financials'!#REF!) -> #REF! | K38: =SUM('Historical Financials'!#REF!) -> #REF! | L38: =SUM('Historical Financials'!#REF!) -> #REF! | M38: =SUM('Historical Financials'!#REF!) -> #REF! | N38: =SUM('Historical Financials'!#REF!) -> #REF! | O38: =SUM('Historical Financials'!#REF!) -> #REF! | ... Q38: =SUM('Historical Financials'!#REF!) -> #REF! | X38: =SUM(G38:K38) -> #REF! | Y38: =SUM(I38:L38) -> #REF! | Z38: =SUM(J38:M38) -> #REF! | AA38: =SUM(K38:N38) -> #REF! | AB38: =SUM(L38:O38) -> #REF! | AC38: =SUM(M38:P38) -> #REF! | AD38: =SUM(N38:Q38) -> #REF! | AE38: =SUM(O38:R38) -> #REF! | AF38: =SUM(P38:S38) -> #REF! | ... AI38: =SUM(S38:V38) -> 0
B39: (+/-) Divestitures / (Acquisitions) | C39: ='Historical Financials'!#REF! -> #REF! | H39: ='Historical Financials'!#REF! -> #REF! | I39: ='Historical Financials'!#REF! -> #REF! | J39: ='Historical Financials'!#REF! -> #REF! | K39: ='Historical Financials'!#REF! -> #REF! | L39: ='Historical Financials'!#REF! -> #REF! | M39: ='Historical Financials'!#REF! -> #REF! | N39: ='Historical Financials'!#REF! -> #REF! | O39: ='Historical Financials'!#REF! -> #REF! | ... Q39: ='Historical Financials'!#REF! -> #REF! | X39: =SUM(G39:K39) -> #REF! | Y39: =SUM(I39:L39) -> #REF! | Z39: =SUM(J39:M39) -> #REF! | AA39: =SUM(K39:N39) -> #REF! | AB39: =SUM(L39:O39) -> #REF! | AC39: =SUM(M39:P39) -> #REF! | AD39: =SUM(N39:Q39) -> #REF! | AE39: =SUM(O39:R39) -> #REF! | AF39: =SUM(P39:S39) -> #REF! | ... AI39: =SUM(S39:V39) -> 0
B40: (+/-) Other Investing Activities | C40: ='Historical Financials'!#REF! -> #REF! | H40: ='Historical Financials'!#REF! -> #REF! | I40: ='Historical Financials'!#REF! -> #REF! | J40: ='Historical Financials'!#REF! -> #REF! | K40: ='Historical Financials'!#REF! -> #REF! | L40: ='Historical Financials'!#REF! -> #REF! | M40: ='Historical Financials'!#REF! -> #REF! | N40: ='Historical Financials'!#REF! -> #REF! | O40: ='Historical Financials'!#REF! -> #REF! | ... Q40: ='Historical Financials'!#REF! -> #REF! | X40: =SUM(G40:K40) -> #REF! | Y40: =SUM(I40:L40) -> #REF! | Z40: =SUM(J40:M40) -> #REF! | AA40: =SUM(K40:N40) -> #REF! | AB40: =SUM(L40:O40) -> #REF! | AC40: =SUM(M40:P40) -> #REF! | AD40: =SUM(N40:Q40) -> #REF! | AE40: =SUM(O40:R40) -> #REF! | AF40: =SUM(P40:S40) -> #REF! | ... AI40: =SUM(S40:V40) -> 0
B41: (+/-) Other Financing Activities | C41: ='Historical Financials'!#REF! -> #REF! | H41: ='Historical Financials'!#REF! -> #REF! | I41: ='Historical Financials'!#REF! -> #REF! | J41: ='Historical Financials'!#REF! -> #REF! | K41: ='Historical Financials'!#REF! -> #REF! | L41: ='Historical Financials'!#REF! -> #REF! | M41: ='Historical Financials'!#REF! -> #REF! | N41: ='Historical Financials'!#REF! -> #REF! | O41: ='Historical Financials'!#REF! -> #REF! | ... Q41: ='Historical Financials'!#REF! -> #REF! | X41: =SUM(G41:K41) -> #REF! | Y41: =SUM(I41:L41) -> #REF! | Z41: =SUM(J41:M41) -> #REF! | AA41: =SUM(K41:N41) -> #REF! | AB41: =SUM(L41:O41) -> #REF! | AC41: =SUM(M41:P41) -> #REF! | AD41: =SUM(N41:Q41) -> #REF! | AE41: =SUM(O41:R41) -> #REF! | AF41: =SUM(P41:S41) -> #REF! | ... AI41: =SUM(S41:V41) -> 0
B42: (+/-) Other Operating Activities | C42: ='Historical Financials'!#REF! -> #REF! | H42: ='Historical Financials'!#REF! -> #REF! | I42: ='Historical Financials'!#REF! -> #REF! | J42: ='Historical Financials'!#REF! -> #REF! | K42: ='Historical Financials'!#REF! -> #REF! | L42: ='Historical Financials'!#REF! -> #REF! | M42: ='Historical Financials'!#REF! -> #REF! | N42: ='Historical Financials'!#REF! -> #REF! | O42: ='Historical Financials'!#REF! -> #REF! | ... Q42: ='Historical Financials'!#REF! -> #REF! | X42: =SUM(G42:K42) -> #REF! | Y42: =SUM(I42:L42) -> #REF! | Z42: =SUM(J42:M42) -> #REF! | AA42: =SUM(K42:N42) -> #REF! | AB42: =SUM(L42:O42) -> #REF! | AC42: =SUM(M42:P42) -> #REF! | AD42: =SUM(N42:Q42) -> #REF! | AE42: =SUM(O42:R42) -> #REF! | AF42: =SUM(P42:S42) -> #REF! | ... AI42: =SUM(S42:V42) -> 0
B43: (+/-) Other | H43: =SUM(H48:H49)-SUM(C48:C49)-SUM(H35:H42) -> #REF! | I43: =SUM(I48:I49)-SUM(H48:H49)-SUM(I35:I42) -> #REF! | J43: =SUM(J48:J49)-SUM(I48:I49)-SUM(J35:J42) -> #REF! | K43: =SUM(K48:K49)-SUM(J48:J49)-SUM(K35:K42) -> #REF! | L43: =SUM(L48:L49)-SUM(K48:K49)-SUM(L35:L42) -> #REF! | M43: =SUM(M48:M49)-SUM(L48:L49)-SUM(M35:M42) -> #REF! | N43: =SUM(N48:N49)-SUM(M48:M49)-SUM(N35:N42) -> #REF! | O43: =SUM(O48:O49)-SUM(N48:N49)-SUM(O35:O42) -> #REF! | P43: =SUM(P48:P49)-SUM(O48:O49)-SUM(P35:P42) -> #REF! | Q43: =SUM(Q48:Q49)-SUM(P48:P49)-SUM(Q35:Q42) -> #REF! | X43: =SUM(G43:K43) -> #REF! | Y43: =SUM(I43:L43) -> #REF! | Z43: =SUM(J43:M43) -> #REF! | AA43: =SUM(K43:N43) -> #REF! | AB43: =SUM(L43:O43) -> #REF! | AC43: =SUM(M43:P43) -> #REF! | AD43: =SUM(N43:Q43) -> #REF! | AE43: =SUM(O43:R43) -> #REF! | AF43: =SUM(P43:S43) -> #REF! | ... AI43: =SUM(S43:V43) -> 0
B44: Free-Cash Flows | C44: =SUM(C35+SUM(C37:C43)) -> #REF! | D44: =SUM(D35+SUM(D37:D43)) -> 0 | E44: =SUM(E35+SUM(E37:E43)) -> 0 | F44: =SUM(F35+SUM(F37:F43)) -> 0 | H44: =SUM(H35+SUM(H37:H43)) -> #REF! | I44: =SUM(I35+SUM(I37:I43)) -> #REF! | J44: =SUM(J35+SUM(J37:J43)) -> #REF! | K44: =SUM(K35+SUM(K37:K43)) -> #REF! | L44: =SUM(L35+SUM(L37:L43)) -> #REF! | M44: =SUM(M35+SUM(M37:M43)) -> #REF! | N44: =SUM(N35+SUM(N37:N43)) -> #REF! | O44: =SUM(O35+SUM(O37:O43)) -> #REF! | ... V44: =SUM(V35+SUM(V37:V43)) -> 0 | X44: =SUM(X35+SUM(X37:X43)) -> #REF! | Y44: =SUM(Y35+SUM(Y37:Y43)) -> #REF! | Z44: =SUM(Z35+SUM(Z37:Z43)) -> #REF! | AA44: =SUM(AA35+SUM(AA37:AA43)) -> #REF! | AB44: =SUM(AB35+SUM(AB37:AB43)) -> #REF! | AC44: =SUM(AC35+SUM(AC37:AC43)) -> #REF! | AD44: =SUM(AD35+SUM(AD37:AD43)) -> #REF! | AE44: =SUM(AE35+SUM(AE37:AE43)) -> #REF! | ... AI44: =SUM(AI35+SUM(AI37:AI43)) -> 0
B46: Capitalization
B48: Cash & Cash Equivelants | C48: ='Historical Financials'!#REF! -> #REF! | H48: ='Historical Financials'!G43 -> 31606 | I48: ='Historical Financials'!H43 -> 24178 | J48: ='Historical Financials'!I43 -> 15831 | K48: ='Historical Financials'!J43 -> 18592 | L48: ='Historical Financials'!K43 -> 17799 | M48: ='Historical Financials'!L43 -> 17966 | N48: ='Historical Financials'!M43 -> 20362 | O48: ='Historical Financials'!N43 -> 25660 | ... Q48: ='Historical Financials'!P43 -> 25598 | X48: =K48 -> 18592 | Y48: =L48 -> 17799 | Z48: =M48 -> 17966 | AA48: =N48 -> 20362 | AB48: =O48 -> 25660 | AC48: =P48 -> 23555 | AD48: =Q48 -> 25598 | AE48: =R48 -> 0 | ... AI48: =V48 -> 0
B49: Restricted Cash | C49: ='Historical Financials'!#REF! -> #REF! | H49: ='Historical Financials'!#REF! -> #REF! | I49: ='Historical Financials'!#REF! -> #REF! | J49: ='Historical Financials'!#REF! -> #REF! | K49: ='Historical Financials'!#REF! -> #REF! | L49: ='Historical Financials'!#REF! -> #REF! | M49: ='Historical Financials'!#REF! -> #REF! | N49: ='Historical Financials'!#REF! -> #REF! | O49: ='Historical Financials'!#REF! -> #REF! | ... Q49: ='Historical Financials'!#REF! -> #REF! | X49: =K49 -> #REF! | Y49: =L49 -> #REF! | Z49: =M49 -> #REF! | AA49: =N49 -> #REF! | AB49: =O49 -> #REF! | AC49: =P49 -> #REF! | AD49: =Q49 -> #REF! | AE49: =R49 -> 0 | ... AI49: =V49 -> 0
B50: Short-term Investments | C50: ='Historical Financials'!#REF! -> #REF! | H50: ='Historical Financials'!#REF! -> #REF! | I50: ='Historical Financials'!#REF! -> #REF! | J50: ='Historical Financials'!#REF! -> #REF! | K50: ='Historical Financials'!#REF! -> #REF! | L50: ='Historical Financials'!#REF! -> #REF! | M50: ='Historical Financials'!#REF! -> #REF! | N50: ='Historical Financials'!#REF! -> #REF! | O50: ='Historical Financials'!#REF! -> #REF! | ... Q50: ='Historical Financials'!#REF! -> #REF! | X50: =K50 -> #REF! | Y50: =L50 -> #REF! | Z50: =M50 -> #REF! | AA50: =N50 -> #REF! | AB50: =O50 -> #REF! | AC50: =P50 -> #REF! | AD50: =Q50 -> #REF! | AE50: =R50 -> 0 | ... AI50: =V50 -> 0
...
